Workbook

Sheet Overview
A1: Paskola | I1: Pabaiga | M1: Grąžinta | Q1: Pinigai | U1: Grąžinta | W1: Vertė | AA1: Mokesčiai
A2: Nr. | B2: Inv. data | C2: Pavadinimas | D2: Šalis | E2: Kompanija | F2: Terminas | G2: % | H2: Investuota | I2: Planuojama | J2: Reali | K2: Liko | L2: Vėluoja | M2: Paskola | N2: Palūkanos | O2: Mokesčiai | Q2: Įnešta | R2: Investuota | S2: Premijos | T2: Gryni | U2: Paskola | V2: Palūkanos | W2: Viso | X2: Eur. | Y2: % | Z2: XIRR | AA2: Eur. | AC2: Vėluoja
A3: 1 | B3: ='10000159'!B9 -> 45962 | C3: ='10000159'!B1 -> ID 205551187 - 10000159 | D3: ='10000159'!B2 -> Bulgaria | E3: ='10000159'!B3 -> Lev Credit | F3: ='10000159'!B8 -> 1 m. 0 mėn. 2 d. | G3: ='10000159'!B15 -> 0.08 | H3: ='10000159'!B16 -> 80 | I3: ='10000159'!B11 -> 46329 | J3: ='10000159'!O3 | K3: ='10000159'!B12 -> 34 | L3: ='10000159'!P3 | M3: ='10000159'!K3 -> 0 | N3: ='10000159'!L3 -> 5.32 | O3: ='10000159'!M3 -> 0.5 | Q3: =Pinigai!I2 -> 300 | R3: =SUM(H3:H100)-U3 -> 317.41 | S3: =Pinigai!H2 -> 1.87 | T3: =W3-R3 -> 2.38 | U3: =SUM(M3:M100) -> 31.82 | V3: =SUM(N3:N100)-AA3 -> 17.92 | W3: =Q3+V3+S3 -> 319.79 | X3: =W3-Q3 -> 19.79 | Y3: =(W3-Q3)/Q3 -> 0.065966667 | Z3: =XIRR(Pinigai!K2:K200,Pinigai!A2:A200) -> 0.094623056 | AA3: =SUM(O3:O100) -> 2.07 | AC3: ='10000159'!Z3
A4: 2 | B4: ='10000160'!B9 -> 45962 | C4: ='10000160'!B1 -> ID 205551187 - 10000160 | D4: ='10000160'!B2 -> Bulgaria | E4: ='10000160'!B3 -> Lev Credit | F4: ='10000160'!B8 -> 1 m. 6 mėn. 2 d. | G4: ='10000160'!B15 -> 0.085 | H4: ='10000160'!B16 -> 10 | I4: ='10000160'!B11 -> 46510 | J4: ='10000160'!O3 | K4: ='10000160'!B12 -> 215 | L4: ='10000160'!P3 | M4: ='10000160'!K3 -> 0 | N4: ='10000160'!L3 -> 0.7 | O4: ='10000160'!M3 -> 0.1 | AC4: ='10000160'!Z3
A5: 3 | B5: ='10000158'!B9 -> 45962 | C5: ='10000158'!B1 -> ID 205551187 - 10000158 | D5: ='10000158'!B2 -> Bulgaria | E5: ='10000158'!B3 -> Lev Credit | F5: ='10000158'!B8 -> 0 m. 9 mėn. 2 d. | G5: ='10000158'!B15 -> 0.075 | H5: ='10000158'!B16 -> 10 | I5: ='10000158'!B11 -> 46237 | J5: ='10000158'!O3 -> 46237 | K5: ='10000158'!B12 | L5: ='10000158'!P3 | M5: ='10000158'!K3 -> 10 | N5: ='10000158'!L3 -> 0.54 | O5: ='10000158'!M3 -> 0.09 | AC5: ='10000158'!Z3
A6: 4 | B6: ='10000170'!B9 -> 45972 | C6: ='10000170'!B1 -> ID 202557159 - 10000170 | D6: ='10000170'!B2 -> Bulgaria | E6: ='10000170'!B3 -> Stikcredit | F6: ='10000170'!B8 -> 1 m. 0 mėn. 3 d. | G6: ='10000170'!B15 -> 0.11 | H6: ='10000170'!B16 -> 50 | I6: ='10000170'!B11 -> 46340 | J6: ='10000170'!O3 | K6: ='10000170'!B12 -> 45 | L6: ='10000170'!P3 | M6: ='10000170'!K3 -> 0 | N6: ='10000170'!L3 -> 4.59 | O6: ='10000170'!M3 -> 0.49 | AC6: ='10000170'!Z3
A7: 5 | B7: ='10000212'!B9 -> 46007 | C7: ='10000212'!B1 -> ID 203811241 - 10000212 | D7: ='10000212'!B2 -> Bulgaria | E7: ='10000212'!B3 -> Lendivo | F7: ='10000212'!B8 -> 1 m. 0 mėn. 3 d. | G7: ='10000212'!B15 -> 0.11 | H7: ='10000212'!B16 -> 21.49 | I7: ='10000212'!B11 -> 46375 | J7: ='10000212'!O3 | K7: ='10000212'!B12 -> 80 | L7: ='10000212'!P3 | M7: ='10000212'!K3 -> 0 | N7: ='10000212'!L3 -> 1.76 | O7: ='10000212'!M3 -> 0.18 | AC7: ='10000212'!Z3
A8: 6 | B8: ='10000263'!B9 -> 46042 | C8: ='10000263'!B1 -> ID 205174291 - 10000263 | D8: ='10000263'!B2 -> Bulgaria | E8: ='10000263'!B3 -> Tiberus | F8: ='10000263'!B8 -> 1 m. 0 mėn. 26 d. | G8: ='10000263'!B15 -> 0.1 | H8: ='10000263'!B16 -> 21.2 | I8: ='10000263'!B11 -> 46433 | J8: ='10000263'!O3 | K8: ='10000263'!B12 -> 138 | L8: ='10000263'!P3 | M8: ='10000263'!K3 -> 0 | N8: ='10000263'!L3 -> 1.36 | O8: ='10000263'!M3 -> 0.15 | AC8: ='10000263'!Z3
A9: 7 | B9: ='10000288'!B9 -> 46065 | C9: ='10000288'!B1 -> ID 202557159 - 10000288 | D9: ='10000288'!B2 -> Bulgaria | E9: ='10000288'!B3 -> Stickcredit | F9: ='10000288'!B8 -> 1 m. 0 mėn. 3 d. | G9: ='10000288'!B15 -> 0.12 | H9: ='10000288'!B16 -> 21.97 | I9: ='10000288'!B11 -> 46433 | J9: ='10000288'!O3 | K9: ='10000288'!B12 -> 138 | L9: ='10000288'!P3 | M9: ='10000288'!K3 -> 0 | N9: ='10000288'!L3 -> 1.54 | O9: ='10000288'!M3 -> 0.14 | AC9: ='10000288'!Z3
A10: 8 | B10: ='10000437'!B9 -> 46101 | C10: ='10000437'!B1 -> ID 202557159 - 10000437 | D10: ='10000437'!B2 -> Bulgaria | E10: ='10000437'!B3 -> Stickcredit | F10: ='10000437'!B8 -> 3 m. 0 mėn. 8 d. | G10: ='10000437'!B15 -> 0.16 | H10: ='10000437'!B16 -> 22.16 | I10: ='10000437'!B11 -> 47205 | J10: ='10000437'!O3 | K10: ='10000437'!B12 -> 910 | L10: ='10000437'!P3 | M10: ='10000437'!K3 -> 0 | N10: ='10000437'!L3 -> 1.83 | O10: ='10000437'!M3 -> 0.19 | AC10: ='10000437'!Z3
A11: 9 | B11: ='10000591'!B9 -> 46133 | C11: ='10000591'!B1 -> ID 205174291 - 10000591 | D11: ='10000591'!B2 -> Bulgaria | E11: ='10000591'!B3 -> Tiberus | F11: ='10000591'!B8 -> 1 m. 0 mėn. 7 d. | G11: ='10000591'!B15 -> 0.12 | H11: ='10000591'!B16 -> 21.56 | I11: ='10000591'!B11 -> 46505 | J11: ='10000591'!O3 | K11: ='10000591'!B12 -> 210 | L11: ='10000591'!P3 | M11: ='10000591'!K3 -> 0 | N11: ='10000591'!L3 -> 1.1 | O11: ='10000591'!M3 -> 0.1 | AC11: ='10000591'!Z3
A12: 10 | B12: ='10000722'!B9 -> 46165 | C12: ='10000722'!B1 -> ID 205174291 - 10000722 | D12: ='10000722'!B2 -> Bulgaria | E12: ='10000722'!B3 -> Tiberus | F12: ='10000722'!B8 -> 0 m. 3 mėn. 5 d. | G12: ='10000722'!B15 -> 0.1 | H12: ='10000722'!B16 -> 21.82 | I12: ='10000722'!B11 -> 46262 | J12: ='10000722'!O3 -> 46262 | K12: ='10000722'!B12 | L12: ='10000722'!P3 | M12: ='10000722'!K3 -> 21.82 | N12: ='10000722'!L3 -> 0.57 | O12: ='10000722'!M3 -> 0.06 | AC12: ='10000722'!Z3
A13: 11 | B13: ='10001244'!B9 -> 46210 | C13: ='10001244'!B1 -> ID 205174291 - 10001244 | D13: ='10001244'!B2 -> Bulgaria | E13: ='10001244'!B3 -> Tiberus | F13: ='10001244'!B8 -> 0 m. 3 mėn. 8 d. | G13: ='10001244'!B15 -> 0.1 | H13: ='10001244'!B16 -> 23.27 | I13: ='10001244'!B11 -> 46310 | J13: ='10001244'!O3 | K13: ='10001244'!B12 -> 15 | L13: ='10001244'!P3 | M13: ='10001244'!K3 -> 0 | N13: ='10001244'!L3 -> 0.43 | O13: ='10001244'!M3 -> 0.04 | AC13: ='10001244'!Z3
A14: 12 | B14: ='10001352'!B9 -> 46238 | C14: ='10001352'!B1 -> ID 205174291 - 10001352 | D14: ='10001352'!B2 -> Bulgaria | E14: ='10001352'!B3 -> Tiberus | F14: ='10001352'!B8 -> 0 m. 3 mėn. 11 d. | G14: ='10001352'!B15 -> 0.1 | H14: ='10001352'!B16 -> 22.13 | I14: ='10001352'!B11 -> 46341 | J14: ='10001352'!O3 | K14: ='10001352'!B12 -> 46 | L14: ='10001352'!P3 | M14: ='10001352'!K3 -> 0 | N14: ='10001352'!L3 -> 0.25 | O14: ='10001352'!M3 -> 0.03 | AC14: ='10001352'!Z3
A15: 13 | B15: ='10001457'!B9 -> 46263 | C15: ='10001457'!B1 -> ID 205174291 - 10001457 | D15: ='10001457'!B2 -> Bulgaria | E15: ='10001457'!B3 -> Tiberus | F15: ='10001457'!B8 -> 1 m. 0 mėn. 17 d. | G15: ='10001457'!B15 -> 0.11 | H15: ='10001457'!B16 -> 23.63 | I15: ='10001457'!B11 -> 46645 | J15: ='10001457'!O3 | K15: ='10001457'!B12 -> 350 | L15: ='10001457'!P3 | M15: ='10001457'!K3 -> 0 | N15: ='10001457'!L3 -> 0 | O15: ='10001457'!M3 -> 0 | AC15: ='10001457'!Z3

Sheet Pinigai
A1: Data | B1: Įnešta | C1: Išimta | D1: Premija | F1: Įnešta | G1: Išimta | H1: Premija | I1: Skirtumas | K1: XIRR
A2: 45962 | B2: 100 | C2: 0 | D2: 0 | F2: =SUM(B2:B35) -> 300 | G2: =SUM(C2:C35) -> 0 | H2: =SUM(D2:D14) -> 1.87 | I2: =F2-G2 -> 300 | K2: =B2*-1 -> -100
A3: 45972 | B3: 50 | C3: 0 | D3: 0 | K3: =B3*-1 -> -50
A4: 45986 | B4: 0 | C4: 0 | D4: 0.5 | K4: =B4*-1 -> 0
A5: 46006 | B5: 20 | C5: 0 | D5: 0 | K5: =B5*-1 -> -20
A6: 46041 | B6: 20 | C6: 0 | D6: 0 | K6: =B6*-1 -> -20
A7: 46049 | B7: 0 | C7: 0 | D7: 0.95 | K7: =B7*-1 -> 0
A8: 46057 | B8: 0 | C8: 0 | D8: 0.42 | K8: =B8*-1 -> 0
A9: 46064 | B9: 20 | C9: 0 | D9: 0 | K9: =B9*-1 -> -20
A10: 46100 | B10: 20 | C10: 0 | D10: 0 | K10: =B10*-1 -> -20
A11: 46131 | B11: 20 | C11: 0 | D11: 0 | K11: =B11*-1 -> -20
A12: 46164 | B12: 20 | C12: 0 | D12: 0 | K12: =B12*-1 -> -20
A13: 46206 | B13: 20 | C13: 0 | D13: 0 | K13: =B13*-1 -> -20
A14: 46238 | B14: 10 | C14: 0 | D14: 0 | K14: =B14*-1 -> -10
A200: =TODAY() -> 46295 | K200: =Overview!W3 -> 319.79

Sheet 10001457
A1: Loan ID | B1: ID 205174291 - 10001457 | D1: Data | G1: Paskola | K1: Grąžinimas
A2: Šalis | B2: Bulgaria | D2: Planuojama | E2: Reali | F2: Vėl./Anks. | G2: Principal | H2: Interest | I2: Mokestis | K2: Paskola | L2: Palūkanos | M2: Mokesčiai | N2: XIRR | O2: Data | P2: Vėluoja | Q2: Vėl./Anks. | X2: Data | Y2: Suma | Z2: Vėluoja
A3: Skolintojas | B3: Tiberus | D3: 46310 | F3: =IF(E3>0,E3-D3,"") | K3: =G53 -> 0 | L3: =H53 -> 0 | M3: =I53 -> 0 | N3: =IF(B16=K3,XIRR(Y3:Y52,X3:X52),"") | O3: =IF(B16=K3,MAX(E:E),"") | P3: =IF(Z3="+",TODAY()-B11,"") | Q3: =IF(B16=K3,MAX(E:E)-B11,"") | X3: =B9 -> 46263 | Y3: =B16*-1 -> -23.63 | Z3: =IF(AND(TODAY()>B11, K3<>B16), "+", "")
A4: Tipas | B4: Business loan | X4: =E3 -> 0 | Y4: =G3+H3-I3 -> 0
F5: =IF(E5>0,E5-D5,"") | X5: =E4 -> 0 | Y5: =G4+H4-I4 -> 0
F6: =IF(E6>0,E6-D6,"") | X6: =E5 -> 0 | Y6: =G5+H5-I5 -> 0
F7: =IF(E7>0,E7-D7,"") | X7: =E6 -> 0 | Y7: =G6+H6-I6 -> 0
A8: Terminas | B8: =DATEDIF(B9,B11,"y") & " m. " & DATEDIF(B9,B11,"ym") & " mėn. " & DATEDIF(B9,B11,"md") & " d." -> 1 m. 0 mėn. 17 d. | F8: =IF(E8>0,E8-D8,"") | X8: =E7 -> 0 | Y8: =G7+H7-I7 -> 0
A9: Investuota | B9: 46263 | F9: =IF(E9>0,E9-D9,"") | X9: =E8 -> 0 | Y9: =G8+H8-I8 -> 0
A10: Pradžia | B10: 46263 | F10: =IF(E10>0,E10-D10,"") | X10: =E9 -> 0 | Y10: =G9+H9-I9 -> 0
A11: Pabaiga | B11: 46645 | F11: =IF(E11>0,E11-D11,"") | X11: =E10 -> 0 | Y11: =G10+H10-I10 -> 0
A12: Liko, dienos | B12: =IF(B16<>K3,(TODAY()-B11)*-1,"") -> 350 | F12: =IF(E12>0,E12-D12,"") | X12: =E11 -> 0 | Y12: =G11+H11-I11 -> 0
F13: =IF(E13>0,E13-D13,"") | X13: =E12 -> 0 | Y13: =G12+H12-I12 -> 0
F14: =IF(E14>0,E14-D14,"") | X14: =E13 -> 0 | Y14: =G13+H13-I13 -> 0
A15: Palūkanos | B15: 0.11 | F15: =IF(E15>0,E15-D15,"") | X15: =E14 -> 0 | Y15: =G14+H14-I14 -> 0
A16: Investuota, Eur | B16: 23.63 | F16: =IF(E16>0,E16-D16,"") | X16: =E15 -> 0 | Y16: =G15+H15-I15 -> 0
F17: =IF(E17>0,E17-D17,"") | X17: =E16 -> 0 | Y17: =G16+H16-I16 -> 0
F18: =IF(E18>0,E18-D18,"") | X18: =E17 -> 0 | Y18: =G17+H17-I17 -> 0
F19: =IF(E19>0,E19-D19,"") | X19: =E18 -> 0 | Y19: =G18+H18-I18 -> 0
F20: =IF(E20>0,E20-D20,"") | X20: =E19 -> 0 | Y20: =G19+H19-I19 -> 0
F21: =IF(E21>0,E21-D21,"") | X21: =E20 -> 0 | Y21: =G20+H20-I20 -> 0
F22: =IF(E22>0,E22-D22,"") | X22: =E21 -> 0 | Y22: =G21+H21-I21 -> 0
F23: =IF(E23>0,E23-D23,"") | X23: =E22 -> 0 | Y23: =G22+H22-I22 -> 0
F24: =IF(E24>0,E24-D24,"") | X24: =E23 -> 0 | Y24: =G23+H23-I23 -> 0
F25: =IF(E25>0,E25-D25,"") | X25: =E24 -> 0 | Y25: =G24+H24-I24 -> 0
F26: =IF(E26>0,E26-D26,"") | X26: =E25 -> 0 | Y26: =G25+H25-I25 -> 0
F27: =IF(E27>0,E27-D27,"") | X27: =E26 -> 0 | Y27: =G26+H26-I26 -> 0
F28: =IF(E28>0,E28-D28,"") | X28: =E27 -> 0 | Y28: =G27+H27-I27 -> 0
... F52: =IF(E52>0,E52-D52,"") | X52: =E51 -> 0 | Y52: =G51+H51-I51 -> 0
D53: Viso: | G53: =SUM(G3:G52) -> 0 | H53: =SUM(H3:H52) -> 0 | I53: =SUM(I3:I52) -> 0

Sheet 10001352
A1: Loan ID | B1: ID 205174291 - 10001352 | D1: Data | G1: Paskola | K1: Grąžinimas
A2: Šalis | B2: Bulgaria | D2: Planuojama | E2: Reali | F2: Vėl./Anks. | G2: Principal | H2: Interest | I2: Mokestis | K2: Paskola | L2: Palūkanos | M2: Mokesčiai | N2: XIRR | O2: Data | P2: Vėluoja | Q2: Vėl./Anks. | X2: Data | Y2: Suma | Z2: Vėluoja
A3: Skolintojas | B3: Tiberus | D3: 46280 | E3: 46280 | F3: =IF(E3>0,E3-D3,"") -> 0 | G3: 0 | H3: 0.25 | I3: 0.03 | K3: =G53 -> 0 | L3: =H53 -> 0.25 | M3: =I53 -> 0.03 | N3: =IF(B16=K3,XIRR(Y3:Y52,X3:X52),"") | O3: =IF(B16=K3,MAX(E:E),"") | P3: =IF(Z3="+",TODAY()-B11,"") | Q3: =IF(B16=K3,MAX(E:E)-B11,"") | X3: =B9 -> 46238 | Y3: =B16*-1 -> -22.13 | Z3: =IF(AND(TODAY()>B11, K3<>B16), "+", "")
A4: Tipas | B4: Business loan | D4: 46310 | X4: =E3 -> 46280 | Y4: =G3+H3-I3 -> 0.22
D5: 46341 | F5: =IF(E5>0,E5-D5,"") | X5: =E4 -> 0 | Y5: =G4+H4-I4 -> 0
F6: =IF(E6>0,E6-D6,"") | X6: =E5 -> 0 | Y6: =G5+H5-I5 -> 0
F7: =IF(E7>0,E7-D7,"") | X7: =E6 -> 0 | Y7: =G6+H6-I6 -> 0
A8: Terminas | B8: =DATEDIF(B9,B11,"y") & " m. " & DATEDIF(B9,B11,"ym") & " mėn. " & DATEDIF(B9,B11,"md") & " d." -> 0 m. 3 mėn. 11 d. | F8: =IF(E8>0,E8-D8,"") | X8: =E7 -> 0 | Y8: =G7+H7-I7 -> 0
A9: Investuota | B9: 46238 | F9: =IF(E9>0,E9-D9,"") | X9: =E8 -> 0 | Y9: =G8+H8-I8 -> 0
A10: Pradžia | B10: 46234 | F10: =IF(E10>0,E10-D10,"") | X10: =E9 -> 0 | Y10: =G9+H9-I9 -> 0
A11: Pabaiga | B11: 46341 | F11: =IF(E11>0,E11-D11,"") | X11: =E10 -> 0 | Y11: =G10+H10-I10 -> 0
A12: Liko, dienos | B12: =IF(B16<>K3,(TODAY()-B11)*-1,"") -> 46 | F12: =IF(E12>0,E12-D12,"") | X12: =E11 -> 0 | Y12: =G11+H11-I11 -> 0
F13: =IF(E13>0,E13-D13,"") | X13: =E12 -> 0 | Y13: =G12+H12-I12 -> 0
F14: =IF(E14>0,E14-D14,"") | X14: =E13 -> 0 | Y14: =G13+H13-I13 -> 0
A15: Palūkanos | B15: 0.1 | F15: =IF(E15>0,E15-D15,"") | X15: =E14 -> 0 | Y15: =G14+H14-I14 -> 0
A16: Investuota, Eur | B16: 22.13 | F16: =IF(E16>0,E16-D16,"") | X16: =E15 -> 0 | Y16: =G15+H15-I15 -> 0
F17: =IF(E17>0,E17-D17,"") | X17: =E16 -> 0 | Y17: =G16+H16-I16 -> 0
F18: =IF(E18>0,E18-D18,"") | X18: =E17 -> 0 | Y18: =G17+H17-I17 -> 0
F19: =IF(E19>0,E19-D19,"") | X19: =E18 -> 0 | Y19: =G18+H18-I18 -> 0
F20: =IF(E20>0,E20-D20,"") | X20: =E19 -> 0 | Y20: =G19+H19-I19 -> 0
F21: =IF(E21>0,E21-D21,"") | X21: =E20 -> 0 | Y21: =G20+H20-I20 -> 0
F22: =IF(E22>0,E22-D22,"") | X22: =E21 -> 0 | Y22: =G21+H21-I21 -> 0
F23: =IF(E23>0,E23-D23,"") | X23: =E22 -> 0 | Y23: =G22+H22-I22 -> 0
F24: =IF(E24>0,E24-D24,"") | X24: =E23 -> 0 | Y24: =G23+H23-I23 -> 0
F25: =IF(E25>0,E25-D25,"") | X25: =E24 -> 0 | Y25: =G24+H24-I24 -> 0
F26: =IF(E26>0,E26-D26,"") | X26: =E25 -> 0 | Y26: =G25+H25-I25 -> 0
F27: =IF(E27>0,E27-D27,"") | X27: =E26 -> 0 | Y27: =G26+H26-I26 -> 0
F28: =IF(E28>0,E28-D28,"") | X28: =E27 -> 0 | Y28: =G27+H27-I27 -> 0
... F52: =IF(E52>0,E52-D52,"") | X52: =E51 -> 0 | Y52: =G51+H51-I51 -> 0
D53: Viso: | G53: =SUM(G3:G52) -> 0 | H53: =SUM(H3:H52) -> 0.25 | I53: =SUM(I3:I52) -> 0.03

Sheet 10001244
A1: Loan ID | B1: ID 205174291 - 10001244 | D1: Data | G1: Paskola | K1: Grąžinimas
A2: Šalis | B2: Bulgaria | D2: Planuojama | E2: Reali | F2: Vėl./Anks. | G2: Principal | H2: Interest | I2: Mokestis | K2: Paskola | L2: Palūkanos | M2: Mokesčiai | N2: XIRR | O2: Data | P2: Vėluoja | Q2: Vėl./Anks. | X2: Data | Y2: Suma | Z2: Vėluoja
A3: Skolintojas | B3: Tiberus | D3: 46249 | E3: 46249 | F3: =IF(E3>0,E3-D3,"") -> 0 | G3: 0 | H3: 0.23 | I3: 0.02 | K3: =G53 -> 0 | L3: =H53 -> 0.43 | M3: =I53 -> 0.04 | N3: =IF(B16=K3,XIRR(Y3:Y52,X3:X52),"") | O3: =IF(B16=K3,MAX(E:E),"") | P3: =IF(Z3="+",TODAY()-B11,"") | Q3: =IF(B16=K3,MAX(E:E)-B11,"") | X3: =B9 -> 46210 | Y3: =B16*-1 -> -23.27 | Z3: =IF(AND(TODAY()>B11, K3<>B16), "+", "")
A4: Tipas | B4: Business loan | D4: 46280 | E4: 46280 | F4: 0 | G4: 0 | H4: 0.2 | I4: 0.02 | X4: =E3 -> 46249 | Y4: =G3+H3-I3 -> 0.21
D5: 46310 | F5: =IF(E5>0,E5-D5,"") | X5: =E4 -> 46280 | Y5: =G4+H4-I4 -> 0.18
F6: =IF(E6>0,E6-D6,"") | X6: =E5 -> 0 | Y6: =G5+H5-I5 -> 0
F7: =IF(E7>0,E7-D7,"") | X7: =E6 -> 0 | Y7: =G6+H6-I6 -> 0
A8: Terminas | B8: =DATEDIF(B9,B11,"y") & " m. " & DATEDIF(B9,B11,"ym") & " mėn. " & DATEDIF(B9,B11,"md") & " d." -> 0 m. 3 mėn. 8 d. | F8: =IF(E8>0,E8-D8,"") | X8: =E7 -> 0 | Y8: =G7+H7-I7 -> 0
A9: Investuota | B9: 46210 | F9: =IF(E9>0,E9-D9,"") | X9: =E8 -> 0 | Y9: =G8+H8-I8 -> 0
A10: Pradžia | B10: 46209 | F10: =IF(E10>0,E10-D10,"") | X10: =E9 -> 0 | Y10: =G9+H9-I9 -> 0
A11: Pabaiga | B11: 46310 | F11: =IF(E11>0,E11-D11,"") | X11: =E10 -> 0 | Y11: =G10+H10-I10 -> 0
A12: Liko, dienos | B12: =IF(B16<>K3,(TODAY()-B11)*-1,"") -> 15 | F12: =IF(E12>0,E12-D12,"") | X12: =E11 -> 0 | Y12: =G11+H11-I11 -> 0
F13: =IF(E13>0,E13-D13,"") | X13: =E12 -> 0 | Y13: =G12+H12-I12 -> 0
F14: =IF(E14>0,E14-D14,"") | X14: =E13 -> 0 | Y14: =G13+H13-I13 -> 0
A15: Palūkanos | B15: 0.1 | F15: =IF(E15>0,E15-D15,"") | X15: =E14 -> 0 | Y15: =G14+H14-I14 -> 0
A16: Investuota, Eur | B16: 23.27 | F16: =IF(E16>0,E16-D16,"") | X16: =E15 -> 0 | Y16: =G15+H15-I15 -> 0
F17: =IF(E17>0,E17-D17,"") | X17: =E16 -> 0 | Y17: =G16+H16-I16 -> 0
F18: =IF(E18>0,E18-D18,"") | X18: =E17 -> 0 | Y18: =G17+H17-I17 -> 0
F19: =IF(E19>0,E19-D19,"") | X19: =E18 -> 0 | Y19: =G18+H18-I18 -> 0
F20: =IF(E20>0,E20-D20,"") | X20: =E19 -> 0 | Y20: =G19+H19-I19 -> 0
F21: =IF(E21>0,E21-D21,"") | X21: =E20 -> 0 | Y21: =G20+H20-I20 -> 0
F22: =IF(E22>0,E22-D22,"") | X22: =E21 -> 0 | Y22: =G21+H21-I21 -> 0
F23: =IF(E23>0,E23-D23,"") | X23: =E22 -> 0 | Y23: =G22+H22-I22 -> 0
F24: =IF(E24>0,E24-D24,"") | X24: =E23 -> 0 | Y24: =G23+H23-I23 -> 0
F25: =IF(E25>0,E25-D25,"") | X25: =E24 -> 0 | Y25: =G24+H24-I24 -> 0
F26: =IF(E26>0,E26-D26,"") | X26: =E25 -> 0 | Y26: =G25+H25-I25 -> 0
F27: =IF(E27>0,E27-D27,"") | X27: =E26 -> 0 | Y27: =G26+H26-I26 -> 0
F28: =IF(E28>0,E28-D28,"") | X28: =E27 -> 0 | Y28: =G27+H27-I27 -> 0
... F52: =IF(E52>0,E52-D52,"") | X52: =E51 -> 0 | Y52: =G51+H51-I51 -> 0
D53: Viso: | G53: =SUM(G3:G52) -> 0 | H53: =SUM(H3:H52) -> 0.43 | I53: =SUM(I3:I52) -> 0.04

Sheet 10000722
A1: Loan ID | B1: ID 205174291 - 10000722 | D1: Data | G1: Paskola | K1: Grąžinimas
A2: Šalis | B2: Bulgaria | D2: Planuojama | E2: Reali | F2: Vėl./Anks. | G2: Principal | H2: Interest | I2: Mokestis | K2: Paskola | L2: Palūkanos | M2: Mokesčiai | N2: XIRR | O2: Data | P2: Vėluoja | Q2: Vėl./Anks. | X2: Data | Y2: Suma | Z2: Vėluoja
A3: Skolintojas | B3: Tiberus | D3: 46201 | E3: 46201 | F3: =IF(E3>0,E3-D3,"") -> 0 | G3: 0 | H3: 0.2 | I3: 0.02 | K3: =G53 -> 21.82 | L3: =H53 -> 0.57 | M3: =I53 -> 0.06 | N3: =IF(B16=K3,XIRR(Y3:Y52,X3:X52),"") -> 0.091536757 | O3: =IF(B16=K3,MAX(E:E),"") -> 46262 | P3: =IF(Z3="+",TODAY()-B11,"") | Q3: =IF(B16=K3,MAX(E:E)-B11,"") -> 0 | X3: =B9 -> 46165 | Y3: =B16*-1 -> -21.82 | Z3: =IF(AND(TODAY()>B11, K3<>B16), "+", "")
A4: Tipas | B4: Business loan | D4: 46231 | E4: 46231 | F4: =IF(E4>0,E4-D4,"") -> 0 | G4: 0 | H4: 0.18 | I4: 0.02 | X4: =E3 -> 46201 | Y4: =G3+H3-I3 -> 0.18
D5: 46262 | E5: 46262 | F5: =IF(E5>0,E5-D5,"") -> 0 | G5: 21.82 | H5: 0.19 | I5: 0.02 | X5: =E4 -> 46231 | Y5: =G4+H4-I4 -> 0.16
F6: =IF(E6>0,E6-D6,"") | X6: =E5 -> 46262 | Y6: =G5+H5-I5 -> 21.99
F7: =IF(E7>0,E7-D7,"") | X7: =E6 -> 0 | Y7: =G6+H6-I6 -> 0
A8: Terminas | B8: =DATEDIF(B9,B11,"y") & " m. " & DATEDIF(B9,B11,"ym") & " mėn. " & DATEDIF(B9,B11,"md") & " d." -> 0 m. 3 mėn. 5 d. | F8: =IF(E8>0,E8-D8,"") | X8: =E7 -> 0 | Y8: =G7+H7-I7 -> 0
A9: Investuota | B9: 46165 | F9: =IF(E9>0,E9-D9,"") | X9: =E8 -> 0 | Y9: =G8+H8-I8 -> 0
A10: Pradžia | B10: 46164 | F10: =IF(E10>0,E10-D10,"") | X10: =E9 -> 0 | Y10: =G9+H9-I9 -> 0
A11: Pabaiga | B11: 46262 | F11: =IF(E11>0,E11-D11,"") | X11: =E10 -> 0 | Y11: =G10+H10-I10 -> 0
A12: Liko, dienos | B12: =IF(B16<>K3,(TODAY()-B11)*-1,"") | F12: =IF(E12>0,E12-D12,"") | X12: =E11 -> 0 | Y12: =G11+H11-I11 -> 0
F13: =IF(E13>0,E13-D13,"") | X13: =E12 -> 0 | Y13: =G12+H12-I12 -> 0
F14: =IF(E14>0,E14-D14,"") | X14: =E13 -> 0 | Y14: =G13+H13-I13 -> 0
A15: Palūkanos | B15: 0.1 | F15: =IF(E15>0,E15-D15,"") | X15: =E14 -> 0 | Y15: =G14+H14-I14 -> 0
A16: Investuota, Eur | B16: 21.82 | F16: =IF(E16>0,E16-D16,"") | X16: =E15 -> 0 | Y16: =G15+H15-I15 -> 0
F17: =IF(E17>0,E17-D17,"") | X17: =E16 -> 0 | Y17: =G16+H16-I16 -> 0
F18: =IF(E18>0,E18-D18,"") | X18: =E17 -> 0 | Y18: =G17+H17-I17 -> 0
F19: =IF(E19>0,E19-D19,"") | X19: =E18 -> 0 | Y19: =G18+H18-I18 -> 0
F20: =IF(E20>0,E20-D20,"") | X20: =E19 -> 0 | Y20: =G19+H19-I19 -> 0
F21: =IF(E21>0,E21-D21,"") | X21: =E20 -> 0 | Y21: =G20+H20-I20 -> 0
F22: =IF(E22>0,E22-D22,"") | X22: =E21 -> 0 | Y22: =G21+H21-I21 -> 0
F23: =IF(E23>0,E23-D23,"") | X23: =E22 -> 0 | Y23: =G22+H22-I22 -> 0
F24: =IF(E24>0,E24-D24,"") | X24: =E23 -> 0 | Y24: =G23+H23-I23 -> 0
F25: =IF(E25>0,E25-D25,"") | X25: =E24 -> 0 | Y25: =G24+H24-I24 -> 0
F26: =IF(E26>0,E26-D26,"") | X26: =E25 -> 0 | Y26: =G25+H25-I25 -> 0
F27: =IF(E27>0,E27-D27,"") | X27: =E26 -> 0 | Y27: =G26+H26-I26 -> 0
F28: =IF(E28>0,E28-D28,"") | X28: =E27 -> 0 | Y28: =G27+H27-I27 -> 0
... F52: =IF(E52>0,E52-D52,"") | X52: =E51 -> 0 | Y52: =G51+H51-I51 -> 0
D53: Viso: | G53: =SUM(G3:G52) -> 21.82 | H53: =SUM(H3:H52) -> 0.57 | I53: =SUM(I3:I52) -> 0.06

Sheet 10000591
A1: Loan ID | B1: ID 205174291 - 10000591 | D1: Data | G1: Paskola | K1: Grąžinimas
A2: Šalis | B2: Bulgaria | D2: Planuojama | E2: Reali | F2: Vėl./Anks. | G2: Principal | H2: Interest | I2: Mokestis | K2: Paskola | L2: Palūkanos | M2: Mokesčiai | N2: XIRR | O2: Data | P2: Vėluoja | Q2: Vėl./Anks. | X2: Data | Y2: Suma | Z2: Vėluoja
A3: Skolintojas | B3: Tiberus | D3: 46170 | E3: 46170 | F3: =IF(E3>0,E3-D3,"") -> 0 | G3: 0 | H3: 0.23 | I3: 0.02 | K3: =G53 -> 0 | L3: =H53 -> 1.1 | M3: =I53 -> 0.1 | N3: =IF(B16=K3,XIRR(Y3:Y52,X3:X52),"") | O3: =IF(B16=K3,MAX(E:E),"") | P3: =IF(Z3="+",TODAY()-B11,"") | Q3: =IF(B16=K3,MAX(E:E)-B11,"") | X3: =B9 -> 46133 | Y3: =B16*-1 -> -21.56 | Z3: =IF(AND(TODAY()>B11, K3<>B16), "+", "")
A4: Tipas | B4: Business loan | D4: 46201 | E4: 46201 | F4: =IF(E4>0,E4-D4,"") -> 0 | G4: 0 | H4: 0.22 | I4: 0.02 | X4: =E3 -> 46170 | Y4: =G3+H3-I3 -> 0.21
D5: 46231 | E5: 46231 | F5: =IF(E5>0,E5-D5,"") -> 0 | G5: 0 | H5: 0.21 | I5: 0.02 | X5: =E4 -> 46201 | Y5: =G4+H4-I4 -> 0.2
D6: 46262 | E6: 46262 | F6: =IF(E6>0,E6-D6,"") -> 0 | G6: 0 | H6: 0.22 | I6: 0.02 | X6: =E5 -> 46231 | Y6: =G5+H5-I5 -> 0.19
D7: 46293 | E7: 46293 | F7: =IF(E7>0,E7-D7,"") -> 0 | G7: 0 | H7: 0.22 | I7: 0.02 | X7: =E6 -> 46262 | Y7: =G6+H6-I6 -> 0.2
A8: Terminas | B8: =DATEDIF(B9,B11,"y") & " m. " & DATEDIF(B9,B11,"ym") & " mėn. " & DATEDIF(B9,B11,"md") & " d." -> 1 m. 0 mėn. 7 d. | D8: 46323 | F8: =IF(E8>0,E8-D8,"") | X8: =E7 -> 46293 | Y8: =G7+H7-I7 -> 0.2
A9: Investuota | B9: 46133 | D9: 46354 | F9: =IF(E9>0,E9-D9,"") | X9: =E8 -> 0 | Y9: =G8+H8-I8 -> 0
A10: Pradžia | B10: 46137 | D10: 46384 | F10: =IF(E10>0,E10-D10,"") | X10: =E9 -> 0 | Y10: =G9+H9-I9 -> 0
A11: Pabaiga | B11: 46505 | D11: 46415 | F11: =IF(E11>0,E11-D11,"") | X11: =E10 -> 0 | Y11: =G10+H10-I10 -> 0
A12: Liko, dienos | B12: =IF(B16<>K3,(TODAY()-B11)*-1,"") -> 210 | D12: 46446 | F12: =IF(E12>0,E12-D12,"") | X12: =E11 -> 0 | Y12: =G11+H11-I11 -> 0
D13: 46474 | F13: =IF(E13>0,E13-D13,"") | X13: =E12 -> 0 | Y13: =G12+H12-I12 -> 0
D14: 46505 | F14: =IF(E14>0,E14-D14,"") | X14: =E13 -> 0 | Y14: =G13+H13-I13 -> 0
A15: Palūkanos | B15: 0.12 | F15: =IF(E15>0,E15-D15,"") | X15: =E14 -> 0 | Y15: =G14+H14-I14 -> 0
A16: Investuota, Eur | B16: 21.56 | F16: =IF(E16>0,E16-D16,"") | X16: =E15 -> 0 | Y16: =G15+H15-I15 -> 0
F17: =IF(E17>0,E17-D17,"") | X17: =E16 -> 0 | Y17: =G16+H16-I16 -> 0
F18: =IF(E18>0,E18-D18,"") | X18: =E17 -> 0 | Y18: =G17+H17-I17 -> 0
F19: =IF(E19>0,E19-D19,"") | X19: =E18 -> 0 | Y19: =G18+H18-I18 -> 0
F20: =IF(E20>0,E20-D20,"") | X20: =E19 -> 0 | Y20: =G19+H19-I19 -> 0
F21: =IF(E21>0,E21-D21,"") | X21: =E20 -> 0 | Y21: =G20+H20-I20 -> 0
F22: =IF(E22>0,E22-D22,"") | X22: =E21 -> 0 | Y22: =G21+H21-I21 -> 0
F23: =IF(E23>0,E23-D23,"") | X23: =E22 -> 0 | Y23: =G22+H22-I22 -> 0
F24: =IF(E24>0,E24-D24,"") | X24: =E23 -> 0 | Y24: =G23+H23-I23 -> 0
F25: =IF(E25>0,E25-D25,"") | X25: =E24 -> 0 | Y25: =G24+H24-I24 -> 0
F26: =IF(E26>0,E26-D26,"") | X26: =E25 -> 0 | Y26: =G25+H25-I25 -> 0
F27: =IF(E27>0,E27-D27,"") | X27: =E26 -> 0 | Y27: =G26+H26-I26 -> 0
F28: =IF(E28>0,E28-D28,"") | X28: =E27 -> 0 | Y28: =G27+H27-I27 -> 0
... F52: =IF(E52>0,E52-D52,"") | X52: =E51 -> 0 | Y52: =G51+H51-I51 -> 0
D53: Viso: | G53: =SUM(G3:G52) -> 0 | H53: =SUM(H3:H52) -> 1.1 | I53: =SUM(I3:I52) -> 0.1

Sheet 10000437
A1: Loan ID | B1: ID 202557159 - 10000437 | D1: Data | G1: Paskola | K1: Grąžinimas
A2: Šalis | B2: Bulgaria | D2: Planuojama | E2: Reali | F2: Vėl./Anks. | G2: Principal | H2: Interest | I2: Mokestis | K2: Paskola | L2: Palūkanos | M2: Mokesčiai | N2: XIRR | O2: Data | P2: Vėluoja | Q2: Vėl./Anks. | X2: Data | Y2: Suma | Z2: Vėluoja
A3: Skolintojas | B3: Stickcredit | D3: 46140 | E3: 46140 | F3: =IF(E3>0,E3-D3,"") -> 0 | G3: 0 | H3: 0.35 | I3: 0.04 | K3: =G53 -> 0 | L3: =H53 -> 1.83 | M3: =I53 -> 0.19 | N3: =IF(B16=K3,XIRR(Y3:Y52,X3:X52),"") | O3: =IF(B16=K3,MAX(E:E),"") | P3: =IF(Z3="+",TODAY()-B11,"") | Q3: =IF(B16=K3,MAX(E:E)-B11,"") | X3: =B9 -> 46101 | Y3: =B16*-1 -> -22.16 | Z3: =IF(AND(TODAY()>B11, K3<>B16), "+", "")
A4: Tipas | B4: Business loan | D4: 46170 | E4: 46170 | F4: 0 | G4: 0 | H4: 0.29 | I4: 0.03 | X4: =E3 -> 46140 | Y4: =G3+H3-I3 -> 0.31
D5: 46201 | E5: 46201 | F5: =IF(E5>0,E5-D5,"") -> 0 | G5: 0 | H5: 0.3 | I5: 0.03 | X5: =E4 -> 46170 | Y5: =G4+H4-I4 -> 0.26
D6: 46231 | E6: 46231 | F6: =IF(E6>0,E6-D6,"") -> 0 | G6: 0 | H6: 0.29 | I6: 0.03 | X6: =E5 -> 46201 | Y6: =G5+H5-I5 -> 0.27
D7: 46262 | E7: 46262 | F7: =IF(E7>0,E7-D7,"") -> 0 | G7: 0 | H7: 0.3 | I7: 0.03 | X7: =E6 -> 46231 | Y7: =G6+H6-I6 -> 0.26
A8: Terminas | B8: =DATEDIF(B9,B11,"y") & " m. " & DATEDIF(B9,B11,"ym") & " mėn. " & DATEDIF(B9,B11,"md") & " d." -> 3 m. 0 mėn. 8 d. | D8: 46293 | E8: 46293 | F8: =IF(E8>0,E8-D8,"") -> 0 | G8: 0 | H8: 0.3 | I8: 0.03 | X8: =E7 -> 46262 | Y8: =G7+H7-I7 -> 0.27
A9: Investuota | B9: 46101 | D9: 46323 | F9: =IF(E9>0,E9-D9,"") | X9: =E8 -> 46293 | Y9: =G8+H8-I8 -> 0.27
A10: Pradžia | B10: 46104 | D10: 46354 | F10: =IF(E10>0,E10-D10,"") | X10: =E9 -> 0 | Y10: =G9+H9-I9 -> 0
A11: Pabaiga | B11: 47205 | D11: 46384 | F11: =IF(E11>0,E11-D11,"") | X11: =E10 -> 0 | Y11: =G10+H10-I10 -> 0
A12: Liko, dienos | B12: =IF(B16<>K3,(TODAY()-B11)*-1,"") -> 910 | D12: 46415 | F12: =IF(E12>0,E12-D12,"") | X12: =E11 -> 0 | Y12: =G11+H11-I11 -> 0
D13: 46446 | F13: =IF(E13>0,E13-D13,"") | X13: =E12 -> 0 | Y13: =G12+H12-I12 -> 0
D14: 46474 | F14: =IF(E14>0,E14-D14,"") | X14: =E13 -> 0 | Y14: =G13+H13-I13 -> 0
A15: Palūkanos | B15: 0.16 | D15: 46505 | F15: =IF(E15>0,E15-D15,"") | X15: =E14 -> 0 | Y15: =G14+H14-I14 -> 0
A16: Investuota, Eur | B16: 22.16 | D16: 46535 | F16: =IF(E16>0,E16-D16,"") | X16: =E15 -> 0 | Y16: =G15+H15-I15 -> 0
D17: 46566 | F17: =IF(E17>0,E17-D17,"") | X17: =E16 -> 0 | Y17: =G16+H16-I16 -> 0
D18: 46596 | F18: =IF(E18>0,E18-D18,"") | X18: =E17 -> 0 | Y18: =G17+H17-I17 -> 0
D19: 46627 | F19: =IF(E19>0,E19-D19,"") | X19: =E18 -> 0 | Y19: =G18+H18-I18 -> 0
D20: 46658 | F20: =IF(E20>0,E20-D20,"") | X20: =E19 -> 0 | Y20: =G19+H19-I19 -> 0
D21: 46688 | F21: =IF(E21>0,E21-D21,"") | X21: =E20 -> 0 | Y21: =G20+H20-I20 -> 0
D22: 46719 | F22: =IF(E22>0,E22-D22,"") | X22: =E21 -> 0 | Y22: =G21+H21-I21 -> 0
D23: 46749 | F23: =IF(E23>0,E23-D23,"") | X23: =E22 -> 0 | Y23: =G22+H22-I22 -> 0
D24: 46780 | F24: =IF(E24>0,E24-D24,"") | X24: =E23 -> 0 | Y24: =G23+H23-I23 -> 0
D25: 46811 | F25: =IF(E25>0,E25-D25,"") | X25: =E24 -> 0 | Y25: =G24+H24-I24 -> 0
D26: 46840 | F26: =IF(E26>0,E26-D26,"") | X26: =E25 -> 0 | Y26: =G25+H25-I25 -> 0
D27: 46871 | F27: =IF(E27>0,E27-D27,"") | X27: =E26 -> 0 | Y27: =G26+H26-I26 -> 0
D28: 46901 | F28: =IF(E28>0,E28-D28,"") | X28: =E27 -> 0 | Y28: =G27+H27-I27 -> 0
... D38: 47205 | F38: =IF(E38>0,E38-D38,"") | X38: =E37 -> 0 | Y38: =G37+H37-I37 -> 0
F39: =IF(E39>0,E39-D39,"") | X39: =E38 -> 0 | Y39: =G38+H38-I38 -> 0
F40: =IF(E40>0,E40-D40,"") | X40: =E39 -> 0 | Y40: =G39+H39-I39 -> 0
F41: =IF(E41>0,E41-D41,"") | X41: =E40 -> 0 | Y41: =G40+H40-I40 -> 0
F42: =IF(E42>0,E42-D42,"") | X42: =E41 -> 0 | Y42: =G41+H41-I41 -> 0
F43: =IF(E43>0,E43-D43,"") | X43: =E42 -> 0 | Y43: =G42+H42-I42 -> 0
F44: =IF(E44>0,E44-D44,"") | X44: =E43 -> 0 | Y44: =G43+H43-I43 -> 0
F45: =IF(E45>0,E45-D45,"") | X45: =E44 -> 0 | Y45: =G44+H44-I44 -> 0
F46: =IF(E46>0,E46-D46,"") | X46: =E45 -> 0 | Y46: =G45+H45-I45 -> 0
F47: =IF(E47>0,E47-D47,"") | X47: =E46 -> 0 | Y47: =G46+H46-I46 -> 0
F48: =IF(E48>0,E48-D48,"") | X48: =E47 -> 0 | Y48: =G47+H47-I47 -> 0
F49: =IF(E49>0,E49-D49,"") | X49: =E48 -> 0 | Y49: =G48+H48-I48 -> 0
...

Sheet 10000288
A1: Loan ID | B1: ID 202557159 - 10000288 | D1: Data | G1: Paskola | K1: Grąžinimas
A2: Šalis | B2: Bulgaria | D2: Planuojama | E2: Reali | F2: Vėl./Anks. | G2: Principal | H2: Interest | I2: Mokestis | K2: Paskola | L2: Palūkanos | M2: Mokesčiai | N2: XIRR | O2: Data | P2: Vėluoja | Q2: Vėl./Anks. | X2: Data | Y2: Suma | Z2: Vėluoja
A3: Skolintojas | B3: Stickcredit | D3: 46096 | E3: 46096 | F3: =IF(E3>0,E3-D3,"") -> 0 | G3: 0 | H3: 0.22 | I3: 0.02 | K3: =G53 -> 0 | L3: =H53 -> 1.54 | M3: =I53 -> 0.14 | N3: =IF(B16=K3,XIRR(Y3:Y52,X3:X52),"") | O3: =IF(B16=K3,MAX(E:E),"") | P3: =IF(Z3="+",TODAY()-B11,"") | Q3: =IF(B16=K3,MAX(E:E)-B11,"") | X3: =B9 -> 46065 | Y3: =B16*-1 -> -21.97 | Z3: =IF(AND(TODAY()>B11, K3<>B16), "+", "")
A4: Tipas | B4: Business loan | D4: 46127 | E4: 46127 | F4: =IF(E4>0,E4-D4,"") -> 0 | G4: 0 | H4: 0.22 | I4: 0.02 | X4: =E3 -> 46096 | Y4: =G3+H3-I3 -> 0.2
D5: 46157 | E5: 46157 | F5: =IF(E5>0,E5-D5,"") -> 0 | G5: 0 | H5: 0.22 | I5: 0.02 | X5: =E4 -> 46127 | Y5: =G4+H4-I4 -> 0.2
D6: 46188 | E6: 46188 | F6: =IF(E6>0,E6-D6,"") -> 0 | G6: 0 | H6: 0.22 | I6: 0.02 | X6: =E5 -> 46157 | Y6: =G5+H5-I5 -> 0.2
D7: 46218 | E7: 46218 | F7: =IF(E7>0,E7-D7,"") -> 0 | G7: 0 | H7: 0.22 | I7: 0.02 | X7: =E6 -> 46188 | Y7: =G6+H6-I6 -> 0.2
A8: Terminas | B8: =DATEDIF(B9,B11,"y") & " m. " & DATEDIF(B9,B11,"ym") & " mėn. " & DATEDIF(B9,B11,"md") & " d." -> 1 m. 0 mėn. 3 d. | D8: 46249 | E8: 46249 | F8: =IF(E8>0,E8-D8,"") -> 0 | G8: 0 | H8: 0.22 | I8: 0.02 | X8: =E7 -> 46218 | Y8: =G7+H7-I7 -> 0.2
A9: Investuota | B9: 46065 | D9: 46280 | E9: 46280 | F9: =IF(E9>0,E9-D9,"") -> 0 | G9: 0 | H9: 0.22 | I9: 0.02 | X9: =E8 -> 46249 | Y9: =G8+H8-I8 -> 0.2
A10: Pradžia | B10: 46066 | D10: 46310 | F10: =IF(E10>0,E10-D10,"") | X10: =E9 -> 46280 | Y10: =G9+H9-I9 -> 0.2
A11: Pabaiga | B11: 46433 | D11: 46341 | F11: =IF(E11>0,E11-D11,"") | X11: =E10 -> 0 | Y11: =G10+H10-I10 -> 0
A12: Liko, dienos | B12: =IF(B16<>K3,(TODAY()-B11)*-1,"") -> 138 | D12: 46371 | F12: =IF(E12>0,E12-D12,"") | X12: =E11 -> 0 | Y12: =G11+H11-I11 -> 0
D13: 46402 | F13: =IF(E13>0,E13-D13,"") | X13: =E12 -> 0 | Y13: =G12+H12-I12 -> 0
D14: 46433 | F14: =IF(E14>0,E14-D14,"") | X14: =E13 -> 0 | Y14: =G13+H13-I13 -> 0
A15: Palūkanos | B15: 0.12 | F15: =IF(E15>0,E15-D15,"") | X15: =E14 -> 0 | Y15: =G14+H14-I14 -> 0
A16: Investuota, Eur | B16: 21.97 | F16: =IF(E16>0,E16-D16,"") | X16: =E15 -> 0 | Y16: =G15+H15-I15 -> 0
F17: =IF(E17>0,E17-D17,"") | X17: =E16 -> 0 | Y17: =G16+H16-I16 -> 0
F18: =IF(E18>0,E18-D18,"") | X18: =E17 -> 0 | Y18: =G17+H17-I17 -> 0
F19: =IF(E19>0,E19-D19,"") | X19: =E18 -> 0 | Y19: =G18+H18-I18 -> 0
F20: =IF(E20>0,E20-D20,"") | X20: =E19 -> 0 | Y20: =G19+H19-I19 -> 0
F21: =IF(E21>0,E21-D21,"") | X21: =E20 -> 0 | Y21: =G20+H20-I20 -> 0
F22: =IF(E22>0,E22-D22,"") | X22: =E21 -> 0 | Y22: =G21+H21-I21 -> 0
F23: =IF(E23>0,E23-D23,"") | X23: =E22 -> 0 | Y23: =G22+H22-I22 -> 0
F24: =IF(E24>0,E24-D24,"") | X24: =E23 -> 0 | Y24: =G23+H23-I23 -> 0
F25: =IF(E25>0,E25-D25,"") | X25: =E24 -> 0 | Y25: =G24+H24-I24 -> 0
F26: =IF(E26>0,E26-D26,"") | X26: =E25 -> 0 | Y26: =G25+H25-I25 -> 0
F27: =IF(E27>0,E27-D27,"") | X27: =E26 -> 0 | Y27: =G26+H26-I26 -> 0
F28: =IF(E28>0,E28-D28,"") | X28: =E27 -> 0 | Y28: =G27+H27-I27 -> 0
... F52: =IF(E52>0,E52-D52,"") | X52: =E51 -> 0 | Y52: =G51+H51-I51 -> 0
D53: Viso: | G53: =SUM(G3:G52) -> 0 | H53: =SUM(H3:H52) -> 1.54 | I53: =SUM(I3:I52) -> 0.14

Sheet 10000263
A1: Loan ID | B1: ID 205174291 - 10000263 | D1: Data | G1: Paskola | K1: Grąžinimas
A2: Šalis | B2: Bulgaria | D2: Planuojama | E2: Reali | F2: Vėl./Anks. | G2: Principal | H2: Interest | I2: Mokestis | K2: Paskola | L2: Palūkanos | M2: Mokesčiai | N2: XIRR | O2: Data | P2: Vėluoja | Q2: Vėl./Anks. | X2: Data | Y2: Suma | Z2: Vėluoja
A3: Skolintojas | B3: Tiberus | D3: 46096 | E3: 46096 | F3: =IF(E3>0,E3-D3,"") -> 0 | G3: 0 | H3: 0.3 | I3: 0.03 | K3: =G53 -> 0 | L3: =H53 -> 1.36 | M3: =I53 -> 0.15 | N3: =IF(B16=K3,XIRR(Y3:Y52,X3:X52),"") | O3: =IF(B16=K3,MAX(E:E),"") | P3: =IF(Z3="+",TODAY()-B11,"") | Q3: =IF(B16=K3,MAX(E:E)-B11,"") | X3: =B9 -> 46042 | Y3: =B16*-1 -> -21.2 | Z3: =IF(AND(TODAY()>B11, K3<>B16), "+", "")
A4: Tipas | B4: Business loan | D4: 46127 | E4: 46127 | F4: =IF(E4>0,E4-D4,"") -> 0 | G4: 0 | H4: 0.18 | I4: 0.02 | X4: =E3 -> 46096 | Y4: =G3+H3-I3 -> 0.27
D5: 46157 | E5: 46157 | F5: =IF(E5>0,E5-D5,"") -> 0 | G5: 0 | H5: 0.17 | I5: 0.02 | X5: =E4 -> 46127 | Y5: =G4+H4-I4 -> 0.16
D6: 46188 | E6: 46188 | F6: =IF(E6>0,E6-D6,"") -> 0 | G6: 0 | H6: 0.18 | I6: 0.02 | X6: =E5 -> 46157 | Y6: =G5+H5-I5 -> 0.15
D7: 46218 | E7: 46218 | F7: =IF(E7>0,E7-D7,"") -> 0 | G7: 0 | H7: 0.17 | I7: 0.02 | X7: =E6 -> 46188 | Y7: =G6+H6-I6 -> 0.16
A8: Terminas | B8: =DATEDIF(B9,B11,"y") & " m. " & DATEDIF(B9,B11,"ym") & " mėn. " & DATEDIF(B9,B11,"md") & " d." -> 1 m. 0 mėn. 26 d. | D8: 46249 | E8: 46249 | F8: =IF(E8>0,E8-D8,"") -> 0 | G8: 0 | H8: 0.18 | I8: 0.02 | X8: =E7 -> 46218 | Y8: =G7+H7-I7 -> 0.15
A9: Investuota | B9: 46042 | D9: 46280 | E9: 46280 | F9: =IF(E9>0,E9-D9,"") -> 0 | G9: 0 | H9: 0.18 | I9: 0.02 | X9: =E8 -> 46249 | Y9: =G8+H8-I8 -> 0.16
A10: Pradžia | B10: 46045 | D10: 46310 | F10: =IF(E10>0,E10-D10,"") | X10: =E9 -> 46280 | Y10: =G9+H9-I9 -> 0.16
A11: Pabaiga | B11: 46433 | D11: 46341 | F11: =IF(E11>0,E11-D11,"") | X11: =E10 -> 0 | Y11: =G10+H10-I10 -> 0
A12: Liko, dienos | B12: =IF(B16<>K3,(TODAY()-B11)*-1,"") -> 138 | D12: 46371 | F12: =IF(E12>0,E12-D12,"") | X12: =E11 -> 0 | Y12: =G11+H11-I11 -> 0
D13: 46402 | F13: =IF(E13>0,E13-D13,"") | X13: =E12 -> 0 | Y13: =G12+H12-I12 -> 0
D14: 46433 | F14: =IF(E14>0,E14-D14,"") | X14: =E13 -> 0 | Y14: =G13+H13-I13 -> 0
A15: Palūkanos | B15: 0.1 | F15: =IF(E15>0,E15-D15,"") | X15: =E14 -> 0 | Y15: =G14+H14-I14 -> 0
A16: Investuota, Eur | B16: 21.2 | F16: =IF(E16>0,E16-D16,"") | X16: =E15 -> 0 | Y16: =G15+H15-I15 -> 0
F17: =IF(E17>0,E17-D17,"") | X17: =E16 -> 0 | Y17: =G16+H16-I16 -> 0
F18: =IF(E18>0,E18-D18,"") | X18: =E17 -> 0 | Y18: =G17+H17-I17 -> 0
F19: =IF(E19>0,E19-D19,"") | X19: =E18 -> 0 | Y19: =G18+H18-I18 -> 0
F20: =IF(E20>0,E20-D20,"") | X20: =E19 -> 0 | Y20: =G19+H19-I19 -> 0
F21: =IF(E21>0,E21-D21,"") | X21: =E20 -> 0 | Y21: =G20+H20-I20 -> 0
F22: =IF(E22>0,E22-D22,"") | X22: =E21 -> 0 | Y22: =G21+H21-I21 -> 0
F23: =IF(E23>0,E23-D23,"") | X23: =E22 -> 0 | Y23: =G22+H22-I22 -> 0
F24: =IF(E24>0,E24-D24,"") | X24: =E23 -> 0 | Y24: =G23+H23-I23 -> 0
F25: =IF(E25>0,E25-D25,"") | X25: =E24 -> 0 | Y25: =G24+H24-I24 -> 0
F26: =IF(E26>0,E26-D26,"") | X26: =E25 -> 0 | Y26: =G25+H25-I25 -> 0
F27: =IF(E27>0,E27-D27,"") | X27: =E26 -> 0 | Y27: =G26+H26-I26 -> 0
F28: =IF(E28>0,E28-D28,"") | X28: =E27 -> 0 | Y28: =G27+H27-I27 -> 0
... F52: =IF(E52>0,E52-D52,"") | X52: =E51 -> 0 | Y52: =G51+H51-I51 -> 0
D53: Viso: | G53: =SUM(G3:G52) -> 0 | H53: =SUM(H3:H52) -> 1.36 | I53: =SUM(I3:I52) -> 0.15

Sheet 10000212
A1: Loan ID | B1: ID 203811241 - 10000212 | D1: Data | G1: Paskola | K1: Grąžinimas
A2: Šalis | B2: Bulgaria | D2: Planuojama | E2: Reali | F2: Vėl./Anks. | G2: Principal | H2: Interest | I2: Mokestis | K2: Paskola | L2: Palūkanos | M2: Mokesčiai | N2: XIRR | O2: Data | P2: Vėluoja | Q2: Vėl./Anks. | X2: Data | Y2: Suma | Z2: Vėluoja
A3: Skolintojas | B3: Lendivo | D3: 46041 | E3: 46041 | F3: =IF(E3>0,E3-D3,"") -> 0 | G3: 0 | H3: 0.2 | I3: 0.02 | K3: =G53 -> 0 | L3: =H53 -> 1.76 | M3: =I53 -> 0.18 | N3: =IF(B16=K3,XIRR(Y3:Y52,X3:X52),"") | O3: =IF(B16=K3,MAX(E:E),"") | P3: =IF(Z3="+",TODAY()-B11,"") | Q3: =IF(B16=K3,MAX(E:E)-B11,"") | X3: =B9 -> 46007 | Y3: =B16*-1 -> -21.49 | Z3: =IF(AND(TODAY()>B11, K3<>B16), "+", "")
A4: Tipas | B4: Business loan | D4: 46072 | E4: 46072 | F4: =IF(E4>0,E4-D4,"") -> 0 | G4: 0 | H4: 0.2 | I4: 0.02 | X4: =E3 -> 46041 | Y4: =G3+H3-I3 -> 0.18
D5: 46100 | E5: 46100 | F5: =IF(E5>0,E5-D5,"") -> 0 | G5: 0 | H5: 0.18 | I5: 0.02 | X5: =E4 -> 46072 | Y5: =G4+H4-I4 -> 0.18
D6: 46131 | E6: 46131 | F6: =IF(E6>0,E6-D6,"") -> 0 | G6: 0 | H6: 0.2 | I6: 0.02 | X6: =E5 -> 46100 | Y6: =G5+H5-I5 -> 0.16
D7: 46161 | E7: 46161 | F7: =IF(E7>0,E7-D7,"") -> 0 | G7: 0 | H7: 0.19 | I7: 0.02 | X7: =E6 -> 46131 | Y7: =G6+H6-I6 -> 0.18
A8: Terminas | B8: =DATEDIF(B9,B11,"y") & " m. " & DATEDIF(B9,B11,"ym") & " mėn. " & DATEDIF(B9,B11,"md") & " d." -> 1 m. 0 mėn. 3 d. | D8: 46192 | E8: 46192 | F8: =IF(E8>0,E8-D8,"") -> 0 | G8: 0 | H8: 0.2 | I8: 0.02 | X8: =E7 -> 46161 | Y8: =G7+H7-I7 -> 0.17
A9: Investuota | B9: 46007 | D9: 46222 | E9: 46222 | F9: =IF(E9>0,E9-D9,"") -> 0 | G9: 0 | H9: 0.19 | I9: 0.02 | X9: =E8 -> 46192 | Y9: =G8+H8-I8 -> 0.18
A10: Pradžia | B10: 46010 | D10: 46253 | E10: 46253 | F10: =IF(E10>0,E10-D10,"") -> 0 | G10: 0 | H10: 0.2 | I10: 0.02 | X10: =E9 -> 46222 | Y10: =G9+H9-I9 -> 0.17
A11: Pabaiga | B11: 46375 | D11: 46284 | E11: 46284 | F11: =IF(E11>0,E11-D11,"") -> 0 | G11: 0 | H11: 0.2 | I11: 0.02 | X11: =E10 -> 46253 | Y11: =G10+H10-I10 -> 0.18
A12: Liko, dienos | B12: =IF(B16<>K3,(TODAY()-B11)*-1,"") -> 80 | D12: 46314 | F12: =IF(E12>0,E12-D12,"") | X12: =E11 -> 46284 | Y12: =G11+H11-I11 -> 0.18
D13: 46345 | F13: =IF(E13>0,E13-D13,"") | X13: =E12 -> 0 | Y13: =G12+H12-I12 -> 0
D14: 46375 | F14: =IF(E14>0,E14-D14,"") | X14: =E13 -> 0 | Y14: =G13+H13-I13 -> 0
A15: Palūkanos | B15: 0.11 | F15: =IF(E15>0,E15-D15,"") | X15: =E14 -> 0 | Y15: =G14+H14-I14 -> 0
A16: Investuota, Eur | B16: 21.49 | F16: =IF(E16>0,E16-D16,"") | X16: =E15 -> 0 | Y16: =G15+H15-I15 -> 0
F17: =IF(E17>0,E17-D17,"") | X17: =E16 -> 0 | Y17: =G16+H16-I16 -> 0
F18: =IF(E18>0,E18-D18,"") | X18: =E17 -> 0 | Y18: =G17+H17-I17 -> 0
F19: =IF(E19>0,E19-D19,"") | X19: =E18 -> 0 | Y19: =G18+H18-I18 -> 0
F20: =IF(E20>0,E20-D20,"") | X20: =E19 -> 0 | Y20: =G19+H19-I19 -> 0
F21: =IF(E21>0,E21-D21,"") | X21: =E20 -> 0 | Y21: =G20+H20-I20 -> 0
F22: =IF(E22>0,E22-D22,"") | X22: =E21 -> 0 | Y22: =G21+H21-I21 -> 0
F23: =IF(E23>0,E23-D23,"") | X23: =E22 -> 0 | Y23: =G22+H22-I22 -> 0
F24: =IF(E24>0,E24-D24,"") | X24: =E23 -> 0 | Y24: =G23+H23-I23 -> 0
F25: =IF(E25>0,E25-D25,"") | X25: =E24 -> 0 | Y25: =G24+H24-I24 -> 0
F26: =IF(E26>0,E26-D26,"") | X26: =E25 -> 0 | Y26: =G25+H25-I25 -> 0
F27: =IF(E27>0,E27-D27,"") | X27: =E26 -> 0 | Y27: =G26+H26-I26 -> 0
F28: =IF(E28>0,E28-D28,"") | X28: =E27 -> 0 | Y28: =G27+H27-I27 -> 0
... F52: =IF(E52>0,E52-D52,"") | X52: =E51 -> 0 | Y52: =G51+H51-I51 -> 0
D53: Viso: | G53: =SUM(G3:G52) -> 0 | H53: =SUM(H3:H52) -> 1.76 | I53: =SUM(I3:I52) -> 0.18

Sheet 10000170
A1: Loan ID | B1: ID 202557159 - 10000170 | D1: Data | G1: Paskola | K1: Grąžinimas
A2: Šalis | B2: Bulgaria | D2: Planuojama | E2: Reali | F2: Vėl./Anks. | G2: Principal | H2: Interest | I2: Mokestis | K2: Paskola | L2: Palūkanos | M2: Mokesčiai | N2: XIRR | O2: Data | P2: Vėluoja | Q2: Vėl./Anks. | X2: Data | Y2: Suma | Z2: Vėluoja
A3: Skolintojas | B3: Stikcredit | D3: 46005 | E3: 46005 | F3: =IF(E3>0,E3-D3,"") -> 0 | G3: 0 | H3: 0.45 | I3: 0.05 | K3: =G53 -> 0 | L3: =H53 -> 4.59 | M3: =I53 -> 0.49 | N3: =IF(B16=K3,XIRR(Y3:Y52,X3:X52),"") | O3: =IF(B16=K3,MAX(E:E),"") | P3: =IF(Z3="+",TODAY()-B11,"") | Q3: =IF(B16=K3,MAX(E:E)-B11,"") | X3: =B9 -> 45972 | Y3: =B16*-1 -> -50 | Z3: =IF(AND(TODAY()>B11, K3<>B16), "+", "")
A4: Tipas | B4: Business loan | D4: 46036 | E4: 46036 | F4: =IF(E4>0,E4-D4,"") -> 0 | G4: 0 | H4: 0.47 | I4: 0.05 | X4: =E3 -> 46005 | Y4: =G3+H3-I3 -> 0.4
D5: 46067 | E5: 46067 | F5: =IF(E5>0,E5-D5,"") -> 0 | G5: 0 | H5: 0.47 | I5: 0.05 | X5: =E4 -> 46036 | Y5: =G4+H4-I4 -> 0.42
D6: 46095 | E6: 46095 | F6: =IF(E6>0,E6-D6,"") -> 0 | G6: 0 | H6: 0.42 | I6: 0.04 | X6: =E5 -> 46067 | Y6: =G5+H5-I5 -> 0.42
D7: 46126 | E7: 46126 | F7: =IF(E7>0,E7-D7,"") -> 0 | G7: 0 | H7: 0.47 | I7: 0.05 | X7: =E6 -> 46095 | Y7: =G6+H6-I6 -> 0.38
A8: Terminas | B8: =DATEDIF(B9,B11,"y") & " m. " & DATEDIF(B9,B11,"ym") & " mėn. " & DATEDIF(B9,B11,"md") & " d." -> 1 m. 0 mėn. 3 d. | D8: 46156 | E8: 46156 | F8: =IF(E8>0,E8-D8,"") -> 0 | G8: 0 | H8: 0.45 | I8: 0.05 | X8: =E7 -> 46126 | Y8: =G7+H7-I7 -> 0.42
A9: Investuota | B9: 45972 | D9: 46187 | E9: 46187 | F9: =IF(E9>0,E9-D9,"") -> 0 | G9: 0 | H9: 0.47 | I9: 0.05 | X9: =E8 -> 46156 | Y9: =G8+H8-I8 -> 0.4
A10: Pradžia | B10: 45975 | D10: 46217 | E10: 46217 | F10: =IF(E10>0,E10-D10,"") -> 0 | G10: 0 | H10: 0.45 | I10: 0.05 | X10: =E9 -> 46187 | Y10: =G9+H9-I9 -> 0.42
A11: Pabaiga | B11: 46340 | D11: 46248 | E11: 46248 | F11: =IF(E11>0,E11-D11,"") -> 0 | G11: 0 | H11: 0.47 | I11: 0.05 | X11: =E10 -> 46217 | Y11: =G10+H10-I10 -> 0.4
A12: Liko, dienos | B12: =IF(B16<>K3,(TODAY()-B11)*-1,"") -> 45 | D12: 46279 | E12: 46279 | F12: =IF(E12>0,E12-D12,"") -> 0 | G12: 0 | H12: 0.47 | I12: 0.05 | X12: =E11 -> 46248 | Y12: =G11+H11-I11 -> 0.42
D13: 46309 | F13: =IF(E13>0,E13-D13,"") | X13: =E12 -> 46279 | Y13: =G12+H12-I12 -> 0.42
D14: 46340 | F14: =IF(E14>0,E14-D14,"") | X14: =E13 -> 0 | Y14: =G13+H13-I13 -> 0
A15: Palūkanos | B15: 0.11 | F15: =IF(E15>0,E15-D15,"") | X15: =E14 -> 0 | Y15: =G14+H14-I14 -> 0
A16: Investuota, Eur | B16: 50 | F16: =IF(E16>0,E16-D16,"") | X16: =E15 -> 0 | Y16: =G15+H15-I15 -> 0
F17: =IF(E17>0,E17-D17,"") | X17: =E16 -> 0 | Y17: =G16+H16-I16 -> 0
F18: =IF(E18>0,E18-D18,"") | X18: =E17 -> 0 | Y18: =G17+H17-I17 -> 0
F19: =IF(E19>0,E19-D19,"") | X19: =E18 -> 0 | Y19: =G18+H18-I18 -> 0
F20: =IF(E20>0,E20-D20,"") | X20: =E19 -> 0 | Y20: =G19+H19-I19 -> 0
F21: =IF(E21>0,E21-D21,"") | X21: =E20 -> 0 | Y21: =G20+H20-I20 -> 0
F22: =IF(E22>0,E22-D22,"") | X22: =E21 -> 0 | Y22: =G21+H21-I21 -> 0
F23: =IF(E23>0,E23-D23,"") | X23: =E22 -> 0 | Y23: =G22+H22-I22 -> 0
F24: =IF(E24>0,E24-D24,"") | X24: =E23 -> 0 | Y24: =G23+H23-I23 -> 0
F25: =IF(E25>0,E25-D25,"") | X25: =E24 -> 0 | Y25: =G24+H24-I24 -> 0
F26: =IF(E26>0,E26-D26,"") | X26: =E25 -> 0 | Y26: =G25+H25-I25 -> 0
F27: =IF(E27>0,E27-D27,"") | X27: =E26 -> 0 | Y27: =G26+H26-I26 -> 0
F28: =IF(E28>0,E28-D28,"") | X28: =E27 -> 0 | Y28: =G27+H27-I27 -> 0
... F52: =IF(E52>0,E52-D52,"") | X52: =E51 -> 0 | Y52: =G51+H51-I51 -> 0
D53: Viso: | G53: =SUM(G3:G52) -> 0 | H53: =SUM(H3:H52) -> 4.59 | I53: =SUM(I3:I52) -> 0.49

Sheet 10000158
A1: Loan ID | B1: ID 205551187 - 10000158 | D1: Data | G1: Paskola | K1: Grąžinimas
A2: Šalis | B2: Bulgaria | D2: Planuojama | E2: Reali | F2: Vėl./Anks. | G2: Principal | H2: Interest | I2: Mokestis | K2: Paskola | L2: Palūkanos | M2: Mokesčiai | N2: XIRR | O2: Data | P2: Vėluoja | Q2: Vėl./Anks. | X2: Data | Y2: Suma | Z2: Vėluoja
A3: Skolintojas | B3: Lev Credit | D3: 45994 | E3: 45994 | F3: =IF(E3>0,E3-D3,"") -> 0 | G3: 0 | H3: 0.06 | I3: 0.01 | K3: =G53 -> 10 | L3: =H53 -> 0.54 | M3: =I53 -> 0.09 | N3: =IF(B16=K3,XIRR(Y3:Y52,X3:X52),"") -> 0.061380932 | O3: =IF(B16=K3,MAX(E:E),"") -> 46237 | P3: =IF(Z3="+",TODAY()-B11,"") | Q3: =IF(B16=K3,MAX(E:E)-B11,"") -> 0 | X3: =B9 -> 45962 | Y3: =B16*-1 -> -10 | Z3: =IF(AND(TODAY()>B11, K3<>B16), "+", "")
A4: Tipas | B4: Business loan | D4: 46025 | E4: 46025 | F4: =IF(E4>0,E4-D4,"") -> 0 | G4: 0 | H4: 0.06 | I4: 0.01 | X4: =E3 -> 45994 | Y4: =G3+H3-I3 -> 0.05
D5: 46056 | E5: 46056 | F5: =IF(E5>0,E5-D5,"") -> 0 | G5: 0 | H5: 0.06 | I5: 0.01 | X5: =E4 -> 46025 | Y5: =G4+H4-I4 -> 0.05
D6: 46084 | E6: 46084 | F6: =IF(E6>0,E6-D6,"") -> 0 | G6: 0 | H6: 0.06 | I6: 0.01 | X6: =E5 -> 46056 | Y6: =G5+H5-I5 -> 0.05
D7: 46115 | E7: 46115 | F7: =IF(E7>0,E7-D7,"") -> 0 | G7: 0 | H7: 0.06 | I7: 0.01 | X7: =E6 -> 46084 | Y7: =G6+H6-I6 -> 0.05
A8: Terminas | B8: =DATEDIF(B9,B11,"y") & " m. " & DATEDIF(B9,B11,"ym") & " mėn. " & DATEDIF(B9,B11,"md") & " d." -> 0 m. 9 mėn. 2 d. | D8: 46145 | E8: 46147 | F8: =IF(E8>0,E8-D8,"") -> 2 | G8: 0 | H8: 0.06 | I8: 0.01 | X8: =E7 -> 46115 | Y8: =G7+H7-I7 -> 0.05
A9: Investuota | B9: 45962 | D9: 46176 | E9: 46176 | F9: =IF(E9>0,E9-D9,"") -> 0 | G9: 0 | H9: 0.06 | I9: 0.01 | X9: =E8 -> 46147 | Y9: =G8+H8-I8 -> 0.05
A10: Pradžia | B10: 45964 | D10: 46206 | E10: 46206 | F10: =IF(E10>0,E10-D10,"") -> 0 | G10: 0 | H10: 0.06 | I10: 0.01 | X10: =E9 -> 46176 | Y10: =G9+H9-I9 -> 0.05
A11: Pabaiga | B11: 46237 | D11: 46237 | E11: 46237 | F11: =IF(E11>0,E11-D11,"") -> 0 | G11: 10 | H11: 0.06 | I11: 0.01 | X11: =E10 -> 46206 | Y11: =G10+H10-I10 -> 0.05
A12: Liko, dienos | B12: =IF(B16<>K3,(TODAY()-B11)*-1,"") | F12: =IF(E12>0,E12-D12,"") | X12: =E11 -> 46237 | Y12: =G11+H11-I11 -> 10.05
F13: =IF(E13>0,E13-D13,"") | X13: =E12 -> 0 | Y13: =G12+H12-I12 -> 0
F14: =IF(E14>0,E14-D14,"") | X14: =E13 -> 0 | Y14: =G13+H13-I13 -> 0
A15: Palūkanos | B15: 0.075 | F15: =IF(E15>0,E15-D15,"") | X15: =E14 -> 0 | Y15: =G14+H14-I14 -> 0
A16: Investuota, Eur | B16: 10 | F16: =IF(E16>0,E16-D16,"") | X16: =E15 -> 0 | Y16: =G15+H15-I15 -> 0
F17: =IF(E17>0,E17-D17,"") | X17: =E16 -> 0 | Y17: =G16+H16-I16 -> 0
F18: =IF(E18>0,E18-D18,"") | X18: =E17 -> 0 | Y18: =G17+H17-I17 -> 0
F19: =IF(E19>0,E19-D19,"") | X19: =E18 -> 0 | Y19: =G18+H18-I18 -> 0
F20: =IF(E20>0,E20-D20,"") | X20: =E19 -> 0 | Y20: =G19+H19-I19 -> 0
F21: =IF(E21>0,E21-D21,"") | X21: =E20 -> 0 | Y21: =G20+H20-I20 -> 0
F22: =IF(E22>0,E22-D22,"") | X22: =E21 -> 0 | Y22: =G21+H21-I21 -> 0
F23: =IF(E23>0,E23-D23,"") | X23: =E22 -> 0 | Y23: =G22+H22-I22 -> 0
F24: =IF(E24>0,E24-D24,"") | X24: =E23 -> 0 | Y24: =G23+H23-I23 -> 0
F25: =IF(E25>0,E25-D25,"") | X25: =E24 -> 0 | Y25: =G24+H24-I24 -> 0
F26: =IF(E26>0,E26-D26,"") | X26: =E25 -> 0 | Y26: =G25+H25-I25 -> 0
F27: =IF(E27>0,E27-D27,"") | X27: =E26 -> 0 | Y27: =G26+H26-I26 -> 0
F28: =IF(E28>0,E28-D28,"") | X28: =E27 -> 0 | Y28: =G27+H27-I27 -> 0
... F52: =IF(E52>0,E52-D52,"") | X52: =E51 -> 0 | Y52: =G51+H51-I51 -> 0
D53: Viso: | G53: =SUM(G3:G52) -> 10 | H53: =SUM(H3:H52) -> 0.54 | I53: =SUM(I3:I52) -> 0.09

Sheet 10000160
A1: Loan ID | B1: ID 205551187 - 10000160 | D1: Data | G1: Paskola | K1: Grąžinimas
A2: Šalis | B2: Bulgaria | D2: Planuojama | E2: Reali | F2: Vėl./Anks. | G2: Principal | H2: Interest | I2: Mokestis | K2: Paskola | L2: Palūkanos | M2: Mokesčiai | N2: XIRR | O2: Data | P2: Vėluoja | Q2: Vėl./Anks. | X2: Data | Y2: Suma | Z2: Vėluoja
A3: Skolintojas | B3: Lev Credit | D3: 45994 | E3: 45994 | F3: =IF(E3>0,E3-D3,"") -> 0 | G3: 0 | H3: 0.07 | I3: 0.01 | K3: =G53 -> 0 | L3: =H53 -> 0.7 | M3: =I53 -> 0.1 | N3: =IF(B16=K3,XIRR(Y3:Y52,X3:X52),"") | O3: =IF(B16=K3,MAX(E:E),"") | P3: =IF(Z3="+",TODAY()-B11,"") | Q3: =IF(B16=K3,MAX(E:E)-B11,"") | X3: =B9 -> 45962 | Y3: =B16*-1 -> -10 | Z3: =IF(AND(TODAY()>B11, K3<>B16), "+", "")
A4: Tipas | B4: Business loan | D4: 46025 | E4: 46025 | F4: =IF(E4>0,E4-D4,"") -> 0 | G4: 0 | H4: 0.07 | I4: 0.01 | X4: =E3 -> 45994 | Y4: =G3+H3-I3 -> 0.06
D5: 46056 | E5: 46056 | F5: =IF(E5>0,E5-D5,"") -> 0 | G5: 0 | H5: 0.07 | I5: 0.01 | X5: =E4 -> 46025 | Y5: =G4+H4-I4 -> 0.06
D6: 46084 | E6: 46084 | F6: =IF(E6>0,E6-D6,"") -> 0 | G6: 0 | H6: 0.07 | I6: 0.01 | X6: =E5 -> 46056 | Y6: =G5+H5-I5 -> 0.06
D7: 46115 | E7: 46115 | F7: =IF(E7>0,E7-D7,"") -> 0 | G7: 0 | H7: 0.07 | I7: 0.01 | X7: =E6 -> 46084 | Y7: =G6+H6-I6 -> 0.06
A8: Terminas | B8: =DATEDIF(B9,B11,"y") & " m. " & DATEDIF(B9,B11,"ym") & " mėn. " & DATEDIF(B9,B11,"md") & " d." -> 1 m. 6 mėn. 2 d. | D8: 46145 | E8: 46147 | F8: =IF(E8>0,E8-D8,"") -> 2 | G8: 0 | H8: 0.07 | I8: 0.01 | X8: =E7 -> 46115 | Y8: =G7+H7-I7 -> 0.06
A9: Investuota | B9: 45962 | D9: 46176 | E9: 46176 | F9: =IF(E9>0,E9-D9,"") -> 0 | G9: 0 | H9: 0.07 | I9: 0.01 | X9: =E8 -> 46147 | Y9: =G8+H8-I8 -> 0.06
A10: Pradžia | B10: 45964 | D10: 46206 | E10: 46206 | F10: =IF(E10>0,E10-D10,"") -> 0 | G10: 0 | H10: 0.07 | I10: 0.01 | X10: =E9 -> 46176 | Y10: =G9+H9-I9 -> 0.06
A11: Pabaiga | B11: 46510 | D11: 46237 | E11: 46237 | F11: =IF(E11>0,E11-D11,"") -> 0 | G11: 0 | H11: 0.07 | I11: 0.01 | X11: =E10 -> 46206 | Y11: =G10+H10-I10 -> 0.06
A12: Liko, dienos | B12: =IF(B16<>K3,(TODAY()-B11)*-1,"") -> 215 | D12: 46268 | E12: 46268 | F12: =IF(E12>0,E12-D12,"") -> 0 | G12: 0 | H12: 0.07 | I12: 0.01 | X12: =E11 -> 46237 | Y12: =G11+H11-I11 -> 0.06
D13: 46298 | F13: =IF(E13>0,E13-D13,"") | X13: =E12 -> 46268 | Y13: =G12+H12-I12 -> 0.06
D14: 46329 | F14: =IF(E14>0,E14-D14,"") | X14: =E13 -> 0 | Y14: =G13+H13-I13 -> 0
A15: Palūkanos | B15: 0.085 | D15: 46359 | F15: =IF(E15>0,E15-D15,"") | X15: =E14 -> 0 | Y15: =G14+H14-I14 -> 0
A16: Investuota, Eur | B16: 10 | D16: 46390 | F16: =IF(E16>0,E16-D16,"") | X16: =E15 -> 0 | Y16: =G15+H15-I15 -> 0
D17: 46421 | F17: =IF(E17>0,E17-D17,"") | X17: =E16 -> 0 | Y17: =G16+H16-I16 -> 0
D18: 46449 | F18: =IF(E18>0,E18-D18,"") | X18: =E17 -> 0 | Y18: =G17+H17-I17 -> 0
D19: 46480 | F19: =IF(E19>0,E19-D19,"") | X19: =E18 -> 0 | Y19: =G18+H18-I18 -> 0
D20: 46510 | F20: =IF(E20>0,E20-D20,"") | X20: =E19 -> 0 | Y20: =G19+H19-I19 -> 0
F21: =IF(E21>0,E21-D21,"") | X21: =E20 -> 0 | Y21: =G20+H20-I20 -> 0
F22: =IF(E22>0,E22-D22,"") | X22: =E21 -> 0 | Y22: =G21+H21-I21 -> 0
F23: =IF(E23>0,E23-D23,"") | X23: =E22 -> 0 | Y23: =G22+H22-I22 -> 0
F24: =IF(E24>0,E24-D24,"") | X24: =E23 -> 0 | Y24: =G23+H23-I23 -> 0
F25: =IF(E25>0,E25-D25,"") | X25: =E24 -> 0 | Y25: =G24+H24-I24 -> 0
F26: =IF(E26>0,E26-D26,"") | X26: =E25 -> 0 | Y26: =G25+H25-I25 -> 0
F27: =IF(E27>0,E27-D27,"") | X27: =E26 -> 0 | Y27: =G26+H26-I26 -> 0
F28: =IF(E28>0,E28-D28,"") | X28: =E27 -> 0 | Y28: =G27+H27-I27 -> 0
F29: =IF(E29>0,E29-D29,"") | X29: =E28 -> 0 | Y29: =G28+H28-I28 -> 0
F30: =IF(E30>0,E30-D30,"") | X30: =E29 -> 0 | Y30: =G29+H29-I29 -> 0
F31: =IF(E31>0,E31-D31,"") | X31: =E30 -> 0 | Y31: =G30+H30-I30 -> 0
F32: =IF(E32>0,E32-D32,"") | X32: =E31 -> 0 | Y32: =G31+H31-I31 -> 0
... F52: =IF(E52>0,E52-D52,"") | X52: =E51 -> 0 | Y52: =G51+H51-I51 -> 0
D53: Viso: | G53: =SUM(G3:G52) -> 0 | H53: =SUM(H3:H52) -> 0.7 | I53: =SUM(I3:I52) -> 0.1

Sheet 10000159
A1: Loan ID | B1: ID 205551187 - 10000159 | D1: Data | G1: Paskola | K1: Grąžinimas
A2: Šalis | B2: Bulgaria | D2: Planuojama | E2: Reali | F2: Vėl./Anks. | G2: Principal | H2: Interest | I2: Mokestis | K2: Paskola | L2: Palūkanos | M2: Mokesčiai | N2: XIRR | O2: Data | P2: Vėluoja | Q2: Vėl./Anks. | X2: Data | Y2: Suma | Z2: Vėluoja
A3: Skolintojas | B3: Lev Credit | D3: 45994 | E3: 45994 | F3: =IF(E3>0,E3-D3,"") -> 0 | G3: 0 | H3: 0.53 | I3: 0.05 | K3: =G53 -> 0 | L3: =H53 -> 5.32 | M3: =I53 -> 0.5 | N3: =IF(B16=K3,XIRR(Y3:Y52,X3:X52),"") | O3: =IF(B16=K3,MAX(E:E),"") | P3: =IF(Z3="+",TODAY()-B11,"") | Q3: =IF(B16=K3,MAX(E:E)-B11,"") | X3: =B9 -> 45962 | Y3: =B16*-1 -> -80 | Z3: =IF(AND(TODAY()>B11, K3<>B16), "+", "")
A4: Tipas | B4: Business loan | D4: 46025 | E4: 46025 | F4: =IF(E4>0,E4-D4,"") -> 0 | G4: 0 | H4: 0.54 | I4: 0.05 | X4: =E3 -> 45994 | Y4: =G3+H3-I3 -> 0.48
D5: 46056 | E5: 46056 | F5: =IF(E5>0,E5-D5,"") -> 0 | G5: 0 | H5: 0.54 | I5: 0.05 | X5: =E4 -> 46025 | Y5: =G4+H4-I4 -> 0.49
D6: 46084 | E6: 46084 | F6: =IF(E6>0,E6-D6,"") -> 0 | G6: 0 | H6: 0.49 | I6: 0.05 | X6: =E5 -> 46056 | Y6: =G5+H5-I5 -> 0.49
D7: 46115 | E7: 46115 | F7: =IF(E7>0,E7-D7,"") -> 0 | G7: 0 | H7: 0.54 | I7: 0.05 | X7: =E6 -> 46084 | Y7: =G6+H6-I6 -> 0.44
A8: Terminas | B8: =DATEDIF(B9,B11,"y") & " m. " & DATEDIF(B9,B11,"ym") & " mėn. " & DATEDIF(B9,B11,"md") & " d." -> 1 m. 0 mėn. 2 d. | D8: 46145 | E8: 46147 | F8: =IF(E8>0,E8-D8,"") -> 2 | G8: 0 | H8: 0.53 | I8: 0.05 | X8: =E7 -> 46115 | Y8: =G7+H7-I7 -> 0.49
A9: Investuota | B9: 45962 | D9: 46176 | E9: 46176 | F9: =IF(E9>0,E9-D9,"") -> 0 | G9: 0 | H9: 0.54 | I9: 0.05 | X9: =E8 -> 46147 | Y9: =G8+H8-I8 -> 0.48
A10: Pradžia | B10: 45964 | D10: 46206 | E10: 46206 | F10: =IF(E10>0,E10-D10,"") -> 0 | G10: 0 | H10: 0.53 | I10: 0.05 | X10: =E9 -> 46176 | Y10: =G9+H9-I9 -> 0.49
A11: Pabaiga | B11: 46329 | D11: 46237 | E11: 46237 | F11: =IF(E11>0,E11-D11,"") -> 0 | G11: 0 | H11: 0.54 | I11: 0.05 | X11: =E10 -> 46206 | Y11: =G10+H10-I10 -> 0.48
A12: Liko, dienos | B12: =IF(B16<>K3,(TODAY()-B11)*-1,"") -> 34 | D12: 46268 | E12: 46268 | F12: =IF(E12>0,E12-D12,"") -> 0 | G12: 0 | H12: 0.54 | I12: 0.05 | X12: =E11 -> 46237 | Y12: =G11+H11-I11 -> 0.49
D13: 46298 | F13: =IF(E13>0,E13-D13,"") | X13: =E12 -> 46268 | Y13: =G12+H12-I12 -> 0.49
D14: 46329 | F14: =IF(E14>0,E14-D14,"") | X14: =E13 -> 0 | Y14: =G13+H13-I13 -> 0
A15: Palūkanos | B15: 0.08 | F15: =IF(E15>0,E15-D15,"") | X15: =E14 -> 0 | Y15: =G14+H14-I14 -> 0
A16: Investuota, Eur | B16: 80 | F16: =IF(E16>0,E16-D16,"") | X16: =E15 -> 0 | Y16: =G15+H15-I15 -> 0
F17: =IF(E17>0,E17-D17,"") | X17: =E16 -> 0 | Y17: =G16+H16-I16 -> 0
F18: =IF(E18>0,E18-D18,"") | X18: =E17 -> 0 | Y18: =G17+H17-I17 -> 0
F19: =IF(E19>0,E19-D19,"") | X19: =E18 -> 0 | Y19: =G18+H18-I18 -> 0
F20: =IF(E20>0,E20-D20,"") | X20: =E19 -> 0 | Y20: =G19+H19-I19 -> 0
F21: =IF(E21>0,E21-D21,"") | X21: =E20 -> 0 | Y21: =G20+H20-I20 -> 0
F22: =IF(E22>0,E22-D22,"") | X22: =E21 -> 0 | Y22: =G21+H21-I21 -> 0
F23: =IF(E23>0,E23-D23,"") | X23: =E22 -> 0 | Y23: =G22+H22-I22 -> 0
F24: =IF(E24>0,E24-D24,"") | X24: =E23 -> 0 | Y24: =G23+H23-I23 -> 0
F25: =IF(E25>0,E25-D25,"") | X25: =E24 -> 0 | Y25: =G24+H24-I24 -> 0
F26: =IF(E26>0,E26-D26,"") | X26: =E25 -> 0 | Y26: =G25+H25-I25 -> 0
F27: =IF(E27>0,E27-D27,"") | X27: =E26 -> 0 | Y27: =G26+H26-I26 -> 0
F28: =IF(E28>0,E28-D28,"") | X28: =E27 -> 0 | Y28: =G27+H27-I27 -> 0
... F52: =IF(E52>0,E52-D52,"") | X52: =E51 -> 0 | Y52: =G51+H51-I51 -> 0
D53: Viso: | G53: =SUM(G3:G52) -> 0 | H53: =SUM(H3:H52) -> 5.32 | I53: =SUM(I3:I52) -> 0.5
