Workbook

Sheet Overview
A1: Paskola | H1: Grąžinimas | O1: Pinigai | S1: Grąžinta | U1: Vertė
A2: Nr. | B2: Data | C2: Pavadinimas | D2: Laikotarpis | E2: Reitingas | F2: Palūkanos | G2: Investuota | H2: Planuojamas | I2: Realus | J2: Liko | K2: Vėluoja | L2: Paskola | M2: Palūkanos | O2: Įnešta | P2: Investuota | Q2: Premijos | R2: Gryni | S2: Paskola | T2: Palūkanos | U2: Viso | V2: Eur. | W2: % | X2: XIRR | AC2: Vėluoja
A3: 1 | B3: ='Užnerio butai III'!B3 -> 45719 | C3: ='Užnerio butai III'!B2 -> Užnerio butai III | D3: ='Užnerio butai III'!B8 -> 12 | E3: ='Užnerio butai III'!B5 -> C | F3: ='Užnerio butai III'!B10 -> 0.105 | G3: ='Užnerio butai III'!B11 -> 100 | H3: ='Užnerio butai III'!B12 -> 46087 | I3: ='Užnerio butai III'!R3 -> 46091 | J3: ='Užnerio butai III'!B13 | K3: ='Užnerio butai III'!S3 | L3: ='Užnerio butai III'!N3 -> 100 | M3: ='Užnerio butai III'!P3 -> 10.77 | O3: =Pinigai!I2 -> 1030 | P3: =SUM(G3:G200)-S3 -> 1191.83 | Q3: =Pinigai!H2 -> 40 | R3: =U3-P3 -> 6.01 | S3: =SUM(L3:L200) -> 1377.57 | T3: =SUM(M3:M200) -> 127.84 | U3: =O3+T3+Q3 -> 1197.84 | V3: =U3-O3 -> 167.84 | W3: =(U3-O3)/O3 -> 0.16295146 | X3: =XIRR(Pinigai!K2:K200,Pinigai!A2:A200) -> 0.12084302 | AC3: ='Užnerio butai III'!AA2
A4: 2 | B4: ='Pušynas VII'!B3 -> 45721 | C4: ='Pušynas VII'!B2 -> Pušynas VII | D4: ='Pušynas VII'!B8 -> 11 | E4: ='Pušynas VII'!B5 -> D | F4: ='Pušynas VII'!B10 -> 0.115 | G4: ='Pušynas VII'!B11 -> 100 | H4: ='Pušynas VII'!B12 -> 46054 | I4: ='Pušynas VII'!R3 -> 46056 | J4: ='Pušynas VII'!B13 | K4: ='Pušynas VII'!S3 | L4: ='Pušynas VII'!N3 -> 100 | M4: ='Pušynas VII'!P3 -> 10.51 | AC4: ='Pušynas VII'!AA2
A5: 3 | B5: ='Sodziaus 7A'!B3 -> 45725 | C5: ='Sodziaus 7A'!B2 -> Sodziaus 7A | D5: ='Sodziaus 7A'!B8 -> 9 | E5: ='Sodziaus 7A'!B5 -> C | F5: ='Sodziaus 7A'!B10 -> 0.11 | G5: ='Sodziaus 7A'!B11 -> 100 | H5: ='Sodziaus 7A'!B12 -> 46005 | I5: ='Sodziaus 7A'!R3 -> 46049 | J5: ='Sodziaus 7A'!B13 | K5: ='Sodziaus 7A'!S3 | L5: ='Sodziaus 7A'!N3 -> 100 | M5: ='Sodziaus 7A'!P3 -> 11 | AC5: ='Sodziaus 7A'!AA2
A6: 4 | B6: ='Sodziaus 7A (1)'!B3 -> 45729 | C6: ='Sodziaus 7A (1)'!B2 -> Sodziaus 7A | D6: ='Sodziaus 7A (1)'!B8 -> 9 | E6: ='Sodziaus 7A (1)'!B5 -> C | F6: ='Sodziaus 7A (1)'!B10 -> 0.11 | G6: ='Sodziaus 7A (1)'!B11 -> 10 | H6: ='Sodziaus 7A (1)'!B12 -> 46005 | I6: ='Sodziaus 7A (1)'!R3 -> 46049 | J6: ='Sodziaus 7A (1)'!B13 | K6: ='Sodziaus 7A (1)'!S3 | L6: ='Sodziaus 7A (1)'!N3 -> 10 | M6: ='Sodziaus 7A (1)'!P3 -> 1.1 | AC6: ='Sodziaus 7A (1)'!AA2
A7: 5 | B7: ='Kauno 36-232'!B3 -> 45743 | C7: ='Kauno 36-232'!B2 -> Kauno 36-232 | D7: ='Kauno 36-232'!B8 -> 12 | E7: ='Kauno 36-232'!B5 -> C | F7: ='Kauno 36-232'!B10 -> 0.11 | G7: ='Kauno 36-232'!B11 -> 100 | H7: ='Kauno 36-232'!B12 -> 46112 | I7: ='Kauno 36-232'!R3 -> 46035 | J7: ='Kauno 36-232'!B13 | K7: ='Kauno 36-232'!S3 | L7: ='Kauno 36-232'!N3 -> 100 | M7: ='Kauno 36-232'!P3 -> 8.51 | AC7: ='Kauno 36-232'!AA2
A8: 6 | B8: ='Girinaičių 7'!B3 -> 45757 | C8: ='Girinaičių 7'!B2 -> Girinaičių 7 | D8: ='Girinaičių 7'!B8 -> 6 | E8: ='Girinaičių 7'!B5 -> B | F8: ='Girinaičių 7'!B10 -> 0.105 | G8: ='Girinaičių 7'!B11 -> 100 | H8: ='Girinaičių 7'!B12 -> 45948 | I8: ='Girinaičių 7'!R3 -> 45911 | J8: ='Girinaičių 7'!B13 | K8: ='Girinaičių 7'!S3 | L8: ='Girinaičių 7'!N3 -> 100 | M8: ='Girinaičių 7'!P3 -> 4.41 | AC8: ='Girinaičių 7'!AA2
A9: 7 | B9: ='Piliarožių 10 VI'!B3 -> 45764 | C9: ='Piliarožių 10 VI'!B2 -> Piliarožių 10 VI | D9: ='Piliarožių 10 VI'!B8 -> 12 | E9: ='Piliarožių 10 VI'!B5 -> C | F9: ='Piliarožių 10 VI'!B10 -> 0.11 | G9: ='Piliarožių 10 VI'!B11 -> 10 | H9: ='Piliarožių 10 VI'!B12 -> 46136 | I9: ='Piliarožių 10 VI'!R3 -> 46105 | J9: ='Piliarožių 10 VI'!B13 | K9: ='Piliarožių 10 VI'!S3 | L9: ='Piliarožių 10 VI'!N3 -> 10 | M9: ='Piliarožių 10 VI'!P3 -> 0.94 | AC9: ='Piliarožių 10 VI'!AA2
A10: 8 | B10: ='Girios 112 II'!B3 -> 45770 | C10: ='Girios 112 II'!B2 -> Girios 112 II | D10: ='Girios 112 II'!B8 -> 12 | E10: ='Girios 112 II'!B5 -> C | F10: ='Girios 112 II'!B10 -> 0.11 | G10: ='Girios 112 II'!B11 -> 100 | H10: ='Girios 112 II'!B12 -> 46140 | I10: ='Girios 112 II'!R3 -> 46073 | J10: ='Girios 112 II'!B13 | K10: ='Girios 112 II'!S3 | L10: ='Girios 112 II'!N3 -> 100 | M10: ='Girios 112 II'!P3 -> 9.39 | AC10: ='Girios 112 II'!AA2
A11: 9 | B11: ='Girinaičių 7 II'!B3 -> 45791 | C11: ='Girinaičių 7 II'!B2 -> Girinaičių 7 II | D11: ='Girinaičių 7 II'!B8 -> 6 | E11: ='Girinaičių 7 II'!B5 -> B | F11: ='Girinaičių 7 II'!B10 -> 0.105 | G11: ='Girinaičių 7 II'!B11 -> 100 | H11: ='Girinaičių 7 II'!B12 -> 45975 | I11: ='Girinaičių 7 II'!R3 -> 45912 | J11: ='Girinaičių 7 II'!B13 | K11: ='Girinaičių 7 II'!S3 | L11: ='Girinaičių 7 II'!N3 -> 100 | M11: ='Girinaičių 7 II'!P3 -> 3.41 | AC11: ='Girinaičių 7 II'!AA2
A12: 10 | B12: ='Sfintii Arhangheli 21'!B3 -> 45908 | C12: ='Sfintii Arhangheli 21'!B2 -> Sfintii Arhangheli 21 | D12: ='Sfintii Arhangheli 21'!B8 -> 12 | E12: ='Sfintii Arhangheli 21'!B5 -> B | F12: ='Sfintii Arhangheli 21'!B10 -> 0.105 | G12: ='Sfintii Arhangheli 21'!B11 -> 123.24 | H12: ='Sfintii Arhangheli 21'!B12 -> 46274 | I12: ='Sfintii Arhangheli 21'!R3 -> 46267 | J12: ='Sfintii Arhangheli 21'!B13 | K12: ='Sfintii Arhangheli 21'!S3 | L12: ='Sfintii Arhangheli 21'!N3 -> 123.24 | M12: ='Sfintii Arhangheli 21'!P3 -> 12.74 | AC12: ='Sfintii Arhangheli 21'!AA2
A13: 11 | B13: ='Dvibutis Sodybų 12'!B3 -> 45912 | C13: ='Dvibutis Sodybų 12'!B2 -> Dvibutis Sodybų 12 | D13: ='Dvibutis Sodybų 12'!B8 -> 6 | E13: ='Dvibutis Sodybų 12'!B5 -> C | F13: ='Dvibutis Sodybų 12'!B10 -> 0.09 | G13: ='Dvibutis Sodybų 12'!B11 -> 100 | H13: ='Dvibutis Sodybų 12'!B12 -> 46098 | I13: ='Dvibutis Sodybų 12'!R3 -> 46084 | J13: ='Dvibutis Sodybų 12'!B13 | K13: ='Dvibutis Sodybų 12'!S3 | L13: ='Dvibutis Sodybų 12'!N3 -> 100 | M13: ='Dvibutis Sodybų 12'!P3 -> 4.15 | AC13: ='Dvibutis Sodybų 12'!AA2
A14: 12 | B14: ='Vienbutis Minsko 5A'!B3 -> 45915 | C14: ='Vienbutis Minsko 5A'!B2 -> Vienbutis Minsko 5A | D14: ='Vienbutis Minsko 5A'!B8 -> 12 | E14: ='Vienbutis Minsko 5A'!B5 -> C | F14: ='Vienbutis Minsko 5A'!B10 -> 0.09 | G14: ='Vienbutis Minsko 5A'!B11 -> 101.49 | H14: ='Vienbutis Minsko 5A'!B12 -> 46281 | I14: ='Vienbutis Minsko 5A'!R3 | J14: ='Vienbutis Minsko 5A'!B13 -> -14 | K14: ='Vienbutis Minsko 5A'!S3 -> 14 | L14: ='Vienbutis Minsko 5A'!N3 -> 0 | M14: ='Vienbutis Minsko 5A'!P3 -> 7.22 | AC14: ='Vienbutis Minsko 5A'!AA2 -> +
A15: 13 | B15: ='Pagojo 1 II'!B3 -> 45950 | C15: ='Pagojo 1 II'!B2 -> Pagojo 1 II | D15: ='Pagojo 1 II'!B8 -> 9 | E15: ='Pagojo 1 II'!B5 -> B | F15: ='Pagojo 1 II'!B10 -> 0.08 | G15: ='Pagojo 1 II'!B11 -> 108.26 | H15: ='Pagojo 1 II'!B12 -> 46224 | I15: ='Pagojo 1 II'!R3 -> 46072 | J15: ='Pagojo 1 II'!B13 | K15: ='Pagojo 1 II'!S3 | L15: ='Pagojo 1 II'!N3 -> 108.26 | M15: ='Pagojo 1 II'!P3 -> 2.86 | AC15: ='Pagojo 1 II'!AA2
A16: 14 | B16: ='Miškininkų 30 II'!B3 -> 45958 | C16: ='Miškininkų 30 II'!B2 -> Miškininkų 30 II | D16: ='Miškininkų 30 II'!B8 -> 12 | E16: ='Miškininkų 30 II'!B5 -> C | F16: ='Miškininkų 30 II'!B10 -> 0.09 | G16: ='Miškininkų 30 II'!B11 -> 10 | H16: ='Miškininkų 30 II'!B12 -> 46332 | I16: ='Miškininkų 30 II'!R3 | J16: ='Miškininkų 30 II'!B13 -> 37 | K16: ='Miškininkų 30 II'!S3 | L16: ='Miškininkų 30 II'!N3 -> 0 | M16: ='Miškininkų 30 II'!P3 -> 0.75 | AC16: ='Miškininkų 30 II'!AA2
A17: 15 | B17: ='Sūduvos 8-2'!B3 -> 46003 | C17: ='Sūduvos 8-2'!B2 -> Sūduvos 8-2 | D17: ='Sūduvos 8-2'!B8 -> 12 | E17: ='Sūduvos 8-2'!B5 -> C | F17: ='Sūduvos 8-2'!B10 -> 0.095 | G17: ='Sūduvos 8-2'!B11 -> 106.06 | H17: ='Sūduvos 8-2'!B12 -> 46371 | I17: ='Sūduvos 8-2'!R3 | J17: ='Sūduvos 8-2'!B13 -> 76 | K17: ='Sūduvos 8-2'!S3 | L17: ='Sūduvos 8-2'!N3 -> 0 | M17: ='Sūduvos 8-2'!P3 -> 5.54 | AC17: ='Sūduvos 8-2'!AA2
A18: 16 | B18: ='Birelių namas II'!B3 -> 46010 | C18: ='Birelių namas II'!B2 -> Birelių namas II | D18: ='Birelių namas II'!B8 -> 12 | E18: ='Birelių namas II'!B5 -> B | F18: ='Birelių namas II'!B10 -> 0.0825 | G18: ='Birelių namas II'!B11 -> 10 | H18: ='Birelių namas II'!B12 -> 46378 | I18: ='Birelių namas II'!R3 | J18: ='Birelių namas II'!B13 -> 83 | K18: ='Birelių namas II'!S3 | L18: ='Birelių namas II'!N3 -> 0 | M18: ='Birelių namas II'!P3 -> 0.65 | AC18: ='Birelių namas II'!AA2
A19: 17 | B19: ='Druskonio perlai VII'!B3 -> 46035 | C19: ='Druskonio perlai VII'!B2 -> Druskonio perlai VII | D19: ='Druskonio perlai VII'!B8 -> 12 | E19: ='Druskonio perlai VII'!B5 -> C | F19: ='Druskonio perlai VII'!B10 -> 0.095 | G19: ='Druskonio perlai VII'!B11 -> 118.77 | H19: ='Druskonio perlai VII'!B12 -> 46408 | I19: ='Druskonio perlai VII'!R3 -> 46086 | J19: ='Druskonio perlai VII'!B13 | K19: ='Druskonio perlai VII'!S3 | L19: ='Druskonio perlai VII'!N3 -> 118.77 | M19: ='Druskonio perlai VII'!P3 -> 3.35 | AC19: ='Druskonio perlai VII'!AA2
A20: 18 | B20: ='Vingio namai XIV'!B3 -> 46049 | C20: ='Vingio namai XIV'!B2 -> Vingio namai XIV | D20: ='Vingio namai XIV'!B8 -> 12 | E20: ='Vingio namai XIV'!B5 -> C | F20: ='Vingio namai XIV'!B10 -> 0.095 | G20: ='Vingio namai XIV'!B11 -> 123.63 | H20: ='Vingio namai XIV'!B12 -> 46420 | I20: ='Vingio namai XIV'!R3 | J20: ='Vingio namai XIV'!B13 -> 125 | K20: ='Vingio namai XIV'!S3 | L20: ='Vingio namai XIV'!N3 -> 0 | M20: ='Vingio namai XIV'!P3 -> 6.95 | AC20: ='Vingio namai XIV'!AA2
A21: 19 | B21: ='Vanagupės 36A-204 II'!B3 -> 46056 | C21: ='Vanagupės 36A-204 II'!B2 -> Vanagupės 36A-204 II | D21: ='Vanagupės 36A-204 II'!B8 -> 9 | E21: ='Vanagupės 36A-204 II'!B5 -> B | F21: ='Vanagupės 36A-204 II'!B10 -> 0.085 | G21: ='Vanagupės 36A-204 II'!B11 -> 103.62 | H21: ='Vanagupės 36A-204 II'!B12 -> 46330 | I21: ='Vanagupės 36A-204 II'!R3 -> 46211 | J21: ='Vanagupės 36A-204 II'!B13 | K21: ='Vanagupės 36A-204 II'!S3 | L21: ='Vanagupės 36A-204 II'!N3 -> 103.62 | M21: ='Vanagupės 36A-204 II'!P3 -> 3.8 | AC21: ='Vanagupės 36A-204 II'!AA2
A22: 20 | B22: ='Namas Panevėžyje'!B3 -> 46072 | C22: ='Namas Panevėžyje'!B2 -> Namas Panevėžyje | D22: ='Namas Panevėžyje'!B8 -> 9 | E22: ='Namas Panevėžyje'!B5 -> B | F22: ='Namas Panevėžyje'!B10 -> 0.085 | G22: ='Namas Panevėžyje'!B11 -> 157.15 | H22: ='Namas Panevėžyje'!B12 -> 46346 | I22: ='Namas Panevėžyje'!R3 | J22: ='Namas Panevėžyje'!B13 -> 51 | K22: ='Namas Panevėžyje'!S3 | L22: ='Namas Panevėžyje'!N3 -> 0 | M22: ='Namas Panevėžyje'!P3 -> 7.08 | AC22: ='Namas Panevėžyje'!AA2
A23: 21 | B23: ='Žemoji 52 XXIX“'!B3 -> 46073 | C23: ='Žemoji 52 XXIX“'!B2 -> Žemoji 52 XXIX“ | D23: ='Žemoji 52 XXIX“'!B8 -> 5 | E23: ='Žemoji 52 XXIX“'!B5 -> C | F23: ='Žemoji 52 XXIX“'!B10 -> 0.095 | G23: ='Žemoji 52 XXIX“'!B11 -> 103.68 | H23: ='Žemoji 52 XXIX“'!B12 -> 46220 | I23: ='Žemoji 52 XXIX“'!R3 -> 46232 | J23: ='Žemoji 52 XXIX“'!B13 | K23: ='Žemoji 52 XXIX“'!S3 | L23: ='Žemoji 52 XXIX“'!N3 -> 103.68 | M23: ='Žemoji 52 XXIX“'!P3 -> 4.52 | AC23: ='Žemoji 52 XXIX“'!AA2
A24: 22 | B24: ='Horizonto 2A XII'!B3 -> 46091 | C24: ='Horizonto 2A XII'!B2 -> Horizonto 2A XII | D24: ='Horizonto 2A XII'!B8 -> 9 | E24: ='Horizonto 2A XII'!B5 -> C | F24: ='Horizonto 2A XII'!B10 -> 0.095 | G24: ='Horizonto 2A XII'!B11 -> 100 | H24: ='Horizonto 2A XII'!B12 -> 46365 | I24: ='Horizonto 2A XII'!R3 | J24: ='Horizonto 2A XII'!B13 -> 70 | K24: ='Horizonto 2A XII'!S3 -> 92 | L24: ='Horizonto 2A XII'!N3 -> 0 | M24: ='Horizonto 2A XII'!P3 -> 0 | AC24: ='Horizonto 2A XII'!AA2 -> +
A25: 23 | B25: ='Tautvilo kotedžai XIV'!B3 -> 46088 | C25: ='Tautvilo kotedžai XIV'!B2 -> Tautvilo kotedžai XIV | D25: ='Tautvilo kotedžai XIV'!B8 -> 16 | E25: ='Tautvilo kotedžai XIV'!B5 -> C | F25: ='Tautvilo kotedžai XIV'!B10 -> 0.1 | G25: ='Tautvilo kotedžai XIV'!B11 -> 100 | H25: ='Tautvilo kotedžai XIV'!B12 -> 46549 | I25: ='Tautvilo kotedžai XIV'!R3 | J25: ='Tautvilo kotedžai XIV'!B13 -> 254 | K25: ='Tautvilo kotedžai XIV'!S3 | L25: ='Tautvilo kotedžai XIV'!N3 -> 0 | M25: ='Tautvilo kotedžai XIV'!P3 -> 5.64 | AC25: ='Tautvilo kotedžai XIV'!AA2
A26: 24 | B26: ='Kauno 36-118 II'!B3 -> 46095 | C26: ='Kauno 36-118 II'!B2 -> Kauno 36-118 II | D26: ='Kauno 36-118 II'!B8 -> 12 | E26: ='Kauno 36-118 II'!B5 -> B | F26: ='Kauno 36-118 II'!B10 -> 0.085 | G26: ='Kauno 36-118 II'!B11 -> 102.01 | H26: ='Kauno 36-118 II'!B12 -> 46462 | I26: ='Kauno 36-118 II'!R3 | J26: ='Kauno 36-118 II'!B13 -> 167 | K26: ='Kauno 36-118 II'!S3 | L26: ='Kauno 36-118 II'!N3 -> 0 | M26: ='Kauno 36-118 II'!P3 -> 2.55 | AC26: ='Kauno 36-118 II'!AA2
A27: 25 | B27: ='Vakaro 3A K1 III'!B3 -> 46211 | C27: ='Vakaro 3A K1 III'!B2 -> Vakaro 3A K1 III | D27: ='Vakaro 3A K1 III'!B8 -> 12 | E27: ='Vakaro 3A K1 III'!B5 -> C | F27: ='Vakaro 3A K1 III'!B10 -> 0.0925 | G27: ='Vakaro 3A K1 III'!B11 -> 142.39 | H27: ='Vakaro 3A K1 III'!B12 -> 46577 | I27: ='Vakaro 3A K1 III'!R3 | J27: ='Vakaro 3A K1 III'!B13 -> 282 | K27: ='Vakaro 3A K1 III'!S3 | L27: ='Vakaro 3A K1 III'!N3 -> 0 | M27: ='Vakaro 3A K1 III'!P3 -> 0 | AC27: ='Vakaro 3A K1 III'!AA2
A28: 26 | B28: ='Užnerio butai XV'!B3 -> 46232 | C28: ='Užnerio butai XV'!B2 -> Užnerio butai XV | D28: ='Užnerio butai XV'!B8 -> 12 | E28: ='Užnerio butai XV'!B5 -> C | F28: ='Užnerio butai XV'!B10 -> 0.095 | G28: ='Užnerio butai XV'!B11 -> 110.51 | H28: ='Užnerio butai XV'!B12 -> 46603 | I28: ='Užnerio butai XV'!R3 | J28: ='Užnerio butai XV'!B13 -> 308 | K28: ='Užnerio butai XV'!S3 | L28: ='Užnerio butai XV'!N3 -> 0 | M28: ='Užnerio butai XV'!P3 -> 0 | AC28: ='Užnerio butai XV'!AA2
A29: 27 | B29: ='Vienbutis Gilužiuose III'!B3 -> 46267 | C29: ='Vienbutis Gilužiuose III'!B2 -> Vienbutis Gilužiuose III | D29: ='Vienbutis Gilužiuose III'!B8 -> 12 | E29: ='Vienbutis Gilužiuose III'!B5 -> C | F29: ='Vienbutis Gilužiuose III'!B10 -> 0.095 | G29: ='Vienbutis Gilužiuose III'!B11 -> 128.59 | H29: ='Vienbutis Gilužiuose III'!B12 -> 46634 | I29: ='Užnerio butai XV'!R3 | J29: ='Vienbutis Gilužiuose III'!B13 -> 339 | K29: ='Vienbutis Gilužiuose III'!S3 | L29: ='Vienbutis Gilužiuose III'!N3 -> 0 | M29: ='Vienbutis Gilužiuose III'!P3 -> 0 | AC29: ='Vienbutis Gilužiuose III'!AA2

Sheet Pinigai
A1: Data | B1: Įnešta | C1: Išimta | D1: Premija | F1: Įnešta | G1: Išimta | H1: Premija | I1: Skirtumas | K1: XIRR | L1: =XIRR(Pinigai!K2:K200,Pinigai!A2:A200) -> 0.12084302
A2: 45719 | B2: 200 | C2: 0 | D2: 0 | F2: =SUM(B2:B39) -> 1030 | G2: =SUM(C2:C39) -> 0 | H2: =SUM(D2:D39) -> 40 | I2: =F2-G2 -> 1030 | K2: =B2*-1 -> -200
A3: 45725 | B3: 100 | C3: 0 | D3: 0 | K3: =B3*-1 -> -100
A4: 45729 | B4: 0 | C4: 0 | D4: 10 | K4: =B4*-1 -> 0
A5: 45743 | B5: 100 | C5: 0 | D5: 0 | K5: =B5*-1 -> -100
A6: 45757 | B6: 100 | C6: 0 | D6: 0 | K6: =B6*-1 -> -100
A7: 45764 | B7: 0 | C7: 0 | D7: 10 | K7: =B7*-1 -> 0
A8: 45770 | B8: 100 | C8: 0 | D8: 0 | K8: =B8*-1 -> -100
A9: 45791 | B9: 100 | C9: 0 | D9: 0 | K9: =B9*-1 -> -100
A10: 45908 | B10: 100 | C10: 0 | D10: 0 | K10: =B10*-1 -> -100
A11: 45919 | B11: 100 | C11: 0 | D11: 0 | K11: =B11*-1 -> -100
A12: 45957 | B12: 0 | C12: 0 | D12: 10 | K12: =B12*-1 -> 0
A13: 46002 | B13: 100 | C13: 0 | D13: 0 | K13: =B13*-1 -> -100
A14: 46010 | B14: 0 | C14: 0 | D14: 10 | K14: =B14*-1 -> 0
A15: 46095 | B15: 30 | C15: 0 | D15: 0 | K15: =B15*-1 -> -30
K16: =B16*-1 -> 0
K17: =B17*-1 -> 0
A200: =TODAY() -> 46295 | K200: =Overview!U3 -> 1197.84

Sheet Vienbutis Gilužiuose III
A1: Paskola | B1: LT-591 | D1: Data | E1: Paskola | F1: Palūkanos | G1: Paskola | H1: Palūkanos | I1: Papildomos | J1: Data | K1: Vėlavimas | M1: Paskola | O1: Palūkanos | Q1: XIRR | R1: Grąžinta | S1: Vėluoja | Y1: Data | Z1: Suma | AA1: Vėluoja
A2: Objektas | B2: Vienbutis Gilužiuose III | D2: 46387 | E2: 0 | F2: 4 | K2: =IF(J2>0,J2-D2,"") | M2: Suteikta | N2: Grąžinta | O2: Planuotos | P2: Realios | Y2: =B4 -> 46269 | Z2: =B11*-1 -> -128.59 | AA2: =IF(COUNTIFS(D:D,"<"&TODAY(),J:J,"")>0,"+","")
A3: Investicijos data | B3: 46267 | D3: 46477 | E3: 0 | F3: 3.05 | K3: =IF(J3>0,J3-D3,"") | M3: =B11 -> 128.59 | N3: =G42 -> 0 | O3: =F42 -> 12.27 | P3: =H42+I42 -> 0 | Q3: =IF(M3=N3,XIRR(Z2:Z14,Y2:Y14),"") | R3: =IF(M3=N3,B14,"") | S3: =IF(COUNTIFS(D:D,"<"&TODAY(),J:J,"")=0,"",TODAY()-_xlfn.MINIFS(D:D,D:D,"<"&TODAY(),J:J,"")) | Y3: =J2 -> 0 | Z3: =G2+H2+I2 -> 0
A4: Palūkanų pradžia | B4: 46269 | D4: 46568 | E4: 0 | F4: 3.05 | K4: =IF(J4>0,J4-D4,"") | Y4: =J3 -> 0 | Z4: =G3+H3+I3 -> 0
A5: Projekto reitingas | B5: C | D5: 46634 | E5: 128.59 | F5: 2.17 | K5: =IF(J5>0,J5-D5,"") | Y5: =J4 -> 0 | Z5: =G4+H4+I4 -> 0
A6: LTV, % | B6: 0.7 | K6: =IF(J6>0,J6-D6,"") | Y6: =J5 -> 0 | Z6: =G5+H5+I5 -> 0
A7: LTV max, % | B7: 0.8 | K7: =IF(J7>0,J7-D7,"") | Y7: =J6 -> 0 | Z7: =G6+H6+I6 -> 0
A8: Investicijos laikotarpis, mėn. | B8: 12 | K8: =IF(J8>0,J8-D8,"") | Y8: =J7 -> 0 | Z8: =G7+H7+I7 -> 0
A9: Palūkanų mokėjimas | B9: Q | K9: =IF(J9>0,J9-D9,"") | Y9: =J8 -> 0 | Z9: =G8+H8+I8 -> 0
A10: Palūkanos, % | B10: 0.095 | K10: =IF(J10>0,J10-D10,"") | Y10: =J9 -> 0 | Z10: =G9+H9+I9 -> 0
A11: Investuota, Eur | B11: 128.59 | K11: =IF(J11>0,J11-D11,"") | Y11: =J10 -> 0 | Z11: =G10+H10+I10 -> 0
A12: Paskolos pabaiga | B12: 46634 | K12: =IF(J12>0,J12-D12,"") | Y12: =J11 -> 0 | Z12: =G11+H11+I11 -> 0
A13: Liko dienų | B13: =IF(B11<>N3,(TODAY()-B12)*-1,"") -> 339 | K13: =IF(J13>0,J13-D13,"") | Y13: =J12 -> 0 | Z13: =G12+H12+I12 -> 0
A14: Grąžinta | K14: =IF(J14>0,J14-D14,"") | Y14: =J13 -> 0 | Z14: =G13+H13+I13 -> 0
A15: Vėlavo/Anksčiau | B15: =IF(M3=N3,B14-B12,"") | K15: =IF(J15>0,J15-D15,"")
K16: =IF(J16>0,J16-D16,"")
K17: =IF(J17>0,J17-D17,"")
K18: =IF(J18>0,J18-D18,"")
K19: =IF(J19>0,J19-D19,"")
K20: =IF(J20>0,J20-D20,"")
K21: =IF(J21>0,J21-D21,"")
K22: =IF(J22>0,J22-D22,"")
K23: =IF(J23>0,J23-D23,"")
K24: =IF(J24>0,J24-D24,"")
K25: =IF(J25>0,J25-D25,"")
K26: =IF(J26>0,J26-D26,"")
K27: =IF(J27>0,J27-D27,"")
... K41: =IF(J41>0,J41-D41,"")
D42: Viso: | E42: =SUM(E2:E41) -> 128.59 | F42: =SUM(F2:F41) -> 12.27 | G42: =SUM(G2:G41) -> 0 | H42: =SUM(H2:H41) -> 0 | I42: =SUM(I2:I41) -> 0

Sheet Užnerio butai XV
A1: Paskola | B1: LT-571 | D1: Data | E1: Paskola | F1: Palūkanos | G1: Paskola | H1: Palūkanos | I1: Papildomos | J1: Data | K1: Vėlavimas | M1: Paskola | O1: Palūkanos | Q1: XIRR | R1: Grąžinta | S1: Vėluoja | Y1: Data | Z1: Suma | AA1: Vėluoja
A2: Objektas | B2: Užnerio butai XV | D2: 46329 | E2: 0 | F2: 2.74 | K2: =IF(J2>0,J2-D2,"") | M2: Suteikta | N2: Grąžinta | O2: Planuotos | P2: Realios | Y2: =B4 -> 46238 | Z2: =B11*-1 -> -110.51 | AA2: =IF(COUNTIFS(D:D,"<"&TODAY(),J:J,"")>0,"+","")
A3: Investicijos data | B3: 46232 | D3: 46419 | E3: 0 | F3: 2.57 | K3: =IF(J3>0,J3-D3,"") | M3: =B11 -> 110.51 | N3: =G42 -> 0 | O3: =F42 -> 10.65 | P3: =H42+I42 -> 0 | Q3: =IF(M3=N3,XIRR(Z2:Z14,Y2:Y14),"") | R3: =IF(M3=N3,B14,"") | S3: =IF(COUNTIFS(D:D,"<"&TODAY(),J:J,"")=0,"",TODAY()-_xlfn.MINIFS(D:D,D:D,"<"&TODAY(),J:J,"")) | Y3: =J2 -> 0 | Z3: =G2+H2+I2 -> 0
A4: Palūkanų pradžia | B4: 46238 | D4: 46507 | E4: 0 | F4: 2.6 | K4: =IF(J4>0,J4-D4,"") | Y4: =J3 -> 0 | Z4: =G3+H3+I3 -> 0
A5: Projekto reitingas | B5: C | D5: 46603 | E5: 110.51 | F5: 2.74 | K5: =IF(J5>0,J5-D5,"") | Y5: =J4 -> 0 | Z5: =G4+H4+I4 -> 0
A6: LTV, % | B6: 0.7 | K6: =IF(J6>0,J6-D6,"") | Y6: =J5 -> 0 | Z6: =G5+H5+I5 -> 0
A7: LTV max, % | B7: 0.75 | K7: =IF(J7>0,J7-D7,"") | Y7: =J6 -> 0 | Z7: =G6+H6+I6 -> 0
A8: Investicijos laikotarpis, mėn. | B8: 12 | K8: =IF(J8>0,J8-D8,"") | Y8: =J7 -> 0 | Z8: =G7+H7+I7 -> 0
A9: Palūkanų mokėjimas | B9: Q | K9: =IF(J9>0,J9-D9,"") | Y9: =J8 -> 0 | Z9: =G8+H8+I8 -> 0
A10: Palūkanos, % | B10: 0.095 | K10: =IF(J10>0,J10-D10,"") | Y10: =J9 -> 0 | Z10: =G9+H9+I9 -> 0
A11: Investuota, Eur | B11: 110.51 | K11: =IF(J11>0,J11-D11,"") | Y11: =J10 -> 0 | Z11: =G10+H10+I10 -> 0
A12: Paskolos pabaiga | B12: 46603 | K12: =IF(J12>0,J12-D12,"") | Y12: =J11 -> 0 | Z12: =G11+H11+I11 -> 0
A13: Liko dienų | B13: =IF(B11<>N3,(TODAY()-B12)*-1,"") -> 308 | K13: =IF(J13>0,J13-D13,"") | Y13: =J12 -> 0 | Z13: =G12+H12+I12 -> 0
A14: Grąžinta | K14: =IF(J14>0,J14-D14,"") | Y14: =J13 -> 0 | Z14: =G13+H13+I13 -> 0
A15: Vėlavo/Anksčiau | B15: =IF(M3=N3,B14-B12,"") | K15: =IF(J15>0,J15-D15,"")
K16: =IF(J16>0,J16-D16,"")
K17: =IF(J17>0,J17-D17,"")
K18: =IF(J18>0,J18-D18,"")
K19: =IF(J19>0,J19-D19,"")
K20: =IF(J20>0,J20-D20,"")
K21: =IF(J21>0,J21-D21,"")
K22: =IF(J22>0,J22-D22,"")
K23: =IF(J23>0,J23-D23,"")
K24: =IF(J24>0,J24-D24,"")
K25: =IF(J25>0,J25-D25,"")
K26: =IF(J26>0,J26-D26,"")
K27: =IF(J27>0,J27-D27,"")
... K41: =IF(J41>0,J41-D41,"")
D42: Viso: | E42: =SUM(E2:E41) -> 110.51 | F42: =SUM(F2:F41) -> 10.65 | G42: =SUM(G2:G41) -> 0 | H42: =SUM(H2:H41) -> 0 | I42: =SUM(I2:I41) -> 0

Sheet Vakaro 3A K1 III
A1: Paskola | B1: LT-558 | D1: Data | E1: Paskola | F1: Palūkanos | G1: Paskola | H1: Palūkanos | I1: Papildomos | J1: Data | K1: Vėlavimas | M1: Paskola | O1: Palūkanos | Q1: XIRR | R1: Grąžinta | S1: Vėluoja | Y1: Data | Z1: Suma | AA1: Vėluoja
A2: Objektas | B2: Vakaro 3A K1 III | D2: 46329 | E2: 0 | F2: 4.21 | K2: =IF(J2>0,J2-D2,"") | M2: Suteikta | N2: Grąžinta | O2: Planuotos | P2: Realios | Y2: =B4 -> 46212 | Z2: =B11*-1 -> -142.39 | AA2: =IF(COUNTIFS(D:D,"<"&TODAY(),J:J,"")>0,"+","")
A3: Investicijos data | B3: 46211 | D3: 46419 | E3: 0 | F3: 3.22 | K3: =IF(J3>0,J3-D3,"") | M3: =B11 -> 142.39 | N3: =G42 -> 0 | O3: =F42 -> 13.21 | P3: =H42+I42 -> 0 | Q3: =IF(M3=N3,XIRR(Z2:Z14,Y2:Y14),"") | R3: =IF(M3=N3,B14,"") | S3: =IF(COUNTIFS(D:D,"<"&TODAY(),J:J,"")=0,"",TODAY()-_xlfn.MINIFS(D:D,D:D,"<"&TODAY(),J:J,"")) | Y3: =J2 -> 0 | Z3: =G2+H2+I2 -> 0
A4: Palūkanų pradžia | B4: 46212 | D4: 46507 | E4: 0 | F4: 3.26 | K4: =IF(J4>0,J4-D4,"") | Y4: =J3 -> 0 | Z4: =G3+H3+I3 -> 0
A5: Projekto reitingas | B5: C | D5: 46577 | E5: 142.39 | F5: 2.52 | K5: =IF(J5>0,J5-D5,"") | Y5: =J4 -> 0 | Z5: =G4+H4+I4 -> 0
A6: LTV, % | B6: 0.7 | K6: =IF(J6>0,J6-D6,"") | Y6: =J5 -> 0 | Z6: =G5+H5+I5 -> 0
A7: LTV max, % | B7: 0.7 | K7: =IF(J7>0,J7-D7,"") | Y7: =J6 -> 0 | Z7: =G6+H6+I6 -> 0
A8: Investicijos laikotarpis, mėn. | B8: 12 | K8: =IF(J8>0,J8-D8,"") | Y8: =J7 -> 0 | Z8: =G7+H7+I7 -> 0
A9: Palūkanų mokėjimas | B9: Q | K9: =IF(J9>0,J9-D9,"") | Y9: =J8 -> 0 | Z9: =G8+H8+I8 -> 0
A10: Palūkanos, % | B10: 0.0925 | K10: =IF(J10>0,J10-D10,"") | Y10: =J9 -> 0 | Z10: =G9+H9+I9 -> 0
A11: Investuota, Eur | B11: 142.39 | K11: =IF(J11>0,J11-D11,"") | Y11: =J10 -> 0 | Z11: =G10+H10+I10 -> 0
A12: Paskolos pabaiga | B12: 46577 | K12: =IF(J12>0,J12-D12,"") | Y12: =J11 -> 0 | Z12: =G11+H11+I11 -> 0
A13: Liko dienų | B13: =IF(B11<>N3,(TODAY()-B12)*-1,"") -> 282 | K13: =IF(J13>0,J13-D13,"") | Y13: =J12 -> 0 | Z13: =G12+H12+I12 -> 0
A14: Grąžinta | K14: =IF(J14>0,J14-D14,"") | Y14: =J13 -> 0 | Z14: =G13+H13+I13 -> 0
A15: Vėlavo/Anksčiau | B15: =IF(M3=N3,B14-B12,"") | K15: =IF(J15>0,J15-D15,"")
K16: =IF(J16>0,J16-D16,"")
K17: =IF(J17>0,J17-D17,"")
K18: =IF(J18>0,J18-D18,"")
K19: =IF(J19>0,J19-D19,"")
K20: =IF(J20>0,J20-D20,"")
K21: =IF(J21>0,J21-D21,"")
K22: =IF(J22>0,J22-D22,"")
K23: =IF(J23>0,J23-D23,"")
K24: =IF(J24>0,J24-D24,"")
K25: =IF(J25>0,J25-D25,"")
K26: =IF(J26>0,J26-D26,"")
K27: =IF(J27>0,J27-D27,"")
... K41: =IF(J41>0,J41-D41,"")
D42: Viso: | E42: =SUM(E2:E41) -> 142.39 | F42: =SUM(F2:F41) -> 13.21 | G42: =SUM(G2:G41) -> 0 | H42: =SUM(H2:H41) -> 0 | I42: =SUM(I2:I41) -> 0

Sheet Kauno 36-118 II
A1: Paskola | B1: LT-484 | D1: Data | E1: Paskola | F1: Palūkanos | G1: Paskola | H1: Palūkanos | I1: Papildomos | J1: Data | K1: Vėlavimas | M1: Paskola | O1: Palūkanos | Q1: XIRR | R1: Grąžinta | S1: Vėluoja | Y1: Data | Z1: Suma | AA1: Vėluoja
A2: Objektas | B2: Kauno 36-118 II | D2: 46203 | E2: 0 | F2: 2.55 | G2: 0 | H2: 2.55 | I2: 0 | J2: 46213 | K2: =IF(J2>0,J2-D2,"") -> 10 | M2: Suteikta | N2: Grąžinta | O2: Planuotos | P2: Realios | Y2: =B4 -> 46097 | Z2: =B11*-1 -> -102.01 | AA2: =IF(COUNTIFS(D:D,"<"&TODAY(),J:J,"")>0,"+","")
A3: Investicijos data | B3: 46095 | D3: 46295 | E3: 0 | F3: 2.17 | K3: =IF(J3>0,J3-D3,"") | M3: =B11 -> 102.01 | N3: =G42 -> 0 | O3: =F42 -> 8.72 | P3: =H42+I42 -> 2.55 | Q3: =IF(M3=N3,XIRR(Z2:Z14,Y2:Y14),"") | R3: =IF(M3=N3,B14,"") | S3: =IF(COUNTIFS(D:D,"<"&TODAY(),J:J,"")=0,"",TODAY()-_xlfn.MINIFS(D:D,D:D,"<"&TODAY(),J:J,"")) | Y3: =J2 -> 46213 | Z3: =G2+H2+I2 -> 2.55
A4: Palūkanų pradžia | B4: 46097 | D4: 46387 | E4: 0 | F4: 2.17 | K4: =IF(J4>0,J4-D4,"") | Y4: =J3 -> 0 | Z4: =G3+H3+I3 -> 0
A5: Projekto reitingas | B5: B | D5: 46462 | E5: 102.01 | F5: 1.83 | K5: =IF(J5>0,J5-D5,"") | Y5: =J4 -> 0 | Z5: =G4+H4+I4 -> 0
A6: LTV, % | B6: 0.73 | K6: =IF(J6>0,J6-D6,"") | Y6: =J5 -> 0 | Z6: =G5+H5+I5 -> 0
A7: LTV max, % | B7: 0.75 | K7: =IF(J7>0,J7-D7,"") | Y7: =J6 -> 0 | Z7: =G6+H6+I6 -> 0
A8: Investicijos laikotarpis, mėn. | B8: 12 | K8: =IF(J8>0,J8-D8,"") | Y8: =J7 -> 0 | Z8: =G7+H7+I7 -> 0
A9: Palūkanų mokėjimas | B9: Q | K9: =IF(J9>0,J9-D9,"") | Y9: =J8 -> 0 | Z9: =G8+H8+I8 -> 0
A10: Palūkanos, % | B10: 0.085 | K10: =IF(J10>0,J10-D10,"") | Y10: =J9 -> 0 | Z10: =G9+H9+I9 -> 0
A11: Investuota, Eur | B11: 102.01 | K11: =IF(J11>0,J11-D11,"") | Y11: =J10 -> 0 | Z11: =G10+H10+I10 -> 0
A12: Paskolos pabaiga | B12: 46462 | K12: =IF(J12>0,J12-D12,"") | Y12: =J11 -> 0 | Z12: =G11+H11+I11 -> 0
A13: Liko dienų | B13: =IF(B11<>N3,(TODAY()-B12)*-1,"") -> 167 | K13: =IF(J13>0,J13-D13,"") | Y13: =J12 -> 0 | Z13: =G12+H12+I12 -> 0
A14: Grąžinta | K14: =IF(J14>0,J14-D14,"") | Y14: =J13 -> 0 | Z14: =G13+H13+I13 -> 0
A15: Vėlavo/Anksčiau | B15: =IF(M3=N3,B14-B12,"") | K15: =IF(J15>0,J15-D15,"")
K16: =IF(J16>0,J16-D16,"")
K17: =IF(J17>0,J17-D17,"")
K18: =IF(J18>0,J18-D18,"")
K19: =IF(J19>0,J19-D19,"")
K20: =IF(J20>0,J20-D20,"")
K21: =IF(J21>0,J21-D21,"")
K22: =IF(J22>0,J22-D22,"")
K23: =IF(J23>0,J23-D23,"")
K24: =IF(J24>0,J24-D24,"")
K25: =IF(J25>0,J25-D25,"")
K26: =IF(J26>0,J26-D26,"")
K27: =IF(J27>0,J27-D27,"")
... K41: =IF(J41>0,J41-D41,"")
D42: Viso: | E42: =SUM(E2:E41) -> 102.01 | F42: =SUM(F2:F41) -> 8.72 | G42: =SUM(G2:G41) -> 0 | H42: =SUM(H2:H41) -> 2.55 | I42: =SUM(I2:I41) -> 0

Sheet Tautvilo kotedžai XIV
A1: Paskola | B1: LT-477 | D1: Data | E1: Paskola | F1: Palūkanos | G1: Paskola | H1: Palūkanos | I1: Papildomos | J1: Data | K1: Vėlavimas | M1: Paskola | O1: Palūkanos | Q1: XIRR | R1: Grąžinta | S1: Vėluoja | Y1: Data | Z1: Suma | AA1: Vėluoja
A2: Objektas | B2: Tautvilo kotedžai XIV | D2: 46203 | E2: 0 | F2: 3.14 | G2: 0 | H2: 3.14 | I2: 0 | J2: 46203 | K2: =IF(J2>0,J2-D2,"") -> 0 | M2: Suteikta | N2: Grąžinta | O2: Planuotos | P2: Realios | Y2: =B4 -> 46092 | Z2: =B11*-1 -> -100 | AA2: =IF(COUNTIFS(D:D,"<"&TODAY(),J:J,"")>0,"+","")
A3: Investicijos data | B3: 46088 | D3: 46295 | E3: 0 | F3: 2.5 | G3: 0 | H3: 2.5 | I3: 0 | J3: 46295 | K3: =IF(J3>0,J3-D3,"") -> 0 | M3: =B11 -> 100 | N3: =G42 -> 0 | O3: =F42 -> 12.61 | P3: =H42+I42 -> 5.64 | Q3: =IF(M3=N3,XIRR(Z2:Z14,Y2:Y14),"") | R3: =IF(M3=N3,B14,"") | S3: =IF(COUNTIFS(D:D,"<"&TODAY(),J:J,"")=0,"",TODAY()-_xlfn.MINIFS(D:D,D:D,"<"&TODAY(),J:J,"")) | Y3: =J2 -> 46203 | Z3: =G2+H2+I2 -> 3.14
A4: Palūkanų pradžia | B4: 46092 | D4: 46387 | E4: 0 | F4: 2.5 | K4: =IF(J4>0,J4-D4,"") | Y4: =J3 -> 46295 | Z4: =G3+H3+I3 -> 2.5
A5: Projekto reitingas | B5: C | D5: 46477 | E5: 0 | F5: 2.5 | K5: =IF(J5>0,J5-D5,"") | Y5: =J4 -> 0 | Z5: =G4+H4+I4 -> 0
A6: LTV, % | B6: 0.6 | D6: 46549 | E6: 100 | F6: 1.97 | K6: =IF(J6>0,J6-D6,"") | Y6: =J5 -> 0 | Z6: =G5+H5+I5 -> 0
A7: LTV max, % | B7: 0.75 | K7: =IF(J7>0,J7-D7,"") | Y7: =J6 -> 0 | Z7: =G6+H6+I6 -> 0
A8: Investicijos laikotarpis, mėn. | B8: 16 | K8: =IF(J8>0,J8-D8,"") | Y8: =J7 -> 0 | Z8: =G7+H7+I7 -> 0
A9: Palūkanų mokėjimas | B9: Q | K9: =IF(J9>0,J9-D9,"") | Y9: =J8 -> 0 | Z9: =G8+H8+I8 -> 0
A10: Palūkanos, % | B10: 0.1 | K10: =IF(J10>0,J10-D10,"") | Y10: =J9 -> 0 | Z10: =G9+H9+I9 -> 0
A11: Investuota, Eur | B11: 100 | K11: =IF(J11>0,J11-D11,"") | Y11: =J10 -> 0 | Z11: =G10+H10+I10 -> 0
A12: Paskolos pabaiga | B12: 46549 | K12: =IF(J12>0,J12-D12,"") | Y12: =J11 -> 0 | Z12: =G11+H11+I11 -> 0
A13: Liko dienų | B13: =IF(B11<>N3,(TODAY()-B12)*-1,"") -> 254 | K13: =IF(J13>0,J13-D13,"") | Y13: =J12 -> 0 | Z13: =G12+H12+I12 -> 0
A14: Grąžinta | K14: =IF(J14>0,J14-D14,"") | Y14: =J13 -> 0 | Z14: =G13+H13+I13 -> 0
A15: Vėlavo/Anksčiau | B15: =IF(M3=N3,B14-B12,"") | K15: =IF(J15>0,J15-D15,"")
K16: =IF(J16>0,J16-D16,"")
K17: =IF(J17>0,J17-D17,"")
K18: =IF(J18>0,J18-D18,"")
K19: =IF(J19>0,J19-D19,"")
K20: =IF(J20>0,J20-D20,"")
K21: =IF(J21>0,J21-D21,"")
K22: =IF(J22>0,J22-D22,"")
K23: =IF(J23>0,J23-D23,"")
K24: =IF(J24>0,J24-D24,"")
K25: =IF(J25>0,J25-D25,"")
K26: =IF(J26>0,J26-D26,"")
K27: =IF(J27>0,J27-D27,"")
... K41: =IF(J41>0,J41-D41,"")
D42: Viso: | E42: =SUM(E2:E41) -> 100 | F42: =SUM(F2:F41) -> 12.61 | G42: =SUM(G2:G41) -> 0 | H42: =SUM(H2:H41) -> 5.64 | I42: =SUM(I2:I41) -> 0

Sheet Horizonto 2A XII
A1: Paskola | B1: LT-481 | D1: Data | E1: Paskola | F1: Palūkanos | G1: Paskola | H1: Palūkanos | I1: Papildomos | J1: Data | K1: Vėlavimas | M1: Paskola | O1: Palūkanos | Q1: XIRR | R1: Grąžinta | S1: Vėluoja | Y1: Data | Z1: Suma | AA1: Vėluoja
A2: Objektas | B2: Horizonto 2A XII | D2: 46203 | E2: 0 | F2: 2.9 | K2: =IF(J2>0,J2-D2,"") | M2: Suteikta | N2: Grąžinta | O2: Planuotos | P2: Realios | Y2: =B4 -> 46091 | Z2: =B11*-1 -> -100 | AA2: =IF(COUNTIFS(D:D,"<"&TODAY(),J:J,"")>0,"+","") -> +
A3: Investicijos data | B3: 46091 | D3: 46295 | E3: 0 | F3: 2.38 | K3: =IF(J3>0,J3-D3,"") | M3: =B11 -> 100 | N3: =G42 -> 0 | O3: =F42 -> 7.1 | P3: =H42+I42 -> 0 | Q3: =IF(M3=N3,XIRR(Z2:Z14,Y2:Y14),"") | R3: =IF(M3=N3,B14,"") | S3: =IF(COUNTIFS(D:D,"<"&TODAY(),J:J,"")=0,"",TODAY()-_xlfn.MINIFS(D:D,D:D,"<"&TODAY(),J:J,"")) -> 92 | Y3: =J2 -> 0 | Z3: =G2+H2+I2 -> 0
A4: Palūkanų pradžia | B4: 46091 | D4: 46365 | E4: 100 | F4: 1.82 | K4: =IF(J4>0,J4-D4,"") | Y4: =J3 -> 0 | Z4: =G3+H3+I3 -> 0
A5: Projekto reitingas | B5: C | K5: =IF(J5>0,J5-D5,"") | Y5: =J4 -> 0 | Z5: =G4+H4+I4 -> 0
A6: LTV, % | B6: 0.7 | K6: =IF(J6>0,J6-D6,"") | Y6: =J5 -> 0 | Z6: =G5+H5+I5 -> 0
A7: LTV max, % | B7: 0.7 | K7: =IF(J7>0,J7-D7,"") | Y7: =J6 -> 0 | Z7: =G6+H6+I6 -> 0
A8: Investicijos laikotarpis, mėn. | B8: 9 | K8: =IF(J8>0,J8-D8,"") | Y8: =J7 -> 0 | Z8: =G7+H7+I7 -> 0
A9: Palūkanų mokėjimas | B9: Q | K9: =IF(J9>0,J9-D9,"") | Y9: =J8 -> 0 | Z9: =G8+H8+I8 -> 0
A10: Palūkanos, % | B10: 0.095 | K10: =IF(J10>0,J10-D10,"") | Y10: =J9 -> 0 | Z10: =G9+H9+I9 -> 0
A11: Investuota, Eur | B11: 100 | K11: =IF(J11>0,J11-D11,"") | Y11: =J10 -> 0 | Z11: =G10+H10+I10 -> 0
A12: Paskolos pabaiga | B12: 46365 | K12: =IF(J12>0,J12-D12,"") | Y12: =J11 -> 0 | Z12: =G11+H11+I11 -> 0
A13: Liko dienų | B13: =IF(B11<>N3,(TODAY()-B12)*-1,"") -> 70 | K13: =IF(J13>0,J13-D13,"") | Y13: =J12 -> 0 | Z13: =G12+H12+I12 -> 0
A14: Grąžinta | K14: =IF(J14>0,J14-D14,"") | Y14: =J13 -> 0 | Z14: =G13+H13+I13 -> 0
A15: Vėlavo/Anksčiau | B15: =IF(M3=N3,B14-B12,"") | K15: =IF(J15>0,J15-D15,"")
K16: =IF(J16>0,J16-D16,"")
K17: =IF(J17>0,J17-D17,"")
K18: =IF(J18>0,J18-D18,"")
K19: =IF(J19>0,J19-D19,"")
K20: =IF(J20>0,J20-D20,"")
K21: =IF(J21>0,J21-D21,"")
K22: =IF(J22>0,J22-D22,"")
K23: =IF(J23>0,J23-D23,"")
K24: =IF(J24>0,J24-D24,"")
K25: =IF(J25>0,J25-D25,"")
K26: =IF(J26>0,J26-D26,"")
K27: =IF(J27>0,J27-D27,"")
... K41: =IF(J41>0,J41-D41,"")
D42: Viso: | E42: =SUM(E2:E41) -> 100 | F42: =SUM(F2:F41) -> 7.1 | G42: =SUM(G2:G41) -> 0 | H42: =SUM(H2:H41) -> 0 | I42: =SUM(I2:I41) -> 0

Sheet Žemoji 52 XXIX“
A1: Paskola | B1: LT-466 | D1: Data | E1: Paskola | F1: Palūkanos | G1: Paskola | H1: Palūkanos | I1: Papildomos | J1: Data | K1: Vėlavimas | M1: Paskola | O1: Palūkanos | Q1: XIRR | R1: Grąžinta | S1: Vėluoja | Y1: Data | Z1: Suma | AA1: Vėluoja
A2: Objektas | B2: Žemoji 52 XXIX“ | D2: 46174 | E2: 0 | F2: 2.76 | G2: 0 | H2: 2.76 | I2: 0 | J2: 46174 | K2: =IF(J2>0,J2-D2,"") -> 0 | M2: Suteikta | N2: Grąžinta | O2: Planuotos | P2: Realios | Y2: =B4 -> 46073 | Z2: =B11*-1 -> -103.68 | AA2: =IF(COUNTIFS(D:D,"<"&TODAY(),J:J,"")>0,"+","")
A3: Investicijos data | B3: 46073 | D3: 46220 | E3: 103.68 | F3: 1.26 | G3: 103.68 | H3: 1.26 | I3: 0.5 | J3: 46232 | K3: =IF(J3>0,J3-D3,"") -> 12 | M3: =B11 -> 103.68 | N3: =G42 -> 103.68 | O3: =F42 -> 4.02 | P3: =H42+I42 -> 4.52 | Q3: =IF(M3=N3,XIRR(Z2:Z14,Y2:Y14),"") -> 0.10393961 | R3: =IF(M3=N3,B14,"") -> 46232 | S3: =IF(COUNTIFS(D:D,"<"&TODAY(),J:J,"")=0,"",TODAY()-_xlfn.MINIFS(D:D,D:D,"<"&TODAY(),J:J,"")) | Y3: =J2 -> 46174 | Z3: =G2+H2+I2 -> 2.76
A4: Palūkanų pradžia | B4: 46073 | K4: =IF(J4>0,J4-D4,"") | Y4: =J3 -> 46232 | Z4: =G3+H3+I3 -> 105.44
A5: Projekto reitingas | B5: C | K5: =IF(J5>0,J5-D5,"") | Y5: =J4 -> 0 | Z5: =G4+H4+I4 -> 0
A6: LTV, % | B6: 0.71 | K6: =IF(J6>0,J6-D6,"") | Y6: =J5 -> 0 | Z6: =G5+H5+I5 -> 0
A7: LTV max, % | B7: 0.8 | K7: =IF(J7>0,J7-D7,"") | Y7: =J6 -> 0 | Z7: =G6+H6+I6 -> 0
A8: Investicijos laikotarpis, mėn. | B8: 5 | K8: =IF(J8>0,J8-D8,"") | Y8: =J7 -> 0 | Z8: =G7+H7+I7 -> 0
A9: Palūkanų mokėjimas | B9: Q | K9: =IF(J9>0,J9-D9,"") | Y9: =J8 -> 0 | Z9: =G8+H8+I8 -> 0
A10: Palūkanos, % | B10: 0.095 | K10: =IF(J10>0,J10-D10,"") | Y10: =J9 -> 0 | Z10: =G9+H9+I9 -> 0
A11: Investuota, Eur | B11: 103.68 | K11: =IF(J11>0,J11-D11,"") | Y11: =J10 -> 0 | Z11: =G10+H10+I10 -> 0
A12: Paskolos pabaiga | B12: 46220 | K12: =IF(J12>0,J12-D12,"") | Y12: =J11 -> 0 | Z12: =G11+H11+I11 -> 0
A13: Liko dienų | B13: =IF(B11<>N3,(TODAY()-B12)*-1,"") | K13: =IF(J13>0,J13-D13,"") | Y13: =J12 -> 0 | Z13: =G12+H12+I12 -> 0
A14: Grąžinta | B14: 46232 | K14: =IF(J14>0,J14-D14,"") | Y14: =J13 -> 0 | Z14: =G13+H13+I13 -> 0
A15: Vėlavo/Anksčiau | B15: =IF(M3=N3,B14-B12,"") -> 12 | K15: =IF(J15>0,J15-D15,"")
K16: =IF(J16>0,J16-D16,"")
K17: =IF(J17>0,J17-D17,"")
K18: =IF(J18>0,J18-D18,"")
K19: =IF(J19>0,J19-D19,"")
K20: =IF(J20>0,J20-D20,"")
K21: =IF(J21>0,J21-D21,"")
K22: =IF(J22>0,J22-D22,"")
K23: =IF(J23>0,J23-D23,"")
K24: =IF(J24>0,J24-D24,"")
K25: =IF(J25>0,J25-D25,"")
K26: =IF(J26>0,J26-D26,"")
K27: =IF(J27>0,J27-D27,"")
... K41: =IF(J41>0,J41-D41,"")
D42: Viso: | E42: =SUM(E2:E41) -> 103.68 | F42: =SUM(F2:F41) -> 4.02 | G42: =SUM(G2:G41) -> 103.68 | H42: =SUM(H2:H41) -> 4.02 | I42: =SUM(I2:I41) -> 0.5

Sheet Namas Panevėžyje
A1: Paskola | B1: LT-465 | D1: Data | E1: Paskola | F1: Palūkanos | G1: Paskola | H1: Palūkanos | I1: Papildomos | J1: Data | K1: Vėlavimas | M1: Paskola | O1: Palūkanos | Q1: XIRR | R1: Grąžinta | S1: Vėluoja | Y1: Data | Z1: Suma | AA1: Vėluoja
A2: Objektas | B2: Namas Panevėžyje | D2: 46174 | E2: 0 | F2: 3.78 | G2: 0 | H2: 3.78 | I2: 0 | J2: 46174 | K2: =IF(J2>0,J2-D2,"") -> 0 | M2: Suteikta | N2: Grąžinta | O2: Planuotos | P2: Realios | Y2: =B4 -> 46073 | Z2: =B11*-1 -> -157.15 | AA2: =IF(COUNTIFS(D:D,"<"&TODAY(),J:J,"")>0,"+","")
A3: Investicijos data | B3: 46072 | D3: 46265 | E3: 0 | F3: 3.3 | G3: 0 | H3: 3.3 | I3: 0 | J3: 46268 | K3: =IF(J3>0,J3-D3,"") -> 3 | M3: =B11 -> 157.15 | N3: =G42 -> 0 | O3: =F42 -> 10.05 | P3: =H42+I42 -> 7.08 | Q3: =IF(M3=N3,XIRR(Z2:Z14,Y2:Y14),"") | R3: =IF(M3=N3,B14,"") | S3: =IF(COUNTIFS(D:D,"<"&TODAY(),J:J,"")=0,"",TODAY()-_xlfn.MINIFS(D:D,D:D,"<"&TODAY(),J:J,"")) | Y3: =J2 -> 46174 | Z3: =G2+H2+I2 -> 3.78
A4: Palūkanų pradžia | B4: 46073 | D4: 46346 | E4: 157.15 | F4: 2.97 | K4: =IF(J4>0,J4-D4,"") | Y4: =J3 -> 46268 | Z4: =G3+H3+I3 -> 3.3
A5: Projekto reitingas | B5: B | K5: =IF(J5>0,J5-D5,"") | Y5: =J4 -> 0 | Z5: =G4+H4+I4 -> 0
A6: LTV, % | B6: 0.24 | K6: =IF(J6>0,J6-D6,"") | Y6: =J5 -> 0 | Z6: =G5+H5+I5 -> 0
A7: LTV max, % | B7: 0.59 | K7: =IF(J7>0,J7-D7,"") | Y7: =J6 -> 0 | Z7: =G6+H6+I6 -> 0
A8: Investicijos laikotarpis, mėn. | B8: 9 | K8: =IF(J8>0,J8-D8,"") | Y8: =J7 -> 0 | Z8: =G7+H7+I7 -> 0
A9: Palūkanų mokėjimas | B9: Q | K9: =IF(J9>0,J9-D9,"") | Y9: =J8 -> 0 | Z9: =G8+H8+I8 -> 0
A10: Palūkanos, % | B10: 0.085 | K10: =IF(J10>0,J10-D10,"") | Y10: =J9 -> 0 | Z10: =G9+H9+I9 -> 0
A11: Investuota, Eur | B11: 157.15 | K11: =IF(J11>0,J11-D11,"") | Y11: =J10 -> 0 | Z11: =G10+H10+I10 -> 0
A12: Paskolos pabaiga | B12: 46346 | K12: =IF(J12>0,J12-D12,"") | Y12: =J11 -> 0 | Z12: =G11+H11+I11 -> 0
A13: Liko dienų | B13: =IF(B11<>N3,(TODAY()-B12)*-1,"") -> 51 | K13: =IF(J13>0,J13-D13,"") | Y13: =J12 -> 0 | Z13: =G12+H12+I12 -> 0
A14: Grąžinta | K14: =IF(J14>0,J14-D14,"") | Y14: =J13 -> 0 | Z14: =G13+H13+I13 -> 0
A15: Vėlavo/Anksčiau | B15: =IF(M3=N3,B14-B12,"") | K15: =IF(J15>0,J15-D15,"")
K16: =IF(J16>0,J16-D16,"")
K17: =IF(J17>0,J17-D17,"")
K18: =IF(J18>0,J18-D18,"")
K19: =IF(J19>0,J19-D19,"")
K20: =IF(J20>0,J20-D20,"")
K21: =IF(J21>0,J21-D21,"")
K22: =IF(J22>0,J22-D22,"")
K23: =IF(J23>0,J23-D23,"")
K24: =IF(J24>0,J24-D24,"")
K25: =IF(J25>0,J25-D25,"")
K26: =IF(J26>0,J26-D26,"")
K27: =IF(J27>0,J27-D27,"")
... K41: =IF(J41>0,J41-D41,"")
D42: Viso: | E42: =SUM(E2:E41) -> 157.15 | F42: =SUM(F2:F41) -> 10.05 | G42: =SUM(G2:G41) -> 0 | H42: =SUM(H2:H41) -> 7.08 | I42: =SUM(I2:I41) -> 0

Sheet Vanagupės 36A-204 II
A1: Paskola | B1: LT-457 | D1: Data | E1: Paskola | F1: Palūkanos | G1: Paskola | H1: Palūkanos | I1: Papildomos | J1: Data | K1: Vėlavimas | M1: Paskola | O1: Palūkanos | Q1: XIRR | R1: Grąžinta | S1: Vėluoja | Y1: Data | Z1: Suma | AA1: Vėluoja
A2: Objektas | B2: Vanagupės 36A-204 II | D2: 46174 | E2: 0 | F2: 2.89 | G2: 0 | H2: 2.89 | I2: 0 | J2: 46174 | K2: =IF(J2>0,J2-D2,"") -> 0 | M2: Suteikta | N2: Grąžinta | O2: Planuotos | P2: Realios | Y2: =B4 -> 46057 | Z2: =B11*-1 -> -103.62 | AA2: =IF(COUNTIFS(D:D,"<"&TODAY(),J:J,"")>0,"+","")
A3: Investicijos data | B3: 46056 | D3: 46265 | E3: 0 | F3: 2.18 | G3: 0 | H3: 0 | I3: 0 | J3: 46211 | K3: =IF(J3>0,J3-D3,"") -> -54 | M3: =B11 -> 103.62 | N3: =G42 -> 103.62 | O3: =F42 -> 6.64 | P3: =H42+I42 -> 3.8 | Q3: =IF(M3=N3,XIRR(Z2:Z14,Y2:Y14),"") -> 0.089719573 | R3: =IF(M3=N3,B14,"") -> 46211 | S3: =IF(COUNTIFS(D:D,"<"&TODAY(),J:J,"")=0,"",TODAY()-_xlfn.MINIFS(D:D,D:D,"<"&TODAY(),J:J,"")) | Y3: =J2 -> 46174 | Z3: =G2+H2+I2 -> 2.89
A4: Palūkanų pradžia | B4: 46057 | D4: 46330 | E4: 103.62 | F4: 1.57 | G4: 103.62 | H4: 0.91 | I4: 0 | J4: 46211 | K4: =IF(J4>0,J4-D4,"") -> -119 | Y4: =J3 -> 46211 | Z4: =G3+H3+I3 -> 0
A5: Projekto reitingas | B5: B | K5: =IF(J5>0,J5-D5,"") | Y5: =J4 -> 46211 | Z5: =G4+H4+I4 -> 104.53
A6: LTV, % | B6: 0.41 | K6: =IF(J6>0,J6-D6,"") | Y6: =J5 -> 0 | Z6: =G5+H5+I5 -> 0
A7: LTV max, % | B7: 0.65 | K7: =IF(J7>0,J7-D7,"") | Y7: =J6 -> 0 | Z7: =G6+H6+I6 -> 0
A8: Investicijos laikotarpis, mėn. | B8: 9 | K8: =IF(J8>0,J8-D8,"") | Y8: =J7 -> 0 | Z8: =G7+H7+I7 -> 0
A9: Palūkanų mokėjimas | B9: Q | K9: =IF(J9>0,J9-D9,"") | Y9: =J8 -> 0 | Z9: =G8+H8+I8 -> 0
A10: Palūkanos, % | B10: 0.085 | K10: =IF(J10>0,J10-D10,"") | Y10: =J9 -> 0 | Z10: =G9+H9+I9 -> 0
A11: Investuota, Eur | B11: 103.62 | K11: =IF(J11>0,J11-D11,"") | Y11: =J10 -> 0 | Z11: =G10+H10+I10 -> 0
A12: Paskolos pabaiga | B12: 46330 | K12: =IF(J12>0,J12-D12,"") | Y12: =J11 -> 0 | Z12: =G11+H11+I11 -> 0
A13: Liko dienų | B13: =IF(B11<>N3,(TODAY()-B12)*-1,"") | K13: =IF(J13>0,J13-D13,"") | Y13: =J12 -> 0 | Z13: =G12+H12+I12 -> 0
A14: Grąžinta | B14: 46211 | K14: =IF(J14>0,J14-D14,"") | Y14: =J13 -> 0 | Z14: =G13+H13+I13 -> 0
A15: Vėlavo/Anksčiau | B15: =IF(M3=N3,B14-B12,"") -> -119 | K15: =IF(J15>0,J15-D15,"")
K16: =IF(J16>0,J16-D16,"")
K17: =IF(J17>0,J17-D17,"")
K18: =IF(J18>0,J18-D18,"")
K19: =IF(J19>0,J19-D19,"")
K20: =IF(J20>0,J20-D20,"")
K21: =IF(J21>0,J21-D21,"")
K22: =IF(J22>0,J22-D22,"")
K23: =IF(J23>0,J23-D23,"")
K24: =IF(J24>0,J24-D24,"")
K25: =IF(J25>0,J25-D25,"")
K26: =IF(J26>0,J26-D26,"")
K27: =IF(J27>0,J27-D27,"")
... K41: =IF(J41>0,J41-D41,"")
D42: Viso: | E42: =SUM(E2:E41) -> 103.62 | F42: =SUM(F2:F41) -> 6.64 | G42: =SUM(G2:G41) -> 103.62 | H42: =SUM(H2:H41) -> 3.8 | I42: =SUM(I2:I41) -> 0

Sheet Vingio namai XIV
A1: Paskola | B1: LT-451 | D1: Data | E1: Paskola | F1: Palūkanos | G1: Paskola | H1: Palūkanos | I1: Papildomos | J1: Data | K1: Vėlavimas | M1: Paskola | O1: Palūkanos | Q1: XIRR | R1: Grąžinta | S1: Vėluoja | Y1: Data | Z1: Suma | AA1: Vėluoja
A2: Objektas | B2: Vingio namai XIV | D2: 46174 | E2: 0 | F2: 4.05 | G2: 0 | H2: 4.05 | I2: 0 | J2: 46174 | K2: =IF(J2>0,J2-D2,"") -> 0 | M2: Suteikta | N2: Grąžinta | O2: Planuotos | P2: Realios | Y2: =B4 -> 46055 | Z2: =B11*-1 -> -123.63 | AA2: =IF(COUNTIFS(D:D,"<"&TODAY(),J:J,"")>0,"+","")
A3: Investicijos data | B3: 46049 | D3: 46265 | E3: 0 | F3: 2.9 | G3: 0 | H3: 2.9 | I3: 0 | J3: 46267 | K3: =IF(J3>0,J3-D3,"") -> 2 | M3: =B11 -> 123.63 | N3: =G42 -> 0 | O3: =F42 -> 11.91 | P3: =H42+I42 -> 6.95 | Q3: =IF(M3=N3,XIRR(Z2:Z14,Y2:Y14),"") | R3: =IF(M3=N3,B14,"") | S3: =IF(COUNTIFS(D:D,"<"&TODAY(),J:J,"")=0,"",TODAY()-_xlfn.MINIFS(D:D,D:D,"<"&TODAY(),J:J,"")) | Y3: =J2 -> 46174 | Z3: =G2+H2+I2 -> 4.05
A4: Palūkanų pradžia | B4: 46055 | D4: 46356 | E4: 0 | F4: 2.94 | K4: =IF(J4>0,J4-D4,"") | Y4: =J3 -> 46267 | Z4: =G3+H3+I3 -> 2.9
A5: Projekto reitingas | B5: C | D5: 46420 | E5: 123.63 | F5: 2.02 | K5: =IF(J5>0,J5-D5,"") | Y5: =J4 -> 0 | Z5: =G4+H4+I4 -> 0
A6: LTV, % | B6: 0.62 | K6: =IF(J6>0,J6-D6,"") | Y6: =J5 -> 0 | Z6: =G5+H5+I5 -> 0
A7: LTV max, % | B7: 0.8 | K7: =IF(J7>0,J7-D7,"") | Y7: =J6 -> 0 | Z7: =G6+H6+I6 -> 0
A8: Investicijos laikotarpis, mėn. | B8: 12 | K8: =IF(J8>0,J8-D8,"") | Y8: =J7 -> 0 | Z8: =G7+H7+I7 -> 0
A9: Palūkanų mokėjimas | B9: Q | K9: =IF(J9>0,J9-D9,"") | Y9: =J8 -> 0 | Z9: =G8+H8+I8 -> 0
A10: Palūkanos, % | B10: 0.095 | K10: =IF(J10>0,J10-D10,"") | Y10: =J9 -> 0 | Z10: =G9+H9+I9 -> 0
A11: Investuota, Eur | B11: 123.63 | K11: =IF(J11>0,J11-D11,"") | Y11: =J10 -> 0 | Z11: =G10+H10+I10 -> 0
A12: Paskolos pabaiga | B12: 46420 | K12: =IF(J12>0,J12-D12,"") | Y12: =J11 -> 0 | Z12: =G11+H11+I11 -> 0
A13: Liko dienų | B13: =IF(B11<>N3,(TODAY()-B12)*-1,"") -> 125 | K13: =IF(J13>0,J13-D13,"") | Y13: =J12 -> 0 | Z13: =G12+H12+I12 -> 0
A14: Grąžinta | K14: =IF(J14>0,J14-D14,"") | Y14: =J13 -> 0 | Z14: =G13+H13+I13 -> 0
A15: Vėlavo/Anksčiau | B15: =IF(M3=N3,B14-B12,"") | K15: =IF(J15>0,J15-D15,"")
K16: =IF(J16>0,J16-D16,"")
K17: =IF(J17>0,J17-D17,"")
K18: =IF(J18>0,J18-D18,"")
K19: =IF(J19>0,J19-D19,"")
K20: =IF(J20>0,J20-D20,"")
K21: =IF(J21>0,J21-D21,"")
K22: =IF(J22>0,J22-D22,"")
K23: =IF(J23>0,J23-D23,"")
K24: =IF(J24>0,J24-D24,"")
K25: =IF(J25>0,J25-D25,"")
K26: =IF(J26>0,J26-D26,"")
K27: =IF(J27>0,J27-D27,"")
... K41: =IF(J41>0,J41-D41,"")
D42: Viso: | E42: =SUM(E2:E41) -> 123.63 | F42: =SUM(F2:F41) -> 11.91 | G42: =SUM(G2:G41) -> 0 | H42: =SUM(H2:H41) -> 6.95 | I42: =SUM(I2:I41) -> 0

Sheet Druskonio perlai VII
A1: Paskola | B1: LT-440 | D1: Data | E1: Paskola | F1: Palūkanos | G1: Paskola | H1: Palūkanos | I1: Papildomos | J1: Data | K1: Vėlavimas | M1: Paskola | O1: Palūkanos | Q1: XIRR | R1: Grąžinta | S1: Vėluoja | Y1: Data | Z1: Suma | AA1: Vėluoja
A2: Objektas | B2: Druskonio perlai VII | D2: 46142 | E2: 0 | F2: 3.35 | G2: 0 | H2: 3.35 | I2: 0 | J2: 46086 | K2: =IF(J2>0,J2-D2,"") -> -56 | M2: Suteikta | N2: Grąžinta | O2: Planuotos | P2: Realios | Y2: =B4 -> 46043 | Z2: =B11*-1 -> -118.77 | AA2: =IF(COUNTIFS(D:D,"<"&TODAY(),J:J,"")>0,"+","")
A3: Investicijos data | B3: 46035 | D3: 46234 | E3: 0 | F3: 2.82 | G3: 0 | H3: 0 | I3: 0 | J3: 46086 | K3: =IF(J3>0,J3-D3,"") -> -148 | M3: =B11 -> 118.77 | N3: =G42 -> 118.77 | O3: =F42 -> 11.52 | P3: =H42+I42 -> 3.35 | Q3: =IF(M3=N3,XIRR(Z2:Z14,Y2:Y14),"") -> 0.26630951 | R3: =IF(M3=N3,B14,"") -> 46086 | S3: =IF(COUNTIFS(D:D,"<"&TODAY(),J:J,"")=0,"",TODAY()-_xlfn.MINIFS(D:D,D:D,"<"&TODAY(),J:J,"")) | Y3: =J2 -> 46086 | Z3: =G2+H2+I2 -> 3.35
A4: Palūkanų pradžia | B4: 46043 | D4: 46329 | E4: 0 | F4: 2.91 | G4: 0 | H4: 0 | I4: 0 | J4: 46086 | K4: =IF(J4>0,J4-D4,"") -> -243 | Y4: =J3 -> 46086 | Z4: =G3+H3+I3 -> 0
A5: Projekto reitingas | B5: C | D5: 46408 | E5: 118.77 | F5: 2.44 | G5: 118.77 | H5: 0 | I5: 0 | J5: 46086 | K5: =IF(J5>0,J5-D5,"") -> -322 | Y5: =J4 -> 46086 | Z5: =G4+H4+I4 -> 0
A6: LTV, % | B6: 0.32 | K6: =IF(J6>0,J6-D6,"") | Y6: =J5 -> 46086 | Z6: =G5+H5+I5 -> 118.77
A7: LTV max, % | B7: 0.7 | K7: =IF(J7>0,J7-D7,"") | Y7: =J6 -> 0 | Z7: =G6+H6+I6 -> 0
A8: Investicijos laikotarpis, mėn. | B8: 12 | K8: =IF(J8>0,J8-D8,"") | Y8: =J7 -> 0 | Z8: =G7+H7+I7 -> 0
A9: Palūkanų mokėjimas | B9: Q | K9: =IF(J9>0,J9-D9,"") | Y9: =J8 -> 0 | Z9: =G8+H8+I8 -> 0
A10: Palūkanos, % | B10: 0.095 | K10: =IF(J10>0,J10-D10,"") | Y10: =J9 -> 0 | Z10: =G9+H9+I9 -> 0
A11: Investuota, Eur | B11: 118.77 | K11: =IF(J11>0,J11-D11,"") | Y11: =J10 -> 0 | Z11: =G10+H10+I10 -> 0
A12: Paskolos pabaiga | B12: 46408 | K12: =IF(J12>0,J12-D12,"") | Y12: =J11 -> 0 | Z12: =G11+H11+I11 -> 0
A13: Liko dienų | B13: =IF(B11<>N3,(TODAY()-B12)*-1,"") | K13: =IF(J13>0,J13-D13,"") | Y13: =J12 -> 0 | Z13: =G12+H12+I12 -> 0
A14: Grąžinta | B14: 46086 | K14: =IF(J14>0,J14-D14,"") | Y14: =J13 -> 0 | Z14: =G13+H13+I13 -> 0
A15: Vėlavo/Anksčiau | B15: =IF(M3=N3,B14-B12,"") -> -322 | K15: =IF(J15>0,J15-D15,"")
K16: =IF(J16>0,J16-D16,"")
K17: =IF(J17>0,J17-D17,"")
K18: =IF(J18>0,J18-D18,"")
K19: =IF(J19>0,J19-D19,"")
K20: =IF(J20>0,J20-D20,"")
K21: =IF(J21>0,J21-D21,"")
K22: =IF(J22>0,J22-D22,"")
K23: =IF(J23>0,J23-D23,"")
K24: =IF(J24>0,J24-D24,"")
K25: =IF(J25>0,J25-D25,"")
K26: =IF(J26>0,J26-D26,"")
K27: =IF(J27>0,J27-D27,"")
... K41: =IF(J41>0,J41-D41,"")
D42: Viso: | E42: =SUM(E2:E41) -> 118.77 | F42: =SUM(F2:F41) -> 11.52 | G42: =SUM(G2:G41) -> 118.77 | H42: =SUM(H2:H41) -> 3.35 | I42: =SUM(I2:I41) -> 0

Sheet Birelių namas II
A1: Paskola | B1: LT-424 | D1: Data | E1: Paskola | F1: Palūkanos | G1: Paskola | H1: Palūkanos | I1: Papildomos | J1: Data | K1: Vėlavimas | M1: Paskola | O1: Palūkanos | Q1: XIRR | R1: Grąžinta | S1: Vėluoja | Y1: Data | Z1: Suma | AA1: Vėluoja
A2: Objektas | B2: Birelių namas II | D2: 46112 | E2: 0 | F2: 0.23 | G2: 0 | H2: 0.23 | I2: 0 | J2: 46112 | K2: =IF(J2>0,J2-D2,"") -> 0 | M2: Suteikta | N2: Grąžinta | O2: Planuotos | P2: Realios | Y2: =B4 -> 46013 | Z2: =B11*-1 -> -10 | AA2: =IF(COUNTIFS(D:D,"<"&TODAY(),J:J,"")>0,"+","")
A3: Investicijos data | B3: 46010 | D3: 46203 | E3: 0 | F3: 0.21 | G3: 0 | H3: 0.21 | I3: 0 | J3: 46203 | K3: =IF(J3>0,J3-D3,"") -> 0 | M3: =B11 -> 10 | N3: =G42 -> 0 | O3: =F42 -> 0.84 | P3: =H42+I42 -> 0.65 | Q3: =IF(M3=N3,XIRR(Z2:Z14,Y2:Y14),"") | R3: =IF(M3=N3,B14,"") | S3: =IF(COUNTIFS(D:D,"<"&TODAY(),J:J,"")=0,"",TODAY()-_xlfn.MINIFS(D:D,D:D,"<"&TODAY(),J:J,"")) | Y3: =J2 -> 46112 | Z3: =G2+H2+I2 -> 0.23
A4: Palūkanų pradžia | B4: 46013 | D4: 46295 | E4: 0 | F4: 0.21 | G4: 0 | H4: 0.21 | I4: 0 | J4: 46295 | K4: =IF(J4>0,J4-D4,"") -> 0 | Y4: =J3 -> 46203 | Z4: =G3+H3+I3 -> 0.21
A5: Projekto reitingas | B5: B | D5: 46378 | E5: 10 | F5: 0.19 | K5: =IF(J5>0,J5-D5,"") | Y5: =J4 -> 46295 | Z5: =G4+H4+I4 -> 0.21
A6: LTV, % | B6: 0.49 | K6: =IF(J6>0,J6-D6,"") | Y6: =J5 -> 0 | Z6: =G5+H5+I5 -> 0
A7: LTV max, % | B7: 0.7 | K7: =IF(J7>0,J7-D7,"") | Y7: =J6 -> 0 | Z7: =G6+H6+I6 -> 0
A8: Investicijos laikotarpis, mėn. | B8: 12 | K8: =IF(J8>0,J8-D8,"") | Y8: =J7 -> 0 | Z8: =G7+H7+I7 -> 0
A9: Palūkanų mokėjimas | B9: Q | K9: =IF(J9>0,J9-D9,"") | Y9: =J8 -> 0 | Z9: =G8+H8+I8 -> 0
A10: Palūkanos, % | B10: 0.0825 | K10: =IF(J10>0,J10-D10,"") | Y10: =J9 -> 0 | Z10: =G9+H9+I9 -> 0
A11: Investuota, Eur | B11: 10 | K11: =IF(J11>0,J11-D11,"") | Y11: =J10 -> 0 | Z11: =G10+H10+I10 -> 0
A12: Paskolos pabaiga | B12: 46378 | K12: =IF(J12>0,J12-D12,"") | Y12: =J11 -> 0 | Z12: =G11+H11+I11 -> 0
A13: Liko dienų | B13: =IF(B11<>N3,(TODAY()-B12)*-1,"") -> 83 | K13: =IF(J13>0,J13-D13,"") | Y13: =J12 -> 0 | Z13: =G12+H12+I12 -> 0
A14: Grąžinta | K14: =IF(J14>0,J14-D14,"") | Y14: =J13 -> 0 | Z14: =G13+H13+I13 -> 0
A15: Vėlavo/Anksčiau | B15: =IF(M3=N3,B14-B12,"") | K15: =IF(J15>0,J15-D15,"")
K16: =IF(J16>0,J16-D16,"")
K17: =IF(J17>0,J17-D17,"")
K18: =IF(J18>0,J18-D18,"")
K19: =IF(J19>0,J19-D19,"")
K20: =IF(J20>0,J20-D20,"")
K21: =IF(J21>0,J21-D21,"")
K22: =IF(J22>0,J22-D22,"")
K23: =IF(J23>0,J23-D23,"")
K24: =IF(J24>0,J24-D24,"")
K25: =IF(J25>0,J25-D25,"")
K26: =IF(J26>0,J26-D26,"")
K27: =IF(J27>0,J27-D27,"")
... K41: =IF(J41>0,J41-D41,"")
D42: Viso: | E42: =SUM(E2:E41) -> 10 | F42: =SUM(F2:F41) -> 0.84 | G42: =SUM(G2:G41) -> 0 | H42: =SUM(H2:H41) -> 0.65 | I42: =SUM(I2:I41) -> 0

Sheet Sūduvos 8-2
A1: Paskola | B1: LT-418 | D1: Data | E1: Paskola | F1: Palūkanos | G1: Paskola | H1: Palūkanos | I1: Papildomos | J1: Data | K1: Vėlavimas | M1: Paskola | O1: Palūkanos | Q1: XIRR | R1: Grąžinta | S1: Vėluoja | Y1: Data | Z1: Suma | AA1: Vėluoja
A2: Objektas | B2: Sūduvos 8-2 | D2: 46112 | E2: 0 | F2: 3.02 | G2: 0 | H2: 3.02 | I2: 0 | J2: 46112 | K2: =IF(J2>0,J2-D2,"") -> 0 | M2: Suteikta | N2: Grąžinta | O2: Planuotos | P2: Realios | Y2: =B4 -> 46003 | Z2: =B11*-1 -> -106.06 | AA2: =IF(COUNTIFS(D:D,"<"&TODAY(),J:J,"")>0,"+","")
A3: Investicijos data | B3: 46003 | D3: 46203 | E3: 0 | F3: 2.52 | G3: 0 | H3: 2.52 | I3: 0 | J3: 46217 | K3: =IF(J3>0,J3-D3,"") -> 14 | M3: =B11 -> 106.06 | N3: =G42 -> 0 | O3: =F42 -> 10.16 | P3: =H42+I42 -> 5.54 | Q3: =IF(M3=N3,XIRR(Z2:Z14,Y2:Y14),"") | R3: =IF(M3=N3,B14,"") | S3: =IF(COUNTIFS(D:D,"<"&TODAY(),J:J,"")=0,"",TODAY()-_xlfn.MINIFS(D:D,D:D,"<"&TODAY(),J:J,"")) | Y3: =J2 -> 46112 | Z3: =G2+H2+I2 -> 3.02
A4: Palūkanų pradžia | B4: 46003 | D4: 46295 | E4: 0 | F4: 2.52 | K4: =IF(J4>0,J4-D4,"") | Y4: =J3 -> 46217 | Z4: =G3+H3+I3 -> 2.52
A5: Projekto reitingas | B5: C | D5: 46371 | E5: 106.06 | F5: 2.1 | K5: =IF(J5>0,J5-D5,"") | Y5: =J4 -> 0 | Z5: =G4+H4+I4 -> 0
A6: LTV, % | B6: 0.22 | K6: =IF(J6>0,J6-D6,"") | Y6: =J5 -> 0 | Z6: =G5+H5+I5 -> 0
A7: LTV max, % | B7: 0.7 | K7: =IF(J7>0,J7-D7,"") | Y7: =J6 -> 0 | Z7: =G6+H6+I6 -> 0
A8: Investicijos laikotarpis, mėn. | B8: 12 | K8: =IF(J8>0,J8-D8,"") | Y8: =J7 -> 0 | Z8: =G7+H7+I7 -> 0
A9: Palūkanų mokėjimas | B9: Q | K9: =IF(J9>0,J9-D9,"") | Y9: =J8 -> 0 | Z9: =G8+H8+I8 -> 0
A10: Palūkanos, % | B10: 0.095 | K10: =IF(J10>0,J10-D10,"") | Y10: =J9 -> 0 | Z10: =G9+H9+I9 -> 0
A11: Investuota, Eur | B11: 106.06 | K11: =IF(J11>0,J11-D11,"") | Y11: =J10 -> 0 | Z11: =G10+H10+I10 -> 0
A12: Paskolos pabaiga | B12: 46371 | K12: =IF(J12>0,J12-D12,"") | Y12: =J11 -> 0 | Z12: =G11+H11+I11 -> 0
A13: Liko dienų | B13: =IF(B11<>N3,(TODAY()-B12)*-1,"") -> 76 | K13: =IF(J13>0,J13-D13,"") | Y13: =J12 -> 0 | Z13: =G12+H12+I12 -> 0
A14: Grąžinta | K14: =IF(J14>0,J14-D14,"") | Y14: =J13 -> 0 | Z14: =G13+H13+I13 -> 0
A15: Vėlavo/Anksčiau | B15: =IF(M3=N3,B14-B12,"") | K15: =IF(J15>0,J15-D15,"")
K16: =IF(J16>0,J16-D16,"")
K17: =IF(J17>0,J17-D17,"")
K18: =IF(J18>0,J18-D18,"")
K19: =IF(J19>0,J19-D19,"")
K20: =IF(J20>0,J20-D20,"")
K21: =IF(J21>0,J21-D21,"")
K22: =IF(J22>0,J22-D22,"")
K23: =IF(J23>0,J23-D23,"")
K24: =IF(J24>0,J24-D24,"")
K25: =IF(J25>0,J25-D25,"")
K26: =IF(J26>0,J26-D26,"")
K27: =IF(J27>0,J27-D27,"")
... K41: =IF(J41>0,J41-D41,"")
D42: Viso: | E42: =SUM(E2:E41) -> 106.06 | F42: =SUM(F2:F41) -> 10.16 | G42: =SUM(G2:G41) -> 0 | H42: =SUM(H2:H41) -> 5.54 | I42: =SUM(I2:I41) -> 0

Sheet Miškininkų 30 II
A1: Paskola | B1: LT-388 | D1: Data | E1: Paskola | F1: Palūkanos | G1: Paskola | H1: Palūkanos | I1: Papildomos | J1: Data | K1: Vėlavimas | M1: Paskola | O1: Palūkanos | Q1: XIRR | R1: Grąžinta | S1: Vėluoja | Y1: Data | Z1: Suma | AA1: Vėluoja
A2: Objektas | B2: Miškininkų 30 II | D2: 46083 | E2: 0 | F2: 0.31 | G2: 0 | H2: 0.31 | I2: 0 | J2: 46083 | K2: =IF(J2>0,J2-D2,"") -> 0 | M2: Suteikta | N2: Grąžinta | O2: Planuotos | P2: Realios | Y2: =B4 -> 45967 | Z2: =B11*-1 -> -10 | AA2: =IF(COUNTIFS(D:D,"<"&TODAY(),J:J,"")>0,"+","")
A3: Investicijos data | B3: 45958 | D3: 46174 | E3: 0 | F3: 0.22 | G3: 0 | H3: 0.22 | I3: 0 | J3: 46174 | K3: =IF(J3>0,J3-D3,"") -> 0 | M3: =B11 -> 10 | N3: =G42 -> 0 | O3: =F42 -> 0.92 | P3: =H42+I42 -> 0.75 | Q3: =IF(M3=N3,XIRR(Z2:Z14,Y2:Y14),"") | R3: =IF(M3=N3,B14,"") | S3: =IF(COUNTIFS(D:D,"<"&TODAY(),J:J,"")=0,"",TODAY()-_xlfn.MINIFS(D:D,D:D,"<"&TODAY(),J:J,"")) | Y3: =J2 -> 46083 | Z3: =G2+H2+I2 -> 0.31
A4: Palūkanų pradžia | B4: 45967 | D4: 46265 | E4: 0 | F4: 0.22 | G4: 0 | H4: 0.22 | I4: 0 | J4: 46265 | K4: =IF(J4>0,J4-D4,"") -> 0 | Y4: =J3 -> 46174 | Z4: =G3+H3+I3 -> 0.22
A5: Projekto reitingas | B5: C | D5: 46332 | E5: 10 | F5: 0.17 | K5: =IF(J5>0,J5-D5,"") | Y5: =J4 -> 46265 | Z5: =G4+H4+I4 -> 0.22
A6: LTV, % | B6: 0.65 | K6: =IF(J6>0,J6-D6,"") | Y6: =J5 -> 0 | Z6: =G5+H5+I5 -> 0
A7: LTV max, % | B7: 0.7 | K7: =IF(J7>0,J7-D7,"") | Y7: =J6 -> 0 | Z7: =G6+H6+I6 -> 0
A8: Investicijos laikotarpis, mėn. | B8: 12 | K8: =IF(J8>0,J8-D8,"") | Y8: =J7 -> 0 | Z8: =G7+H7+I7 -> 0
A9: Palūkanų mokėjimas | B9: Q | K9: =IF(J9>0,J9-D9,"") | Y9: =J8 -> 0 | Z9: =G8+H8+I8 -> 0
A10: Palūkanos, % | B10: 0.09 | K10: =IF(J10>0,J10-D10,"") | Y10: =J9 -> 0 | Z10: =G9+H9+I9 -> 0
A11: Investuota, Eur | B11: 10 | K11: =IF(J11>0,J11-D11,"") | Y11: =J10 -> 0 | Z11: =G10+H10+I10 -> 0
A12: Paskolos pabaiga | B12: 46332 | K12: =IF(J12>0,J12-D12,"") | Y12: =J11 -> 0 | Z12: =G11+H11+I11 -> 0
A13: Liko dienų | B13: =IF(B11<>N3,(TODAY()-B12)*-1,"") -> 37 | K13: =IF(J13>0,J13-D13,"") | Y13: =J12 -> 0 | Z13: =G12+H12+I12 -> 0
A14: Grąžinta | K14: =IF(J14>0,J14-D14,"") | Y14: =J13 -> 0 | Z14: =G13+H13+I13 -> 0
A15: Vėlavo/Anksčiau | B15: =IF(M3=N3,B14-B12,"") | K15: =IF(J15>0,J15-D15,"")
K16: =IF(J16>0,J16-D16,"")
K17: =IF(J17>0,J17-D17,"")
K18: =IF(J18>0,J18-D18,"")
K19: =IF(J19>0,J19-D19,"")
K20: =IF(J20>0,J20-D20,"")
K21: =IF(J21>0,J21-D21,"")
K22: =IF(J22>0,J22-D22,"")
K23: =IF(J23>0,J23-D23,"")
K24: =IF(J24>0,J24-D24,"")
K25: =IF(J25>0,J25-D25,"")
K26: =IF(J26>0,J26-D26,"")
K27: =IF(J27>0,J27-D27,"")
... K41: =IF(J41>0,J41-D41,"")
D42: Viso: | E42: =SUM(E2:E41) -> 10 | F42: =SUM(F2:F41) -> 0.92 | G42: =SUM(G2:G41) -> 0 | H42: =SUM(H2:H41) -> 0.75 | I42: =SUM(I2:I41) -> 0

Sheet Pagojo 1 II
A1: Paskola | B1: LT-382 | D1: Data | E1: Paskola | F1: Palūkanos | G1: Paskola | H1: Palūkanos | I1: Papildomos | J1: Data | K1: Vėlavimas | M1: Paskola | O1: Palūkanos | Q1: XIRR | R1: Grąžinta | S1: Vėluoja | Y1: Data | Z1: Suma | AA1: Vėluoja
A2: Objektas | B2: Pagojo 1 II | D2: 46055 | E2: 0 | F2: 2.45 | G2: 0 | H2: 2.45 | I2: 0 | J2: 46055 | K2: =IF(J2>0,J2-D2,"") -> 0 | M2: Suteikta | N2: Grąžinta | O2: Planuotos | P2: Realios | Y2: =B4 -> 45951 | Z2: =B11*-1 -> -108.26 | AA2: =IF(COUNTIFS(D:D,"<"&TODAY(),J:J,"")>0,"+","")
A3: Investicijos data | B3: 45950 | D3: 46142 | E3: 0 | F3: 2.12 | G3: 0 | H3: 0 | I3: 0 | J3: 46072 | K3: =IF(J3>0,J3-D3,"") -> -70 | M3: =B11 -> 108.26 | N3: =G42 -> 108.26 | O3: =F42 -> 6.52 | P3: =H42+I42 -> 2.86 | Q3: =IF(M3=N3,XIRR(Z2:Z14,Y2:Y14),"") -> 0.082096878 | R3: =IF(M3=N3,B14,"") -> 46072 | S3: =IF(COUNTIFS(D:D,"<"&TODAY(),J:J,"")=0,"",TODAY()-_xlfn.MINIFS(D:D,D:D,"<"&TODAY(),J:J,"")) | Y3: =J2 -> 46055 | Z3: =G2+H2+I2 -> 2.45
A4: Palūkanų pradžia | B4: 45951 | D4: 46224 | E4: 108.26 | F4: 1.95 | G4: 108.26 | H4: 0.41 | I4: 0 | J4: 46072 | K4: =IF(J4>0,J4-D4,"") -> -152 | Y4: =J3 -> 46072 | Z4: =G3+H3+I3 -> 0
A5: Projekto reitingas | B5: B | K5: =IF(J5>0,J5-D5,"") | Y5: =J4 -> 46072 | Z5: =G4+H4+I4 -> 108.67
A6: LTV, % | B6: 0.41 | K6: =IF(J6>0,J6-D6,"") | Y6: =J5 -> 0 | Z6: =G5+H5+I5 -> 0
A7: LTV max, % | B7: 0.7 | K7: =IF(J7>0,J7-D7,"") | Y7: =J6 -> 0 | Z7: =G6+H6+I6 -> 0
A8: Investicijos laikotarpis, mėn. | B8: 9 | K8: =IF(J8>0,J8-D8,"") | Y8: =J7 -> 0 | Z8: =G7+H7+I7 -> 0
A9: Palūkanų mokėjimas | B9: Q | K9: =IF(J9>0,J9-D9,"") | Y9: =J8 -> 0 | Z9: =G8+H8+I8 -> 0
A10: Palūkanos, % | B10: 0.08 | K10: =IF(J10>0,J10-D10,"") | Y10: =J9 -> 0 | Z10: =G9+H9+I9 -> 0
A11: Investuota, Eur | B11: 108.26 | K11: =IF(J11>0,J11-D11,"") | Y11: =J10 -> 0 | Z11: =G10+H10+I10 -> 0
A12: Paskolos pabaiga | B12: 46224 | K12: =IF(J12>0,J12-D12,"") | Y12: =J11 -> 0 | Z12: =G11+H11+I11 -> 0
A13: Liko dienų | B13: =IF(B11<>N3,(TODAY()-B12)*-1,"") | K13: =IF(J13>0,J13-D13,"") | Y13: =J12 -> 0 | Z13: =G12+H12+I12 -> 0
A14: Grąžinta | B14: 46072 | K14: =IF(J14>0,J14-D14,"") | Y14: =J13 -> 0 | Z14: =G13+H13+I13 -> 0
A15: Vėlavo/Anksčiau | B15: =IF(M3=N3,B14-B12,"") -> -152 | K15: =IF(J15>0,J15-D15,"")
K16: =IF(J16>0,J16-D16,"")
K17: =IF(J17>0,J17-D17,"")
K18: =IF(J18>0,J18-D18,"")
K19: =IF(J19>0,J19-D19,"")
K20: =IF(J20>0,J20-D20,"")
K21: =IF(J21>0,J21-D21,"")
K22: =IF(J22>0,J22-D22,"")
K23: =IF(J23>0,J23-D23,"")
K24: =IF(J24>0,J24-D24,"")
K25: =IF(J25>0,J25-D25,"")
K26: =IF(J26>0,J26-D26,"")
K27: =IF(J27>0,J27-D27,"")
... K41: =IF(J41>0,J41-D41,"")
D42: Viso: | E42: =SUM(E2:E41) -> 108.26 | F42: =SUM(F2:F41) -> 6.52 | G42: =SUM(G2:G41) -> 108.26 | H42: =SUM(H2:H41) -> 2.86 | I42: =SUM(I2:I41) -> 0

Sheet Vienbutis Minsko 5A
A1: Paskola | B1: LT-363 | D1: Data | E1: Paskola | F1: Palūkanos | G1: Paskola | H1: Palūkanos | I1: Papildomos | J1: Data | K1: Vėlavimas | M1: Paskola | O1: Palūkanos | Q1: XIRR | R1: Grąžinta | S1: Vėluoja | Y1: Data | Z1: Suma | AA1: Vėluoja
A2: Objektas | B2: Vienbutis Minsko 5A | D2: 46022 | E2: 0 | F2: 2.66 | G2: 0 | H2: 2.66 | I2: 0 | J2: 46022 | K2: =IF(J2>0,J2-D2,"") -> 0 | M2: Suteikta | N2: Grąžinta | O2: Planuotos | P2: Realios | Y2: =B4 -> 45916 | Z2: =B11*-1 -> -101.49 | AA2: =IF(COUNTIFS(D:D,"<"&TODAY(),J:J,"")>0,"+","") -> +
A3: Investicijos data | B3: 45915 | D3: 46112 | E3: 0 | F3: 2.28 | G3: 0 | H3: 2.28 | I3: 0 | J3: 46112 | K3: =IF(J3>0,J3-D3,"") -> 0 | M3: =B11 -> 101.49 | N3: =G42 -> 0 | O3: =F42 -> 9.15 | P3: =H42+I42 -> 7.22 | Q3: =IF(M3=N3,XIRR(Z2:Z14,Y2:Y14),"") | R3: =IF(M3=N3,B14,"") | S3: =IF(COUNTIFS(D:D,"<"&TODAY(),J:J,"")=0,"",TODAY()-_xlfn.MINIFS(D:D,D:D,"<"&TODAY(),J:J,"")) -> 14 | Y3: =J2 -> 46022 | Z3: =G2+H2+I2 -> 2.66
A4: Palūkanų pradžia | B4: 45916 | D4: 46203 | E4: 0 | F4: 2.28 | G4: 0 | H4: 2.28 | I4: 0 | J4: 46203 | K4: =IF(J4>0,J4-D4,"") -> 0 | Y4: =J3 -> 46112 | Z4: =G3+H3+I3 -> 2.28
A5: Projekto reitingas | B5: C | D5: 46281 | E5: 101.49 | F5: 1.93 | K5: =IF(J5>0,J5-D5,"") | Y5: =J4 -> 46203 | Z5: =G4+H4+I4 -> 2.28
A6: LTV, % | B6: 0.56 | K6: =IF(J6>0,J6-D6,"") | Y6: =J5 -> 0 | Z6: =G5+H5+I5 -> 0
A7: LTV max, % | B7: 0.56 | K7: =IF(J7>0,J7-D7,"") | Y7: =J6 -> 0 | Z7: =G6+H6+I6 -> 0
A8: Investicijos laikotarpis, mėn. | B8: 12 | K8: =IF(J8>0,J8-D8,"") | Y8: =J7 -> 0 | Z8: =G7+H7+I7 -> 0
A9: Palūkanų mokėjimas | B9: Q | K9: =IF(J9>0,J9-D9,"") | Y9: =J8 -> 0 | Z9: =G8+H8+I8 -> 0
A10: Palūkanos, % | B10: 0.09 | K10: =IF(J10>0,J10-D10,"") | Y10: =J9 -> 0 | Z10: =G9+H9+I9 -> 0
A11: Investuota, Eur | B11: 101.49 | K11: =IF(J11>0,J11-D11,"") | Y11: =J10 -> 0 | Z11: =G10+H10+I10 -> 0
A12: Paskolos pabaiga | B12: 46281 | K12: =IF(J12>0,J12-D12,"") | Y12: =J11 -> 0 | Z12: =G11+H11+I11 -> 0
A13: Liko dienų | B13: =IF(B11<>N3,(TODAY()-B12)*-1,"") -> -14 | K13: =IF(J13>0,J13-D13,"") | Y13: =J12 -> 0 | Z13: =G12+H12+I12 -> 0
A14: Grąžinta | K14: =IF(J14>0,J14-D14,"") | Y14: =J13 -> 0 | Z14: =G13+H13+I13 -> 0
A15: Vėlavo/Anksčiau | B15: =IF(M3=N3,B14-B12,"") | K15: =IF(J15>0,J15-D15,"")
K16: =IF(J16>0,J16-D16,"")
K17: =IF(J17>0,J17-D17,"")
K18: =IF(J18>0,J18-D18,"")
K19: =IF(J19>0,J19-D19,"")
K20: =IF(J20>0,J20-D20,"")
K21: =IF(J21>0,J21-D21,"")
K22: =IF(J22>0,J22-D22,"")
K23: =IF(J23>0,J23-D23,"")
K24: =IF(J24>0,J24-D24,"")
K25: =IF(J25>0,J25-D25,"")
K26: =IF(J26>0,J26-D26,"")
K27: =IF(J27>0,J27-D27,"")
... K41: =IF(J41>0,J41-D41,"")
D42: Viso: | E42: =SUM(E2:E41) -> 101.49 | F42: =SUM(F2:F41) -> 9.15 | G42: =SUM(G2:G41) -> 0 | H42: =SUM(H2:H41) -> 7.22 | I42: =SUM(I2:I41) -> 0

Sheet Dvibutis Sodybų 12
A1: Paskola | B1: LT-364 | D1: Data | E1: Paskola | F1: Palūkanos | G1: Paskola | H1: Palūkanos | I1: Papildomos | J1: Data | K1: Vėlavimas | M1: Paskola | O1: Palūkanos | Q1: XIRR | R1: Grąžinta | S1: Vėluoja | Y1: Data | Z1: Suma | AA1: Vėluoja
A2: Objektas | B2: Dvibutis Sodybų 12 | D2: 46022 | E2: 5.55 | F2: 2.7 | G2: 5.55 | H2: 2.73 | I2: 0 | J2: 46041 | K2: =IF(J2>0,J2-D2,"") -> 19 | M2: Suteikta | N2: Grąžinta | O2: Planuotos | P2: Realios | Y2: =B4 -> 45917 | Z2: =B11*-1 -> -100 | AA2: =IF(COUNTIFS(D:D,"<"&TODAY(),J:J,"")>0,"+","")
A3: Investicijos data | B3: 45912 | D3: 46059 | E3: 48.05 | F3: 0.43 | G3: 48.05 | H3: 0.43 | I3: 0 | J3: 46059 | K3: =IF(J3>0,J3-D3,"") -> 0 | M3: =B11 -> 100 | N3: =G42 -> 100 | O3: =F42 -> 4.02 | P3: =H42+I42 -> 4.15 | Q3: =IF(M3=N3,XIRR(Z2:Z14,Y2:Y14),"") -> 0.10262772 | R3: =IF(M3=N3,B14,"") -> 46084 | S3: =IF(COUNTIFS(D:D,"<"&TODAY(),J:J,"")=0,"",TODAY()-_xlfn.MINIFS(D:D,D:D,"<"&TODAY(),J:J,"")) | Y3: =J2 -> 46041 | Z3: =G2+H2+I2 -> 8.28
A4: Palūkanų pradžia | B4: 45917 | D4: 46098 | E4: 46.4 | F4: 0.89 | G4: 46.4 | H4: 0.73 | I4: 0.26 | J4: 46084 | K4: =IF(J4>0,J4-D4,"") -> -14 | Y4: =J3 -> 46059 | Z4: =G3+H3+I3 -> 48.48
A5: Projekto reitingas | B5: C | K5: =IF(J5>0,J5-D5,"") | Y5: =J4 -> 46084 | Z5: =G4+H4+I4 -> 47.39
A6: LTV, % | B6: 0.7 | K6: =IF(J6>0,J6-D6,"") | Y6: =J5 -> 0 | Z6: =G5+H5+I5 -> 0
A7: LTV max, % | B7: 0.7 | K7: =IF(J7>0,J7-D7,"") | Y7: =J6 -> 0 | Z7: =G6+H6+I6 -> 0
