Workbook

Sheet Overview
A1: Paskola | I1: Pabaiga | M1: Grąžinta | Q1: Pinigai | U1: Grąžinta | W1: Vertė | AA1: Mokesčiai
A2: Nr. | B2: Inv. data | C2: Pavadinimas | D2: Šalis | E2: Tipas | F2: Terminas | G2: % | H2: Suma | I2: Planuojama | J2: Reali | K2: Liko | L2: Vėluoja | M2: Paskola | N2: Palūkanos | O2: Mokesčiai | Q2: Įnešta | R2: Investuota | S2: Premijos | T2: Gryni | U2: Paskola | V2: Palūkanos | W2: Viso | X2: Eur. | Y2: % | Z2: XIRR | AA2: Eur. | AC2: Vėluoja
A3: 1 | B3: ='LV0000106516'!B9 -> 45923 | C3: ='LV0000106516'!B1 -> LV0000106516 | D3: ='LV0000106516'!B2 -> Latvia | E3: ='LV0000106516'!B4 -> Notes | F3: ='LV0000106516'!B8 -> 0 m. 11 mėn. 22 d. | G3: ='LV0000106516'!B15 -> 0.13 | H3: ='LV0000106516'!B16 -> 30 | I3: ='LV0000106516'!B11 -> 46279 | J3: ='LV0000106516'!O3 -> 46280 | K3: ='LV0000106516'!B12 | L3: ='LV0000106516'!P3 | M3: ='LV0000106516'!K3 -> 30 | N3: ='LV0000106516'!L3 -> 3.87 | O3: ='LV0000106516'!M3 -> 0 | Q3: =Pinigai!I2 -> 300 | R3: =SUM(H3:H100)-U3 -> 318.58 | S3: =Pinigai!H2 -> 0.89 | T3: =W3-R3 -> 2.82 | U3: =SUM(M3:M100) -> 143.43 | V3: =SUM(N3:N100)-AA3 -> 20.51 | W3: =Q3+S3+V3 -> 321.4 | X3: =W3-Q3 -> 21.4 | Y3: =(W3-Q3)/Q3 -> 0.071333333 | Z3: =XIRR(Pinigai!K2:K200,Pinigai!A2:A200) -> 0.12656479 | AA3: =SUM(O3:O100) -> 0 | AC3: ='LV0000106516'!Z3
A4: 2 | B4: ='LV0000106920'!B9 -> 45923 | C4: ='LV0000106920'!B1 -> LV0000106920 | D4: ='LV0000106920'!B2 -> Latvia | E4: ='LV0000106920'!B4 -> Loans | F4: ='LV0000106920'!B8 -> 0 m. 11 mėn. 29 d. | G4: ='LV0000106920'!B15 -> 0.1 | H4: ='LV0000106920'!B16 -> 20 | I4: ='LV0000106920'!B11 -> 46286 | J4: ='LV0000106920'!O3 -> 46258 | K4: ='LV0000106920'!B12 | L4: ='LV0000106920'!P3 | M4: ='LV0000106920'!K3 -> 20 | N4: ='LV0000106920'!L3 -> 1.95 | O4: ='LV0000106920'!M3 -> 0 | AC4: ='LV0000106920'!Z3
A5: 3 | B5: ='LV0000107902'!B9 -> 45973 | C5: ='LV0000107902'!B1 -> LV0000107902 | D5: ='LV0000107902'!B2 -> Latvia | E5: ='LV0000107902'!B4 -> Notes | F5: ='LV0000107902'!B8 -> 0 m. 6 mėn. 15 d. | G5: ='LV0000107902'!B15 -> 0.11 | H5: ='LV0000107902'!B16 -> 30 | I5: ='LV0000107902'!B11 -> 46169 | J5: ='LV0000107902'!O3 -> 46169 | K5: ='LV0000107902'!B12 | L5: ='LV0000107902'!P3 | M5: ='LV0000107902'!K3 -> 30 | N5: ='LV0000107902'!L3 -> 1.8 | O5: ='LV0000107902'!M3 -> 0 | AC5: ='LV0000107902'!Z3
A6: 4 | B6: ='LV0000107886'!B9 -> 45973 | C6: ='LV0000107886'!B1 -> LV0000107886 | D6: ='LV0000107886'!B2 -> Latvia | E6: ='LV0000107886'!B4 -> Notes | F6: ='LV0000107886'!B8 -> 0 m. 3 mėn. 19 d. | G6: ='LV0000107886'!B15 -> 0.104 | H6: ='LV0000107886'!B16 -> 20.64 | I6: ='LV0000107886'!B11 -> 46084 | J6: ='LV0000107886'!O3 -> 46083 | K6: ='LV0000107886'!B12 | L6: ='LV0000107886'!P3 | M6: ='LV0000107886'!K3 -> 20.64 | N6: ='LV0000107886'!L3 -> 0.66 | O6: ='LV0000107886'!M3 -> 0 | AC6: ='LV0000107886'!Z3
A7: 5 | B7: ='LV0000108736'!B9 -> 46007 | C7: ='LV0000108736'!B1 -> LV0000108736 | D7: ='LV0000108736'!B2 -> Latvia | E7: ='LV0000108736'!B4 -> Notes | F7: ='LV0000108736'!B8 -> 0 m. 5 mėn. 26 d. | G7: ='LV0000108736'!B15 -> 0.11 | H7: ='LV0000108736'!B16 -> 20.99 | I7: ='LV0000108736'!B11 -> 46184 | J7: ='LV0000108736'!O3 -> 46185 | K7: ='LV0000108736'!B12 | L7: ='LV0000108736'!P3 | M7: ='LV0000108736'!K3 -> 20.99 | N7: ='LV0000108736'!L3 -> 1.14 | O7: ='LV0000108736'!M3 -> 0 | AC7: ='LV0000108736'!Z3
A8: 6 | B8: ='LV0000109064'!B9 -> 46029 | C8: ='LV0000109064'!B1 -> LV0000109064 | D8: ='LV0000109064'!B2 -> Latvia | E8: ='LV0000109064'!B4 -> Notes | F8: ='LV0000109064'!B8 -> 0 m. 11 mėn. 21 d. | G8: ='LV0000109064'!B15 -> 0.1125 | H8: ='LV0000109064'!B16 -> 21.01 | I8: ='LV0000109064'!B11 -> 46384 | J8: ='LV0000109064'!O3 | K8: ='LV0000109064'!B12 -> 89 | L8: ='LV0000109064'!P3 | M8: ='LV0000109064'!K3 -> 0 | N8: ='LV0000109064'!L3 -> 1.74 | O8: ='LV0000109064'!M3 -> 0 | AC8: ='LV0000109064'!Z3
A9: 7 | B9: ='LV0000110047'!B9 -> 46064 | C9: ='LV0000110047'!B1 -> LV0000110047 | D9: ='LV0000110047'!B2 -> Latvia | E9: ='LV0000110047'!B4 -> Loans | F9: ='LV0000110047'!B8 -> 0 m. 11 mėn. 22 d. | G9: ='LV0000110047'!B15 -> 0.105 | H9: ='LV0000110047'!B16 -> 21.43 | I9: ='LV0000110047'!B11 -> 46420 | J9: ='LV0000110047'!O3 | K9: ='LV0000110047'!B12 -> 125 | L9: ='LV0000110047'!P3 | M9: ='LV0000110047'!K3 -> 0 | N9: ='LV0000110047'!L3 -> 1.43 | O9: ='LV0000110047'!M3 -> 0 | AC9: ='LV0000110047'!Z3
A10: 8 | B10: ='LV0000110328'!B9 -> 46083 | C10: ='LV0000110328'!B1 -> LV0000110328 | D10: ='LV0000110328'!B2 -> Latvia | E10: ='LV0000110328'!B4 -> Notes | F10: ='LV0000110328'!B8 -> 0 m. 6 mėn. 6 d. | G10: ='LV0000110328'!B15 -> 0.11 | H10: ='LV0000110328'!B16 -> 21.8 | I10: ='LV0000110328'!B11 -> 46273 | J10: ='LV0000110328'!O3 -> 46273 | K10: ='LV0000110328'!B12 | L10: ='LV0000110328'!P3 | M10: ='LV0000110328'!K3 -> 21.8 | N10: ='LV0000110328'!L3 -> 1.26 | O10: ='LV0000110328'!M3 -> 0 | AC10: ='LV0000110328'!Z3
A11: 9 | B11: ='LV0000111102'!B9 -> 46128 | C11: ='LV0000111102'!B1 -> LV0000111102 | D11: ='LV0000111102'!B2 -> Latvia | E11: ='LV0000111102'!B4 -> Notes | F11: ='LV0000111102'!B8 -> 1 m. 0 mėn. 12 d. | G11: ='LV0000111102'!B15 -> 0.12 | H11: ='LV0000111102'!B16 -> 21.84 | I11: ='LV0000111102'!B11 -> 46505 | J11: ='LV0000111102'!O3 | K11: ='LV0000111102'!B12 -> 210 | L11: ='LV0000111102'!P3 | M11: ='LV0000111102'!K3 -> 0 | N11: ='LV0000111102'!L3 -> 1.2 | O11: ='LV0000111102'!M3 -> 0 | AC11: ='LV0000111102'!Z3
A12: 10 | B12: ='LV0000111060'!B9 -> 46147 | C12: ='LV0000111060'!B1 -> LV0000111060 | D12: ='LV0000111060'!B2 -> Latvia | E12: ='LV0000111060'!B4 -> Notes | F12: ='LV0000111060'!B8 -> 0 m. 8 mėn. 6 d. | G12: ='LV0000111060'!B15 -> 0.1075 | H12: ='LV0000111060'!B16 -> 21.75 | I12: ='LV0000111060'!B11 -> 46398 | J12: ='LV0000111060'!O3 | K12: ='LV0000111060'!B12 -> 103 | L12: ='LV0000111060'!P3 | M12: ='LV0000111060'!K3 -> 0 | N12: ='LV0000111060'!L3 -> 0.95 | O12: ='LV0000111060'!M3 -> 0 | AC12: ='LV0000111060'!Z3
A13: 11 | B13: ='LV0000111698'!B9 -> 46169 | C13: ='LV0000111698'!B1 -> LV0000111698 | D13: ='LV0000111698'!B2 -> Latvia | E13: ='LV0000111698'!B4 -> Notes | F13: ='LV0000111698'!B8 -> 0 m. 8 mėn. 24 d. | G13: ='LV0000111698'!B15 -> 0.1075 | H13: ='LV0000111698'!B16 -> 30.48 | I13: ='LV0000111698'!B11 -> 46438 | J13: ='LV0000111698'!O3 | K13: ='LV0000111698'!B12 -> 143 | L13: ='LV0000111698'!P3 | M13: ='LV0000111698'!K3 -> 0 | N13: ='LV0000111698'!L3 -> 1.14 | O13: ='LV0000111698'!M3 -> 0 | AC13: ='LV0000111698'!Z3
A14: 12 | B14: ='LV0000111847'!B9 -> 46186 | C14: ='LV0000111847'!B1 -> LV0000111847 | D14: ='LV0000111847'!B2 -> Latvia | E14: ='LV0000111847'!B4 -> Notes | F14: ='LV0000111847'!B8 -> 0 m. 8 mėn. 21 d. | G14: ='LV0000111847'!B15 -> 0.115 | H14: ='LV0000111847'!B16 -> 22.92 | I14: ='LV0000111847'!B11 -> 46452 | J14: ='LV0000111847'!O3 | K14: ='LV0000111847'!B12 -> 157 | L14: ='LV0000111847'!P3 | M14: ='LV0000111847'!K3 -> 0 | N14: ='LV0000111847'!L3 -> 0.78 | O14: ='LV0000111847'!M3 -> 0 | AC14: ='LV0000111847'!Z3
A15: 13 | B15: ='LV0000112340'!B9 -> 46205 | C15: ='LV0000112340'!B1 -> LV0000112340 | D15: ='LV0000112340'!B2 -> Latvia | E15: ='LV0000112340'!B4 -> Loans | F15: ='LV0000112340'!B8 -> 0 m. 11 mėn. 27 d. | G15: ='LV0000112340'!B15 -> 0.125 | H15: ='LV0000112340'!B16 -> 22.02 | I15: ='LV0000112340'!B11 -> 46567 | J15: ='LV0000112340'!O3 | K15: ='LV0000112340'!B12 -> 272 | L15: ='LV0000112340'!P3 | M15: ='LV0000112340'!K3 -> 0 | N15: ='LV0000112340'!L3 -> 0.68 | O15: ='LV0000112340'!M3 -> 0 | AC15: ='LV0000112340'!Z3
A16: 14 | B16: ='LV0000112639'!B9 -> 46217 | C16: ='LV0000112639'!B1 -> LV0000112639 | D16: ='LV0000112639'!B2 -> Latvia | E16: ='LV0000112639'!B4 -> Loans | F16: ='LV0000112639'!B8 -> 0 m. 11 mėn. 29 d. | G16: ='LV0000112639'!B15 -> 0.125 | H16: ='LV0000112639'!B16 -> 20 | I16: ='LV0000112639'!B11 -> 46581 | J16: ='LV0000112639'!O3 | K16: ='LV0000112639'!B12 -> 286 | L16: ='LV0000112639'!P3 | M16: ='LV0000112639'!K3 -> 0 | N16: ='LV0000112639'!L3 -> 0.54 | O16: ='LV0000112639'!M3 -> 0 | AC16: ='LV0000112639'!Z3
A17: 15 | B17: ='LV0000112548'!B9 -> 46237 | C17: ='LV0000112548'!B1 -> LV0000112548 | D17: ='LV0000112548'!B2 -> Latvia | E17: ='LV0000112548'!B4 -> Notes | F17: ='LV0000112548'!B8 -> 0 m. 11 mėn. 23 d. | G17: ='LV0000112548'!B15 -> 0.12 | H17: ='LV0000112548'!B16 -> 22.39 | I17: ='LV0000112548'!B11 -> 46594 | J17: ='LV0000112548'!O3 | K17: ='LV0000112548'!B12 -> 299 | L17: ='LV0000112548'!P3 | M17: ='LV0000112548'!K3 -> 0 | N17: ='LV0000112548'!L3 -> 0.43 | O17: ='LV0000112548'!M3 -> 0 | AC17: ='LV0000112548'!Z3
A18: 16 | B18: ='LV0000112365'!B9 -> 46258 | C18: ='LV0000112365'!B1 -> LV0000112365 | D18: ='LV0000112365'!B2 -> Latvia | E18: ='LV0000112365'!B4 -> Notes | F18: ='LV0000112365'!B8 -> 1 m. 4 mėn. 27 d. | G18: ='LV0000112365'!B15 -> 0.125 | H18: ='LV0000112365'!B16 -> 20.14 | I18: ='LV0000112365'!B11 -> 46772 | J18: ='LV0000112365'!O3 | K18: ='LV0000112365'!B12 -> 477 | L18: ='LV0000112365'!P3 | M18: ='LV0000112365'!K3 -> 0 | N18: ='LV0000112365'!L3 -> 0.26 | O18: ='LV0000112365'!M3 -> 0 | AC18: ='LV0000112365'!Z3
A19: 17 | B19: ='LV0000113066'!B9 -> 46267 | C19: ='LV0000113066'!B1 -> LV0000113066 | D19: ='LV0000113066'!B2 -> Latvia | E19: ='LV0000113066'!B4 -> Notes | F19: ='LV0000113066'!B8 -> 0 m. 11 mėn. 13 d. | G19: ='LV0000113066'!B15 -> 0.1 | H19: ='LV0000113066'!B16 -> 22.59 | I19: ='LV0000113066'!B11 -> 46614 | J19: ='LV0000113066'!O3 | K19: ='LV0000113066'!B12 -> 319 | L19: ='LV0000113066'!P3 | M19: ='LV0000113066'!K3 -> 0 | N19: ='LV0000113066'!L3 -> 0.19 | O19: ='LV0000113066'!M3 -> 0 | AC19: ='LV0000113066'!Z3
A20: 18 | B20: ='LV0000113389'!B9 -> 46272 | C20: ='LV0000113389'!B1 -> LV0000113389 | D20: ='LV0000113389'!B2 -> Latvia | E20: ='LV0000113389'!B4 -> Loans | F20: ='LV0000113389'!B8 -> 0 m. 11 mėn. 30 d. | G20: ='LV0000113389'!B15 -> 0.125 | H20: ='LV0000113389'!B16 -> 20 | I20: ='LV0000113389'!B11 -> 46636 | J20: ='LV0000113389'!O3 | K20: ='LV0000113389'!B12 -> 341 | L20: ='LV0000113389'!P3 | M20: ='LV0000113389'!K3 -> 0 | N20: ='LV0000113389'!L3 -> 0.16 | O20: ='LV0000113389'!M3 -> 0 | AC20: ='LV0000113389'!Z3
A21: 19 | B21: ='LV0000113207'!B9 -> 46273 | C21: ='LV0000113207'!B1 -> LV0000113207 | D21: ='LV0000113207'!B2 -> Latvia | E21: ='LV0000113207'!B4 -> Notes | F21: ='LV0000113207'!B8 -> 1 m. 6 mėn. 4 d. | G21: ='LV0000113207'!B15 -> 0.125 | H21: ='LV0000113207'!B16 -> 21.85 | I21: ='LV0000113207'!B11 -> 46824 | J21: ='LV0000113207'!O3 | K21: ='LV0000113207'!B12 -> 529 | L21: ='LV0000113207'!P3 | M21: ='LV0000113207'!K3 -> 0 | N21: ='LV0000113207'!L3 -> 0.17 | O21: ='LV0000113207'!M3 -> 0 | AC21: ='LV0000113207'!Z3
A22: 20 | B22: ='LV0000113298'!B9 -> 46280 | C22: ='LV0000113298'!B1 -> LV0000113298 | D22: ='LV0000113298'!B2 -> Latvia | E22: ='LV0000113298'!B4 -> Notes | F22: ='LV0000113298'!B8 -> 0 m. 11 mėn. 17 d. | G22: ='LV0000113298'!B15 -> 0.12 | H22: ='LV0000113298'!B16 -> 30.16 | I22: ='LV0000113298'!B11 -> 46631 | J22: ='LV0000113298'!O3 | K22: ='LV0000113298'!B12 -> 336 | L22: ='LV0000113298'!P3 | M22: ='LV0000113298'!K3 -> 0 | N22: ='LV0000113298'!L3 -> 0.16 | O22: ='LV0000113298'!M3 -> 0 | AC22: ='LV0000113298'!Z3

Sheet Pinigai
A1: Data | B1: Įnešta | C1: Išimta | D1: Premija | F1: Įnešta | G1: Išimta | H1: Premija | I1: Skirtumas | K1: XIRR
A2: 45922 | B2: 50 | C2: 0 | D2: 0 | F2: =SUM(B2:B35) -> 300 | G2: =SUM(C2:C35) -> 0 | H2: =SUM(D2:D35) -> 0.89 | I2: =F2-G2 -> 300 | K2: =B2*-1 -> -50
A3: 45972 | B3: 50 | C3: 0 | D3: 0 | K3: =B3*-1 -> -50
A4: 46006 | B4: 20 | C4: 0 | D4: 0 | K4: =B4*-1 -> -20
A5: 46024 | B5: 20 | C5: 0 | D5: 0 | K5: =B5*-1 -> -20
A6: 46064 | B6: 20 | C6: 0 | D6: 0 | K6: =B6*-1 -> -20
A7: 46128 | B7: 20 | C7: 0 | D7: 0.34 | K7: =B7*-1 -> -20
A8: 46144 | B8: 20 | C8: 0 | D8: 0 | K8: =B8*-1 -> -20
A9: 46147 | B9: 0 | C9: 0 | D9: 0.15 | K9: =B9*-1 -> 0
A10: 46169 | B10: 0 | C10: 0 | D10: 0.4 | K10: =B10*-1 -> 0
A11: 46205 | B11: 20 | C11: 0 | D11: 0 | K11: =B11*-1 -> -20
A12: 46217 | B12: 20 | C12: 0 | D12: 0 | K12: =B12*-1 -> -20
A13: 46237 | B13: 20 | C13: 0 | D13: 0 | K13: =B13*-1 -> -20
A14: 46267 | B14: 20 | C14: 0 | D14: 0 | K14: =B14*-1 -> -20
A15: 46271 | B15: 20 | C15: 0 | D15: 0 | K15: =B15*-1 -> -20
A200: =TODAY() -> 46295 | K200: =Overview!W3 -> 321.4

Sheet LV0000113298
A1: Loan ID | B1: LV0000113298 | D1: Data | G1: Paskola | K1: Grąžinimas
A2: Šalis | B2: Latvia | D2: Planuojama | E2: Reali | F2: Vėl./Anks. | G2: Principal | H2: Interest | I2: Mokestis | K2: Paskola | L2: Palūkanos | M2: Mokesčiai | N2: XIRR | O2: Data | P2: Vėluoja | Q2: Vėl./Anks. | X2: Data | Y2: Suma | Z2: Vėluoja
A3: Skolintojas | B3: Latvian Forest Developement Fund | D3: 46295 | E3: 46295 | F3: =IF(E3>0,E3-D3,"") -> 0 | G3: 0 | H3: 0.16 | I3: 0 | K3: =G53 -> 0 | L3: =H53 -> 0.16 | M3: =I53 -> 0 | N3: =IF(B16=K3,XIRR(Y3:Y52,X3:X52),"") | O3: =IF(B16=K3,MAX(E:E),"") | P3: =IF(Z3="+",TODAY()-B11,"") | Q3: =IF(B16=K3,MAX(E:E)-B11,"") | X3: =B9 -> 46280 | Y3: =B16*-1 -> -30.16 | Z3: =IF(AND(TODAY()>B11, K3<>B16), "+", "")
A4: Tipas | B4: Notes | F4: =IF(E4>0,E4-D4,"") | X4: =E3 -> 46295 | Y4: =G3+H3-I3 -> 0.16
A5: ID | B5: dd0b19ae-bdc0-4c9f-b824-99949a748bdc | F5: =IF(E5>0,E5-D5,"") | X5: =E4 -> 0 | Y5: =G4+H4-I4 -> 0
A6: Trust score | B6: A | F6: =IF(E6>0,E6-D6,"") | X6: =E5 -> 0 | Y6: =G5+H5-I5 -> 0
F7: =IF(E7>0,E7-D7,"") | X7: =E6 -> 0 | Y7: =G6+H6-I6 -> 0
A8: Terminas | B8: =DATEDIF(B9,B11,"y") & " m. " & DATEDIF(B9,B11,"ym") & " mėn. " & DATEDIF(B9,B11,"md") & " d." -> 0 m. 11 mėn. 17 d. | F8: =IF(E8>0,E8-D8,"") | X8: =E7 -> 0 | Y8: =G7+H7-I7 -> 0
A9: Investuota | B9: 46280 | F9: =IF(E9>0,E9-D9,"") | X9: =E8 -> 0 | Y9: =G8+H8-I8 -> 0
A10: Pradžia | B10: 46265 | F10: =IF(E10>0,E10-D10,"") | X10: =E9 -> 0 | Y10: =G9+H9-I9 -> 0
A11: Pabaiga | B11: 46631 | F11: =IF(E11>0,E11-D11,"") | X11: =E10 -> 0 | Y11: =G10+H10-I10 -> 0
A12: Liko, dienos | B12: =IF(B16<>K3,(TODAY()-B11)*-1,"") -> 336 | F12: =IF(E12>0,E12-D12,"") | X12: =E11 -> 0 | Y12: =G11+H11-I11 -> 0
F13: =IF(E13>0,E13-D13,"") | X13: =E12 -> 0 | Y13: =G12+H12-I12 -> 0
F14: =IF(E14>0,E14-D14,"") | X14: =E13 -> 0 | Y14: =G13+H13-I13 -> 0
A15: Palūkanos | B15: 0.12 | F15: =IF(E15>0,E15-D15,"") | X15: =E14 -> 0 | Y15: =G14+H14-I14 -> 0
A16: Investuota, Eur | B16: 30.16 | F16: =IF(E16>0,E16-D16,"") | X16: =E15 -> 0 | Y16: =G15+H15-I15 -> 0
F17: =IF(E17>0,E17-D17,"") | X17: =E16 -> 0 | Y17: =G16+H16-I16 -> 0
F18: =IF(E18>0,E18-D18,"") | X18: =E17 -> 0 | Y18: =G17+H17-I17 -> 0
F19: =IF(E19>0,E19-D19,"") | X19: =E18 -> 0 | Y19: =G18+H18-I18 -> 0
F20: =IF(E20>0,E20-D20,"") | X20: =E19 -> 0 | Y20: =G19+H19-I19 -> 0
F21: =IF(E21>0,E21-D21,"") | X21: =E20 -> 0 | Y21: =G20+H20-I20 -> 0
F22: =IF(E22>0,E22-D22,"") | X22: =E21 -> 0 | Y22: =G21+H21-I21 -> 0
F23: =IF(E23>0,E23-D23,"") | X23: =E22 -> 0 | Y23: =G22+H22-I22 -> 0
F24: =IF(E24>0,E24-D24,"") | X24: =E23 -> 0 | Y24: =G23+H23-I23 -> 0
F25: =IF(E25>0,E25-D25,"") | X25: =E24 -> 0 | Y25: =G24+H24-I24 -> 0
F26: =IF(E26>0,E26-D26,"") | X26: =E25 -> 0 | Y26: =G25+H25-I25 -> 0
F27: =IF(E27>0,E27-D27,"") | X27: =E26 -> 0 | Y27: =G26+H26-I26 -> 0
F28: =IF(E28>0,E28-D28,"") | X28: =E27 -> 0 | Y28: =G27+H27-I27 -> 0
... F52: =IF(E52>0,E52-D52,"") | X52: =E51 -> 0 | Y52: =G51+H51-I51 -> 0
D53: Viso: | G53: =SUM(G3:G52) -> 0 | H53: =SUM(H3:H52) -> 0.16 | I53: =SUM(I3:I52) -> 0

Sheet LV0000113207
A1: Loan ID | B1: LV0000113207 | D1: Data | G1: Paskola | K1: Grąžinimas
A2: Šalis | B2: Latvia | D2: Planuojama | E2: Reali | F2: Vėl./Anks. | G2: Principal | H2: Interest | I2: Mokestis | K2: Paskola | L2: Palūkanos | M2: Mokesčiai | N2: XIRR | O2: Data | P2: Vėluoja | Q2: Vėl./Anks. | X2: Data | Y2: Suma | Z2: Vėluoja
A3: Skolintojas | B3: Baltic Terra | D3: 46295 | E3: 46295 | F3: =IF(E3>0,E3-D3,"") -> 0 | G3: 0 | H3: 0.17 | I3: 0 | K3: =G53 -> 0 | L3: =H53 -> 0.17 | M3: =I53 -> 0 | N3: =IF(B16=K3,XIRR(Y3:Y52,X3:X52),"") | O3: =IF(B16=K3,MAX(E:E),"") | P3: =IF(Z3="+",TODAY()-B11,"") | Q3: =IF(B16=K3,MAX(E:E)-B11,"") | X3: =B9 -> 46273 | Y3: =B16*-1 -> -21.85 | Z3: =IF(AND(TODAY()>B11, K3<>B16), "+", "")
A4: Tipas | B4: Notes | F4: =IF(E4>0,E4-D4,"") | X4: =E3 -> 46295 | Y4: =G3+H3-I3 -> 0.17
A5: ID | B5: 6ffc241c-4674-470d-9bcc-1d396527f990 | F5: =IF(E5>0,E5-D5,"") | X5: =E4 -> 0 | Y5: =G4+H4-I4 -> 0
A6: Trust score | B6: A | F6: =IF(E6>0,E6-D6,"") | X6: =E5 -> 0 | Y6: =G5+H5-I5 -> 0
F7: =IF(E7>0,E7-D7,"") | X7: =E6 -> 0 | Y7: =G6+H6-I6 -> 0
A8: Terminas | B8: =DATEDIF(B9,B11,"y") & " m. " & DATEDIF(B9,B11,"ym") & " mėn. " & DATEDIF(B9,B11,"md") & " d." -> 1 m. 6 mėn. 4 d. | F8: =IF(E8>0,E8-D8,"") | X8: =E7 -> 0 | Y8: =G7+H7-I7 -> 0
A9: Investuota | B9: 46273 | F9: =IF(E9>0,E9-D9,"") | X9: =E8 -> 0 | Y9: =G8+H8-I8 -> 0
A10: Pradžia | B10: 46261 | F10: =IF(E10>0,E10-D10,"") | X10: =E9 -> 0 | Y10: =G9+H9-I9 -> 0
A11: Pabaiga | B11: 46824 | F11: =IF(E11>0,E11-D11,"") | X11: =E10 -> 0 | Y11: =G10+H10-I10 -> 0
A12: Liko, dienos | B12: =IF(B16<>K3,(TODAY()-B11)*-1,"") -> 529 | F12: =IF(E12>0,E12-D12,"") | X12: =E11 -> 0 | Y12: =G11+H11-I11 -> 0
F13: =IF(E13>0,E13-D13,"") | X13: =E12 -> 0 | Y13: =G12+H12-I12 -> 0
F14: =IF(E14>0,E14-D14,"") | X14: =E13 -> 0 | Y14: =G13+H13-I13 -> 0
A15: Palūkanos | B15: 0.125 | F15: =IF(E15>0,E15-D15,"") | X15: =E14 -> 0 | Y15: =G14+H14-I14 -> 0
A16: Investuota, Eur | B16: 21.85 | F16: =IF(E16>0,E16-D16,"") | X16: =E15 -> 0 | Y16: =G15+H15-I15 -> 0
F17: =IF(E17>0,E17-D17,"") | X17: =E16 -> 0 | Y17: =G16+H16-I16 -> 0
F18: =IF(E18>0,E18-D18,"") | X18: =E17 -> 0 | Y18: =G17+H17-I17 -> 0
F19: =IF(E19>0,E19-D19,"") | X19: =E18 -> 0 | Y19: =G18+H18-I18 -> 0
F20: =IF(E20>0,E20-D20,"") | X20: =E19 -> 0 | Y20: =G19+H19-I19 -> 0
F21: =IF(E21>0,E21-D21,"") | X21: =E20 -> 0 | Y21: =G20+H20-I20 -> 0
F22: =IF(E22>0,E22-D22,"") | X22: =E21 -> 0 | Y22: =G21+H21-I21 -> 0
F23: =IF(E23>0,E23-D23,"") | X23: =E22 -> 0 | Y23: =G22+H22-I22 -> 0
F24: =IF(E24>0,E24-D24,"") | X24: =E23 -> 0 | Y24: =G23+H23-I23 -> 0
F25: =IF(E25>0,E25-D25,"") | X25: =E24 -> 0 | Y25: =G24+H24-I24 -> 0
F26: =IF(E26>0,E26-D26,"") | X26: =E25 -> 0 | Y26: =G25+H25-I25 -> 0
F27: =IF(E27>0,E27-D27,"") | X27: =E26 -> 0 | Y27: =G26+H26-I26 -> 0
F28: =IF(E28>0,E28-D28,"") | X28: =E27 -> 0 | Y28: =G27+H27-I27 -> 0
... F52: =IF(E52>0,E52-D52,"") | X52: =E51 -> 0 | Y52: =G51+H51-I51 -> 0
D53: Viso: | G53: =SUM(G3:G52) -> 0 | H53: =SUM(H3:H52) -> 0.17 | I53: =SUM(I3:I52) -> 0

Sheet LV0000113389
A1: Loan ID | B1: LV0000113389 | D1: Data | G1: Paskola | K1: Grąžinimas
A2: Šalis | B2: Latvia | D2: Planuojama | E2: Reali | F2: Vėl./Anks. | G2: Principal | H2: Interest | I2: Mokestis | K2: Paskola | L2: Palūkanos | M2: Mokesčiai | N2: XIRR | O2: Data | P2: Vėluoja | Q2: Vėl./Anks. | X2: Data | Y2: Suma | Z2: Vėluoja
A3: Skolintojas | B3: Sandbox Funding | D3: 46295 | E3: 46295 | F3: =IF(E3>0,E3-D3,"") -> 0 | G3: 0 | H3: 0.16 | I3: 0 | K3: =G53 -> 0 | L3: =H53 -> 0.16 | M3: =I53 -> 0 | N3: =IF(B16=K3,XIRR(Y3:Y52,X3:X52),"") | O3: =IF(B16=K3,MAX(E:E),"") | P3: =IF(Z3="+",TODAY()-B11,"") | Q3: =IF(B16=K3,MAX(E:E)-B11,"") | X3: =B9 -> 46272 | Y3: =B16*-1 -> -20 | Z3: =IF(AND(TODAY()>B11, K3<>B16), "+", "")
A4: Tipas | B4: Loans | F4: =IF(E4>0,E4-D4,"") | X4: =E3 -> 46295 | Y4: =G3+H3-I3 -> 0.16
A5: ID | B5: 9e874a76-f3bf-42c5-9a2b-1450e0af9ae3 | F5: =IF(E5>0,E5-D5,"") | X5: =E4 -> 0 | Y5: =G4+H4-I4 -> 0
A6: Trust score | B6: B+ | F6: =IF(E6>0,E6-D6,"") | X6: =E5 -> 0 | Y6: =G5+H5-I5 -> 0
F7: =IF(E7>0,E7-D7,"") | X7: =E6 -> 0 | Y7: =G6+H6-I6 -> 0
A8: Terminas | B8: =DATEDIF(B9,B11,"y") & " m. " & DATEDIF(B9,B11,"ym") & " mėn. " & DATEDIF(B9,B11,"md") & " d." -> 0 m. 11 mėn. 30 d. | F8: =IF(E8>0,E8-D8,"") | X8: =E7 -> 0 | Y8: =G7+H7-I7 -> 0
A9: Investuota | B9: 46272 | F9: =IF(E9>0,E9-D9,"") | X9: =E8 -> 0 | Y9: =G8+H8-I8 -> 0
A10: Pradžia | B10: 46269 | F10: =IF(E10>0,E10-D10,"") | X10: =E9 -> 0 | Y10: =G9+H9-I9 -> 0
A11: Pabaiga | B11: 46636 | F11: =IF(E11>0,E11-D11,"") | X11: =E10 -> 0 | Y11: =G10+H10-I10 -> 0
A12: Liko, dienos | B12: =IF(B16<>K3,(TODAY()-B11)*-1,"") -> 341 | F12: =IF(E12>0,E12-D12,"") | X12: =E11 -> 0 | Y12: =G11+H11-I11 -> 0
F13: =IF(E13>0,E13-D13,"") | X13: =E12 -> 0 | Y13: =G12+H12-I12 -> 0
F14: =IF(E14>0,E14-D14,"") | X14: =E13 -> 0 | Y14: =G13+H13-I13 -> 0
A15: Palūkanos | B15: 0.125 | F15: =IF(E15>0,E15-D15,"") | X15: =E14 -> 0 | Y15: =G14+H14-I14 -> 0
A16: Investuota, Eur | B16: 20 | F16: =IF(E16>0,E16-D16,"") | X16: =E15 -> 0 | Y16: =G15+H15-I15 -> 0
F17: =IF(E17>0,E17-D17,"") | X17: =E16 -> 0 | Y17: =G16+H16-I16 -> 0
F18: =IF(E18>0,E18-D18,"") | X18: =E17 -> 0 | Y18: =G17+H17-I17 -> 0
F19: =IF(E19>0,E19-D19,"") | X19: =E18 -> 0 | Y19: =G18+H18-I18 -> 0
F20: =IF(E20>0,E20-D20,"") | X20: =E19 -> 0 | Y20: =G19+H19-I19 -> 0
F21: =IF(E21>0,E21-D21,"") | X21: =E20 -> 0 | Y21: =G20+H20-I20 -> 0
F22: =IF(E22>0,E22-D22,"") | X22: =E21 -> 0 | Y22: =G21+H21-I21 -> 0
F23: =IF(E23>0,E23-D23,"") | X23: =E22 -> 0 | Y23: =G22+H22-I22 -> 0
F24: =IF(E24>0,E24-D24,"") | X24: =E23 -> 0 | Y24: =G23+H23-I23 -> 0
F25: =IF(E25>0,E25-D25,"") | X25: =E24 -> 0 | Y25: =G24+H24-I24 -> 0
F26: =IF(E26>0,E26-D26,"") | X26: =E25 -> 0 | Y26: =G25+H25-I25 -> 0
F27: =IF(E27>0,E27-D27,"") | X27: =E26 -> 0 | Y27: =G26+H26-I26 -> 0
F28: =IF(E28>0,E28-D28,"") | X28: =E27 -> 0 | Y28: =G27+H27-I27 -> 0
... F52: =IF(E52>0,E52-D52,"") | X52: =E51 -> 0 | Y52: =G51+H51-I51 -> 0
D53: Viso: | G53: =SUM(G3:G52) -> 0 | H53: =SUM(H3:H52) -> 0.16 | I53: =SUM(I3:I52) -> 0

Sheet LV0000113066
A1: Loan ID | B1: LV0000113066 | D1: Data | G1: Paskola | K1: Grąžinimas
A2: Šalis | B2: Latvia | D2: Planuojama | E2: Reali | F2: Vėl./Anks. | G2: Principal | H2: Interest | I2: Mokestis | K2: Paskola | L2: Palūkanos | M2: Mokesčiai | N2: XIRR | O2: Data | P2: Vėluoja | Q2: Vėl./Anks. | X2: Data | Y2: Suma | Z2: Vėluoja
A3: Skolintojas | B3: Latvian Forest Developement Fund II | D3: 2026.09.30 | E3: 46295 | F3: =IF(E3>0,E3-D3,"") -> 0 | G3: 0 | H3: 0.19 | I3: 0 | K3: =G53 -> 0 | L3: =H53 -> 0.19 | M3: =I53 -> 0 | N3: =IF(B16=K3,XIRR(Y3:Y52,X3:X52),"") | O3: =IF(B16=K3,MAX(E:E),"") | P3: =IF(Z3="+",TODAY()-B11,"") | Q3: =IF(B16=K3,MAX(E:E)-B11,"") | X3: =B9 -> 46267 | Y3: =B16*-1 -> -22.59 | Z3: =IF(AND(TODAY()>B11, K3<>B16), "+", "")
A4: Tipas | B4: Notes | F4: =IF(E4>0,E4-D4,"") | X4: =E3 -> 46295 | Y4: =G3+H3-I3 -> 0.19
A5: ID | B5: 75ded71b-70d3-480f-b30e-fc40bee751fa | F5: =IF(E5>0,E5-D5,"") | X5: =E4 -> 0 | Y5: =G4+H4-I4 -> 0
A6: Trust score | B6: B | F6: =IF(E6>0,E6-D6,"") | X6: =E5 -> 0 | Y6: =G5+H5-I5 -> 0
F7: =IF(E7>0,E7-D7,"") | X7: =E6 -> 0 | Y7: =G6+H6-I6 -> 0
A8: Terminas | B8: =DATEDIF(B9,B11,"y") & " m. " & DATEDIF(B9,B11,"ym") & " mėn. " & DATEDIF(B9,B11,"md") & " d." -> 0 m. 11 mėn. 13 d. | F8: =IF(E8>0,E8-D8,"") | X8: =E7 -> 0 | Y8: =G7+H7-I7 -> 0
A9: Investuota | B9: 46267 | F9: =IF(E9>0,E9-D9,"") | X9: =E8 -> 0 | Y9: =G8+H8-I8 -> 0
A10: Pradžia | B10: 46246 | F10: =IF(E10>0,E10-D10,"") | X10: =E9 -> 0 | Y10: =G9+H9-I9 -> 0
A11: Pabaiga | B11: 46614 | F11: =IF(E11>0,E11-D11,"") | X11: =E10 -> 0 | Y11: =G10+H10-I10 -> 0
A12: Liko, dienos | B12: =IF(B16<>K3,(TODAY()-B11)*-1,"") -> 319 | F12: =IF(E12>0,E12-D12,"") | X12: =E11 -> 0 | Y12: =G11+H11-I11 -> 0
F13: =IF(E13>0,E13-D13,"") | X13: =E12 -> 0 | Y13: =G12+H12-I12 -> 0
F14: =IF(E14>0,E14-D14,"") | X14: =E13 -> 0 | Y14: =G13+H13-I13 -> 0
A15: Palūkanos | B15: 0.1 | F15: =IF(E15>0,E15-D15,"") | X15: =E14 -> 0 | Y15: =G14+H14-I14 -> 0
A16: Investuota, Eur | B16: 22.59 | F16: =IF(E16>0,E16-D16,"") | X16: =E15 -> 0 | Y16: =G15+H15-I15 -> 0
F17: =IF(E17>0,E17-D17,"") | X17: =E16 -> 0 | Y17: =G16+H16-I16 -> 0
F18: =IF(E18>0,E18-D18,"") | X18: =E17 -> 0 | Y18: =G17+H17-I17 -> 0
F19: =IF(E19>0,E19-D19,"") | X19: =E18 -> 0 | Y19: =G18+H18-I18 -> 0
F20: =IF(E20>0,E20-D20,"") | X20: =E19 -> 0 | Y20: =G19+H19-I19 -> 0
F21: =IF(E21>0,E21-D21,"") | X21: =E20 -> 0 | Y21: =G20+H20-I20 -> 0
F22: =IF(E22>0,E22-D22,"") | X22: =E21 -> 0 | Y22: =G21+H21-I21 -> 0
F23: =IF(E23>0,E23-D23,"") | X23: =E22 -> 0 | Y23: =G22+H22-I22 -> 0
F24: =IF(E24>0,E24-D24,"") | X24: =E23 -> 0 | Y24: =G23+H23-I23 -> 0
F25: =IF(E25>0,E25-D25,"") | X25: =E24 -> 0 | Y25: =G24+H24-I24 -> 0
F26: =IF(E26>0,E26-D26,"") | X26: =E25 -> 0 | Y26: =G25+H25-I25 -> 0
F27: =IF(E27>0,E27-D27,"") | X27: =E26 -> 0 | Y27: =G26+H26-I26 -> 0
F28: =IF(E28>0,E28-D28,"") | X28: =E27 -> 0 | Y28: =G27+H27-I27 -> 0
... F52: =IF(E52>0,E52-D52,"") | X52: =E51 -> 0 | Y52: =G51+H51-I51 -> 0
D53: Viso: | G53: =SUM(G3:G52) -> 0 | H53: =SUM(H3:H52) -> 0.19 | I53: =SUM(I3:I52) -> 0

Sheet LV0000112365
A1: Loan ID | B1: LV0000112365 | D1: Data | G1: Paskola | K1: Grąžinimas
A2: Šalis | B2: Latvia | D2: Planuojama | E2: Reali | F2: Vėl./Anks. | G2: Principal | H2: Interest | I2: Mokestis | K2: Paskola | L2: Palūkanos | M2: Mokesčiai | N2: XIRR | O2: Data | P2: Vėluoja | Q2: Vėl./Anks. | X2: Data | Y2: Suma | Z2: Vėluoja
A3: Skolintojas | B3: Latvian Forest Developement Fund | D3: 46265 | E3: 46265 | F3: =IF(E3>0,E3-D3,"") -> 0 | G3: 0 | H3: 0.04 | I3: 0 | K3: =G53 -> 0 | L3: =H53 -> 0.26 | M3: =I53 -> 0 | N3: =IF(B16=K3,XIRR(Y3:Y52,X3:X52),"") | O3: =IF(B16=K3,MAX(E:E),"") | P3: =IF(Z3="+",TODAY()-B11,"") | Q3: =IF(B16=K3,MAX(E:E)-B11,"") | X3: =B9 -> 46258 | Y3: =B16*-1 -> -20.14 | Z3: =IF(AND(TODAY()>B11, K3<>B16), "+", "")
A4: Tipas | B4: Notes | D4: 46295 | E4: 46295 | F4: =IF(E4>0,E4-D4,"") -> 0 | G4: 0 | H4: 0.22 | I4: 0 | X4: =E3 -> 46265 | Y4: =G3+H3-I3 -> 0.04
A5: ID | B5: 44050fe8-efc4-4b40-b065-7643731bd5d6 | F5: =IF(E5>0,E5-D5,"") | X5: =E4 -> 46295 | Y5: =G4+H4-I4 -> 0.22
A6: Trust score | B6: A | F6: =IF(E6>0,E6-D6,"") | X6: =E5 -> 0 | Y6: =G5+H5-I5 -> 0
F7: =IF(E7>0,E7-D7,"") | X7: =E6 -> 0 | Y7: =G6+H6-I6 -> 0
A8: Terminas | B8: =DATEDIF(B9,B11,"y") & " m. " & DATEDIF(B9,B11,"ym") & " mėn. " & DATEDIF(B9,B11,"md") & " d." -> 1 m. 4 mėn. 27 d. | F8: =IF(E8>0,E8-D8,"") | X8: =E7 -> 0 | Y8: =G7+H7-I7 -> 0
A9: Investuota | B9: 46258 | F9: =IF(E9>0,E9-D9,"") | X9: =E8 -> 0 | Y9: =G8+H8-I8 -> 0
A10: Pradžia | B10: 46205 | F10: =IF(E10>0,E10-D10,"") | X10: =E9 -> 0 | Y10: =G9+H9-I9 -> 0
A11: Pabaiga | B11: 46772 | F11: =IF(E11>0,E11-D11,"") | X11: =E10 -> 0 | Y11: =G10+H10-I10 -> 0
A12: Liko, dienos | B12: =IF(B16<>K3,(TODAY()-B11)*-1,"") -> 477 | F12: =IF(E12>0,E12-D12,"") | X12: =E11 -> 0 | Y12: =G11+H11-I11 -> 0
F13: =IF(E13>0,E13-D13,"") | X13: =E12 -> 0 | Y13: =G12+H12-I12 -> 0
F14: =IF(E14>0,E14-D14,"") | X14: =E13 -> 0 | Y14: =G13+H13-I13 -> 0
A15: Palūkanos | B15: 0.125 | F15: =IF(E15>0,E15-D15,"") | X15: =E14 -> 0 | Y15: =G14+H14-I14 -> 0
A16: Investuota, Eur | B16: 20.14 | F16: =IF(E16>0,E16-D16,"") | X16: =E15 -> 0 | Y16: =G15+H15-I15 -> 0
F17: =IF(E17>0,E17-D17,"") | X17: =E16 -> 0 | Y17: =G16+H16-I16 -> 0
F18: =IF(E18>0,E18-D18,"") | X18: =E17 -> 0 | Y18: =G17+H17-I17 -> 0
F19: =IF(E19>0,E19-D19,"") | X19: =E18 -> 0 | Y19: =G18+H18-I18 -> 0
F20: =IF(E20>0,E20-D20,"") | X20: =E19 -> 0 | Y20: =G19+H19-I19 -> 0
F21: =IF(E21>0,E21-D21,"") | X21: =E20 -> 0 | Y21: =G20+H20-I20 -> 0
F22: =IF(E22>0,E22-D22,"") | X22: =E21 -> 0 | Y22: =G21+H21-I21 -> 0
F23: =IF(E23>0,E23-D23,"") | X23: =E22 -> 0 | Y23: =G22+H22-I22 -> 0
F24: =IF(E24>0,E24-D24,"") | X24: =E23 -> 0 | Y24: =G23+H23-I23 -> 0
F25: =IF(E25>0,E25-D25,"") | X25: =E24 -> 0 | Y25: =G24+H24-I24 -> 0
F26: =IF(E26>0,E26-D26,"") | X26: =E25 -> 0 | Y26: =G25+H25-I25 -> 0
F27: =IF(E27>0,E27-D27,"") | X27: =E26 -> 0 | Y27: =G26+H26-I26 -> 0
F28: =IF(E28>0,E28-D28,"") | X28: =E27 -> 0 | Y28: =G27+H27-I27 -> 0
... F52: =IF(E52>0,E52-D52,"") | X52: =E51 -> 0 | Y52: =G51+H51-I51 -> 0
D53: Viso: | G53: =SUM(G3:G52) -> 0 | H53: =SUM(H3:H52) -> 0.26 | I53: =SUM(I3:I52) -> 0

Sheet LV0000112548
A1: Loan ID | B1: LV0000112548 | D1: Data | G1: Paskola | K1: Grąžinimas
A2: Šalis | B2: Latvia | D2: Planuojama | E2: Reali | F2: Vėl./Anks. | G2: Principal | H2: Interest | I2: Mokestis | K2: Paskola | L2: Palūkanos | M2: Mokesčiai | N2: XIRR | O2: Data | P2: Vėluoja | Q2: Vėl./Anks. | X2: Data | Y2: Suma | Z2: Vėluoja
A3: Skolintojas | B3: Latvian Forest Developement Fund | D3: 46265 | E3: 46265 | F3: =IF(E3>0,E3-D3,"") -> 0 | G3: 0 | H3: 0.2 | I3: 0 | K3: =G53 -> 0 | L3: =H53 -> 0.43 | M3: =I53 -> 0 | N3: =IF(B16=K3,XIRR(Y3:Y52,X3:X52),"") | O3: =IF(B16=K3,MAX(E:E),"") | P3: =IF(Z3="+",TODAY()-B11,"") | Q3: =IF(B16=K3,MAX(E:E)-B11,"") | X3: =B9 -> 46237 | Y3: =B16*-1 -> -22.39 | Z3: =IF(AND(TODAY()>B11, K3<>B16), "+", "")
A4: Tipas | B4: Notes | D4: 46295 | E4: 46295 | F4: =IF(E4>0,E4-D4,"") -> 0 | G4: 0 | H4: 0.23 | I4: 0 | X4: =E3 -> 46265 | Y4: =G3+H3-I3 -> 0.2
A5: ID | B5: bdb3036f-f951-45a6-b18b-b9271bd2431c | F5: =IF(E5>0,E5-D5,"") | X5: =E4 -> 46295 | Y5: =G4+H4-I4 -> 0.23
A6: Trust score | B6: A | F6: =IF(E6>0,E6-D6,"") | X6: =E5 -> 0 | Y6: =G5+H5-I5 -> 0
F7: =IF(E7>0,E7-D7,"") | X7: =E6 -> 0 | Y7: =G6+H6-I6 -> 0
A8: Terminas | B8: =DATEDIF(B9,B11,"y") & " m. " & DATEDIF(B9,B11,"ym") & " mėn. " & DATEDIF(B9,B11,"md") & " d." -> 0 m. 11 mėn. 23 d. | F8: =IF(E8>0,E8-D8,"") | X8: =E7 -> 0 | Y8: =G7+H7-I7 -> 0
A9: Investuota | B9: 46237 | F9: =IF(E9>0,E9-D9,"") | X9: =E8 -> 0 | Y9: =G8+H8-I8 -> 0
A10: Pradžia | B10: 46211 | F10: =IF(E10>0,E10-D10,"") | X10: =E9 -> 0 | Y10: =G9+H9-I9 -> 0
A11: Pabaiga | B11: 46594 | F11: =IF(E11>0,E11-D11,"") | X11: =E10 -> 0 | Y11: =G10+H10-I10 -> 0
A12: Liko, dienos | B12: =IF(B16<>K3,(TODAY()-B11)*-1,"") -> 299 | F12: =IF(E12>0,E12-D12,"") | X12: =E11 -> 0 | Y12: =G11+H11-I11 -> 0
F13: =IF(E13>0,E13-D13,"") | X13: =E12 -> 0 | Y13: =G12+H12-I12 -> 0
F14: =IF(E14>0,E14-D14,"") | X14: =E13 -> 0 | Y14: =G13+H13-I13 -> 0
A15: Palūkanos | B15: 0.12 | F15: =IF(E15>0,E15-D15,"") | X15: =E14 -> 0 | Y15: =G14+H14-I14 -> 0
A16: Investuota, Eur | B16: 22.39 | F16: =IF(E16>0,E16-D16,"") | X16: =E15 -> 0 | Y16: =G15+H15-I15 -> 0
F17: =IF(E17>0,E17-D17,"") | X17: =E16 -> 0 | Y17: =G16+H16-I16 -> 0
F18: =IF(E18>0,E18-D18,"") | X18: =E17 -> 0 | Y18: =G17+H17-I17 -> 0
F19: =IF(E19>0,E19-D19,"") | X19: =E18 -> 0 | Y19: =G18+H18-I18 -> 0
F20: =IF(E20>0,E20-D20,"") | X20: =E19 -> 0 | Y20: =G19+H19-I19 -> 0
F21: =IF(E21>0,E21-D21,"") | X21: =E20 -> 0 | Y21: =G20+H20-I20 -> 0
F22: =IF(E22>0,E22-D22,"") | X22: =E21 -> 0 | Y22: =G21+H21-I21 -> 0
F23: =IF(E23>0,E23-D23,"") | X23: =E22 -> 0 | Y23: =G22+H22-I22 -> 0
F24: =IF(E24>0,E24-D24,"") | X24: =E23 -> 0 | Y24: =G23+H23-I23 -> 0
F25: =IF(E25>0,E25-D25,"") | X25: =E24 -> 0 | Y25: =G24+H24-I24 -> 0
F26: =IF(E26>0,E26-D26,"") | X26: =E25 -> 0 | Y26: =G25+H25-I25 -> 0
F27: =IF(E27>0,E27-D27,"") | X27: =E26 -> 0 | Y27: =G26+H26-I26 -> 0
F28: =IF(E28>0,E28-D28,"") | X28: =E27 -> 0 | Y28: =G27+H27-I27 -> 0
... F52: =IF(E52>0,E52-D52,"") | X52: =E51 -> 0 | Y52: =G51+H51-I51 -> 0
D53: Viso: | G53: =SUM(G3:G52) -> 0 | H53: =SUM(H3:H52) -> 0.43 | I53: =SUM(I3:I52) -> 0

Sheet LV0000112639
A1: Loan ID | B1: LV0000112639 | D1: Data | G1: Paskola | K1: Grąžinimas
A2: Šalis | B2: Latvia | D2: Planuojama | E2: Reali | F2: Vėl./Anks. | G2: Principal | H2: Interest | I2: Mokestis | K2: Paskola | L2: Palūkanos | M2: Mokesčiai | N2: XIRR | O2: Data | P2: Vėluoja | Q2: Vėl./Anks. | X2: Data | Y2: Suma | Z2: Vėluoja
A3: Skolintojas | B3: Sandbox Funding | D3: 46234 | E3: 46234 | F3: =IF(E3>0,E3-D3,"") -> 0 | G3: 0 | H3: 0.11 | I3: 0 | K3: =G53 -> 0 | L3: =H53 -> 0.54 | M3: =I53 -> 0 | N3: =IF(B16=K3,XIRR(Y3:Y52,X3:X52),"") | O3: =IF(B16=K3,MAX(E:E),"") | P3: =IF(Z3="+",TODAY()-B11,"") | Q3: =IF(B16=K3,MAX(E:E)-B11,"") | X3: =B9 -> 46217 | Y3: =B16*-1 -> -20 | Z3: =IF(AND(TODAY()>B11, K3<>B16), "+", "")
A4: Tipas | B4: Loans | D4: 46265 | E4: 46265 | F4: =IF(E4>0,E4-D4,"") -> 0 | G4: 0 | H4: 0.22 | I4: 0 | X4: =E3 -> 46234 | Y4: =G3+H3-I3 -> 0.11
A5: ID | B5: 4d675011-7d10-48f2-8b75-877c5e500aa8 | D5: 46295 | E5: 46295 | F5: =IF(E5>0,E5-D5,"") -> 0 | G5: 0 | H5: 0.21 | I5: 0 | X5: =E4 -> 46265 | Y5: =G4+H4-I4 -> 0.22
A6: Trust score | B6: B+ | F6: =IF(E6>0,E6-D6,"") | X6: =E5 -> 46295 | Y6: =G5+H5-I5 -> 0.21
F7: =IF(E7>0,E7-D7,"") | X7: =E6 -> 0 | Y7: =G6+H6-I6 -> 0
A8: Terminas | B8: =DATEDIF(B9,B11,"y") & " m. " & DATEDIF(B9,B11,"ym") & " mėn. " & DATEDIF(B9,B11,"md") & " d." -> 0 m. 11 mėn. 29 d. | F8: =IF(E8>0,E8-D8,"") | X8: =E7 -> 0 | Y8: =G7+H7-I7 -> 0
A9: Investuota | B9: 46217 | F9: =IF(E9>0,E9-D9,"") | X9: =E8 -> 0 | Y9: =G8+H8-I8 -> 0
A10: Pradžia | B10: 46214 | F10: =IF(E10>0,E10-D10,"") | X10: =E9 -> 0 | Y10: =G9+H9-I9 -> 0
A11: Pabaiga | B11: 46581 | F11: =IF(E11>0,E11-D11,"") | X11: =E10 -> 0 | Y11: =G10+H10-I10 -> 0
A12: Liko, dienos | B12: =IF(B16<>K3,(TODAY()-B11)*-1,"") -> 286 | F12: =IF(E12>0,E12-D12,"") | X12: =E11 -> 0 | Y12: =G11+H11-I11 -> 0
F13: =IF(E13>0,E13-D13,"") | X13: =E12 -> 0 | Y13: =G12+H12-I12 -> 0
F14: =IF(E14>0,E14-D14,"") | X14: =E13 -> 0 | Y14: =G13+H13-I13 -> 0
A15: Palūkanos | B15: 0.125 | F15: =IF(E15>0,E15-D15,"") | X15: =E14 -> 0 | Y15: =G14+H14-I14 -> 0
A16: Investuota, Eur | B16: 20 | F16: =IF(E16>0,E16-D16,"") | X16: =E15 -> 0 | Y16: =G15+H15-I15 -> 0
F17: =IF(E17>0,E17-D17,"") | X17: =E16 -> 0 | Y17: =G16+H16-I16 -> 0
F18: =IF(E18>0,E18-D18,"") | X18: =E17 -> 0 | Y18: =G17+H17-I17 -> 0
F19: =IF(E19>0,E19-D19,"") | X19: =E18 -> 0 | Y19: =G18+H18-I18 -> 0
F20: =IF(E20>0,E20-D20,"") | X20: =E19 -> 0 | Y20: =G19+H19-I19 -> 0
F21: =IF(E21>0,E21-D21,"") | X21: =E20 -> 0 | Y21: =G20+H20-I20 -> 0
F22: =IF(E22>0,E22-D22,"") | X22: =E21 -> 0 | Y22: =G21+H21-I21 -> 0
F23: =IF(E23>0,E23-D23,"") | X23: =E22 -> 0 | Y23: =G22+H22-I22 -> 0
F24: =IF(E24>0,E24-D24,"") | X24: =E23 -> 0 | Y24: =G23+H23-I23 -> 0
F25: =IF(E25>0,E25-D25,"") | X25: =E24 -> 0 | Y25: =G24+H24-I24 -> 0
F26: =IF(E26>0,E26-D26,"") | X26: =E25 -> 0 | Y26: =G25+H25-I25 -> 0
F27: =IF(E27>0,E27-D27,"") | X27: =E26 -> 0 | Y27: =G26+H26-I26 -> 0
F28: =IF(E28>0,E28-D28,"") | X28: =E27 -> 0 | Y28: =G27+H27-I27 -> 0
... F52: =IF(E52>0,E52-D52,"") | X52: =E51 -> 0 | Y52: =G51+H51-I51 -> 0
D53: Viso: | G53: =SUM(G3:G52) -> 0 | H53: =SUM(H3:H52) -> 0.54 | I53: =SUM(I3:I52) -> 0

Sheet LV0000112340
A1: Loan ID | B1: LV0000112340 | D1: Data | G1: Paskola | K1: Grąžinimas
A2: Šalis | B2: Latvia | D2: Planuojama | E2: Reali | F2: Vėl./Anks. | G2: Principal | H2: Interest | I2: Mokestis | K2: Paskola | L2: Palūkanos | M2: Mokesčiai | N2: XIRR | O2: Data | P2: Vėluoja | Q2: Vėl./Anks. | X2: Data | Y2: Suma | Z2: Vėluoja
A3: Skolintojas | B3: Sandbox Funding | D3: 46234 | E3: 46234 | F3: =IF(E3>0,E3-D3,"") -> 0 | G3: 0 | H3: 0.22 | I3: 0 | K3: =G53 -> 0 | L3: =H53 -> 0.68 | M3: =I53 -> 0 | N3: =IF(B16=K3,XIRR(Y3:Y52,X3:X52),"") | O3: =IF(B16=K3,MAX(E:E),"") | P3: =IF(Z3="+",TODAY()-B11,"") | Q3: =IF(B16=K3,MAX(E:E)-B11,"") | X3: =B9 -> 46205 | Y3: =B16*-1 -> -22.02 | Z3: =IF(AND(TODAY()>B11, K3<>B16), "+", "")
A4: Tipas | B4: Loans | D4: 46265 | E4: 46265 | F4: =IF(E4>0,E4-D4,"") -> 0 | G4: 0 | H4: 0.23 | I4: 0 | X4: =E3 -> 46234 | Y4: =G3+H3-I3 -> 0.22
A5: ID | B5: a1bc197d-257c-4974-99fa-cdc266369d55 | D5: 46295 | E5: 46295 | F5: =IF(E5>0,E5-D5,"") -> 0 | G5: 0 | H5: 0.23 | I5: 0 | X5: =E4 -> 46265 | Y5: =G4+H4-I4 -> 0.23
A6: Trust score | B6: B+ | F6: =IF(E6>0,E6-D6,"") | X6: =E5 -> 46295 | Y6: =G5+H5-I5 -> 0.23
F7: =IF(E7>0,E7-D7,"") | X7: =E6 -> 0 | Y7: =G6+H6-I6 -> 0
A8: Terminas | B8: =DATEDIF(B9,B11,"y") & " m. " & DATEDIF(B9,B11,"ym") & " mėn. " & DATEDIF(B9,B11,"md") & " d." -> 0 m. 11 mėn. 27 d. | F8: =IF(E8>0,E8-D8,"") | X8: =E7 -> 0 | Y8: =G7+H7-I7 -> 0
A9: Investuota | B9: 46205 | F9: =IF(E9>0,E9-D9,"") | X9: =E8 -> 0 | Y9: =G8+H8-I8 -> 0
A10: Pradžia | B10: 46203 | F10: =IF(E10>0,E10-D10,"") | X10: =E9 -> 0 | Y10: =G9+H9-I9 -> 0
A11: Pabaiga | B11: 46567 | F11: =IF(E11>0,E11-D11,"") | X11: =E10 -> 0 | Y11: =G10+H10-I10 -> 0
A12: Liko, dienos | B12: =IF(B16<>K3,(TODAY()-B11)*-1,"") -> 272 | F12: =IF(E12>0,E12-D12,"") | X12: =E11 -> 0 | Y12: =G11+H11-I11 -> 0
F13: =IF(E13>0,E13-D13,"") | X13: =E12 -> 0 | Y13: =G12+H12-I12 -> 0
F14: =IF(E14>0,E14-D14,"") | X14: =E13 -> 0 | Y14: =G13+H13-I13 -> 0
A15: Palūkanos | B15: 0.125 | F15: =IF(E15>0,E15-D15,"") | X15: =E14 -> 0 | Y15: =G14+H14-I14 -> 0
A16: Investuota, Eur | B16: 22.02 | F16: =IF(E16>0,E16-D16,"") | X16: =E15 -> 0 | Y16: =G15+H15-I15 -> 0
F17: =IF(E17>0,E17-D17,"") | X17: =E16 -> 0 | Y17: =G16+H16-I16 -> 0
F18: =IF(E18>0,E18-D18,"") | X18: =E17 -> 0 | Y18: =G17+H17-I17 -> 0
F19: =IF(E19>0,E19-D19,"") | X19: =E18 -> 0 | Y19: =G18+H18-I18 -> 0
F20: =IF(E20>0,E20-D20,"") | X20: =E19 -> 0 | Y20: =G19+H19-I19 -> 0
F21: =IF(E21>0,E21-D21,"") | X21: =E20 -> 0 | Y21: =G20+H20-I20 -> 0
F22: =IF(E22>0,E22-D22,"") | X22: =E21 -> 0 | Y22: =G21+H21-I21 -> 0
F23: =IF(E23>0,E23-D23,"") | X23: =E22 -> 0 | Y23: =G22+H22-I22 -> 0
F24: =IF(E24>0,E24-D24,"") | X24: =E23 -> 0 | Y24: =G23+H23-I23 -> 0
F25: =IF(E25>0,E25-D25,"") | X25: =E24 -> 0 | Y25: =G24+H24-I24 -> 0
F26: =IF(E26>0,E26-D26,"") | X26: =E25 -> 0 | Y26: =G25+H25-I25 -> 0
F27: =IF(E27>0,E27-D27,"") | X27: =E26 -> 0 | Y27: =G26+H26-I26 -> 0
F28: =IF(E28>0,E28-D28,"") | X28: =E27 -> 0 | Y28: =G27+H27-I27 -> 0
... F52: =IF(E52>0,E52-D52,"") | X52: =E51 -> 0 | Y52: =G51+H51-I51 -> 0
D53: Viso: | G53: =SUM(G3:G52) -> 0 | H53: =SUM(H3:H52) -> 0.68 | I53: =SUM(I3:I52) -> 0

Sheet LV0000111847
A1: Loan ID | B1: LV0000111847 | D1: Data | G1: Paskola | K1: Grąžinimas
A2: Šalis | B2: Latvia | D2: Planuojama | E2: Reali | F2: Vėl./Anks. | G2: Principal | H2: Interest | I2: Mokestis | K2: Paskola | L2: Palūkanos | M2: Mokesčiai | N2: XIRR | O2: Data | P2: Vėluoja | Q2: Vėl./Anks. | X2: Data | Y2: Suma | Z2: Vėluoja
A3: Skolintojas | B3: Latvian Forest Developement Fund | D3: 46203 | E3: 46203 | F3: =IF(E3>0,E3-D3,"") -> 0 | G3: 0 | H3: 0.13 | I3: 0 | K3: =G53 -> 0 | L3: =H53 -> 0.78 | M3: =I53 -> 0 | N3: =IF(B16=K3,XIRR(Y3:Y52,X3:X52),"") | O3: =IF(B16=K3,MAX(E:E),"") | P3: =IF(Z3="+",TODAY()-B11,"") | Q3: =IF(B16=K3,MAX(E:E)-B11,"") | X3: =B9 -> 46186 | Y3: =B16*-1 -> -22.92 | Z3: =IF(AND(TODAY()>B11, K3<>B16), "+", "")
A4: Tipas | B4: Notes | D4: 46234 | E4: 46234 | F4: =IF(E4>0,E4-D4,"") -> 0 | G4: 0 | H4: 0.22 | I4: 0 | X4: =E3 -> 46203 | Y4: =G3+H3-I3 -> 0.13
A5: ID | B5: adfe9a00-ffd1-4b14-b52f-30de1ffe3b4e | D5: 46265 | E5: 46265 | F5: =IF(E5>0,E5-D5,"") -> 0 | G5: 0 | H5: 0.22 | I5: 0 | X5: =E4 -> 46234 | Y5: =G4+H4-I4 -> 0.22
A6: Trust score | B6: A | D6: 46295 | E6: 46295 | F6: =IF(E6>0,E6-D6,"") -> 0 | G6: 0 | H6: 0.21 | I6: 0 | X6: =E5 -> 46265 | Y6: =G5+H5-I5 -> 0.22
F7: =IF(E7>0,E7-D7,"") | X7: =E6 -> 46295 | Y7: =G6+H6-I6 -> 0.21
A8: Terminas | B8: =DATEDIF(B9,B11,"y") & " m. " & DATEDIF(B9,B11,"ym") & " mėn. " & DATEDIF(B9,B11,"md") & " d." -> 0 m. 8 mėn. 21 d. | F8: =IF(E8>0,E8-D8,"") | X8: =E7 -> 0 | Y8: =G7+H7-I7 -> 0
A9: Investuota | B9: 46186 | F9: =IF(E9>0,E9-D9,"") | X9: =E8 -> 0 | Y9: =G8+H8-I8 -> 0
A10: Pradžia | B10: 46170 | F10: =IF(E10>0,E10-D10,"") | X10: =E9 -> 0 | Y10: =G9+H9-I9 -> 0
A11: Pabaiga | B11: 46452 | F11: =IF(E11>0,E11-D11,"") | X11: =E10 -> 0 | Y11: =G10+H10-I10 -> 0
A12: Liko, dienos | B12: =IF(B16<>K3,(TODAY()-B11)*-1,"") -> 157 | F12: =IF(E12>0,E12-D12,"") | X12: =E11 -> 0 | Y12: =G11+H11-I11 -> 0
F13: =IF(E13>0,E13-D13,"") | X13: =E12 -> 0 | Y13: =G12+H12-I12 -> 0
F14: =IF(E14>0,E14-D14,"") | X14: =E13 -> 0 | Y14: =G13+H13-I13 -> 0
A15: Palūkanos | B15: 0.115 | F15: =IF(E15>0,E15-D15,"") | X15: =E14 -> 0 | Y15: =G14+H14-I14 -> 0
A16: Investuota, Eur | B16: 22.92 | F16: =IF(E16>0,E16-D16,"") | X16: =E15 -> 0 | Y16: =G15+H15-I15 -> 0
F17: =IF(E17>0,E17-D17,"") | X17: =E16 -> 0 | Y17: =G16+H16-I16 -> 0
F18: =IF(E18>0,E18-D18,"") | X18: =E17 -> 0 | Y18: =G17+H17-I17 -> 0
F19: =IF(E19>0,E19-D19,"") | X19: =E18 -> 0 | Y19: =G18+H18-I18 -> 0
F20: =IF(E20>0,E20-D20,"") | X20: =E19 -> 0 | Y20: =G19+H19-I19 -> 0
F21: =IF(E21>0,E21-D21,"") | X21: =E20 -> 0 | Y21: =G20+H20-I20 -> 0
F22: =IF(E22>0,E22-D22,"") | X22: =E21 -> 0 | Y22: =G21+H21-I21 -> 0
F23: =IF(E23>0,E23-D23,"") | X23: =E22 -> 0 | Y23: =G22+H22-I22 -> 0
F24: =IF(E24>0,E24-D24,"") | X24: =E23 -> 0 | Y24: =G23+H23-I23 -> 0
F25: =IF(E25>0,E25-D25,"") | X25: =E24 -> 0 | Y25: =G24+H24-I24 -> 0
F26: =IF(E26>0,E26-D26,"") | X26: =E25 -> 0 | Y26: =G25+H25-I25 -> 0
F27: =IF(E27>0,E27-D27,"") | X27: =E26 -> 0 | Y27: =G26+H26-I26 -> 0
F28: =IF(E28>0,E28-D28,"") | X28: =E27 -> 0 | Y28: =G27+H27-I27 -> 0
... F52: =IF(E52>0,E52-D52,"") | X52: =E51 -> 0 | Y52: =G51+H51-I51 -> 0
D53: Viso: | G53: =SUM(G3:G52) -> 0 | H53: =SUM(H3:H52) -> 0.78 | I53: =SUM(I3:I52) -> 0

Sheet LV0000111698
A1: Loan ID | B1: LV0000111698 | D1: Data | G1: Paskola | K1: Grąžinimas
A2: Šalis | B2: Latvia | D2: Planuojama | E2: Reali | F2: Vėl./Anks. | G2: Principal | H2: Interest | I2: Mokestis | K2: Paskola | L2: Palūkanos | M2: Mokesčiai | N2: XIRR | O2: Data | P2: Vėluoja | Q2: Vėl./Anks. | X2: Data | Y2: Suma | Z2: Vėluoja
A3: Skolintojas | B3: Baltic Terra | D3: 46171 | E3: 46171 | F3: =IF(E3>0,E3-D3,"") -> 0 | G3: 0 | H3: 0.01 | I3: 0 | K3: =G53 -> 0 | L3: =H53 -> 1.14 | M3: =I53 -> 0 | N3: =IF(B16=K3,XIRR(Y3:Y52,X3:X52),"") | O3: =IF(B16=K3,MAX(E:E),"") | P3: =IF(Z3="+",TODAY()-B11,"") | Q3: =IF(B16=K3,MAX(E:E)-B11,"") | X3: =B9 -> 46169 | Y3: =B16*-1 -> -30.48 | Z3: =IF(AND(TODAY()>B11, K3<>B16), "+", "")
A4: Tipas | B4: Notes | D4: 46203 | E4: 46203 | F4: =IF(E4>0,E4-D4,"") -> 0 | G4: 0 | H4: 0.29 | I4: 0 | X4: =E3 -> 46171 | Y4: =G3+H3-I3 -> 0.01
A5: ID | B5: d4a9dcc7-82af-408f-bedb-9203f6d11007 | D5: 46234 | E5: 46234 | F5: =IF(E5>0,E5-D5,"") -> 0 | G5: 0 | H5: 0.28 | I5: 0 | X5: =E4 -> 46203 | Y5: =G4+H4-I4 -> 0.29
A6: Trust score | B6: A | D6: 46265 | E6: 46265 | F6: =IF(E6>0,E6-D6,"") -> 0 | G6: 0 | H6: 0.29 | I6: 0 | X6: =E5 -> 46234 | Y6: =G5+H5-I5 -> 0.28
D7: 46295 | E7: 46295 | F7: =IF(E7>0,E7-D7,"") -> 0 | G7: 0 | H7: 0.27 | I7: 0 | X7: =E6 -> 46265 | Y7: =G6+H6-I6 -> 0.29
A8: Terminas | B8: =DATEDIF(B9,B11,"y") & " m. " & DATEDIF(B9,B11,"ym") & " mėn. " & DATEDIF(B9,B11,"md") & " d." -> 0 m. 8 mėn. 24 d. | F8: =IF(E8>0,E8-D8,"") | X8: =E7 -> 46295 | Y8: =G7+H7-I7 -> 0.27
A9: Investuota | B9: 46169 | F9: =IF(E9>0,E9-D9,"") | X9: =E8 -> 0 | Y9: =G8+H8-I8 -> 0
A10: Pradžia | B10: 46127 | F10: =IF(E10>0,E10-D10,"") | X10: =E9 -> 0 | Y10: =G9+H9-I9 -> 0
A11: Pabaiga | B11: 46438 | F11: =IF(E11>0,E11-D11,"") | X11: =E10 -> 0 | Y11: =G10+H10-I10 -> 0
A12: Liko, dienos | B12: =IF(B16<>K3,(TODAY()-B11)*-1,"") -> 143 | F12: =IF(E12>0,E12-D12,"") | X12: =E11 -> 0 | Y12: =G11+H11-I11 -> 0
F13: =IF(E13>0,E13-D13,"") | X13: =E12 -> 0 | Y13: =G12+H12-I12 -> 0
F14: =IF(E14>0,E14-D14,"") | X14: =E13 -> 0 | Y14: =G13+H13-I13 -> 0
A15: Palūkanos | B15: 0.1075 | F15: =IF(E15>0,E15-D15,"") | X15: =E14 -> 0 | Y15: =G14+H14-I14 -> 0
A16: Investuota, Eur | B16: 30.48 | F16: =IF(E16>0,E16-D16,"") | X16: =E15 -> 0 | Y16: =G15+H15-I15 -> 0
F17: =IF(E17>0,E17-D17,"") | X17: =E16 -> 0 | Y17: =G16+H16-I16 -> 0
F18: =IF(E18>0,E18-D18,"") | X18: =E17 -> 0 | Y18: =G17+H17-I17 -> 0
F19: =IF(E19>0,E19-D19,"") | X19: =E18 -> 0 | Y19: =G18+H18-I18 -> 0
F20: =IF(E20>0,E20-D20,"") | X20: =E19 -> 0 | Y20: =G19+H19-I19 -> 0
F21: =IF(E21>0,E21-D21,"") | X21: =E20 -> 0 | Y21: =G20+H20-I20 -> 0
F22: =IF(E22>0,E22-D22,"") | X22: =E21 -> 0 | Y22: =G21+H21-I21 -> 0
F23: =IF(E23>0,E23-D23,"") | X23: =E22 -> 0 | Y23: =G22+H22-I22 -> 0
F24: =IF(E24>0,E24-D24,"") | X24: =E23 -> 0 | Y24: =G23+H23-I23 -> 0
F25: =IF(E25>0,E25-D25,"") | X25: =E24 -> 0 | Y25: =G24+H24-I24 -> 0
F26: =IF(E26>0,E26-D26,"") | X26: =E25 -> 0 | Y26: =G25+H25-I25 -> 0
F27: =IF(E27>0,E27-D27,"") | X27: =E26 -> 0 | Y27: =G26+H26-I26 -> 0
F28: =IF(E28>0,E28-D28,"") | X28: =E27 -> 0 | Y28: =G27+H27-I27 -> 0
... F52: =IF(E52>0,E52-D52,"") | X52: =E51 -> 0 | Y52: =G51+H51-I51 -> 0
D53: Viso: | G53: =SUM(G3:G52) -> 0 | H53: =SUM(H3:H52) -> 1.14 | I53: =SUM(I3:I52) -> 0

Sheet LV0000111060
A1: Loan ID | B1: LV0000111060 | D1: Data | G1: Paskola | K1: Grąžinimas
A2: Šalis | B2: Latvia | D2: Planuojama | E2: Reali | F2: Vėl./Anks. | G2: Principal | H2: Interest | I2: Mokestis | K2: Paskola | L2: Palūkanos | M2: Mokesčiai | N2: XIRR | O2: Data | P2: Vėluoja | Q2: Vėl./Anks. | X2: Data | Y2: Suma | Z2: Vėluoja
A3: Skolintojas | B3: Baltic Terra | D3: 46171 | E3: 46171 | F3: =IF(E3>0,E3-D3,"") -> 0 | G3: 0 | H3: 0.15 | I3: 0 | K3: =G53 -> 0 | L3: =H53 -> 0.95 | M3: =I53 -> 0 | N3: =IF(B16=K3,XIRR(Y3:Y52,X3:X52),"") | O3: =IF(B16=K3,MAX(E:E),"") | P3: =IF(Z3="+",TODAY()-B11,"") | Q3: =IF(B16=K3,MAX(E:E)-B11,"") | X3: =B9 -> 46147 | Y3: =B16*-1 -> -21.75 | Z3: =IF(AND(TODAY()>B11, K3<>B16), "+", "")
A4: Tipas | B4: Notes | D4: 46203 | E4: 46203 | F4: =IF(E4>0,E4-D4,"") -> 0 | G4: 0 | H4: 0.2 | I4: 0 | X4: =E3 -> 46171 | Y4: =G3+H3-I3 -> 0.15
A5: ID | B5: 02a81318-bea5-4db2-8b3c-4d81db59fc9b | D5: 46234 | E5: 46234 | F5: =IF(E5>0,E5-D5,"") -> 0 | G5: 0 | H5: 0.2 | I5: 0 | X5: =E4 -> 46203 | Y5: =G4+H4-I4 -> 0.2
A6: Trust score | B6: A | D6: 46265 | E6: 46265 | F6: =IF(E6>0,E6-D6,"") -> 0 | G6: 0 | H6: 0.21 | I6: 0 | X6: =E5 -> 46234 | Y6: =G5+H5-I5 -> 0.2
D7: 46295 | E7: 46295 | F7: =IF(E7>0,E7-D7,"") -> 0 | G7: 0 | H7: 0.19 | I7: 0 | X7: =E6 -> 46265 | Y7: =G6+H6-I6 -> 0.21
A8: Terminas | B8: =DATEDIF(B9,B11,"y") & " m. " & DATEDIF(B9,B11,"ym") & " mėn. " & DATEDIF(B9,B11,"md") & " d." -> 0 m. 8 mėn. 6 d. | F8: =IF(E8>0,E8-D8,"") | X8: =E7 -> 46295 | Y8: =G7+H7-I7 -> 0.19
A9: Investuota | B9: 46147 | F9: =IF(E9>0,E9-D9,"") | X9: =E8 -> 0 | Y9: =G8+H8-I8 -> 0
A10: Pradžia | B10: 46120 | F10: =IF(E10>0,E10-D10,"") | X10: =E9 -> 0 | Y10: =G9+H9-I9 -> 0
A11: Pabaiga | B11: 46398 | F11: =IF(E11>0,E11-D11,"") | X11: =E10 -> 0 | Y11: =G10+H10-I10 -> 0
A12: Liko, dienos | B12: =IF(B16<>K3,(TODAY()-B11)*-1,"") -> 103 | F12: =IF(E12>0,E12-D12,"") | X12: =E11 -> 0 | Y12: =G11+H11-I11 -> 0
F13: =IF(E13>0,E13-D13,"") | X13: =E12 -> 0 | Y13: =G12+H12-I12 -> 0
F14: =IF(E14>0,E14-D14,"") | X14: =E13 -> 0 | Y14: =G13+H13-I13 -> 0
A15: Palūkanos | B15: 0.1075 | F15: =IF(E15>0,E15-D15,"") | X15: =E14 -> 0 | Y15: =G14+H14-I14 -> 0
A16: Investuota, Eur | B16: 21.75 | F16: =IF(E16>0,E16-D16,"") | X16: =E15 -> 0 | Y16: =G15+H15-I15 -> 0
F17: =IF(E17>0,E17-D17,"") | X17: =E16 -> 0 | Y17: =G16+H16-I16 -> 0
F18: =IF(E18>0,E18-D18,"") | X18: =E17 -> 0 | Y18: =G17+H17-I17 -> 0
F19: =IF(E19>0,E19-D19,"") | X19: =E18 -> 0 | Y19: =G18+H18-I18 -> 0
F20: =IF(E20>0,E20-D20,"") | X20: =E19 -> 0 | Y20: =G19+H19-I19 -> 0
F21: =IF(E21>0,E21-D21,"") | X21: =E20 -> 0 | Y21: =G20+H20-I20 -> 0
F22: =IF(E22>0,E22-D22,"") | X22: =E21 -> 0 | Y22: =G21+H21-I21 -> 0
F23: =IF(E23>0,E23-D23,"") | X23: =E22 -> 0 | Y23: =G22+H22-I22 -> 0
F24: =IF(E24>0,E24-D24,"") | X24: =E23 -> 0 | Y24: =G23+H23-I23 -> 0
F25: =IF(E25>0,E25-D25,"") | X25: =E24 -> 0 | Y25: =G24+H24-I24 -> 0
F26: =IF(E26>0,E26-D26,"") | X26: =E25 -> 0 | Y26: =G25+H25-I25 -> 0
F27: =IF(E27>0,E27-D27,"") | X27: =E26 -> 0 | Y27: =G26+H26-I26 -> 0
F28: =IF(E28>0,E28-D28,"") | X28: =E27 -> 0 | Y28: =G27+H27-I27 -> 0
... F52: =IF(E52>0,E52-D52,"") | X52: =E51 -> 0 | Y52: =G51+H51-I51 -> 0
D53: Viso: | G53: =SUM(G3:G52) -> 0 | H53: =SUM(H3:H52) -> 0.95 | I53: =SUM(I3:I52) -> 0

Sheet LV0000111102
A1: Loan ID | B1: LV0000111102 | D1: Data | G1: Paskola | K1: Grąžinimas
A2: Šalis | B2: Latvia | D2: Planuojama | E2: Reali | F2: Vėl./Anks. | G2: Principal | H2: Interest | I2: Mokestis | K2: Paskola | L2: Palūkanos | M2: Mokesčiai | N2: XIRR | O2: Data | P2: Vėluoja | Q2: Vėl./Anks. | X2: Data | Y2: Suma | Z2: Vėluoja
A3: Skolintojas | B3: Latvian Forest Developement Fund | D3: 46142 | E3: 46142 | F3: =IF(E3>0,E3-D3,"") -> 0 | G3: 0 | H3: 0.1 | I3: 0 | K3: =G53 -> 0 | L3: =H53 -> 1.2 | M3: =I53 -> 0 | N3: =IF(B16=K3,XIRR(Y3:Y52,X3:X52),"") | O3: =IF(B16=K3,MAX(E:E),"") | P3: =IF(Z3="+",TODAY()-B11,"") | Q3: =IF(B16=K3,MAX(E:E)-B11,"") | X3: =B9 -> 46128 | Y3: =B16*-1 -> -21.84 | Z3: =IF(AND(TODAY()>B11, K3<>B16), "+", "")
A4: Tipas | B4: Notes | D4: 46171 | E4: 46171 | F4: =IF(E4>0,E4-D4,"") -> 0 | G4: 0 | H4: 0.21 | I4: 0 | X4: =E3 -> 46142 | Y4: =G3+H3-I3 -> 0.1
A5: ID | B5: cf699f4c-f1b5-444f-9077-c94668c39431 | D5: 46203 | E5: 46203 | F5: =IF(E5>0,E5-D5,"") -> 0 | G5: 0 | H5: 0.23 | I5: 0 | X5: =E4 -> 46171 | Y5: =G4+H4-I4 -> 0.21
A6: Trust score | B6: A | D6: 46234 | E6: 46234 | F6: =IF(E6>0,E6-D6,"") -> 0 | G6: 0 | H6: 0.22 | I6: 0 | X6: =E5 -> 46203 | Y6: =G5+H5-I5 -> 0.23
D7: 46265 | E7: 46265 | F7: =IF(E7>0,E7-D7,"") -> 0 | G7: 0 | H7: 0.23 | I7: 0 | X7: =E6 -> 46234 | Y7: =G6+H6-I6 -> 0.22
A8: Terminas | B8: =DATEDIF(B9,B11,"y") & " m. " & DATEDIF(B9,B11,"ym") & " mėn. " & DATEDIF(B9,B11,"md") & " d." -> 1 m. 0 mėn. 12 d. | D8: 46295 | E8: 46295 | F8: =IF(E8>0,E8-D8,"") -> 0 | G8: 0 | H8: 0.21 | I8: 0 | X8: =E7 -> 46265 | Y8: =G7+H7-I7 -> 0.23
A9: Investuota | B9: 46128 | F9: =IF(E9>0,E9-D9,"") | X9: =E8 -> 46295 | Y9: =G8+H8-I8 -> 0.21
A10: Pradžia | B10: 46125 | F10: =IF(E10>0,E10-D10,"") | X10: =E9 -> 0 | Y10: =G9+H9-I9 -> 0
A11: Pabaiga | B11: 46505 | F11: =IF(E11>0,E11-D11,"") | X11: =E10 -> 0 | Y11: =G10+H10-I10 -> 0
A12: Liko, dienos | B12: =IF(B16<>K3,(TODAY()-B11)*-1,"") -> 210 | F12: =IF(E12>0,E12-D12,"") | X12: =E11 -> 0 | Y12: =G11+H11-I11 -> 0
F13: =IF(E13>0,E13-D13,"") | X13: =E12 -> 0 | Y13: =G12+H12-I12 -> 0
F14: =IF(E14>0,E14-D14,"") | X14: =E13 -> 0 | Y14: =G13+H13-I13 -> 0
A15: Palūkanos | B15: 0.12 | F15: =IF(E15>0,E15-D15,"") | X15: =E14 -> 0 | Y15: =G14+H14-I14 -> 0
A16: Investuota, Eur | B16: 21.84 | F16: =IF(E16>0,E16-D16,"") | X16: =E15 -> 0 | Y16: =G15+H15-I15 -> 0
F17: =IF(E17>0,E17-D17,"") | X17: =E16 -> 0 | Y17: =G16+H16-I16 -> 0
F18: =IF(E18>0,E18-D18,"") | X18: =E17 -> 0 | Y18: =G17+H17-I17 -> 0
F19: =IF(E19>0,E19-D19,"") | X19: =E18 -> 0 | Y19: =G18+H18-I18 -> 0
F20: =IF(E20>0,E20-D20,"") | X20: =E19 -> 0 | Y20: =G19+H19-I19 -> 0
F21: =IF(E21>0,E21-D21,"") | X21: =E20 -> 0 | Y21: =G20+H20-I20 -> 0
F22: =IF(E22>0,E22-D22,"") | X22: =E21 -> 0 | Y22: =G21+H21-I21 -> 0
F23: =IF(E23>0,E23-D23,"") | X23: =E22 -> 0 | Y23: =G22+H22-I22 -> 0
F24: =IF(E24>0,E24-D24,"") | X24: =E23 -> 0 | Y24: =G23+H23-I23 -> 0
F25: =IF(E25>0,E25-D25,"") | X25: =E24 -> 0 | Y25: =G24+H24-I24 -> 0
F26: =IF(E26>0,E26-D26,"") | X26: =E25 -> 0 | Y26: =G25+H25-I25 -> 0
F27: =IF(E27>0,E27-D27,"") | X27: =E26 -> 0 | Y27: =G26+H26-I26 -> 0
F28: =IF(E28>0,E28-D28,"") | X28: =E27 -> 0 | Y28: =G27+H27-I27 -> 0
... F52: =IF(E52>0,E52-D52,"") | X52: =E51 -> 0 | Y52: =G51+H51-I51 -> 0
D53: Viso: | G53: =SUM(G3:G52) -> 0 | H53: =SUM(H3:H52) -> 1.2 | I53: =SUM(I3:I52) -> 0

Sheet LV0000110328
A1: Loan ID | B1: LV0000110328 | D1: Data | G1: Paskola | K1: Grąžinimas
A2: Šalis | B2: Latvia | D2: Planuojama | E2: Reali | F2: Vėl./Anks. | G2: Principal | H2: Interest | I2: Mokestis | K2: Paskola | L2: Palūkanos | M2: Mokesčiai | N2: XIRR | O2: Data | P2: Vėluoja | Q2: Vėl./Anks. | X2: Data | Y2: Suma | Z2: Vėluoja
A3: Skolintojas | B3: Latvian Forest Developement Fund | D3: 46112 | E3: 46112 | F3: =IF(E3>0,E3-D3,"") -> 0 | G3: 0 | H3: 0.2 | I3: 0 | K3: =G53 -> 21.8 | L3: =H53 -> 1.26 | M3: =I53 -> 0 | N3: =IF(B16=K3,XIRR(Y3:Y52,X3:X52),"") -> 0.11689513 | O3: =IF(B16=K3,MAX(E:E),"") -> 46273 | P3: =IF(Z3="+",TODAY()-B11,"") | Q3: =IF(B16=K3,MAX(E:E)-B11,"") -> 0 | X3: =B9 -> 46083 | Y3: =B16*-1 -> -21.8 | Z3: =IF(AND(TODAY()>B11, K3<>B16), "+", "")
A4: Tipas | B4: Notes | D4: 46142 | E4: 46142 | F4: =IF(E4>0,E4-D4,"") -> 0 | G4: 0 | H4: 0.19 | I4: 0 | X4: =E3 -> 46112 | Y4: =G3+H3-I3 -> 0.2
A5: ID | B5: 392596bb-f6fe-4c38-8522-ce14eec475b6 | D5: 46171 | E5: 46171 | F5: =IF(E5>0,E5-D5,"") -> 0 | G5: 0 | H5: 0.2 | I5: 0 | X5: =E4 -> 46142 | Y5: =G4+H4-I4 -> 0.19
A6: Trust score | B6: A | D6: 46203 | E6: 46203 | F6: =IF(E6>0,E6-D6,"") -> 0 | G6: 0 | H6: 0.21 | I6: 0 | X6: =E5 -> 46171 | Y6: =G5+H5-I5 -> 0.2
D7: 46234 | E7: 46234 | F7: =IF(E7>0,E7-D7,"") -> 0 | G7: 0 | H7: 0.2 | I7: 0 | X7: =E6 -> 46203 | Y7: =G6+H6-I6 -> 0.21
A8: Terminas | B8: =DATEDIF(B9,B11,"y") & " m. " & DATEDIF(B9,B11,"ym") & " mėn. " & DATEDIF(B9,B11,"md") & " d." -> 0 m. 6 mėn. 6 d. | D8: 46265 | E8: 46265 | F8: 0 | G8: 0 | H8: 0.21 | I8: 0 | X8: =E7 -> 46234 | Y8: =G7+H7-I7 -> 0.2
A9: Investuota | B9: 46083 | D9: 46273 | E9: 46273 | F9: =IF(E9>0,E9-D9,"") -> 0 | G9: 21.8 | H9: 0.05 | I9: 0 | X9: =E8 -> 46265 | Y9: =G8+H8-I8 -> 0.21
A10: Pradžia | B10: 46077 | F10: =IF(E10>0,E10-D10,"") | X10: =E9 -> 46273 | Y10: =G9+H9-I9 -> 21.85
A11: Pabaiga | B11: 46273 | F11: =IF(E11>0,E11-D11,"") | X11: =E10 -> 0 | Y11: =G10+H10-I10 -> 0
A12: Liko, dienos | B12: =IF(B16<>K3,(TODAY()-B11)*-1,"") | F12: =IF(E12>0,E12-D12,"") | X12: =E11 -> 0 | Y12: =G11+H11-I11 -> 0
F13: =IF(E13>0,E13-D13,"") | X13: =E12 -> 0 | Y13: =G12+H12-I12 -> 0
F14: =IF(E14>0,E14-D14,"") | X14: =E13 -> 0 | Y14: =G13+H13-I13 -> 0
A15: Palūkanos | B15: 0.11 | F15: =IF(E15>0,E15-D15,"") | X15: =E14 -> 0 | Y15: =G14+H14-I14 -> 0
A16: Investuota, Eur | B16: 21.8 | F16: =IF(E16>0,E16-D16,"") | X16: =E15 -> 0 | Y16: =G15+H15-I15 -> 0
F17: =IF(E17>0,E17-D17,"") | X17: =E16 -> 0 | Y17: =G16+H16-I16 -> 0
F18: =IF(E18>0,E18-D18,"") | X18: =E17 -> 0 | Y18: =G17+H17-I17 -> 0
F19: =IF(E19>0,E19-D19,"") | X19: =E18 -> 0 | Y19: =G18+H18-I18 -> 0
F20: =IF(E20>0,E20-D20,"") | X20: =E19 -> 0 | Y20: =G19+H19-I19 -> 0
F21: =IF(E21>0,E21-D21,"") | X21: =E20 -> 0 | Y21: =G20+H20-I20 -> 0
F22: =IF(E22>0,E22-D22,"") | X22: =E21 -> 0 | Y22: =G21+H21-I21 -> 0
F23: =IF(E23>0,E23-D23,"") | X23: =E22 -> 0 | Y23: =G22+H22-I22 -> 0
F24: =IF(E24>0,E24-D24,"") | X24: =E23 -> 0 | Y24: =G23+H23-I23 -> 0
F25: =IF(E25>0,E25-D25,"") | X25: =E24 -> 0 | Y25: =G24+H24-I24 -> 0
F26: =IF(E26>0,E26-D26,"") | X26: =E25 -> 0 | Y26: =G25+H25-I25 -> 0
F27: =IF(E27>0,E27-D27,"") | X27: =E26 -> 0 | Y27: =G26+H26-I26 -> 0
F28: =IF(E28>0,E28-D28,"") | X28: =E27 -> 0 | Y28: =G27+H27-I27 -> 0
... F52: =IF(E52>0,E52-D52,"") | X52: =E51 -> 0 | Y52: =G51+H51-I51 -> 0
D53: Viso: | G53: =SUM(G3:G52) -> 21.8 | H53: =SUM(H3:H52) -> 1.26 | I53: =SUM(I3:I52) -> 0

Sheet LV0000110047
A1: Loan ID | B1: LV0000110047 | D1: Data | G1: Paskola | K1: Grąžinimas
A2: Šalis | B2: Latvia | D2: Planuojama | E2: Reali | F2: Vėl./Anks. | G2: Principal | H2: Interest | I2: Mokestis | K2: Paskola | L2: Palūkanos | M2: Mokesčiai | N2: XIRR | O2: Data | P2: Vėluoja | Q2: Vėl./Anks. | X2: Data | Y2: Suma | Z2: Vėluoja
A3: Skolintojas | B3: Sandbox Funding | D3: 46081 | E3: 46081 | F3: =IF(E3>0,E3-D3,"") -> 0 | G3: 0 | H3: 0.1 | I3: 0 | K3: =G53 -> 0 | L3: =H53 -> 1.43 | M3: =I53 -> 0 | N3: =IF(B16=K3,XIRR(Y3:Y52,X3:X52),"") | O3: =IF(B16=K3,MAX(E:E),"") | P3: =IF(Z3="+",TODAY()-B11,"") | Q3: =IF(B16=K3,MAX(E:E)-B11,"") | X3: =B9 -> 46064 | Y3: =B16*-1 -> -21.43 | Z3: =IF(AND(TODAY()>B11, K3<>B16), "+", "")
A4: Tipas | B4: Loans | D4: 46112 | E4: 46112 | F4: =IF(E4>0,E4-D4,"") -> 0 | G4: 0 | H4: 0.2 | I4: 0 | X4: =E3 -> 46081 | Y4: =G3+H3-I3 -> 0.1
A5: ID | B5: ccf30376-99e2-4ee5-8dd9-bd88dc4179b3 | D5: 46142 | E5: 46142 | F5: =IF(E5>0,E5-D5,"") -> 0 | G5: 0 | H5: 0.19 | I5: 0 | X5: =E4 -> 46112 | Y5: =G4+H4-I4 -> 0.2
A6: Trust score | B6: B+ | D6: 46171 | E6: 46171 | F6: =IF(E6>0,E6-D6,"") -> 0 | G6: 0 | H6: 0.18 | I6: 0 | X6: =E5 -> 46142 | Y6: =G5+H5-I5 -> 0.19
D7: 46203 | E7: 46203 | F7: =IF(E7>0,E7-D7,"") -> 0 | G7: 0 | H7: 0.2 | I7: 0 | X7: =E6 -> 46171 | Y7: =G6+H6-I6 -> 0.18
A8: Terminas | B8: =DATEDIF(B9,B11,"y") & " m. " & DATEDIF(B9,B11,"ym") & " mėn. " & DATEDIF(B9,B11,"md") & " d." -> 0 m. 11 mėn. 22 d. | D8: 46234 | E8: 46234 | F8: =IF(E8>0,E8-D8,"") -> 0 | G8: 0 | H8: 0.19 | I8: 0 | X8: =E7 -> 46203 | Y8: =G7+H7-I7 -> 0.2
A9: Investuota | B9: 46064 | D9: 46265 | E9: 46265 | F9: =IF(E9>0,E9-D9,"") -> 0 | G9: 0 | H9: 0.19 | I9: 0 | X9: =E8 -> 46234 | Y9: =G8+H8-I8 -> 0.19
A10: Pradžia | B10: 46084 | D10: 46295 | E10: 46295 | F10: =IF(E10>0,E10-D10,"") -> 0 | G10: 0 | H10: 0.18 | I10: 0 | X10: =E9 -> 46265 | Y10: =G9+H9-I9 -> 0.19
A11: Pabaiga | B11: 46420 | F11: =IF(E11>0,E11-D11,"") | X11: =E10 -> 46295 | Y11: =G10+H10-I10 -> 0.18
A12: Liko, dienos | B12: =IF(B16<>K3,(TODAY()-B11)*-1,"") -> 125 | F12: =IF(E12>0,E12-D12,"") | X12: =E11 -> 0 | Y12: =G11+H11-I11 -> 0
F13: =IF(E13>0,E13-D13,"") | X13: =E12 -> 0 | Y13: =G12+H12-I12 -> 0
F14: =IF(E14>0,E14-D14,"") | X14: =E13 -> 0 | Y14: =G13+H13-I13 -> 0
A15: Palūkanos | B15: 0.105 | F15: =IF(E15>0,E15-D15,"") | X15: =E14 -> 0 | Y15: =G14+H14-I14 -> 0
A16: Investuota, Eur | B16: 21.43 | F16: =IF(E16>0,E16-D16,"") | X16: =E15 -> 0 | Y16: =G15+H15-I15 -> 0
F17: =IF(E17>0,E17-D17,"") | X17: =E16 -> 0 | Y17: =G16+H16-I16 -> 0
F18: =IF(E18>0,E18-D18,"") | X18: =E17 -> 0 | Y18: =G17+H17-I17 -> 0
F19: =IF(E19>0,E19-D19,"") | X19: =E18 -> 0 | Y19: =G18+H18-I18 -> 0
F20: =IF(E20>0,E20-D20,"") | X20: =E19 -> 0 | Y20: =G19+H19-I19 -> 0
F21: =IF(E21>0,E21-D21,"") | X21: =E20 -> 0 | Y21: =G20+H20-I20 -> 0
F22: =IF(E22>0,E22-D22,"") | X22: =E21 -> 0 | Y22: =G21+H21-I21 -> 0
F23: =IF(E23>0,E23-D23,"") | X23: =E22 -> 0 | Y23: =G22+H22-I22 -> 0
F24: =IF(E24>0,E24-D24,"") | X24: =E23 -> 0 | Y24: =G23+H23-I23 -> 0
F25: =IF(E25>0,E25-D25,"") | X25: =E24 -> 0 | Y25: =G24+H24-I24 -> 0
F26: =IF(E26>0,E26-D26,"") | X26: =E25 -> 0 | Y26: =G25+H25-I25 -> 0
F27: =IF(E27>0,E27-D27,"") | X27: =E26 -> 0 | Y27: =G26+H26-I26 -> 0
F28: =IF(E28>0,E28-D28,"") | X28: =E27 -> 0 | Y28: =G27+H27-I27 -> 0
... F52: =IF(E52>0,E52-D52,"") | X52: =E51 -> 0 | Y52: =G51+H51-I51 -> 0
D53: Viso: | G53: =SUM(G3:G52) -> 0 | H53: =SUM(H3:H52) -> 1.43 | I53: =SUM(I3:I52) -> 0

Sheet LV0000109064
A1: Loan ID | B1: LV0000109064 | D1: Data | G1: Paskola | K1: Grąžinimas
A2: Šalis | B2: Latvia | D2: Planuojama | E2: Reali | F2: Vėl./Anks. | G2: Principal | H2: Interest | I2: Mokestis | K2: Paskola | L2: Palūkanos | M2: Mokesčiai | N2: XIRR | O2: Data | P2: Vėluoja | Q2: Vėl./Anks. | X2: Data | Y2: Suma | Z2: Vėluoja
A3: Skolintojas | B3: Baltic Terra | D3: 46053 | E3: 46053 | F3: =IF(E3>0,E3-D3,"") -> 0 | G3: 0 | H3: 0.16 | I3: 0 | K3: =G53 -> 0 | L3: =H53 -> 1.74 | M3: =I53 -> 0 | N3: =IF(B16=K3,XIRR(Y3:Y52,X3:X52),"") | O3: =IF(B16=K3,MAX(E:E),"") | P3: =IF(Z3="+",TODAY()-B11,"") | Q3: =IF(B16=K3,MAX(E:E)-B11,"") | X3: =B9 -> 46029 | Y3: =B16*-1 -> -21.01 | Z3: =IF(AND(TODAY()>B11, K3<>B16), "+", "")
A4: Tipas | B4: Notes | D4: 46081 | E4: 46081 | F4: =IF(E4>0,E4-D4,"") -> 0 | G4: 0 | H4: 0.19 | I4: 0 | X4: =E3 -> 46053 | Y4: =G3+H3-I3 -> 0.16
A5: ID | B5: e26c310c-331f-4855-9f5d-294789304acd | D5: 46112 | E5: 46112 | F5: =IF(E5>0,E5-D5,"") -> 0 | G5: 0 | H5: 0.21 | I5: 0 | X5: =E4 -> 46081 | Y5: =G4+H4-I4 -> 0.19
A6: Trust score | B6: A | D6: 46142 | E6: 46142 | F6: =IF(E6>0,E6-D6,"") -> 0 | G6: 0 | H6: 0.19 | I6: 0 | X6: =E5 -> 46112 | Y6: =G5+H5-I5 -> 0.21
D7: 46171 | E7: 46171 | F7: =IF(E7>0,E7-D7,"") -> 0 | G7: 0 | H7: 0.19 | I7: 0 | X7: =E6 -> 46142 | Y7: =G6+H6-I6 -> 0.19
A8: Terminas | B8: =DATEDIF(B9,B11,"y") & " m. " & DATEDIF(B9,B11,"ym") & " mėn. " & DATEDIF(B9,B11,"md") & " d." -> 0 m. 11 mėn. 21 d. | D8: 46203 | E8: 46203 | F8: =IF(E8>0,E8-D8,"") -> 0 | G8: 0 | H8: 0.21 | I8: 0 | X8: =E7 -> 46171 | Y8: =G7+H7-I7 -> 0.19
A9: Investuota | B9: 46029 | D9: 46234 | E9: 46234 | F9: =IF(E9>0,E9-D9,"") -> 0 | G9: 0 | H9: 0.2 | I9: 0 | X9: =E8 -> 46203 | Y9: =G8+H8-I8 -> 0.21
A10: Pradžia | B10: 46013 | D10: 46265 | E10: 46265 | F10: =IF(E10>0,E10-D10,"") -> 0 | G10: 0 | H10: 0.2 | I10: 0 | X10: =E9 -> 46234 | Y10: =G9+H9-I9 -> 0.2
A11: Pabaiga | B11: 46384 | D11: 46295 | E11: 46295 | F11: =IF(E11>0,E11-D11,"") -> 0 | G11: 0 | H11: 0.19 | I11: 0 | X11: =E10 -> 46265 | Y11: =G10+H10-I10 -> 0.2
A12: Liko, dienos | B12: =IF(B16<>K3,(TODAY()-B11)*-1,"") -> 89 | F12: =IF(E12>0,E12-D12,"") | X12: =E11 -> 46295 | Y12: =G11+H11-I11 -> 0.19
F13: =IF(E13>0,E13-D13,"") | X13: =E12 -> 0 | Y13: =G12+H12-I12 -> 0
F14: =IF(E14>0,E14-D14,"") | X14: =E13 -> 0 | Y14: =G13+H13-I13 -> 0
A15: Palūkanos | B15: 0.1125 | F15: =IF(E15>0,E15-D15,"") | X15: =E14 -> 0 | Y15: =G14+H14-I14 -> 0
A16: Investuota, Eur | B16: 21.01 | F16: =IF(E16>0,E16-D16,"") | X16: =E15 -> 0 | Y16: =G15+H15-I15 -> 0
F17: =IF(E17>0,E17-D17,"") | X17: =E16 -> 0 | Y17: =G16+H16-I16 -> 0
F18: =IF(E18>0,E18-D18,"") | X18: =E17 -> 0 | Y18: =G17+H17-I17 -> 0
F19: =IF(E19>0,E19-D19,"") | X19: =E18 -> 0 | Y19: =G18+H18-I18 -> 0
F20: =IF(E20>0,E20-D20,"") | X20: =E19 -> 0 | Y20: =G19+H19-I19 -> 0
F21: =IF(E21>0,E21-D21,"") | X21: =E20 -> 0 | Y21: =G20+H20-I20 -> 0
F22: =IF(E22>0,E22-D22,"") | X22: =E21 -> 0 | Y22: =G21+H21-I21 -> 0
F23: =IF(E23>0,E23-D23,"") | X23: =E22 -> 0 | Y23: =G22+H22-I22 -> 0
F24: =IF(E24>0,E24-D24,"") | X24: =E23 -> 0 | Y24: =G23+H23-I23 -> 0
