Workbook

Sheet Overview
B1: Loan ID | C1: Investuota | E1: Grąžinta | K1: Pinigai | O1: Grąžinta | Q1: Vertė
C2: Suma | D2: Data | E2: Data | F2: Laikas | G2: Paskola | H2: Palūkanos | I2: XIRR | K2: Įnešta | L2: Investuota | M2: Premijos | N2: Gryni | O2: Paskola | P2: Palūkanos | Q2: Viso | R2: Eur | S2: % | T2: XIRR
A3: 1 | B3: ='J035'!$B$1 -> J035 | C3: ='J035'!$B$10 -> 0.12 | D3: ='J035'!$B$7 -> 45769 | E3: =IF(C3=G3,'J035'!$B$9,"") | F3: ='J035'!$B$14 | G3: ='J035'!$B$11 -> 0 | H3: ='J035'!$B$12 -> 0 | I3: ='J035'!$B$13 | K3: =Pinigai!F2 -> 550 | L3: =SUM(C3:C201)-O3 -> 636.74 | M3: =Pinigai!H2 -> 84.49 | N3: =Q3-L3 -> 0.32 | O3: =SUM(G3:G201) -> 23.87 | P3: =SUM(H3:H201) -> 2.57 | Q3: =K3+M3+P3 -> 637.06 | R3: =Q3-K3 -> 87.06 | S3: =(Q3-K3)/Q3 -> 0.13665903 | T3: =XIRR(Pinigai!K2:K200,Pinigai!A2:A200) -> 0.12463425
A4: 2 | B4: ='J036'!$B$1 -> J036 | C4: ='J036'!$B$10 -> 0.62 | D4: ='J036'!$B$7 -> 45741 | E4: =IF(C4=G4,'J036'!$B$9,"") | F4: ='J036'!$B$14 | G4: ='J036'!$B$11 -> 0 | H4: ='J036'!$B$12 -> 0 | I4: ='J036'!$B$13
A5: 3 | B5: ='J037'!$B$1 -> J037 | C5: ='J037'!$B$10 -> 0.13 | D5: ='J037'!$B$7 -> 45769 | E5: =IF(C5=G5,'J037'!$B$9,"") | F5: ='J037'!$B$14 | G5: ='J037'!$B$11 -> 0 | H5: ='J037'!$B$12 -> 0 | I5: ='J037'!$B$13
A6: 4 | B6: ='J038'!$B$1 -> J038 | C6: ='J038'!$B$10 -> 0.76 | D6: ='J038'!$B$7 -> 45741 | E6: =IF(C6=G6,'J038'!$B$9,"") -> 45996 | F6: ='J038'!$B$14 -> 255 | G6: ='J038'!$B$11 -> 0.76 | H6: ='J038'!$B$12 -> 0.11 | I6: ='J038'!$B$13 -> 0.21347175
A7: 5 | B7: ='J039'!$B$1 -> J039 | C7: ='J039'!$B$10 -> 0.13 | D7: ='J039'!$B$7 -> 45769 | E7: =IF(C7=G7,'J039'!$B$9,"") | F7: ='J039'!$B$14 | G7: ='J039'!$B$11 -> 0 | H7: ='J039'!$B$12 -> 0 | I7: ='J039'!$B$13
A8: 6 | B8: ='J040'!$B$1 -> J040 | C8: ='J040'!$B$10 -> 21.51 | D8: ='J040'!$B$7 -> 45743.935 | E8: =IF(C8=G8,'J040'!$B$9,"") | F8: ='J040'!$B$14 | G8: ='J040'!$B$11 -> 0 | H8: ='J040'!$B$12 -> 0 | I8: ='J040'!$B$13
A9: 7 | B9: ='J041'!$B$1 -> J041 | C9: ='J041'!$B$10 -> 6.79 | D9: ='J041'!$B$7 -> 45762.969 | E9: =IF(C9=G9,'J041'!$B$9,"") -> 45995 | F9: ='J041'!$B$14 -> 232.03093 | G9: ='J041'!$B$11 -> 6.79 | H9: ='J041'!$B$12 -> 0.68 | I9: ='J041'!$B$13 -> 0.16198474
A10: 8 | B10: ='J042'!$B$1 -> J042 | C10: ='J042'!$B$10 -> 0.97 | D10: ='J042'!$B$7 -> 45807.031 | E10: =IF(C10=G10,'J042'!$B$9,"") | F10: ='J042'!$B$14 | G10: ='J042'!$B$11 -> 0 | H10: ='J042'!$B$12 -> 0 | I10: ='J042'!$B$13
A11: 9 | B11: ='J043'!$B$1 -> J043 | C11: ='J043'!$B$10 -> 1.09 | D11: ='J043'!$B$7 -> 45867 | E11: =IF(C11=G11,'J043'!$B$9,"") | F11: ='J043'!$B$14 | G11: ='J043'!$B$11 -> 0 | H11: ='J043'!$B$12 -> 0 | I11: ='J043'!$B$13
A12: 10 | B12: ='J044'!$B$1 -> J044 | C12: ='J044'!$B$10 -> 3.11 | D12: ='J044'!$B$7 -> 45742.733 | E12: =IF(C12=G12,'J044'!$B$9,"") -> 46169 | F12: ='J044'!$B$14 -> 426.26688 | G12: ='J044'!$B$11 -> 3.11 | H12: ='J044'!$B$12 -> 0.51 | I12: ='J044'!$B$13 -> 0.13885676
A13: 11 | B13: ='J046'!$B$1 -> J046 | C13: ='J046'!$B$10 -> 14.66 | D13: ='J046'!$B$7 -> 45744.046 | E13: =IF(C13=G13,'J046'!$B$9,"") | F13: ='J046'!$B$14 | G13: ='J046'!$B$11 -> 0 | H13: ='J046'!$B$12 -> 0 | I13: ='J046'!$B$13
A14: 12 | B14: ='J048'!$B$1 -> J048 | C14: ='J048'!$B$10 -> 6.88 | D14: ='J048'!$B$7 -> 45763.078 | E14: =IF(C14=G14,'J048'!$B$9,"") | F14: ='J048'!$B$14 | G14: ='J048'!$B$11 -> 0 | H14: ='J048'!$B$12 -> 0 | I14: ='J048'!$B$13
A15: 13 | B15: ='J049'!$B$1 -> J049 | C15: ='J049'!$B$10 -> 3.22 | D15: ='J049'!$B$7 -> 45771.37 | E15: =IF(C15=G15,'J049'!$B$9,"") | F15: ='J049'!$B$14 | G15: ='J049'!$B$11 -> 0 | H15: ='J049'!$B$12 -> 0 | I15: ='J049'!$B$13
A16: 14 | B16: ='J050'!$B$1 -> J050 | C16: ='J050'!$B$10 -> 5.12 | D16: ='J050'!$B$7 -> 45770.887 | E16: =IF(C16=G16,'J050'!$B$9,"") | F16: ='J050'!$B$14 | G16: ='J050'!$B$11 -> 0 | H16: ='J050'!$B$12 -> 0 | I16: ='J050'!$B$13
A17: 15 | B17: ='J051'!$B$1 -> J051 | C17: ='J051'!$B$10 -> 0.21 | D17: ='J051'!$B$7 -> 45769 | E17: =IF(C17=G17,'J051'!$B$9,"") -> 46099 | F17: ='J051'!$B$14 -> 330 | G17: ='J051'!$B$11 -> 0.21 | H17: ='J051'!$B$12 -> 0.03 | I17: ='J051'!$B$13 -> 0.15915793
A18: 16 | B18: ='J052'!$B$1 -> J052 | C18: ='J052'!$B$10 -> 14.66 | D18: ='J052'!$B$7 -> 45743.946 | E18: =IF(C18=G18,'J052'!$B$9,"") | F18: ='J052'!$B$14 | G18: ='J052'!$B$11 -> 0 | H18: ='J052'!$B$12 -> 0 | I18: ='J052'!$B$13
A19: 17 | B19: ='J053'!$B$1 -> J053 | C19: ='J053'!$B$10 -> 4.02 | D19: ='J053'!$B$7 -> 45743.786 | E19: =IF(C19=G19,'J053'!$B$9,"") | F19: ='J053'!$B$14 | G19: ='J053'!$B$11 -> 0 | H19: ='J053'!$B$12 -> 0 | I19: ='J053'!$B$13
A20: 18 | B20: ='J054'!$B$1 -> J054 | C20: ='J054'!$B$10 -> 5.6 | D20: ='J054'!$B$7 -> 45872.55 | E20: =IF(C20=G20,'J054'!$B$9,"") | F20: ='J054'!$B$14 | G20: ='J054'!$B$11 -> 0 | H20: ='J054'!$B$12 -> 0 | I20: ='J054'!$B$13
A21: 19 | B21: ='J055'!$B$1 -> J055 | C21: ='J055'!$B$10 -> 2.08 | D21: ='J055'!$B$7 -> 45806.019 | E21: =IF(C21=G21,'J055'!$B$9,"") | F21: ='J055'!$B$14 | G21: ='J055'!$B$11 -> 0 | H21: ='J055'!$B$12 -> 0 | I21: ='J055'!$B$13
A22: 20 | B22: ='J056'!$B$1 -> J056 | C22: ='J056'!$B$10 -> 5.01 | D22: ='J056'!$B$7 -> 45811.992 | E22: =IF(C22=G22,'J056'!$B$9,"") | F22: ='J056'!$B$14 | G22: ='J056'!$B$11 -> 0 | H22: ='J056'!$B$12 -> 0 | I22: ='J056'!$B$13
A23: 21 | B23: ='J057'!$B$1 -> J057 | C23: ='J057'!$B$10 -> 3.85 | D23: ='J057'!$B$7 -> 45804 | E23: =IF(C23=G23,'J057'!$B$9,"") | F23: ='J057'!$B$14 | G23: ='J057'!$B$11 -> 0 | H23: ='J057'!$B$12 -> 0 | I23: ='J057'!$B$13
A24: 22 | B24: ='J059'!$B$1 -> J059 | C24: ='J059'!$B$10 -> 10.86 | D24: ='J059'!$B$7 -> 45744.184 | E24: =IF(C24=G24,'J059'!$B$9,"") | F24: ='J059'!$B$14 | G24: ='J059'!$B$11 -> 0 | H24: ='J059'!$B$12 -> 0 | I24: ='J059'!$B$13
A25: 23 | B25: ='J060'!$B$1 -> J060 | C25: ='J060'!$B$10 -> 5.97 | D25: ='J060'!$B$7 -> 45768.812 | E25: =IF(C25=G25,'J060'!$B$9,"") | F25: ='J060'!$B$14 | G25: ='J060'!$B$11 -> 0 | H25: ='J060'!$B$12 -> 0 | I25: ='J060'!$B$13
A26: 24 | B26: ='J061'!$B$1 -> J061 | C26: ='J061'!$B$10 -> 3.58 | D26: ='J061'!$B$7 -> 45744.754 | E26: =IF(C26=G26,'J061'!$B$9,"") | F26: ='J061'!$B$14 | G26: ='J061'!$B$11 -> 0 | H26: ='J061'!$B$12 -> 0 | I26: ='J061'!$B$13
A27: 25 | B27: ='J062'!$B$1 -> J062 | C27: ='J062'!$B$10 -> 40.03 | D27: ='J062'!$B$7 -> 45747.528 | E27: =IF(C27=G27,'J062'!$B$9,"") | F27: ='J062'!$B$14 | G27: ='J062'!$B$11 -> 0 | H27: ='J062'!$B$12 -> 0 | I27: ='J062'!$B$13
A28: 26 | B28: ='J063'!$B$1 -> J063 | C28: ='J063'!$B$10 -> 10.45 | D28: ='J063'!$B$7 -> 45743.854 | E28: =IF(C28=G28,'J063'!$B$9,"") | F28: ='J063'!$B$14 | G28: ='J063'!$B$11 -> 0 | H28: ='J063'!$B$12 -> 0 | I28: ='J063'!$B$13
A29: 27 | B29: ='J064'!$B$1 -> J064 | C29: ='J064'!$B$10 -> 2.27 | D29: ='J064'!$B$7 -> 45804 | E29: =IF(C29=G29,'J064'!$B$9,"") | F29: ='J064'!$B$14 | G29: ='J064'!$B$11 -> 0 | H29: ='J064'!$B$12 -> 0 | I29: ='J064'!$B$13
A30: 28 | B30: ='J065'!$B$1 -> J065 | C30: ='J065'!$B$10 -> 0.11 | D30: ='J065'!$B$7 -> 45776 | E30: =IF(C30=G30,'J065'!$B$9,"") -> 46233 | F30: ='J065'!$B$14 -> 457 | G30: ='J065'!$B$11 -> 0.11 | H30: ='J065'!$B$12 -> 0.03 | I30: ='J065'!$B$13 -> 0.21241352
A31: 29 | B31: ='J066'!$B$1 -> J066 | C31: ='J066'!$B$10 -> 0.63 | D31: ='J066'!$B$7 -> 45748 | E31: =IF(C31=G31,'J066'!$B$9,"") | F31: ='J066'!$B$14 | G31: ='J066'!$B$11 -> 0 | H31: ='J066'!$B$12 -> 0 | I31: ='J066'!$B$13
A32: 30 | B32: ='J067'!$B$1 -> J067 | C32: ='J067'!$B$10 -> 3.03 | D32: ='J067'!$B$7 -> 45742.848 | E32: =IF(C32=G32,'J067'!$B$9,"") | F32: ='J067'!$B$14 | G32: ='J067'!$B$11 -> 0 | H32: ='J067'!$B$12 -> 0 | I32: ='J067'!$B$13
A33: 31 | B33: ='J068'!$B$1 -> J068 | C33: ='J068'!$B$10 -> 0.43 | D33: ='J068'!$B$7 -> 45804 | E33: =IF(C33=G33,'J068'!$B$9,"") | F33: ='J068'!$B$14 | G33: ='J068'!$B$11 -> 0 | H33: ='J068'!$B$12 -> 0 | I33: ='J068'!$B$13
A34: 32 | B34: ='J069'!$B$1 -> J069 | C34: ='J069'!$B$10 -> 2.33 | D34: ='J069'!$B$7 -> 45804 | E34: =IF(C34=G34,'J069'!$B$9,"") | F34: ='J069'!$B$14 | G34: ='J069'!$B$11 -> 0 | H34: ='J069'!$B$12 -> 0 | I34: ='J069'!$B$13
A35: 33 | B35: ='J071'!$B$1 -> J071 | C35: ='J071'!$B$10 -> 12.65 | D35: ='J071'!$B$7 -> 45744.138 | E35: =IF(C35=G35,'J071'!$B$9,"") | F35: ='J071'!$B$14 | G35: ='J071'!$B$11 -> 0 | H35: ='J071'!$B$12 -> 0 | I35: ='J071'!$B$13
A36: 34 | B36: ='J072'!$B$1 -> J072 | C36: ='J072'!$B$10 -> 4.83 | D36: ='J072'!$B$7 -> 45770.71 | E36: =IF(C36=G36,'J072'!$B$9,"") | F36: ='J072'!$B$14 | G36: ='J072'!$B$11 -> 0 | H36: ='J072'!$B$12 -> 0 | I36: ='J072'!$B$13
A37: 35 | B37: ='J073'!$B$1 -> J073 | C37: ='J073'!$B$10 -> 2.87 | D37: ='J073'!$B$7 -> 45769.293 | E37: =IF(C37=G37,'J073'!$B$9,"") | F37: ='J073'!$B$14 | G37: ='J073'!$B$11 -> 0 | H37: ='J073'!$B$12 -> 0 | I37: ='J073'!$B$13
A38: 36 | B38: ='J074'!$B$1 -> J074 | C38: ='J074'!$B$10 -> 0.49 | D38: ='J074'!$B$7 -> 45748 | E38: =IF(C38=G38,'J074'!$B$9,"") | F38: ='J074'!$B$14 | G38: ='J074'!$B$11 -> 0 | H38: ='J074'!$B$12 -> 0 | I38: ='J074'!$B$13
A39: 37 | B39: ='J076'!$B$1 -> J076 | C39: ='J076'!$B$10 -> 13.41 | D39: ='J076'!$B$7 -> 45767.846 | E39: =IF(C39=G39,'J076'!$B$9,"") | F39: ='J076'!$B$14 | G39: ='J076'!$B$11 -> 0 | H39: ='J076'!$B$12 -> 0 | I39: ='J076'!$B$13
A40: 38 | B40: ='R030'!$B$1 -> R030 | C40: ='R030'!$B$10 -> 0.08 | D40: ='R030'!$B$7 -> 45769 | E40: =IF(C40=G40,'R030'!$B$9,"") | F40: ='R030'!$B$14 | G40: ='R030'!$B$11 -> 0 | H40: ='R030'!$B$12 -> 0 | I40: ='R030'!$B$13
...

Sheet Pinigai
A1: Data | B1: Įnešta | C1: Išimta | D1: Premijos | F1: Įnešta | G1: Išimta | H1: Premijos | I1: XIRR | K1: XIRR
A2: 45737 | B2: 60 | C2: 0 | D2: 0 | F2: =SUM(B2:B200) -> 550 | G2: =SUM(C2:C200) -> 0 | H2: =SUM(D2:D200) -> 84.49 | I2: =XIRR(K2:K200,A2:A200) -> 0.12463425 | K2: =B2*-1 -> -60
A3: 45738 | B3: 0 | C3: 0 | D3: 30 | K3: =B3*-1 -> 0
A4: 45738 | B4: 0 | C4: 0 | D4: 25 | K4: =B4*-1 -> 0
A5: 45740 | B5: 0 | C5: 0 | D5: 25 | K5: =B5*-1 -> 0
A6: 45747 | B6: 20 | C6: 0 | D6: 0 | K6: =B6*-1 -> -20
A7: 45750 | B7: 20 | C7: 0 | D7: 0 | K7: =B7*-1 -> -20
A8: 45755 | B8: 30 | C8: 0 | D8: 3 | K8: =B8*-1 -> -30
A9: 45755 | B9: 0 | C9: 0 | D9: 0.15 | K9: =B9*-1 -> 0
A10: 45761 | B10: 30 | C10: 0 | D10: 0.15 | K10: =B10*-1 -> -30
A11: 45761 | B11: 0 | C11: 0 | D11: 0.15 | K11: =B11*-1 -> 0
A12: 45761 | B12: 0 | C12: 0 | D12: 0.2 | K12: =B12*-1 -> 0
A13: 45769 | B13: 30 | C13: 0 | D13: 0 | K13: =B13*-1 -> -30
A14: 45776 | B14: 30 | C14: 0 | D14: 0 | K14: =B14*-1 -> -30
... A28: 46233 | B28: 10 | C28: 0 | D28: 0.31 | K28: =B28*-1 -> -10
K29: =B29*-1 -> 0
K30: =B30*-1 -> 0
K31: =B31*-1 -> 0
K32: =B32*-1 -> 0
K33: =B33*-1 -> 0
A200: =TODAY() -> 46295 | I200: 614.37 | J200: 615.37 | K200: =Overview!Q3 -> 637.06

Sheet J035
A1: Mortgage loan ID | B1: J035 | E1: Note | F1: Investuota | H1: Grąžinimas
A2: Pavadinimas | B2: House at Calle Pino Apolinario | F2: Data | G2: Suma | H2: Grąž. Data | I2: Paskola | J2: Palūkanos | K2: Pelnas | L2: Laikas
A3: PTV | B3: 0.62 | D3: 1 | E3: LV0000104107 | F3: 45769 | G3: 0.12 | H3: =IF(B9>0,B9,"") | L3: =IF(B10=B11,H3-F3,"") | W3: =F3 -> 45769 | X3: =H3 | Y3: =G3*(-1) -> -0.12 | Z3: =I3+J3 -> 0
A4: PDT | B4: 0.38 | W4: =F4 -> 0 | X4: =H4 -> 0 | Y4: =G4*(-1) -> 0 | Z4: =I4+J4 -> 0
W5: =F5 -> 0 | X5: =H5 -> 0 | Y5: =G5*(-1) -> 0 | Z5: =I5+J5 -> 0
A7: Investuota | B7: =SUMPRODUCT(F3:F20,G3:G20)/SUM(G3:G20) -> 45769
A8: Paskolos pradžia | B8: 45551
A9: Paskola grąžinta
A10: Investuota | B10: =SUM(G3:G20) -> 0.12
A11: Grąžinta | B11: =SUM(I3:I20) -> 0
A12: Palūkanos | B12: =SUM(J3:J20) -> 0
A13: XIRR | B13: =IF(B10=B11,XIRR(Y3:Z20,W3:X20),"")
A14: Terminas | B14: =IF(B10=B11,SUMPRODUCT(L3:L20,G3:G20)/SUM(G3:G20),"")

Sheet J036
A1: Mortgage loan ID | B1: J036 | E1: Note | F1: Investuota | H1: Grąžinimas
A2: Pavadinimas | B2: Flat at Calle Noguera | F2: Data | G2: Suma | H2: Grąž. Data | I2: Paskola | J2: Palūkanos | K2: Pelnas | L2: Laikas
A3: PTV | B3: 0.59 | D3: 1 | E3: LV0000103620 | F3: 45741 | G3: 0.62 | H3: =IF(B9>0,B9,"") | L3: =IF(B10=B11,H3-F3,"") | W3: =F3 -> 45741 | X3: =H3 | Y3: =G3*(-1) -> -0.62 | Z3: =I3+J3 -> 0
A4: PDT | B4: 0.51 | W4: =F4 -> 0 | X4: =H4 -> 0 | Y4: =G4*(-1) -> 0 | Z4: =I4+J4 -> 0
W5: =F5 -> 0 | X5: =H5 -> 0 | Y5: =G5*(-1) -> 0 | Z5: =I5+J5 -> 0
A7: Investuota | B7: =SUMPRODUCT(F3:F20,G3:G20)/SUM(G3:G20) -> 45741
A8: Paskolos pradžia | B8: 45551
A9: Paskola grąžinta
A10: Investuota | B10: =SUM(G3:G20) -> 0.62
A11: Grąžinta | B11: =SUM(I3:I20) -> 0
A12: Palūkanos | B12: =SUM(J3:J20) -> 0
A13: XIRR | B13: =IF(B10=B11,XIRR(Y3:Z20,W3:X20),"")
A14: Terminas | B14: =IF(B10=B11,SUMPRODUCT(L3:L20,G3:G20)/SUM(G3:G20),"")

Sheet J037
A1: Mortgage loan ID | B1: J037 | E1: Note | F1: Investuota | H1: Grąžinimas
A2: Pavadinimas | B2: House at Calle Concepción Arenal | F2: Data | G2: Suma | H2: Grąž. Data | I2: Paskola | J2: Palūkanos | K2: Pelnas | L2: Laikas
A3: PTV | B3: 0.59 | D3: 1 | E3: LV0000104081 | F3: 45769 | G3: 0.13 | H3: =IF(B9>0,B9,"") | L3: =IF(B10=B11,H3-F3,"") | W3: =F3 -> 45769 | X3: =H3 | Y3: =G3*(-1) -> -0.13 | Z3: =I3+J3 -> 0
A4: PDT | B4: 0.61 | W4: =F4 -> 0 | X4: =H4 -> 0 | Y4: =G4*(-1) -> 0 | Z4: =I4+J4 -> 0
W5: =F5 -> 0 | X5: =H5 -> 0 | Y5: =G5*(-1) -> 0 | Z5: =I5+J5 -> 0
A7: Investuota | B7: =SUMPRODUCT(F3:F20,G3:G20)/SUM(G3:G20) -> 45769
A8: Paskolos pradžia | B8: 45551
A9: Paskola grąžinta
A10: Investuota | B10: =SUM(G3:G20) -> 0.13
A11: Grąžinta | B11: =SUM(I3:I20) -> 0
A12: Palūkanos | B12: =SUM(J3:J20) -> 0
A13: XIRR | B13: =IF(B10=B11,XIRR(Y3:Z20,W3:X20),"")
A14: Terminas | B14: =IF(B10=B11,SUMPRODUCT(L3:L20,G3:G20)/SUM(G3:G20),"")

Sheet J038
A1: Mortgage loan ID | B1: J038 | E1: Note | F1: Investuota | H1: Grąžinimas
A2: Pavadinimas | B2: House at Calle Virgen María | F2: Data | G2: Suma | H2: Grąž. Data | I2: Paskola | J2: Palūkanos | K2: Pelnas | L2: Laikas
A3: PTV | B3: 0.59 | D3: 1 | E3: LV0000103620 | F3: 45741 | G3: 0.76 | H3: =IF(B9>0,B9,"") -> 45996 | I3: 0.76 | J3: 0.11 | K3: 0.2128 | L3: =IF(B10=B11,H3-F3,"") -> 255 | W3: =F3 -> 45741 | X3: =H3 -> 45996 | Y3: =G3*(-1) -> -0.76 | Z3: =I3+J3 -> 0.87
A4: PDT | B4: 0.64 | W4: =F4 -> 0 | X4: =H4 -> 0 | Y4: =G4*(-1) -> 0 | Z4: =I4+J4 -> 0
W5: =F5 -> 0 | X5: =H5 -> 0 | Y5: =G5*(-1) -> 0 | Z5: =I5+J5 -> 0
A7: Investuota | B7: =SUMPRODUCT(F3:F20,G3:G20)/SUM(G3:G20) -> 45741
A8: Paskolos pradžia | B8: 45551
A9: Paskola grąžinta | B9: 45996
A10: Investuota | B10: =SUM(G3:G20) -> 0.76
A11: Grąžinta | B11: =SUM(I3:I20) -> 0.76
A12: Palūkanos | B12: =SUM(J3:J20) -> 0.11
A13: XIRR | B13: =IF(B10=B11,XIRR(Y3:Z20,W3:X20),"") -> 0.21347175
A14: Terminas | B14: =IF(B10=B11,SUMPRODUCT(L3:L20,G3:G20)/SUM(G3:G20),"") -> 255

Sheet J039
A1: Mortgage loan ID | B1: J039 | E1: Note | F1: Investuota | H1: Grąžinimas
A2: Pavadinimas | B2: Flat at Calle Mercurio | F2: Data | G2: Suma | H2: Grąž. Data | I2: Paskola | J2: Palūkanos | K2: Pelnas | L2: Laikas
A3: PTV | B3: 0.52 | D3: 1 | E3: LV0000104099 | F3: 45769 | G3: 0.13 | H3: =IF(B9>0,B9,"") | L3: =IF(B10=B11,H3-F3,"") | W3: =F3 -> 45769 | X3: =H3 | Y3: =G3*(-1) -> -0.13 | Z3: =I3+J3 -> 0
A4: PDT | B4: 0.76 | W4: =F4 -> 0 | X4: =H4 -> 0 | Y4: =G4*(-1) -> 0 | Z4: =I4+J4 -> 0
W5: =F5 -> 0 | X5: =H5 -> 0 | Y5: =G5*(-1) -> 0 | Z5: =I5+J5 -> 0
A7: Investuota | B7: =SUMPRODUCT(F3:F20,G3:G20)/SUM(G3:G20) -> 45769
A8: Paskolos pradžia | B8: 45551
A9: Paskola grąžinta
A10: Investuota | B10: =SUM(G3:G20) -> 0.13
A11: Grąžinta | B11: =SUM(I3:I20) -> 0
A12: Palūkanos | B12: =SUM(J3:J20) -> 0
A13: XIRR | B13: =IF(B10=B11,XIRR(Y3:Z20,W3:X20),"")
A14: Terminas | B14: =IF(B10=B11,SUMPRODUCT(L3:L20,G3:G20)/SUM(G3:G20),"")

Sheet J040
A1: Mortgage loan ID | B1: J040 | E1: Note | F1: Investuota | H1: Grąžinimas
A2: Pavadinimas | B2: Apartment in Cambrils | F2: Data | G2: Suma | H2: Grąž. Data | I2: Paskola | J2: Palūkanos | K2: Pelnas | L2: Laikas
A3: PTV | B3: 0.58 | D3: 1 | E3: LV0000103620 | F3: 45741 | G3: 7.82 | H3: =IF($B$9>0,$B$9,"") | L3: =IF($B$10=$B$11,H3-F3,"") | W3: =F3 -> 45741 | X3: =H3 | Y3: =G3*(-1) -> -7.82 | Z3: =I3+J3 -> 0
A4: PDT | B4: 0.55 | D4: 2 | E4: LV0000103612 | F4: 45741 | G4: 6.95 | H4: =IF($B$9>0,$B$9,"") | L4: =IF($B$10=$B$11,H4-F4,"") | W4: =F4 -> 45741 | X4: =H4 | Y4: =G4*(-1) -> -6.95 | Z4: =I4+J4 -> 0
D5: 3 | E5: LV0000103745 | F5: 45748 | G5: 2.9 | H5: =IF($B$9>0,$B$9,"") | L5: =IF($B$10=$B$11,H5-F5,"") | W5: =F5 -> 45748 | X5: =H5 | Y5: =G5*(-1) -> -2.9 | Z5: =I5+J5 -> 0
D6: 4 | E6: LV0000103752 | F6: 45748 | G6: 1.8 | H6: =IF($B$9>0,$B$9,"") | L6: =IF($B$10=$B$11,H6-F6,"") | W6: =F6 -> 45748 | X6: =H6 | Y6: =G6*(-1) -> -1.8 | Z6: =I6+J6 -> 0
A7: Investuota | B7: =SUMPRODUCT(F3:F20,G3:G20)/SUM(G3:G20) -> 45743.935 | D7: 5 | E7: LV0000103828 | F7: 45755 | G7: 2 | H7: =IF($B$9>0,$B$9,"") | L7: =IF($B$10=$B$11,H7-F7,"") | W7: =F7 -> 45755 | X7: =H7 | Y7: =G7*(-1) -> -2 | Z7: =I7+J7 -> 0
A8: Paskolos pradžia | B8: 45551 | D8: 6 | E8: LV0000104586 | F8: 45797 | G8: 0.04 | H8: =IF($B$9>0,$B$9,"") | L8: =IF($B$10=$B$11,H8-F8,"") | W8: =F8 -> 45797 | X8: =H8 | Y8: =G8*(-1) -> -0.04 | Z8: =I8+J8 -> 0
A9: Paskola grąžinta | W9: =F9 -> 0 | X9: =H9 -> 0 | Y9: =G9*(-1) -> 0 | Z9: =I9+J9 -> 0
A10: Investuota | B10: =SUM(G3:G20) -> 21.51 | W10: =F10 -> 0 | X10: =H10 -> 0 | Y10: =G10*(-1) -> 0 | Z10: =I10+J10 -> 0
A11: Grąžinta | B11: =SUM(I3:I20) -> 0 | W11: =F11 -> 0 | X11: =H11 -> 0 | Y11: =G11*(-1) -> 0 | Z11: =I11+J11 -> 0
A12: Palūkanos | B12: =SUM(J3:J20) -> 0 | W12: =F12 -> 0 | X12: =H12 -> 0 | Y12: =G12*(-1) -> 0 | Z12: =I12+J12 -> 0
A13: XIRR | B13: =IF(B10=B11,XIRR(Y3:Z20,W3:X20),"") | W13: =F13 -> 0 | X13: =H13 -> 0 | Y13: =G13*(-1) -> 0 | Z13: =I13+J13 -> 0
A14: Terminas | B14: =IF(B10=B11,SUMPRODUCT(L3:L20,G3:G20)/SUM(G3:G20),"") | W14: =F14 -> 0 | X14: =H14 -> 0 | Y14: =G14*(-1) -> 0 | Z14: =I14+J14 -> 0
W15: =F15 -> 0 | X15: =H15 -> 0 | Y15: =G15*(-1) -> 0 | Z15: =I15+J15 -> 0
W16: =F16 -> 0 | X16: =H16 -> 0 | Y16: =G16*(-1) -> 0 | Z16: =I16+J16 -> 0
W17: =F17 -> 0 | X17: =H17 -> 0 | Y17: =G17*(-1) -> 0 | Z17: =I17+J17 -> 0
W18: =F18 -> 0 | X18: =H18 -> 0 | Y18: =G18*(-1) -> 0 | Z18: =I18+J18 -> 0
W19: =F19 -> 0 | X19: =H19 -> 0 | Y19: =G19*(-1) -> 0 | Z19: =I19+J19 -> 0
W20: =F20 -> 0 | X20: =H20 -> 0 | Y20: =G20*(-1) -> 0 | Z20: =I20+J20 -> 0
W21: =F21 -> 0 | X21: =H21 -> 0 | Y21: =G21*(-1) -> 0 | Z21: =I21+J21 -> 0
W22: =F22 -> 0 | X22: =H22 -> 0 | Y22: =G22*(-1) -> 0 | Z22: =I22+J22 -> 0
W23: =F23 -> 0 | X23: =H23 -> 0 | Y23: =G23*(-1) -> 0 | Z23: =I23+J23 -> 0

Sheet J041
A1: Mortgage loan ID | B1: J041 | E1: Note | F1: Investuota | H1: Grąžinimas
A2: Pavadinimas | B2: House in Piera | F2: Data | G2: Suma | H2: Grąž. Data | I2: Paskola | J2: Palūkanos | K2: Pelnas | L2: Laikas
A3: PTV | B3: 0.57 | D3: 1 | E3: LV0000103935 | F3: 45755 | G3: 0.9 | H3: =IF($B$9>0,$B$9,"") -> 45995 | I3: 0.9 | J3: 0.09 | K3: 0.159 | L3: =IF($B$10=$B$11,H3-F3,"") -> 240 | W3: =F3 -> 45755 | X3: =H3 -> 45995 | Y3: =G3*(-1) -> -0.9 | Z3: =I3+J3 -> 0.99
A4: PDT | B4: 0.35 | D4: 2 | E4: LV0000103927 | F4: 45755 | G4: 0.97 | H4: =IF($B$9>0,$B$9,"") -> 45995 | I4: 0.97 | J4: 0.1 | K4: 0.159 | L4: =IF($B$10=$B$11,H4-F4,"") -> 240 | W4: =F4 -> 45755 | X4: =H4 -> 45995 | Y4: =G4*(-1) -> -0.97 | Z4: =I4+J4 -> 1.07
D5: 3 | E5: LV0000103950 | F5: 45762 | G5: 1.21 | H5: =IF($B$9>0,$B$9,"") -> 45995 | I5: 1.21 | J5: 0.12 | K5: 0.1638 | L5: =IF($B$10=$B$11,H5-F5,"") -> 233 | W5: =F5 -> 45762 | X5: =H5 -> 45995 | Y5: =G5*(-1) -> -1.21 | Z5: =I5+J5 -> 1.33
D6: 4 | E6: LV0000103976 | F6: 45762 | G6: 1.85 | H6: =IF($B$9>0,$B$9,"") -> 45995 | I6: 1.85 | J6: 0.19 | K6: 0.1638 | L6: =IF($B$10=$B$11,H6-F6,"") -> 233 | W6: =F6 -> 45762 | X6: =H6 -> 45995 | Y6: =G6*(-1) -> -1.85 | Z6: =I6+J6 -> 2.04
A7: Investuota | B7: =SUMPRODUCT(F3:F20,G3:G20)/SUM(G3:G20) -> 45762.969 | D7: 5 | E7: LV0000104099 | F7: 45762 | G7: 0.88 | H7: =IF($B$9>0,$B$9,"") -> 45995 | I7: 0.88 | J7: 0.09 | K7: 0.1689 | L7: =IF($B$10=$B$11,H7-F7,"") -> 233 | W7: =F7 -> 45762 | X7: =H7 -> 45995 | Y7: =G7*(-1) -> -0.88 | Z7: =I7+J7 -> 0.97
A8: Paskolos pradžia | B8: 45551 | D8: 6 | E8: LV0000104180 | F8: 45776 | G8: 0.41 | H8: =IF($B$9>0,$B$9,"") -> 45995 | I8: 0.41 | J8: 0.04 | K8: 0.1743 | L8: =IF($B$10=$B$11,H8-F8,"") -> 219 | W8: =F8 -> 45776 | X8: =H8 -> 45995 | Y8: =G8*(-1) -> -0.41 | Z8: =I8+J8 -> 0.45
A9: Paskola grąžinta | B9: 45995 | D9: 7 | E9: LV0000104289 | F9: 45783 | G9: 0.43 | H9: =IF($B$9>0,$B$9,"") -> 45995 | I9: 0.43 | J9: 0.04 | K9: 0.18 | L9: =IF($B$10=$B$11,H9-F9,"") -> 212 | W9: =F9 -> 45783 | X9: =H9 -> 45995 | Y9: =G9*(-1) -> -0.43 | Z9: =I9+J9 -> 0.47
A10: Investuota | B10: =SUM(G3:G20) -> 6.79 | D10: 8 | E10: LV0000104560 | F10: 45797 | G10: 0.14 | H10: =IF($B$9>0,$B$9,"") -> 45995 | I10: 0.14 | J10: 0.01 | K10: 0.1927 | L10: =IF($B$10=$B$11,H10-F10,"") -> 198 | W10: =F10 -> 45797 | X10: =H10 -> 45995 | Y10: =G10*(-1) -> -0.14 | Z10: =I10+J10 -> 0.15
A11: Grąžinta | B11: =SUM(I3:I20) -> 6.79 | W11: =F11 -> 0 | X11: =H11 -> 0 | Y11: =G11*(-1) -> 0 | Z11: =I11+J11 -> 0
A12: Palūkanos | B12: =SUM(J3:J20) -> 0.68 | W12: =F12 -> 0 | X12: =H12 -> 0 | Y12: =G12*(-1) -> 0 | Z12: =I12+J12 -> 0
A13: XIRR | B13: =IF(B10=B11,XIRR(Y3:Z20,W3:X20),"") -> 0.16198474 | W13: =F13 -> 0 | X13: =H13 -> 0 | Y13: =G13*(-1) -> 0 | Z13: =I13+J13 -> 0
A14: Terminas | B14: =IF(B10=B11,SUMPRODUCT(L3:L20,G3:G20)/SUM(G3:G20),"") -> 232.03093 | W14: =F14 -> 0 | X14: =H14 -> 0 | Y14: =G14*(-1) -> 0 | Z14: =I14+J14 -> 0
W15: =F15 -> 0 | X15: =H15 -> 0 | Y15: =G15*(-1) -> 0 | Z15: =I15+J15 -> 0
W16: =F16 -> 0 | X16: =H16 -> 0 | Y16: =G16*(-1) -> 0 | Z16: =I16+J16 -> 0
W17: =F17 -> 0 | X17: =H17 -> 0 | Y17: =G17*(-1) -> 0 | Z17: =I17+J17 -> 0
W18: =F18 -> 0 | X18: =H18 -> 0 | Y18: =G18*(-1) -> 0 | Z18: =I18+J18 -> 0
W19: =F19 -> 0 | X19: =H19 -> 0 | Y19: =G19*(-1) -> 0 | Z19: =I19+J19 -> 0
W20: =F20 -> 0 | X20: =H20 -> 0 | Y20: =G20*(-1) -> 0 | Z20: =I20+J20 -> 0

Sheet J042
A1: Mortgage loan ID | B1: J042 | E1: Note | F1: Investuota | H1: Grąžinimas
A2: Pavadinimas | B2: Apartment in Madrid | F2: Data | G2: Suma | H2: Grąž. Data | I2: Paskola | J2: Palūkanos | K2: Pelnas | L2: Laikas
A3: PTV | B3: 0.34 | D3: 1 | E3: LV0000104636 | F3: 45804 | G3: 0.9 | H3: =IF($B$9>0,$B$9,"") | L3: =IF($B$10=$B$11,H3-F3,"") | W3: =F3 -> 45804 | X3: =H3 | Y3: =G3*(-1) -> -0.9 | Z3: =I3+J3 -> 0
A4: PDT | B4: 0.58 | D4: 2 | E4: LV0000105385 | F4: 45846 | G4: 0.07 | H4: =IF($B$9>0,$B$9,"") | L4: =IF($B$10=$B$11,H4-F4,"") | W4: =F4 -> 45846 | X4: =H4 | Y4: =G4*(-1) -> -0.07 | Z4: =I4+J4 -> 0
H5: =IF($B$9>0,$B$9,"") | L5: =IF($B$10=$B$11,H5-F5,"") | W5: =F5 -> 0 | X5: =H5 | Y5: =G5*(-1) -> 0 | Z5: =I5+J5 -> 0
H6: =IF($B$9>0,$B$9,"") | L6: =IF($B$10=$B$11,H6-F6,"") | W6: =F6 -> 0 | X6: =H6 | Y6: =G6*(-1) -> 0 | Z6: =I6+J6 -> 0
A7: Investuota | B7: =SUMPRODUCT(F3:F20,G3:G20)/SUM(G3:G20) -> 45807.031 | H7: =IF($B$9>0,$B$9,"") | L7: =IF($B$10=$B$11,H7-F7,"") | W7: =F7 -> 0 | X7: =H7 | Y7: =G7*(-1) -> 0 | Z7: =I7+J7 -> 0
A8: Paskolos pradžia | B8: 45551 | H8: =IF($B$9>0,$B$9,"") | L8: =IF($B$10=$B$11,H8-F8,"") | W8: =F8 -> 0 | X8: =H8 | Y8: =G8*(-1) -> 0 | Z8: =I8+J8 -> 0
A9: Paskola grąžinta | H9: =IF($B$9>0,$B$9,"") | L9: =IF($B$10=$B$11,H9-F9,"") | W9: =F9 -> 0 | X9: =H9 | Y9: =G9*(-1) -> 0 | Z9: =I9+J9 -> 0
A10: Investuota | B10: =SUM(G3:G20) -> 0.97 | H10: =IF($B$9>0,$B$9,"") | L10: =IF($B$10=$B$11,H10-F10,"") | W10: =F10 -> 0 | X10: =H10 | Y10: =G10*(-1) -> 0 | Z10: =I10+J10 -> 0
A11: Grąžinta | B11: =SUM(I3:I20) -> 0 | W11: =F11 -> 0 | X11: =H11 -> 0 | Y11: =G11*(-1) -> 0 | Z11: =I11+J11 -> 0
A12: Palūkanos | B12: =SUM(J3:J20) -> 0 | W12: =F12 -> 0 | X12: =H12 -> 0 | Y12: =G12*(-1) -> 0 | Z12: =I12+J12 -> 0
A13: XIRR | B13: =IF(B10=B11,XIRR(Y3:Z20,W3:X20),"") | W13: =F13 -> 0 | X13: =H13 -> 0 | Y13: =G13*(-1) -> 0 | Z13: =I13+J13 -> 0
A14: Terminas | B14: =IF(B10=B11,SUMPRODUCT(L3:L20,G3:G20)/SUM(G3:G20),"") | W14: =F14 -> 0 | X14: =H14 -> 0 | Y14: =G14*(-1) -> 0 | Z14: =I14+J14 -> 0
W15: =F15 -> 0 | X15: =H15 -> 0 | Y15: =G15*(-1) -> 0 | Z15: =I15+J15 -> 0
W16: =F16 -> 0 | X16: =H16 -> 0 | Y16: =G16*(-1) -> 0 | Z16: =I16+J16 -> 0
W17: =F17 -> 0 | X17: =H17 -> 0 | Y17: =G17*(-1) -> 0 | Z17: =I17+J17 -> 0
W18: =F18 -> 0 | X18: =H18 -> 0 | Y18: =G18*(-1) -> 0 | Z18: =I18+J18 -> 0
W19: =F19 -> 0 | X19: =H19 -> 0 | Y19: =G19*(-1) -> 0 | Z19: =I19+J19 -> 0
W20: =F20 -> 0 | X20: =H20 -> 0 | Y20: =G20*(-1) -> 0 | Z20: =I20+J20 -> 0

Sheet J043
A1: Mortgage loan ID | B1: J043 | E1: Note | F1: Investuota | H1: Grąžinimas
A2: Pavadinimas | B2: House in Elche | F2: Data | G2: Suma | H2: Grąž. Data | I2: Paskola | J2: Palūkanos | K2: Pelnas | L2: Laikas
A3: PTV | B3: 0.63 | D3: 1 | E3: LV0000105799 | F3: 45867 | G3: 0.5 | H3: =IF($B$9>0,$B$9,"") | L3: =IF($B$10=$B$11,H3-F3,"") | W3: =F3 -> 45867 | X3: =H3 | Y3: =G3*(-1) -> -0.5 | Z3: =I3+J3 -> 0
A4: PDT | B4: 0.34 | D4: 2 | E4: LV0000105807 | F4: 45867 | G4: 0.59 | H4: =IF($B$9>0,$B$9,"") | L4: =IF($B$10=$B$11,H4-F4,"") | W4: =F4 -> 45867 | X4: =H4 | Y4: =G4*(-1) -> -0.59 | Z4: =I4+J4 -> 0
H5: =IF($B$9>0,$B$9,"") | L5: =IF($B$10=$B$11,H5-F5,"") | W5: =F5 -> 0 | X5: =H5 | Y5: =G5*(-1) -> 0 | Z5: =I5+J5 -> 0
H6: =IF($B$9>0,$B$9,"") | L6: =IF($B$10=$B$11,H6-F6,"") | W6: =F6 -> 0 | X6: =H6 | Y6: =G6*(-1) -> 0 | Z6: =I6+J6 -> 0
A7: Investuota | B7: =SUMPRODUCT(F3:F20,G3:G20)/SUM(G3:G20) -> 45867 | H7: =IF($B$9>0,$B$9,"") | L7: =IF($B$10=$B$11,H7-F7,"") | W7: =F7 -> 0 | X7: =H7 | Y7: =G7*(-1) -> 0 | Z7: =I7+J7 -> 0
A8: Paskolos pradžia | B8: 45551 | H8: =IF($B$9>0,$B$9,"") | L8: =IF($B$10=$B$11,H8-F8,"") | W8: =F8 -> 0 | X8: =H8 | Y8: =G8*(-1) -> 0 | Z8: =I8+J8 -> 0
A9: Paskola grąžinta | H9: =IF($B$9>0,$B$9,"") | L9: =IF($B$10=$B$11,H9-F9,"") | W9: =F9 -> 0 | X9: =H9 | Y9: =G9*(-1) -> 0 | Z9: =I9+J9 -> 0
A10: Investuota | B10: =SUM(G3:G20) -> 1.09 | H10: =IF($B$9>0,$B$9,"") | L10: =IF($B$10=$B$11,H10-F10,"") | W10: =F10 -> 0 | X10: =H10 | Y10: =G10*(-1) -> 0 | Z10: =I10+J10 -> 0
A11: Grąžinta | B11: =SUM(I3:I20) -> 0 | W11: =F11 -> 0 | X11: =H11 -> 0 | Y11: =G11*(-1) -> 0 | Z11: =I11+J11 -> 0
A12: Palūkanos | B12: =SUM(J3:J20) -> 0 | W12: =F12 -> 0 | X12: =H12 -> 0 | Y12: =G12*(-1) -> 0 | Z12: =I12+J12 -> 0
A13: XIRR | B13: =IF(B10=B11,XIRR(Y3:Z20,W3:X20),"") | W13: =F13 -> 0 | X13: =H13 -> 0 | Y13: =G13*(-1) -> 0 | Z13: =I13+J13 -> 0
A14: Terminas | B14: =IF(B10=B11,SUMPRODUCT(L3:L20,G3:G20)/SUM(G3:G20),"") | W14: =F14 -> 0 | X14: =H14 -> 0 | Y14: =G14*(-1) -> 0 | Z14: =I14+J14 -> 0
W15: =F15 -> 0 | X15: =H15 -> 0 | Y15: =G15*(-1) -> 0 | Z15: =I15+J15 -> 0
W16: =F16 -> 0 | X16: =H16 -> 0 | Y16: =G16*(-1) -> 0 | Z16: =I16+J16 -> 0
W17: =F17 -> 0 | X17: =H17 -> 0 | Y17: =G17*(-1) -> 0 | Z17: =I17+J17 -> 0
W18: =F18 -> 0 | X18: =H18 -> 0 | Y18: =G18*(-1) -> 0 | Z18: =I18+J18 -> 0
W19: =F19 -> 0 | X19: =H19 -> 0 | Y19: =G19*(-1) -> 0 | Z19: =I19+J19 -> 0
W20: =F20 -> 0 | X20: =H20 -> 0 | Y20: =G20*(-1) -> 0 | Z20: =I20+J20 -> 0

Sheet J044
A1: Mortgage loan ID | B1: J044 | E1: Note | F1: Investuota | H1: Grąžinimas
A2: Pavadinimas | B2: Apartment in Adeje | F2: Data | G2: Suma | H2: Grąž. Data | I2: Paskola | J2: Palūkanos | K2: Pelnas | L2: Laikas
A3: PTV | B3: 0.2 | D3: 1 | E3: LV0000103612 | F3: 45741 | G3: 2.61 | H3: =IF($B$9>0,$B$9,"") -> 46169 | I3: 2.61 | J3: 0.44 | K3: 0.1452 | L3: =IF($B$10=$B$11,H3-F3,"") -> 428 | W3: =F3 -> 45741 | X3: =H3 -> 46169 | Y3: =G3*(-1) -> -2.61 | Z3: =I3+J3 -> 3.05
A4: PDT | B4: 0.64 | D4: 2 | E4: LV0000103752 | F4: 45748 | G4: 0.23 | H4: =IF($B$9>0,$B$9,"") -> 46169 | I4: 0.23 | J4: 0.03 | K4: 0.1477 | L4: =IF($B$10=$B$11,H4-F4,"") -> 421 | W4: =F4 -> 45748 | X4: =H4 -> 46169 | Y4: =G4*(-1) -> -0.23 | Z4: =I4+J4 -> 0.26
D5: 3 | E5: LV0000103810 | F5: 45755 | G5: 0.27 | H5: =IF($B$9>0,$B$9,"") -> 46169 | I5: 0.27 | J5: 0.04 | K5: 0.1502 | L5: =IF($B$10=$B$11,H5-F5,"") -> 414 | W5: =F5 -> 45755 | X5: =H5 -> 46169 | Y5: =G5*(-1) -> -0.27 | Z5: =I5+J5 -> 0.31
W6: =F6 -> 0 | X6: =H6 -> 0 | Y6: =G6*(-1) -> 0 | Z6: =I6+J6 -> 0
A7: Investuota | B7: =SUMPRODUCT(F3:F20,G3:G20)/SUM(G3:G20) -> 45742.733 | W7: =F7 -> 0 | X7: =H7 -> 0 | Y7: =G7*(-1) -> 0 | Z7: =I7+J7 -> 0
A8: Paskolos pradžia | B8: 45551 | W8: =F8 -> 0 | X8: =H8 -> 0 | Y8: =G8*(-1) -> 0 | Z8: =I8+J8 -> 0
A9: Paskola grąžinta | B9: 46169 | W9: =F9 -> 0 | X9: =H9 -> 0 | Y9: =G9*(-1) -> 0 | Z9: =I9+J9 -> 0
A10: Investuota | B10: =SUM(G3:G20) -> 3.11 | W10: =F10 -> 0 | X10: =H10 -> 0 | Y10: =G10*(-1) -> 0 | Z10: =I10+J10 -> 0
A11: Grąžinta | B11: =SUM(I3:I20) -> 3.11 | W11: =F11 -> 0 | X11: =H11 -> 0 | Y11: =G11*(-1) -> 0 | Z11: =I11+J11 -> 0
A12: Palūkanos | B12: =SUM(J3:J20) -> 0.51 | W12: =F12 -> 0 | X12: =H12 -> 0 | Y12: =G12*(-1) -> 0 | Z12: =I12+J12 -> 0
A13: XIRR | B13: =IF(B10=B11,XIRR(Y3:Z20,W3:X20),"") -> 0.13885676 | W13: =F13 -> 0 | X13: =H13 -> 0 | Y13: =G13*(-1) -> 0 | Z13: =I13+J13 -> 0
A14: Terminas | B14: =IF(B10=B11,SUMPRODUCT(L3:L20,G3:G20)/SUM(G3:G20),"") -> 426.26688 | W14: =F14 -> 0 | X14: =H14 -> 0 | Y14: =G14*(-1) -> 0 | Z14: =I14+J14 -> 0
W15: =F15 -> 0 | X15: =H15 -> 0 | Y15: =G15*(-1) -> 0 | Z15: =I15+J15 -> 0
W16: =F16 -> 0 | X16: =H16 -> 0 | Y16: =G16*(-1) -> 0 | Z16: =I16+J16 -> 0
W17: =F17 -> 0 | X17: =H17 -> 0 | Y17: =G17*(-1) -> 0 | Z17: =I17+J17 -> 0
W18: =F18 -> 0 | X18: =H18 -> 0 | Y18: =G18*(-1) -> 0 | Z18: =I18+J18 -> 0
W19: =F19 -> 0 | X19: =H19 -> 0 | Y19: =G19*(-1) -> 0 | Z19: =I19+J19 -> 0
W20: =F20 -> 0 | X20: =H20 -> 0 | Y20: =G20*(-1) -> 0 | Z20: =I20+J20 -> 0

Sheet J046
A1: Mortgage loan ID | B1: J046 | E1: Note | F1: Investuota | H1: Grąžinimas
A2: Pavadinimas | B2: House in Torrevieja | F2: Data | G2: Suma | H2: Grąž. Data | I2: Paskola | J2: Palūkanos | K2: Pelnas | L2: Laikas
A3: PTV | B3: 0.58 | D3: 1 | E3: LV0000103620 | F3: 45741 | G3: 3.92 | H3: =IF($B$9>0,$B$9,"") | L3: =IF($B$10=$B$11,H3-F3,"") | W3: =F3 -> 45741 | X3: =H3 | Y3: =G3*(-1) -> -3.92 | Z3: =I3+J3 -> 0
A4: PDT | B4: 0.52 | D4: 2 | E4: LV0000103612 | F4: 45741 | G4: 5.96 | H4: =IF($B$9>0,$B$9,"") | L4: =IF($B$10=$B$11,H4-F4,"") | W4: =F4 -> 45741 | X4: =H4 | Y4: =G4*(-1) -> -5.96 | Z4: =I4+J4 -> 0
D5: 3 | E5: LV0000103745 | F5: 45748 | G5: 2.03 | H5: =IF($B$9>0,$B$9,"") | L5: =IF($B$10=$B$11,H5-F5,"") | W5: =F5 -> 45748 | X5: =H5 | Y5: =G5*(-1) -> -2.03 | Z5: =I5+J5 -> 0
D6: 4 | E6: LV0000103752 | F6: 45748 | G6: 1.33 | H6: =IF($B$9>0,$B$9,"") | L6: =IF($B$10=$B$11,H6-F6,"") | W6: =F6 -> 45748 | X6: =H6 | Y6: =G6*(-1) -> -1.33 | Z6: =I6+J6 -> 0
A7: Investuota | B7: =SUMPRODUCT(F3:F20,G3:G20)/SUM(G3:G20) -> 45744.046 | D7: 5 | E7: LV0000103828 | F7: 45755 | G7: 1.39 | H7: =IF($B$9>0,$B$9,"") | L7: =IF($B$10=$B$11,H7-F7,"") | W7: =F7 -> 45755 | X7: =H7 | Y7: =G7*(-1) -> -1.39 | Z7: =I7+J7 -> 0
A8: Paskolos pradžia | B8: 45551 | D8: 6 | E8: LV0000104586 | F8: 45797 | G8: 0.03 | H8: =IF($B$9>0,$B$9,"") | L8: =IF($B$10=$B$11,H8-F8,"") | W8: =F8 -> 45797 | X8: =H8 | Y8: =G8*(-1) -> -0.03 | Z8: =I8+J8 -> 0
A9: Paskola grąžinta | H9: =IF($B$9>0,$B$9,"") | L9: =IF($B$10=$B$11,H9-F9,"") | W9: =F9 -> 0 | X9: =H9 | Y9: =G9*(-1) -> 0 | Z9: =I9+J9 -> 0
A10: Investuota | B10: =SUM(G3:G20) -> 14.66 | H10: =IF($B$9>0,$B$9,"") | L10: =IF($B$10=$B$11,H10-F10,"") | W10: =F10 -> 0 | X10: =H10 | Y10: =G10*(-1) -> 0 | Z10: =I10+J10 -> 0
A11: Grąžinta | B11: =SUM(I3:I20) -> 0 | W11: =F11 -> 0 | X11: =H11 -> 0 | Y11: =G11*(-1) -> 0 | Z11: =I11+J11 -> 0
A12: Palūkanos | B12: =SUM(J3:J20) -> 0 | W12: =F12 -> 0 | X12: =H12 -> 0 | Y12: =G12*(-1) -> 0 | Z12: =I12+J12 -> 0
A13: XIRR | B13: =IF(B10=B11,XIRR(Y3:Z20,W3:X20),"") | W13: =F13 -> 0 | X13: =H13 -> 0 | Y13: =G13*(-1) -> 0 | Z13: =I13+J13 -> 0
A14: Terminas | B14: =IF(B10=B11,SUMPRODUCT(L3:L20,G3:G20)/SUM(G3:G20),"") | W14: =F14 -> 0 | X14: =H14 -> 0 | Y14: =G14*(-1) -> 0 | Z14: =I14+J14 -> 0
W15: =F15 -> 0 | X15: =H15 -> 0 | Y15: =G15*(-1) -> 0 | Z15: =I15+J15 -> 0
W16: =F16 -> 0 | X16: =H16 -> 0 | Y16: =G16*(-1) -> 0 | Z16: =I16+J16 -> 0
W17: =F17 -> 0 | X17: =H17 -> 0 | Y17: =G17*(-1) -> 0 | Z17: =I17+J17 -> 0
W18: =F18 -> 0 | X18: =H18 -> 0 | Y18: =G18*(-1) -> 0 | Z18: =I18+J18 -> 0
W19: =F19 -> 0 | X19: =H19 -> 0 | Y19: =G19*(-1) -> 0 | Z19: =I19+J19 -> 0
W20: =F20 -> 0 | X20: =H20 -> 0 | Y20: =G20*(-1) -> 0 | Z20: =I20+J20 -> 0

Sheet J048
A1: Mortgage loan ID | B1: J048 | E1: Note | F1: Investuota | H1: Grąžinimas
A2: Pavadinimas | B2: Apartment in Roquetas de Mar | F2: Data | G2: Suma | H2: Grąž. Data | I2: Paskola | J2: Palūkanos | K2: Pelnas | L2: Laikas
A3: PTV | B3: 0.57 | D3: 1 | E3: LV0000103935 | F3: 45755 | G3: 0.94 | H3: =IF($B$9>0,$B$9,"") | L3: =IF($B$10=$B$11,H3-F3,"") | W3: =F3 -> 45755 | X3: =H3 | Y3: =G3*(-1) -> -0.94 | Z3: =I3+J3 -> 0
A4: PDT | B4: 0.51 | D4: 2 | E4: LV0000103927 | F4: 45755 | G4: 1 | H4: =IF($B$9>0,$B$9,"") | L4: =IF($B$10=$B$11,H4-F4,"") | W4: =F4 -> 45755 | X4: =H4 | Y4: =G4*(-1) -> -1 | Z4: =I4+J4 -> 0
D5: 3 | E5: LV0000103950 | F5: 45762 | G5: 1.24 | H5: =IF($B$9>0,$B$9,"") | L5: =IF($B$10=$B$11,H5-F5,"") | W5: =F5 -> 45762 | X5: =H5 | Y5: =G5*(-1) -> -1.24 | Z5: =I5+J5 -> 0
D6: 4 | E6: LV0000103976 | F6: 45762 | G6: 1.9 | H6: =IF($B$9>0,$B$9,"") | L6: =IF($B$10=$B$11,H6-F6,"") | W6: =F6 -> 45762 | X6: =H6 | Y6: =G6*(-1) -> -1.9 | Z6: =I6+J6 -> 0
A7: Investuota | B7: =SUMPRODUCT(F3:F20,G3:G20)/SUM(G3:G20) -> 45763.078 | D7: 5 | E7: LV0000104107 | F7: 45769 | G7: 1.2 | H7: =IF($B$9>0,$B$9,"") | L7: =IF($B$10=$B$11,H7-F7,"") | W7: =F7 -> 45769 | X7: =H7 | Y7: =G7*(-1) -> -1.2 | Z7: =I7+J7 -> 0
A8: Paskolos pradžia | B8: 45551 | D8: 6 | E8: LV0000104198 | F8: 45776 | G8: 0.4 | H8: =IF($B$9>0,$B$9,"") | L8: =IF($B$10=$B$11,H8-F8,"") | W8: =F8 -> 45776 | X8: =H8 | Y8: =G8*(-1) -> -0.4 | Z8: =I8+J8 -> 0
A9: Paskola grąžinta | D9: 7 | E9: LV0000104560 | F9: 45797 | G9: 0.2 | H9: =IF($B$9>0,$B$9,"") | L9: =IF($B$10=$B$11,H9-F9,"") | W9: =F9 -> 45797 | X9: =H9 | Y9: =G9*(-1) -> -0.2 | Z9: =I9+J9 -> 0
A10: Investuota | B10: =SUM(G3:G20) -> 6.88 | H10: =IF($B$9>0,$B$9,"") | L10: =IF($B$10=$B$11,H10-F10,"") | W10: =F10 -> 0 | X10: =H10 | Y10: =G10*(-1) -> 0 | Z10: =I10+J10 -> 0
A11: Grąžinta | B11: =SUM(I3:I20) -> 0 | W11: =F11 -> 0 | X11: =H11 -> 0 | Y11: =G11*(-1) -> 0 | Z11: =I11+J11 -> 0
A12: Palūkanos | B12: =SUM(J3:J20) -> 0 | W12: =F12 -> 0 | X12: =H12 -> 0 | Y12: =G12*(-1) -> 0 | Z12: =I12+J12 -> 0
A13: XIRR | B13: =IF(B10=B11,XIRR(Y3:Z20,W3:X20),"") | W13: =F13 -> 0 | X13: =H13 -> 0 | Y13: =G13*(-1) -> 0 | Z13: =I13+J13 -> 0
A14: Terminas | B14: =IF(B10=B11,SUMPRODUCT(L3:L20,G3:G20)/SUM(G3:G20),"") | W14: =F14 -> 0 | X14: =H14 -> 0 | Y14: =G14*(-1) -> 0 | Z14: =I14+J14 -> 0
W15: =F15 -> 0 | X15: =H15 -> 0 | Y15: =G15*(-1) -> 0 | Z15: =I15+J15 -> 0
W16: =F16 -> 0 | X16: =H16 -> 0 | Y16: =G16*(-1) -> 0 | Z16: =I16+J16 -> 0
W17: =F17 -> 0 | X17: =H17 -> 0 | Y17: =G17*(-1) -> 0 | Z17: =I17+J17 -> 0
W18: =F18 -> 0 | X18: =H18 -> 0 | Y18: =G18*(-1) -> 0 | Z18: =I18+J18 -> 0
W19: =F19 -> 0 | X19: =H19 -> 0 | Y19: =G19*(-1) -> 0 | Z19: =I19+J19 -> 0
W20: =F20 -> 0 | X20: =H20 -> 0 | Y20: =G20*(-1) -> 0 | Z20: =I20+J20 -> 0

Sheet J049
A1: Mortgage loan ID | B1: J049 | E1: Note | F1: Investuota | H1: Grąžinimas
A2: Pavadinimas | B2: House in Fines | F2: Data | G2: Suma | H2: Grąž. Data | I2: Paskola | J2: Palūkanos | K2: Pelnas | L2: Laikas
A3: PTV | B3: 0.58 | D3: 1 | E3: LV0000103927 | F3: 45755 | G3: 0.43 | H3: =IF($B$9>0,$B$9,"") | L3: =IF($B$10=$B$11,H3-F3,"") | W3: =F3 -> 45755 | X3: =H3 | Y3: =G3*(-1) -> -0.43 | Z3: =I3+J3 -> 0
A4: PDT | B4: 0.38 | D4: 2 | E4: LV0000103950 | F4: 45762 | G4: 0.67 | H4: =IF($B$9>0,$B$9,"") | L4: =IF($B$10=$B$11,H4-F4,"") | W4: =F4 -> 45762 | X4: =H4 | Y4: =G4*(-1) -> -0.67 | Z4: =I4+J4 -> 0
D5: 3 | E5: LV0000103976 | F5: 45762 | G5: 0.14 | H5: =IF($B$9>0,$B$9,"") | L5: =IF($B$10=$B$11,H5-F5,"") | W5: =F5 -> 45762 | X5: =H5 | Y5: =G5*(-1) -> -0.14 | Z5: =I5+J5 -> 0
D6: 4 | E6: LV0000103968 | F6: 45762 | G6: 0.6 | H6: =IF($B$9>0,$B$9,"") | L6: =IF($B$10=$B$11,H6-F6,"") | W6: =F6 -> 45762 | X6: =H6 | Y6: =G6*(-1) -> -0.6 | Z6: =I6+J6 -> 0
A7: Investuota | B7: =SUMPRODUCT(F3:F20,G3:G20)/SUM(G3:G20) -> 45771.37 | D7: 5 | E7: LV0000104198 | F7: 45776 | G7: 0.44 | H7: =IF($B$9>0,$B$9,"") | L7: =IF($B$10=$B$11,H7-F7,"") | W7: =F7 -> 45776 | X7: =H7 | Y7: =G7*(-1) -> -0.44 | Z7: =I7+J7 -> 0
A8: Paskolos pradžia | B8: 45551 | D8: 6 | E8: LV0000104297 | F8: 45783 | G8: 0.42 | H8: =IF($B$9>0,$B$9,"") | L8: =IF($B$10=$B$11,H8-F8,"") | W8: =F8 -> 45783 | X8: =H8 | Y8: =G8*(-1) -> -0.42 | Z8: =I8+J8 -> 0
A9: Paskola grąžinta | D9: 7 | E9: LV0000104578 | F9: 45797 | G9: 0.52 | H9: =IF($B$9>0,$B$9,"") | L9: =IF($B$10=$B$11,H9-F9,"") | W9: =F9 -> 45797 | X9: =H9 | Y9: =G9*(-1) -> -0.52 | Z9: =I9+J9 -> 0
A10: Investuota | B10: =SUM(G3:G20) -> 3.22 | H10: =IF($B$9>0,$B$9,"") | L10: =IF($B$10=$B$11,H10-F10,"") | W10: =F10 -> 0 | X10: =H10 | Y10: =G10*(-1) -> 0 | Z10: =I10+J10 -> 0
A11: Grąžinta | B11: =SUM(I3:I20) -> 0 | W11: =F11 -> 0 | X11: =H11 -> 0 | Y11: =G11*(-1) -> 0 | Z11: =I11+J11 -> 0
A12: Palūkanos | B12: =SUM(J3:J20) -> 0 | W12: =F12 -> 0 | X12: =H12 -> 0 | Y12: =G12*(-1) -> 0 | Z12: =I12+J12 -> 0
A13: XIRR | B13: =IF(B10=B11,XIRR(Y3:Z20,W3:X20),"") | W13: =F13 -> 0 | X13: =H13 -> 0 | Y13: =G13*(-1) -> 0 | Z13: =I13+J13 -> 0
A14: Terminas | B14: =IF(B10=B11,SUMPRODUCT(L3:L20,G3:G20)/SUM(G3:G20),"") | W14: =F14 -> 0 | X14: =H14 -> 0 | Y14: =G14*(-1) -> 0 | Z14: =I14+J14 -> 0
W15: =F15 -> 0 | X15: =H15 -> 0 | Y15: =G15*(-1) -> 0 | Z15: =I15+J15 -> 0
W16: =F16 -> 0 | X16: =H16 -> 0 | Y16: =G16*(-1) -> 0 | Z16: =I16+J16 -> 0
W17: =F17 -> 0 | X17: =H17 -> 0 | Y17: =G17*(-1) -> 0 | Z17: =I17+J17 -> 0
W18: =F18 -> 0 | X18: =H18 -> 0 | Y18: =G18*(-1) -> 0 | Z18: =I18+J18 -> 0
W19: =F19 -> 0 | X19: =H19 -> 0 | Y19: =G19*(-1) -> 0 | Z19: =I19+J19 -> 0
W20: =F20 -> 0 | X20: =H20 -> 0 | Y20: =G20*(-1) -> 0 | Z20: =I20+J20 -> 0

Sheet J050
A1: Mortgage loan ID | B1: J050 | E1: Note | F1: Investuota | H1: Grąžinimas
A2: Pavadinimas | B2: Apartment in Almeria | F2: Data | G2: Suma | H2: Grąž. Data | I2: Paskola | J2: Palūkanos | K2: Pelnas | L2: Laikas
A3: PTV | B3: 0.58 | D3: 1 | E3: LV0000103927 | F3: 45755 | G3: 0.75 | H3: =IF($B$9>0,$B$9,"") | L3: =IF($B$10=$B$11,H3-F3,"") | W3: =F3 -> 45755 | X3: =H3 | Y3: =G3*(-1) -> -0.75 | Z3: =I3+J3 -> 0
A4: PDT | B4: 0.22 | D4: 2 | E4: LV0000103950 | F4: 45762 | G4: 1.17 | H4: =IF($B$9>0,$B$9,"") | L4: =IF($B$10=$B$11,H4-F4,"") | W4: =F4 -> 45762 | X4: =H4 | Y4: =G4*(-1) -> -1.17 | Z4: =I4+J4 -> 0
D5: 3 | E5: LV0000103968 | F5: 45762 | G5: 1.04 | H5: =IF($B$9>0,$B$9,"") | L5: =IF($B$10=$B$11,H5-F5,"") | W5: =F5 -> 45762 | X5: =H5 | Y5: =G5*(-1) -> -1.04 | Z5: =I5+J5 -> 0
D6: 4 | E6: LV0000104198 | F6: 45776 | G6: 0.76 | H6: =IF($B$9>0,$B$9,"") | L6: =IF($B$10=$B$11,H6-F6,"") | W6: =F6 -> 45776 | X6: =H6 | Y6: =G6*(-1) -> -0.76 | Z6: =I6+J6 -> 0
A7: Investuota | B7: =SUMPRODUCT(F3:F20,G3:G20)/SUM(G3:G20) -> 45770.887 | D7: 5 | E7: LV0000104297 | F7: 45783 | G7: 0.89 | H7: =IF($B$9>0,$B$9,"") | L7: =IF($B$10=$B$11,H7-F7,"") | W7: =F7 -> 45783 | X7: =H7 | Y7: =G7*(-1) -> -0.89 | Z7: =I7+J7 -> 0
A8: Paskolos pradžia | B8: 45551 | D8: 6 | E8: LV0000104628 | F8: 45804 | G8: 0.51 | H8: =IF($B$9>0,$B$9,"") | L8: =IF($B$10=$B$11,H8-F8,"") | W8: =F8 -> 45804 | X8: =H8 | Y8: =G8*(-1) -> -0.51 | Z8: =I8+J8 -> 0
A9: Paskola grąžinta | H9: =IF($B$9>0,$B$9,"") | L9: =IF($B$10=$B$11,H9-F9,"") | W9: =F9 -> 0 | X9: =H9 | Y9: =G9*(-1) -> 0 | Z9: =I9+J9 -> 0
A10: Investuota | B10: =SUM(G3:G20) -> 5.12 | H10: =IF($B$9>0,$B$9,"") | L10: =IF($B$10=$B$11,H10-F10,"") | W10: =F10 -> 0 | X10: =H10 | Y10: =G10*(-1) -> 0 | Z10: =I10+J10 -> 0
A11: Grąžinta | B11: =SUM(I3:I20) -> 0 | W11: =F11 -> 0 | X11: =H11 -> 0 | Y11: =G11*(-1) -> 0 | Z11: =I11+J11 -> 0
A12: Palūkanos | B12: =SUM(J3:J20) -> 0 | W12: =F12 -> 0 | X12: =H12 -> 0 | Y12: =G12*(-1) -> 0 | Z12: =I12+J12 -> 0
A13: XIRR | B13: =IF(B10=B11,XIRR(Y3:Z20,W3:X20),"") | W13: =F13 -> 0 | X13: =H13 -> 0 | Y13: =G13*(-1) -> 0 | Z13: =I13+J13 -> 0
A14: Terminas | B14: =IF(B10=B11,SUMPRODUCT(L3:L20,G3:G20)/SUM(G3:G20),"") | W14: =F14 -> 0 | X14: =H14 -> 0 | Y14: =G14*(-1) -> 0 | Z14: =I14+J14 -> 0
W15: =F15 -> 0 | X15: =H15 -> 0 | Y15: =G15*(-1) -> 0 | Z15: =I15+J15 -> 0
W16: =F16 -> 0 | X16: =H16 -> 0 | Y16: =G16*(-1) -> 0 | Z16: =I16+J16 -> 0
W17: =F17 -> 0 | X17: =H17 -> 0 | Y17: =G17*(-1) -> 0 | Z17: =I17+J17 -> 0
W18: =F18 -> 0 | X18: =H18 -> 0 | Y18: =G18*(-1) -> 0 | Z18: =I18+J18 -> 0
W19: =F19 -> 0 | X19: =H19 -> 0 | Y19: =G19*(-1) -> 0 | Z19: =I19+J19 -> 0
W20: =F20 -> 0 | X20: =H20 -> 0 | Y20: =G20*(-1) -> 0 | Z20: =I20+J20 -> 0

Sheet J051
A1: Mortgage loan ID | B1: J051 | E1: Note | F1: Investuota | H1: Grąžinimas
A2: Pavadinimas | B2: House in Aznalcázar | F2: Data | G2: Suma | H2: Grąž. Data | I2: Paskola | J2: Palūkanos | K2: Pelnas | L2: Laikas
A3: PTV | B3: 0.53 | D3: 1 | E3: LV0000104107 | F3: 45769 | G3: 0.21 | H3: =IF($B$9>0,$B$9,"") -> 46099 | I3: 0.21 | J3: 0.03 | K3: 0.1791 | L3: =IF($B$10=$B$11,H3-F3,"") -> 330 | W3: =F3 -> 45769 | X3: =H3 -> 46099 | Y3: =G3*(-1) -> -0.21 | Z3: =I3+J3 -> 0.24
A4: PDT | B4: 0.13 | W4: =F4 -> 0 | X4: =H4 -> 0 | Y4: =G4*(-1) -> 0 | Z4: =I4+J4 -> 0
W5: =F5 -> 0 | X5: =H5 -> 0 | Y5: =G5*(-1) -> 0 | Z5: =I5+J5 -> 0
W6: =F6 -> 0 | X6: =H6 -> 0 | Y6: =G6*(-1) -> 0 | Z6: =I6+J6 -> 0
A7: Investuota | B7: =SUMPRODUCT(F3:F20,G3:G20)/SUM(G3:G20) -> 45769 | W7: =F7 -> 0 | X7: =H7 -> 0 | Y7: =G7*(-1) -> 0 | Z7: =I7+J7 -> 0
A8: Paskolos pradžia | B8: 45551 | W8: =F8 -> 0 | X8: =H8 -> 0 | Y8: =G8*(-1) -> 0 | Z8: =I8+J8 -> 0
A9: Paskola grąžinta | B9: 46099 | W9: =F9 -> 0 | X9: =H9 -> 0 | Y9: =G9*(-1) -> 0 | Z9: =I9+J9 -> 0
A10: Investuota | B10: =SUM(G3:G20) -> 0.21 | W10: =F10 -> 0 | X10: =H10 -> 0 | Y10: =G10*(-1) -> 0 | Z10: =I10+J10 -> 0
A11: Grąžinta | B11: =SUM(I3:I20) -> 0.21 | W11: =F11 -> 0 | X11: =H11 -> 0 | Y11: =G11*(-1) -> 0 | Z11: =I11+J11 -> 0
A12: Palūkanos | B12: =SUM(J3:J20) -> 0.03 | W12: =F12 -> 0 | X12: =H12 -> 0 | Y12: =G12*(-1) -> 0 | Z12: =I12+J12 -> 0
A13: XIRR | B13: =IF(B10=B11,XIRR(Y3:Z20,W3:X20),"") -> 0.15915793 | W13: =F13 -> 0 | X13: =H13 -> 0 | Y13: =G13*(-1) -> 0 | Z13: =I13+J13 -> 0
A14: Terminas | B14: =IF(B10=B11,SUMPRODUCT(L3:L20,G3:G20)/SUM(G3:G20),"") -> 330 | W14: =F14 -> 0 | X14: =H14 -> 0 | Y14: =G14*(-1) -> 0 | Z14: =I14+J14 -> 0
W15: =F15 -> 0 | X15: =H15 -> 0 | Y15: =G15*(-1) -> 0 | Z15: =I15+J15 -> 0
W16: =F16 -> 0 | X16: =H16 -> 0 | Y16: =G16*(-1) -> 0 | Z16: =I16+J16 -> 0
W17: =F17 -> 0 | X17: =H17 -> 0 | Y17: =G17*(-1) -> 0 | Z17: =I17+J17 -> 0
W18: =F18 -> 0 | X18: =H18 -> 0 | Y18: =G18*(-1) -> 0 | Z18: =I18+J18 -> 0
W19: =F19 -> 0 | X19: =H19 -> 0 | Y19: =G19*(-1) -> 0 | Z19: =I19+J19 -> 0
W20: =F20 -> 0 | X20: =H20 -> 0 | Y20: =G20*(-1) -> 0 | Z20: =I20+J20 -> 0

Sheet J052
A1: Mortgage loan ID | B1: J052 | E1: Note | F1: Investuota | H1: Grąžinimas
A2: Pavadinimas | B2: Apartment on Ronda de los Tejares | F2: Data | G2: Suma | H2: Grąž. Data | I2: Paskola | J2: Palūkanos | K2: Pelnas | L2: Laikas
A3: PTV | B3: 0.37 | D3: 1 | E3: LV0000103620 | F3: 45741 | G3: 3.92 | H3: =IF($B$9>0,$B$9,"") | L3: =IF($B$10=$B$11,H3-F3,"") | W3: =F3 -> 45741 | X3: =H3 | Y3: =G3*(-1) -> -3.92 | Z3: =I3+J3 -> 0
A4: PDT | B4: 0.68 | D4: 2 | E4: LV0000103612 | F4: 45741 | G4: 5.96 | H4: =IF($B$9>0,$B$9,"") | L4: =IF($B$10=$B$11,H4-F4,"") | W4: =F4 -> 45741 | X4: =H4 | Y4: =G4*(-1) -> -5.96 | Z4: =I4+J4 -> 0
D5: 3 | E5: LV0000103745 | F5: 45748 | G5: 2.13 | H5: =IF($B$9>0,$B$9,"") | L5: =IF($B$10=$B$11,H5-F5,"") | W5: =F5 -> 45748 | X5: =H5 | Y5: =G5*(-1) -> -2.13 | Z5: =I5+J5 -> 0
D6: 4 | E6: LV0000103752 | F6: 45748 | G6: 1.26 | H6: =IF($B$9>0,$B$9,"") | L6: =IF($B$10=$B$11,H6-F6,"") | W6: =F6 -> 45748 | X6: =H6 | Y6: =G6*(-1) -> -1.26 | Z6: =I6+J6 -> 0
A7: Investuota | B7: =SUMPRODUCT(F3:F20,G3:G20)/SUM(G3:G20) -> 45743.946 | D7: 5 | E7: LV0000103828 | F7: 45755 | G7: 1.39 | H7: =IF($B$9>0,$B$9,"") | L7: =IF($B$10=$B$11,H7-F7,"") | W7: =F7 -> 45755 | X7: =H7 | Y7: =G7*(-1) -> -1.39 | Z7: =I7+J7 -> 0
A8: Paskolos pradžia | B8: 45551 | H8: =IF($B$9>0,$B$9,"") | L8: =IF($B$10=$B$11,H8-F8,"") | W8: =F8 -> 0 | X8: =H8 | Y8: =G8*(-1) -> 0 | Z8: =I8+J8 -> 0
A9: Paskola grąžinta | H9: =IF($B$9>0,$B$9,"") | L9: =IF($B$10=$B$11,H9-F9,"") | W9: =F9 -> 0 | X9: =H9 | Y9: =G9*(-1) -> 0 | Z9: =I9+J9 -> 0
A10: Investuota | B10: =SUM(G3:G20) -> 14.66 | H10: =IF($B$9>0,$B$9,"") | L10: =IF($B$10=$B$11,H10-F10,"") | W10: =F10 -> 0 | X10: =H10 | Y10: =G10*(-1) -> 0 | Z10: =I10+J10 -> 0
A11: Grąžinta | B11: =SUM(I3:I20) -> 0 | W11: =F11 -> 0 | X11: =H11 -> 0 | Y11: =G11*(-1) -> 0 | Z11: =I11+J11 -> 0
A12: Palūkanos | B12: =SUM(J3:J20) -> 0 | W12: =F12 -> 0 | X12: =H12 -> 0 | Y12: =G12*(-1) -> 0 | Z12: =I12+J12 -> 0
A13: XIRR | B13: =IF(B10=B11,XIRR(Y3:Z20,W3:X20),"") | W13: =F13 -> 0 | X13: =H13 -> 0 | Y13: =G13*(-1) -> 0 | Z13: =I13+J13 -> 0
A14: Terminas | B14: =IF(B10=B11,SUMPRODUCT(L3:L20,G3:G20)/SUM(G3:G20),"") | W14: =F14 -> 0 | X14: =H14 -> 0 | Y14: =G14*(-1) -> 0 | Z14: =I14+J14 -> 0
W15: =F15 -> 0 | X15: =H15 -> 0 | Y15: =G15*(-1) -> 0 | Z15: =I15+J15 -> 0
W16: =F16 -> 0 | X16: =H16 -> 0 | Y16: =G16*(-1) -> 0 | Z16: =I16+J16 -> 0
W17: =F17 -> 0 | X17: =H17 -> 0 | Y17: =G17*(-1) -> 0 | Z17: =I17+J17 -> 0
W18: =F18 -> 0 | X18: =H18 -> 0 | Y18: =G18*(-1) -> 0 | Z18: =I18+J18 -> 0
W19: =F19 -> 0 | X19: =H19 -> 0 | Y19: =G19*(-1) -> 0 | Z19: =I19+J19 -> 0
W20: =F20 -> 0 | X20: =H20 -> 0 | Y20: =G20*(-1) -> 0 | Z20: =I20+J20 -> 0

Sheet J053
A1: Mortgage loan ID | B1: J053 | E1: Note | F1: Investuota | H1: Grąžinimas
A2: Pavadinimas | B2: Apartment in Vic | F2: Data | G2: Suma | H2: Grąž. Data | I2: Paskola | J2: Palūkanos | K2: Pelnas | L2: Laikas
A3: PTV | B3: 0.57 | D3: 1 | E3: LV0000103604 | F3: 45741 | G3: 3.22 | H3: =IF($B$9>0,$B$9,"") | L3: =IF($B$10=$B$11,H3-F3,"") | W3: =F3 -> 45741 | X3: =H3 | Y3: =G3*(-1) -> -3.22 | Z3: =I3+J3 -> 0
A4: PDT | B4: 0.48 | D4: 2 | E4: LV0000103810 | F4: 45755 | G4: 0.8 | H4: =IF($B$9>0,$B$9,"") | L4: =IF($B$10=$B$11,H4-F4,"") | W4: =F4 -> 45755 | X4: =H4 | Y4: =G4*(-1) -> -0.8 | Z4: =I4+J4 -> 0
H5: =IF($B$9>0,$B$9,"") | L5: =IF($B$10=$B$11,H5-F5,"") | W5: =F5 -> 0 | X5: =H5 | Y5: =G5*(-1) -> 0 | Z5: =I5+J5 -> 0
H6: =IF($B$9>0,$B$9,"") | L6: =IF($B$10=$B$11,H6-F6,"") | W6: =F6 -> 0 | X6: =H6 | Y6: =G6*(-1) -> 0 | Z6: =I6+J6 -> 0
A7: Investuota | B7: =SUMPRODUCT(F3:F20,G3:G20)/SUM(G3:G20) -> 45743.786 | H7: =IF($B$9>0,$B$9,"") | L7: =IF($B$10=$B$11,H7-F7,"") | W7: =F7 -> 0 | X7: =H7 | Y7: =G7*(-1) -> 0 | Z7: =I7+J7 -> 0
A8: Paskolos pradžia | B8: 45551 | H8: =IF($B$9>0,$B$9,"") | L8: =IF($B$10=$B$11,H8-F8,"") | W8: =F8 -> 0 | X8: =H8 | Y8: =G8*(-1) -> 0 | Z8: =I8+J8 -> 0
A9: Paskola grąžinta | H9: =IF($B$9>0,$B$9,"") | L9: =IF($B$10=$B$11,H9-F9,"") | W9: =F9 -> 0 | X9: =H9 | Y9: =G9*(-1) -> 0 | Z9: =I9+J9 -> 0
A10: Investuota | B10: =SUM(G3:G20) -> 4.02 | H10: =IF($B$9>0,$B$9,"") | L10: =IF($B$10=$B$11,H10-F10,"") | W10: =F10 -> 0 | X10: =H10 | Y10: =G10*(-1) -> 0 | Z10: =I10+J10 -> 0
A11: Grąžinta | B11: =SUM(I3:I20) -> 0 | W11: =F11 -> 0 | X11: =H11 -> 0 | Y11: =G11*(-1) -> 0 | Z11: =I11+J11 -> 0
A12: Palūkanos | B12: =SUM(J3:J20) -> 0 | W12: =F12 -> 0 | X12: =H12 -> 0 | Y12: =G12*(-1) -> 0 | Z12: =I12+J12 -> 0
A13: XIRR | B13: =IF(B10=B11,XIRR(Y3:Z20,W3:X20),"") | W13: =F13 -> 0 | X13: =H13 -> 0 | Y13: =G13*(-1) -> 0 | Z13: =I13+J13 -> 0
A14: Terminas | B14: =IF(B10=B11,SUMPRODUCT(L3:L20,G3:G20)/SUM(G3:G20),"") | W14: =F14 -> 0 | X14: =H14 -> 0 | Y14: =G14*(-1) -> 0 | Z14: =I14+J14 -> 0
W15: =F15 -> 0 | X15: =H15 -> 0 | Y15: =G15*(-1) -> 0 | Z15: =I15+J15 -> 0
W16: =F16 -> 0 | X16: =H16 -> 0 | Y16: =G16*(-1) -> 0 | Z16: =I16+J16 -> 0
W17: =F17 -> 0 | X17: =H17 -> 0 | Y17: =G17*(-1) -> 0 | Z17: =I17+J17 -> 0
W18: =F18 -> 0 | X18: =H18 -> 0 | Y18: =G18*(-1) -> 0 | Z18: =I18+J18 -> 0
W19: =F19 -> 0 | X19: =H19 -> 0 | Y19: =G19*(-1) -> 0 | Z19: =I19+J19 -> 0
W20: =F20 -> 0 | X20: =H20 -> 0 | Y20: =G20*(-1) -> 0 | Z20: =I20+J20 -> 0

Sheet J054
A1: Mortgage loan ID | B1: J054 | E1: Note | F1: Investuota | H1: Grąžinimas
A2: Pavadinimas | B2: Apartments in Igualada | F2: Data | G2: Suma | H2: Grąž. Data | I2: Paskola | J2: Palūkanos | K2: Pelnas | L2: Laikas
A3: PTV | B3: 0.63 | D3: 1 | E3: LV0000105799 | F3: 45867 | G3: 1.47 | H3: =IF($B$9>0,$B$9,"") | L3: =IF($B$10=$B$11,H3-F3,"") | W3: =F3 -> 45867 | X3: =H3 | Y3: =G3*(-1) -> -1.47 | Z3: =I3+J3 -> 0
A4: PDT | B4: 0.48 | D4: 2 | E4: LV0000105807 | F4: 45867 | G4: 1.75 | H4: =IF($B$9>0,$B$9,"") | L4: =IF($B$10=$B$11,H4-F4,"") | W4: =F4 -> 45867 | X4: =H4 | Y4: =G4*(-1) -> -1.75 | Z4: =I4+J4 -> 0
D5: 3 | E5: LV0000105815 | F5: 45867 | G5: 1.44 | H5: =IF($B$9>0,$B$9,"") | L5: =IF($B$10=$B$11,H5-F5,"") | W5: =F5 -> 45867 | X5: =H5 | Y5: =G5*(-1) -> -1.44 | Z5: =I5+J5 -> 0
D6: 4 | E6: LV0000106102 | F6: 45888 | G6: 0.13 | H6: =IF($B$9>0,$B$9,"") | L6: =IF($B$10=$B$11,H6-F6,"") | W6: =F6 -> 45888 | X6: =H6 | Y6: =G6*(-1) -> -0.13 | Z6: =I6+J6 -> 0
A7: Investuota | B7: =SUMPRODUCT(F3:F20,G3:G20)/SUM(G3:G20) -> 45872.55 | D7: 5 | E7: LV0000106391 | F7: 45902 | G7: 0.81 | H7: =IF($B$9>0,$B$9,"") | L7: =IF($B$10=$B$11,H7-F7,"") | W7: =F7 -> 45902 | X7: =H7 | Y7: =G7*(-1) -> -0.81 | Z7: =I7+J7 -> 0
A8: Paskolos pradžia | B8: 45551 | H8: =IF($B$9>0,$B$9,"") | L8: =IF($B$10=$B$11,H8-F8,"") | W8: =F8 -> 0 | X8: =H8 | Y8: =G8*(-1) -> 0 | Z8: =I8+J8 -> 0
A9: Paskola grąžinta | H9: =IF($B$9>0,$B$9,"") | L9: =IF($B$10=$B$11,H9-F9,"") | W9: =F9 -> 0 | X9: =H9 | Y9: =G9*(-1) -> 0 | Z9: =I9+J9 -> 0
A10: Investuota | B10: =SUM(G3:G20) -> 5.6 | H10: =IF($B$9>0,$B$9,"") | L10: =IF($B$10=$B$11,H10-F10,"") | W10: =F10 -> 0 | X10: =H10 | Y10: =G10*(-1) -> 0 | Z10: =I10+J10 -> 0
A11: Grąžinta | B11: =SUM(I3:I20) -> 0 | W11: =F11 -> 0 | X11: =H11 -> 0 | Y11: =G11*(-1) -> 0 | Z11: =I11+J11 -> 0
A12: Palūkanos | B12: =SUM(J3:J20) -> 0 | W12: =F12 -> 0 | X12: =H12 -> 0 | Y12: =G12*(-1) -> 0 | Z12: =I12+J12 -> 0
A13: XIRR | B13: =IF(B10=B11,XIRR(Y3:Z20,W3:X20),"") | W13: =F13 -> 0 | X13: =H13 -> 0 | Y13: =G13*(-1) -> 0 | Z13: =I13+J13 -> 0
A14: Terminas | B14: =IF(B10=B11,SUMPRODUCT(L3:L20,G3:G20)/SUM(G3:G20),"") | W14: =F14 -> 0 | X14: =H14 -> 0 | Y14: =G14*(-1) -> 0 | Z14: =I14+J14 -> 0
W15: =F15 -> 0 | X15: =H15 -> 0 | Y15: =G15*(-1) -> 0 | Z15: =I15+J15 -> 0
W16: =F16 -> 0 | X16: =H16 -> 0 | Y16: =G16*(-1) -> 0 | Z16: =I16+J16 -> 0
W17: =F17 -> 0 | X17: =H17 -> 0 | Y17: =G17*(-1) -> 0 | Z17: =I17+J17 -> 0
W18: =F18 -> 0 | X18: =H18 -> 0 | Y18: =G18*(-1) -> 0 | Z18: =I18+J18 -> 0
W19: =F19 -> 0 | X19: =H19 -> 0 | Y19: =G19*(-1) -> 0 | Z19: =I19+J19 -> 0
W20: =F20 -> 0 | X20: =H20 -> 0 | Y20: =G20*(-1) -> 0 | Z20: =I20+J20 -> 0

Sheet J055
A1: Mortgage loan ID | B1: J055 | E1: Note | F1: Investuota | H1: Grąžinimas
A2: Pavadinimas | B2: Apartment in Sabinanigo | F2: Data | G2: Suma | H2: Grąž. Data | I2: Paskola | J2: Palūkanos | K2: Pelnas | L2: Laikas
A3: PTV | B3: 0.59 | D3: 1 | E3: LV0000104644 | F3: 45804 | G3: 1.01 | H3: =IF($B$9>0,$B$9,"") | L3: =IF($B$10=$B$11,H3-F3,"") | W3: =F3 -> 45804 | X3: =H3 | Y3: =G3*(-1) -> -1.01 | Z3: =I3+J3 -> 0
A4: PDT | B4: 0.33 | D4: 2 | E4: LV0000104636 | F4: 45804 | G4: 0.98 | H4: =IF($B$9>0,$B$9,"") | L4: =IF($B$10=$B$11,H4-F4,"") | W4: =F4 -> 45804 | X4: =H4 | Y4: =G4*(-1) -> -0.98 | Z4: =I4+J4 -> 0
D5: 3 | E5: LV0000105369 | F5: 45846 | G5: 0.07 | H5: =IF($B$9>0,$B$9,"") | L5: =IF($B$10=$B$11,H5-F5,"") | W5: =F5 -> 45846 | X5: =H5 | Y5: =G5*(-1) -> -0.07 | Z5: =I5+J5 -> 0
D6: 4 | E6: LV0000105807 | F6: 45867 | G6: 0.02 | H6: =IF($B$9>0,$B$9,"") | L6: =IF($B$10=$B$11,H6-F6,"") | W6: =F6 -> 45867 | X6: =H6 | Y6: =G6*(-1) -> -0.02 | Z6: =I6+J6 -> 0
A7: Investuota | B7: =SUMPRODUCT(F3:F20,G3:G20)/SUM(G3:G20) -> 45806.019 | H7: =IF($B$9>0,$B$9,"") | L7: =IF($B$10=$B$11,H7-F7,"") | W7: =F7 -> 0 | X7: =H7 | Y7: =G7*(-1) -> 0 | Z7: =I7+J7 -> 0
A8: Paskolos pradžia | B8: 45551 | H8: =IF($B$9>0,$B$9,"") | L8: =IF($B$10=$B$11,H8-F8,"") | W8: =F8 -> 0 | X8: =H8 | Y8: =G8*(-1) -> 0 | Z8: =I8+J8 -> 0
A9: Paskola grąžinta | H9: =IF($B$9>0,$B$9,"") | L9: =IF($B$10=$B$11,H9-F9,"") | W9: =F9 -> 0 | X9: =H9 | Y9: =G9*(-1) -> 0 | Z9: =I9+J9 -> 0
A10: Investuota | B10: =SUM(G3:G20) -> 2.08 | H10: =IF($B$9>0,$B$9,"") | L10: =IF($B$10=$B$11,H10-F10,"") | W10: =F10 -> 0 | X10: =H10 | Y10: =G10*(-1) -> 0 | Z10: =I10+J10 -> 0
A11: Grąžinta | B11: =SUM(I3:I20) -> 0 | W11: =F11 -> 0 | X11: =H11 -> 0 | Y11: =G11*(-1) -> 0 | Z11: =I11+J11 -> 0
A12: Palūkanos | B12: =SUM(J3:J20) -> 0 | W12: =F12 -> 0 | X12: =H12 -> 0 | Y12: =G12*(-1) -> 0 | Z12: =I12+J12 -> 0
A13: XIRR | B13: =IF(B10=B11,XIRR(Y3:Z20,W3:X20),"") | W13: =F13 -> 0 | X13: =H13 -> 0 | Y13: =G13*(-1) -> 0 | Z13: =I13+J13 -> 0
A14: Terminas | B14: =IF(B10=B11,SUMPRODUCT(L3:L20,G3:G20)/SUM(G3:G20),"") | W14: =F14 -> 0 | X14: =H14 -> 0 | Y14: =G14*(-1) -> 0 | Z14: =I14+J14 -> 0
W15: =F15 -> 0 | X15: =H15 -> 0 | Y15: =G15*(-1) -> 0 | Z15: =I15+J15 -> 0
W16: =F16 -> 0 | X16: =H16 -> 0 | Y16: =G16*(-1) -> 0 | Z16: =I16+J16 -> 0
W17: =F17 -> 0 | X17: =H17 -> 0 | Y17: =G17*(-1) -> 0 | Z17: =I17+J17 -> 0
W18: =F18 -> 0 | X18: =H18 -> 0 | Y18: =G18*(-1) -> 0 | Z18: =I18+J18 -> 0
W19: =F19 -> 0 | X19: =H19 -> 0 | Y19: =G19*(-1) -> 0 | Z19: =I19+J19 -> 0
W20: =F20 -> 0 | X20: =H20 -> 0 | Y20: =G20*(-1) -> 0 | Z20: =I20+J20 -> 0

Sheet J056
A1: Mortgage loan ID | B1: J056 | E1: Note | F1: Investuota | H1: Grąžinimas
A2: Pavadinimas | B2: House in Alicante and Apartment in Albacete | F2: Data | G2: Suma | H2: Grąž. Data | I2: Paskola | J2: Palūkanos | K2: Pelnas | L2: Laikas
A3: PTV | B3: 0.63 | D3: 1 | E3: LV0000104644 | F3: 45804 | G3: 1.97 | H3: =IF($B$9>0,$B$9,"") | L3: =IF($B$10=$B$11,H3-F3,"") | W3: =F3 -> 45804 | X3: =H3 | Y3: =G3*(-1) -> -1.97 | Z3: =I3+J3 -> 0
A4: PDT | B4: 0.31 | D4: 2 | E4: LV0000104636 | F4: 45804 | G4: 1.61 | H4: =IF($B$9>0,$B$9,"") | L4: =IF($B$10=$B$11,H4-F4,"") | W4: =F4 -> 45804 | X4: =H4 | Y4: =G4*(-1) -> -1.61 | Z4: =I4+J4 -> 0
D5: 3 | E5: LV0000105054 | F5: 45832 | G5: 1.43 | H5: =IF($B$9>0,$B$9,"") | L5: =IF($B$10=$B$11,H5-F5,"") | W5: =F5 -> 45832 | X5: =H5 | Y5: =G5*(-1) -> -1.43 | Z5: =I5+J5 -> 0
H6: =IF($B$9>0,$B$9,"") | L6: =IF($B$10=$B$11,H6-F6,"") | W6: =F6 -> 0 | X6: =H6 | Y6: =G6*(-1) -> 0 | Z6: =I6+J6 -> 0
A7: Investuota | B7: =SUMPRODUCT(F3:F20,G3:G20)/SUM(G3:G20) -> 45811.992 | H7: =IF($B$9>0,$B$9,"") | L7: =IF($B$10=$B$11,H7-F7,"") | W7: =F7 -> 0 | X7: =H7 | Y7: =G7*(-1) -> 0 | Z7: =I7+J7 -> 0
A8: Paskolos pradžia | B8: 45551 | H8: =IF($B$9>0,$B$9,"") | L8: =IF($B$10=$B$11,H8-F8,"") | W8: =F8 -> 0 | X8: =H8 | Y8: =G8*(-1) -> 0 | Z8: =I8+J8 -> 0
A9: Paskola grąžinta | H9: =IF($B$9>0,$B$9,"") | L9: =IF($B$10=$B$11,H9-F9,"") | W9: =F9 -> 0 | X9: =H9 | Y9: =G9*(-1) -> 0 | Z9: =I9+J9 -> 0
A10: Investuota | B10: =SUM(G3:G20) -> 5.01 | H10: =IF($B$9>0,$B$9,"") | L10: =IF($B$10=$B$11,H10-F10,"") | W10: =F10 -> 0 | X10: =H10 | Y10: =G10*(-1) -> 0 | Z10: =I10+J10 -> 0
A11: Grąžinta | B11: =SUM(I3:I20) -> 0 | W11: =F11 -> 0 | X11: =H11 -> 0 | Y11: =G11*(-1) -> 0 | Z11: =I11+J11 -> 0
A12: Palūkanos | B12: =SUM(J3:J20) -> 0 | W12: =F12 -> 0 | X12: =H12 -> 0 | Y12: =G12*(-1) -> 0 | Z12: =I12+J12 -> 0
A13: XIRR | B13: =IF(B10=B11,XIRR(Y3:Z20,W3:X20),"") | W13: =F13 -> 0 | X13: =H13 -> 0 | Y13: =G13*(-1) -> 0 | Z13: =I13+J13 -> 0
A14: Terminas | B14: =IF(B10=B11,SUMPRODUCT(L3:L20,G3:G20)/SUM(G3:G20),"") | W14: =F14 -> 0 | X14: =H14 -> 0 | Y14: =G14*(-1) -> 0 | Z14: =I14+J14 -> 0
W15: =F15 -> 0 | X15: =H15 -> 0 | Y15: =G15*(-1) -> 0 | Z15: =I15+J15 -> 0
W16: =F16 -> 0 | X16: =H16 -> 0 | Y16: =G16*(-1) -> 0 | Z16: =I16+J16 -> 0
W17: =F17 -> 0 | X17: =H17 -> 0 | Y17: =G17*(-1) -> 0 | Z17: =I17+J17 -> 0
W18: =F18 -> 0 | X18: =H18 -> 0 | Y18: =G18*(-1) -> 0 | Z18: =I18+J18 -> 0
W19: =F19 -> 0 | X19: =H19 -> 0 | Y19: =G19*(-1) -> 0 | Z19: =I19+J19 -> 0
W20: =F20 -> 0 | X20: =H20 -> 0 | Y20: =G20*(-1) -> 0 | Z20: =I20+J20 -> 0

Sheet J057
A1: Mortgage loan ID | B1: J057 | E1: Note | F1: Investuota | H1: Grąžinimas
A2: Pavadinimas | B2: Apartment in Vigo | F2: Data | G2: Suma | H2: Grąž. Data | I2: Paskola | J2: Palūkanos | K2: Pelnas | L2: Laikas
A3: PTV | B3: 0.61 | D3: 1 | E3: LV0000104644 | F3: 45804 | G3: 1.97 | H3: =IF($B$9>0,$B$9,"") | L3: =IF($B$10=$B$11,H3-F3,"") | W3: =F3 -> 45804 | X3: =H3 | Y3: =G3*(-1) -> -1.97 | Z3: =I3+J3 -> 0
A4: PDT | B4: 0.32 | D4: 2 | E4: LV0000104636 | F4: 45804 | G4: 1.88 | H4: =IF($B$9>0,$B$9,"") | L4: =IF($B$10=$B$11,H4-F4,"") | W4: =F4 -> 45804 | X4: =H4 | Y4: =G4*(-1) -> -1.88 | Z4: =I4+J4 -> 0
H5: =IF($B$9>0,$B$9,"") | L5: =IF($B$10=$B$11,H5-F5,"") | W5: =F5 -> 0 | X5: =H5 | Y5: =G5*(-1) -> 0 | Z5: =I5+J5 -> 0
H6: =IF($B$9>0,$B$9,"") | L6: =IF($B$10=$B$11,H6-F6,"") | W6: =F6 -> 0 | X6: =H6 | Y6: =G6*(-1) -> 0 | Z6: =I6+J6 -> 0
A7: Investuota | B7: =SUMPRODUCT(F3:F20,G3:G20)/SUM(G3:G20) -> 45804 | H7: =IF($B$9>0,$B$9,"") | L7: =IF($B$10=$B$11,H7-F7,"") | W7: =F7 -> 0 | X7: =H7 | Y7: =G7*(-1) -> 0 | Z7: =I7+J7 -> 0
A8: Paskolos pradžia | B8: 45551 | H8: =IF($B$9>0,$B$9,"") | L8: =IF($B$10=$B$11,H8-F8,"") | W8: =F8 -> 0 | X8: =H8 | Y8: =G8*(-1) -> 0 | Z8: =I8+J8 -> 0
A9: Paskola grąžinta | H9: =IF($B$9>0,$B$9,"") | L9: =IF($B$10=$B$11,H9-F9,"") | W9: =F9 -> 0 | X9: =H9 | Y9: =G9*(-1) -> 0 | Z9: =I9+J9 -> 0
A10: Investuota | B10: =SUM(G3:G20) -> 3.85 | H10: =IF($B$9>0,$B$9,"") | L10: =IF($B$10=$B$11,H10-F10,"") | W10: =F10 -> 0 | X10: =H10 | Y10: =G10*(-1) -> 0 | Z10: =I10+J10 -> 0
A11: Grąžinta | B11: =SUM(I3:I20) -> 0 | W11: =F11 -> 0 | X11: =H11 -> 0 | Y11: =G11*(-1) -> 0 | Z11: =I11+J11 -> 0
A12: Palūkanos | B12: =SUM(J3:J20) -> 0 | W12: =F12 -> 0 | X12: =H12 -> 0 | Y12: =G12*(-1) -> 0 | Z12: =I12+J12 -> 0
A13: XIRR | B13: =IF(B10=B11,XIRR(Y3:Z20,W3:X20),"") | W13: =F13 -> 0 | X13: =H13 -> 0 | Y13: =G13*(-1) -> 0 | Z13: =I13+J13 -> 0
A14: Terminas | B14: =IF(B10=B11,SUMPRODUCT(L3:L20,G3:G20)/SUM(G3:G20),"") | W14: =F14 -> 0 | X14: =H14 -> 0 | Y14: =G14*(-1) -> 0 | Z14: =I14+J14 -> 0
W15: =F15 -> 0 | X15: =H15 -> 0 | Y15: =G15*(-1) -> 0 | Z15: =I15+J15 -> 0
W16: =F16 -> 0 | X16: =H16 -> 0 | Y16: =G16*(-1) -> 0 | Z16: =I16+J16 -> 0
W17: =F17 -> 0 | X17: =H17 -> 0 | Y17: =G17*(-1) -> 0 | Z17: =I17+J17 -> 0
W18: =F18 -> 0 | X18: =H18 -> 0 | Y18: =G18*(-1) -> 0 | Z18: =I18+J18 -> 0
W19: =F19 -> 0 | X19: =H19 -> 0 | Y19: =G19*(-1) -> 0 | Z19: =I19+J19 -> 0
W20: =F20 -> 0 | X20: =H20 -> 0 | Y20: =G20*(-1) -> 0 | Z20: =I20+J20 -> 0

Sheet J059
A1: Mortgage loan ID | B1: J059 | E1: Note | F1: Investuota | H1: Grąžinimas
A2: Pavadinimas | B2: House in Arroyomolinos | F2: Data | G2: Suma | H2: Grąž. Data | I2: Paskola | J2: Palūkanos | K2: Pelnas | L2: Laikas
A3: PTV | B3: 0.59 | D3: 1 | E3: LV0000103604 | F3: 45741 | G3: 7.88 | H3: =IF($B$9>0,$B$9,"") | L3: =IF($B$10=$B$11,H3-F3,"") | W3: =F3 -> 45741 | X3: =H3 | Y3: =G3*(-1) -> -7.88 | Z3: =I3+J3 -> 0
A4: PDT | B4: 0.45 | D4: 2 | E4: LV0000103752 | F4: 45748 | G4: 1.02 | H4: =IF($B$9>0,$B$9,"") | L4: =IF($B$10=$B$11,H4-F4,"") | W4: =F4 -> 45748 | X4: =H4 | Y4: =G4*(-1) -> -1.02 | Z4: =I4+J4 -> 0
D5: 3 | E5: LV0000103810 | F5: 45755 | G5: 1.96 | H5: =IF($B$9>0,$B$9,"") | L5: =IF($B$10=$B$11,H5-F5,"") | W5: =F5 -> 45755 | X5: =H5 | Y5: =G5*(-1) -> -1.96 | Z5: =I5+J5 -> 0
H6: =IF($B$9>0,$B$9,"") | L6: =IF($B$10=$B$11,H6-F6,"") | W6: =F6 -> 0 | X6: =H6 | Y6: =G6*(-1) -> 0 | Z6: =I6+J6 -> 0
A7: Investuota | B7: =SUMPRODUCT(F3:F20,G3:G20)/SUM(G3:G20) -> 45744.184 | H7: =IF($B$9>0,$B$9,"") | L7: =IF($B$10=$B$11,H7-F7,"") | W7: =F7 -> 0 | X7: =H7 | Y7: =G7*(-1) -> 0 | Z7: =I7+J7 -> 0
A8: Paskolos pradžia | B8: 45551 | H8: =IF($B$9>0,$B$9,"") | L8: =IF($B$10=$B$11,H8-F8,"") | W8: =F8 -> 0 | X8: =H8 | Y8: =G8*(-1) -> 0 | Z8: =I8+J8 -> 0
A9: Paskola grąžinta | H9: =IF($B$9>0,$B$9,"") | L9: =IF($B$10=$B$11,H9-F9,"") | W9: =F9 -> 0 | X9: =H9 | Y9: =G9*(-1) -> 0 | Z9: =I9+J9 -> 0
A10: Investuota | B10: =SUM(G3:G20) -> 10.86 | H10: =IF($B$9>0,$B$9,"") | L10: =IF($B$10=$B$11,H10-F10,"") | W10: =F10 -> 0 | X10: =H10 | Y10: =G10*(-1) -> 0 | Z10: =I10+J10 -> 0
A11: Grąžinta | B11: =SUM(I3:I20) -> 0 | W11: =F11 -> 0 | X11: =H11 -> 0 | Y11: =G11*(-1) -> 0 | Z11: =I11+J11 -> 0
A12: Palūkanos | B12: =SUM(J3:J20) -> 0 | W12: =F12 -> 0 | X12: =H12 -> 0 | Y12: =G12*(-1) -> 0 | Z12: =I12+J12 -> 0
A13: XIRR | B13: =IF(B10=B11,XIRR(Y3:Z20,W3:X20),"") | W13: =F13 -> 0 | X13: =H13 -> 0 | Y13: =G13*(-1) -> 0 | Z13: =I13+J13 -> 0
A14: Terminas | B14: =IF(B10=B11,SUMPRODUCT(L3:L20,G3:G20)/SUM(G3:G20),"") | W14: =F14 -> 0 | X14: =H14 -> 0 | Y14: =G14*(-1) -> 0 | Z14: =I14+J14 -> 0
W15: =F15 -> 0 | X15: =H15 -> 0 | Y15: =G15*(-1) -> 0 | Z15: =I15+J15 -> 0
