Workbook

Sheet Overview
B1: Loan ID | C1: Investuota | E1: Grąžinta | K1: Pinigai | O1: Grąžinta | Q1: Vertė
C2: Suma | D2: Data | E2: Data | F2: Laikas | G2: Paskola | H2: Palūkanos | I2: XIRR | K2: Įnešta | L2: Investuota | M2: Premijos | N2: Gryni | O2: Paskola | P2: Palūkanos | Q2: Viso | R2: Eur. | S2: % | T2: XIRR
A3: 1 | B3: ='J036'!$B$1 -> J036 | C3: ='J036'!$B$10 -> 0.31 | D3: ='J036'!$B$7 -> 45740 | E3: =IF(C3=G3,'J036'!$B$9,"") | F3: ='J036'!$B$14 | G3: ='J036'!$B$11 -> 0 | H3: ='J036'!$B$12 -> 0 | I3: ='J036'!$B$13 | K3: =Pinigai!F2 -> 30 | L3: =SUM(C3:C140)-O3 -> 83.18 | M3: =Pinigai!H2 -> 55 | N3: =Q3-L3 -> 2.17 | O3: =SUM(G3:G140) -> 2.87 | P3: =SUM(H3:H140) -> 0.35 | Q3: =K3+M3+P3 -> 85.35 | R3: =Q3-K3 -> 55.35 | S3: =(Q3-K3)/Q3 -> 0.64850615 | T3: =XIRR(Pinigai!K2:K200,Pinigai!A2:A200) -> 1.157466
A4: 2 | B4: ='J038'!$B$1 -> J038 | C4: ='J038'!$B$10 -> 0.38 | D4: ='J038'!$B$7 -> 45740 | E4: =IF(C4=G4,'J038'!$B$9,"") -> 45996 | F4: ='J038'!$B$14 -> 256 | G4: ='J038'!$B$11 -> 0.38 | H4: ='J038'!$B$12 -> 0.05 | I4: ='J038'!$B$13 -> 0.19273198
A5: 3 | B5: ='J040'!$B$1 -> J040 | C5: ='J040'!$B$10 -> 7.88 | D5: ='J040'!$B$7 -> 45740 | E5: =IF(C5=G5,'J040'!$B$9,"") | F5: ='J040'!$B$14 | G5: ='J040'!$B$11 -> 0 | H5: ='J040'!$B$12 -> 0 | I5: ='J040'!$B$13
A6: 4 | B6: ='J044'!$B$1 -> J044 | C6: ='J044'!$B$10 -> 1.49 | D6: ='J044'!$B$7 -> 45740 | E6: =IF(C6=G6,'J044'!$B$9,"") -> 46169 | F6: ='J044'!$B$14 -> 429 | G6: ='J044'!$B$11 -> 1.49 | H6: ='J044'!$B$12 -> 0.25 | I6: ='J044'!$B$13 -> 0.14107316
A7: 5 | B7: ='J046'!$B$1 -> J046 | C7: ='J046'!$B$10 -> 5.37 | D7: ='J046'!$B$7 -> 45740 | E7: =IF(C7=G7,'J046'!$B$9,"") | F7: ='J046'!$B$14 | G7: ='J046'!$B$11 -> 0 | H7: ='J046'!$B$12 -> 0 | I7: ='J046'!$B$13
A8: 6 | B8: ='J052'!$B$1 -> J052 | C8: ='J052'!$B$10 -> 5.37 | D8: ='J052'!$B$7 -> 45740 | E8: =IF(C8=G8,'J052'!$B$9,"") | F8: ='J052'!$B$14 | G8: ='J052'!$B$11 -> 0 | H8: ='J052'!$B$12 -> 0 | I8: ='J052'!$B$13
A9: 7 | B9: ='J053'!$B$1 -> J053 | C9: ='J053'!$B$10 -> 2.01 | D9: ='J053'!$B$7 -> 45740 | E9: =IF(C9=G9,'J053'!$B$9,"") | F9: ='J053'!$B$14 | G9: ='J053'!$B$11 -> 0 | H9: ='J053'!$B$12 -> 0 | I9: ='J053'!$B$13
A10: 8 | B10: ='J057'!$B$1 -> J057 | C10: ='J057'!$B$10 -> 3.7 | D10: ='J057'!$B$7 -> 45831 | E10: =IF(C10=G10,'J057'!$B$9,"") | F10: ='J057'!$B$14 | G10: ='J057'!$B$11 -> 0 | H10: ='J057'!$B$12 -> 0 | I10: ='J057'!$B$13
A11: 9 | B11: ='J059'!$B$1 -> J059 | C11: ='J059'!$B$10 -> 4.92 | D11: ='J059'!$B$7 -> 45740 | E11: =IF(C11=G11,'J059'!$B$9,"") | F11: ='J059'!$B$14 | G11: ='J059'!$B$11 -> 0 | H11: ='J059'!$B$12 -> 0 | I11: ='J059'!$B$13
A12: 10 | B12: ='J061'!$B$1 -> J061 | C12: ='J061'!$B$10 -> 1.63 | D12: ='J061'!$B$7 -> 45740 | E12: =IF(C12=G12,'J061'!$B$9,"") | F12: ='J061'!$B$14 | G12: ='J061'!$B$11 -> 0 | H12: ='J061'!$B$12 -> 0 | I12: ='J061'!$B$13
A13: 11 | B13: ='J062'!$B$1 -> J062 | C13: ='J062'!$B$10 -> 12.88 | D13: ='J062'!$B$7 -> 45740 | E13: =IF(C13=G13,'J062'!$B$9,"") | F13: ='J062'!$B$14 | G13: ='J062'!$B$11 -> 0 | H13: ='J062'!$B$12 -> 0 | I13: ='J062'!$B$13
A14: 12 | B14: ='J063'!$B$1 -> J063 | C14: ='J063'!$B$10 -> 3.53 | D14: ='J063'!$B$7 -> 45740 | E14: =IF(C14=G14,'J063'!$B$9,"") | F14: ='J063'!$B$14 | G14: ='J063'!$B$11 -> 0 | H14: ='J063'!$B$12 -> 0 | I14: ='J063'!$B$13
A15: 13 | B15: ='J067'!$B$1 -> J067 | C15: ='J067'!$B$10 -> 1.5 | D15: ='J067'!$B$7 -> 45740 | E15: =IF(C15=G15,'J067'!$B$9,"") | F15: ='J067'!$B$14 | G15: ='J067'!$B$11 -> 0 | H15: ='J067'!$B$12 -> 0 | I15: ='J067'!$B$13
A16: 14 | B16: ='J071'!$B$1 -> J071 | C16: ='J071'!$B$10 -> 3.99 | D16: ='J071'!$B$7 -> 45740 | E16: =IF(C16=G16,'J071'!$B$9,"") | F16: ='J071'!$B$14 | G16: ='J071'!$B$11 -> 0 | H16: ='J071'!$B$12 -> 0 | I16: ='J071'!$B$13
A17: 15 | B17: ='R077'!$B$1 -> R077 | C17: ='R077'!$B$10 -> 4.6 | D17: ='R077'!$B$7 -> 45740 | E17: =IF(C17=G17,'R077'!$B$9,"") | F17: ='R077'!$B$14 | G17: ='R077'!$B$11 -> 0 | H17: ='R077'!$B$12 -> 0 | I17: ='R077'!$B$13
A18: 16 | B18: ='R078'!$B$1 -> R078 | C18: ='R078'!$B$10 -> 2.74 | D18: ='R078'!$B$7 -> 45740 | E18: =IF(C18=G18,'R078'!$B$9,"") | F18: ='R078'!$B$14 | G18: ='R078'!$B$11 -> 0 | H18: ='R078'!$B$12 -> 0 | I18: ='R078'!$B$13
A19: 17 | B19: ='R079'!$B$1 -> R079 | C19: ='R079'!$B$10 -> 1 | D19: ='R079'!$B$7 -> 45740 | E19: =IF(C19=G19,'R079'!$B$9,"") -> 45817 | F19: ='R079'!$B$14 -> 77 | G19: ='R079'!$B$11 -> 1 | H19: ='R079'!$B$12 -> 0.05 | I19: ='R079'!$B$13 -> 0.26020959
A20: 18 | B20: ='R080'!$B$1 -> R080 | C20: ='R080'!$B$10 -> 4.19 | D20: ='R080'!$B$7 -> 45741 | E20: =IF(C20=G20,'R080'!$B$9,"") | F20: ='R080'!$B$14 | G20: ='R080'!$B$11 -> 0 | H20: ='R080'!$B$12 -> 0 | I20: ='R080'!$B$13
A21: 19 | B21: ='R081'!$B$1 -> R081 | C21: ='R081'!$B$10 -> 1.21 | D21: ='R081'!$B$7 -> 45741 | E21: =IF(C21=G21,'R081'!$B$9,"") | F21: ='R081'!$B$14 | G21: ='R081'!$B$11 -> 0 | H21: ='R081'!$B$12 -> 0 | I21: ='R081'!$B$13
A22: 20 | B22: ='R089'!$B$1 -> R089 | C22: ='R089'!$B$10 -> 2.32 | D22: ='R089'!$B$7 -> 45831 | E22: =IF(C22=G22,'R089'!$B$9,"") | F22: ='R089'!$B$14 | G22: ='R089'!$B$11 -> 0 | H22: ='R089'!$B$12 -> 0 | I22: ='R089'!$B$13
A23: 21 | B23: ='R090'!$B$1 -> R090 | C23: ='R090'!$B$10 -> 2.8 | D23: ='R090'!$B$7 -> 45831 | E23: =IF(C23=G23,'R090'!$B$9,"") | F23: ='R090'!$B$14 | G23: ='R090'!$B$11 -> 0 | H23: ='R090'!$B$12 -> 0 | I23: ='R090'!$B$13
A24: 22 | B24: ='R091'!$B$1 -> R091 | C24: ='R091'!$B$10 -> 1.72 | D24: ='R091'!$B$7 -> 45831 | E24: =IF(C24=G24,'R091'!$B$9,"") | F24: ='R091'!$B$14 | G24: ='R091'!$B$11 -> 0 | H24: ='R091'!$B$12 -> 0 | I24: ='R091'!$B$13
A25: 23 | B25: ='R092'!$B$1 -> R092 | C25: ='R092'!$B$10 -> 2.34 | D25: ='R092'!$B$7 -> 45831 | E25: =IF(C25=G25,'R092'!$B$9,"") | F25: ='R092'!$B$14 | G25: ='R092'!$B$11 -> 0 | H25: ='R092'!$B$12 -> 0 | I25: ='R092'!$B$13
A26: 24 | B26: ='R093'!$B$1 -> R093 | C26: ='R093'!$B$10 -> 1.6 | D26: ='R093'!$B$7 -> 45831 | E26: =IF(C26=G26,'R093'!$B$9,"") | F26: ='R093'!$B$14 | G26: ='R093'!$B$11 -> 0 | H26: ='R093'!$B$12 -> 0 | I26: ='R093'!$B$13
A27: 25 | B27: ='R094'!$B$1 -> R094 | C27: ='R094'!$B$10 -> 3.92 | D27: ='R094'!$B$7 -> 45831 | E27: =IF(C27=G27,'R094'!$B$9,"") | F27: ='R094'!$B$14 | G27: ='R094'!$B$11 -> 0 | H27: ='R094'!$B$12 -> 0 | I27: ='R094'!$B$13
A28: 26 | B28: ='R096'!$B$1 -> R096 | C28: ='R096'!$B$10 -> 2.65 | D28: ='R096'!$B$7 -> 45831 | E28: =IF(C28=G28,'R096'!$B$9,"") | F28: ='R096'!$B$14 | G28: ='R096'!$B$11 -> 0 | H28: ='R096'!$B$12 -> 0 | I28: ='R096'!$B$13

Sheet Pinigai
A1: Data | B1: Įnešta | C1: Išimta | D1: Premijos | F1: Įnešta | G1: Išimta | H1: Premijos | I1: XIRR | K1: XIRR
A2: 45740 | B2: 10 | C2: 0 | D2: 30 | F2: =SUM(B2:B200) -> 30 | G2: =SUM(C2:C200) -> 0 | H2: =SUM(D2:D200) -> 55 | I2: =XIRR(K2:K200,A2:A200) -> 1.157466 | K2: =B2*-1 -> -10
A3: 45740 | B3: 0 | C3: 0 | D3: 25 | K3: =B3*-1 -> 0
A4: 45831 | B4: 20 | C4: 0 | D4: 0 | K4: =B4*-1 -> -20
A200: =TODAY() -> 46295 | K200: =Overview!Q3 -> 85.35

Sheet J036
A1: Mortgage loan ID | B1: J036 | E1: Note | F1: Investuota | H1: Grąžinimas
A2: Pavadinimas | B2: Flat at Calle Noguera | F2: Data | G2: Suma | H2: Grąž. Data | I2: Paskola | J2: Palūkanos | K2: Pelnas | L2: Laikas
A3: PTV | B3: 0.59 | D3: 1 | E3: LV0000103620 | F3: 45740 | G3: 0.31 | H3: =IF(B9>0,B9,"") | L3: =IF(B10=B11,H3-F3,"") | W3: =F3 -> 45740 | X3: =H3 | Y3: =G3*(-1) -> -0.31 | Z3: =I3+J3 -> 0
A4: PDT | B4: 0.51 | W4: =F4 -> 0 | X4: =H4 -> 0 | Y4: =G4*(-1) -> 0 | Z4: =I4+J4 -> 0
W5: =F5 -> 0 | X5: =H5 -> 0 | Y5: =G5*(-1) -> 0 | Z5: =I5+J5 -> 0
A7: Investuota | B7: =SUMPRODUCT(F3:F20,G3:G20)/SUM(G3:G20) -> 45740
A8: Paskolos pradžia | B8: 45551
A9: Paskola grąžinta
A10: Investuota | B10: =SUM(G3:G20) -> 0.31
A11: Grąžinta | B11: =SUM(I3:I20) -> 0
A12: Palūkanos | B12: =SUM(J3:J20) -> 0
A13: XIRR | B13: =IF(B10=B11,XIRR(Y3:Z20,W3:X20),"")
A14: Terminas | B14: =IF(B10=B11,SUMPRODUCT(L3:L20,G3:G20)/SUM(G3:G20),"")

Sheet J038
A1: Mortgage loan ID | B1: J038 | E1: Note | F1: Investuota | H1: Grąžinimas
A2: Pavadinimas | B2: House at Calle Virgen María | F2: Data | G2: Suma | H2: Grąž. Data | I2: Paskola | J2: Palūkanos | K2: Pelnas | L2: Laikas
A3: PTV | B3: 0.59 | D3: 1 | E3: LV0000103620 | F3: 45740 | G3: 0.38 | H3: =IF(B9>0,B9,"") -> 45996 | I3: 0.38 | J3: 0.05 | K3: 0.2128 | L3: =IF(B10=B11,H3-F3,"") -> 256 | W3: =F3 -> 45740 | X3: =H3 -> 45996 | Y3: =G3*(-1) -> -0.38 | Z3: =I3+J3 -> 0.43
A4: PDT | B4: 0.64 | W4: =F4 -> 0 | X4: =H4 -> 0 | Y4: =G4*(-1) -> 0 | Z4: =I4+J4 -> 0
W5: =F5 -> 0 | X5: =H5 -> 0 | Y5: =G5*(-1) -> 0 | Z5: =I5+J5 -> 0
A7: Investuota | B7: =SUMPRODUCT(F3:F20,G3:G20)/SUM(G3:G20) -> 45740
A8: Paskolos pradžia | B8: 45551
A9: Paskola grąžinta | B9: 45996
A10: Investuota | B10: =SUM(G3:G20) -> 0.38
A11: Grąžinta | B11: =SUM(I3:I20) -> 0.38
A12: Palūkanos | B12: =SUM(J3:J20) -> 0.05
A13: XIRR | B13: =IF(B10=B11,XIRR(Y3:Z20,W3:X20),"") -> 0.19273198
A14: Terminas | B14: =IF(B10=B11,SUMPRODUCT(L3:L20,G3:G20)/SUM(G3:G20),"") -> 256

Sheet J040
A1: Mortgage loan ID | B1: J040 | E1: Note | F1: Investuota | H1: Grąžinimas
A2: Pavadinimas | B2: Apartment in Cambrils | F2: Data | G2: Suma | H2: Grąž. Data | I2: Paskola | J2: Palūkanos | K2: Pelnas | L2: Laikas
A3: PTV | B3: 0.58 | D3: 1 | E3: LV0000103620 | F3: 45740 | G3: 3.91 | H3: =IF($B$9>0,$B$9,"") | L3: =IF($B$10=$B$11,H3-#REF!,"") | W3: =#REF! -> #REF! | X3: =H3 | Y3: =#REF!*(-1) -> #REF! | Z3: =I3+J3 -> 0
A4: PDT | B4: 0.55 | D4: 2 | E4: LV0000103612 | F4: 45740 | G4: 3.97 | H4: =IF($B$9>0,$B$9,"") | L4: =IF($B$10=$B$11,H4-#REF!,"") | W4: =#REF! -> #REF! | X4: =H4 | Y4: =#REF!*(-1) -> #REF! | Z4: =I4+J4 -> 0
H5: =IF($B$9>0,$B$9,"") | L5: =IF($B$10=$B$11,H5-F5,"") | W5: =F5 -> 0 | X5: =H5 | Y5: =G5*(-1) -> 0 | Z5: =I5+J5 -> 0
H6: =IF($B$9>0,$B$9,"") | L6: =IF($B$10=$B$11,H6-F6,"") | W6: =F6 -> 0 | X6: =H6 | Y6: =G6*(-1) -> 0 | Z6: =I6+J6 -> 0
A7: Investuota | B7: =SUMPRODUCT(F3:F20,G3:G20)/SUM(G3:G20) -> 45740 | H7: =IF($B$9>0,$B$9,"") | L7: =IF($B$10=$B$11,H7-F7,"") | W7: =F7 -> 0 | X7: =H7 | Y7: =G7*(-1) -> 0 | Z7: =I7+J7 -> 0
A8: Paskolos pradžia | B8: 45551 | H8: =IF($B$9>0,$B$9,"") | L8: =IF($B$10=$B$11,H8-F8,"") | W8: =F8 -> 0 | X8: =H8 | Y8: =G8*(-1) -> 0 | Z8: =I8+J8 -> 0
A9: Paskola grąžinta | W9: =F9 -> 0 | X9: =H9 -> 0 | Y9: =G9*(-1) -> 0 | Z9: =I9+J9 -> 0
A10: Investuota | B10: =SUM(G3:G20) -> 7.88 | W10: =F10 -> 0 | X10: =H10 -> 0 | Y10: =G10*(-1) -> 0 | Z10: =I10+J10 -> 0
A11: Grąžinta | B11: =SUM(I3:I20) -> 0 | W11: =F11 -> 0 | X11: =H11 -> 0 | Y11: =G11*(-1) -> 0 | Z11: =I11+J11 -> 0
A12: Palūkanos | B12: =SUM(J3:J20) -> 0 | W12: =F12 -> 0 | X12: =H12 -> 0 | Y12: =G12*(-1) -> 0 | Z12: =I12+J12 -> 0
A13: XIRR | B13: =IF(B10=B11,XIRR(Y3:Z20,W3:X20),"") | W13: =F13 -> 0 | X13: =H13 -> 0 | Y13: =G13*(-1) -> 0 | Z13: =I13+J13 -> 0
A14: Terminas | B14: =IF(B10=B11,SUMPRODUCT(L3:L20,G3:G20)/SUM(G3:G20),"") | W14: =F14 -> 0 | X14: =H14 -> 0 | Y14: =G14*(-1) -> 0 | Z14: =I14+J14 -> 0
W15: =F15 -> 0 | X15: =H15 -> 0 | Y15: =G15*(-1) -> 0 | Z15: =I15+J15 -> 0
W16: =F16 -> 0 | X16: =H16 -> 0 | Y16: =G16*(-1) -> 0 | Z16: =I16+J16 -> 0
W17: =F17 -> 0 | X17: =H17 -> 0 | Y17: =G17*(-1) -> 0 | Z17: =I17+J17 -> 0
W18: =F18 -> 0 | X18: =H18 -> 0 | Y18: =G18*(-1) -> 0 | Z18: =I18+J18 -> 0
W19: =F19 -> 0 | X19: =H19 -> 0 | Y19: =G19*(-1) -> 0 | Z19: =I19+J19 -> 0
W20: =F20 -> 0 | X20: =H20 -> 0 | Y20: =G20*(-1) -> 0 | Z20: =I20+J20 -> 0
W21: =F21 -> 0 | X21: =H21 -> 0 | Y21: =G21*(-1) -> 0 | Z21: =I21+J21 -> 0
W22: =F22 -> 0 | X22: =H22 -> 0 | Y22: =G22*(-1) -> 0 | Z22: =I22+J22 -> 0
W23: =F23 -> 0 | X23: =H23 -> 0 | Y23: =G23*(-1) -> 0 | Z23: =I23+J23 -> 0

Sheet J044
A1: Mortgage loan ID | B1: J044 | E1: Note | F1: Investuota | H1: Grąžinimas
A2: Pavadinimas | B2: Apartment in Adeje | F2: Data | G2: Suma | H2: Grąž. Data | I2: Paskola | J2: Palūkanos | K2: Pelnas | L2: Laikas
A3: PTV | B3: 0.2 | D3: 1 | E3: LV0000103612 | F3: 45740 | G3: 1.49 | H3: =IF($B$9>0,$B$9,"") -> 46169 | I3: 1.49 | J3: 0.25 | K3: 0.1452 | L3: =IF($B$10=$B$11,H3-F3,"") -> 429 | W3: =F3 -> 45740 | X3: =H3 -> 46169 | Y3: =G3*(-1) -> -1.49 | Z3: =I3+J3 -> 1.74
A4: PDT | B4: 0.64 | W4: =F4 -> 0 | X4: =H4 -> 0 | Y4: =G4*(-1) -> 0 | Z4: =I4+J4 -> 0
W5: =F5 -> 0 | X5: =H5 -> 0 | Y5: =G5*(-1) -> 0 | Z5: =I5+J5 -> 0
W6: =F6 -> 0 | X6: =H6 -> 0 | Y6: =G6*(-1) -> 0 | Z6: =I6+J6 -> 0
A7: Investuota | B7: =SUMPRODUCT(F3:F20,G3:G20)/SUM(G3:G20) -> 45740 | W7: =F7 -> 0 | X7: =H7 -> 0 | Y7: =G7*(-1) -> 0 | Z7: =I7+J7 -> 0
A8: Paskolos pradžia | B8: 45551 | W8: =F8 -> 0 | X8: =H8 -> 0 | Y8: =G8*(-1) -> 0 | Z8: =I8+J8 -> 0
A9: Paskola grąžinta | B9: 46169 | W9: =F9 -> 0 | X9: =H9 -> 0 | Y9: =G9*(-1) -> 0 | Z9: =I9+J9 -> 0
A10: Investuota | B10: =SUM(G3:G20) -> 1.49 | W10: =F10 -> 0 | X10: =H10 -> 0 | Y10: =G10*(-1) -> 0 | Z10: =I10+J10 -> 0
A11: Grąžinta | B11: =SUM(I3:I20) -> 1.49 | W11: =F11 -> 0 | X11: =H11 -> 0 | Y11: =G11*(-1) -> 0 | Z11: =I11+J11 -> 0
A12: Palūkanos | B12: =SUM(J3:J20) -> 0.25 | W12: =F12 -> 0 | X12: =H12 -> 0 | Y12: =G12*(-1) -> 0 | Z12: =I12+J12 -> 0
A13: XIRR | B13: =IF(B10=B11,XIRR(Y3:Z20,W3:X20),"") -> 0.14107316 | W13: =F13 -> 0 | X13: =H13 -> 0 | Y13: =G13*(-1) -> 0 | Z13: =I13+J13 -> 0
A14: Terminas | B14: =IF(B10=B11,SUMPRODUCT(L3:L20,G3:G20)/SUM(G3:G20),"") -> 429 | W14: =F14 -> 0 | X14: =H14 -> 0 | Y14: =G14*(-1) -> 0 | Z14: =I14+J14 -> 0
W15: =F15 -> 0 | X15: =H15 -> 0 | Y15: =G15*(-1) -> 0 | Z15: =I15+J15 -> 0
W16: =F16 -> 0 | X16: =H16 -> 0 | Y16: =G16*(-1) -> 0 | Z16: =I16+J16 -> 0
W17: =F17 -> 0 | X17: =H17 -> 0 | Y17: =G17*(-1) -> 0 | Z17: =I17+J17 -> 0
W18: =F18 -> 0 | X18: =H18 -> 0 | Y18: =G18*(-1) -> 0 | Z18: =I18+J18 -> 0
W19: =F19 -> 0 | X19: =H19 -> 0 | Y19: =G19*(-1) -> 0 | Z19: =I19+J19 -> 0
W20: =F20 -> 0 | X20: =H20 -> 0 | Y20: =G20*(-1) -> 0 | Z20: =I20+J20 -> 0

Sheet J046
A1: Mortgage loan ID | B1: J046 | E1: Note | F1: Investuota | H1: Grąžinimas
A2: Pavadinimas | B2: House in Torrevieja | F2: Data | G2: Suma | H2: Grąž. Data | I2: Paskola | J2: Palūkanos | K2: Pelnas | L2: Laikas
A3: PTV | B3: 0.58 | D3: 1 | E3: LV0000103620 | F3: 45740 | G3: 1.96 | H3: =IF($B$9>0,$B$9,"") | L3: =IF($B$10=$B$11,H3-F3,"") | W3: =F3 -> 45740 | X3: =H3 | Y3: =G3*(-1) -> -1.96 | Z3: =I3+J3 -> 0
A4: PDT | B4: 0.52 | D4: 2 | E4: LV0000103612 | F4: 45740 | G4: 3.41 | H4: =IF($B$9>0,$B$9,"") | L4: =IF($B$10=$B$11,H4-F4,"") | W4: =F4 -> 45740 | X4: =H4 | Y4: =G4*(-1) -> -3.41 | Z4: =I4+J4 -> 0
H5: =IF($B$9>0,$B$9,"") | L5: =IF($B$10=$B$11,H5-F5,"") | W5: =F5 -> 0 | X5: =H5 | Y5: =G5*(-1) -> 0 | Z5: =I5+J5 -> 0
H6: =IF($B$9>0,$B$9,"") | L6: =IF($B$10=$B$11,H6-F6,"") | W6: =F6 -> 0 | X6: =H6 | Y6: =G6*(-1) -> 0 | Z6: =I6+J6 -> 0
A7: Investuota | B7: =SUMPRODUCT(F3:F20,G3:G20)/SUM(G3:G20) -> 45740 | H7: =IF($B$9>0,$B$9,"") | L7: =IF($B$10=$B$11,H7-F7,"") | W7: =F7 -> 0 | X7: =H7 | Y7: =G7*(-1) -> 0 | Z7: =I7+J7 -> 0
A8: Paskolos pradžia | B8: 45551 | H8: =IF($B$9>0,$B$9,"") | L8: =IF($B$10=$B$11,H8-F8,"") | W8: =F8 -> 0 | X8: =H8 | Y8: =G8*(-1) -> 0 | Z8: =I8+J8 -> 0
A9: Paskola grąžinta | H9: =IF($B$9>0,$B$9,"") | L9: =IF($B$10=$B$11,H9-F9,"") | W9: =F9 -> 0 | X9: =H9 | Y9: =G9*(-1) -> 0 | Z9: =I9+J9 -> 0
A10: Investuota | B10: =SUM(G3:G20) -> 5.37 | H10: =IF($B$9>0,$B$9,"") | L10: =IF($B$10=$B$11,H10-F10,"") | W10: =F10 -> 0 | X10: =H10 | Y10: =G10*(-1) -> 0 | Z10: =I10+J10 -> 0
A11: Grąžinta | B11: =SUM(I3:I20) -> 0 | W11: =F11 -> 0 | X11: =H11 -> 0 | Y11: =G11*(-1) -> 0 | Z11: =I11+J11 -> 0
A12: Palūkanos | B12: =SUM(J3:J20) -> 0 | W12: =F12 -> 0 | X12: =H12 -> 0 | Y12: =G12*(-1) -> 0 | Z12: =I12+J12 -> 0
A13: XIRR | B13: =IF(B10=B11,XIRR(Y3:Z20,W3:X20),"") | W13: =F13 -> 0 | X13: =H13 -> 0 | Y13: =G13*(-1) -> 0 | Z13: =I13+J13 -> 0
A14: Terminas | B14: =IF(B10=B11,SUMPRODUCT(L3:L20,G3:G20)/SUM(G3:G20),"") | W14: =F14 -> 0 | X14: =H14 -> 0 | Y14: =G14*(-1) -> 0 | Z14: =I14+J14 -> 0
W15: =F15 -> 0 | X15: =H15 -> 0 | Y15: =G15*(-1) -> 0 | Z15: =I15+J15 -> 0
W16: =F16 -> 0 | X16: =H16 -> 0 | Y16: =G16*(-1) -> 0 | Z16: =I16+J16 -> 0
W17: =F17 -> 0 | X17: =H17 -> 0 | Y17: =G17*(-1) -> 0 | Z17: =I17+J17 -> 0
W18: =F18 -> 0 | X18: =H18 -> 0 | Y18: =G18*(-1) -> 0 | Z18: =I18+J18 -> 0
W19: =F19 -> 0 | X19: =H19 -> 0 | Y19: =G19*(-1) -> 0 | Z19: =I19+J19 -> 0
W20: =F20 -> 0 | X20: =H20 -> 0 | Y20: =G20*(-1) -> 0 | Z20: =I20+J20 -> 0

Sheet J052
A1: Mortgage loan ID | B1: J052 | E1: Note | F1: Investuota | H1: Grąžinimas
A2: Pavadinimas | B2: Apartment on Ronda de los Tejares | F2: Data | G2: Suma | H2: Grąž. Data | I2: Paskola | J2: Palūkanos | K2: Pelnas | L2: Laikas
A3: PTV | B3: 0.37 | D3: 1 | E3: LV0000103620 | F3: 45740 | G3: 1.96 | H3: =IF($B$9>0,$B$9,"") | L3: =IF($B$10=$B$11,H3-F3,"") | W3: =F3 -> 45740 | X3: =H3 | Y3: =G3*(-1) -> -1.96 | Z3: =I3+J3 -> 0
A4: PDT | B4: 0.68 | D4: 2 | E4: LV0000103612 | F4: 45740 | G4: 3.41 | H4: =IF($B$9>0,$B$9,"") | L4: =IF($B$10=$B$11,H4-F4,"") | W4: =F4 -> 45740 | X4: =H4 | Y4: =G4*(-1) -> -3.41 | Z4: =I4+J4 -> 0
L5: =IF($B$10=$B$11,H5-F5,"") | W5: =F5 -> 0 | X5: =H5 -> 0 | Y5: =G5*(-1) -> 0 | Z5: =I5+J5 -> 0
L6: =IF($B$10=$B$11,H6-F6,"") | W6: =F6 -> 0 | X6: =H6 -> 0 | Y6: =G6*(-1) -> 0 | Z6: =I6+J6 -> 0
A7: Investuota | B7: =SUMPRODUCT(F3:F20,G3:G20)/SUM(G3:G20) -> 45740 | L7: =IF($B$10=$B$11,H7-F7,"") | W7: =F7 -> 0 | X7: =H7 -> 0 | Y7: =G7*(-1) -> 0 | Z7: =I7+J7 -> 0
A8: Paskolos pradžia | B8: 45551 | H8: =IF($B$9>0,$B$9,"") | L8: =IF($B$10=$B$11,H8-F8,"") | W8: =F8 -> 0 | X8: =H8 | Y8: =G8*(-1) -> 0 | Z8: =I8+J8 -> 0
A9: Paskola grąžinta | H9: =IF($B$9>0,$B$9,"") | L9: =IF($B$10=$B$11,H9-F9,"") | W9: =F9 -> 0 | X9: =H9 | Y9: =G9*(-1) -> 0 | Z9: =I9+J9 -> 0
A10: Investuota | B10: =SUM(G3:G20) -> 5.37 | H10: =IF($B$9>0,$B$9,"") | L10: =IF($B$10=$B$11,H10-F10,"") | W10: =F10 -> 0 | X10: =H10 | Y10: =G10*(-1) -> 0 | Z10: =I10+J10 -> 0
A11: Grąžinta | B11: =SUM(I3:I20) -> 0 | W11: =F11 -> 0 | X11: =H11 -> 0 | Y11: =G11*(-1) -> 0 | Z11: =I11+J11 -> 0
A12: Palūkanos | B12: =SUM(J3:J20) -> 0 | W12: =F12 -> 0 | X12: =H12 -> 0 | Y12: =G12*(-1) -> 0 | Z12: =I12+J12 -> 0
A13: XIRR | B13: =IF(B10=B11,XIRR(Y3:Z20,W3:X20),"") | W13: =F13 -> 0 | X13: =H13 -> 0 | Y13: =G13*(-1) -> 0 | Z13: =I13+J13 -> 0
A14: Terminas | B14: =IF(B10=B11,SUMPRODUCT(L3:L20,G3:G20)/SUM(G3:G20),"") | W14: =F14 -> 0 | X14: =H14 -> 0 | Y14: =G14*(-1) -> 0 | Z14: =I14+J14 -> 0
W15: =F15 -> 0 | X15: =H15 -> 0 | Y15: =G15*(-1) -> 0 | Z15: =I15+J15 -> 0
W16: =F16 -> 0 | X16: =H16 -> 0 | Y16: =G16*(-1) -> 0 | Z16: =I16+J16 -> 0
W17: =F17 -> 0 | X17: =H17 -> 0 | Y17: =G17*(-1) -> 0 | Z17: =I17+J17 -> 0
W18: =F18 -> 0 | X18: =H18 -> 0 | Y18: =G18*(-1) -> 0 | Z18: =I18+J18 -> 0
W19: =F19 -> 0 | X19: =H19 -> 0 | Y19: =G19*(-1) -> 0 | Z19: =I19+J19 -> 0
W20: =F20 -> 0 | X20: =H20 -> 0 | Y20: =G20*(-1) -> 0 | Z20: =I20+J20 -> 0

Sheet J053
A1: Mortgage loan ID | B1: J053 | E1: Note | F1: Investuota | H1: Grąžinimas
A2: Pavadinimas | B2: Apartment in Vic | F2: Data | G2: Suma | H2: Grąž. Data | I2: Paskola | J2: Palūkanos | K2: Pelnas | L2: Laikas
A3: PTV | B3: 0.57 | D3: 1 | E3: LV0000103604 | F3: 45740 | G3: 2.01 | H3: =IF($B$9>0,$B$9,"") | L3: =IF($B$10=$B$11,H3-F3,"") | W3: =F3 -> 45740 | X3: =H3 | Y3: =G3*(-1) -> -2.01 | Z3: =I3+J3 -> 0
A4: PDT | B4: 0.48 | H4: =IF($B$9>0,$B$9,"") | L4: =IF($B$10=$B$11,H4-F4,"") | W4: =F4 -> 0 | X4: =H4 | Y4: =G4*(-1) -> 0 | Z4: =I4+J4 -> 0
H5: =IF($B$9>0,$B$9,"") | L5: =IF($B$10=$B$11,H5-F5,"") | W5: =F5 -> 0 | X5: =H5 | Y5: =G5*(-1) -> 0 | Z5: =I5+J5 -> 0
H6: =IF($B$9>0,$B$9,"") | L6: =IF($B$10=$B$11,H6-F6,"") | W6: =F6 -> 0 | X6: =H6 | Y6: =G6*(-1) -> 0 | Z6: =I6+J6 -> 0
A7: Investuota | B7: =SUMPRODUCT(F3:F20,G3:G20)/SUM(G3:G20) -> 45740 | H7: =IF($B$9>0,$B$9,"") | L7: =IF($B$10=$B$11,H7-F7,"") | W7: =F7 -> 0 | X7: =H7 | Y7: =G7*(-1) -> 0 | Z7: =I7+J7 -> 0
A8: Paskolos pradžia | B8: 45551 | H8: =IF($B$9>0,$B$9,"") | L8: =IF($B$10=$B$11,H8-F8,"") | W8: =F8 -> 0 | X8: =H8 | Y8: =G8*(-1) -> 0 | Z8: =I8+J8 -> 0
A9: Paskola grąžinta | H9: =IF($B$9>0,$B$9,"") | L9: =IF($B$10=$B$11,H9-F9,"") | W9: =F9 -> 0 | X9: =H9 | Y9: =G9*(-1) -> 0 | Z9: =I9+J9 -> 0
A10: Investuota | B10: =SUM(G3:G20) -> 2.01 | H10: =IF($B$9>0,$B$9,"") | L10: =IF($B$10=$B$11,H10-F10,"") | W10: =F10 -> 0 | X10: =H10 | Y10: =G10*(-1) -> 0 | Z10: =I10+J10 -> 0
A11: Grąžinta | B11: =SUM(I3:I20) -> 0 | W11: =F11 -> 0 | X11: =H11 -> 0 | Y11: =G11*(-1) -> 0 | Z11: =I11+J11 -> 0
A12: Palūkanos | B12: =SUM(J3:J20) -> 0 | W12: =F12 -> 0 | X12: =H12 -> 0 | Y12: =G12*(-1) -> 0 | Z12: =I12+J12 -> 0
A13: XIRR | B13: =IF(B10=B11,XIRR(Y3:Z20,W3:X20),"") | W13: =F13 -> 0 | X13: =H13 -> 0 | Y13: =G13*(-1) -> 0 | Z13: =I13+J13 -> 0
A14: Terminas | B14: =IF(B10=B11,SUMPRODUCT(L3:L20,G3:G20)/SUM(G3:G20),"") | W14: =F14 -> 0 | X14: =H14 -> 0 | Y14: =G14*(-1) -> 0 | Z14: =I14+J14 -> 0
W15: =F15 -> 0 | X15: =H15 -> 0 | Y15: =G15*(-1) -> 0 | Z15: =I15+J15 -> 0
W16: =F16 -> 0 | X16: =H16 -> 0 | Y16: =G16*(-1) -> 0 | Z16: =I16+J16 -> 0
W17: =F17 -> 0 | X17: =H17 -> 0 | Y17: =G17*(-1) -> 0 | Z17: =I17+J17 -> 0
W18: =F18 -> 0 | X18: =H18 -> 0 | Y18: =G18*(-1) -> 0 | Z18: =I18+J18 -> 0
W19: =F19 -> 0 | X19: =H19 -> 0 | Y19: =G19*(-1) -> 0 | Z19: =I19+J19 -> 0
W20: =F20 -> 0 | X20: =H20 -> 0 | Y20: =G20*(-1) -> 0 | Z20: =I20+J20 -> 0

Sheet J057
A1: Mortgage loan ID | B1: J057 | E1: Note | F1: Investuota | H1: Grąžinimas
A2: Pavadinimas | B2: Apartment in Vigo | F2: Data | G2: Suma | H2: Grąž. Data | I2: Paskola | J2: Palūkanos | K2: Pelnas | L2: Laikas
A3: PTV | B3: 0.61 | D3: 1 | E3: LV0000105062 | F3: 45831 | G3: 3.7 | H3: =IF($B$9>0,$B$9,"") | L3: =IF($B$10=$B$11,H3-F3,"") | W3: =F3 -> 45831 | X3: =H3 | Y3: =G3*(-1) -> -3.7 | Z3: =I3+J3 -> 0
A4: PDT | B4: 0.32 | H4: =IF($B$9>0,$B$9,"") | L4: =IF($B$10=$B$11,H4-F4,"") | W4: =F4 -> 0 | X4: =H4 | Y4: =G4*(-1) -> 0 | Z4: =I4+J4 -> 0
H5: =IF($B$9>0,$B$9,"") | L5: =IF($B$10=$B$11,H5-F5,"") | W5: =F5 -> 0 | X5: =H5 | Y5: =G5*(-1) -> 0 | Z5: =I5+J5 -> 0
H6: =IF($B$9>0,$B$9,"") | L6: =IF($B$10=$B$11,H6-F6,"") | W6: =F6 -> 0 | X6: =H6 | Y6: =G6*(-1) -> 0 | Z6: =I6+J6 -> 0
A7: Investuota | B7: =SUMPRODUCT(F3:F20,G3:G20)/SUM(G3:G20) -> 45831 | H7: =IF($B$9>0,$B$9,"") | L7: =IF($B$10=$B$11,H7-F7,"") | W7: =F7 -> 0 | X7: =H7 | Y7: =G7*(-1) -> 0 | Z7: =I7+J7 -> 0
A8: Paskolos pradžia | B8: 45551 | H8: =IF($B$9>0,$B$9,"") | L8: =IF($B$10=$B$11,H8-F8,"") | W8: =F8 -> 0 | X8: =H8 | Y8: =G8*(-1) -> 0 | Z8: =I8+J8 -> 0
A9: Paskola grąžinta | H9: =IF($B$9>0,$B$9,"") | L9: =IF($B$10=$B$11,H9-F9,"") | W9: =F9 -> 0 | X9: =H9 | Y9: =G9*(-1) -> 0 | Z9: =I9+J9 -> 0
A10: Investuota | B10: =SUM(G3:G20) -> 3.7 | H10: =IF($B$9>0,$B$9,"") | L10: =IF($B$10=$B$11,H10-F10,"") | W10: =F10 -> 0 | X10: =H10 | Y10: =G10*(-1) -> 0 | Z10: =I10+J10 -> 0
A11: Grąžinta | B11: =SUM(I3:I20) -> 0 | W11: =F11 -> 0 | X11: =H11 -> 0 | Y11: =G11*(-1) -> 0 | Z11: =I11+J11 -> 0
A12: Palūkanos | B12: =SUM(J3:J20) -> 0 | W12: =F12 -> 0 | X12: =H12 -> 0 | Y12: =G12*(-1) -> 0 | Z12: =I12+J12 -> 0
A13: XIRR | B13: =IF(B10=B11,XIRR(Y3:Z20,W3:X20),"") | W13: =F13 -> 0 | X13: =H13 -> 0 | Y13: =G13*(-1) -> 0 | Z13: =I13+J13 -> 0
A14: Terminas | B14: =IF(B10=B11,SUMPRODUCT(L3:L20,G3:G20)/SUM(G3:G20),"") | W14: =F14 -> 0 | X14: =H14 -> 0 | Y14: =G14*(-1) -> 0 | Z14: =I14+J14 -> 0
W15: =F15 -> 0 | X15: =H15 -> 0 | Y15: =G15*(-1) -> 0 | Z15: =I15+J15 -> 0
W16: =F16 -> 0 | X16: =H16 -> 0 | Y16: =G16*(-1) -> 0 | Z16: =I16+J16 -> 0
W17: =F17 -> 0 | X17: =H17 -> 0 | Y17: =G17*(-1) -> 0 | Z17: =I17+J17 -> 0
W18: =F18 -> 0 | X18: =H18 -> 0 | Y18: =G18*(-1) -> 0 | Z18: =I18+J18 -> 0
W19: =F19 -> 0 | X19: =H19 -> 0 | Y19: =G19*(-1) -> 0 | Z19: =I19+J19 -> 0
W20: =F20 -> 0 | X20: =H20 -> 0 | Y20: =G20*(-1) -> 0 | Z20: =I20+J20 -> 0

Sheet J059
A1: Mortgage loan ID | B1: J059 | E1: Note | F1: Investuota | H1: Grąžinimas
A2: Pavadinimas | B2: House in Arroyomolinos | F2: Data | G2: Suma | H2: Grąž. Data | I2: Paskola | J2: Palūkanos | K2: Pelnas | L2: Laikas
A3: PTV | B3: 0.59 | D3: 1 | E3: LV0000103604 | F3: 45740 | G3: 4.92 | H3: =IF($B$9>0,$B$9,"") | L3: =IF($B$10=$B$11,H3-F3,"") | W3: =F3 -> 45740 | X3: =H3 | Y3: =G3*(-1) -> -4.92 | Z3: =I3+J3 -> 0
A4: PDT | B4: 0.45 | H4: =IF($B$9>0,$B$9,"") | L4: =IF($B$10=$B$11,H4-F4,"") | W4: =F4 -> 0 | X4: =H4 | Y4: =G4*(-1) -> 0 | Z4: =I4+J4 -> 0
H5: =IF($B$9>0,$B$9,"") | L5: =IF($B$10=$B$11,H5-F5,"") | W5: =F5 -> 0 | X5: =H5 | Y5: =G5*(-1) -> 0 | Z5: =I5+J5 -> 0
H6: =IF($B$9>0,$B$9,"") | L6: =IF($B$10=$B$11,H6-F6,"") | W6: =F6 -> 0 | X6: =H6 | Y6: =G6*(-1) -> 0 | Z6: =I6+J6 -> 0
A7: Investuota | B7: =SUMPRODUCT(F3:F20,G3:G20)/SUM(G3:G20) -> 45740 | H7: =IF($B$9>0,$B$9,"") | L7: =IF($B$10=$B$11,H7-F7,"") | W7: =F7 -> 0 | X7: =H7 | Y7: =G7*(-1) -> 0 | Z7: =I7+J7 -> 0
A8: Paskolos pradžia | B8: 45551 | H8: =IF($B$9>0,$B$9,"") | L8: =IF($B$10=$B$11,H8-F8,"") | W8: =F8 -> 0 | X8: =H8 | Y8: =G8*(-1) -> 0 | Z8: =I8+J8 -> 0
A9: Paskola grąžinta | H9: =IF($B$9>0,$B$9,"") | L9: =IF($B$10=$B$11,H9-F9,"") | W9: =F9 -> 0 | X9: =H9 | Y9: =G9*(-1) -> 0 | Z9: =I9+J9 -> 0
A10: Investuota | B10: =SUM(G3:G20) -> 4.92 | H10: =IF($B$9>0,$B$9,"") | L10: =IF($B$10=$B$11,H10-F10,"") | W10: =F10 -> 0 | X10: =H10 | Y10: =G10*(-1) -> 0 | Z10: =I10+J10 -> 0
A11: Grąžinta | B11: =SUM(I3:I20) -> 0 | W11: =F11 -> 0 | X11: =H11 -> 0 | Y11: =G11*(-1) -> 0 | Z11: =I11+J11 -> 0
A12: Palūkanos | B12: =SUM(J3:J20) -> 0 | W12: =F12 -> 0 | X12: =H12 -> 0 | Y12: =G12*(-1) -> 0 | Z12: =I12+J12 -> 0
A13: XIRR | B13: =IF(B10=B11,XIRR(Y3:Z20,W3:X20),"") | W13: =F13 -> 0 | X13: =H13 -> 0 | Y13: =G13*(-1) -> 0 | Z13: =I13+J13 -> 0
A14: Terminas | B14: =IF(B10=B11,SUMPRODUCT(L3:L20,G3:G20)/SUM(G3:G20),"") | W14: =F14 -> 0 | X14: =H14 -> 0 | Y14: =G14*(-1) -> 0 | Z14: =I14+J14 -> 0
W15: =F15 -> 0 | X15: =H15 -> 0 | Y15: =G15*(-1) -> 0 | Z15: =I15+J15 -> 0
W16: =F16 -> 0 | X16: =H16 -> 0 | Y16: =G16*(-1) -> 0 | Z16: =I16+J16 -> 0
W17: =F17 -> 0 | X17: =H17 -> 0 | Y17: =G17*(-1) -> 0 | Z17: =I17+J17 -> 0
W18: =F18 -> 0 | X18: =H18 -> 0 | Y18: =G18*(-1) -> 0 | Z18: =I18+J18 -> 0
W19: =F19 -> 0 | X19: =H19 -> 0 | Y19: =G19*(-1) -> 0 | Z19: =I19+J19 -> 0
W20: =F20 -> 0 | X20: =H20 -> 0 | Y20: =G20*(-1) -> 0 | Z20: =I20+J20 -> 0

Sheet J061
A1: Mortgage loan ID | B1: J061 | E1: Note | F1: Investuota | H1: Grąžinimas
A2: Pavadinimas | B2: Apartment in Fuenlabrada | F2: Data | G2: Suma | H2: Grąž. Data | I2: Paskola | J2: Palūkanos | K2: Pelnas | L2: Laikas
A3: PTV | B3: 0.55 | D3: 1 | E3: LV0000103604 | F3: 45740 | G3: 1.63 | H3: =IF($B$9>0,$B$9,"") | L3: =IF($B$10=$B$11,H3-F3,"") | W3: =F3 -> 45740 | X3: =H3 | Y3: =G3*(-1) -> -1.63 | Z3: =I3+J3 -> 0
A4: PDT | B4: 0.42 | H4: =IF($B$9>0,$B$9,"") | L4: =IF($B$10=$B$11,H4-F4,"") | W4: =F4 -> 0 | X4: =H4 | Y4: =G4*(-1) -> 0 | Z4: =I4+J4 -> 0
H5: =IF($B$9>0,$B$9,"") | L5: =IF($B$10=$B$11,H5-F5,"") | W5: =F5 -> 0 | X5: =H5 | Y5: =G5*(-1) -> 0 | Z5: =I5+J5 -> 0
H6: =IF($B$9>0,$B$9,"") | L6: =IF($B$10=$B$11,H6-F6,"") | W6: =F6 -> 0 | X6: =H6 | Y6: =G6*(-1) -> 0 | Z6: =I6+J6 -> 0
A7: Investuota | B7: =SUMPRODUCT(F3:F20,G3:G20)/SUM(G3:G20) -> 45740 | H7: =IF($B$9>0,$B$9,"") | L7: =IF($B$10=$B$11,H7-F7,"") | W7: =F7 -> 0 | X7: =H7 | Y7: =G7*(-1) -> 0 | Z7: =I7+J7 -> 0
A8: Paskolos pradžia | B8: 45551 | H8: =IF($B$9>0,$B$9,"") | L8: =IF($B$10=$B$11,H8-F8,"") | W8: =F8 -> 0 | X8: =H8 | Y8: =G8*(-1) -> 0 | Z8: =I8+J8 -> 0
A9: Paskola grąžinta | H9: =IF($B$9>0,$B$9,"") | L9: =IF($B$10=$B$11,H9-F9,"") | W9: =F9 -> 0 | X9: =H9 | Y9: =G9*(-1) -> 0 | Z9: =I9+J9 -> 0
A10: Investuota | B10: =SUM(G3:G20) -> 1.63 | H10: =IF($B$9>0,$B$9,"") | L10: =IF($B$10=$B$11,H10-F10,"") | W10: =F10 -> 0 | X10: =H10 | Y10: =G10*(-1) -> 0 | Z10: =I10+J10 -> 0
A11: Grąžinta | B11: =SUM(I3:I20) -> 0 | W11: =F11 -> 0 | X11: =H11 -> 0 | Y11: =G11*(-1) -> 0 | Z11: =I11+J11 -> 0
A12: Palūkanos | B12: =SUM(J3:J20) -> 0 | W12: =F12 -> 0 | X12: =H12 -> 0 | Y12: =G12*(-1) -> 0 | Z12: =I12+J12 -> 0
A13: XIRR | B13: =IF(B10=B11,XIRR(Y3:Z20,W3:X20),"") | W13: =F13 -> 0 | X13: =H13 -> 0 | Y13: =G13*(-1) -> 0 | Z13: =I13+J13 -> 0
A14: Terminas | B14: =IF(B10=B11,SUMPRODUCT(L3:L20,G3:G20)/SUM(G3:G20),"") | W14: =F14 -> 0 | X14: =H14 -> 0 | Y14: =G14*(-1) -> 0 | Z14: =I14+J14 -> 0
W15: =F15 -> 0 | X15: =H15 -> 0 | Y15: =G15*(-1) -> 0 | Z15: =I15+J15 -> 0
W16: =F16 -> 0 | X16: =H16 -> 0 | Y16: =G16*(-1) -> 0 | Z16: =I16+J16 -> 0
W17: =F17 -> 0 | X17: =H17 -> 0 | Y17: =G17*(-1) -> 0 | Z17: =I17+J17 -> 0
W18: =F18 -> 0 | X18: =H18 -> 0 | Y18: =G18*(-1) -> 0 | Z18: =I18+J18 -> 0
W19: =F19 -> 0 | X19: =H19 -> 0 | Y19: =G19*(-1) -> 0 | Z19: =I19+J19 -> 0
W20: =F20 -> 0 | X20: =H20 -> 0 | Y20: =G20*(-1) -> 0 | Z20: =I20+J20 -> 0

Sheet J062
A1: Mortgage loan ID | B1: J062 | E1: Note | F1: Investuota | H1: Grąžinimas
A2: Pavadinimas | B2: Apartment and House in Malaga | F2: Data | G2: Suma | H2: Grąž. Data | I2: Paskola | J2: Palūkanos | K2: Pelnas | L2: Laikas
A3: PTV | B3: 0.49 | D3: 1 | E3: LV0000103604 | F3: 45740 | G3: 4.93 | H3: =IF($B$9>0,$B$9,"") | L3: =IF($B$10=$B$11,H3-F3,"") | W3: =F3 -> 45740 | X3: =H3 | Y3: =G3*(-1) -> -4.93 | Z3: =I3+J3 -> 0
A4: PDT | B4: 0.68 | D4: 2 | E4: LV0000103620 | F4: 45740 | G4: 3.96 | H4: =IF($B$9>0,$B$9,"") | L4: =IF($B$10=$B$11,H4-F4,"") | W4: =F4 -> 45740 | X4: =H4 | Y4: =G4*(-1) -> -3.96 | Z4: =I4+J4 -> 0
D5: 3 | E5: LV0000103612 | F5: 45740 | G5: 3.99 | H5: =IF($B$9>0,$B$9,"") | L5: =IF($B$10=$B$11,H5-F5,"") | W5: =F5 -> 45740 | X5: =H5 | Y5: =G5*(-1) -> -3.99 | Z5: =I5+J5 -> 0
H6: =IF($B$9>0,$B$9,"") | L6: =IF($B$10=$B$11,H6-F6,"") | W6: =F6 -> 0 | X6: =H6 | Y6: =G6*(-1) -> 0 | Z6: =I6+J6 -> 0
A7: Investuota | B7: =SUMPRODUCT(F3:F20,G3:G20)/SUM(G3:G20) -> 45740 | H7: =IF($B$9>0,$B$9,"") | L7: =IF($B$10=$B$11,H7-F7,"") | W7: =F7 -> 0 | X7: =H7 | Y7: =G7*(-1) -> 0 | Z7: =I7+J7 -> 0
A8: Paskolos pradžia | B8: 45551 | H8: =IF($B$9>0,$B$9,"") | L8: =IF($B$10=$B$11,H8-F8,"") | W8: =F8 -> 0 | X8: =H8 | Y8: =G8*(-1) -> 0 | Z8: =I8+J8 -> 0
A9: Paskola grąžinta | H9: =IF($B$9>0,$B$9,"") | L9: =IF($B$10=$B$11,H9-F9,"") | W9: =F9 -> 0 | X9: =H9 | Y9: =G9*(-1) -> 0 | Z9: =I9+J9 -> 0
A10: Investuota | B10: =SUM(G3:G20) -> 12.88 | H10: =IF($B$9>0,$B$9,"") | L10: =IF($B$10=$B$11,H10-F10,"") | W10: =F10 -> 0 | X10: =H10 | Y10: =G10*(-1) -> 0 | Z10: =I10+J10 -> 0
A11: Grąžinta | B11: =SUM(I3:I20) -> 0 | H11: =IF($B$9>0,$B$9,"") | L11: =IF($B$10=$B$11,H11-F11,"") | W11: =F11 -> 0 | X11: =H11 | Y11: =G11*(-1) -> 0 | Z11: =I11+J11 -> 0
A12: Palūkanos | B12: =SUM(J3:J20) -> 0 | H12: =IF($B$9>0,$B$9,"") | L12: =IF($B$10=$B$11,H12-F12,"") | W12: =F12 -> 0 | X12: =H12 | Y12: =G12*(-1) -> 0 | Z12: =I12+J12 -> 0
A13: XIRR | B13: =IF(B10=B11,XIRR(Y3:Z20,W3:X20),"") | H13: =IF($B$9>0,$B$9,"") | L13: =IF($B$10=$B$11,H13-F13,"") | W13: =F13 -> 0 | X13: =H13 | Y13: =G13*(-1) -> 0 | Z13: =I13+J13 -> 0
A14: Terminas | B14: =IF(B10=B11,SUMPRODUCT(L3:L20,G3:G20)/SUM(G3:G20),"") | H14: =IF($B$9>0,$B$9,"") | L14: =IF($B$10=$B$11,H14-F14,"") | W14: =F14 -> 0 | X14: =H14 | Y14: =G14*(-1) -> 0 | Z14: =I14+J14 -> 0
H15: =IF($B$9>0,$B$9,"") | L15: =IF($B$10=$B$11,H15-F15,"") | W15: =F15 -> 0 | X15: =H15 | Y15: =G15*(-1) -> 0 | Z15: =I15+J15 -> 0
H16: =IF($B$9>0,$B$9,"") | L16: =IF($B$10=$B$11,H16-F16,"") | W16: =F16 -> 0 | X16: =H16 | Y16: =G16*(-1) -> 0 | Z16: =I16+J16 -> 0
H17: =IF($B$9>0,$B$9,"") | L17: =IF($B$10=$B$11,H17-F17,"") | W17: =F17 -> 0 | X17: =H17 | Y17: =G17*(-1) -> 0 | Z17: =I17+J17 -> 0
H18: =IF($B$9>0,$B$9,"") | L18: =IF($B$10=$B$11,H18-F18,"") | W18: =F18 -> 0 | X18: =H18 | Y18: =G18*(-1) -> 0 | Z18: =I18+J18 -> 0
W19: =F19 -> 0 | X19: =H19 -> 0 | Y19: =G19*(-1) -> 0 | Z19: =I19+J19 -> 0
W20: =F20 -> 0 | X20: =H20 -> 0 | Y20: =G20*(-1) -> 0 | Z20: =I20+J20 -> 0

Sheet J063
A1: Mortgage loan ID | B1: J063 | E1: Note | F1: Investuota | H1: Grąžinimas
A2: Pavadinimas | B2: Apartment in Torrejón de Ardoz | F2: Data | G2: Suma | H2: Grąž. Data | I2: Paskola | J2: Palūkanos | K2: Pelnas | L2: Laikas
A3: PTV | B3: 0.57 | D3: 1 | E3: LV0000103620 | F3: 45740 | G3: 3.53 | H3: =IF($B$9>0,$B$9,"") | L3: =IF($B$10=$B$11,H3-F3,"") | W3: =F3 -> 45740 | X3: =H3 | Y3: =G3*(-1) -> -3.53 | Z3: =I3+J3 -> 0
A4: PDT | B4: 0.17 | L4: =IF($B$10=$B$11,H4-F4,"") | W4: =F4 -> 0 | X4: =H4 -> 0 | Y4: =G4*(-1) -> 0 | Z4: =I4+J4 -> 0
L5: =IF($B$10=$B$11,H5-F5,"") | W5: =F5 -> 0 | X5: =H5 -> 0 | Y5: =G5*(-1) -> 0 | Z5: =I5+J5 -> 0
L6: =IF($B$10=$B$11,H6-F6,"") | W6: =F6 -> 0 | X6: =H6 -> 0 | Y6: =G6*(-1) -> 0 | Z6: =I6+J6 -> 0
A7: Investuota | B7: =SUMPRODUCT(F3:F20,G3:G20)/SUM(G3:G20) -> 45740 | H7: =IF($B$9>0,$B$9,"") | L7: =IF($B$10=$B$11,H7-F7,"") | W7: =F7 -> 0 | X7: =H7 | Y7: =G7*(-1) -> 0 | Z7: =I7+J7 -> 0
A8: Paskolos pradžia | B8: 45551 | H8: =IF($B$9>0,$B$9,"") | L8: =IF($B$10=$B$11,H8-F8,"") | W8: =F8 -> 0 | X8: =H8 | Y8: =G8*(-1) -> 0 | Z8: =I8+J8 -> 0
A9: Paskola grąžinta | H9: =IF($B$9>0,$B$9,"") | L9: =IF($B$10=$B$11,H9-F9,"") | W9: =F9 -> 0 | X9: =H9 | Y9: =G9*(-1) -> 0 | Z9: =I9+J9 -> 0
A10: Investuota | B10: =SUM(G3:G20) -> 3.53 | H10: =IF($B$9>0,$B$9,"") | L10: =IF($B$10=$B$11,H10-F10,"") | W10: =F10 -> 0 | X10: =H10 | Y10: =G10*(-1) -> 0 | Z10: =I10+J10 -> 0
A11: Grąžinta | B11: =SUM(I3:I20) -> 0 | H11: =IF($B$9>0,$B$9,"") | L11: =IF($B$10=$B$11,H11-F11,"") | W11: =F11 -> 0 | X11: =H11 | Y11: =G11*(-1) -> 0 | Z11: =I11+J11 -> 0
A12: Palūkanos | B12: =SUM(J3:J20) -> 0 | H12: =IF($B$9>0,$B$9,"") | L12: =IF($B$10=$B$11,H12-F12,"") | W12: =F12 -> 0 | X12: =H12 | Y12: =G12*(-1) -> 0 | Z12: =I12+J12 -> 0
A13: XIRR | B13: =IF(B10=B11,XIRR(Y3:Z20,W3:X20),"") | H13: =IF($B$9>0,$B$9,"") | L13: =IF($B$10=$B$11,H13-F13,"") | W13: =F13 -> 0 | X13: =H13 | Y13: =G13*(-1) -> 0 | Z13: =I13+J13 -> 0
A14: Terminas | B14: =IF(B10=B11,SUMPRODUCT(L3:L20,G3:G20)/SUM(G3:G20),"") | H14: =IF($B$9>0,$B$9,"") | L14: =IF($B$10=$B$11,H14-F14,"") | W14: =F14 -> 0 | X14: =H14 | Y14: =G14*(-1) -> 0 | Z14: =I14+J14 -> 0
H15: =IF($B$9>0,$B$9,"") | L15: =IF($B$10=$B$11,H15-F15,"") | W15: =F15 -> 0 | X15: =H15 | Y15: =G15*(-1) -> 0 | Z15: =I15+J15 -> 0
H16: =IF($B$9>0,$B$9,"") | L16: =IF($B$10=$B$11,H16-F16,"") | W16: =F16 -> 0 | X16: =H16 | Y16: =G16*(-1) -> 0 | Z16: =I16+J16 -> 0
H17: =IF($B$9>0,$B$9,"") | L17: =IF($B$10=$B$11,H17-F17,"") | W17: =F17 -> 0 | X17: =H17 | Y17: =G17*(-1) -> 0 | Z17: =I17+J17 -> 0
H18: =IF($B$9>0,$B$9,"") | L18: =IF($B$10=$B$11,H18-F18,"") | W18: =F18 -> 0 | X18: =H18 | Y18: =G18*(-1) -> 0 | Z18: =I18+J18 -> 0
W19: =F19 -> 0 | X19: =H19 -> 0 | Y19: =G19*(-1) -> 0 | Z19: =I19+J19 -> 0
W20: =F20 -> 0 | X20: =H20 -> 0 | Y20: =G20*(-1) -> 0 | Z20: =I20+J20 -> 0

Sheet J067
A1: Mortgage loan ID | B1: J067 | E1: Note | F1: Investuota | H1: Grąžinimas
A2: Pavadinimas | B2: Apartment on Calle Guadalajara | F2: Data | G2: Suma | H2: Grąž. Data | I2: Paskola | J2: Palūkanos | K2: Pelnas | L2: Laikas
A3: PTV | B3: 0.53 | D3: 1 | E3: LV0000103612 | F3: 45740 | G3: 1.5 | H3: =IF($B$9>0,$B$9,"") | L3: =IF($B$10=$B$11,H3-F3,"") | W3: =F3 -> 45740 | X3: =H3 | Y3: =G3*(-1) -> -1.5 | Z3: =I3+J3 -> 0
A4: PDT | B4: 0.15 | H4: =IF($B$9>0,$B$9,"") | L4: =IF($B$10=$B$11,H4-F4,"") | W4: =F4 -> 0 | X4: =H4 | Y4: =G4*(-1) -> 0 | Z4: =I4+J4 -> 0
H5: =IF($B$9>0,$B$9,"") | L5: =IF($B$10=$B$11,H5-F5,"") | W5: =F5 -> 0 | X5: =H5 | Y5: =G5*(-1) -> 0 | Z5: =I5+J5 -> 0
H6: =IF($B$9>0,$B$9,"") | L6: =IF($B$10=$B$11,H6-F6,"") | W6: =F6 -> 0 | X6: =H6 | Y6: =G6*(-1) -> 0 | Z6: =I6+J6 -> 0
A7: Investuota | B7: =SUMPRODUCT(F3:F20,G3:G20)/SUM(G3:G20) -> 45740 | H7: =IF($B$9>0,$B$9,"") | L7: =IF($B$10=$B$11,H7-F7,"") | W7: =F7 -> 0 | X7: =H7 | Y7: =G7*(-1) -> 0 | Z7: =I7+J7 -> 0
A8: Paskolos pradžia | B8: 45551 | H8: =IF($B$9>0,$B$9,"") | L8: =IF($B$10=$B$11,H8-F8,"") | W8: =F8 -> 0 | X8: =H8 | Y8: =G8*(-1) -> 0 | Z8: =I8+J8 -> 0
A9: Paskola grąžinta | H9: =IF($B$9>0,$B$9,"") | L9: =IF($B$10=$B$11,H9-F9,"") | W9: =F9 -> 0 | X9: =H9 | Y9: =G9*(-1) -> 0 | Z9: =I9+J9 -> 0
A10: Investuota | B10: =SUM(G3:G20) -> 1.5 | H10: =IF($B$9>0,$B$9,"") | L10: =IF($B$10=$B$11,H10-F10,"") | W10: =F10 -> 0 | X10: =H10 | Y10: =G10*(-1) -> 0 | Z10: =I10+J10 -> 0
A11: Grąžinta | B11: =SUM(I3:I20) -> 0 | H11: =IF($B$9>0,$B$9,"") | L11: =IF($B$10=$B$11,H11-F11,"") | W11: =F11 -> 0 | X11: =H11 | Y11: =G11*(-1) -> 0 | Z11: =I11+J11 -> 0
A12: Palūkanos | B12: =SUM(J3:J20) -> 0 | H12: =IF($B$9>0,$B$9,"") | L12: =IF($B$10=$B$11,H12-F12,"") | W12: =F12 -> 0 | X12: =H12 | Y12: =G12*(-1) -> 0 | Z12: =I12+J12 -> 0
A13: XIRR | B13: =IF(B10=B11,XIRR(Y3:Z20,W3:X20),"") | H13: =IF($B$9>0,$B$9,"") | L13: =IF($B$10=$B$11,H13-F13,"") | W13: =F13 -> 0 | X13: =H13 | Y13: =G13*(-1) -> 0 | Z13: =I13+J13 -> 0
A14: Terminas | B14: =IF(B10=B11,SUMPRODUCT(L3:L20,G3:G20)/SUM(G3:G20),"") | H14: =IF($B$9>0,$B$9,"") | L14: =IF($B$10=$B$11,H14-F14,"") | W14: =F14 -> 0 | X14: =H14 | Y14: =G14*(-1) -> 0 | Z14: =I14+J14 -> 0
H15: =IF($B$9>0,$B$9,"") | L15: =IF($B$10=$B$11,H15-F15,"") | W15: =F15 -> 0 | X15: =H15 | Y15: =G15*(-1) -> 0 | Z15: =I15+J15 -> 0
H16: =IF($B$9>0,$B$9,"") | L16: =IF($B$10=$B$11,H16-F16,"") | W16: =F16 -> 0 | X16: =H16 | Y16: =G16*(-1) -> 0 | Z16: =I16+J16 -> 0
H17: =IF($B$9>0,$B$9,"") | L17: =IF($B$10=$B$11,H17-F17,"") | W17: =F17 -> 0 | X17: =H17 | Y17: =G17*(-1) -> 0 | Z17: =I17+J17 -> 0
H18: =IF($B$9>0,$B$9,"") | L18: =IF($B$10=$B$11,H18-F18,"") | W18: =F18 -> 0 | X18: =H18 | Y18: =G18*(-1) -> 0 | Z18: =I18+J18 -> 0
W19: =F19 -> 0 | X19: =H19 -> 0 | Y19: =G19*(-1) -> 0 | Z19: =I19+J19 -> 0
W20: =F20 -> 0 | X20: =H20 -> 0 | Y20: =G20*(-1) -> 0 | Z20: =I20+J20 -> 0

Sheet J071
A1: Mortgage loan ID | B1: J071 | E1: Note | F1: Investuota | H1: Grąžinimas
A2: Pavadinimas | B2: Apartments in Sevilla | F2: Data | G2: Suma | H2: Grąž. Data | I2: Paskola | J2: Palūkanos | K2: Pelnas | L2: Laikas
A3: PTV | B3: 0.6 | D3: 1 | E3: LV0000103620 | F3: 45740 | G3: 3.99 | H3: =IF($B$9>0,$B$9,"") | L3: =IF($B$10=$B$11,H3-F3,"") | W3: =F3 -> 45740 | X3: =H3 | Y3: =G3*(-1) -> -3.99 | Z3: =I3+J3 -> 0
A4: PDT | B4: 0.48 | H4: =IF($B$9>0,$B$9,"") | L4: =IF($B$10=$B$11,H4-F4,"") | W4: =F4 -> 0 | X4: =H4 | Y4: =G4*(-1) -> 0 | Z4: =I4+J4 -> 0
H5: =IF($B$9>0,$B$9,"") | L5: =IF($B$10=$B$11,H5-F5,"") | W5: =F5 -> 0 | X5: =H5 | Y5: =G5*(-1) -> 0 | Z5: =I5+J5 -> 0
H6: =IF($B$9>0,$B$9,"") | L6: =IF($B$10=$B$11,H6-F6,"") | W6: =F6 -> 0 | X6: =H6 | Y6: =G6*(-1) -> 0 | Z6: =I6+J6 -> 0
A7: Investuota | B7: =SUMPRODUCT(F3:F20,G3:G20)/SUM(G3:G20) -> 45740 | H7: =IF($B$9>0,$B$9,"") | L7: =IF($B$10=$B$11,H7-F7,"") | W7: =F7 -> 0 | X7: =H7 | Y7: =G7*(-1) -> 0 | Z7: =I7+J7 -> 0
A8: Paskolos pradžia | B8: 45551 | H8: =IF($B$9>0,$B$9,"") | L8: =IF($B$10=$B$11,H8-F8,"") | W8: =F8 -> 0 | X8: =H8 | Y8: =G8*(-1) -> 0 | Z8: =I8+J8 -> 0
A9: Paskola grąžinta | H9: =IF($B$9>0,$B$9,"") | L9: =IF($B$10=$B$11,H9-F9,"") | W9: =F9 -> 0 | X9: =H9 | Y9: =G9*(-1) -> 0 | Z9: =I9+J9 -> 0
A10: Investuota | B10: =SUM(G3:G20) -> 3.99 | H10: =IF($B$9>0,$B$9,"") | L10: =IF($B$10=$B$11,H10-F10,"") | W10: =F10 -> 0 | X10: =H10 | Y10: =G10*(-1) -> 0 | Z10: =I10+J10 -> 0
A11: Grąžinta | B11: =SUM(I3:I20) -> 0 | H11: =IF($B$9>0,$B$9,"") | L11: =IF($B$10=$B$11,H11-F11,"") | W11: =F11 -> 0 | X11: =H11 | Y11: =G11*(-1) -> 0 | Z11: =I11+J11 -> 0
A12: Palūkanos | B12: =SUM(J3:J20) -> 0 | H12: =IF($B$9>0,$B$9,"") | L12: =IF($B$10=$B$11,H12-F12,"") | W12: =F12 -> 0 | X12: =H12 | Y12: =G12*(-1) -> 0 | Z12: =I12+J12 -> 0
A13: XIRR | B13: =IF(B10=B11,XIRR(Y3:Z20,W3:X20),"") | H13: =IF($B$9>0,$B$9,"") | L13: =IF($B$10=$B$11,H13-F13,"") | W13: =F13 -> 0 | X13: =H13 | Y13: =G13*(-1) -> 0 | Z13: =I13+J13 -> 0
A14: Terminas | B14: =IF(B10=B11,SUMPRODUCT(L3:L20,G3:G20)/SUM(G3:G20),"") | H14: =IF($B$9>0,$B$9,"") | L14: =IF($B$10=$B$11,H14-F14,"") | W14: =F14 -> 0 | X14: =H14 | Y14: =G14*(-1) -> 0 | Z14: =I14+J14 -> 0
H15: =IF($B$9>0,$B$9,"") | L15: =IF($B$10=$B$11,H15-F15,"") | W15: =F15 -> 0 | X15: =H15 | Y15: =G15*(-1) -> 0 | Z15: =I15+J15 -> 0
H16: =IF($B$9>0,$B$9,"") | L16: =IF($B$10=$B$11,H16-F16,"") | W16: =F16 -> 0 | X16: =H16 | Y16: =G16*(-1) -> 0 | Z16: =I16+J16 -> 0
H17: =IF($B$9>0,$B$9,"") | L17: =IF($B$10=$B$11,H17-F17,"") | W17: =F17 -> 0 | X17: =H17 | Y17: =G17*(-1) -> 0 | Z17: =I17+J17 -> 0
H18: =IF($B$9>0,$B$9,"") | L18: =IF($B$10=$B$11,H18-F18,"") | W18: =F18 -> 0 | X18: =H18 | Y18: =G18*(-1) -> 0 | Z18: =I18+J18 -> 0
W19: =F19 -> 0 | X19: =H19 -> 0 | Y19: =G19*(-1) -> 0 | Z19: =I19+J19 -> 0
W20: =F20 -> 0 | X20: =H20 -> 0 | Y20: =G20*(-1) -> 0 | Z20: =I20+J20 -> 0

Sheet R077
A1: Mortgage loan ID | B1: R077 | E1: Note | F1: Investuota | H1: Grąžinimas
A2: Pavadinimas | B2: House in Les Franqueses del Valles | F2: Data | G2: Suma | H2: Grąž. Data | I2: Paskola | J2: Palūkanos | K2: Pelnas | L2: Laikas
A3: PTV | B3: 0.59 | D3: 1 | E3: LV0000103604 | F3: 45740 | G3: 3.58 | H3: =IF($B$9>0,$B$9,"") | L3: =IF($B$10=$B$11,H3-F3,"") | W3: =F3 -> 45740 | X3: =H3 | Y3: =G3*(-1) -> -3.58 | Z3: =I3+J3 -> 0
A4: PDT | B4: 0.63 | D4: 2 | E4: LV0000103612 | F4: 45740 | G4: 1.02 | H4: =IF($B$9>0,$B$9,"") | L4: =IF($B$10=$B$11,H4-F4,"") | W4: =F4 -> 45740 | X4: =H4 | Y4: =G4*(-1) -> -1.02 | Z4: =I4+J4 -> 0
H5: =IF($B$9>0,$B$9,"") | L5: =IF($B$10=$B$11,H5-F5,"") | W5: =F5 -> 0 | X5: =H5 | Y5: =G5*(-1) -> 0 | Z5: =I5+J5 -> 0
H6: =IF($B$9>0,$B$9,"") | L6: =IF($B$10=$B$11,H6-F6,"") | W6: =F6 -> 0 | X6: =H6 | Y6: =G6*(-1) -> 0 | Z6: =I6+J6 -> 0
A7: Investuota | B7: =SUMPRODUCT(F3:F20,G3:G20)/SUM(G3:G20) -> 45740 | H7: =IF($B$9>0,$B$9,"") | L7: =IF($B$10=$B$11,H7-F7,"") | W7: =F7 -> 0 | X7: =H7 | Y7: =G7*(-1) -> 0 | Z7: =I7+J7 -> 0
A8: Paskolos pradžia | B8: 45624 | H8: =IF($B$9>0,$B$9,"") | L8: =IF($B$10=$B$11,H8-F8,"") | W8: =F8 -> 0 | X8: =H8 | Y8: =G8*(-1) -> 0 | Z8: =I8+J8 -> 0
A9: Paskola grąžinta | H9: =IF($B$9>0,$B$9,"") | L9: =IF($B$10=$B$11,H9-F9,"") | W9: =F9 -> 0 | X9: =H9 | Y9: =G9*(-1) -> 0 | Z9: =I9+J9 -> 0
A10: Investuota | B10: =SUM(G3:G20) -> 4.6 | H10: =IF($B$9>0,$B$9,"") | L10: =IF($B$10=$B$11,H10-F10,"") | W10: =F10 -> 0 | X10: =H10 | Y10: =G10*(-1) -> 0 | Z10: =I10+J10 -> 0
A11: Grąžinta | B11: =SUM(I3:I20) -> 0 | H11: =IF($B$9>0,$B$9,"") | L11: =IF($B$10=$B$11,H11-F11,"") | W11: =F11 -> 0 | X11: =H11 | Y11: =G11*(-1) -> 0 | Z11: =I11+J11 -> 0
A12: Palūkanos | B12: =SUM(J3:J20) -> 0 | H12: =IF($B$9>0,$B$9,"") | L12: =IF($B$10=$B$11,H12-F12,"") | W12: =F12 -> 0 | X12: =H12 | Y12: =G12*(-1) -> 0 | Z12: =I12+J12 -> 0
A13: XIRR | B13: =IF(B10=B11,XIRR(Y3:Z20,W3:X20),"") | H13: =IF($B$9>0,$B$9,"") | L13: =IF($B$10=$B$11,H13-F13,"") | W13: =F13 -> 0 | X13: =H13 | Y13: =G13*(-1) -> 0 | Z13: =I13+J13 -> 0
A14: Terminas | B14: =IF(B10=B11,SUMPRODUCT(L3:L20,G3:G20)/SUM(G3:G20),"") | H14: =IF($B$9>0,$B$9,"") | L14: =IF($B$10=$B$11,H14-F14,"") | W14: =F14 -> 0 | X14: =H14 | Y14: =G14*(-1) -> 0 | Z14: =I14+J14 -> 0
H15: =IF($B$9>0,$B$9,"") | L15: =IF($B$10=$B$11,H15-F15,"") | W15: =F15 -> 0 | X15: =H15 | Y15: =G15*(-1) -> 0 | Z15: =I15+J15 -> 0
H16: =IF($B$9>0,$B$9,"") | L16: =IF($B$10=$B$11,H16-F16,"") | W16: =F16 -> 0 | X16: =H16 | Y16: =G16*(-1) -> 0 | Z16: =I16+J16 -> 0
H17: =IF($B$9>0,$B$9,"") | L17: =IF($B$10=$B$11,H17-F17,"") | W17: =F17 -> 0 | X17: =H17 | Y17: =G17*(-1) -> 0 | Z17: =I17+J17 -> 0
H18: =IF($B$9>0,$B$9,"") | L18: =IF($B$10=$B$11,H18-F18,"") | W18: =F18 -> 0 | X18: =H18 | Y18: =G18*(-1) -> 0 | Z18: =I18+J18 -> 0
W19: =F19 -> 0 | X19: =H19 -> 0 | Y19: =G19*(-1) -> 0 | Z19: =I19+J19 -> 0
W20: =F20 -> 0 | X20: =H20 -> 0 | Y20: =G20*(-1) -> 0 | Z20: =I20+J20 -> 0

Sheet R078
A1: Mortgage loan ID | B1: R078 | E1: Note | F1: Investuota | H1: Grąžinimas
A2: Pavadinimas | B2: House in Lloret de Mar | F2: Data | G2: Suma | H2: Grąž. Data | I2: Paskola | J2: Palūkanos | K2: Pelnas | L2: Laikas
A3: PTV | B3: 0.74 | D3: 1 | E3: LV0000103604 | F3: 45740 | G3: 2.74 | H3: =IF($B$9>0,$B$9,"") | L3: =IF($B$10=$B$11,H3-F3,"") | W3: =F3 -> 45740 | X3: =H3 | Y3: =G3*(-1) -> -2.74 | Z3: =I3+J3 -> 0
A4: PDT | B4: 0.84 | H4: =IF($B$9>0,$B$9,"") | L4: =IF($B$10=$B$11,H4-F4,"") | W4: =F4 -> 0 | X4: =H4 | Y4: =G4*(-1) -> 0 | Z4: =I4+J4 -> 0
H5: =IF($B$9>0,$B$9,"") | L5: =IF($B$10=$B$11,H5-F5,"") | W5: =F5 -> 0 | X5: =H5 | Y5: =G5*(-1) -> 0 | Z5: =I5+J5 -> 0
H6: =IF($B$9>0,$B$9,"") | L6: =IF($B$10=$B$11,H6-F6,"") | W6: =F6 -> 0 | X6: =H6 | Y6: =G6*(-1) -> 0 | Z6: =I6+J6 -> 0
A7: Investuota | B7: =SUMPRODUCT(F3:F20,G3:G20)/SUM(G3:G20) -> 45740 | H7: =IF($B$9>0,$B$9,"") | L7: =IF($B$10=$B$11,H7-F7,"") | W7: =F7 -> 0 | X7: =H7 | Y7: =G7*(-1) -> 0 | Z7: =I7+J7 -> 0
A8: Paskolos pradžia | B8: 45624 | H8: =IF($B$9>0,$B$9,"") | L8: =IF($B$10=$B$11,H8-F8,"") | W8: =F8 -> 0 | X8: =H8 | Y8: =G8*(-1) -> 0 | Z8: =I8+J8 -> 0
A9: Paskola grąžinta | H9: =IF($B$9>0,$B$9,"") | L9: =IF($B$10=$B$11,H9-F9,"") | W9: =F9 -> 0 | X9: =H9 | Y9: =G9*(-1) -> 0 | Z9: =I9+J9 -> 0
A10: Investuota | B10: =SUM(G3:G20) -> 2.74 | H10: =IF($B$9>0,$B$9,"") | L10: =IF($B$10=$B$11,H10-F10,"") | W10: =F10 -> 0 | X10: =H10 | Y10: =G10*(-1) -> 0 | Z10: =I10+J10 -> 0
A11: Grąžinta | B11: =SUM(I3:I20) -> 0 | H11: =IF($B$9>0,$B$9,"") | L11: =IF($B$10=$B$11,H11-F11,"") | W11: =F11 -> 0 | X11: =H11 | Y11: =G11*(-1) -> 0 | Z11: =I11+J11 -> 0
A12: Palūkanos | B12: =SUM(J3:J20) -> 0 | H12: =IF($B$9>0,$B$9,"") | L12: =IF($B$10=$B$11,H12-F12,"") | W12: =F12 -> 0 | X12: =H12 | Y12: =G12*(-1) -> 0 | Z12: =I12+J12 -> 0
A13: XIRR | B13: =IF(B10=B11,XIRR(Y3:Z20,W3:X20),"") | H13: =IF($B$9>0,$B$9,"") | L13: =IF($B$10=$B$11,H13-F13,"") | W13: =F13 -> 0 | X13: =H13 | Y13: =G13*(-1) -> 0 | Z13: =I13+J13 -> 0
A14: Terminas | B14: =IF(B10=B11,SUMPRODUCT(L3:L20,G3:G20)/SUM(G3:G20),"") | H14: =IF($B$9>0,$B$9,"") | L14: =IF($B$10=$B$11,H14-F14,"") | W14: =F14 -> 0 | X14: =H14 | Y14: =G14*(-1) -> 0 | Z14: =I14+J14 -> 0
H15: =IF($B$9>0,$B$9,"") | L15: =IF($B$10=$B$11,H15-F15,"") | W15: =F15 -> 0 | X15: =H15 | Y15: =G15*(-1) -> 0 | Z15: =I15+J15 -> 0
H16: =IF($B$9>0,$B$9,"") | L16: =IF($B$10=$B$11,H16-F16,"") | W16: =F16 -> 0 | X16: =H16 | Y16: =G16*(-1) -> 0 | Z16: =I16+J16 -> 0
H17: =IF($B$9>0,$B$9,"") | L17: =IF($B$10=$B$11,H17-F17,"") | W17: =F17 -> 0 | X17: =H17 | Y17: =G17*(-1) -> 0 | Z17: =I17+J17 -> 0
H18: =IF($B$9>0,$B$9,"") | L18: =IF($B$10=$B$11,H18-F18,"") | W18: =F18 -> 0 | X18: =H18 | Y18: =G18*(-1) -> 0 | Z18: =I18+J18 -> 0
W19: =F19 -> 0 | X19: =H19 -> 0 | Y19: =G19*(-1) -> 0 | Z19: =I19+J19 -> 0
W20: =F20 -> 0 | X20: =H20 -> 0 | Y20: =G20*(-1) -> 0 | Z20: =I20+J20 -> 0

Sheet R079
A1: Mortgage loan ID | B1: R079 | E1: Note | F1: Investuota | H1: Grąžinimas
A2: Pavadinimas | B2: House in Les Preses | F2: Data | G2: Suma | H2: Grąž. Data | I2: Paskola | J2: Palūkanos | K2: Pelnas | L2: Laikas
A3: PTV | B3: 0.6 | D3: 1 | E3: LV0000103604 | F3: 45740 | G3: 1 | H3: =IF($B$9>0,$B$9,"") -> 45817 | I3: 1 | J3: 0.05 | K3: 0.2752 | L3: =IF($B$10=$B$11,H3-F3,"") -> 77 | W3: =F3 -> 45740 | X3: =H3 -> 45817 | Y3: =G3*(-1) -> -1 | Z3: =I3+J3 -> 1.05
A4: PDT | B4: 0.57 | W4: =F4 -> 0 | X4: =H4 -> 0 | Y4: =G4*(-1) -> 0 | Z4: =I4+J4 -> 0
W5: =F5 -> 0 | X5: =H5 -> 0 | Y5: =G5*(-1) -> 0 | Z5: =I5+J5 -> 0
W6: =F6 -> 0 | X6: =H6 -> 0 | Y6: =G6*(-1) -> 0 | Z6: =I6+J6 -> 0
A7: Investuota | B7: =SUMPRODUCT(F3:F20,G3:G20)/SUM(G3:G20) -> 45740 | W7: =F7 -> 0 | X7: =H7 -> 0 | Y7: =G7*(-1) -> 0 | Z7: =I7+J7 -> 0
A8: Paskolos pradžia | B8: 45624 | W8: =F8 -> 0 | X8: =H8 -> 0 | Y8: =G8*(-1) -> 0 | Z8: =I8+J8 -> 0
A9: Paskola grąžinta | B9: 45817 | W9: =F9 -> 0 | X9: =H9 -> 0 | Y9: =G9*(-1) -> 0 | Z9: =I9+J9 -> 0
A10: Investuota | B10: =SUM(G3:G20) -> 1 | W10: =F10 -> 0 | X10: =H10 -> 0 | Y10: =G10*(-1) -> 0 | Z10: =I10+J10 -> 0
A11: Grąžinta | B11: =SUM(I3:I20) -> 1 | W11: =F11 -> 0 | X11: =H11 -> 0 | Y11: =G11*(-1) -> 0 | Z11: =I11+J11 -> 0
A12: Palūkanos | B12: =SUM(J3:J20) -> 0.05 | W12: =F12 -> 0 | X12: =H12 -> 0 | Y12: =G12*(-1) -> 0 | Z12: =I12+J12 -> 0
A13: XIRR | B13: =IF(B10=B11,XIRR(Y3:Z20,W3:X20),"") -> 0.26020959 | W13: =F13 -> 0 | X13: =H13 -> 0 | Y13: =G13*(-1) -> 0 | Z13: =I13+J13 -> 0
A14: Terminas | B14: =IF(B10=B11,SUMPRODUCT(L3:L20,G3:G20)/SUM(G3:G20),"") -> 77 | W14: =F14 -> 0 | X14: =H14 -> 0 | Y14: =G14*(-1) -> 0 | Z14: =I14+J14 -> 0
W15: =F15 -> 0 | X15: =H15 -> 0 | Y15: =G15*(-1) -> 0 | Z15: =I15+J15 -> 0
W16: =F16 -> 0 | X16: =H16 -> 0 | Y16: =G16*(-1) -> 0 | Z16: =I16+J16 -> 0
W17: =F17 -> 0 | X17: =H17 -> 0 | Y17: =G17*(-1) -> 0 | Z17: =I17+J17 -> 0
W18: =F18 -> 0 | X18: =H18 -> 0 | Y18: =G18*(-1) -> 0 | Z18: =I18+J18 -> 0
W19: =F19 -> 0 | X19: =H19 -> 0 | Y19: =G19*(-1) -> 0 | Z19: =I19+J19 -> 0
W20: =F20 -> 0 | X20: =H20 -> 0 | Y20: =G20*(-1) -> 0 | Z20: =I20+J20 -> 0

Sheet R080
A1: Mortgage loan ID | B1: R080 | E1: Note | F1: Investuota | H1: Grąžinimas
A2: Pavadinimas | B2: Apartament in St. Cugat Valles | F2: Data | G2: Suma | H2: Grąž. Data | I2: Paskola | J2: Palūkanos | K2: Pelnas | L2: Laikas
A3: PTV | B3: 0.55 | D3: 1 | E3: LV0000103604 | F3: 45741 | G3: 4.19 | H3: =IF($B$9>0,$B$9,"") | L3: =IF($B$10=$B$11,H3-F3,"") | W3: =F3 -> 45741 | X3: =H3 | Y3: =G3*(-1) -> -4.19 | Z3: =I3+J3 -> 0
A4: PDT | B4: 0.59 | H4: =IF($B$9>0,$B$9,"") | L4: =IF($B$10=$B$11,H4-F4,"") | W4: =F4 -> 0 | X4: =H4 | Y4: =G4*(-1) -> 0 | Z4: =I4+J4 -> 0
H5: =IF($B$9>0,$B$9,"") | L5: =IF($B$10=$B$11,H5-F5,"") | W5: =F5 -> 0 | X5: =H5 | Y5: =G5*(-1) -> 0 | Z5: =I5+J5 -> 0
H6: =IF($B$9>0,$B$9,"") | L6: =IF($B$10=$B$11,H6-F6,"") | W6: =F6 -> 0 | X6: =H6 | Y6: =G6*(-1) -> 0 | Z6: =I6+J6 -> 0
A7: Investuota | B7: =SUMPRODUCT(F3:F20,G3:G20)/SUM(G3:G20) -> 45741 | H7: =IF($B$9>0,$B$9,"") | L7: =IF($B$10=$B$11,H7-F7,"") | W7: =F7 -> 0 | X7: =H7 | Y7: =G7*(-1) -> 0 | Z7: =I7+J7 -> 0
A8: Paskolos pradžia | B8: 45624 | H8: =IF($B$9>0,$B$9,"") | L8: =IF($B$10=$B$11,H8-F8,"") | W8: =F8 -> 0 | X8: =H8 | Y8: =G8*(-1) -> 0 | Z8: =I8+J8 -> 0
A9: Paskola grąžinta | H9: =IF($B$9>0,$B$9,"") | L9: =IF($B$10=$B$11,H9-F9,"") | W9: =F9 -> 0 | X9: =H9 | Y9: =G9*(-1) -> 0 | Z9: =I9+J9 -> 0
A10: Investuota | B10: =SUM(G3:G20) -> 4.19 | H10: =IF($B$9>0,$B$9,"") | L10: =IF($B$10=$B$11,H10-F10,"") | W10: =F10 -> 0 | X10: =H10 | Y10: =G10*(-1) -> 0 | Z10: =I10+J10 -> 0
A11: Grąžinta | B11: =SUM(I3:I20) -> 0 | H11: =IF($B$9>0,$B$9,"") | L11: =IF($B$10=$B$11,H11-F11,"") | W11: =F11 -> 0 | X11: =H11 | Y11: =G11*(-1) -> 0 | Z11: =I11+J11 -> 0
A12: Palūkanos | B12: =SUM(J3:J20) -> 0 | H12: =IF($B$9>0,$B$9,"") | L12: =IF($B$10=$B$11,H12-F12,"") | W12: =F12 -> 0 | X12: =H12 | Y12: =G12*(-1) -> 0 | Z12: =I12+J12 -> 0
A13: XIRR | B13: =IF(B10=B11,XIRR(Y3:Z20,W3:X20),"") | H13: =IF($B$9>0,$B$9,"") | L13: =IF($B$10=$B$11,H13-F13,"") | W13: =F13 -> 0 | X13: =H13 | Y13: =G13*(-1) -> 0 | Z13: =I13+J13 -> 0
A14: Terminas | B14: =IF(B10=B11,SUMPRODUCT(L3:L20,G3:G20)/SUM(G3:G20),"") | H14: =IF($B$9>0,$B$9,"") | L14: =IF($B$10=$B$11,H14-F14,"") | W14: =F14 -> 0 | X14: =H14 | Y14: =G14*(-1) -> 0 | Z14: =I14+J14 -> 0
H15: =IF($B$9>0,$B$9,"") | L15: =IF($B$10=$B$11,H15-F15,"") | W15: =F15 -> 0 | X15: =H15 | Y15: =G15*(-1) -> 0 | Z15: =I15+J15 -> 0
H16: =IF($B$9>0,$B$9,"") | L16: =IF($B$10=$B$11,H16-F16,"") | W16: =F16 -> 0 | X16: =H16 | Y16: =G16*(-1) -> 0 | Z16: =I16+J16 -> 0
H17: =IF($B$9>0,$B$9,"") | L17: =IF($B$10=$B$11,H17-F17,"") | W17: =F17 -> 0 | X17: =H17 | Y17: =G17*(-1) -> 0 | Z17: =I17+J17 -> 0
H18: =IF($B$9>0,$B$9,"") | L18: =IF($B$10=$B$11,H18-F18,"") | W18: =F18 -> 0 | X18: =H18 | Y18: =G18*(-1) -> 0 | Z18: =I18+J18 -> 0
W19: =F19 -> 0 | X19: =H19 -> 0 | Y19: =G19*(-1) -> 0 | Z19: =I19+J19 -> 0
W20: =F20 -> 0 | X20: =H20 -> 0 | Y20: =G20*(-1) -> 0 | Z20: =I20+J20 -> 0

Sheet R081
A1: Mortgage loan ID | B1: R081 | E1: Note | F1: Investuota | H1: Grąžinimas
A2: Pavadinimas | B2: House in Llinars del Valles | F2: Data | G2: Suma | H2: Grąž. Data | I2: Paskola | J2: Palūkanos | K2: Pelnas | L2: Laikas
A3: PTV | B3: 0.46 | D3: 1 | E3: LV0000103612 | F3: 45741 | G3: 1.21 | H3: =IF($B$9>0,$B$9,"") | L3: =IF($B$10=$B$11,H3-F3,"") | W3: =F3 -> 45741 | X3: =H3 | Y3: =G3*(-1) -> -1.21 | Z3: =I3+J3 -> 0
A4: PDT | B4: 0.52 | H4: =IF($B$9>0,$B$9,"") | L4: =IF($B$10=$B$11,H4-F4,"") | W4: =F4 -> 0 | X4: =H4 | Y4: =G4*(-1) -> 0 | Z4: =I4+J4 -> 0
H5: =IF($B$9>0,$B$9,"") | L5: =IF($B$10=$B$11,H5-F5,"") | W5: =F5 -> 0 | X5: =H5 | Y5: =G5*(-1) -> 0 | Z5: =I5+J5 -> 0
H6: =IF($B$9>0,$B$9,"") | L6: =IF($B$10=$B$11,H6-F6,"") | W6: =F6 -> 0 | X6: =H6 | Y6: =G6*(-1) -> 0 | Z6: =I6+J6 -> 0
A7: Investuota | B7: =SUMPRODUCT(F3:F20,G3:G20)/SUM(G3:G20) -> 45741 | H7: =IF($B$9>0,$B$9,"") | L7: =IF($B$10=$B$11,H7-F7,"") | W7: =F7 -> 0 | X7: =H7 | Y7: =G7*(-1) -> 0 | Z7: =I7+J7 -> 0
A8: Paskolos pradžia | B8: 45666 | H8: =IF($B$9>0,$B$9,"") | L8: =IF($B$10=$B$11,H8-F8,"") | W8: =F8 -> 0 | X8: =H8 | Y8: =G8*(-1) -> 0 | Z8: =I8+J8 -> 0
A9: Paskola grąžinta | H9: =IF($B$9>0,$B$9,"") | L9: =IF($B$10=$B$11,H9-F9,"") | W9: =F9 -> 0 | X9: =H9 | Y9: =G9*(-1) -> 0 | Z9: =I9+J9 -> 0
A10: Investuota | B10: =SUM(G3:G20) -> 1.21 | H10: =IF($B$9>0,$B$9,"") | L10: =IF($B$10=$B$11,H10-F10,"") | W10: =F10 -> 0 | X10: =H10 | Y10: =G10*(-1) -> 0 | Z10: =I10+J10 -> 0
A11: Grąžinta | B11: =SUM(I3:I20) -> 0 | H11: =IF($B$9>0,$B$9,"") | L11: =IF($B$10=$B$11,H11-F11,"") | W11: =F11 -> 0 | X11: =H11 | Y11: =G11*(-1) -> 0 | Z11: =I11+J11 -> 0
A12: Palūkanos | B12: =SUM(J3:J20) -> 0 | H12: =IF($B$9>0,$B$9,"") | L12: =IF($B$10=$B$11,H12-F12,"") | W12: =F12 -> 0 | X12: =H12 | Y12: =G12*(-1) -> 0 | Z12: =I12+J12 -> 0
A13: XIRR | B13: =IF(B10=B11,XIRR(Y3:Z20,W3:X20),"") | H13: =IF($B$9>0,$B$9,"") | L13: =IF($B$10=$B$11,H13-F13,"") | W13: =F13 -> 0 | X13: =H13 | Y13: =G13*(-1) -> 0 | Z13: =I13+J13 -> 0
A14: Terminas | B14: =IF(B10=B11,SUMPRODUCT(L3:L20,G3:G20)/SUM(G3:G20),"") | H14: =IF($B$9>0,$B$9,"") | L14: =IF($B$10=$B$11,H14-F14,"") | W14: =F14 -> 0 | X14: =H14 | Y14: =G14*(-1) -> 0 | Z14: =I14+J14 -> 0
H15: =IF($B$9>0,$B$9,"") | L15: =IF($B$10=$B$11,H15-F15,"") | W15: =F15 -> 0 | X15: =H15 | Y15: =G15*(-1) -> 0 | Z15: =I15+J15 -> 0
H16: =IF($B$9>0,$B$9,"") | L16: =IF($B$10=$B$11,H16-F16,"") | W16: =F16 -> 0 | X16: =H16 | Y16: =G16*(-1) -> 0 | Z16: =I16+J16 -> 0
H17: =IF($B$9>0,$B$9,"") | L17: =IF($B$10=$B$11,H17-F17,"") | W17: =F17 -> 0 | X17: =H17 | Y17: =G17*(-1) -> 0 | Z17: =I17+J17 -> 0
H18: =IF($B$9>0,$B$9,"") | L18: =IF($B$10=$B$11,H18-F18,"") | W18: =F18 -> 0 | X18: =H18 | Y18: =G18*(-1) -> 0 | Z18: =I18+J18 -> 0
W19: =F19 -> 0 | X19: =H19 -> 0 | Y19: =G19*(-1) -> 0 | Z19: =I19+J19 -> 0
W20: =F20 -> 0 | X20: =H20 -> 0 | Y20: =G20*(-1) -> 0 | Z20: =I20+J20 -> 0

Sheet R089
A1: Mortgage loan ID | B1: R089 | E1: Note | F1: Investuota | H1: Grąžinimas
A2: Pavadinimas | B2: House in Castellar del Valles | F2: Data | G2: Suma | H2: Grąž. Data | I2: Paskola | J2: Palūkanos | K2: Pelnas | L2: Laikas
A3: PTV | B3: 0.64 | D3: 1 | E3: LV0000105062 | F3: 45831 | G3: 2.32 | H3: =IF($B$9>0,$B$9,"") | L3: =IF($B$10=$B$11,H3-F3,"") | W3: =F3 -> 45831 | X3: =H3 | Y3: =G3*(-1) -> -2.32 | Z3: =I3+J3 -> 0
A4: PDT | B4: 0.42 | H4: =IF($B$9>0,$B$9,"") | L4: =IF($B$10=$B$11,H4-F4,"") | W4: =F4 -> 0 | X4: =H4 | Y4: =G4*(-1) -> 0 | Z4: =I4+J4 -> 0
H5: =IF($B$9>0,$B$9,"") | L5: =IF($B$10=$B$11,H5-F5,"") | W5: =F5 -> 0 | X5: =H5 | Y5: =G5*(-1) -> 0 | Z5: =I5+J5 -> 0
H6: =IF($B$9>0,$B$9,"") | L6: =IF($B$10=$B$11,H6-F6,"") | W6: =F6 -> 0 | X6: =H6 | Y6: =G6*(-1) -> 0 | Z6: =I6+J6 -> 0
A7: Investuota | B7: =SUMPRODUCT(F3:F20,G3:G20)/SUM(G3:G20) -> 45831 | H7: =IF($B$9>0,$B$9,"") | L7: =IF($B$10=$B$11,H7-F7,"") | W7: =F7 -> 0 | X7: =H7 | Y7: =G7*(-1) -> 0 | Z7: =I7+J7 -> 0
A8: Paskolos pradžia | B8: 45740 | H8: =IF($B$9>0,$B$9,"") | L8: =IF($B$10=$B$11,H8-F8,"") | W8: =F8 -> 0 | X8: =H8 | Y8: =G8*(-1) -> 0 | Z8: =I8+J8 -> 0
A9: Paskola grąžinta | H9: =IF($B$9>0,$B$9,"") | L9: =IF($B$10=$B$11,H9-F9,"") | W9: =F9 -> 0 | X9: =H9 | Y9: =G9*(-1) -> 0 | Z9: =I9+J9 -> 0
A10: Investuota | B10: =SUM(G3:G20) -> 2.32 | H10: =IF($B$9>0,$B$9,"") | L10: =IF($B$10=$B$11,H10-F10,"") | W10: =F10 -> 0 | X10: =H10 | Y10: =G10*(-1) -> 0 | Z10: =I10+J10 -> 0
A11: Grąžinta | B11: =SUM(I3:I20) -> 0 | H11: =IF($B$9>0,$B$9,"") | L11: =IF($B$10=$B$11,H11-F11,"") | W11: =F11 -> 0 | X11: =H11 | Y11: =G11*(-1) -> 0 | Z11: =I11+J11 -> 0
A12: Palūkanos | B12: =SUM(J3:J20) -> 0 | H12: =IF($B$9>0,$B$9,"") | L12: =IF($B$10=$B$11,H12-F12,"") | W12: =F12 -> 0 | X12: =H12 | Y12: =G12*(-1) -> 0 | Z12: =I12+J12 -> 0
A13: XIRR | B13: =IF(B10=B11,XIRR(Y3:Z20,W3:X20),"") | H13: =IF($B$9>0,$B$9,"") | L13: =IF($B$10=$B$11,H13-F13,"") | W13: =F13 -> 0 | X13: =H13 | Y13: =G13*(-1) -> 0 | Z13: =I13+J13 -> 0
A14: Terminas | B14: =IF(B10=B11,SUMPRODUCT(L3:L20,G3:G20)/SUM(G3:G20),"") | H14: =IF($B$9>0,$B$9,"") | L14: =IF($B$10=$B$11,H14-F14,"") | W14: =F14 -> 0 | X14: =H14 | Y14: =G14*(-1) -> 0 | Z14: =I14+J14 -> 0
H15: =IF($B$9>0,$B$9,"") | L15: =IF($B$10=$B$11,H15-F15,"") | W15: =F15 -> 0 | X15: =H15 | Y15: =G15*(-1) -> 0 | Z15: =I15+J15 -> 0
H16: =IF($B$9>0,$B$9,"") | L16: =IF($B$10=$B$11,H16-F16,"") | W16: =F16 -> 0 | X16: =H16 | Y16: =G16*(-1) -> 0 | Z16: =I16+J16 -> 0
H17: =IF($B$9>0,$B$9,"") | L17: =IF($B$10=$B$11,H17-F17,"") | W17: =F17 -> 0 | X17: =H17 | Y17: =G17*(-1) -> 0 | Z17: =I17+J17 -> 0
H18: =IF($B$9>0,$B$9,"") | L18: =IF($B$10=$B$11,H18-F18,"") | W18: =F18 -> 0 | X18: =H18 | Y18: =G18*(-1) -> 0 | Z18: =I18+J18 -> 0
H19: =IF($B$9>0,$B$9,"") | L19: =IF($B$10=$B$11,H19-F19,"") | W19: =F19 -> 0 | X19: =H19 | Y19: =G19*(-1) -> 0 | Z19: =I19+J19 -> 0
H20: =IF($B$9>0,$B$9,"") | L20: =IF($B$10=$B$11,H20-F20,"") | W20: =F20 -> 0 | X20: =H20 | Y20: =G20*(-1) -> 0 | Z20: =I20+J20 -> 0

Sheet R090
A1: Mortgage loan ID | B1: R090 | E1: Note | F1: Investuota | H1: Grąžinimas
A2: Pavadinimas | B2: House in Llers | F2: Data | G2: Suma | H2: Grąž. Data | I2: Paskola | J2: Palūkanos | K2: Pelnas | L2: Laikas
A3: PTV | B3: 0.65 | D3: 1 | E3: LV0000105062 | F3: 45831 | G3: 2.8 | H3: =IF($B$9>0,$B$9,"") | L3: =IF($B$10=$B$11,H3-F3,"") | W3: =F3 -> 45831 | X3: =H3 | Y3: =G3*(-1) -> -2.8 | Z3: =I3+J3 -> 0
A4: PDT | B4: 0.62 | H4: =IF($B$9>0,$B$9,"") | L4: =IF($B$10=$B$11,H4-F4,"") | W4: =F4 -> 0 | X4: =H4 | Y4: =G4*(-1) -> 0 | Z4: =I4+J4 -> 0
H5: =IF($B$9>0,$B$9,"") | L5: =IF($B$10=$B$11,H5-F5,"") | W5: =F5 -> 0 | X5: =H5 | Y5: =G5*(-1) -> 0 | Z5: =I5+J5 -> 0
H6: =IF($B$9>0,$B$9,"") | L6: =IF($B$10=$B$11,H6-F6,"") | W6: =F6 -> 0 | X6: =H6 | Y6: =G6*(-1) -> 0 | Z6: =I6+J6 -> 0
A7: Investuota | B7: =SUMPRODUCT(F3:F20,G3:G20)/SUM(G3:G20) -> 45831 | H7: =IF($B$9>0,$B$9,"") | L7: =IF($B$10=$B$11,H7-F7,"") | W7: =F7 -> 0 | X7: =H7 | Y7: =G7*(-1) -> 0 | Z7: =I7+J7 -> 0
A8: Paskolos pradžia | B8: 45740 | H8: =IF($B$9>0,$B$9,"") | L8: =IF($B$10=$B$11,H8-F8,"") | W8: =F8 -> 0 | X8: =H8 | Y8: =G8*(-1) -> 0 | Z8: =I8+J8 -> 0
A9: Paskola grąžinta | H9: =IF($B$9>0,$B$9,"") | L9: =IF($B$10=$B$11,H9-F9,"") | W9: =F9 -> 0 | X9: =H9 | Y9: =G9*(-1) -> 0 | Z9: =I9+J9 -> 0
A10: Investuota | B10: =SUM(G3:G20) -> 2.8 | H10: =IF($B$9>0,$B$9,"") | L10: =IF($B$10=$B$11,H10-F10,"") | W10: =F10 -> 0 | X10: =H10 | Y10: =G10*(-1) -> 0 | Z10: =I10+J10 -> 0
A11: Grąžinta | B11: =SUM(I3:I20) -> 0 | H11: =IF($B$9>0,$B$9,"") | L11: =IF($B$10=$B$11,H11-F11,"") | W11: =F11 -> 0 | X11: =H11 | Y11: =G11*(-1) -> 0 | Z11: =I11+J11 -> 0
A12: Palūkanos | B12: =SUM(J3:J20) -> 0 | H12: =IF($B$9>0,$B$9,"") | L12: =IF($B$10=$B$11,H12-F12,"") | W12: =F12 -> 0 | X12: =H12 | Y12: =G12*(-1) -> 0 | Z12: =I12+J12 -> 0
A13: XIRR | B13: =IF(B10=B11,XIRR(Y3:Z20,W3:X20),"") | H13: =IF($B$9>0,$B$9,"") | L13: =IF($B$10=$B$11,H13-F13,"") | W13: =F13 -> 0 | X13: =H13 | Y13: =G13*(-1) -> 0 | Z13: =I13+J13 -> 0
A14: Terminas | B14: =IF(B10=B11,SUMPRODUCT(L3:L20,G3:G20)/SUM(G3:G20),"") | H14: =IF($B$9>0,$B$9,"") | L14: =IF($B$10=$B$11,H14-F14,"") | W14: =F14 -> 0 | X14: =H14 | Y14: =G14*(-1) -> 0 | Z14: =I14+J14 -> 0
H15: =IF($B$9>0,$B$9,"") | L15: =IF($B$10=$B$11,H15-F15,"") | W15: =F15 -> 0 | X15: =H15 | Y15: =G15*(-1) -> 0 | Z15: =I15+J15 -> 0
H16: =IF($B$9>0,$B$9,"") | L16: =IF($B$10=$B$11,H16-F16,"") | W16: =F16 -> 0 | X16: =H16 | Y16: =G16*(-1) -> 0 | Z16: =I16+J16 -> 0
H17: =IF($B$9>0,$B$9,"") | L17: =IF($B$10=$B$11,H17-F17,"") | W17: =F17 -> 0 | X17: =H17 | Y17: =G17*(-1) -> 0 | Z17: =I17+J17 -> 0
H18: =IF($B$9>0,$B$9,"") | L18: =IF($B$10=$B$11,H18-F18,"") | W18: =F18 -> 0 | X18: =H18 | Y18: =G18*(-1) -> 0 | Z18: =I18+J18 -> 0
H19: =IF($B$9>0,$B$9,"") | L19: =IF($B$10=$B$11,H19-F19,"") | W19: =F19 -> 0 | X19: =H19 | Y19: =G19*(-1) -> 0 | Z19: =I19+J19 -> 0
H20: =IF($B$9>0,$B$9,"") | L20: =IF($B$10=$B$11,H20-F20,"") | W20: =F20 -> 0 | X20: =H20 | Y20: =G20*(-1) -> 0 | Z20: =I20+J20 -> 0

Sheet R091
A1: Mortgage loan ID | B1: R091 | E1: Note | F1: Investuota | H1: Grąžinimas
A2: Pavadinimas | B2: Apartment in Sabadell | F2: Data | G2: Suma | H2: Grąž. Data | I2: Paskola | J2: Palūkanos | K2: Pelnas | L2: Laikas
