Workbook

Sheet Investavimas
A1: Data | B1: SEB Fondai | E1: SEB Mikro | H1: SEB Robo | K1: Revolut Brokerage | N1: Revolut Robo | Q1: Synergy | T1: Profitus | W1: Nordstreet | Z1: Indemo | AC1: Crowdpear | AF1: Scramble | AI1: Nectaro | AL1: Debitum | AO1: Viainvest | AR1: Rontgen | AU1: Afranga | AX1: Lendermarket | BA1: Loanch | BD1: Peerberry | BG1: Income | BJ1: Lande | BM1: Twino | BQ1: Fondai | BY1: P2P | CG1: Viso
B2: Investuota | C2: Vertė | D2: % | E2: Investuota | F2: Vertė | G2: % | H2: Investuota | I2: Vertė | J2: % | K2: Investuota | L2: Vertė | M2: % | N2: Investuota | O2: Vertė | P2: % | Q2: Investuota | R2: Vertė | S2: % | T2: Investuota | U2: Vertė | V2: % | W2: Investuota | X2: Vertė | Y2: % | Z2: Investuota | AA2: Vertė | AB2: % | AC2: Investuota | AD2: Vertė | AE2: % | AF2: Įnešta | AG2: Vertė | AH2: % | AI2: Įnešta | AJ2: Vertė | AK2: % | AL2: Įnešta | AM2: Vertė | AN2: % | AO2: Įnešta | AP2: Vertė | AQ2: % | AR2: Įnešta | AS2: Vertė | AT2: % | AU2: Įnešta | AV2: Vertė | AW2: % | AX2: Įnešta | AY2: Vertė | AZ2: % | BA2: Įnešta | BB2: Vertė | BC2: % | BD2: Įnešta | BE2: Vertė | BF2: % | BG2: Įnešta | BH2: Vertė | BI2: % | BJ2: Įnešta | BK2: Vertė | BL2: % | BM2: Įnešta | BN2: Vertė | BO2: % | BQ2: Data | BR2: Įnešta | BS2: Per mėn. | BT2: Vertė | BU2: Prieaugis | BV2: % | BW2: Per mėn. | BY2: Data | BZ2: Įnešta | CA2: Per mėn. | CB2: Vertė | CC2: Prieaugis | CD2: % | CE2: Per mėn. | CG2: Data | CH2: Įnešta | CI2: Per mėn. | CJ2: Vertė | CK2: Prieaugis | CL2: % | CM2: Per mėn. | CO2: =A1 -> Data | CP2: =B1 -> SEB Fondai | CQ2: =E1 -> SEB Mikro | CR2: =H1 -> SEB Robo | CS2: =K1 -> Revolut Brokerage | CT2: =N1 -> Revolut Robo | CU2: =Q1 -> Synergy | CV2: =T1 -> Profitus | CW2: =W1 -> Nordstreet | CX2: =Z1 -> Indemo | CY2: =AC1 -> Crowdpear | CZ2: =AF1 -> Scramble | DA2: =AI1 -> Nectaro | DB2: =AL1 -> Debitum | DC2: =AO1 -> Viainvest | DD2: =AR1 -> Rontgen | DE2: =AU1 -> Afranga | DF2: =AX1 -> Lendermarket | DG2: =BA1 -> Loanch | DH2: =BD1 -> Peerberry | DI2: =BG1 -> Income | DJ2: =BJ1 -> Lande | DK2: =BM1 -> Twino
A3: 44377 | B3: 63 | C3: 62.88 | D3: =(C3-B3)/B3 -> -0.0019047619 | E3: 0 | F3: 0 | G3: 0 | H3: 0 | I3: 0 | J3: 0 | K3: 0 | L3: 0 | M3: 0 | N3: 0 | O3: 0 | P3: 0 | Q3: 0 | R3: 0 | S3: 0 | T3: 0 | U3: 0 | V3: 0 | W3: 0 | X3: 0 | Y3: 0 | Z3: 0 | AA3: 0 | AB3: 0 | AC3: 0 | AD3: 0 | AE3: 0 | AF3: 0 | AG3: 0 | AH3: 0 | AI3: 0 | AJ3: 0 | AK3: 0 | AL3: 0 | AM3: 0 | AN3: 0 | AO3: 0 | AP3: 0 | AQ3: 0 | AR3: 0 | AS3: 0 | AT3: 0 | AU3: 0 | AV3: 0 | AW3: 0 | AX3: 0 | AY3: 0 | AZ3: 0 | BA3: 0 | BB3: 0 | BC3: 0 | BD3: 0 | BE3: 0 | BF3: 0 | BG3: 0 | BH3: 0 | BI3: 0 | BJ3: 0 | BK3: 0 | BL3: 0 | BM3: 0 | BN3: 0 | BO3: 0 | BQ3: 44378 | BR3: =B3+E3+H3+K3+N3+Q3 -> 63 | BS3: 63 | BT3: =C3+F3+I3+L3+O3+R3 -> 62.88 | BU3: =BT3-BR3 -> -0.12 | BV3: =BU3/BR3 -> -0.0019047619 | BW3: =BU3 -> -0.12 | BY3: =A3 -> 44377 | BZ3: =Z3+T3+AC3+W3+AR3+AF3+AI3+AL3+AO3+AU3+AX3+BA3+BD3+BG3+BJ3+BM3 -> 0 | CA3: 0 | CB3: =AA3+U3+AD3+X3+AS3+AG3+AJ3+AM3+AP3+AV3+AY3+BB3+BE3 -> 0 | CC3: =CB3-BZ3 -> 0 | CD3: 0 | CE3: =CC3 -> 0 | CG3: =A3 -> 44377 | CH3: =BR3+BZ3 -> 63 | CI3: =BS3+CA3 -> 63 | CJ3: =BT3+CB3 -> 62.88 | CK3: =CJ3-CH3 -> -0.12 | CL3: =CK3/CH3 -> -0.0019047619 | CM3: =CK3 -> -0.12 | CO3: =A3 -> 44377 | CP3: =(C3-B3) -> -0.12 | CQ3: =(F3-E3) -> 0 | CR3: =(I3-H3) -> 0 | CS3: =(L3-K3) -> 0 | CT3: =O3-N3 -> 0 | CU3: =R3-Q3 -> 0 | CV3: =U3-T3 -> 0 | CW3: =X3-W3 -> 0 | CX3: =AA3-Z3 -> 0 | CY3: =AD3-AC3 -> 0 | CZ3: =AG3-AF3 -> 0 | DA3: =AJ3-AI3 -> 0 | DB3: =AM3-AL3 -> 0 | DC3: =AP3-AO3 -> 0 | DD3: =AS3-AR3 -> 0 | DE3: =(AV3-AU3) -> 0 | DF3: =(AY3-AX3) -> 0 | DG3: =(BB3-BA3) -> 0 | DH3: =(BE3-BD3) -> 0 | DI3: =(BH3-BG3) -> 0 | DJ3: =(BK3-BJ3) -> 0 | DK3: =(BN3-BM3) -> 0
A4: 44408 | B4: 81 | C4: 82.3 | D4: =(C4-B4)/B4 -> 0.016049383 | E4: 0 | F4: 0 | G4: 0 | H4: 0 | I4: 0 | J4: 0 | K4: 0 | L4: 0 | M4: 0 | N4: 0 | O4: 0 | P4: 0 | Q4: 0 | R4: 0 | S4: 0 | T4: 0 | U4: 0 | V4: 0 | W4: 0 | X4: 0 | Y4: 0 | Z4: 0 | AA4: 0 | AB4: 0 | AC4: 0 | AD4: 0 | AE4: 0 | AF4: 0 | AG4: 0 | AH4: 0 | AI4: 0 | AJ4: 0 | AK4: 0 | AL4: 0 | AM4: 0 | AN4: 0 | AO4: 0 | AP4: 0 | AQ4: 0 | AR4: 0 | AS4: 0 | AT4: 0 | AU4: 0 | AV4: 0 | AW4: 0 | AX4: 0 | AY4: 0 | AZ4: 0 | BA4: 0 | BB4: 0 | BC4: 0 | BD4: 0 | BE4: 0 | BF4: 0 | BG4: 0 | BH4: 0 | BI4: 0 | BJ4: 0 | BK4: 0 | BL4: 0 | BM4: 0 | BN4: 0 | BO4: 0 | BQ4: =A4 -> 44408 | BR4: =B4+E4+H4+K4+N4+Q4 -> 81 | BS4: =BR4-BR3 -> 18 | BT4: =C4+F4+I4+L4+O4+R4 -> 82.3 | BU4: =BT4-BR4 -> 1.3 | BV4: =BU4/BR4 -> 0.016049383 | BW4: =BU4-BU3 -> 1.42 | BY4: =A4 -> 44408 | BZ4: =Z4+T4+AC4+W4+AR4+AF4+AI4+AL4+AO4+AU4+AX4+BA4+BD4+BG4+BJ4+BM4 -> 0 | CA4: =BZ4-BZ3 -> 0 | CB4: =AA4+U4+AD4+X4+AS4+AG4+AJ4+AM4+AP4+AV4+AY4+BB4+BE4 -> 0 | CC4: =CB4-BZ4 -> 0 | CD4: 0 | CE4: =CC4-CC3 -> 0 | CG4: =A4 -> 44408 | CH4: =BR4+BZ4 -> 81 | CI4: =BS4+CA4 -> 18 | CJ4: =BT4+CB4 -> 82.3 | CK4: =CJ4-CH4 -> 1.3 | CL4: =CK4/CH4 -> 0.016049383 | CM4: =CK4-CK3 -> 1.42 | CO4: =A4 -> 44408 | CP4: =(C4-B4)-(C3-B3) -> 1.42 | CQ4: =(F4-E4)-(F3-E3) -> 0 | CR4: =(I4-H4)-(I3-H3) -> 0 | CS4: =(L4-K4)-(L3-K3) -> 0 | CT4: =(O4-N4)-(O3-N3) -> 0 | CU4: =(R4-Q4)-(R3-Q3) -> 0 | CV4: =(U4-T4)-(U3-T3) -> 0 | CW4: =(X4-W4)-(X3-W3) -> 0 | CX4: =(AA4-Z4)-(AA3-Z3) -> 0 | CY4: =(AD4-AC4)-(AD3-AC3) -> 0 | CZ4: =(AG4-AF4)-(AG3-AF3) -> 0 | DA4: =(AJ4-AI4)-(AJ3-AI3) -> 0 | DB4: =(AM4-AL4)-(AM3-AL3) -> 0 | DC4: =(AP4-AO4)-(AP3-AO3) -> 0 | DD4: =(AS4-AR4)-(AS3-AR3) -> 0 | DE4: =(AV4-AU4)-(AV3-AU3) -> 0 | DF4: =(AY4-AX4)-(AY3-AX3) -> 0 | DG4: =(BB4-BA4)-(BB3-BA3) -> 0 | DH4: =(BE4-BD4)-(BE3-BD3) -> 0 | DI4: =(BH4-BG4)-(BH3-BG3) -> 0 | DJ4: =(BK4-BJ4)-(BK3-BJ3) -> 0 | DK4: =(BN4-BM4)-(BN3-BM3) -> 0
A5: 44439 | B5: 97 | C5: 98.79 | D5: =(C5-B5)/B5 -> 0.018453608 | E5: 0 | F5: 0 | G5: 0 | H5: 0 | I5: 0 | J5: 0 | K5: 0 | L5: 0 | M5: 0 | N5: 0 | O5: 0 | P5: 0 | Q5: 0 | R5: 0 | S5: 0 | T5: 0 | U5: 0 | V5: 0 | W5: 0 | X5: 0 | Y5: 0 | Z5: 0 | AA5: 0 | AB5: 0 | AC5: 0 | AD5: 0 | AE5: 0 | AF5: 0 | AG5: 0 | AH5: 0 | AI5: 0 | AJ5: 0 | AK5: 0 | AL5: 0 | AM5: 0 | AN5: 0 | AO5: 0 | AP5: 0 | AQ5: 0 | AR5: 0 | AS5: 0 | AT5: 0 | AU5: 0 | AV5: 0 | AW5: 0 | AX5: 0 | AY5: 0 | AZ5: 0 | BA5: 0 | BB5: 0 | BC5: 0 | BD5: 0 | BE5: 0 | BF5: 0 | BG5: 0 | BH5: 0 | BI5: 0 | BJ5: 0 | BK5: 0 | BL5: 0 | BM5: 0 | BN5: 0 | BO5: 0 | BQ5: =A5 -> 44439 | BR5: =B5+E5+H5+K5+N5+Q5 -> 97 | BS5: =BR5-BR4 -> 16 | BT5: =C5+F5+I5+L5+O5+R5 -> 98.79 | BU5: =BT5-BR5 -> 1.79 | BV5: =BU5/BR5 -> 0.018453608 | BW5: =BU5-BU4 -> 0.49 | BY5: =A5 -> 44439 | BZ5: =Z5+T5+AC5+W5+AR5+AF5+AI5+AL5+AO5+AU5+AX5+BA5+BD5+BG5+BJ5+BM5 -> 0 | CA5: =BZ5-BZ4 -> 0 | CB5: =AA5+U5+AD5+X5+AS5+AG5+AJ5+AM5+AP5+AV5+AY5+BB5+BE5+BG5+BK5+BM5 -> 0 | CC5: =CB5-BZ5 -> 0 | CD5: 0 | CE5: =CC5-CC4 -> 0 | CG5: =A5 -> 44439 | CH5: =BR5+BZ5 -> 97 | CI5: =BS5+CA5 -> 16 | CJ5: =BT5+CB5 -> 98.79 | CK5: =CJ5-CH5 -> 1.79 | CL5: =CK5/CH5 -> 0.018453608 | CM5: =CK5-CK4 -> 0.49 | CO5: =A5 -> 44439 | CP5: =(C5-B5)-(C4-B4) -> 0.49 | CQ5: =(F5-E5)-(F4-E4) -> 0 | CR5: =(I5-H5)-(I4-H4) -> 0 | CS5: =(L5-K5)-(L4-K4) -> 0 | CT5: =(O5-N5)-(O4-N4) -> 0 | CU5: =(R5-Q5)-(R4-Q4) -> 0 | CV5: =(U5-T5)-(U4-T4) -> 0 | CW5: =(X5-W5)-(X4-W4) -> 0 | CX5: =(AA5-Z5)-(AA4-Z4) -> 0 | CY5: =(AD5-AC5)-(AD4-AC4) -> 0 | CZ5: =(AG5-AF5)-(AG4-AF4) -> 0 | DA5: =(AJ5-AI5)-(AJ4-AI4) -> 0 | DB5: =(AM5-AL5)-(AM4-AL4) -> 0 | DC5: =(AP5-AO5)-(AP4-AO4) -> 0 | DD5: =(AS5-AR5)-(AS4-AR4) -> 0 | DE5: =(AV5-AU5)-(AV4-AU4) -> 0 | DF5: =(AY5-AX5)-(AY4-AX4) -> 0 | DG5: =(BB5-BA5)-(BB4-BA4) -> 0 | DH5: =(BE5-BD5)-(BE4-BD4) -> 0 | DI5: =(BH5-BG5)-(BH4-BG4) -> 0 | DJ5: =(BK5-BJ5)-(BK4-BJ4) -> 0 | DK5: =(BN5-BM5)-(BN4-BM4) -> 0
A6: 44469 | B6: 153 | C6: 154.27 | D6: =(C6-B6)/B6 -> 0.0083006536 | E6: 0 | F6: 0 | G6: 0 | H6: 0 | I6: 0 | J6: 0 | K6: 0 | L6: 0 | M6: 0 | N6: 0 | O6: 0 | P6: 0 | Q6: 0 | R6: 0 | S6: 0 | T6: 0 | U6: 0 | V6: 0 | W6: 0 | X6: 0 | Y6: 0 | Z6: 0 | AA6: 0 | AB6: 0 | AC6: 0 | AD6: 0 | AE6: 0 | AF6: 0 | AG6: 0 | AH6: 0 | AI6: 0 | AJ6: 0 | AK6: 0 | AL6: 0 | AM6: 0 | AN6: 0 | AO6: 0 | AP6: 0 | AQ6: 0 | AR6: 0 | AS6: 0 | AT6: 0 | AU6: 0 | AV6: 0 | AW6: 0 | AX6: 0 | AY6: 0 | AZ6: 0 | BA6: 0 | BB6: 0 | BC6: 0 | BD6: 0 | BE6: 0 | BF6: 0 | BG6: 0 | BH6: 0 | BI6: 0 | BJ6: 0 | BK6: 0 | BL6: 0 | BM6: 0 | BN6: 0 | BO6: 0 | BQ6: =A6 -> 44469 | BR6: =B6+E6+H6+K6+N6+Q6 -> 153 | BS6: =BR6-BR5 -> 56 | BT6: =C6+F6+I6+L6+O6+R6 -> 154.27 | BU6: =BT6-BR6 -> 1.27 | BV6: =BU6/BR6 -> 0.0083006536 | BW6: =BU6-BU5 -> -0.52 | BY6: =A6 -> 44469 | BZ6: =Z6+T6+AC6+W6+AR6+AF6+AI6+AL6+AO6+AU6+AX6+BA6+BD6+BG6+BJ6+BM6 -> 0 | CA6: =BZ6-BZ5 -> 0 | CB6: =AA6+U6+AD6+X6+AS6+AG6+AJ6+AM6+AP6+AV6+AY6+BB6+BE6+BG6+BK6+BM6 -> 0 | CC6: =CB6-BZ6 -> 0 | CD6: 0 | CE6: =CC6-CC5 -> 0 | CG6: =A6 -> 44469 | CH6: =BR6+BZ6 -> 153 | CI6: =BS6+CA6 -> 56 | CJ6: =BT6+CB6 -> 154.27 | CK6: =CJ6-CH6 -> 1.27 | CL6: 0 | CM6: =CK6-CK5 -> -0.52 | CO6: =A6 -> 44469 | CP6: =(C6-B6)-(C5-B5) -> -0.52 | CQ6: =(F6-E6)-(F5-E5) -> 0 | CR6: =(I6-H6)-(I5-H5) -> 0 | CS6: =(L6-K6)-(L5-K5) -> 0 | CT6: =(O6-N6)-(O5-N5) -> 0 | CU6: =(R6-Q6)-(R5-Q5) -> 0 | CV6: =(U6-T6)-(U5-T5) -> 0 | CW6: =(X6-W6)-(X5-W5) -> 0 | CX6: =(AA6-Z6)-(AA5-Z5) -> 0 | CY6: =(AD6-AC6)-(AD5-AC5) -> 0 | CZ6: =(AG6-AF6)-(AG5-AF5) -> 0 | DA6: =(AJ6-AI6)-(AJ5-AI5) -> 0 | DB6: =(AM6-AL6)-(AM5-AL5) -> 0 | DC6: =(AP6-AO6)-(AP5-AO5) -> 0 | DD6: =(AS6-AR6)-(AS5-AR5) -> 0 | DE6: =(AV6-AU6)-(AV5-AU5) -> 0 | DF6: =(AY6-AX6)-(AY5-AX5) -> 0 | DG6: =(BB6-BA6)-(BB5-BA5) -> 0 | DH6: =(BE6-BD6)-(BE5-BD5) -> 0 | DI6: =(BH6-BG6)-(BH5-BG5) -> 0 | DJ6: =(BK6-BJ6)-(BK5-BJ5) -> 0 | DK6: =(BN6-BM6)-(BN5-BM5) -> 0
A7: 44500 | B7: 190 | C7: 189.71 | D7: =(C7-B7)/B7 -> -0.0015263158 | E7: 0 | F7: 0 | G7: 0 | H7: 0 | I7: 0 | J7: 0 | K7: 0 | L7: 0 | M7: 0 | N7: 0 | O7: 0 | P7: 0 | Q7: 0 | R7: 0 | S7: 0 | T7: 0 | U7: 0 | V7: 0 | W7: 0 | X7: 0 | Y7: 0 | Z7: 0 | AA7: 0 | AB7: 0 | AC7: 0 | AD7: 0 | AE7: 0 | AF7: 0 | AG7: 0 | AH7: 0 | AI7: 0 | AJ7: 0 | AK7: 0 | AL7: 0 | AM7: 0 | AN7: 0 | AO7: 0 | AP7: 0 | AQ7: 0 | AR7: 0 | AS7: 0 | AT7: 0 | AU7: 0 | AV7: 0 | AW7: 0 | AX7: 0 | AY7: 0 | AZ7: 0 | BA7: 0 | BB7: 0 | BC7: 0 | BD7: 0 | BE7: 0 | BF7: 0 | BG7: 0 | BH7: 0 | BI7: 0 | BJ7: 0 | BK7: 0 | BL7: 0 | BM7: 0 | BN7: 0 | BO7: 0 | BQ7: =A7 -> 44500 | BR7: =B7+E7+H7+K7+N7+Q7 -> 190 | BS7: =BR7-BR6 -> 37 | BT7: =C7+F7+I7+L7+O7+R7 -> 189.71 | BU7: =BT7-BR7 -> -0.29 | BV7: =BU7/BR7 -> -0.0015263158 | BW7: =BU7-BU6 -> -1.56 | BY7: =A7 -> 44500 | BZ7: =Z7+T7+AC7+W7+AR7+AF7+AI7+AL7+AO7+AU7+AX7+BA7+BD7+BG7+BJ7+BM7 -> 0 | CA7: =BZ7-BZ6 -> 0 | CB7: =AA7+U7+AD7+X7+AS7+AG7+AJ7+AM7+AP7+AV7+AY7+BB7+BE7+BG7+BK7+BM7 -> 0 | CC7: =CB7-BZ7 -> 0 | CD7: 0 | CE7: =CC7-CC6 -> 0 | CG7: =A7 -> 44500 | CH7: =BR7+BZ7 -> 190 | CI7: =BS7+CA7 -> 37 | CJ7: =BT7+CB7 -> 189.71 | CK7: =CJ7-CH7 -> -0.29 | CL7: 0 | CM7: =CK7-CK6 -> -1.56 | CO7: =A7 -> 44500 | CP7: =(C7-B7)-(C6-B6) -> -1.56 | CQ7: =(F7-E7)-(F6-E6) -> 0 | CR7: =(I7-H7)-(I6-H6) -> 0 | CS7: =(L7-K7)-(L6-K6) -> 0 | CT7: =(O7-N7)-(O6-N6) -> 0 | CU7: =(R7-Q7)-(R6-Q6) -> 0 | CV7: =(U7-T7)-(U6-T6) -> 0 | CW7: =(X7-W7)-(X6-W6) -> 0 | CX7: =(AA7-Z7)-(AA6-Z6) -> 0 | CY7: =(AD7-AC7)-(AD6-AC6) -> 0 | CZ7: =(AG7-AF7)-(AG6-AF6) -> 0 | DA7: =(AJ7-AI7)-(AJ6-AI6) -> 0 | DB7: =(AM7-AL7)-(AM6-AL6) -> 0 | DC7: =(AP7-AO7)-(AP6-AO6) -> 0 | DD7: =(AS7-AR7)-(AS6-AR6) -> 0 | DE7: =(AV7-AU7)-(AV6-AU6) -> 0 | DF7: =(AY7-AX7)-(AY6-AX6) -> 0 | DG7: =(BB7-BA7)-(BB6-BA6) -> 0 | DH7: =(BE7-BD7)-(BE6-BD6) -> 0 | DI7: =(BH7-BG7)-(BH6-BG6) -> 0 | DJ7: =(BK7-BJ7)-(BK6-BJ6) -> 0 | DK7: =(BN7-BM7)-(BN6-BM6) -> 0
A8: 44530 | B8: 199 | C8: 200.02 | D8: =(C8-B8)/B8 -> 0.0051256281 | E8: 0 | F8: 0 | G8: 0 | H8: 0 | I8: 0 | J8: 0 | K8: 0 | L8: 0 | M8: 0 | N8: 0 | O8: 0 | P8: 0 | Q8: 0 | R8: 0 | S8: 0 | T8: 0 | U8: 0 | V8: 0 | W8: 0 | X8: 0 | Y8: 0 | Z8: 0 | AA8: 0 | AB8: 0 | AC8: 0 | AD8: 0 | AE8: 0 | AF8: 0 | AG8: 0 | AH8: 0 | AI8: 0 | AJ8: 0 | AK8: 0 | AL8: 0 | AM8: 0 | AN8: 0 | AO8: 0 | AP8: 0 | AQ8: 0 | AR8: 0 | AS8: 0 | AT8: 0 | AU8: 0 | AV8: 0 | AW8: 0 | AX8: 0 | AY8: 0 | AZ8: 0 | BA8: 0 | BB8: 0 | BC8: 0 | BD8: 0 | BE8: 0 | BF8: 0 | BG8: 0 | BH8: 0 | BI8: 0 | BJ8: 0 | BK8: 0 | BL8: 0 | BM8: 0 | BN8: 0 | BO8: 0 | BQ8: =A8 -> 44530 | BR8: =B8+E8+H8+K8+N8+Q8 -> 199 | BS8: =BR8-BR7 -> 9 | BT8: =C8+F8+I8+L8+O8+R8 -> 200.02 | BU8: =BT8-BR8 -> 1.02 | BV8: =BU8/BR8 -> 0.0051256281 | BW8: =BU8-BU7 -> 1.31 | BY8: =A8 -> 44530 | BZ8: =Z8+T8+AC8+W8+AR8+AF8+AI8+AL8+AO8+AU8+AX8+BA8+BD8+BG8+BJ8+BM8 -> 0 | CA8: =BZ8-BZ7 -> 0 | CB8: =AA8+U8+AD8+X8+AS8+AG8+AJ8+AM8+AP8+AV8+AY8+BB8+BE8+BG8+BK8+BM8 -> 0 | CC8: =CB8-BZ8 -> 0 | CD8: 0 | CE8: =CC8-CC7 -> 0 | CG8: =A8 -> 44530 | CH8: =BR8+BZ8 -> 199 | CI8: =BS8+CA8 -> 9 | CJ8: =BT8+CB8 -> 200.02 | CK8: =CJ8-CH8 -> 1.02 | CL8: 0 | CM8: =CK8-CK7 -> 1.31 | CO8: =A8 -> 44530 | CP8: =(C8-B8)-(C7-B7) -> 1.31 | CQ8: =(F8-E8)-(F7-E7) -> 0 | CR8: =(I8-H8)-(I7-H7) -> 0 | CS8: =(L8-K8)-(L7-K7) -> 0 | CT8: =(O8-N8)-(O7-N7) -> 0 | CU8: =(R8-Q8)-(R7-Q7) -> 0 | CV8: =(U8-T8)-(U7-T7) -> 0 | CW8: =(X8-W8)-(X7-W7) -> 0 | CX8: =(AA8-Z8)-(AA7-Z7) -> 0 | CY8: =(AD8-AC8)-(AD7-AC7) -> 0 | CZ8: =(AG8-AF8)-(AG7-AF7) -> 0 | DA8: =(AJ8-AI8)-(AJ7-AI7) -> 0 | DB8: =(AM8-AL8)-(AM7-AL7) -> 0 | DC8: =(AP8-AO8)-(AP7-AO7) -> 0 | DD8: =(AS8-AR8)-(AS7-AR7) -> 0 | DE8: =(AV8-AU8)-(AV7-AU7) -> 0 | DF8: =(AY8-AX8)-(AY7-AX7) -> 0 | DG8: =(BB8-BA8)-(BB7-BA7) -> 0 | DH8: =(BE8-BD8)-(BE7-BD7) -> 0 | DI8: =(BH8-BG8)-(BH7-BG7) -> 0 | DJ8: =(BK8-BJ8)-(BK7-BJ7) -> 0 | DK8: =(BN8-BM8)-(BN7-BM7) -> 0
A9: 44561 | B9: 244 | C9: 248.63 | D9: =(C9-B9)/B9 -> 0.01897541 | E9: 0 | F9: 0 | G9: 0 | H9: 0 | I9: 0 | J9: 0 | K9: 0 | L9: 0 | M9: 0 | N9: 0 | O9: 0 | P9: 0 | Q9: 0 | R9: 0 | S9: 0 | T9: 0 | U9: 0 | V9: 0 | W9: 0 | X9: 0 | Y9: 0 | Z9: 0 | AA9: 0 | AB9: 0 | AC9: 0 | AD9: 0 | AE9: 0 | AF9: 0 | AG9: 0 | AH9: 0 | AI9: 0 | AJ9: 0 | AK9: 0 | AL9: 0 | AM9: 0 | AN9: 0 | AO9: 0 | AP9: 0 | AQ9: 0 | AR9: 0 | AS9: 0 | AT9: 0 | AU9: 0 | AV9: 0 | AW9: 0 | AX9: 0 | AY9: 0 | AZ9: 0 | BA9: 0 | BB9: 0 | BC9: 0 | BD9: 0 | BE9: 0 | BF9: 0 | BG9: 0 | BH9: 0 | BI9: 0 | BJ9: 0 | BK9: 0 | BL9: 0 | BM9: 0 | BN9: 0 | BO9: 0 | BQ9: =A9 -> 44561 | BR9: =B9+E9+H9+K9+N9+Q9 -> 244 | BS9: =BR9-BR8 -> 45 | BT9: =C9+F9+I9+L9+O9+R9 -> 248.63 | BU9: =BT9-BR9 -> 4.63 | BV9: =BU9/BR9 -> 0.01897541 | BW9: =BU9-BU8 -> 3.61 | BY9: =A9 -> 44561 | BZ9: =Z9+T9+AC9+W9+AR9+AF9+AI9+AL9+AO9+AU9+AX9+BA9+BD9+BG9+BJ9+BM9 -> 0 | CA9: =BZ9-BZ8 -> 0 | CB9: =AA9+U9+AD9+X9+AS9+AG9+AJ9+AM9+AP9+AV9+AY9+BB9+BE9+BG9+BK9+BM9 -> 0 | CC9: =CB9-BZ9 -> 0 | CD9: 0 | CE9: =CC9-CC8 -> 0 | CG9: =A9 -> 44561 | CH9: =BR9+BZ9 -> 244 | CI9: =BS9+CA9 -> 45 | CJ9: =BT9+CB9 -> 248.63 | CK9: =CJ9-CH9 -> 4.63 | CL9: 0 | CM9: =CK9-CK8 -> 3.61 | CO9: =A9 -> 44561 | CP9: =(C9-B9)-(C8-B8) -> 3.61 | CQ9: =(F9-E9)-(F8-E8) -> 0 | CR9: =(I9-H9)-(I8-H8) -> 0 | CS9: =(L9-K9)-(L8-K8) -> 0 | CT9: =(O9-N9)-(O8-N8) -> 0 | CU9: =(R9-Q9)-(R8-Q8) -> 0 | CV9: =(U9-T9)-(U8-T8) -> 0 | CW9: =(X9-W9)-(X8-W8) -> 0 | CX9: =(AA9-Z9)-(AA8-Z8) -> 0 | CY9: =(AD9-AC9)-(AD8-AC8) -> 0 | CZ9: =(AG9-AF9)-(AG8-AF8) -> 0 | DA9: =(AJ9-AI9)-(AJ8-AI8) -> 0 | DB9: =(AM9-AL9)-(AM8-AL8) -> 0 | DC9: =(AP9-AO9)-(AP8-AO8) -> 0 | DD9: =(AS9-AR9)-(AS8-AR8) -> 0 | DE9: =(AV9-AU9)-(AV8-AU8) -> 0 | DF9: =(AY9-AX9)-(AY8-AX8) -> 0 | DG9: =(BB9-BA9)-(BB8-BA8) -> 0 | DH9: =(BE9-BD9)-(BE8-BD8) -> 0 | DI9: =(BH9-BG9)-(BH8-BG8) -> 0 | DJ9: =(BK9-BJ9)-(BK8-BJ8) -> 0 | DK9: =(BN9-BM9)-(BN8-BM8) -> 0
A10: 44592 | B10: 272 | C10: 257.85 | D10: =(C10-B10)/B10 -> -0.052022059 | E10: 0 | F10: 0 | G10: 0 | H10: 0 | I10: 0 | J10: 0 | K10: 0 | L10: 0 | M10: 0 | N10: 0 | O10: 0 | P10: 0 | Q10: 0 | R10: 0 | S10: 0 | T10: 0 | U10: 0 | V10: 0 | W10: 0 | X10: 0 | Y10: 0 | Z10: 0 | AA10: 0 | AB10: 0 | AC10: 0 | AD10: 0 | AE10: 0 | AF10: 0 | AG10: 0 | AH10: 0 | AI10: 0 | AJ10: 0 | AK10: 0 | AL10: 0 | AM10: 0 | AN10: 0 | AO10: 0 | AP10: 0 | AQ10: 0 | AR10: 0 | AS10: 0 | AT10: 0 | AU10: 0 | AV10: 0 | AW10: 0 | AX10: 0 | AY10: 0 | AZ10: 0 | BA10: 0 | BB10: 0 | BC10: 0 | BD10: 0 | BE10: 0 | BF10: 0 | BG10: 0 | BH10: 0 | BI10: 0 | BJ10: 0 | BK10: 0 | BL10: 0 | BM10: 0 | BN10: 0 | BO10: 0 | BQ10: =A10 -> 44592 | BR10: =B10+E10+H10+K10+N10+Q10 -> 272 | BS10: =BR10-BR9 -> 28 | BT10: =C10+F10+I10+L10+O10+R10 -> 257.85 | BU10: =BT10-BR10 -> -14.15 | BV10: =BU10/BR10 -> -0.052022059 | BW10: =BU10-BU9 -> -18.78 | BY10: =A10 -> 44592 | BZ10: =Z10+T10+AC10+W10+AR10+AF10+AI10+AL10+AO10+AU10+AX10+BA10+BD10+BG10+BJ10+BM10 -> 0 | CA10: =BZ10-BZ9 -> 0 | CB10: =AA10+U10+AD10+X10+AS10+AG10+AJ10+AM10+AP10+AV10+AY10+BB10+BE10+BG10+BK10+BM10 -> 0 | CC10: =CB10-BZ10 -> 0 | CD10: 0 | CE10: =CC10-CC9 -> 0 | CG10: =A10 -> 44592 | CH10: =BR10+BZ10 -> 272 | CI10: =BS10+CA10 -> 28 | CJ10: =BT10+CB10 -> 257.85 | CK10: =CJ10-CH10 -> -14.15 | CL10: 0 | CM10: =CK10-CK9 -> -18.78 | CO10: =A10 -> 44592 | CP10: =(C10-B10)-(C9-B9) -> -18.78 | CQ10: =(F10-E10)-(F9-E9) -> 0 | CR10: =(I10-H10)-(I9-H9) -> 0 | CS10: =(L10-K10)-(L9-K9) -> 0 | CT10: =(O10-N10)-(O9-N9) -> 0 | CU10: =(R10-Q10)-(R9-Q9) -> 0 | CV10: =(U10-T10)-(U9-T9) -> 0 | CW10: =(X10-W10)-(X9-W9) -> 0 | CX10: =(AA10-Z10)-(AA9-Z9) -> 0 | CY10: =(AD10-AC10)-(AD9-AC9) -> 0 | CZ10: =(AG10-AF10)-(AG9-AF9) -> 0 | DA10: =(AJ10-AI10)-(AJ9-AI9) -> 0 | DB10: =(AM10-AL10)-(AM9-AL9) -> 0 | DC10: =(AP10-AO10)-(AP9-AO9) -> 0 | DD10: =(AS10-AR10)-(AS9-AR9) -> 0 | DE10: =(AV10-AU10)-(AV9-AU9) -> 0 | DF10: =(AY10-AX10)-(AY9-AX9) -> 0 | DG10: =(BB10-BA10)-(BB9-BA9) -> 0 | DH10: =(BE10-BD10)-(BE9-BD9) -> 0 | DI10: =(BH10-BG10)-(BH9-BG9) -> 0 | DJ10: =(BK10-BJ10)-(BK9-BJ9) -> 0 | DK10: =(BN10-BM10)-(BN9-BM9) -> 0
A11: 44620 | B11: 282 | C11: 262.62 | D11: =(C11-B11)/B11 -> -0.068723404 | E11: 0 | F11: 0 | G11: 0 | H11: 0 | I11: 0 | J11: 0 | K11: 0 | L11: 0 | M11: 0 | N11: 0 | O11: 0 | P11: 0 | Q11: 0 | R11: 0 | S11: 0 | T11: 0 | U11: 0 | V11: 0 | W11: 0 | X11: 0 | Y11: 0 | Z11: 0 | AA11: 0 | AB11: 0 | AC11: 0 | AD11: 0 | AE11: 0 | AF11: 0 | AG11: 0 | AH11: 0 | AI11: 0 | AJ11: 0 | AK11: 0 | AL11: 0 | AM11: 0 | AN11: 0 | AO11: 0 | AP11: 0 | AQ11: 0 | AR11: 0 | AS11: 0 | AT11: 0 | AU11: 0 | AV11: 0 | AW11: 0 | AX11: 0 | AY11: 0 | AZ11: 0 | BA11: 0 | BB11: 0 | BC11: 0 | BD11: 0 | BE11: 0 | BF11: 0 | BG11: 0 | BH11: 0 | BI11: 0 | BJ11: 0 | BK11: 0 | BL11: 0 | BM11: 0 | BN11: 0 | BO11: 0 | BQ11: =A11 -> 44620 | BR11: =B11+E11+H11+K11+N11+Q11 -> 282 | BS11: =BR11-BR10 -> 10 | BT11: =C11+F11+I11+L11+O11+R11 -> 262.62 | BU11: =BT11-BR11 -> -19.38 | BV11: =BU11/BR11 -> -0.068723404 | BW11: =BU11-BU10 -> -5.23 | BY11: =A11 -> 44620 | BZ11: =Z11+T11+AC11+W11+AR11+AF11+AI11+AL11+AO11+AU11+AX11+BA11+BD11+BG11+BJ11+BM11 -> 0 | CA11: =BZ11-BZ10 -> 0 | CB11: =AA11+U11+AD11+X11+AS11+AG11+AJ11+AM11+AP11+AV11+AY11+BB11+BE11+BG11+BK11+BM11 -> 0 | CC11: =CB11-BZ11 -> 0 | CD11: 0 | CE11: =CC11-CC10 -> 0 | CG11: =A11 -> 44620 | CH11: =BR11+BZ11 -> 282 | CI11: =BS11+CA11 -> 10 | CJ11: =BT11+CB11 -> 262.62 | CK11: =CJ11-CH11 -> -19.38 | CL11: 0 | CM11: =CK11-CK10 -> -5.23 | CO11: =A11 -> 44620 | CP11: =(C11-B11)-(C10-B10) -> -5.23 | CQ11: =(F11-E11)-(F10-E10) -> 0 | CR11: =(I11-H11)-(I10-H10) -> 0 | CS11: =(L11-K11)-(L10-K10) -> 0 | CT11: =(O11-N11)-(O10-N10) -> 0 | CU11: =(R11-Q11)-(R10-Q10) -> 0 | CV11: =(U11-T11)-(U10-T10) -> 0 | CW11: =(X11-W11)-(X10-W10) -> 0 | CX11: =(AA11-Z11)-(AA10-Z10) -> 0 | CY11: =(AD11-AC11)-(AD10-AC10) -> 0 | CZ11: =(AG11-AF11)-(AG10-AF10) -> 0 | DA11: =(AJ11-AI11)-(AJ10-AI10) -> 0 | DB11: =(AM11-AL11)-(AM10-AL10) -> 0 | DC11: =(AP11-AO11)-(AP10-AO10) -> 0 | DD11: =(AS11-AR11)-(AS10-AR10) -> 0 | DE11: =(AV11-AU11)-(AV10-AU10) -> 0 | DF11: =(AY11-AX11)-(AY10-AX10) -> 0 | DG11: =(BB11-BA11)-(BB10-BA10) -> 0 | DH11: =(BE11-BD11)-(BE10-BD10) -> 0 | DI11: =(BH11-BG11)-(BH10-BG10) -> 0 | DJ11: =(BK11-BJ11)-(BK10-BJ10) -> 0 | DK11: =(BN11-BM11)-(BN10-BM10) -> 0
A12: 44651 | B12: 292 | C12: 280.58 | D12: =(C12-B12)/B12 -> -0.039109589 | E12: 0 | F12: 0 | G12: 0 | H12: 0 | I12: 0 | J12: 0 | K12: 0 | L12: 0 | M12: 0 | N12: 0 | O12: 0 | P12: 0 | Q12: 0 | R12: 0 | S12: 0 | T12: 0 | U12: 0 | V12: 0 | W12: 0 | X12: 0 | Y12: 0 | Z12: 0 | AA12: 0 | AB12: 0 | AC12: 0 | AD12: 0 | AE12: 0 | AF12: 0 | AG12: 0 | AH12: 0 | AI12: 0 | AJ12: 0 | AK12: 0 | AL12: 0 | AM12: 0 | AN12: 0 | AO12: 0 | AP12: 0 | AQ12: 0 | AR12: 0 | AS12: 0 | AT12: 0 | AU12: 0 | AV12: 0 | AW12: 0 | AX12: 0 | AY12: 0 | AZ12: 0 | BA12: 0 | BB12: 0 | BC12: 0 | BD12: 0 | BE12: 0 | BF12: 0 | BG12: 0 | BH12: 0 | BI12: 0 | BJ12: 0 | BK12: 0 | BL12: 0 | BM12: 0 | BN12: 0 | BO12: 0 | BQ12: =A12 -> 44651 | BR12: =B12+E12+H12+K12+N12+Q12 -> 292 | BS12: =BR12-BR11 -> 10 | BT12: =C12+F12+I12+L12+O12+R12 -> 280.58 | BU12: =BT12-BR12 -> -11.42 | BV12: =BU12/BR12 -> -0.039109589 | BW12: =BU12-BU11 -> 7.96 | BY12: =A12 -> 44651 | BZ12: =Z12+T12+AC12+W12+AR12+AF12+AI12+AL12+AO12+AU12+AX12+BA12+BD12+BG12+BJ12+BM12 -> 0 | CA12: =BZ12-BZ11 -> 0 | CB12: =AA12+U12+AD12+X12+AS12+AG12+AJ12+AM12+AP12+AV12+AY12+BB12+BE12+BG12+BK12+BM12 -> 0 | CC12: =CB12-BZ12 -> 0 | CD12: 0 | CE12: =CC12-CC11 -> 0 | CG12: =A12 -> 44651 | CH12: =BR12+BZ12 -> 292 | CI12: =BS12+CA12 -> 10 | CJ12: =BT12+CB12 -> 280.58 | CK12: =CJ12-CH12 -> -11.42 | CL12: 0 | CM12: =CK12-CK11 -> 7.96 | CO12: =A12 -> 44651 | CP12: =(C12-B12)-(C11-B11) -> 7.96 | CQ12: =(F12-E12)-(F11-E11) -> 0 | CR12: =(I12-H12)-(I11-H11) -> 0 | CS12: =(L12-K12)-(L11-K11) -> 0 | CT12: =(O12-N12)-(O11-N11) -> 0 | CU12: =(R12-Q12)-(R11-Q11) -> 0 | CV12: =(U12-T12)-(U11-T11) -> 0 | CW12: =(X12-W12)-(X11-W11) -> 0 | CX12: =(AA12-Z12)-(AA11-Z11) -> 0 | CY12: =(AD12-AC12)-(AD11-AC11) -> 0 | CZ12: =(AG12-AF12)-(AG11-AF11) -> 0 | DA12: =(AJ12-AI12)-(AJ11-AI11) -> 0 | DB12: =(AM12-AL12)-(AM11-AL11) -> 0 | DC12: =(AP12-AO12)-(AP11-AO11) -> 0 | DD12: =(AS12-AR12)-(AS11-AR11) -> 0 | DE12: =(AV12-AU12)-(AV11-AU11) -> 0 | DF12: =(AY12-AX12)-(AY11-AX11) -> 0 | DG12: =(BB12-BA12)-(BB11-BA11) -> 0 | DH12: =(BE12-BD12)-(BE11-BD11) -> 0 | DI12: =(BH12-BG12)-(BH11-BG11) -> 0 | DJ12: =(BK12-BJ12)-(BK11-BJ11) -> 0 | DK12: =(BN12-BM12)-(BN11-BM11) -> 0
A13: 44681 | B13: 302 | C13: 279.52 | D13: =(C13-B13)/B13 -> -0.074437086 | E13: 0 | F13: 0 | G13: 0 | H13: 0 | I13: 0 | J13: 0 | K13: 0 | L13: 0 | M13: 0 | N13: 0 | O13: 0 | P13: 0 | Q13: 0 | R13: 0 | S13: 0 | T13: 0 | U13: 0 | V13: 0 | W13: 0 | X13: 0 | Y13: 0 | Z13: 0 | AA13: 0 | AB13: 0 | AC13: 0 | AD13: 0 | AE13: 0 | AF13: 0 | AG13: 0 | AH13: 0 | AI13: 0 | AJ13: 0 | AK13: 0 | AL13: 0 | AM13: 0 | AN13: 0 | AO13: 0 | AP13: 0 | AQ13: 0 | AR13: 0 | AS13: 0 | AT13: 0 | AU13: 0 | AV13: 0 | AW13: 0 | AX13: 0 | AY13: 0 | AZ13: 0 | BA13: 0 | BB13: 0 | BC13: 0 | BD13: 0 | BE13: 0 | BF13: 0 | BG13: 0 | BH13: 0 | BI13: 0 | BJ13: 0 | BK13: 0 | BL13: 0 | BM13: 0 | BN13: 0 | BO13: 0 | BQ13: =A13 -> 44681 | BR13: =B13+E13+H13+K13+N13+Q13 -> 302 | BS13: =BR13-BR12 -> 10 | BT13: =C13+F13+I13+L13+O13+R13 -> 279.52 | BU13: =BT13-BR13 -> -22.48 | BV13: =BU13/BR13 -> -0.074437086 | BW13: =BU13-BU12 -> -11.06 | BY13: =A13 -> 44681 | BZ13: =Z13+T13+AC13+W13+AR13+AF13+AI13+AL13+AO13+AU13+AX13+BA13+BD13+BG13+BJ13+BM13 -> 0 | CA13: =BZ13-BZ12 -> 0 | CB13: =AA13+U13+AD13+X13+AS13+AG13+AJ13+AM13+AP13+AV13+AY13+BB13+BE13+BG13+BK13+BM13 -> 0 | CC13: =CB13-BZ13 -> 0 | CD13: 0 | CE13: =CC13-CC12 -> 0 | CG13: =A13 -> 44681 | CH13: =BR13+BZ13 -> 302 | CI13: =BS13+CA13 -> 10 | CJ13: =BT13+CB13 -> 279.52 | CK13: =CJ13-CH13 -> -22.48 | CL13: 0 | CM13: =CK13-CK12 -> -11.06 | CO13: =A13 -> 44681 | CP13: =(C13-B13)-(C12-B12) -> -11.06 | CQ13: =(F13-E13)-(F12-E12) -> 0 | CR13: =(I13-H13)-(I12-H12) -> 0 | CS13: =(L13-K13)-(L12-K12) -> 0 | CT13: =(O13-N13)-(O12-N12) -> 0 | CU13: =(R13-Q13)-(R12-Q12) -> 0 | CV13: =(U13-T13)-(U12-T12) -> 0 | CW13: =(X13-W13)-(X12-W12) -> 0 | CX13: =(AA13-Z13)-(AA12-Z12) -> 0 | CY13: =(AD13-AC13)-(AD12-AC12) -> 0 | CZ13: =(AG13-AF13)-(AG12-AF12) -> 0 | DA13: =(AJ13-AI13)-(AJ12-AI12) -> 0 | DB13: =(AM13-AL13)-(AM12-AL12) -> 0 | DC13: =(AP13-AO13)-(AP12-AO12) -> 0 | DD13: =(AS13-AR13)-(AS12-AR12) -> 0 | DE13: =(AV13-AU13)-(AV12-AU12) -> 0 | DF13: =(AY13-AX13)-(AY12-AX12) -> 0 | DG13: =(BB13-BA13)-(BB12-BA12) -> 0 | DH13: =(BE13-BD13)-(BE12-BD12) -> 0 | DI13: =(BH13-BG13)-(BH12-BG12) -> 0 | DJ13: =(BK13-BJ13)-(BK12-BJ12) -> 0 | DK13: =(BN13-BM13)-(BN12-BM12) -> 0
A14: 44712 | B14: 312 | C14: 285.89 | D14: =(C14-B14)/B14 -> -0.083685897 | E14: 0 | F14: 0 | G14: 0 | H14: 0 | I14: 0 | J14: 0 | K14: 0 | L14: 0 | M14: 0 | N14: 0 | O14: 0 | P14: 0 | Q14: 0 | R14: 0 | S14: 0 | T14: 0 | U14: 0 | V14: 0 | W14: 0 | X14: 0 | Y14: 0 | Z14: 0 | AA14: 0 | AB14: 0 | AC14: 0 | AD14: 0 | AE14: 0 | AF14: 0 | AG14: 0 | AH14: 0 | AI14: 0 | AJ14: 0 | AK14: 0 | AL14: 0 | AM14: 0 | AN14: 0 | AO14: 0 | AP14: 0 | AQ14: 0 | AR14: 0 | AS14: 0 | AT14: 0 | AU14: 0 | AV14: 0 | AW14: 0 | AX14: 0 | AY14: 0 | AZ14: 0 | BA14: 0 | BB14: 0 | BC14: 0 | BD14: 0 | BE14: 0 | BF14: 0 | BG14: 0 | BH14: 0 | BI14: 0 | BJ14: 0 | BK14: 0 | BL14: 0 | BM14: 0 | BN14: 0 | BO14: 0 | BQ14: =A14 -> 44712 | BR14: =B14+E14+H14+K14+N14+Q14 -> 312 | BS14: =BR14-BR13 -> 10 | BT14: =C14+F14+I14+L14+O14+R14 -> 285.89 | BU14: =BT14-BR14 -> -26.11 | BV14: =BU14/BR14 -> -0.083685897 | BW14: =BU14-BU13 -> -3.63 | BY14: =A14 -> 44712 | BZ14: =Z14+T14+AC14+W14+AR14+AF14+AI14+AL14+AO14+AU14+AX14+BA14+BD14+BG14+BJ14+BM14 -> 0 | CA14: =BZ14-BZ13 -> 0 | CB14: =AA14+U14+AD14+X14+AS14+AG14+AJ14+AM14+AP14+AV14+AY14+BB14+BE14+BG14+BK14+BM14 -> 0 | CC14: =CB14-BZ14 -> 0 | CD14: 0 | CE14: =CC14-CC13 -> 0 | CG14: =A14 -> 44712 | CH14: =BR14+BZ14 -> 312 | CI14: =BS14+CA14 -> 10 | CJ14: =BT14+CB14 -> 285.89 | CK14: =CJ14-CH14 -> -26.11 | CL14: 0 | CM14: =CK14-CK13 -> -3.63 | CO14: =A14 -> 44712 | CP14: =(C14-B14)-(C13-B13) -> -3.63 | CQ14: =(F14-E14)-(F13-E13) -> 0 | CR14: =(I14-H14)-(I13-H13) -> 0 | CS14: =(L14-K14)-(L13-K13) -> 0 | CT14: =(O14-N14)-(O13-N13) -> 0 | CU14: =(R14-Q14)-(R13-Q13) -> 0 | CV14: =(U14-T14)-(U13-T13) -> 0 | CW14: =(X14-W14)-(X13-W13) -> 0 | CX14: =(AA14-Z14)-(AA13-Z13) -> 0 | CY14: =(AD14-AC14)-(AD13-AC13) -> 0 | CZ14: =(AG14-AF14)-(AG13-AF13) -> 0 | DA14: =(AJ14-AI14)-(AJ13-AI13) -> 0 | DB14: =(AM14-AL14)-(AM13-AL13) -> 0 | DC14: =(AP14-AO14)-(AP13-AO13) -> 0 | DD14: =(AS14-AR14)-(AS13-AR13) -> 0 | DE14: =(AV14-AU14)-(AV13-AU13) -> 0 | DF14: =(AY14-AX14)-(AY13-AX13) -> 0 | DG14: =(BB14-BA14)-(BB13-BA13) -> 0 | DH14: =(BE14-BD14)-(BE13-BD13) -> 0 | DI14: =(BH14-BG14)-(BH13-BG13) -> 0 | DJ14: =(BK14-BJ14)-(BK13-BJ13) -> 0 | DK14: =(BN14-BM14)-(BN13-BM13) -> 0
A15: 44742 | B15: 322 | C15: 280.1 | D15: =(C15-B15)/B15 -> -0.13012422 | E15: 0 | F15: 0 | G15: 0 | H15: 0 | I15: 0 | J15: 0 | K15: 0 | L15: 0 | M15: 0 | N15: 0 | O15: 0 | P15: 0 | Q15: 0 | R15: 0 | S15: 0 | T15: 0 | U15: 0 | V15: 0 | W15: 0 | X15: 0 | Y15: 0 | Z15: 0 | AA15: 0 | AB15: 0 | AC15: 0 | AD15: 0 | AE15: 0 | AF15: 0 | AG15: 0 | AH15: 0 | AI15: 0 | AJ15: 0 | AK15: 0 | AL15: 0 | AM15: 0 | AN15: 0 | AO15: 0 | AP15: 0 | AQ15: 0 | AR15: 0 | AS15: 0 | AT15: 0 | AU15: 0 | AV15: 0 | AW15: 0 | AX15: 0 | AY15: 0 | AZ15: 0 | BA15: 0 | BB15: 0 | BC15: 0 | BD15: 0 | BE15: 0 | BF15: 0 | BG15: 0 | BH15: 0 | BI15: 0 | BJ15: 0 | BK15: 0 | BL15: 0 | BM15: 0 | BN15: 0 | BO15: 0 | BQ15: =A15 -> 44742 | BR15: =B15+E15+H15+K15+N15+Q15 -> 322 | BS15: =BR15-BR14 -> 10 | BT15: =C15+F15+I15+L15+O15+R15 -> 280.1 | BU15: =BT15-BR15 -> -41.9 | BV15: =BU15/BR15 -> -0.13012422 | BW15: =BU15-BU14 -> -15.79 | BY15: =A15 -> 44742 | BZ15: =Z15+T15+AC15+W15+AR15+AF15+AI15+AL15+AO15+AU15+AX15+BA15+BD15+BG15+BJ15+BM15 -> 0 | CA15: =BZ15-BZ14 -> 0 | CB15: =AA15+U15+AD15+X15+AS15+AG15+AJ15+AM15+AP15+AV15+AY15+BB15+BE15+BG15+BK15+BM15 -> 0 | CC15: =CB15-BZ15 -> 0 | CD15: 0 | CE15: =CC15-CC14 -> 0 | CG15: =A15 -> 44742 | CH15: =BR15+BZ15 -> 322 | CI15: =BS15+CA15 -> 10 | CJ15: =BT15+CB15 -> 280.1 | CK15: =CJ15-CH15 -> -41.9 | CL15: 0 | CM15: =CK15-CK14 -> -15.79 | CO15: =A15 -> 44742 | CP15: =(C15-B15)-(C14-B14) -> -15.79 | CQ15: =(F15-E15)-(F14-E14) -> 0 | CR15: =(I15-H15)-(I14-H14) -> 0 | CS15: =(L15-K15)-(L14-K14) -> 0 | CT15: =(O15-N15)-(O14-N14) -> 0 | CU15: =(R15-Q15)-(R14-Q14) -> 0 | CV15: =(U15-T15)-(U14-T14) -> 0 | CW15: =(X15-W15)-(X14-W14) -> 0 | CX15: =(AA15-Z15)-(AA14-Z14) -> 0 | CY15: =(AD15-AC15)-(AD14-AC14) -> 0 | CZ15: =(AG15-AF15)-(AG14-AF14) -> 0 | DA15: =(AJ15-AI15)-(AJ14-AI14) -> 0 | DB15: =(AM15-AL15)-(AM14-AL14) -> 0 | DC15: =(AP15-AO15)-(AP14-AO14) -> 0 | DD15: =(AS15-AR15)-(AS14-AR14) -> 0 | DE15: =(AV15-AU15)-(AV14-AU14) -> 0 | DF15: =(AY15-AX15)-(AY14-AX14) -> 0 | DG15: =(BB15-BA15)-(BB14-BA14) -> 0 | DH15: =(BE15-BD15)-(BE14-BD14) -> 0 | DI15: =(BH15-BG15)-(BH14-BG14) -> 0 | DJ15: =(BK15-BJ15)-(BK14-BJ14) -> 0 | DK15: =(BN15-BM15)-(BN14-BM14) -> 0
A16: 44773 | B16: 332 | C16: 305.31 | D16: =(C16-B16)/B16 -> -0.080391566 | E16: 0 | F16: 0 | G16: 0 | H16: 0 | I16: 0 | J16: 0 | K16: 0 | L16: 0 | M16: 0 | N16: 0 | O16: 0 | P16: 0 | Q16: 0 | R16: 0 | S16: 0 | T16: 0 | U16: 0 | V16: 0 | W16: 0 | X16: 0 | Y16: 0 | Z16: 0 | AA16: 0 | AB16: 0 | AC16: 0 | AD16: 0 | AE16: 0 | AF16: 0 | AG16: 0 | AH16: 0 | AI16: 0 | AJ16: 0 | AK16: 0 | AL16: 0 | AM16: 0 | AN16: 0 | AO16: 0 | AP16: 0 | AQ16: 0 | AR16: 0 | AS16: 0 | AT16: 0 | AU16: 0 | AV16: 0 | AW16: 0 | AX16: 0 | AY16: 0 | AZ16: 0 | BA16: 0 | BB16: 0 | BC16: 0 | BD16: 0 | BE16: 0 | BF16: 0 | BG16: 0 | BH16: 0 | BI16: 0 | BJ16: 0 | BK16: 0 | BL16: 0 | BM16: 0 | BN16: 0 | BO16: 0 | BQ16: =A16 -> 44773 | BR16: =B16+E16+H16+K16+N16+Q16 -> 332 | BS16: =BR16-BR15 -> 10 | BT16: =C16+F16+I16+L16+O16+R16 -> 305.31 | BU16: =BT16-BR16 -> -26.69 | BV16: =BU16/BR16 -> -0.080391566 | BW16: =BU16-BU15 -> 15.21 | BY16: =A16 -> 44773 | BZ16: =Z16+T16+AC16+W16+AR16+AF16+AI16+AL16+AO16+AU16+AX16+BA16+BD16+BG16+BJ16+BM16 -> 0 | CA16: =BZ16-BZ15 -> 0 | CB16: =AA16+U16+AD16+X16+AS16+AG16+AJ16+AM16+AP16+AV16+AY16+BB16+BE16+BG16+BK16+BM16 -> 0 | CC16: =CB16-BZ16 -> 0 | CD16: 0 | CE16: =CC16-CC15 -> 0 | CG16: =A16 -> 44773 | CH16: =BR16+BZ16 -> 332 | CI16: =BS16+CA16 -> 10 | CJ16: =BT16+CB16 -> 305.31 | CK16: =CJ16-CH16 -> -26.69 | CL16: 0 | CM16: =CK16-CK15 -> 15.21 | CO16: =A16 -> 44773 | CP16: =(C16-B16)-(C15-B15) -> 15.21 | CQ16: =(F16-E16)-(F15-E15) -> 0 | CR16: =(I16-H16)-(I15-H15) -> 0 | CS16: =(L16-K16)-(L15-K15) -> 0 | CT16: =(O16-N16)-(O15-N15) -> 0 | CU16: =(R16-Q16)-(R15-Q15) -> 0 | CV16: =(U16-T16)-(U15-T15) -> 0 | CW16: =(X16-W16)-(X15-W15) -> 0 | CX16: =(AA16-Z16)-(AA15-Z15) -> 0 | CY16: =(AD16-AC16)-(AD15-AC15) -> 0 | CZ16: =(AG16-AF16)-(AG15-AF15) -> 0 | DA16: =(AJ16-AI16)-(AJ15-AI15) -> 0 | DB16: =(AM16-AL16)-(AM15-AL15) -> 0 | DC16: =(AP16-AO16)-(AP15-AO15) -> 0 | DD16: =(AS16-AR16)-(AS15-AR15) -> 0 | DE16: =(AV16-AU16)-(AV15-AU15) -> 0 | DF16: =(AY16-AX16)-(AY15-AX15) -> 0 | DG16: =(BB16-BA16)-(BB15-BA15) -> 0 | DH16: =(BE16-BD16)-(BE15-BD15) -> 0 | DI16: =(BH16-BG16)-(BH15-BG15) -> 0 | DJ16: =(BK16-BJ16)-(BK15-BJ15) -> 0 | DK16: =(BN16-BM16)-(BN15-BM15) -> 0
A17: 44804 | B17: 342 | C17: 308.79 | D17: =(C17-B17)/B17 -> -0.097105263 | E17: 0 | F17: 0 | G17: 0 | H17: 0 | I17: 0 | J17: 0 | K17: 0 | L17: 0 | M17: 0 | N17: 0 | O17: 0 | P17: 0 | Q17: 0 | R17: 0 | S17: 0 | T17: 0 | U17: 0 | V17: 0 | W17: 0 | X17: 0 | Y17: 0 | Z17: 0 | AA17: 0 | AB17: 0 | AC17: 0 | AD17: 0 | AE17: 0 | AF17: 0 | AG17: 0 | AH17: 0 | AI17: 0 | AJ17: 0 | AK17: 0 | AL17: 0 | AM17: 0 | AN17: 0 | AO17: 0 | AP17: 0 | AQ17: 0 | AR17: 0 | AS17: 0 | AT17: 0 | AU17: 0 | AV17: 0 | AW17: 0 | AX17: 0 | AY17: 0 | AZ17: 0 | BA17: 0 | BB17: 0 | BC17: 0 | BD17: 0 | BE17: 0 | BF17: 0 | BG17: 0 | BH17: 0 | BI17: 0 | BJ17: 0 | BK17: 0 | BL17: 0 | BM17: 0 | BN17: 0 | BO17: 0 | BQ17: =A17 -> 44804 | BR17: =B17+E17+H17+K17+N17+Q17 -> 342 | BS17: =BR17-BR16 -> 10 | BT17: =C17+F17+I17+L17+O17+R17 -> 308.79 | BU17: =BT17-BR17 -> -33.21 | BV17: =BU17/BR17 -> -0.097105263 | BW17: =BU17-BU16 -> -6.52 | BY17: =A17 -> 44804 | BZ17: =Z17+T17+AC17+W17+AR17+AF17+AI17+AL17+AO17+AU17+AX17+BA17+BD17+BG17+BJ17+BM17 -> 0 | CA17: =BZ17-BZ16 -> 0 | CB17: =AA17+U17+AD17+X17+AS17+AG17+AJ17+AM17+AP17+AV17+AY17+BB17+BE17+BG17+BK17+BM17 -> 0 | CC17: =CB17-BZ17 -> 0 | CD17: 0 | CE17: =CC17-CC16 -> 0 | CG17: =A17 -> 44804 | CH17: =BR17+BZ17 -> 342 | CI17: =BS17+CA17 -> 10 | CJ17: =BT17+CB17 -> 308.79 | CK17: =CJ17-CH17 -> -33.21 | CL17: 0 | CM17: =CK17-CK16 -> -6.52 | CO17: =A17 -> 44804 | CP17: =(C17-B17)-(C16-B16) -> -6.52 | CQ17: =(F17-E17)-(F16-E16) -> 0 | CR17: =(I17-H17)-(I16-H16) -> 0 | CS17: =(L17-K17)-(L16-K16) -> 0 | CT17: =(O17-N17)-(O16-N16) -> 0 | CU17: =(R17-Q17)-(R16-Q16) -> 0 | CV17: =(U17-T17)-(U16-T16) -> 0 | CW17: =(X17-W17)-(X16-W16) -> 0 | CX17: =(AA17-Z17)-(AA16-Z16) -> 0 | CY17: =(AD17-AC17)-(AD16-AC16) -> 0 | CZ17: =(AG17-AF17)-(AG16-AF16) -> 0 | DA17: =(AJ17-AI17)-(AJ16-AI16) -> 0 | DB17: =(AM17-AL17)-(AM16-AL16) -> 0 | DC17: =(AP17-AO17)-(AP16-AO16) -> 0 | DD17: =(AS17-AR17)-(AS16-AR16) -> 0 | DE17: =(AV17-AU17)-(AV16-AU16) -> 0 | DF17: =(AY17-AX17)-(AY16-AX16) -> 0 | DG17: =(BB17-BA17)-(BB16-BA16) -> 0 | DH17: =(BE17-BD17)-(BE16-BD16) -> 0 | DI17: =(BH17-BG17)-(BH16-BG16) -> 0 | DJ17: =(BK17-BJ17)-(BK16-BJ16) -> 0 | DK17: =(BN17-BM17)-(BN16-BM16) -> 0
... A33: 45291 | B33: 502 | C33: 503.87 | D33: =(C33-B33)/B33 -> 0.0037250996 | E33: 0 | F33: 0 | G33: 0 | H33: 0 | I33: 0 | J33: 0 | K33: 0 | L33: 0 | M33: 0 | N33: 0 | O33: 0 | P33: 0 | Q33: 0 | R33: 0 | S33: 0 | T33: 0 | U33: 0 | V33: 0 | W33: 0 | X33: 0 | Y33: 0 | Z33: 0 | AA33: 0 | AB33: 0 | AC33: 0 | AD33: 0 | AE33: 0 | AF33: 0 | AG33: 0 | AH33: 0 | AI33: 0 | AJ33: 0 | AK33: 0 | AL33: 0 | AM33: 0 | AN33: 0 | AO33: 0 | AP33: 0 | AQ33: 0 | AR33: 0 | AS33: 0 | AT33: 0 | AU33: 0 | AV33: 0 | AW33: 0 | AX33: 0 | AY33: 0 | AZ33: 0 | BA33: 0 | BB33: 0 | BC33: 0 | BD33: 0 | BE33: 0 | BF33: 0 | BG33: 0 | BH33: 0 | BI33: 0 | BJ33: 0 | BK33: 0 | BL33: 0 | BM33: 0 | BN33: 0 | BO33: 0 | BQ33: =A33 -> 45291 | BR33: =B33+E33+H33+K33+N33+Q33 -> 502 | BS33: =BR33-BR32 -> 10 | BT33: =C33+F33+I33+L33+O33+R33 -> 503.87 | BU33: =BT33-BR33 -> 1.87 | BV33: =BU33/BR33 -> 0.0037250996 | BW33: =BU33-BU32 -> 20.82 | BY33: =A33 -> 45291 | BZ33: =Z33+T33+AC33+W33+AR33+AF33+AI33+AL33+AO33+AU33+AX33+BA33+BD33+BG33+BJ33+BM33 -> 0 | CA33: =BZ33-BZ32 -> 0 | CB33: =AA33+U33+AD33+X33+AS33+AG33+AJ33+AM33+AP33+AV33+AY33+BB33+BE33+BG33+BK33+BM33 -> 0 | CC33: =CB33-BZ33 -> 0 | CD33: 0 | CE33: =CC33-CC32 -> 0 | CG33: =A33 -> 45291 | CH33: =BR33+BZ33 -> 502 | CI33: =BS33+CA33 -> 10 | CJ33: =BT33+CB33 -> 503.87 | CK33: =CJ33-CH33 -> 1.87 | CL33: 0 | CM33: =CK33-CK32 -> 20.82 | CO33: =A33 -> 45291 | CP33: =(C33-B33)-(C32-B32) -> 20.82 | CQ33: =(F33-E33)-(F32-E32) -> 0 | CR33: =(I33-H33)-(I32-H32) -> 0 | CS33: =(L33-K33)-(L32-K32) -> 0 | CT33: =(O33-N33)-(O32-N32) -> 0 | CU33: =(R33-Q33)-(R32-Q32) -> 0 | CV33: =(U33-T33)-(U32-T32) -> 0 | CW33: =(X33-W33)-(X32-W32) -> 0 | CX33: =(AA33-Z33)-(AA32-Z32) -> 0 | CY33: =(AD33-AC33)-(AD32-AC32) -> 0 | CZ33: =(AG33-AF33)-(AG32-AF32) -> 0 | DA33: =(AJ33-AI33)-(AJ32-AI32) -> 0 | DB33: =(AM33-AL33)-(AM32-AL32) -> 0 | DC33: =(AP33-AO33)-(AP32-AO32) -> 0 | DD33: =(AS33-AR33)-(AS32-AR32) -> 0 | DE33: =(AV33-AU33)-(AV32-AU32) -> 0 | DF33: =(AY33-AX33)-(AY32-AX32) -> 0 | DG33: =(BB33-BA33)-(BB32-BA32) -> 0 | DH33: =(BE33-BD33)-(BE32-BD32) -> 0 | DI33: =(BH33-BG33)-(BH32-BG32) -> 0 | DJ33: =(BK33-BJ33)-(BK32-BJ32) -> 0 | DK33: =(BN33-BM33)-(BN32-BM32) -> 0
A34: 45322 | B34: 540.94 | C34: 550.84 | D34: =(C34-B34)/B34 -> 0.018301475 | E34: 0 | F34: 0 | G34: 0 | H34: 0 | I34: 0 | J34: 0 | K34: 0 | L34: 0 | M34: 0 | N34: 0 | O34: 0 | P34: 0 | Q34: 100 | R34: 96.26 | S34: =(R34-Q34)/Q34 -> -0.0374 | T34: 0 | U34: 0 | V34: 0 | W34: 0 | X34: 0 | Y34: 0 | Z34: 0 | AA34: 0 | AB34: 0 | AC34: 0 | AD34: 0 | AE34: 0 | AF34: 0 | AG34: 0 | AH34: 0 | AI34: 0 | AJ34: 0 | AK34: 0 | AL34: 0 | AM34: 0 | AN34: 0 | AO34: 0 | AP34: 0 | AQ34: 0 | AR34: 0 | AS34: 0 | AT34: 0 | AU34: 0 | AV34: 0 | AW34: 0 | AX34: 0 | AY34: 0 | AZ34: 0 | BA34: 0 | BB34: 0 | BC34: 0 | BD34: 0 | BE34: 0 | BF34: 0 | BG34: 0 | BH34: 0 | BI34: 0 | BJ34: 0 | BK34: 0 | BL34: 0 | BM34: 0 | BN34: 0 | BO34: 0 | BQ34: =A34 -> 45322 | BR34: =B34+E34+H34+K34+N34+Q34 -> 640.94 | BS34: =BR34-BR33 -> 138.94 | BT34: =C34+F34+I34+L34+O34+R34 -> 647.1 | BU34: =BT34-BR34 -> 6.16 | BV34: =BU34/BR34 -> 0.009610884 | BW34: =BU34-BU33 -> 4.29 | BY34: =A34 -> 45322 | BZ34: =Z34+T34+AC34+W34+AR34+AF34+AI34+AL34+AO34+AU34+AX34+BA34+BD34+BG34+BJ34+BM34 -> 0 | CA34: =BZ34-BZ33 -> 0 | CB34: =AA34+U34+AD34+X34+AS34+AG34+AJ34+AM34+AP34+AV34+AY34+BB34+BE34+BG34+BK34+BM34 -> 0 | CC34: =CB34-BZ34 -> 0 | CD34: 0 | CE34: =CC34-CC33 -> 0 | CG34: =A34 -> 45322 | CH34: =BR34+BZ34 -> 640.94 | CI34: =BS34+CA34 -> 138.94 | CJ34: =BT34+CB34 -> 647.1 | CK34: =CJ34-CH34 -> 6.16 | CL34: 0 | CM34: =CK34-CK33 -> 4.29 | CO34: =A34 -> 45322 | CP34: =(C34-B34)-(C33-B33) -> 8.03 | CQ34: =(F34-E34)-(F33-E33) -> 0 | CR34: =(I34-H34)-(I33-H33) -> 0 | CS34: =(L34-K34)-(L33-K33) -> 0 | CT34: =(O34-N34)-(O33-N33) -> 0 | CU34: =(R34-Q34)-(R33-Q33) -> -3.74 | CV34: =(U34-T34)-(U33-T33) -> 0 | CW34: =(X34-W34)-(X33-W33) -> 0 | CX34: =(AA34-Z34)-(AA33-Z33) -> 0 | CY34: =(AD34-AC34)-(AD33-AC33) -> 0 | CZ34: =(AG34-AF34)-(AG33-AF33) -> 0 | DA34: =(AJ34-AI34)-(AJ33-AI33) -> 0 | DB34: =(AM34-AL34)-(AM33-AL33) -> 0 | DC34: =(AP34-AO34)-(AP33-AO33) -> 0 | DD34: =(AS34-AR34)-(AS33-AR33) -> 0 | DE34: =(AV34-AU34)-(AV33-AU33) -> 0 | DF34: =(AY34-AX34)-(AY33-AX33) -> 0 | DG34: =(BB34-BA34)-(BB33-BA33) -> 0 | DH34: =(BE34-BD34)-(BE33-BD33) -> 0 | DI34: =(BH34-BG34)-(BH33-BG33) -> 0 | DJ34: =(BK34-BJ34)-(BK33-BJ33) -> 0 | DK34: =(BN34-BM34)-(BN33-BM33) -> 0
A35: 45351 | B35: 565.94 | C35: 588.96 | D35: =(C35-B35)/B35 -> 0.04067569 | E35: 0 | F35: 0 | G35: 0 | H35: 0 | I35: 0 | J35: 0 | K35: 0 | L35: 0 | M35: 0 | N35: 100 | O35: 100.04 | P35: =(O35-N35)/N35 -> 0.0004 | Q35: 100 | R35: 105.49 | S35: =(R35-Q35)/Q35 -> 0.0549 | T35: 0 | U35: 0 | V35: 0 | W35: 0 | X35: 0 | Y35: 0 | Z35: 0 | AA35: 0 | AB35: 0 | AC35: 0 | AD35: 0 | AE35: 0 | AF35: 0 | AG35: 0 | AH35: 0 | AI35: 0 | AJ35: 0 | AK35: 0 | AL35: 0 | AM35: 0 | AN35: 0 | AO35: 0 | AP35: 0 | AQ35: 0 | AR35: 0 | AS35: 0 | AT35: 0 | AU35: 0 | AV35: 0 | AW35: 0 | AX35: 0 | AY35: 0 | AZ35: 0 | BA35: 0 | BB35: 0 | BC35: 0 | BD35: 0 | BE35: 0 | BF35: 0 | BG35: 0 | BH35: 0 | BI35: 0 | BJ35: 0 | BK35: 0 | BL35: 0 | BM35: 0 | BN35: 0 | BO35: 0 | BQ35: =A35 -> 45351 | BR35: =B35+E35+H35+K35+N35+Q35 -> 765.94 | BS35: =BR35-BR34 -> 125 | BT35: =C35+F35+I35+L35+O35+R35 -> 794.49 | BU35: =BT35-BR35 -> 28.55 | BV35: =BU35/BR35 -> 0.03727446 | BW35: =BU35-BU34 -> 22.39 | BY35: =A35 -> 45351 | BZ35: =Z35+T35+AC35+W35+AR35+AF35+AI35+AL35+AO35+AU35+AX35+BA35+BD35+BG35+BJ35+BM35 -> 0 | CA35: =BZ35-BZ34 -> 0 | CB35: =AA35+U35+AD35+X35+AS35+AG35+AJ35+AM35+AP35+AV35+AY35+BB35+BE35+BG35+BK35+BM35 -> 0 | CC35: =CB35-BZ35 -> 0 | CD35: 0 | CE35: =CC35-CC34 -> 0 | CG35: =A35 -> 45351 | CH35: =BR35+BZ35 -> 765.94 | CI35: =BS35+CA35 -> 125 | CJ35: =BT35+CB35 -> 794.49 | CK35: =CJ35-CH35 -> 28.55 | CL35: 0 | CM35: =CK35-CK34 -> 22.39 | CO35: =A35 -> 45351 | CP35: =(C35-B35)-(C34-B34) -> 13.12 | CQ35: =(F35-E35)-(F34-E34) -> 0 | CR35: =(I35-H35)-(I34-H34) -> 0 | CS35: =(L35-K35)-(L34-K34) -> 0 | CT35: =(O35-N35)-(O34-N34) -> 0.04 | CU35: =(R35-Q35)-(R34-Q34) -> 9.23 | CV35: =(U35-T35)-(U34-T34) -> 0 | CW35: =(X35-W35)-(X34-W34) -> 0 | CX35: =(AA35-Z35)-(AA34-Z34) -> 0 | CY35: =(AD35-AC35)-(AD34-AC34) -> 0 | CZ35: =(AG35-AF35)-(AG34-AF34) -> 0 | DA35: =(AJ35-AI35)-(AJ34-AI34) -> 0 | DB35: =(AM35-AL35)-(AM34-AL34) -> 0 | DC35: =(AP35-AO35)-(AP34-AO34) -> 0 | DD35: =(AS35-AR35)-(AS34-AR34) -> 0 | DE35: =(AV35-AU35)-(AV34-AU34) -> 0 | DF35: =(AY35-AX35)-(AY34-AX34) -> 0 | DG35: =(BB35-BA35)-(BB34-BA34) -> 0 | DH35: =(BE35-BD35)-(BE34-BD34) -> 0 | DI35: =(BH35-BG35)-(BH34-BG34) -> 0 | DJ35: =(BK35-BJ35)-(BK34-BJ34) -> 0 | DK35: =(BN35-BM35)-(BN34-BM34) -> 0
A36: 45382 | B36: 580.94 | C36: 619.74 | D36: =(C36-B36)/B36 -> 0.066788309 | E36: 0 | F36: 0 | G36: 0 | H36: 0 | I36: 0 | J36: 0 | K36: 0 | L36: 0 | M36: 0 | N36: 100 | O36: 101.52 | P36: =(O36-N36)/N36 -> 0.0152 | Q36: 100 | R36: 106.16 | S36: =(R36-Q36)/Q36 -> 0.0616 | T36: 0 | U36: 0 | V36: 0 | W36: 0 | X36: 0 | Y36: 0 | Z36: 0 | AA36: 0 | AB36: 0 | AC36: 0 | AD36: 0 | AE36: 0 | AF36: 0 | AG36: 0 | AH36: 0 | AI36: 0 | AJ36: 0 | AK36: 0 | AL36: 0 | AM36: 0 | AN36: 0 | AO36: 0 | AP36: 0 | AQ36: 0 | AR36: 0 | AS36: 0 | AT36: 0 | AU36: 0 | AV36: 0 | AW36: 0 | AX36: 0 | AY36: 0 | AZ36: 0 | BA36: 0 | BB36: 0 | BC36: 0 | BD36: 0 | BE36: 0 | BF36: 0 | BG36: 0 | BH36: 0 | BI36: 0 | BJ36: 0 | BK36: 0 | BL36: 0 | BM36: 0 | BN36: 0 | BO36: 0 | BQ36: =A36 -> 45382 | BR36: =B36+E36+H36+K36+N36+Q36 -> 780.94 | BS36: =BR36-BR35 -> 15 | BT36: =C36+F36+I36+L36+O36+R36 -> 827.42 | BU36: =BT36-BR36 -> 46.48 | BV36: =BU36/BR36 -> 0.059518017 | BW36: =BU36-BU35 -> 17.93 | BY36: =A36 -> 45382 | BZ36: =Z36+T36+AC36+W36+AR36+AF36+AI36+AL36+AO36+AU36+AX36+BA36+BD36+BG36+BJ36+BM36 -> 0 | CA36: =BZ36-BZ35 -> 0 | CB36: =AA36+U36+AD36+X36+AS36+AG36+AJ36+AM36+AP36+AV36+AY36+BB36+BE36+BG36+BK36+BM36 -> 0 | CC36: =CB36-BZ36 -> 0 | CD36: 0 | CE36: =CC36-CC35 -> 0 | CG36: =A36 -> 45382 | CH36: =BR36+BZ36 -> 780.94 | CI36: =BS36+CA36 -> 15 | CJ36: =BT36+CB36 -> 827.42 | CK36: =CJ36-CH36 -> 46.48 | CL36: 0 | CM36: =CK36-CK35 -> 17.93 | CO36: =A36 -> 45382 | CP36: =(C36-B36)-(C35-B35) -> 15.78 | CQ36: =(F36-E36)-(F35-E35) -> 0 | CR36: =(I36-H36)-(I35-H35) -> 0 | CS36: =(L36-K36)-(L35-K35) -> 0 | CT36: =(O36-N36)-(O35-N35) -> 1.48 | CU36: =(R36-Q36)-(R35-Q35) -> 0.67 | CV36: =(U36-T36)-(U35-T35) -> 0 | CW36: =(X36-W36)-(X35-W35) -> 0 | CX36: =(AA36-Z36)-(AA35-Z35) -> 0 | CY36: =(AD36-AC36)-(AD35-AC35) -> 0 | CZ36: =(AG36-AF36)-(AG35-AF35) -> 0 | DA36: =(AJ36-AI36)-(AJ35-AI35) -> 0 | DB36: =(AM36-AL36)-(AM35-AL35) -> 0 | DC36: =(AP36-AO36)-(AP35-AO35) -> 0 | DD36: =(AS36-AR36)-(AS35-AR35) -> 0 | DE36: =(AV36-AU36)-(AV35-AU35) -> 0 | DF36: =(AY36-AX36)-(AY35-AX35) -> 0 | DG36: =(BB36-BA36)-(BB35-BA35) -> 0 | DH36: =(BE36-BD36)-(BE35-BD35) -> 0 | DI36: =(BH36-BG36)-(BH35-BG35) -> 0 | DJ36: =(BK36-BJ36)-(BK35-BJ35) -> 0 | DK36: =(BN36-BM36)-(BN35-BM35) -> 0
A37: 45412 | B37: 605.94 | C37: 635.34 | D37: =(C37-B37)/B37 -> 0.048519655 | E37: 0 | F37: 0 | G37: 0 | H37: 0 | I37: 0 | J37: 0 | K37: 0 | L37: 0 | M37: 0 | N37: 100 | O37: 100.34 | P37: =(O37-N37)/N37 -> 0.0034 | Q37: 100 | R37: 104.32 | S37: =(R37-Q37)/Q37 -> 0.0432 | T37: 0 | U37: 0 | V37: 0 | W37: 0 | X37: 0 | Y37: 0 | Z37: 0 | AA37: 0 | AB37: 0 | AC37: 0 | AD37: 0 | AE37: 0 | AF37: 0 | AG37: 0 | AH37: 0 | AI37: 0 | AJ37: 0 | AK37: 0 | AL37: 0 | AM37: 0 | AN37: 0 | AO37: 0 | AP37: 0 | AQ37: 0 | AR37: 0 | AS37: 0 | AT37: 0 | AU37: 0 | AV37: 0 | AW37: 0 | AX37: 0 | AY37: 0 | AZ37: 0 | BA37: 0 | BB37: 0 | BC37: 0 | BD37: 0 | BE37: 0 | BF37: 0 | BG37: 0 | BH37: 0 | BI37: 0 | BJ37: 0 | BK37: 0 | BL37: 0 | BM37: 0 | BN37: 0 | BO37: 0 | BQ37: =A37 -> 45412 | BR37: =B37+E37+H37+K37+N37+Q37 -> 805.94 | BS37: =BR37-BR36 -> 25 | BT37: =C37+F37+I37+L37+O37+R37 -> 840 | BU37: =BT37-BR37 -> 34.06 | BV37: =BU37/BR37 -> 0.042261211 | BW37: =BU37-BU36 -> -12.42 | BY37: =A37 -> 45412 | BZ37: =Z37+T37+AC37+W37+AR37+AF37+AI37+AL37+AO37+AU37+AX37+BA37+BD37+BG37+BJ37+BM37 -> 0 | CA37: =BZ37-BZ36 -> 0 | CB37: =AA37+U37+AD37+X37+AS37+AG37+AJ37+AM37+AP37+AV37+AY37+BB37+BE37+BG37+BK37+BM37 -> 0 | CC37: =CB37-BZ37 -> 0 | CD37: 0 | CE37: =CC37-CC36 -> 0 | CG37: =A37 -> 45412 | CH37: =BR37+BZ37 -> 805.94 | CI37: =BS37+CA37 -> 25 | CJ37: =BT37+CB37 -> 840 | CK37: =CJ37-CH37 -> 34.06 | CL37: 0 | CM37: =CK37-CK36 -> -12.42 | CO37: =A37 -> 45412 | CP37: =(C37-B37)-(C36-B36) -> -9.4 | CQ37: =(F37-E37)-(F36-E36) -> 0 | CR37: =(I37-H37)-(I36-H36) -> 0 | CS37: =(L37-K37)-(L36-K36) -> 0 | CT37: =(O37-N37)-(O36-N36) -> -1.18 | CU37: =(R37-Q37)-(R36-Q36) -> -1.84 | CV37: =(U37-T37)-(U36-T36) -> 0 | CW37: =(X37-W37)-(X36-W36) -> 0 | CX37: =(AA37-Z37)-(AA36-Z36) -> 0 | CY37: =(AD37-AC37)-(AD36-AC36) -> 0 | CZ37: =(AG37-AF37)-(AG36-AF36) -> 0 | DA37: =(AJ37-AI37)-(AJ36-AI36) -> 0 | DB37: =(AM37-AL37)-(AM36-AL36) -> 0 | DC37: =(AP37-AO37)-(AP36-AO36) -> 0 | DD37: =(AS37-AR37)-(AS36-AR36) -> 0 | DE37: =(AV37-AU37)-(AV36-AU36) -> 0 | DF37: =(AY37-AX37)-(AY36-AX36) -> 0 | DG37: =(BB37-BA37)-(BB36-BA36) -> 0 | DH37: =(BE37-BD37)-(BE36-BD36) -> 0 | DI37: =(BH37-BG37)-(BH36-BG36) -> 0 | DJ37: =(BK37-BJ37)-(BK36-BJ36) -> 0 | DK37: =(BN37-BM37)-(BN36-BM36) -> 0
A38: 45443 | B38: 659.92 | C38: 704.37 | D38: =(C38-B38)/B38 -> 0.067356649 | E38: 29.96 | F38: 29.26 | G38: =(F38-E38)/E38 -> -0.023364486 | H38: 0 | I38: 0 | J38: 0 | K38: 0 | L38: 0 | M38: 0 | N38: 100 | O38: 101.11 | P38: =(O38-N38)/N38 -> 0.0111 | Q38: 150 | R38: 158.46 | S38: =(R38-Q38)/Q38 -> 0.0564 | T38: 0 | U38: 0 | V38: 0 | W38: 0 | X38: 0 | Y38: 0 | Z38: 0 | AA38: 0 | AB38: 0 | AC38: 0 | AD38: 0 | AE38: 0 | AF38: 0 | AG38: 0 | AH38: 0 | AI38: 0 | AJ38: 0 | AK38: 0 | AL38: 0 | AM38: 0 | AN38: 0 | AO38: 0 | AP38: 0 | AQ38: 0 | AR38: 0 | AS38: 0 | AT38: 0 | AU38: 0 | AV38: 0 | AW38: 0 | AX38: 0 | AY38: 0 | AZ38: 0 | BA38: 0 | BB38: 0 | BC38: 0 | BD38: 0 | BE38: 0 | BF38: 0 | BG38: 0 | BH38: 0 | BI38: 0 | BJ38: 0 | BK38: 0 | BL38: 0 | BM38: 0 | BN38: 0 | BO38: 0 | BQ38: =A38 -> 45443 | BR38: =B38+E38+H38+K38+N38+Q38 -> 939.88 | BS38: =BR38-BR37 -> 133.94 | BT38: =C38+F38+I38+L38+O38+R38 -> 993.2 | BU38: =BT38-BR38 -> 53.32 | BV38: =BU38/BR38 -> 0.056730646 | BW38: =BU38-BU37 -> 19.26 | BY38: =A38 -> 45443 | BZ38: =Z38+T38+AC38+W38+AR38+AF38+AI38+AL38+AO38+AU38+AX38+BA38+BD38+BG38+BJ38+BM38 -> 0 | CA38: =BZ38-BZ37 -> 0 | CB38: =AA38+U38+AD38+X38+AS38+AG38+AJ38+AM38+AP38+AV38+AY38+BB38+BE38+BG38+BK38+BM38 -> 0 | CC38: =CB38-BZ38 -> 0 | CD38: 0 | CE38: =CC38-CC37 -> 0 | CG38: =A38 -> 45443 | CH38: =BR38+BZ38 -> 939.88 | CI38: =BS38+CA38 -> 133.94 | CJ38: =BT38+CB38 -> 993.2 | CK38: =CJ38-CH38 -> 53.32 | CL38: 0 | CM38: =CK38-CK37 -> 19.26 | CO38: =A38 -> 45443 | CP38: =(C38-B38)-(C37-B37) -> 15.05 | CQ38: =(F38-E38)-(F37-E37) -> -0.7 | CR38: =(I38-H38)-(I37-H37) -> 0 | CS38: =(L38-K38)-(L37-K37) -> 0 | CT38: =(O38-N38)-(O37-N37) -> 0.77 | CU38: =(R38-Q38)-(R37-Q37) -> 4.14 | CV38: =(U38-T38)-(U37-T37) -> 0 | CW38: =(X38-W38)-(X37-W37) -> 0 | CX38: =(AA38-Z38)-(AA37-Z37) -> 0 | CY38: =(AD38-AC38)-(AD37-AC37) -> 0 | CZ38: =(AG38-AF38)-(AG37-AF37) -> 0 | DA38: =(AJ38-AI38)-(AJ37-AI37) -> 0 | DB38: =(AM38-AL38)-(AM37-AL37) -> 0 | DC38: =(AP38-AO38)-(AP37-AO37) -> 0 | DD38: =(AS38-AR38)-(AS37-AR37) -> 0 | DE38: =(AV38-AU38)-(AV37-AU37) -> 0 | DF38: =(AY38-AX38)-(AY37-AX37) -> 0 | DG38: =(BB38-BA38)-(BB37-BA37) -> 0 | DH38: =(BE38-BD38)-(BE37-BD37) -> 0 | DI38: =(BH38-BG38)-(BH37-BG37) -> 0 | DJ38: =(BK38-BJ38)-(BK37-BJ37) -> 0 | DK38: =(BN38-BM38)-(BN37-BM37) -> 0
A39: 45473 | B39: 674.92 | C39: 737.28 | D39: =(C39-B39)/B39 -> 0.092396136 | E39: 39.94 | F39: 40.49 | G39: =(F39-E39)/E39 -> 0.013770656 | H39: 0 | I39: 0 | J39: 0 | K39: 0 | L39: 0 | M39: 0 | N39: 100 | O39: 105.83 | P39: =(O39-N39)/N39 -> 0.0583 | Q39: 150 | R39: 169.71 | S39: =(R39-Q39)/Q39 -> 0.1314 | T39: 0 | U39: 0 | V39: 0 | W39: 0 | X39: 0 | Y39: 0 | Z39: 0 | AA39: 0 | AB39: 0 | AC39: 0 | AD39: 0 | AE39: 0 | AF39: 0 | AG39: 0 | AH39: 0 | AI39: 0 | AJ39: 0 | AK39: 0 | AL39: 0 | AM39: 0 | AN39: 0 | AO39: 0 | AP39: 0 | AQ39: 0 | AR39: 0 | AS39: 0 | AT39: 0 | AU39: 0 | AV39: 0 | AW39: 0 | AX39: 0 | AY39: 0 | AZ39: 0 | BA39: 0 | BB39: 0 | BC39: 0 | BD39: 0 | BE39: 0 | BF39: 0 | BG39: 0 | BH39: 0 | BI39: 0 | BJ39: 0 | BK39: 0 | BL39: 0 | BM39: 0 | BN39: 0 | BO39: 0 | BQ39: =A39 -> 45473 | BR39: =B39+E39+H39+K39+N39+Q39 -> 964.86 | BS39: =BR39-BR38 -> 24.98 | BT39: =C39+F39+I39+L39+O39+R39 -> 1053.31 | BU39: =BT39-BR39 -> 88.45 | BV39: =BU39/BR39 -> 0.091671331 | BW39: =BU39-BU38 -> 35.13 | BY39: =A39 -> 45473 | BZ39: =Z39+T39+AC39+W39+AR39+AF39+AI39+AL39+AO39+AU39+AX39+BA39+BD39+BG39+BJ39+BM39 -> 0 | CA39: =BZ39-BZ38 -> 0 | CB39: =AA39+U39+AD39+X39+AS39+AG39+AJ39+AM39+AP39+AV39+AY39+BB39+BE39+BG39+BK39+BM39 -> 0 | CC39: =CB39-BZ39 -> 0 | CD39: 0 | CE39: =CC39-CC38 -> 0 | CG39: =A39 -> 45473 | CH39: =BR39+BZ39 -> 964.86 | CI39: =BS39+CA39 -> 24.98 | CJ39: =BT39+CB39 -> 1053.31 | CK39: =CJ39-CH39 -> 88.45 | CL39: 0 | CM39: =CK39-CK38 -> 35.13 | CO39: =A39 -> 45473 | CP39: =(C39-B39)-(C38-B38) -> 17.91 | CQ39: =(F39-E39)-(F38-E38) -> 1.25 | CR39: =(I39-H39)-(I38-H38) -> 0 | CS39: =(L39-K39)-(L38-K38) -> 0 | CT39: =(O39-N39)-(O38-N38) -> 4.72 | CU39: =(R39-Q39)-(R38-Q38) -> 11.25 | CV39: =(U39-T39)-(U38-T38) -> 0 | CW39: =(X39-W39)-(X38-W38) -> 0 | CX39: =(AA39-Z39)-(AA38-Z38) -> 0 | CY39: =(AD39-AC39)-(AD38-AC38) -> 0 | CZ39: =(AG39-AF39)-(AG38-AF38) -> 0 | DA39: =(AJ39-AI39)-(AJ38-AI38) -> 0 | DB39: =(AM39-AL39)-(AM38-AL38) -> 0 | DC39: =(AP39-AO39)-(AP38-AO38) -> 0 | DD39: =(AS39-AR39)-(AS38-AR38) -> 0 | DE39: =(AV39-AU39)-(AV38-AU38) -> 0 | DF39: =(AY39-AX39)-(AY38-AX38) -> 0 | DG39: =(BB39-BA39)-(BB38-BA38) -> 0 | DH39: =(BE39-BD39)-(BE38-BD38) -> 0 | DI39: =(BH39-BG39)-(BH38-BG38) -> 0 | DJ39: =(BK39-BJ39)-(BK38-BJ38) -> 0 | DK39: =(BN39-BM39)-(BN38-BM38) -> 0
A40: 45504 | B40: 709.92 | C40: 764.75 | D40: =(C40-B40)/B40 -> 0.077234055 | E40: 39.94 | F40: 40.78 | G40: =(F40-E40)/E40 -> 0.021031547 | H40: 0 | I40: 0 | J40: 0 | K40: 0 | L40: 0 | M40: 0 | N40: 100 | O40: 105.37 | P40: =(O40-N40)/N40 -> 0.0537 | Q40: 200 | R40: 215.76 | S40: =(R40-Q40)/Q40 -> 0.0788 | T40: 0 | U40: 0 | V40: 0 | W40: 0 | X40: 0 | Y40: 0 | Z40: 0 | AA40: 0 | AB40: 0 | AC40: 0 | AD40: 0 | AE40: 0 | AF40: 0 | AG40: 0 | AH40: 0 | AI40: 0 | AJ40: 0 | AK40: 0 | AL40: 0 | AM40: 0 | AN40: 0 | AO40: 0 | AP40: 0 | AQ40: 0 | AR40: 0 | AS40: 0 | AT40: 0 | AU40: 0 | AV40: 0 | AW40: 0 | AX40: 0 | AY40: 0 | AZ40: 0 | BA40: 0 | BB40: 0 | BC40: 0 | BD40: 0 | BE40: 0 | BF40: 0 | BG40: 0 | BH40: 0 | BI40: 0 | BJ40: 0 | BK40: 0 | BL40: 0 | BM40: 0 | BN40: 0 | BO40: 0 | BQ40: =A40 -> 45504 | BR40: =B40+E40+H40+K40+N40+Q40 -> 1049.86 | BS40: =BR40-BR39 -> 85 | BT40: =C40+F40+I40+L40+O40+R40 -> 1126.66 | BU40: =BT40-BR40 -> 76.8 | BV40: =BU40/BR40 -> 0.073152611 | BW40: =BU40-BU39 -> -11.65 | BY40: =A40 -> 45504 | BZ40: =Z40+T40+AC40+W40+AR40+AF40+AI40+AL40+AO40+AU40+AX40+BA40+BD40+BG40+BJ40+BM40 -> 0 | CA40: =BZ40-BZ39 -> 0 | CB40: =AA40+U40+AD40+X40+AS40+AG40+AJ40+AM40+AP40+AV40+AY40+BB40+BE40+BG40+BK40+BM40 -> 0 | CC40: =CB40-BZ40 -> 0 | CD40: 0 | CE40: =CC40-CC39 -> 0 | CG40: =A40 -> 45504 | CH40: =BR40+BZ40 -> 1049.86 | CI40: =BS40+CA40 -> 85 | CJ40: =BT40+CB40 -> 1126.66 | CK40: =CJ40-CH40 -> 76.8 | CL40: 0 | CM40: =CK40-CK39 -> -11.65 | CO40: =A40 -> 45504 | CP40: =(C40-B40)-(C39-B39) -> -7.53 | CQ40: =(F40-E40)-(F39-E39) -> 0.29 | CR40: =(I40-H40)-(I39-H39) -> 0 | CS40: =(L40-K40)-(L39-K39) -> 0 | CT40: =(O40-N40)-(O39-N39) -> -0.46 | CU40: =(R40-Q40)-(R39-Q39) -> -3.95 | CV40: =(U40-T40)-(U39-T39) -> 0 | CW40: =(X40-W40)-(X39-W39) -> 0 | CX40: =(AA40-Z40)-(AA39-Z39) -> 0 | CY40: =(AD40-AC40)-(AD39-AC39) -> 0 | CZ40: =(AG40-AF40)-(AG39-AF39) -> 0 | DA40: =(AJ40-AI40)-(AJ39-AI39) -> 0 | DB40: =(AM40-AL40)-(AM39-AL39) -> 0 | DC40: =(AP40-AO40)-(AP39-AO39) -> 0 | DD40: =(AS40-AR40)-(AS39-AR39) -> 0 | DE40: =(AV40-AU40)-(AV39-AU39) -> 0 | DF40: =(AY40-AX40)-(AY39-AX39) -> 0 | DG40: =(BB40-BA40)-(BB39-BA39) -> 0 | DH40: =(BE40-BD40)-(BE39-BD39) -> 0 | DI40: =(BH40-BG40)-(BH39-BG39) -> 0 | DJ40: =(BK40-BJ40)-(BK39-BJ39) -> 0 | DK40: =(BN40-BM40)-(BN39-BM39) -> 0
A41: 45535 | B41: 734.92 | C41: 803.38 | D41: =(C41-B41)/B41 -> 0.093152996 | E41: 39.94 | F41: 40.63 | G41: =(F41-E41)/E41 -> 0.017275914 | H41: 0 | I41: 0 | J41: 0 | K41: 0 | L41: 0 | M41: 0 | N41: 100 | O41: 104.42 | P41: =(O41-N41)/N41 -> 0.0442 | Q41: 200 | R41: 211.23 | S41: =(R41-Q41)/Q41 -> 0.05615 | T41: 0 | U41: 0 | V41: 0 | W41: 0 | X41: 0 | Y41: 0 | Z41: 0 | AA41: 0 | AB41: 0 | AC41: 0 | AD41: 0 | AE41: 0 | AF41: 0 | AG41: 0 | AH41: 0 | AI41: 0 | AJ41: 0 | AK41: 0 | AL41: 0 | AM41: 0 | AN41: 0 | AO41: 0 | AP41: 0 | AQ41: 0 | AR41: 0 | AS41: 0 | AT41: 0 | AU41: 0 | AV41: 0 | AW41: 0 | AX41: 0 | AY41: 0 | AZ41: 0 | BA41: 0 | BB41: 0 | BC41: 0 | BD41: 0 | BE41: 0 | BF41: 0 | BG41: 0 | BH41: 0 | BI41: 0 | BJ41: 0 | BK41: 0 | BL41: 0 | BM41: 0 | BN41: 0 | BO41: 0 | BQ41: =A41 -> 45535 | BR41: =B41+E41+H41+K41+N41+Q41 -> 1074.86 | BS41: =BR41-BR40 -> 25 | BT41: =C41+F41+I41+L41+O41+R41 -> 1159.66 | BU41: =BT41-BR41 -> 84.8 | BV41: =BU41/BR41 -> 0.078893995 | BW41: =BU41-BU40 -> 8 | BY41: =A41 -> 45535 | BZ41: =Z41+T41+AC41+W41+AR41+AF41+AI41+AL41+AO41+AU41+AX41+BA41+BD41+BG41+BJ41+BM41 -> 0 | CA41: =BZ41-BZ40 -> 0 | CB41: =AA41+U41+AD41+X41+AS41+AG41+AJ41+AM41+AP41+AV41+AY41+BB41+BE41+BG41+BK41+BM41 -> 0 | CC41: =CB41-BZ41 -> 0 | CD41: 0 | CE41: =CC41-CC40 -> 0 | CG41: =A41 -> 45535 | CH41: =BR41+BZ41 -> 1074.86 | CI41: =BS41+CA41 -> 25 | CJ41: =BT41+CB41 -> 1159.66 | CK41: =CJ41-CH41 -> 84.8 | CL41: 0 | CM41: =CK41-CK40 -> 8 | CO41: =A41 -> 45535 | CP41: =(C41-B41)-(C40-B40) -> 13.63 | CQ41: =(F41-E41)-(F40-E40) -> -0.15 | CR41: =(I41-H41)-(I40-H40) -> 0 | CS41: =(L41-K41)-(L40-K40) -> 0 | CT41: =(O41-N41)-(O40-N40) -> -0.95 | CU41: =(R41-Q41)-(R40-Q40) -> -4.53 | CV41: =(U41-T41)-(U40-T40) -> 0 | CW41: =(X41-W41)-(X40-W40) -> 0 | CX41: =(AA41-Z41)-(AA40-Z40) -> 0 | CY41: =(AD41-AC41)-(AD40-AC40) -> 0 | CZ41: =(AG41-AF41)-(AG40-AF40) -> 0 | DA41: =(AJ41-AI41)-(AJ40-AI40) -> 0 | DB41: =(AM41-AL41)-(AM40-AL40) -> 0 | DC41: =(AP41-AO41)-(AP40-AO40) -> 0 | DD41: =(AS41-AR41)-(AS40-AR40) -> 0 | DE41: =(AV41-AU41)-(AV40-AU40) -> 0 | DF41: =(AY41-AX41)-(AY40-AX40) -> 0 | DG41: =(BB41-BA41)-(BB40-BA40) -> 0 | DH41: =(BE41-BD41)-(BE40-BD40) -> 0 | DI41: =(BH41-BG41)-(BH40-BG40) -> 0 | DJ41: =(BK41-BJ41)-(BK40-BJ40) -> 0 | DK41: =(BN41-BM41)-(BN40-BM40) -> 0
A42: 45565 | B42: 749.92 | C42: 830.93 | D42: =(C42-B42)/B42 -> 0.10802486 | E42: 39.94 | F42: 41.18 | G42: =(F42-E42)/E42 -> 0.03104657 | H42: 0 | I42: 0 | J42: 0 | K42: 0 | L42: 0 | M42: 0 | N42: 100 | O42: 104.67 | P42: =(O42-N42)/N42 -> 0.0467 | Q42: 200 | R42: 223.06 | S42: =(R42-Q42)/Q42 -> 0.1153 | T42: 0 | U42: 0 | V42: 0 | W42: 0 | X42: 0 | Y42: 0 | Z42: 0 | AA42: 0 | AB42: 0 | AC42: 0 | AD42: 0 | AE42: 0 | AF42: 0 | AG42: 0 | AH42: 0 | AI42: 0 | AJ42: 0 | AK42: 0 | AL42: 0 | AM42: 0 | AN42: 0 | AO42: 0 | AP42: 0 | AQ42: 0 | AR42: 0 | AS42: 0 | AT42: 0 | AU42: 0 | AV42: 0 | AW42: 0 | AX42: 0 | AY42: 0 | AZ42: 0 | BA42: 0 | BB42: 0 | BC42: 0 | BD42: 0 | BE42: 0 | BF42: 0 | BG42: 0 | BH42: 0 | BI42: 0 | BJ42: 0 | BK42: 0 | BL42: 0 | BM42: 0 | BN42: 0 | BO42: 0 | BQ42: =A42 -> 45565 | BR42: =B42+E42+H42+K42+N42+Q42 -> 1089.86 | BS42: =BR42-BR41 -> 15 | BT42: =C42+F42+I42+L42+O42+R42 -> 1199.84 | BU42: =BT42-BR42 -> 109.98 | BV42: =BU42/BR42 -> 0.10091204 | BW42: =BU42-BU41 -> 25.18 | BY42: =A42 -> 45565 | BZ42: =Z42+T42+AC42+W42+AR42+AF42+AI42+AL42+AO42+AU42+AX42+BA42+BD42+BG42+BJ42+BM42 -> 0 | CA42: =BZ42-BZ41 -> 0 | CB42: =AA42+U42+AD42+X42+AS42+AG42+AJ42+AM42+AP42+AV42+AY42+BB42+BE42+BG42+BK42+BM42 -> 0 | CC42: =CB42-BZ42 -> 0 | CD42: 0 | CE42: =CC42-CC41 -> 0 | CG42: =A42 -> 45565 | CH42: =BR42+BZ42 -> 1089.86 | CI42: =BS42+CA42 -> 15 | CJ42: =BT42+CB42 -> 1199.84 | CK42: =CJ42-CH42 -> 109.98 | CL42: 0 | CM42: =CK42-CK41 -> 25.18 | CO42: =A42 -> 45565 | CP42: =(C42-B42)-(C41-B41) -> 12.55 | CQ42: =(F42-E42)-(F41-E41) -> 0.55 | CR42: =(I42-H42)-(I41-H41) -> 0 | CS42: =(L42-K42)-(L41-K41) -> 0 | CT42: =(O42-N42)-(O41-N41) -> 0.25 | CU42: =(R42-Q42)-(R41-Q41) -> 11.83 | CV42: =(U42-T42)-(U41-T41) -> 0 | CW42: =(X42-W42)-(X41-W41) -> 0 | CX42: =(AA42-Z42)-(AA41-Z41) -> 0 | CY42: =(AD42-AC42)-(AD41-AC41) -> 0 | CZ42: =(AG42-AF42)-(AG41-AF41) -> 0 | DA42: =(AJ42-AI42)-(AJ41-AI41) -> 0 | DB42: =(AM42-AL42)-(AM41-AL41) -> 0 | DC42: =(AP42-AO42)-(AP41-AO41) -> 0 | DD42: =(AS42-AR42)-(AS41-AR41) -> 0 | DE42: =(AV42-AU42)-(AV41-AU41) -> 0 | DF42: =(AY42-AX42)-(AY41-AX41) -> 0 | DG42: =(BB42-BA42)-(BB41-BA41) -> 0 | DH42: =(BE42-BD42)-(BE41-BD41) -> 0 | DI42: =(BH42-BG42)-(BH41-BG41) -> 0 | DJ42: =(BK42-BJ42)-(BK41-BJ41) -> 0 | DK42: =(BN42-BM42)-(BN41-BM41) -> 0
A43: 45596 | B43: 784.92 | C43: 866.75 | D43: =(C43-B43)/B43 -> 0.10425266 | E43: 39.94 | F43: 40.65 | G43: =(F43-E43)/E43 -> 0.017776665 | H43: 0 | I43: 0 | J43: 0 | K43: 0 | L43: 0 | M43: 0 | N43: 100 | O43: 106.37 | P43: =(O43-N43)/N43 -> 0.0637 | Q43: 200 | R43: 234.77 | S43: =(R43-Q43)/Q43 -> 0.17385 | T43: 0 | U43: 0 | V43: 0 | W43: 0 | X43: 0 | Y43: 0 | Z43: 0 | AA43: 0 | AB43: 0 | AC43: 0 | AD43: 0 | AE43: 0 | AF43: 0 | AG43: 0 | AH43: 0 | AI43: 0 | AJ43: 0 | AK43: 0 | AL43: 0 | AM43: 0 | AN43: 0 | AO43: 0 | AP43: 0 | AQ43: 0 | AR43: 0 | AS43: 0 | AT43: 0 | AU43: 0 | AV43: 0 | AW43: 0 | AX43: 0 | AY43: 0 | AZ43: 0 | BA43: 0 | BB43: 0 | BC43: 0 | BD43: 0 | BE43: 0 | BF43: 0 | BG43: 0 | BH43: 0 | BI43: 0 | BJ43: 0 | BK43: 0 | BL43: 0 | BM43: 0 | BN43: 0 | BO43: 0 | BQ43: =A43 -> 45596 | BR43: =B43+E43+H43+K43+N43+Q43 -> 1124.86 | BS43: =BR43-BR42 -> 35 | BT43: =C43+F43+I43+L43+O43+R43 -> 1248.54 | BU43: =BT43-BR43 -> 123.68 | BV43: =BU43/BR43 -> 0.10995146 | BW43: =BU43-BU42 -> 13.7 | BY43: =A43 -> 45596 | BZ43: =Z43+T43+AC43+W43+AR43+AF43+AI43+AL43+AO43+AU43+AX43+BA43+BD43+BG43+BJ43+BM43 -> 0 | CA43: =BZ43-BZ42 -> 0 | CB43: =AA43+U43+AD43+X43+AS43+AG43+AJ43+AM43+AP43+AV43+AY43+BB43+BE43+BG43+BK43+BM43 -> 0 | CC43: =CB43-BZ43 -> 0 | CD43: 0 | CE43: =CC43-CC42 -> 0 | CG43: =A43 -> 45596 | CH43: =BR43+BZ43 -> 1124.86 | CI43: =BS43+CA43 -> 35 | CJ43: =BT43+CB43 -> 1248.54 | CK43: =CJ43-CH43 -> 123.68 | CL43: 0 | CM43: =CK43-CK42 -> 13.7 | CO43: =A43 -> 45596 | CP43: =(C43-B43)-(C42-B42) -> 0.82 | CQ43: =(F43-E43)-(F42-E42) -> -0.53 | CR43: =(I43-H43)-(I42-H42) -> 0 | CS43: =(L43-K43)-(L42-K42) -> 0 | CT43: =(O43-N43)-(O42-N42) -> 1.7 | CU43: =(R43-Q43)-(R42-Q42) -> 11.71 | CV43: =(U43-T43)-(U42-T42) -> 0 | CW43: =(X43-W43)-(X42-W42) -> 0 | CX43: =(AA43-Z43)-(AA42-Z42) -> 0 | CY43: =(AD43-AC43)-(AD42-AC42) -> 0 | CZ43: =(AG43-AF43)-(AG42-AF42) -> 0 | DA43: =(AJ43-AI43)-(AJ42-AI42) -> 0 | DB43: =(AM43-AL43)-(AM42-AL42) -> 0 | DC43: =(AP43-AO43)-(AP42-AO42) -> 0 | DD43: =(AS43-AR43)-(AS42-AR42) -> 0 | DE43: =(AV43-AU43)-(AV42-AU42) -> 0 | DF43: =(AY43-AX43)-(AY42-AX42) -> 0 | DG43: =(BB43-BA43)-(BB42-BA42) -> 0 | DH43: =(BE43-BD43)-(BE42-BD42) -> 0 | DI43: =(BH43-BG43)-(BH42-BG42) -> 0 | DJ43: =(BK43-BJ43)-(BK42-BJ42) -> 0 | DK43: =(BN43-BM43)-(BN42-BM42) -> 0
A44: 45626 | B44: 829.92 | C44: 925.59 | D44: =(C44-B44)/B44 -> 0.11527617 | E44: 59.92 | F44: 62.54 | G44: =(F44-E44)/E44 -> 0.043724967 | H44: 0 | I44: 0 | J44: 0 | K44: 0 | L44: 0 | M44: 0 | N44: 100 | O44: 111.48 | P44: =(O44-N44)/N44 -> 0.1148 | Q44: 250 | R44: 293.73 | S44: =(R44-Q44)/Q44 -> 0.17492 | T44: 0 | U44: 0 | V44: 0 | W44: 0 | X44: 0 | Y44: 0 | Z44: 0 | AA44: 0 | AB44: 0 | AC44: 0 | AD44: 0 | AE44: 0 | AF44: 0 | AG44: 0 | AH44: 0 | AI44: 0 | AJ44: 0 | AK44: 0 | AL44: 0 | AM44: 0 | AN44: 0 | AO44: 0 | AP44: 0 | AQ44: 0 | AR44: 0 | AS44: 0 | AT44: 0 | AU44: 0 | AV44: 0 | AW44: 0 | AX44: 0 | AY44: 0 | AZ44: 0 | BA44: 0 | BB44: 0 | BC44: 0 | BD44: 0 | BE44: 0 | BF44: 0 | BG44: 0 | BH44: 0 | BI44: 0 | BJ44: 0 | BK44: 0 | BL44: 0 | BM44: 0 | BN44: 0 | BO44: 0 | BQ44: =A44 -> 45626 | BR44: =B44+E44+H44+K44+N44+Q44 -> 1239.84 | BS44: =BR44-BR43 -> 114.98 | BT44: =C44+F44+I44+L44+O44+R44 -> 1393.34 | BU44: =BT44-BR44 -> 153.5 | BV44: =BU44/BR44 -> 0.1238063 | BW44: =BU44-BU43 -> 29.82 | BY44: =A44 -> 45626 | BZ44: =Z44+T44+AC44+W44+AR44+AF44+AI44+AL44+AO44+AU44+AX44+BA44+BD44+BG44+BJ44+BM44 -> 0 | CA44: =BZ44-BZ43 -> 0 | CB44: =AA44+U44+AD44+X44+AS44+AG44+AJ44+AM44+AP44+AV44+AY44+BB44+BE44+BG44+BK44+BM44 -> 0 | CC44: =CB44-BZ44 -> 0 | CD44: 0 | CE44: =CC44-CC43 -> 0 | CG44: =A44 -> 45626 | CH44: =BR44+BZ44 -> 1239.84 | CI44: =BS44+CA44 -> 114.98 | CJ44: =BT44+CB44 -> 1393.34 | CK44: =CJ44-CH44 -> 153.5 | CL44: 0 | CM44: =CK44-CK43 -> 29.82 | CO44: =A44 -> 45626 | CP44: =(C44-B44)-(C43-B43) -> 13.84 | CQ44: =(F44-E44)-(F43-E43) -> 1.91 | CR44: =(I44-H44)-(I43-H43) -> 0 | CS44: =(L44-K44)-(L43-K43) -> 0 | CT44: =(O44-N44)-(O43-N43) -> 5.11 | CU44: =(R44-Q44)-(R43-Q43) -> 8.96 | CV44: =(U44-T44)-(U43-T43) -> 0 | CW44: =(X44-W44)-(X43-W43) -> 0 | CX44: =(AA44-Z44)-(AA43-Z43) -> 0 | CY44: =(AD44-AC44)-(AD43-AC43) -> 0 | CZ44: =(AG44-AF44)-(AG43-AF43) -> 0 | DA44: =(AJ44-AI44)-(AJ43-AI43) -> 0 | DB44: =(AM44-AL44)-(AM43-AL43) -> 0 | DC44: =(AP44-AO44)-(AP43-AO43) -> 0 | DD44: =(AS44-AR44)-(AS43-AR43) -> 0 | DE44: =(AV44-AU44)-(AV43-AU43) -> 0 | DF44: =(AY44-AX44)-(AY43-AX43) -> 0 | DG44: =(BB44-BA44)-(BB43-BA43) -> 0 | DH44: =(BE44-BD44)-(BE43-BD43) -> 0 | DI44: =(BH44-BG44)-(BH43-BG43) -> 0 | DJ44: =(BK44-BJ44)-(BK43-BJ43) -> 0 | DK44: =(BN44-BM44)-(BN43-BM43) -> 0
