Workbook

Sheet Overview
A1: Paskola | I1: Pabaiga | M1: Grąžinta | Q1: Pinigai | U1: Grąžinta | W1: Vertė | AA1: Mokesčiai
A2: Nr. | B2: Inv. data | C2: Pavadinimas | D2: Šalis | E2: Tipas | F2: Terminas | G2: % | H2: Investuota | I2: Planuojama | J2: Reali | K2: Liko | L2: Vėluoja | M2: Paskola | N2: Palūkanos | O2: Mokesčiai | Q2: Įnešta | R2: Investuota | S2: Premijos | T2: Gryni | U2: Paskola | V2: Palūkanos | W2: Viso | X2: Eur. | Y2: % | Z2: XIRR | AA2: Eur. | AC2: Vėluoja
A3: 1 | B3: =LVX0000P9SY1!B9 -> 45909 | C3: =LVX0000P9SY1!B1 -> LVX0000P9SY1 | D3: =LVX0000P9SY1!B2 -> Romania | E3: =LVX0000P9SY1!B4 -> Pesonal | F3: =LVX0000P9SY1!B8 -> 0 m. 11 mėn. 16 d. | G3: =LVX0000P9SY1!B15 -> 0.125 | H3: =LVX0000P9SY1!B16 -> 50 | I3: =LVX0000P9SY1!B11 -> 46259 | J3: =LVX0000P9SY1!O3 | K3: =LVX0000P9SY1!B12 -> -36 | L3: =LVX0000P9SY1!P3 -> 36 | M3: =LVX0000P9SY1!K3 -> 49.99 | N3: =LVX0000P9SY1!L3 -> 1.9 | O3: =LVX0000P9SY1!M3 -> 0.11 | Q3: =Pinigai!I2 -> 320 | R3: =SUM(H3:H100)-U3 -> 352.87 | S3: =Pinigai!H2 -> 2.71 | T3: =W3-R3 -> 1.07 | U3: =SUM(M3:M100) -> 590.9 | V3: =SUM(N3:N100)-AA3 -> 31.23 | W3: =Q3+V3+S3 -> 353.94 | X3: =W3-Q3 -> 33.94 | Y3: =(W3-Q3)/Q3 -> 0.1060625 | Z3: =XIRR(Pinigai!K2:K200,Pinigai!A2:A200) -> 0.12527701 | AA3: =SUM(O3:O100) -> 1.4 | AC3: =LVX0000P9SY1!Z3 -> +
A4: 2 | B4: =LVX0000PFLZ9!B9 -> 45918 | C4: =LVX0000PFLZ9!B1 -> LVX0000PFLZ9 | D4: =LVX0000PFLZ9!B2 -> Romania | E4: =LVX0000PFLZ9!B4 -> Pesonal | F4: =LVX0000PFLZ9!B8 -> 0 m. 11 mėn. 21 d. | G4: =LVX0000PFLZ9!B15 -> 0.125 | H4: =LVX0000PFLZ9!B16 -> 53.9 | I4: =LVX0000PFLZ9!B11 -> 46273 | J4: =LVX0000PFLZ9!O3 -> 46271 | K4: =LVX0000PFLZ9!B12 | L4: =LVX0000PFLZ9!P3 | M4: =LVX0000PFLZ9!K3 -> 53.9 | N4: =LVX0000PFLZ9!L3 -> 3.07 | O4: =LVX0000PFLZ9!M3 -> 0.15 | AC4: =LVX0000PFLZ9!Z3
A5: 3 | B5: =LVX0000PLPE3!B9 -> 45934 | C5: =LVX0000PLPE3!B1 -> LVX0000PLPE3 | D5: =LVX0000PLPE3!B2 -> Cyprus | E5: =LVX0000PLPE3!B4 -> Business | F5: =LVX0000PLPE3!B8 -> 0 m. 8 mėn. 19 d. | G5: =LVX0000PLPE3!B15 -> 0.12 | H5: =LVX0000PLPE3!B16 -> 13.66 | I5: =LVX0000PLPE3!B11 -> 46196 | J5: =LVX0000PLPE3!O3 -> 46234 | K5: =LVX0000PLPE3!B12 | L5: =LVX0000PLPE3!P3 | M5: =LVX0000PLPE3!K3 -> 13.66 | N5: =LVX0000PLPE3!L3 -> 1.23 | O5: =LVX0000PLPE3!M3 -> 0.06 | AC5: =LVX0000PLPE3!Z3
A6: 4 | B6: =LVX0000PQRD0!B9 -> 45938 | C6: =LVX0000PQRD0!B1 -> LVX0000PQRD0 | D6: =LVX0000PQRD0!B2 -> Moldova | E6: =LVX0000PQRD0!B4 -> Business | F6: =LVX0000PQRD0!B8 -> 0 m. 5 mėn. 23 d. | G6: =LVX0000PQRD0!B15 -> 0.13 | H6: =LVX0000PQRD0!B16 -> 11.35 | I6: =LVX0000PQRD0!B11 -> 46112 | J6: =LVX0000PQRD0!O3 -> 46115 | K6: =LVX0000PQRD0!B12 | L6: =LVX0000PQRD0!P3 | M6: =LVX0000PQRD0!K3 -> 11.35 | N6: =LVX0000PQRD0!L3 -> 0.72 | O6: =LVX0000PQRD0!M3 -> 0.04 | AC6: =LVX0000PQRD0!Z3
A7: 5 | B7: =LVX0000PLQM4!B9 -> 45947 | C7: =LVX0000PLQM4!B1 -> LVX0000PLQM4 | D7: =LVX0000PLQM4!B2 -> Romania | E7: =LVX0000PLQM4!B4 -> Business | F7: =LVX0000PLQM4!B8 -> 0 m. 8 mėn. 5 d. | G7: =LVX0000PLQM4!B15 -> 0.12 | H7: =LVX0000PLQM4!B16 -> 13.86 | I7: =LVX0000PLQM4!B11 -> 46195 | J7: =LVX0000PLQM4!O3 -> 46234 | K7: =LVX0000PLQM4!B12 | L7: =LVX0000PLQM4!P3 | M7: =LVX0000PLQM4!K3 -> 13.86 | N7: =LVX0000PLQM4!L3 -> 1.12 | O7: =LVX0000PLQM4!M3 -> 0.06 | AC7: =LVX0000PLQM4!Z3
A8: 6 | B8: =LVX0000PQUM5!B9 -> 45947 | C8: =LVX0000PQUM5!B1 -> LVX0000PQUM5 | D8: =LVX0000PQUM5!B2 -> Cyprus | E8: =LVX0000PQUM5!B4 -> Business | F8: =LVX0000PQUM5!B8 -> 0 m. 5 mėn. 14 d. | G8: =LVX0000PQUM5!B15 -> 0.12 | H8: =LVX0000PQUM5!B16 -> 10 | I8: =LVX0000PQUM5!B11 -> 46112 | J8: =LVX0000PQUM5!O3 -> 46120 | K8: =LVX0000PQUM5!B12 | L8: =LVX0000PQUM5!P3 | M8: =LVX0000PQUM5!K3 -> 10 | N8: =LVX0000PQUM5!L3 -> 0.57 | O8: =LVX0000PQUM5!M3 -> 0.03 | AC8: =LVX0000PQUM5!Z3
A9: 7 | B9: =LVX0000Q7QJ9!B9 -> 45958 | C9: =LVX0000Q7QJ9!B1 -> LVX0000Q7QJ9 | D9: =LVX0000Q7QJ9!B2 -> Romania | E9: =LVX0000Q7QJ9!B4 -> Pesonal | F9: =LVX0000Q7QJ9!B8 -> 1 m. 8 mėn. 19 d. | G9: =LVX0000Q7QJ9!B15 -> 0.125 | H9: =LVX0000Q7QJ9!B16 -> 25.71 | I9: =LVX0000Q7QJ9!B11 -> 46585 | J9: =LVX0000Q7QJ9!O3 -> 46053 | K9: =LVX0000Q7QJ9!B12 | L9: =LVX0000Q7QJ9!P3 | M9: =LVX0000Q7QJ9!K3 -> 25.71 | N9: =LVX0000Q7QJ9!L3 -> 0.29 | O9: =LVX0000Q7QJ9!M3 -> 0.01 | AC9: =LVX0000Q7QJ9!Z3
A10: 8 | B10: =LVX0000PQUR4!B9 -> 45962 | C10: =LVX0000PQUR4!B1 -> LVX0000PQUR4 | D10: =LVX0000PQUR4!B2 -> Philippines | E10: =LVX0000PQUR4!B4 -> Business | F10: =LVX0000PQUR4!B8 -> 0 m. 2 mėn. 29 d. | G10: =LVX0000PQUR4!B15 -> 0.115 | H10: =LVX0000PQUR4!B16 -> 10 | I10: =LVX0000PQUR4!B11 -> 46052 | J10: =LVX0000PQUR4!O3 -> 46064 | K10: =LVX0000PQUR4!B12 | L10: =LVX0000PQUR4!P3 | M10: =LVX0000PQUR4!K3 -> 10 | N10: =LVX0000PQUR4!L3 -> 0.32 | O10: =LVX0000PQUR4!M3 -> 0.01 | AC10: =LVX0000PQUR4!Z3
A11: 9 | B11: =LVX0000Q0ED3!B9 -> 45962 | C11: =LVX0000Q0ED3!B1 -> LVX0000Q0ED3 | D11: =LVX0000Q0ED3!B2 -> Romania | E11: =LVX0000Q0ED3!B4 -> Business | F11: =LVX0000Q0ED3!B8 -> 0 m. 5 mėn. 14 d. | G11: =LVX0000Q0ED3!B15 -> 0.12 | H11: =LVX0000Q0ED3!B16 -> 17.46 | I11: =LVX0000Q0ED3!B11 -> 46127 | J11: =LVX0000Q0ED3!O3 -> 46130 | K11: =LVX0000Q0ED3!B12 | L11: =LVX0000Q0ED3!P3 | M11: =LVX0000Q0ED3!K3 -> 17.46 | N11: =LVX0000Q0ED3!L3 -> 0.97 | O11: =LVX0000Q0ED3!M3 -> 0.05 | AC11: =LVX0000Q0ED3!Z3
A12: 10 | B12: =LVX0000PQUG7!B9 -> 45971 | C12: =LVX0000PQUG7!B1 -> LVX0000PQUG7 | D12: =LVX0000PQUG7!B2 -> Romania | E12: =LVX0000PQUG7!B4 -> Business | F12: =LVX0000PQUG7!B8 -> 0 m. 4 mėn. 21 d. | G12: =LVX0000PQUG7!B15 -> 0.12 | H12: =LVX0000PQUG7!B16 -> 17.67 | I12: =LVX0000PQUG7!B11 -> 46112 | J12: =LVX0000PQUG7!O3 -> 46142 | K12: =LVX0000PQUG7!B12 | L12: =LVX0000PQUG7!P3 | M12: =LVX0000PQUG7!K3 -> 17.67 | N12: =LVX0000PQUG7!L3 -> 0.78 | O12: =LVX0000PQUG7!M3 -> 0.04 | AC12: =LVX0000PQUG7!Z3
A13: 11 | B13: =LVX0000Q0E27!B9 -> 45981 | C13: =LVX0000Q0E27!B1 -> LVX0000Q0E27 | D13: =LVX0000Q0E27!B2 -> Cyprus | E13: =LVX0000Q0E27!B4 -> Business | F13: =LVX0000Q0E27!B8 -> 0 m. 4 mėn. 25 d. | G13: =LVX0000Q0E27!B15 -> 0.12 | H13: =LVX0000Q0E27!B16 -> 12.74 | I13: =LVX0000Q0E27!B11 -> 46126 | J13: =LVX0000Q0E27!O3 -> 46129 | K13: =LVX0000Q0E27!B12 | L13: =LVX0000Q0E27!P3 | M13: =LVX0000Q0E27!K3 -> 12.74 | N13: =LVX0000Q0E27!L3 -> 0.62 | O13: =LVX0000Q0E27!M3 -> 0.03 | AC13: =LVX0000Q0E27!Z3
A14: 12 | B14: =LVX0000QBKH6!B9 -> 45985 | C14: =LVX0000QBKH6!B1 -> LVX0000QBKH6 | D14: =LVX0000QBKH6!B2 -> Moldova | E14: =LVX0000QBKH6!B4 -> Business | F14: =LVX0000QBKH6!B8 -> 0 m. 5 mėn. 4 d. | G14: =LVX0000QBKH6!B15 -> 0.13 | H14: =LVX0000QBKH6!B16 -> 13.25 | I14: =LVX0000QBKH6!B11 -> 46140 | J14: =LVX0000QBKH6!O3 -> 46135 | K14: =LVX0000QBKH6!B12 | L14: =LVX0000QBKH6!P3 | M14: =LVX0000QBKH6!K3 -> 13.25 | N14: =LVX0000QBKH6!L3 -> 0.71 | O14: =LVX0000QBKH6!M3 -> 0.03 | AC14: =LVX0000QBKH6!Z3
A15: 13 | B15: =LVX0000QSAL3!B9 -> 45996 | C15: =LVX0000QSAL3!B1 -> LVX0000QSAL3 | D15: =LVX0000QSAL3!B2 -> Cyprus | E15: =LVX0000QSAL3!B4 -> Business | F15: =LVX0000QSAL3!B8 -> 0 m. 8 mėn. 18 d. | G15: =LVX0000QSAL3!B15 -> 0.12 | H15: =LVX0000QSAL3!B16 -> 14.43 | I15: =LVX0000QSAL3!B11 -> 46257 | J15: =LVX0000QSAL3!O3 -> 46295 | K15: =LVX0000QSAL3!B12 | L15: =LVX0000QSAL3!P3 | M15: =LVX0000QSAL3!K3 -> 14.43 | N15: =LVX0000QSAL3!L3 -> 1.26 | O15: =LVX0000QSAL3!M3 -> 0.05 | AC15: =LVX0000QSAL3!Z3
A16: 14 | B16: =LVX0000R31L6!B9 -> 46003 | C16: =LVX0000R31L6!B1 -> LVX0000R31L6 | D16: =LVX0000R31L6!B2 -> Romania | E16: =LVX0000R31L6!B4 -> Business | F16: =LVX0000R31L6!B8 -> 0 m. 8 mėn. 26 d. | G16: =LVX0000R31L6!B15 -> 0.12 | H16: =LVX0000R31L6!B16 -> 16.45 | I16: =LVX0000R31L6!B11 -> 46272 | J16: =LVX0000R31L6!O3 -> 46265 | K16: =LVX0000R31L6!B12 | L16: =LVX0000R31L6!P3 | M16: =LVX0000R31L6!K3 -> 16.45 | N16: =LVX0000R31L6!L3 -> 1.21 | O16: =LVX0000R31L6!M3 -> 0.04 | AC16: =LVX0000R31L6!Z3
A17: 15 | B17: =LVX0000R32A7!B9 -> 46004 | C17: =LVX0000R32A7!B1 -> LVX0000R32A7 | D17: =LVX0000R32A7!B2 -> Moldova | E17: =LVX0000R32A7!B4 -> Business | F17: =LVX0000R32A7!B8 -> 0 m. 8 mėn. 25 d. | G17: =LVX0000R32A7!B15 -> 0.125 | H17: =LVX0000R32A7!B16 -> 10.58 | I17: =LVX0000R32A7!B11 -> 46272 | J17: =LVX0000R32A7!O3 -> 46295 | K17: =LVX0000R32A7!B12 | L17: =LVX0000R32A7!P3 | M17: =LVX0000R32A7!K3 -> 10.58 | N17: =LVX0000R32A7!L3 -> 0.94 | O17: =LVX0000R32A7!M3 -> 0.04 | AC17: =LVX0000R32A7!Z3
A18: 16 | B18: =LVX0000RAL27!B9 -> 46015 | C18: =LVX0000RAL27!B1 -> LVX0000RAL27 | D18: =LVX0000RAL27!B2 -> Latvia | E18: =LVX0000RAL27!B4 -> Business | F18: =LVX0000RAL27!B8 -> 0 m. 3 mėn. 24 d. | G18: =LVX0000RAL27!B15 -> 0.11 | H18: =LVX0000RAL27!B16 -> 12.36 | I18: =LVX0000RAL27!B11 -> 46129 | J18: =LVX0000RAL27!O3 -> 46129 | K18: =LVX0000RAL27!B12 | L18: =LVX0000RAL27!P3 | M18: =LVX0000RAL27!K3 -> 12.36 | N18: =LVX0000RAL27!L3 -> 0.42 | O18: =LVX0000RAL27!M3 -> 0.02 | AC18: =LVX0000RAL27!Z3
A19: 17 | B19: =LVX0000RAM67!B9 -> 46024 | C19: =LVX0000RAM67!B1 -> LVX0000RAM67 | D19: =LVX0000RAM67!B2 -> Latvia | E19: =LVX0000RAM67!B4 -> Business | F19: =LVX0000RAM67!B8 -> 0 m. 3 mėn. 15 d. | G19: =LVX0000RAM67!B15 -> 0.11 | H19: =LVX0000RAM67!B16 -> 21.95 | I19: =LVX0000RAM67!B11 -> 46129 | J19: =LVX0000RAM67!O3 -> 46129 | K19: =LVX0000RAM67!B12 | L19: =LVX0000RAM67!P3 | M19: =LVX0000RAM67!K3 -> 21.95 | N19: =LVX0000RAM67!L3 -> 0.69 | O19: =LVX0000RAM67!M3 -> 0.03 | AC19: =LVX0000RAM67!Z3
A20: 18 | B20: =LVX0000R7P58!B9 -> 46029 | C20: =LVX0000R7P58!B1 -> LVX0000R7P58 | D20: =LVX0000R7P58!B2 -> Latvia | E20: =LVX0000R7P58!B4 -> Business | F20: =LVX0000R7P58!B8 -> 0 m. 3 mėn. 10 d. | G20: =LVX0000R7P58!B15 -> 0.11 | H20: =LVX0000R7P58!B16 -> 18.23 | I20: =LVX0000R7P58!B11 -> 46129 | J20: =LVX0000R7P58!O3 -> 46129 | K20: =LVX0000R7P58!B12 | L20: =LVX0000R7P58!P3 | M20: =LVX0000R7P58!K3 -> 18.23 | N20: =LVX0000R7P58!L3 -> 0.54 | O20: =LVX0000R7P58!M3 -> 0.03 | AC20: =LVX0000R7P58!Z3
A21: 19 | B21: =LVX0000RL9Y3!B9 -> 46032 | C21: =LVX0000RL9Y3!B1 -> LVX0000RL9Y3 | D21: =LVX0000RL9Y3!B2 -> Moldova | E21: =LVX0000RL9Y3!B4 -> Business | F21: =LVX0000RL9Y3!B8 -> 0 m. 3 mėn. 27 d. | G21: =LVX0000RL9Y3!B15 -> 0.115 | H21: =LVX0000RL9Y3!B16 -> 13.84 | I21: =LVX0000RL9Y3!B11 -> 46149 | J21: =LVX0000RL9Y3!O3 -> 46150 | K21: =LVX0000RL9Y3!B12 | L21: =LVX0000RL9Y3!P3 | M21: =LVX0000RL9Y3!K3 -> 13.84 | N21: =LVX0000RL9Y3!L3 -> 0.51 | O21: =LVX0000RL9Y3!M3 -> 0.03 | AC21: =LVX0000RL9Y3!Z3
A22: 20 | B22: =LVX0000RL9Z0!B9 -> 46037 | C22: =LVX0000RL9Z0!B1 -> LVX0000RL9Z0 | D22: =LVX0000RL9Z0!B2 -> Moldova | E22: =LVX0000RL9Z0!B4 -> Business | F22: =LVX0000RL9Z0!B8 -> 0 m. 5 mėn. 21 d. | G22: =LVX0000RL9Z0!B15 -> 0.12 | H22: =LVX0000RL9Z0!B16 -> 13.72 | I22: =LVX0000RL9Z0!B11 -> 46209 | J22: =LVX0000RL9Z0!O3 -> 46234 | K22: =LVX0000RL9Z0!B12 | L22: =LVX0000RL9Z0!P3 | M22: =LVX0000RL9Z0!K3 -> 13.72 | N22: =LVX0000RL9Z0!L3 -> 0.7 | O22: =LVX0000RL9Z0!M3 -> 0.04 | AC22: =LVX0000RL9Z0!Z3
A23: 21 | B23: =LVX0000RLA68!B9 -> 46050 | C23: =LVX0000RLA68!B1 -> LVX0000RLA68 | D23: =LVX0000RLA68!B2 -> Philippines | E23: =LVX0000RLA68!B4 -> Business | F23: =LVX0000RLA68!B8 -> 0 m. 3 mėn. 9 d. | G23: =LVX0000RLA68!B15 -> 0.11 | H23: =LVX0000RLA68!B16 -> 11.66 | I23: =LVX0000RLA68!B11 -> 46149 | J23: =LVX0000RLA68!O3 -> 46151 | K23: =LVX0000RLA68!B12 | L23: =LVX0000RLA68!P3 | M23: =LVX0000RLA68!K3 -> 11.66 | N23: =LVX0000RLA68!L3 -> 0.35 | O23: =LVX0000RLA68!M3 -> 0.02 | AC23: =LVX0000RLA68!Z3
A24: 22 | B24: =LVX0000RLA27!B9 -> 46064 | C24: =LVX0000RLA27!B1 -> LVX0000RLA27 | D24: =LVX0000RLA27!B2 -> Cyprus | E24: =LVX0000RLA27!B4 -> Business | F24: =LVX0000RLA27!B8 -> 0 m. 4 mėn. 25 d. | G24: =LVX0000RLA27!B15 -> 0.11 | H24: =LVX0000RLA27!B16 -> 14.08 | I24: =LVX0000RLA27!B11 -> 46209 | J24: =LVX0000RLA27!O3 -> 46265 | K24: =LVX0000RLA27!B12 | L24: =LVX0000RLA27!P3 | M24: =LVX0000RLA27!K3 -> 14.08 | N24: =LVX0000RLA27!L3 -> 0.66 | O24: =LVX0000RLA27!M3 -> 0.03 | AC24: =LVX0000RLA27!Z3
A25: 23 | B25: =LVX0000RXUV8!B9 -> 46079 | C25: =LVX0000RXUV8!B1 -> LVX0000RXUV8 | D25: =LVX0000RXUV8!B2 -> Romania | E25: =LVX0000RXUV8!B4 -> Business | F25: =LVX0000RXUV8!B8 -> 0 m. 4 mėn. 28 d. | G25: =LVX0000RXUV8!B15 -> 0.11 | H25: =LVX0000RXUV8!B16 -> 12.52 | I25: =LVX0000RXUV8!B11 -> 46227 | J25: =LVX0000RXUV8!O3 -> 46234 | K25: =LVX0000RXUV8!B12 | L25: =LVX0000RXUV8!P3 | M25: =LVX0000RXUV8!K3 -> 12.52 | N25: =LVX0000RXUV8!L3 -> 0.51 | O25: =LVX0000RXUV8!M3 -> 0.02 | AC25: =LVX0000RXUV8!Z3
A26: 24 | B26: =LVX0000SIO33!B9 -> 46094 | C26: =LVX0000SIO33!B1 -> LVX0000SIO33 | D26: =LVX0000SIO33!B2 -> Moldova | E26: =LVX0000SIO33!B4 -> Business | F26: =LVX0000SIO33!B8 -> 0 m. 5 mėn. 5 d. | G26: =LVX0000SIO33!B15 -> 0.12 | H26: =LVX0000SIO33!B16 -> 10.74 | I26: =LVX0000SIO33!B11 -> 46252 | J26: =LVX0000SIO33!O3 -> 46234 | K26: =LVX0000SIO33!B12 | L26: =LVX0000SIO33!P3 | M26: =LVX0000SIO33!K3 -> 10.74 | N26: =LVX0000SIO33!L3 -> 0.42 | O26: =LVX0000SIO33!M3 -> 0.01 | AC26: =LVX0000SIO33!Z3
A27: 25 | B27: =LVX0000T2IU1!B9 -> 46106 | C27: =LVX0000T2IU1!B1 -> LVX0000T2IU1 | D27: =LVX0000T2IU1!B2 -> Cyprus | E27: =LVX0000T2IU1!B4 -> Business | F27: =LVX0000T2IU1!B8 -> 1 m. 3 mėn. 0 d. | G27: =LVX0000T2IU1!B15 -> 0.125 | H27: =LVX0000T2IU1!B16 -> 18.62 | I27: =LVX0000T2IU1!B11 -> 46563 | J27: =LVX0000T2IU1!O3 | K27: =LVX0000T2IU1!B12 -> 268 | L27: =LVX0000T2IU1!P3 | M27: =LVX0000T2IU1!K3 -> 0 | N27: =LVX0000T2IU1!L3 -> 1.09 | O27: =LVX0000T2IU1!M3 -> 0.05 | AC27: =LVX0000T2IU1!Z3
A28: 26 | B28: =LVX0000T2IT3!B9 -> 46115 | C28: =LVX0000T2IT3!B1 -> LVX0000T2IT3 | D28: =LVX0000T2IT3!B2 -> Cyprus | E28: =LVX0000T2IT3!B4 -> Business | F28: =LVX0000T2IT3!B8 -> 0 m. 11 mėn. 29 d. | G28: =LVX0000T2IT3!B15 -> 0.12 | H28: =LVX0000T2IT3!B16 -> 14.01 | I28: =LVX0000T2IT3!B11 -> 46478 | J28: =LVX0000T2IT3!O3 | K28: =LVX0000T2IT3!B12 -> 183 | L28: =LVX0000T2IT3!P3 | M28: =LVX0000T2IT3!K3 -> 0 | N28: =LVX0000T2IT3!L3 -> 0.74 | O28: =LVX0000T2IT3!M3 -> 0.03 | AC28: =LVX0000T2IT3!Z3
A29: 27 | B29: =LVX0000ST8W0!B9 -> 46120 | C29: =LVX0000ST8W0!B1 -> LVX0000ST8W0 | D29: =LVX0000ST8W0!B2 -> Moldova | E29: =LVX0000ST8W0!B4 -> Business | F29: =LVX0000ST8W0!B8 -> 0 m. 7 mėn. 22 d. | G29: =LVX0000ST8W0!B15 -> 0.125 | H29: =LVX0000ST8W0!B16 -> 11.15 | I29: =LVX0000ST8W0!B11 -> 46356 | J29: =LVX0000ST8W0!O3 | K29: =LVX0000ST8W0!B12 -> 61 | L29: =LVX0000ST8W0!P3 | M29: =LVX0000ST8W0!K3 -> 0 | N29: =LVX0000ST8W0!L3 -> 0.6 | O29: =LVX0000ST8W0!M3 -> 0.01 | AC29: =LVX0000ST8W0!Z3
A30: 28 | B30: =LVX0000TJMX6!B9 -> 46129 | C30: =LVX0000TJMX6!B1 -> LVX0000TJMX6 | D30: =LVX0000TJMX6!B2 -> Romania | E30: =LVX0000TJMX6!B4 -> Personal | F30: =LVX0000TJMX6!B8 -> 0 m. 10 mėn. 20 d. | G30: =LVX0000TJMX6!B15 -> 0.125 | H30: =LVX0000TJMX6!B16 -> 31.84 | I30: =LVX0000TJMX6!B11 -> 46455 | J30: =LVX0000TJMX6!O3 | K30: =LVX0000TJMX6!B12 -> 160 | L30: =LVX0000TJMX6!P3 | M30: =LVX0000TJMX6!K3 -> 20.99 | N30: =LVX0000TJMX6!L3 -> 1.26 | O30: =LVX0000TJMX6!M3 -> 0.06 | AC30: =LVX0000TJMX6!Z3
A31: 29 | B31: =LVX0000TL6K6!B9 -> 46129 | C31: =LVX0000TL6K6!B1 -> LVX0000TL6K6 | D31: =LVX0000TL6K6!B2 -> Moldova | E31: =LVX0000TL6K6!B4 -> Business | F31: =LVX0000TL6K6!B8 -> 0 m. 6 mėn. 5 d. | G31: =LVX0000TL6K6!B15 -> 0.12 | H31: =LVX0000TL6K6!B16 -> 20 | I31: =LVX0000TL6K6!B11 -> 46317 | J31: =LVX0000TL6K6!O3 -> 46282 | K31: =LVX0000TL6K6!B12 | L31: =LVX0000TL6K6!P3 | M31: =LVX0000TL6K6!K3 -> 20 | N31: =LVX0000TL6K6!L3 -> 0.97 | O31: =LVX0000TL6K6!M3 -> 0.06 | AC31: =LVX0000TL6K6!Z3
A32: 30 | B32: =LVX0000TJR12!B9 -> 46129 | C32: =LVX0000TJR12!B1 -> LVX0000TJR12 | D32: =LVX0000TJR12!B2 -> Moldova | E32: =LVX0000TJR12!B4 -> Business | F32: =LVX0000TJR12!B8 -> 0 m. 8 mėn. 29 d. | G32: =LVX0000TJR12!B15 -> 0.125 | H32: =LVX0000TJR12!B16 -> 20 | I32: =LVX0000TJR12!B11 -> 46402 | J32: =LVX0000TJR12!O3 | K32: =LVX0000TJR12!B12 -> 107 | L32: =LVX0000TJR12!P3 | M32: =LVX0000TJR12!K3 -> 0 | N32: =LVX0000TJR12!L3 -> 1.01 | O32: =LVX0000TJR12!M3 -> 0.05 | AC32: =LVX0000TJR12!Z3
A33: 31 | B33: =LVX0000TJQV1!B9 -> 46130 | C33: =LVX0000TJQV1!B1 -> LVX0000TJQV1 | D33: =LVX0000TJQV1!B2 -> Romania | E33: =LVX0000TJQV1!B4 -> Business | F33: =LVX0000TJQV1!B8 -> 0 m. 8 mėn. 28 d. | G33: =LVX0000TJQV1!B15 -> 0.115 | H33: =LVX0000TJQV1!B16 -> 17.46 | I33: =LVX0000TJQV1!B11 -> 46402 | J33: =LVX0000TJQV1!O3 -> 46295 | K33: =LVX0000TJQV1!B12 | L33: =LVX0000TJQV1!P3 | M33: =LVX0000TJQV1!K3 -> 17.46 | N33: =LVX0000TJQV1!L3 -> 0.71 | O33: =LVX0000TJQV1!M3 -> 0.02 | AC33: =LVX0000TJQV1!Z3
A34: 32 | B34: =LVX0000TPE43!B9 -> 46135 | C34: =LVX0000TPE43!B1 -> LVX0000TPE43 | D34: =LVX0000TPE43!B2 -> Romania | E34: =LVX0000TPE43!B4 -> Business | F34: =LVX0000TPE43!B8 -> 0 m. 5 mėn. 28 d. | G34: =LVX0000TPE43!B15 -> 0.11 | H34: =LVX0000TPE43!B16 -> 13.66 | I34: =LVX0000TPE43!B11 -> 46316 | J34: =LVX0000TPE43!O3 -> 46295 | K34: =LVX0000TPE43!B12 | L34: =LVX0000TPE43!P3 | M34: =LVX0000TPE43!K3 -> 13.66 | N34: =LVX0000TPE43!L3 -> 0.52 | O34: =LVX0000TPE43!M3 -> 0.02 | AC34: =LVX0000TPE43!Z3
A35: 33 | B35: =LVX0000TRIW9!B9 -> 46150 | C35: =LVX0000TRIW9!B1 -> LVX0000TRIW9 | D35: =LVX0000TRIW9!B2 -> Moldova | E35: =LVX0000TRIW9!B4 -> Business | F35: =LVX0000TRIW9!B8 -> 0 m. 5 mėn. 12 d. | G35: =LVX0000TRIW9!B15 -> 0.12 | H35: =LVX0000TRIW9!B16 -> 14.87 | I35: =LVX0000TRIW9!B11 -> 46315 | J35: =LVX0000TRIW9!O3 -> 46282 | K35: =LVX0000TRIW9!B12 | L35: =LVX0000TRIW9!P3 | M35: =LVX0000TRIW9!K3 -> 14.87 | N35: =LVX0000TRIW9!L3 -> 0.62 | O35: =LVX0000TRIW9!M3 -> 0.04 | AC35: =LVX0000TRIW9!Z3
A36: 34 | B36: =LVX0000TRJ61!B9 -> 46151 | C36: =LVX0000TRJ61!B1 -> LVX0000TRJ61 | D36: =LVX0000TRJ61!B2 -> Philippines | E36: =LVX0000TRJ61!B4 -> Business | F36: =LVX0000TRJ61!B8 -> 0 m. 3 mėn. 22 d. | G36: =LVX0000TRJ61!B15 -> 0.11 | H36: =LVX0000TRJ61!B16 -> 11.66 | I36: =LVX0000TRJ61!B11 -> 46265 | J36: =LVX0000TRJ61!O3 -> 46295 | K36: =LVX0000TRJ61!B12 | L36: =LVX0000TRJ61!P3 | M36: =LVX0000TRJ61!K3 -> 11.66 | N36: =LVX0000TRJ61!L3 -> 0.38 | O36: =LVX0000TRJ61!M3 -> 0.02 | AC36: =LVX0000TRJ61!Z3
A37: 35 | B37: =LVX0000U4UG8!B9 -> 46157 | C37: =LVX0000U4UG8!B1 -> LVX0000U4UG8 | D37: =LVX0000U4UG8!B2 -> Romania | E37: =LVX0000U4UG8!B4 -> Personal | F37: =LVX0000U4UG8!B8 -> 0 m. 11 mėn. 21 d. | G37: =LVX0000U4UG8!B15 -> 0.125 | H37: =LVX0000U4UG8!B16 -> 16.58 | I37: =LVX0000U4UG8!B11 -> 46513 | J37: =LVX0000U4UG8!O3 | K37: =LVX0000U4UG8!B12 -> 218 | L37: =LVX0000U4UG8!P3 | M37: =LVX0000U4UG8!K3 -> 8.05 | N37: =LVX0000U4UG8!L3 -> 0.62 | O37: =LVX0000U4UG8!M3 -> 0.03 | AC37: =LVX0000U4UG8!Z3
A38: 36 | B38: =LVX0000ULW59!B9 -> 46188 | C38: =LVX0000ULW59!B1 -> LVX0000ULW59 | D38: =LVX0000ULW59!B2 -> Moldova | E38: =LVX0000ULW59!B4 -> Personal | F38: =LVX0000ULW59!B8 -> 2 m. 5 mėn. 10 d. | G38: =LVX0000ULW59!B15 -> 0.14 | H38: =LVX0000ULW59!B16 -> 10.3 | I38: =LVX0000ULW59!B11 -> 47082 | J38: =LVX0000ULW59!O3 | K38: =LVX0000ULW59!B12 -> 787 | L38: =LVX0000ULW59!P3 | M38: =LVX0000ULW59!K3 -> 2.2 | N38: =LVX0000ULW59!L3 -> 0.38 | O38: =LVX0000ULW59!M3 -> 0.01 | AC38: =LVX0000ULW59!Z3
A39: 37 | B39: =LVX0000UP6R4!B9 -> 46191 | C39: =LVX0000UP6R4!B1 -> LVX0000UP6R4 | D39: =LVX0000UP6R4!B2 -> Romania | E39: =LVX0000UP6R4!B4 -> Personal | F39: =LVX0000UP6R4!B8 -> 1 m. 10 mėn. 0 d. | G39: =LVX0000UP6R4!B15 -> 0.125 | H39: =LVX0000UP6R4!B16 -> 14.5 | I39: =LVX0000UP6R4!B11 -> 46861 | J39: =LVX0000UP6R4!O3 | K39: =LVX0000UP6R4!B12 -> 566 | L39: =LVX0000UP6R4!P3 | M39: =LVX0000UP6R4!K3 -> 11.85 | N39: =LVX0000UP6R4!L3 -> 0.41 | O39: =LVX0000UP6R4!M3 -> 0.01 | AC39: =LVX0000UP6R4!Z3
A40: 38 | B40: =LVX0000URIF2!B9 -> 46195 | C40: =LVX0000URIF2!B1 -> LVX0000URIF2 | D40: =LVX0000URIF2!B2 -> Cyprus | E40: =LVX0000URIF2!B4 -> Business | F40: =LVX0000URIF2!B8 -> 0 m. 5 mėn. 26 d. | G40: =LVX0000URIF2!B15 -> 0.12 | H40: =LVX0000URIF2!B16 -> 14.16 | I40: =LVX0000URIF2!B11 -> 46374 | J40: =LVX0000URIF2!O3 | K40: =LVX0000URIF2!B12 -> 79 | L40: =LVX0000URIF2!P3 | M40: =LVX0000URIF2!K3 -> 0 | N40: =LVX0000URIF2!L3 -> 0.37 | O40: =LVX0000URIF2!M3 -> 0 | AC40: =LVX0000URIF2!Z3
...

Sheet Pinigai
A1: Data | B1: Įnešta | C1: Išimta | D1: Premijos | F1: Įnešta | G1: Išimta | H1: Premijos | I1: Skirtumas | K1: Įnešta
A2: 45909 | B2: 50 | C2: 0 | D2: 0 | F2: =SUM(B2:B37) -> 320 | G2: =SUM(C2:C37) -> 0 | H2: =SUM(D2:D37) -> 2.71 | I2: =F2-G2 -> 320 | K2: =B2*-1 -> -50
A3: 45915 | B3: 50 | C3: 0 | D3: 0 | K3: =B3*-1 -> -50
A4: 45944 | B4: 20 | C4: 0 | D4: 0 | K4: =B4*-1 -> -20
A5: 45947 | B5: 20 | C5: 0 | D5: 0 | K5: =B5*-1 -> -20
A6: 45958 | B6: 50 | C6: 0 | D6: 0 | K6: =B6*-1 -> -50
A7: 45970 | B7: 10 | C7: 0 | D7: 0 | K7: =B7*-1 -> -10
A8: 45975 | B8: 0 | C8: 0 | D8: 0.78 | K8: =B8*-1 -> 0
A9: 45985 | B9: 10 | C9: 0 | D9: 0 | K9: =B9*-1 -> -10
A10: 45996 | B10: 10 | C10: 0 | D10: 0 | K10: =B10*-1 -> -10
A11: 46002 | B11: 10 | C11: 0 | D11: 0 | K11: =B11*-1 -> -10
A12: 46015 | B12: 10 | C12: 0 | D12: 0 | K12: =B12*-1 -> -10
A13: 46024 | B13: 20 | C13: 0 | D13: 0 | K13: =B13*-1 -> -20
A14: 46029 | B14: 10 | C14: 0 | D14: 0 | K14: =B14*-1 -> -10
... A23: 46276 | B23: 0 | C23: 0 | D23: 0.02 | K23: =B23*-1 -> 0
K24: =B24*-1 -> 0
A200: =TODAY() -> 46295 | K200: =Overview!W3 -> 353.94

Sheet LVX0000VRTQ4
A1: Loan ID | B1: LVX0000VRTQ4 | D1: Data | G1: Paskola | K1: Grąžinimas
A2: Šalis | B2: Cyprus | D2: Planuojama | E2: Reali | F2: Vėl./Anks. | G2: Principal | H2: Interest | I2: Mokestis | K2: Paskola | L2: Palūkanos | M2: Mokesčiai | N2: XIRR | O2: Data | P2: Vėluoja | Q2: Vėl./Anks. | X2: Data | Y2: Suma | Z2: Vėluoja
A3: Skolintojas | B3: SIA "Abele Finance" | D3: 46295 | E3: 46295 | F3: =IF(E3>0,E3-D3,"") -> 0 | G3: 0 | H3: 0 | I3: 0 | K3: =G53 -> 0 | L3: =H53 -> 0 | M3: =I53 -> 0 | N3: =IF(B16=K3,XIRR(Y3:Y52,X3:X52),"") | O3: =IF(B16=K3,MAX(E:E),"") | P3: =IF(Z3="+",TODAY()-B11,"") | Q3: =IF(B16=K3,MAX(E:E)-B11,"") | X3: =B9 -> 46293 | Y3: =B16*-1 -> -10.05 | Z3: =IF(AND(TODAY()>B11, K3<>B16), "+", "")
A4: Tipas | B4: Business | F4: =IF(E4>0,E4-D4,"") | X4: =E3 -> 46295 | Y4: =G3+H3-I3 -> 0
F5: =IF(E5>0,E5-D5,"") | X5: =E4 -> 0 | Y5: =G4+H4-I4 -> 0
F6: =IF(E6>0,E6-D6,"") | X6: =E5 -> 0 | Y6: =G5+H5-I5 -> 0
F7: =IF(E7>0,E7-D7,"") | X7: =E6 -> 0 | Y7: =G6+H6-I6 -> 0
A8: Terminas | B8: =DATEDIF(B9,B11,"y") & " m. " & DATEDIF(B9,B11,"ym") & " mėn. " & DATEDIF(B9,B11,"md") & " d." -> 1 m. 2 mėn. 18 d. | F8: =IF(E8>0,E8-D8,"") | X8: =E7 -> 0 | Y8: =G7+H7-I7 -> 0
A9: Investuota | B9: 46293 | X9: =E8 -> 0 | Y9: =G8+H8-I8 -> 0
A10: Pradžia | B10: 46282 | F10: =IF(E10>0,E10-D10,"") | X10: =E9 -> 0 | Y10: =G9+H9-I9 -> 0
A11: Pabaiga | B11: 46737 | F11: =IF(E11>0,E11-D11,"") | X11: =E10 -> 0 | Y11: =G10+H10-I10 -> 0
A12: Liko, dienos | B12: =IF(B16<>K3,(TODAY()-B11)*-1,"") -> 442 | F12: =IF(E12>0,E12-D12,"") | X12: =E11 -> 0 | Y12: =G11+H11-I11 -> 0
F13: =IF(E13>0,E13-D13,"") | X13: =E12 -> 0 | Y13: =G12+H12-I12 -> 0
F14: =IF(E14>0,E14-D14,"") | X14: =E13 -> 0 | Y14: =G13+H13-I13 -> 0
A15: Palūkanos | B15: 0.135 | F15: =IF(E15>0,E15-D15,"") | X15: =E14 -> 0 | Y15: =G14+H14-I14 -> 0
A16: Investuota, Eur | B16: 10.05 | F16: =IF(E16>0,E16-D16,"") | X16: =E15 -> 0 | Y16: =G15+H15-I15 -> 0
F17: =IF(E17>0,E17-D17,"") | X17: =E16 -> 0 | Y17: =G16+H16-I16 -> 0
F18: =IF(E18>0,E18-D18,"") | X18: =E17 -> 0 | Y18: =G17+H17-I17 -> 0
F19: =IF(E19>0,E19-D19,"") | X19: =E18 -> 0 | Y19: =G18+H18-I18 -> 0
F20: =IF(E20>0,E20-D20,"") | X20: =E19 -> 0 | Y20: =G19+H19-I19 -> 0
F21: =IF(E21>0,E21-D21,"") | X21: =E20 -> 0 | Y21: =G20+H20-I20 -> 0
F22: =IF(E22>0,E22-D22,"") | X22: =E21 -> 0 | Y22: =G21+H21-I21 -> 0
F23: =IF(E23>0,E23-D23,"") | X23: =E22 -> 0 | Y23: =G22+H22-I22 -> 0
F24: =IF(E24>0,E24-D24,"") | X24: =E23 -> 0 | Y24: =G23+H23-I23 -> 0
F25: =IF(E25>0,E25-D25,"") | X25: =E24 -> 0 | Y25: =G24+H24-I24 -> 0
F26: =IF(E26>0,E26-D26,"") | X26: =E25 -> 0 | Y26: =G25+H25-I25 -> 0
F27: =IF(E27>0,E27-D27,"") | X27: =E26 -> 0 | Y27: =G26+H26-I26 -> 0
F28: =IF(E28>0,E28-D28,"") | X28: =E27 -> 0 | Y28: =G27+H27-I27 -> 0
... F52: =IF(E52>0,E52-D52,"") | X52: =E51 -> 0 | Y52: =G51+H51-I51 -> 0
D53: Viso: | G53: =SUM(G3:G52) -> 0 | H53: =SUM(H3:H52) -> 0 | I53: =SUM(I3:I52) -> 0

Sheet LVX0000VQWW8
A1: Loan ID | B1: LVX0000VQWW8 | D1: Data | G1: Paskola | K1: Grąžinimas
A2: Šalis | B2: Romania | D2: Planuojama | E2: Reali | F2: Vėl./Anks. | G2: Principal | H2: Interest | I2: Mokestis | K2: Paskola | L2: Palūkanos | M2: Mokesčiai | N2: XIRR | O2: Data | P2: Vėluoja | Q2: Vėl./Anks. | X2: Data | Y2: Suma | Z2: Vėluoja
A3: Skolintojas | B3: ECOFINANCE IFN SA | D3: 46295 | E3: 46295 | F3: =IF(E3>0,E3-D3,"") -> 0 | G3: 4.16 | H3: 0.1 | I3: 0 | K3: =G53 -> 4.16 | L3: =H53 -> 0.1 | M3: =I53 -> 0 | N3: =IF(B16=K3,XIRR(Y3:Y52,X3:X52),"") | O3: =IF(B16=K3,MAX(E:E),"") | P3: =IF(Z3="+",TODAY()-B11,"") | Q3: =IF(B16=K3,MAX(E:E)-B11,"") | X3: =B9 -> 46282 | Y3: =B16*-1 -> -25.39 | Z3: =IF(AND(TODAY()>B11, K3<>B16), "+", "")
A4: Tipas | B4: Personal | F4: =IF(E4>0,E4-D4,"") | X4: =E3 -> 46295 | Y4: =G3+H3-I3 -> 4.26
F5: =IF(E5>0,E5-D5,"") | X5: =E4 -> 0 | Y5: =G4+H4-I4 -> 0
F6: =IF(E6>0,E6-D6,"") | X6: =E5 -> 0 | Y6: =G5+H5-I5 -> 0
F7: =IF(E7>0,E7-D7,"") | X7: =E6 -> 0 | Y7: =G6+H6-I6 -> 0
A8: Terminas | B8: =DATEDIF(B9,B11,"y") & " m. " & DATEDIF(B9,B11,"ym") & " mėn. " & DATEDIF(B9,B11,"md") & " d." -> 1 m. 9 mėn. 14 d. | F8: =IF(E8>0,E8-D8,"") | X8: =E7 -> 0 | Y8: =G7+H7-I7 -> 0
A9: Investuota | B9: 46282 | X9: =E8 -> 0 | Y9: =G8+H8-I8 -> 0
A10: Pradžia | B10: 46280 | F10: =IF(E10>0,E10-D10,"") | X10: =E9 -> 0 | Y10: =G9+H9-I9 -> 0
A11: Pabaiga | B11: 46935 | F11: =IF(E11>0,E11-D11,"") | X11: =E10 -> 0 | Y11: =G10+H10-I10 -> 0
A12: Liko, dienos | B12: =IF(B16<>K3,(TODAY()-B11)*-1,"") -> 640 | F12: =IF(E12>0,E12-D12,"") | X12: =E11 -> 0 | Y12: =G11+H11-I11 -> 0
F13: =IF(E13>0,E13-D13,"") | X13: =E12 -> 0 | Y13: =G12+H12-I12 -> 0
F14: =IF(E14>0,E14-D14,"") | X14: =E13 -> 0 | Y14: =G13+H13-I13 -> 0
A15: Palūkanos | B15: 0.12 | F15: =IF(E15>0,E15-D15,"") | X15: =E14 -> 0 | Y15: =G14+H14-I14 -> 0
A16: Investuota, Eur | B16: 25.39 | F16: =IF(E16>0,E16-D16,"") | X16: =E15 -> 0 | Y16: =G15+H15-I15 -> 0
F17: =IF(E17>0,E17-D17,"") | X17: =E16 -> 0 | Y17: =G16+H16-I16 -> 0
F18: =IF(E18>0,E18-D18,"") | X18: =E17 -> 0 | Y18: =G17+H17-I17 -> 0
F19: =IF(E19>0,E19-D19,"") | X19: =E18 -> 0 | Y19: =G18+H18-I18 -> 0
F20: =IF(E20>0,E20-D20,"") | X20: =E19 -> 0 | Y20: =G19+H19-I19 -> 0
F21: =IF(E21>0,E21-D21,"") | X21: =E20 -> 0 | Y21: =G20+H20-I20 -> 0
F22: =IF(E22>0,E22-D22,"") | X22: =E21 -> 0 | Y22: =G21+H21-I21 -> 0
F23: =IF(E23>0,E23-D23,"") | X23: =E22 -> 0 | Y23: =G22+H22-I22 -> 0
F24: =IF(E24>0,E24-D24,"") | X24: =E23 -> 0 | Y24: =G23+H23-I23 -> 0
F25: =IF(E25>0,E25-D25,"") | X25: =E24 -> 0 | Y25: =G24+H24-I24 -> 0
F26: =IF(E26>0,E26-D26,"") | X26: =E25 -> 0 | Y26: =G25+H25-I25 -> 0
F27: =IF(E27>0,E27-D27,"") | X27: =E26 -> 0 | Y27: =G26+H26-I26 -> 0
F28: =IF(E28>0,E28-D28,"") | X28: =E27 -> 0 | Y28: =G27+H27-I27 -> 0
... F52: =IF(E52>0,E52-D52,"") | X52: =E51 -> 0 | Y52: =G51+H51-I51 -> 0
D53: Viso: | G53: =SUM(G3:G52) -> 4.16 | H53: =SUM(H3:H52) -> 0.1 | I53: =SUM(I3:I52) -> 0

Sheet LVX0000VISL6
A1: Loan ID | B1: LVX0000VISL6 | D1: Data | G1: Paskola | K1: Grąžinimas
A2: Šalis | B2: Philippines | D2: Planuojama | E2: Reali | F2: Vėl./Anks. | G2: Principal | H2: Interest | I2: Mokestis | K2: Paskola | L2: Palūkanos | M2: Mokesčiai | N2: XIRR | O2: Data | P2: Vėluoja | Q2: Vėl./Anks. | X2: Data | Y2: Suma | Z2: Vėluoja
A3: Skolintojas | B3: SIA "Abele Finance" | D3: 46295 | E3: 46295 | F3: =IF(E3>0,E3-D3,"") -> 0 | G3: 0 | H3: 0 | I3: 0 | K3: =G53 -> 0 | L3: =H53 -> 0 | M3: =I53 -> 0 | N3: =IF(B16=K3,XIRR(Y3:Y52,X3:X52),"") | O3: =IF(B16=K3,MAX(E:E),"") | P3: =IF(Z3="+",TODAY()-B11,"") | Q3: =IF(B16=K3,MAX(E:E)-B11,"") | X3: =B9 -> 46282 | Y3: =B16*-1 -> -20 | Z3: =IF(AND(TODAY()>B11, K3<>B16), "+", "")
A4: Tipas | B4: Business | F4: =IF(E4>0,E4-D4,"") | X4: =E3 -> 46295 | Y4: =G3+H3-I3 -> 0
F5: =IF(E5>0,E5-D5,"") | X5: =E4 -> 0 | Y5: =G4+H4-I4 -> 0
F6: =IF(E6>0,E6-D6,"") | X6: =E5 -> 0 | Y6: =G5+H5-I5 -> 0
F7: =IF(E7>0,E7-D7,"") | X7: =E6 -> 0 | Y7: =G6+H6-I6 -> 0
A8: Terminas | B8: =DATEDIF(B9,B11,"y") & " m. " & DATEDIF(B9,B11,"ym") & " mėn. " & DATEDIF(B9,B11,"md") & " d." -> 0 m. 8 mėn. 5 d. | F8: =IF(E8>0,E8-D8,"") | X8: =E7 -> 0 | Y8: =G7+H7-I7 -> 0
A9: Investuota | B9: 46282 | X9: =E8 -> 0 | Y9: =G8+H8-I8 -> 0
A10: Pradžia | B10: 46259 | F10: =IF(E10>0,E10-D10,"") | X10: =E9 -> 0 | Y10: =G9+H9-I9 -> 0
A11: Pabaiga | B11: 46529 | F11: =IF(E11>0,E11-D11,"") | X11: =E10 -> 0 | Y11: =G10+H10-I10 -> 0
A12: Liko, dienos | B12: =IF(B16<>K3,(TODAY()-B11)*-1,"") -> 234 | F12: =IF(E12>0,E12-D12,"") | X12: =E11 -> 0 | Y12: =G11+H11-I11 -> 0
F13: =IF(E13>0,E13-D13,"") | X13: =E12 -> 0 | Y13: =G12+H12-I12 -> 0
F14: =IF(E14>0,E14-D14,"") | X14: =E13 -> 0 | Y14: =G13+H13-I13 -> 0
A15: Palūkanos | B15: 0.12 | F15: =IF(E15>0,E15-D15,"") | X15: =E14 -> 0 | Y15: =G14+H14-I14 -> 0
A16: Investuota, Eur | B16: 20 | F16: =IF(E16>0,E16-D16,"") | X16: =E15 -> 0 | Y16: =G15+H15-I15 -> 0
F17: =IF(E17>0,E17-D17,"") | X17: =E16 -> 0 | Y17: =G16+H16-I16 -> 0
F18: =IF(E18>0,E18-D18,"") | X18: =E17 -> 0 | Y18: =G17+H17-I17 -> 0
F19: =IF(E19>0,E19-D19,"") | X19: =E18 -> 0 | Y19: =G18+H18-I18 -> 0
F20: =IF(E20>0,E20-D20,"") | X20: =E19 -> 0 | Y20: =G19+H19-I19 -> 0
F21: =IF(E21>0,E21-D21,"") | X21: =E20 -> 0 | Y21: =G20+H20-I20 -> 0
F22: =IF(E22>0,E22-D22,"") | X22: =E21 -> 0 | Y22: =G21+H21-I21 -> 0
F23: =IF(E23>0,E23-D23,"") | X23: =E22 -> 0 | Y23: =G22+H22-I22 -> 0
F24: =IF(E24>0,E24-D24,"") | X24: =E23 -> 0 | Y24: =G23+H23-I23 -> 0
F25: =IF(E25>0,E25-D25,"") | X25: =E24 -> 0 | Y25: =G24+H24-I24 -> 0
F26: =IF(E26>0,E26-D26,"") | X26: =E25 -> 0 | Y26: =G25+H25-I25 -> 0
F27: =IF(E27>0,E27-D27,"") | X27: =E26 -> 0 | Y27: =G26+H26-I26 -> 0
F28: =IF(E28>0,E28-D28,"") | X28: =E27 -> 0 | Y28: =G27+H27-I27 -> 0
... F52: =IF(E52>0,E52-D52,"") | X52: =E51 -> 0 | Y52: =G51+H51-I51 -> 0
D53: Viso: | G53: =SUM(G3:G52) -> 0 | H53: =SUM(H3:H52) -> 0 | I53: =SUM(I3:I52) -> 0

Sheet LVX0000VQWF3
A1: Loan ID | B1: LVX0000VQWF3 | D1: Data | G1: Paskola | K1: Grąžinimas
A2: Šalis | B2: Romania | D2: Planuojama | E2: Reali | F2: Vėl./Anks. | G2: Principal | H2: Interest | I2: Mokestis | K2: Paskola | L2: Palūkanos | M2: Mokesčiai | N2: XIRR | O2: Data | P2: Vėluoja | Q2: Vėl./Anks. | X2: Data | Y2: Suma | Z2: Vėluoja
A3: Skolintojas | B3: ECOFINANCE IFN SA | D3: 46295 | E3: 46295 | F3: =IF(E3>0,E3-D3,"") -> 0 | G3: 0.47 | H3: 0.07 | I3: 0 | K3: =G53 -> 0.47 | L3: =H53 -> 0.07 | M3: =I53 -> 0 | N3: =IF(B16=K3,XIRR(Y3:Y52,X3:X52),"") | O3: =IF(B16=K3,MAX(E:E),"") | P3: =IF(Z3="+",TODAY()-B11,"") | Q3: =IF(B16=K3,MAX(E:E)-B11,"") | X3: =B9 -> 46281 | Y3: =B16*-1 -> -15.63 | Z3: =IF(AND(TODAY()>B11, K3<>B16), "+", "")
A4: Tipas | B4: Personal | F4: =IF(E4>0,E4-D4,"") | X4: =E3 -> 46295 | Y4: =G3+H3-I3 -> 0.54
F5: =IF(E5>0,E5-D5,"") | X5: =E4 -> 0 | Y5: =G4+H4-I4 -> 0
F6: =IF(E6>0,E6-D6,"") | X6: =E5 -> 0 | Y6: =G5+H5-I5 -> 0
F7: =IF(E7>0,E7-D7,"") | X7: =E6 -> 0 | Y7: =G6+H6-I6 -> 0
A8: Terminas | B8: =DATEDIF(B9,B11,"y") & " m. " & DATEDIF(B9,B11,"ym") & " mėn. " & DATEDIF(B9,B11,"md") & " d." -> 1 m. 1 mėn. 27 d. | F8: =IF(E8>0,E8-D8,"") | X8: =E7 -> 0 | Y8: =G7+H7-I7 -> 0
A9: Investuota | B9: 46281 | X9: =E8 -> 0 | Y9: =G8+H8-I8 -> 0
A10: Pradžia | B10: 46280 | F10: =IF(E10>0,E10-D10,"") | X10: =E9 -> 0 | Y10: =G9+H9-I9 -> 0
A11: Pabaiga | B11: 46703 | F11: =IF(E11>0,E11-D11,"") | X11: =E10 -> 0 | Y11: =G10+H10-I10 -> 0
A12: Liko, dienos | B12: =IF(B16<>K3,(TODAY()-B11)*-1,"") -> 408 | F12: =IF(E12>0,E12-D12,"") | X12: =E11 -> 0 | Y12: =G11+H11-I11 -> 0
F13: =IF(E13>0,E13-D13,"") | X13: =E12 -> 0 | Y13: =G12+H12-I12 -> 0
F14: =IF(E14>0,E14-D14,"") | X14: =E13 -> 0 | Y14: =G13+H13-I13 -> 0
A15: Palūkanos | B15: 0.12 | F15: =IF(E15>0,E15-D15,"") | X15: =E14 -> 0 | Y15: =G14+H14-I14 -> 0
A16: Investuota, Eur | B16: 15.63 | F16: =IF(E16>0,E16-D16,"") | X16: =E15 -> 0 | Y16: =G15+H15-I15 -> 0
F17: =IF(E17>0,E17-D17,"") | X17: =E16 -> 0 | Y17: =G16+H16-I16 -> 0
F18: =IF(E18>0,E18-D18,"") | X18: =E17 -> 0 | Y18: =G17+H17-I17 -> 0
F19: =IF(E19>0,E19-D19,"") | X19: =E18 -> 0 | Y19: =G18+H18-I18 -> 0
F20: =IF(E20>0,E20-D20,"") | X20: =E19 -> 0 | Y20: =G19+H19-I19 -> 0
F21: =IF(E21>0,E21-D21,"") | X21: =E20 -> 0 | Y21: =G20+H20-I20 -> 0
F22: =IF(E22>0,E22-D22,"") | X22: =E21 -> 0 | Y22: =G21+H21-I21 -> 0
F23: =IF(E23>0,E23-D23,"") | X23: =E22 -> 0 | Y23: =G22+H22-I22 -> 0
F24: =IF(E24>0,E24-D24,"") | X24: =E23 -> 0 | Y24: =G23+H23-I23 -> 0
F25: =IF(E25>0,E25-D25,"") | X25: =E24 -> 0 | Y25: =G24+H24-I24 -> 0
F26: =IF(E26>0,E26-D26,"") | X26: =E25 -> 0 | Y26: =G25+H25-I25 -> 0
F27: =IF(E27>0,E27-D27,"") | X27: =E26 -> 0 | Y27: =G26+H26-I26 -> 0
F28: =IF(E28>0,E28-D28,"") | X28: =E27 -> 0 | Y28: =G27+H27-I27 -> 0
... F52: =IF(E52>0,E52-D52,"") | X52: =E51 -> 0 | Y52: =G51+H51-I51 -> 0
D53: Viso: | G53: =SUM(G3:G52) -> 0.47 | H53: =SUM(H3:H52) -> 0.07 | I53: =SUM(I3:I52) -> 0

Sheet LVX0000VG2M4
A1: Loan ID | B1: LVX0000VG2M4 | D1: Data | G1: Paskola | K1: Grąžinimas
A2: Šalis | B2: Romania | D2: Planuojama | E2: Reali | F2: Vėl./Anks. | G2: Principal | H2: Interest | I2: Mokestis | K2: Paskola | L2: Palūkanos | M2: Mokesčiai | N2: XIRR | O2: Data | P2: Vėluoja | Q2: Vėl./Anks. | X2: Data | Y2: Suma | Z2: Vėluoja
A3: Skolintojas | B3: ECOFINANCE IFN SA | D3: 46295 | E3: 46295 | F3: =IF(E3>0,E3-D3,"") -> 0 | G3: 6.73 | H3: 0.15 | I3: 0 | K3: =G53 -> 6.73 | L3: =H53 -> 0.15 | M3: =I53 -> 0 | N3: =IF(B16=K3,XIRR(Y3:Y52,X3:X52),"") | O3: =IF(B16=K3,MAX(E:E),"") | P3: =IF(Z3="+",TODAY()-B11,"") | Q3: =IF(B16=K3,MAX(E:E)-B11,"") | X3: =B9 -> 46272 | Y3: =B16*-1 -> -25.95 | Z3: =IF(AND(TODAY()>B11, K3<>B16), "+", "")
A4: Tipas | B4: Personal | F4: =IF(E4>0,E4-D4,"") | X4: =E3 -> 46295 | Y4: =G3+H3-I3 -> 6.88
F5: =IF(E5>0,E5-D5,"") | X5: =E4 -> 0 | Y5: =G4+H4-I4 -> 0
F6: =IF(E6>0,E6-D6,"") | X6: =E5 -> 0 | Y6: =G5+H5-I5 -> 0
F7: =IF(E7>0,E7-D7,"") | X7: =E6 -> 0 | Y7: =G6+H6-I6 -> 0
A8: Terminas | B8: =DATEDIF(B9,B11,"y") & " m. " & DATEDIF(B9,B11,"ym") & " mėn. " & DATEDIF(B9,B11,"md") & " d." -> 1 m. 5 mėn. 8 d. | F8: =IF(E8>0,E8-D8,"") | X8: =E7 -> 0 | Y8: =G7+H7-I7 -> 0
A9: Investuota | B9: 46272 | X9: =E8 -> 0 | Y9: =G8+H8-I8 -> 0
A10: Pradžia | B10: 46252 | F10: =IF(E10>0,E10-D10,"") | X10: =E9 -> 0 | Y10: =G9+H9-I9 -> 0
A11: Pabaiga | B11: 46798 | F11: =IF(E11>0,E11-D11,"") | X11: =E10 -> 0 | Y11: =G10+H10-I10 -> 0
A12: Liko, dienos | B12: =IF(B16<>K3,(TODAY()-B11)*-1,"") -> 503 | F12: =IF(E12>0,E12-D12,"") | X12: =E11 -> 0 | Y12: =G11+H11-I11 -> 0
F13: =IF(E13>0,E13-D13,"") | X13: =E12 -> 0 | Y13: =G12+H12-I12 -> 0
F14: =IF(E14>0,E14-D14,"") | X14: =E13 -> 0 | Y14: =G13+H13-I13 -> 0
A15: Palūkanos | B15: 0.12 | F15: =IF(E15>0,E15-D15,"") | X15: =E14 -> 0 | Y15: =G14+H14-I14 -> 0
A16: Investuota, Eur | B16: 25.95 | F16: =IF(E16>0,E16-D16,"") | X16: =E15 -> 0 | Y16: =G15+H15-I15 -> 0
F17: =IF(E17>0,E17-D17,"") | X17: =E16 -> 0 | Y17: =G16+H16-I16 -> 0
F18: =IF(E18>0,E18-D18,"") | X18: =E17 -> 0 | Y18: =G17+H17-I17 -> 0
F19: =IF(E19>0,E19-D19,"") | X19: =E18 -> 0 | Y19: =G18+H18-I18 -> 0
F20: =IF(E20>0,E20-D20,"") | X20: =E19 -> 0 | Y20: =G19+H19-I19 -> 0
F21: =IF(E21>0,E21-D21,"") | X21: =E20 -> 0 | Y21: =G20+H20-I20 -> 0
F22: =IF(E22>0,E22-D22,"") | X22: =E21 -> 0 | Y22: =G21+H21-I21 -> 0
F23: =IF(E23>0,E23-D23,"") | X23: =E22 -> 0 | Y23: =G22+H22-I22 -> 0
F24: =IF(E24>0,E24-D24,"") | X24: =E23 -> 0 | Y24: =G23+H23-I23 -> 0
F25: =IF(E25>0,E25-D25,"") | X25: =E24 -> 0 | Y25: =G24+H24-I24 -> 0
F26: =IF(E26>0,E26-D26,"") | X26: =E25 -> 0 | Y26: =G25+H25-I25 -> 0
F27: =IF(E27>0,E27-D27,"") | X27: =E26 -> 0 | Y27: =G26+H26-I26 -> 0
F28: =IF(E28>0,E28-D28,"") | X28: =E27 -> 0 | Y28: =G27+H27-I27 -> 0
... F52: =IF(E52>0,E52-D52,"") | X52: =E51 -> 0 | Y52: =G51+H51-I51 -> 0
D53: Viso: | G53: =SUM(G3:G52) -> 6.73 | H53: =SUM(H3:H52) -> 0.15 | I53: =SUM(I3:I52) -> 0

Sheet LVX0000VIR76
A1: Loan ID | B1: LVX0000VIR76 | D1: Data | G1: Paskola | K1: Grąžinimas
A2: Šalis | B2: Romania | D2: Planuojama | E2: Reali | F2: Vėl./Anks. | G2: Principal | H2: Interest | I2: Mokestis | K2: Paskola | L2: Palūkanos | M2: Mokesčiai | N2: XIRR | O2: Data | P2: Vėluoja | Q2: Vėl./Anks. | X2: Data | Y2: Suma | Z2: Vėluoja
A3: Skolintojas | B3: ECOFINANCE IFN SA | D3: 46265 | E3: 46265 | F3: =IF(E3>0,E3-D3,"") -> 0 | G3: 0 | H3: 0 | I3: 0 | K3: =G53 -> 6.64 | L3: =H53 -> 0.21 | M3: =I53 -> 0 | N3: =IF(B16=K3,XIRR(Y3:Y52,X3:X52),"") | O3: =IF(B16=K3,MAX(E:E),"") | P3: =IF(Z3="+",TODAY()-B11,"") | Q3: =IF(B16=K3,MAX(E:E)-B11,"") | X3: =B9 -> 46261 | Y3: =B16*-1 -> -23.81 | Z3: =IF(AND(TODAY()>B11, K3<>B16), "+", "")
A4: Tipas | B4: Personal | D4: 46295 | E4: 46295 | F4: =IF(E4>0,E4-D4,"") -> 0 | G4: 6.64 | H4: 0.21 | I4: 0 | X4: =E3 -> 46265 | Y4: =G3+H3-I3 -> 0
F5: =IF(E5>0,E5-D5,"") | X5: =E4 -> 46295 | Y5: =G4+H4-I4 -> 6.85
F6: =IF(E6>0,E6-D6,"") | X6: =E5 -> 0 | Y6: =G5+H5-I5 -> 0
F7: =IF(E7>0,E7-D7,"") | X7: =E6 -> 0 | Y7: =G6+H6-I6 -> 0
A8: Terminas | B8: =DATEDIF(B9,B11,"y") & " m. " & DATEDIF(B9,B11,"ym") & " mėn. " & DATEDIF(B9,B11,"md") & " d." -> 1 m. 10 mėn. 7 d. | F8: =IF(E8>0,E8-D8,"") | X8: =E7 -> 0 | Y8: =G7+H7-I7 -> 0
A9: Investuota | B9: 46261 | X9: =E8 -> 0 | Y9: =G8+H8-I8 -> 0
A10: Pradžia | B10: 46259 | F10: =IF(E10>0,E10-D10,"") | X10: =E9 -> 0 | Y10: =G9+H9-I9 -> 0
A11: Pabaiga | B11: 46938 | F11: =IF(E11>0,E11-D11,"") | X11: =E10 -> 0 | Y11: =G10+H10-I10 -> 0
A12: Liko, dienos | B12: =IF(B16<>K3,(TODAY()-B11)*-1,"") -> 643 | F12: =IF(E12>0,E12-D12,"") | X12: =E11 -> 0 | Y12: =G11+H11-I11 -> 0
F13: =IF(E13>0,E13-D13,"") | X13: =E12 -> 0 | Y13: =G12+H12-I12 -> 0
F14: =IF(E14>0,E14-D14,"") | X14: =E13 -> 0 | Y14: =G13+H13-I13 -> 0
A15: Palūkanos | B15: 0.12 | F15: =IF(E15>0,E15-D15,"") | X15: =E14 -> 0 | Y15: =G14+H14-I14 -> 0
A16: Investuota, Eur | B16: 23.81 | F16: =IF(E16>0,E16-D16,"") | X16: =E15 -> 0 | Y16: =G15+H15-I15 -> 0
F17: =IF(E17>0,E17-D17,"") | X17: =E16 -> 0 | Y17: =G16+H16-I16 -> 0
F18: =IF(E18>0,E18-D18,"") | X18: =E17 -> 0 | Y18: =G17+H17-I17 -> 0
F19: =IF(E19>0,E19-D19,"") | X19: =E18 -> 0 | Y19: =G18+H18-I18 -> 0
F20: =IF(E20>0,E20-D20,"") | X20: =E19 -> 0 | Y20: =G19+H19-I19 -> 0
F21: =IF(E21>0,E21-D21,"") | X21: =E20 -> 0 | Y21: =G20+H20-I20 -> 0
F22: =IF(E22>0,E22-D22,"") | X22: =E21 -> 0 | Y22: =G21+H21-I21 -> 0
F23: =IF(E23>0,E23-D23,"") | X23: =E22 -> 0 | Y23: =G22+H22-I22 -> 0
F24: =IF(E24>0,E24-D24,"") | X24: =E23 -> 0 | Y24: =G23+H23-I23 -> 0
F25: =IF(E25>0,E25-D25,"") | X25: =E24 -> 0 | Y25: =G24+H24-I24 -> 0
F26: =IF(E26>0,E26-D26,"") | X26: =E25 -> 0 | Y26: =G25+H25-I25 -> 0
F27: =IF(E27>0,E27-D27,"") | X27: =E26 -> 0 | Y27: =G26+H26-I26 -> 0
F28: =IF(E28>0,E28-D28,"") | X28: =E27 -> 0 | Y28: =G27+H27-I27 -> 0
... F52: =IF(E52>0,E52-D52,"") | X52: =E51 -> 0 | Y52: =G51+H51-I51 -> 0
D53: Viso: | G53: =SUM(G3:G52) -> 6.64 | H53: =SUM(H3:H52) -> 0.21 | I53: =SUM(I3:I52) -> 0

Sheet LVX0000VHJ69
A1: Loan ID | B1: LVX0000VHJ69 | D1: Data | G1: Paskola | K1: Grąžinimas
A2: Šalis | B2: Moldova | D2: Planuojama | E2: Reali | F2: Vėl./Anks. | G2: Principal | H2: Interest | I2: Mokestis | K2: Paskola | L2: Palūkanos | M2: Mokesčiai | N2: XIRR | O2: Data | P2: Vėluoja | Q2: Vėl./Anks. | X2: Data | Y2: Suma | Z2: Vėluoja
A3: Skolintojas | B3: SIA "Abele Finance" | D3: 46265 | E3: 46265 | F3: =IF(E3>0,E3-D3,"") -> 0 | G3: 0 | H3: 0 | I3: 0 | K3: =G53 -> 0 | L3: =H53 -> 0.13 | M3: =I53 -> 0 | N3: =IF(B16=K3,XIRR(Y3:Y52,X3:X52),"") | O3: =IF(B16=K3,MAX(E:E),"") | P3: =IF(Z3="+",TODAY()-B11,"") | Q3: =IF(B16=K3,MAX(E:E)-B11,"") | X3: =B9 -> 46260 | Y3: =B16*-1 -> -26.67 | Z3: =IF(AND(TODAY()>B11, K3<>B16), "+", "")
A4: Tipas | B4: Business | D4: 46295 | E4: 46295 | F4: =IF(E4>0,E4-D4,"") -> 0 | G4: 0 | H4: 0.13 | I4: 0 | X4: =E3 -> 46265 | Y4: =G3+H3-I3 -> 0
F5: =IF(E5>0,E5-D5,"") | X5: =E4 -> 46295 | Y5: =G4+H4-I4 -> 0.13
F6: =IF(E6>0,E6-D6,"") | X6: =E5 -> 0 | Y6: =G5+H5-I5 -> 0
F7: =IF(E7>0,E7-D7,"") | X7: =E6 -> 0 | Y7: =G6+H6-I6 -> 0
A8: Terminas | B8: =DATEDIF(B9,B11,"y") & " m. " & DATEDIF(B9,B11,"ym") & " mėn. " & DATEDIF(B9,B11,"md") & " d." -> 0 m. 11 mėn. 26 d. | F8: =IF(E8>0,E8-D8,"") | X8: =E7 -> 0 | Y8: =G7+H7-I7 -> 0
A9: Investuota | B9: 46260 | X9: =E8 -> 0 | Y9: =G8+H8-I8 -> 0
A10: Pradžia | B10: 46255 | F10: =IF(E10>0,E10-D10,"") | X10: =E9 -> 0 | Y10: =G9+H9-I9 -> 0
A11: Pabaiga | B11: 46620 | F11: =IF(E11>0,E11-D11,"") | X11: =E10 -> 0 | Y11: =G10+H10-I10 -> 0
A12: Liko, dienos | B12: =IF(B16<>K3,(TODAY()-B11)*-1,"") -> 325 | F12: =IF(E12>0,E12-D12,"") | X12: =E11 -> 0 | Y12: =G11+H11-I11 -> 0
F13: =IF(E13>0,E13-D13,"") | X13: =E12 -> 0 | Y13: =G12+H12-I12 -> 0
F14: =IF(E14>0,E14-D14,"") | X14: =E13 -> 0 | Y14: =G13+H13-I13 -> 0
A15: Palūkanos | B15: 0.1225 | F15: =IF(E15>0,E15-D15,"") | X15: =E14 -> 0 | Y15: =G14+H14-I14 -> 0
A16: Investuota, Eur | B16: 26.67 | F16: =IF(E16>0,E16-D16,"") | X16: =E15 -> 0 | Y16: =G15+H15-I15 -> 0
F17: =IF(E17>0,E17-D17,"") | X17: =E16 -> 0 | Y17: =G16+H16-I16 -> 0
F18: =IF(E18>0,E18-D18,"") | X18: =E17 -> 0 | Y18: =G17+H17-I17 -> 0
F19: =IF(E19>0,E19-D19,"") | X19: =E18 -> 0 | Y19: =G18+H18-I18 -> 0
F20: =IF(E20>0,E20-D20,"") | X20: =E19 -> 0 | Y20: =G19+H19-I19 -> 0
F21: =IF(E21>0,E21-D21,"") | X21: =E20 -> 0 | Y21: =G20+H20-I20 -> 0
F22: =IF(E22>0,E22-D22,"") | X22: =E21 -> 0 | Y22: =G21+H21-I21 -> 0
F23: =IF(E23>0,E23-D23,"") | X23: =E22 -> 0 | Y23: =G22+H22-I22 -> 0
F24: =IF(E24>0,E24-D24,"") | X24: =E23 -> 0 | Y24: =G23+H23-I23 -> 0
F25: =IF(E25>0,E25-D25,"") | X25: =E24 -> 0 | Y25: =G24+H24-I24 -> 0
F26: =IF(E26>0,E26-D26,"") | X26: =E25 -> 0 | Y26: =G25+H25-I25 -> 0
F27: =IF(E27>0,E27-D27,"") | X27: =E26 -> 0 | Y27: =G26+H26-I26 -> 0
F28: =IF(E28>0,E28-D28,"") | X28: =E27 -> 0 | Y28: =G27+H27-I27 -> 0
... F52: =IF(E52>0,E52-D52,"") | X52: =E51 -> 0 | Y52: =G51+H51-I51 -> 0
D53: Viso: | G53: =SUM(G3:G52) -> 0 | H53: =SUM(H3:H52) -> 0.13 | I53: =SUM(I3:I52) -> 0

Sheet LVX0000VG7N1
A1: Loan ID | B1: LVX0000VG7N1 | D1: Data | G1: Paskola | K1: Grąžinimas
A2: Šalis | B2: Philippines | D2: Planuojama | E2: Reali | F2: Vėl./Anks. | G2: Principal | H2: Interest | I2: Mokestis | K2: Paskola | L2: Palūkanos | M2: Mokesčiai | N2: XIRR | O2: Data | P2: Vėluoja | Q2: Vėl./Anks. | X2: Data | Y2: Suma | Z2: Vėluoja
A3: Skolintojas | B3: SIA "Abele Finance" | D3: 46265 | E3: 46265 | F3: =IF(E3>0,E3-D3,"") -> 0 | G3: 0 | H3: 0 | I3: 0 | K3: =G53 -> 0 | L3: =H53 -> 0.09 | M3: =I53 -> 0 | N3: =IF(B16=K3,XIRR(Y3:Y52,X3:X52),"") | O3: =IF(B16=K3,MAX(E:E),"") | P3: =IF(Z3="+",TODAY()-B11,"") | Q3: =IF(B16=K3,MAX(E:E)-B11,"") | X3: =B9 -> 46260 | Y3: =B16*-1 -> -20 | Z3: =IF(AND(TODAY()>B11, K3<>B16), "+", "")
A4: Tipas | B4: Business | D4: 46295 | E4: 46295 | F4: =IF(E4>0,E4-D4,"") -> 0 | G4: 0 | H4: 0.09 | I4: 0 | X4: =E3 -> 46265 | Y4: =G3+H3-I3 -> 0
F5: =IF(E5>0,E5-D5,"") | X5: =E4 -> 46295 | Y5: =G4+H4-I4 -> 0.09
F6: =IF(E6>0,E6-D6,"") | X6: =E5 -> 0 | Y6: =G5+H5-I5 -> 0
F7: =IF(E7>0,E7-D7,"") | X7: =E6 -> 0 | Y7: =G6+H6-I6 -> 0
A8: Terminas | B8: =DATEDIF(B9,B11,"y") & " m. " & DATEDIF(B9,B11,"ym") & " mėn. " & DATEDIF(B9,B11,"md") & " d." -> 0 m. 8 mėn. 22 d. | F8: =IF(E8>0,E8-D8,"") | X8: =E7 -> 0 | Y8: =G7+H7-I7 -> 0
A9: Investuota | B9: 46260 | X9: =E8 -> 0 | Y9: =G8+H8-I8 -> 0
A10: Pradžia | B10: 46252 | F10: =IF(E10>0,E10-D10,"") | X10: =E9 -> 0 | Y10: =G9+H9-I9 -> 0
A11: Pabaiga | B11: 46525 | F11: =IF(E11>0,E11-D11,"") | X11: =E10 -> 0 | Y11: =G10+H10-I10 -> 0
A12: Liko, dienos | B12: =IF(B16<>K3,(TODAY()-B11)*-1,"") -> 230 | F12: =IF(E12>0,E12-D12,"") | X12: =E11 -> 0 | Y12: =G11+H11-I11 -> 0
F13: =IF(E13>0,E13-D13,"") | X13: =E12 -> 0 | Y13: =G12+H12-I12 -> 0
F14: =IF(E14>0,E14-D14,"") | X14: =E13 -> 0 | Y14: =G13+H13-I13 -> 0
A15: Palūkanos | B15: 0.12 | F15: =IF(E15>0,E15-D15,"") | X15: =E14 -> 0 | Y15: =G14+H14-I14 -> 0
A16: Investuota, Eur | B16: 20 | F16: =IF(E16>0,E16-D16,"") | X16: =E15 -> 0 | Y16: =G15+H15-I15 -> 0
F17: =IF(E17>0,E17-D17,"") | X17: =E16 -> 0 | Y17: =G16+H16-I16 -> 0
F18: =IF(E18>0,E18-D18,"") | X18: =E17 -> 0 | Y18: =G17+H17-I17 -> 0
F19: =IF(E19>0,E19-D19,"") | X19: =E18 -> 0 | Y19: =G18+H18-I18 -> 0
F20: =IF(E20>0,E20-D20,"") | X20: =E19 -> 0 | Y20: =G19+H19-I19 -> 0
F21: =IF(E21>0,E21-D21,"") | X21: =E20 -> 0 | Y21: =G20+H20-I20 -> 0
F22: =IF(E22>0,E22-D22,"") | X22: =E21 -> 0 | Y22: =G21+H21-I21 -> 0
F23: =IF(E23>0,E23-D23,"") | X23: =E22 -> 0 | Y23: =G22+H22-I22 -> 0
F24: =IF(E24>0,E24-D24,"") | X24: =E23 -> 0 | Y24: =G23+H23-I23 -> 0
F25: =IF(E25>0,E25-D25,"") | X25: =E24 -> 0 | Y25: =G24+H24-I24 -> 0
F26: =IF(E26>0,E26-D26,"") | X26: =E25 -> 0 | Y26: =G25+H25-I25 -> 0
F27: =IF(E27>0,E27-D27,"") | X27: =E26 -> 0 | Y27: =G26+H26-I26 -> 0
F28: =IF(E28>0,E28-D28,"") | X28: =E27 -> 0 | Y28: =G27+H27-I27 -> 0
... F52: =IF(E52>0,E52-D52,"") | X52: =E51 -> 0 | Y52: =G51+H51-I51 -> 0
D53: Viso: | G53: =SUM(G3:G52) -> 0 | H53: =SUM(H3:H52) -> 0.09 | I53: =SUM(I3:I52) -> 0

Sheet LVX0000VG7G5
A1: Loan ID | B1: LVX0000VG7G5 | D1: Data | G1: Paskola | K1: Grąžinimas
A2: Šalis | B2: Cyprus | D2: Planuojama | E2: Reali | F2: Vėl./Anks. | G2: Principal | H2: Interest | I2: Mokestis | K2: Paskola | L2: Palūkanos | M2: Mokesčiai | N2: XIRR | O2: Data | P2: Vėluoja | Q2: Vėl./Anks. | X2: Data | Y2: Suma | Z2: Vėluoja
A3: Skolintojas | B3: SIA "Abele Finance" | D3: 46265 | E3: 46265 | F3: =IF(E3>0,E3-D3,"") -> 0 | G3: 0 | H3: 0 | I3: 0 | K3: =G53 -> 0 | L3: =H53 -> 0.1 | M3: =I53 -> 0 | N3: =IF(B16=K3,XIRR(Y3:Y52,X3:X52),"") | O3: =IF(B16=K3,MAX(E:E),"") | P3: =IF(Z3="+",TODAY()-B11,"") | Q3: =IF(B16=K3,MAX(E:E)-B11,"") | X3: =B9 -> 46260 | Y3: =B16*-1 -> -20 | Z3: =IF(AND(TODAY()>B11, K3<>B16), "+", "")
A4: Tipas | B4: Business | D4: 46295 | E4: 46295 | F4: =IF(E4>0,E4-D4,"") -> 0 | G4: 0 | H4: 0.1 | I4: 0 | X4: =E3 -> 46265 | Y4: =G3+H3-I3 -> 0
F5: =IF(E5>0,E5-D5,"") | X5: =E4 -> 46295 | Y5: =G4+H4-I4 -> 0.1
F6: =IF(E6>0,E6-D6,"") | X6: =E5 -> 0 | Y6: =G5+H5-I5 -> 0
F7: =IF(E7>0,E7-D7,"") | X7: =E6 -> 0 | Y7: =G6+H6-I6 -> 0
A8: Terminas | B8: =DATEDIF(B9,B11,"y") & " m. " & DATEDIF(B9,B11,"ym") & " mėn. " & DATEDIF(B9,B11,"md") & " d." -> 0 m. 11 mėn. 23 d. | F8: =IF(E8>0,E8-D8,"") | X8: =E7 -> 0 | Y8: =G7+H7-I7 -> 0
A9: Investuota | B9: 46260 | X9: =E8 -> 0 | Y9: =G8+H8-I8 -> 0
A10: Pradžia | B10: 46252 | F10: =IF(E10>0,E10-D10,"") | X10: =E9 -> 0 | Y10: =G9+H9-I9 -> 0
A11: Pabaiga | B11: 46617 | F11: =IF(E11>0,E11-D11,"") | X11: =E10 -> 0 | Y11: =G10+H10-I10 -> 0
A12: Liko, dienos | B12: =IF(B16<>K3,(TODAY()-B11)*-1,"") -> 322 | F12: =IF(E12>0,E12-D12,"") | X12: =E11 -> 0 | Y12: =G11+H11-I11 -> 0
F13: =IF(E13>0,E13-D13,"") | X13: =E12 -> 0 | Y13: =G12+H12-I12 -> 0
F14: =IF(E14>0,E14-D14,"") | X14: =E13 -> 0 | Y14: =G13+H13-I13 -> 0
A15: Palūkanos | B15: 0.13 | F15: =IF(E15>0,E15-D15,"") | X15: =E14 -> 0 | Y15: =G14+H14-I14 -> 0
A16: Investuota, Eur | B16: 20 | F16: =IF(E16>0,E16-D16,"") | X16: =E15 -> 0 | Y16: =G15+H15-I15 -> 0
F17: =IF(E17>0,E17-D17,"") | X17: =E16 -> 0 | Y17: =G16+H16-I16 -> 0
F18: =IF(E18>0,E18-D18,"") | X18: =E17 -> 0 | Y18: =G17+H17-I17 -> 0
F19: =IF(E19>0,E19-D19,"") | X19: =E18 -> 0 | Y19: =G18+H18-I18 -> 0
F20: =IF(E20>0,E20-D20,"") | X20: =E19 -> 0 | Y20: =G19+H19-I19 -> 0
F21: =IF(E21>0,E21-D21,"") | X21: =E20 -> 0 | Y21: =G20+H20-I20 -> 0
F22: =IF(E22>0,E22-D22,"") | X22: =E21 -> 0 | Y22: =G21+H21-I21 -> 0
F23: =IF(E23>0,E23-D23,"") | X23: =E22 -> 0 | Y23: =G22+H22-I22 -> 0
F24: =IF(E24>0,E24-D24,"") | X24: =E23 -> 0 | Y24: =G23+H23-I23 -> 0
F25: =IF(E25>0,E25-D25,"") | X25: =E24 -> 0 | Y25: =G24+H24-I24 -> 0
F26: =IF(E26>0,E26-D26,"") | X26: =E25 -> 0 | Y26: =G25+H25-I25 -> 0
F27: =IF(E27>0,E27-D27,"") | X27: =E26 -> 0 | Y27: =G26+H26-I26 -> 0
F28: =IF(E28>0,E28-D28,"") | X28: =E27 -> 0 | Y28: =G27+H27-I27 -> 0
... F52: =IF(E52>0,E52-D52,"") | X52: =E51 -> 0 | Y52: =G51+H51-I51 -> 0
D53: Viso: | G53: =SUM(G3:G52) -> 0 | H53: =SUM(H3:H52) -> 0.1 | I53: =SUM(I3:I52) -> 0

Sheet LVX0000VDGZ2
A1: Loan ID | B1: LVX0000VDGZ2 | D1: Data | G1: Paskola | K1: Grąžinimas
A2: Šalis | B2: Philippines | D2: Planuojama | E2: Reali | F2: Vėl./Anks. | G2: Principal | H2: Interest | I2: Mokestis | K2: Paskola | L2: Palūkanos | M2: Mokesčiai | N2: XIRR | O2: Data | P2: Vėluoja | Q2: Vėl./Anks. | X2: Data | Y2: Suma | Z2: Vėluoja
A3: Skolintojas | B3: SIA "Abele Finance" | D3: 46265 | E3: 46265 | F3: =IF(E3>0,E3-D3,"") -> 0 | G3: 0 | H3: 0 | I3: 0 | K3: =G53 -> 0 | L3: =H53 -> 0.08 | M3: =I53 -> 0 | N3: =IF(B16=K3,XIRR(Y3:Y52,X3:X52),"") | O3: =IF(B16=K3,MAX(E:E),"") | P3: =IF(Z3="+",TODAY()-B11,"") | Q3: =IF(B16=K3,MAX(E:E)-B11,"") | X3: =B9 -> 46253 | Y3: =B16*-1 -> -11.01 | Z3: =IF(AND(TODAY()>B11, K3<>B16), "+", "")
A4: Tipas | B4: Business | D4: 46295 | E4: 46295 | F4: =IF(E4>0,E4-D4,"") -> 0 | G4: 0 | H4: 0.08 | I4: 0 | X4: =E3 -> 46265 | Y4: =G3+H3-I3 -> 0
F5: =IF(E5>0,E5-D5,"") | X5: =E4 -> 46295 | Y5: =G4+H4-I4 -> 0.08
F6: =IF(E6>0,E6-D6,"") | X6: =E5 -> 0 | Y6: =G5+H5-I5 -> 0
F7: =IF(E7>0,E7-D7,"") | X7: =E6 -> 0 | Y7: =G6+H6-I6 -> 0
A8: Terminas | B8: =DATEDIF(B9,B11,"y") & " m. " & DATEDIF(B9,B11,"ym") & " mėn. " & DATEDIF(B9,B11,"md") & " d." -> 0 m. 8 mėn. 25 d. | F8: =IF(E8>0,E8-D8,"") | X8: =E7 -> 0 | Y8: =G7+H7-I7 -> 0
A9: Investuota | B9: 46253 | X9: =E8 -> 0 | Y9: =G8+H8-I8 -> 0
A10: Pradžia | B10: 46246 | F10: =IF(E10>0,E10-D10,"") | X10: =E9 -> 0 | Y10: =G9+H9-I9 -> 0
A11: Pabaiga | B11: 46521 | F11: =IF(E11>0,E11-D11,"") | X11: =E10 -> 0 | Y11: =G10+H10-I10 -> 0
A12: Liko, dienos | B12: =IF(B16<>K3,(TODAY()-B11)*-1,"") -> 226 | F12: =IF(E12>0,E12-D12,"") | X12: =E11 -> 0 | Y12: =G11+H11-I11 -> 0
F13: =IF(E13>0,E13-D13,"") | X13: =E12 -> 0 | Y13: =G12+H12-I12 -> 0
F14: =IF(E14>0,E14-D14,"") | X14: =E13 -> 0 | Y14: =G13+H13-I13 -> 0
A15: Palūkanos | B15: 0.12 | F15: =IF(E15>0,E15-D15,"") | X15: =E14 -> 0 | Y15: =G14+H14-I14 -> 0
A16: Investuota, Eur | B16: 11.01 | F16: =IF(E16>0,E16-D16,"") | X16: =E15 -> 0 | Y16: =G15+H15-I15 -> 0
F17: =IF(E17>0,E17-D17,"") | X17: =E16 -> 0 | Y17: =G16+H16-I16 -> 0
F18: =IF(E18>0,E18-D18,"") | X18: =E17 -> 0 | Y18: =G17+H17-I17 -> 0
F19: =IF(E19>0,E19-D19,"") | X19: =E18 -> 0 | Y19: =G18+H18-I18 -> 0
F20: =IF(E20>0,E20-D20,"") | X20: =E19 -> 0 | Y20: =G19+H19-I19 -> 0
F21: =IF(E21>0,E21-D21,"") | X21: =E20 -> 0 | Y21: =G20+H20-I20 -> 0
F22: =IF(E22>0,E22-D22,"") | X22: =E21 -> 0 | Y22: =G21+H21-I21 -> 0
F23: =IF(E23>0,E23-D23,"") | X23: =E22 -> 0 | Y23: =G22+H22-I22 -> 0
F24: =IF(E24>0,E24-D24,"") | X24: =E23 -> 0 | Y24: =G23+H23-I23 -> 0
F25: =IF(E25>0,E25-D25,"") | X25: =E24 -> 0 | Y25: =G24+H24-I24 -> 0
F26: =IF(E26>0,E26-D26,"") | X26: =E25 -> 0 | Y26: =G25+H25-I25 -> 0
F27: =IF(E27>0,E27-D27,"") | X27: =E26 -> 0 | Y27: =G26+H26-I26 -> 0
F28: =IF(E28>0,E28-D28,"") | X28: =E27 -> 0 | Y28: =G27+H27-I27 -> 0
... F52: =IF(E52>0,E52-D52,"") | X52: =E51 -> 0 | Y52: =G51+H51-I51 -> 0
D53: Viso: | G53: =SUM(G3:G52) -> 0 | H53: =SUM(H3:H52) -> 0.08 | I53: =SUM(I3:I52) -> 0

Sheet LVX0000V0S54
A1: Loan ID | B1: LVX0000V0S54 | D1: Data | G1: Paskola | K1: Grąžinimas
A2: Šalis | B2: Cyprus | D2: Planuojama | E2: Reali | F2: Vėl./Anks. | G2: Principal | H2: Interest | I2: Mokestis | K2: Paskola | L2: Palūkanos | M2: Mokesčiai | N2: XIRR | O2: Data | P2: Vėluoja | Q2: Vėl./Anks. | X2: Data | Y2: Suma | Z2: Vėluoja
A3: Skolintojas | B3: SIA "Abele Finance" | D3: 46265 | E3: 46265 | F3: =IF(E3>0,E3-D3,"") -> 0 | G3: 0 | H3: 0 | I3: 0 | K3: =G53 -> 0 | L3: =H53 -> 0.11 | M3: =I53 -> 0 | N3: =IF(B16=K3,XIRR(Y3:Y52,X3:X52),"") | O3: =IF(B16=K3,MAX(E:E),"") | P3: =IF(Z3="+",TODAY()-B11,"") | Q3: =IF(B16=K3,MAX(E:E)-B11,"") | X3: =B9 -> 46244 | Y3: =B16*-1 -> -10.84 | Z3: =IF(AND(TODAY()>B11, K3<>B16), "+", "")
A4: Tipas | B4: Business | D4: 46295 | E4: 46295 | F4: =IF(E4>0,E4-D4,"") -> 0 | G4: 0 | H4: 0.11 | I4: 0 | X4: =E3 -> 46265 | Y4: =G3+H3-I3 -> 0
F5: =IF(E5>0,E5-D5,"") | X5: =E4 -> 46295 | Y5: =G4+H4-I4 -> 0.11
F6: =IF(E6>0,E6-D6,"") | X6: =E5 -> 0 | Y6: =G5+H5-I5 -> 0
F7: =IF(E7>0,E7-D7,"") | X7: =E6 -> 0 | Y7: =G6+H6-I6 -> 0
A8: Terminas | B8: =DATEDIF(B9,B11,"y") & " m. " & DATEDIF(B9,B11,"ym") & " mėn. " & DATEDIF(B9,B11,"md") & " d." -> 0 m. 7 mėn. 25 d. | F8: =IF(E8>0,E8-D8,"") | X8: =E7 -> 0 | Y8: =G7+H7-I7 -> 0
A9: Investuota | B9: 46244 | X9: =E8 -> 0 | Y9: =G8+H8-I8 -> 0
A10: Pradžia | B10: 46211 | F10: =IF(E10>0,E10-D10,"") | X10: =E9 -> 0 | Y10: =G9+H9-I9 -> 0
A11: Pabaiga | B11: 46481 | F11: =IF(E11>0,E11-D11,"") | X11: =E10 -> 0 | Y11: =G10+H10-I10 -> 0
A12: Liko, dienos | B12: =IF(B16<>K3,(TODAY()-B11)*-1,"") -> 186 | F12: =IF(E12>0,E12-D12,"") | X12: =E11 -> 0 | Y12: =G11+H11-I11 -> 0
F13: =IF(E13>0,E13-D13,"") | X13: =E12 -> 0 | Y13: =G12+H12-I12 -> 0
F14: =IF(E14>0,E14-D14,"") | X14: =E13 -> 0 | Y14: =G13+H13-I13 -> 0
A15: Palūkanos | B15: 0.125 | F15: =IF(E15>0,E15-D15,"") | X15: =E14 -> 0 | Y15: =G14+H14-I14 -> 0
A16: Investuota, Eur | B16: 10.84 | F16: =IF(E16>0,E16-D16,"") | X16: =E15 -> 0 | Y16: =G15+H15-I15 -> 0
F17: =IF(E17>0,E17-D17,"") | X17: =E16 -> 0 | Y17: =G16+H16-I16 -> 0
F18: =IF(E18>0,E18-D18,"") | X18: =E17 -> 0 | Y18: =G17+H17-I17 -> 0
F19: =IF(E19>0,E19-D19,"") | X19: =E18 -> 0 | Y19: =G18+H18-I18 -> 0
F20: =IF(E20>0,E20-D20,"") | X20: =E19 -> 0 | Y20: =G19+H19-I19 -> 0
F21: =IF(E21>0,E21-D21,"") | X21: =E20 -> 0 | Y21: =G20+H20-I20 -> 0
F22: =IF(E22>0,E22-D22,"") | X22: =E21 -> 0 | Y22: =G21+H21-I21 -> 0
F23: =IF(E23>0,E23-D23,"") | X23: =E22 -> 0 | Y23: =G22+H22-I22 -> 0
F24: =IF(E24>0,E24-D24,"") | X24: =E23 -> 0 | Y24: =G23+H23-I23 -> 0
F25: =IF(E25>0,E25-D25,"") | X25: =E24 -> 0 | Y25: =G24+H24-I24 -> 0
F26: =IF(E26>0,E26-D26,"") | X26: =E25 -> 0 | Y26: =G25+H25-I25 -> 0
F27: =IF(E27>0,E27-D27,"") | X27: =E26 -> 0 | Y27: =G26+H26-I26 -> 0
F28: =IF(E28>0,E28-D28,"") | X28: =E27 -> 0 | Y28: =G27+H27-I27 -> 0
... F52: =IF(E52>0,E52-D52,"") | X52: =E51 -> 0 | Y52: =G51+H51-I51 -> 0
D53: Viso: | G53: =SUM(G3:G52) -> 0 | H53: =SUM(H3:H52) -> 0.11 | I53: =SUM(I3:I52) -> 0

Sheet LVX0000V3XU4
A1: Loan ID | B1: LVX0000V3XU4 | D1: Data | G1: Paskola | K1: Grąžinimas
A2: Šalis | B2: Romania | D2: Planuojama | E2: Reali | F2: Vėl./Anks. | G2: Principal | H2: Interest | I2: Mokestis | K2: Paskola | L2: Palūkanos | M2: Mokesčiai | N2: XIRR | O2: Data | P2: Vėluoja | Q2: Vėl./Anks. | X2: Data | Y2: Suma | Z2: Vėluoja
A3: Skolintojas | B3: ECOFINANCE IFN SA | D3: 46234 | E3: 46234 | F3: =IF(E3>0,E3-D3,"") -> 0 | G3: 1.13 | H3: 0.03 | I3: 0 | K3: =G53 -> 19.43 | L3: =H53 -> 0.18 | M3: =I53 -> 0.01 | N3: =IF(B16=K3,XIRR(Y3:Y52,X3:X52),"") -> 0.080870053 | O3: =IF(B16=K3,MAX(E:E),"") -> 46290 | P3: =IF(Z3="+",TODAY()-B11,"") | Q3: =IF(B16=K3,MAX(E:E)-B11,"") -> -577 | X3: =B9 -> 46226 | Y3: =B16*-1 -> -19.43 | Z3: =IF(AND(TODAY()>B11, K3<>B16), "+", "")
A4: Tipas | B4: Personal | D4: 46265 | E4: 46265 | F4: =IF(E4>0,E4-D4,"") -> 0 | G4: 15.4 | H4: 0.12 | I4: 0.01 | X4: =E3 -> 46234 | Y4: =G3+H3-I3 -> 1.16
D5: 46290 | E5: 46290 | F5: =IF(E5>0,E5-D5,"") -> 0 | G5: 2.9 | H5: 0.03 | I5: 0 | X5: =E4 -> 46265 | Y5: =G4+H4-I4 -> 15.51
F6: =IF(E6>0,E6-D6,"") | X6: =E5 -> 46290 | Y6: =G5+H5-I5 -> 2.93
F7: =IF(E7>0,E7-D7,"") | X7: =E6 -> 0 | Y7: =G6+H6-I6 -> 0
A8: Terminas | B8: =DATEDIF(B9,B11,"y") & " m. " & DATEDIF(B9,B11,"ym") & " mėn. " & DATEDIF(B9,B11,"md") & " d." -> 1 m. 9 mėn. 1 d. | F8: =IF(E8>0,E8-D8,"") | X8: =E7 -> 0 | Y8: =G7+H7-I7 -> 0
A9: Investuota | B9: 46226 | X9: =E8 -> 0 | Y9: =G8+H8-I8 -> 0
A10: Pradžia | B10: 46219 | F10: =IF(E10>0,E10-D10,"") | X10: =E9 -> 0 | Y10: =G9+H9-I9 -> 0
A11: Pabaiga | B11: 46867 | F11: =IF(E11>0,E11-D11,"") | X11: =E10 -> 0 | Y11: =G10+H10-I10 -> 0
A12: Liko, dienos | B12: =IF(B16<>K3,(TODAY()-B11)*-1,"") | F12: =IF(E12>0,E12-D12,"") | X12: =E11 -> 0 | Y12: =G11+H11-I11 -> 0
F13: =IF(E13>0,E13-D13,"") | X13: =E12 -> 0 | Y13: =G12+H12-I12 -> 0
F14: =IF(E14>0,E14-D14,"") | X14: =E13 -> 0 | Y14: =G13+H13-I13 -> 0
A15: Palūkanos | B15: 0.125 | F15: =IF(E15>0,E15-D15,"") | X15: =E14 -> 0 | Y15: =G14+H14-I14 -> 0
A16: Investuota, Eur | B16: 19.43 | F16: =IF(E16>0,E16-D16,"") | X16: =E15 -> 0 | Y16: =G15+H15-I15 -> 0
F17: =IF(E17>0,E17-D17,"") | X17: =E16 -> 0 | Y17: =G16+H16-I16 -> 0
F18: =IF(E18>0,E18-D18,"") | X18: =E17 -> 0 | Y18: =G17+H17-I17 -> 0
F19: =IF(E19>0,E19-D19,"") | X19: =E18 -> 0 | Y19: =G18+H18-I18 -> 0
F20: =IF(E20>0,E20-D20,"") | X20: =E19 -> 0 | Y20: =G19+H19-I19 -> 0
F21: =IF(E21>0,E21-D21,"") | X21: =E20 -> 0 | Y21: =G20+H20-I20 -> 0
F22: =IF(E22>0,E22-D22,"") | X22: =E21 -> 0 | Y22: =G21+H21-I21 -> 0
F23: =IF(E23>0,E23-D23,"") | X23: =E22 -> 0 | Y23: =G22+H22-I22 -> 0
F24: =IF(E24>0,E24-D24,"") | X24: =E23 -> 0 | Y24: =G23+H23-I23 -> 0
F25: =IF(E25>0,E25-D25,"") | X25: =E24 -> 0 | Y25: =G24+H24-I24 -> 0
F26: =IF(E26>0,E26-D26,"") | X26: =E25 -> 0 | Y26: =G25+H25-I25 -> 0
F27: =IF(E27>0,E27-D27,"") | X27: =E26 -> 0 | Y27: =G26+H26-I26 -> 0
F28: =IF(E28>0,E28-D28,"") | X28: =E27 -> 0 | Y28: =G27+H27-I27 -> 0
... F52: =IF(E52>0,E52-D52,"") | X52: =E51 -> 0 | Y52: =G51+H51-I51 -> 0
D53: Viso: | G53: =SUM(G3:G52) -> 19.43 | H53: =SUM(H3:H52) -> 0.18 | I53: =SUM(I3:I52) -> 0.01

Sheet LVX0000UXVI7
A1: Loan ID | B1: LVX0000UXVI7 | D1: Data | G1: Paskola | K1: Grąžinimas
A2: Šalis | B2: Latvia | D2: Planuojama | E2: Reali | F2: Vėl./Anks. | G2: Principal | H2: Interest | I2: Mokestis | K2: Paskola | L2: Palūkanos | M2: Mokesčiai | N2: XIRR | O2: Data | P2: Vėluoja | Q2: Vėl./Anks. | X2: Data | Y2: Suma | Z2: Vėluoja
A3: Skolintojas | B3: SIA "Abele Finance" | D3: 46234 | E3: 46234 | F3: =IF(E3>0,E3-D3,"") -> 0 | G3: 0 | H3: 0 | I3: 0 | K3: =G53 -> 0 | L3: =H53 -> 0.26 | M3: =I53 -> 0 | N3: =IF(B16=K3,XIRR(Y3:Y52,X3:X52),"") | O3: =IF(B16=K3,MAX(E:E),"") | P3: =IF(Z3="+",TODAY()-B11,"") | Q3: =IF(B16=K3,MAX(E:E)-B11,"") | X3: =B9 -> 46219 | Y3: =B16*-1 -> -15.29 | Z3: =IF(AND(TODAY()>B11, K3<>B16), "+", "")
A4: Tipas | B4: Business | D4: 46265 | E4: 46265 | F4: =IF(E4>0,E4-D4,"") -> 0 | G4: 0 | H4: 0.11 | I4: 0 | X4: =E3 -> 46234 | Y4: =G3+H3-I3 -> 0
D5: 46295 | E5: 46295 | F5: =IF(E5>0,E5-D5,"") -> 0 | G5: 0 | H5: 0.15 | I5: 0 | X5: =E4 -> 46265 | Y5: =G4+H4-I4 -> 0.11
F6: =IF(E6>0,E6-D6,"") | X6: =E5 -> 46295 | Y6: =G5+H5-I5 -> 0.15
F7: =IF(E7>0,E7-D7,"") | X7: =E6 -> 0 | Y7: =G6+H6-I6 -> 0
A8: Terminas | B8: =DATEDIF(B9,B11,"y") & " m. " & DATEDIF(B9,B11,"ym") & " mėn. " & DATEDIF(B9,B11,"md") & " d." -> 0 m. 7 mėn. 12 d. | F8: =IF(E8>0,E8-D8,"") | X8: =E7 -> 0 | Y8: =G7+H7-I7 -> 0
A9: Investuota | B9: 46219 | X9: =E8 -> 0 | Y9: =G8+H8-I8 -> 0
A10: Pradžia | B10: 46204 | F10: =IF(E10>0,E10-D10,"") | X10: =E9 -> 0 | Y10: =G9+H9-I9 -> 0
A11: Pabaiga | B11: 46446 | F11: =IF(E11>0,E11-D11,"") | X11: =E10 -> 0 | Y11: =G10+H10-I10 -> 0
A12: Liko, dienos | B12: =IF(B16<>K3,(TODAY()-B11)*-1,"") -> 151 | F12: =IF(E12>0,E12-D12,"") | X12: =E11 -> 0 | Y12: =G11+H11-I11 -> 0
F13: =IF(E13>0,E13-D13,"") | X13: =E12 -> 0 | Y13: =G12+H12-I12 -> 0
F14: =IF(E14>0,E14-D14,"") | X14: =E13 -> 0 | Y14: =G13+H13-I13 -> 0
A15: Palūkanos | B15: 0.11 | F15: =IF(E15>0,E15-D15,"") | X15: =E14 -> 0 | Y15: =G14+H14-I14 -> 0
A16: Investuota, Eur | B16: 15.29 | F16: =IF(E16>0,E16-D16,"") | X16: =E15 -> 0 | Y16: =G15+H15-I15 -> 0
F17: =IF(E17>0,E17-D17,"") | X17: =E16 -> 0 | Y17: =G16+H16-I16 -> 0
F18: =IF(E18>0,E18-D18,"") | X18: =E17 -> 0 | Y18: =G17+H17-I17 -> 0
F19: =IF(E19>0,E19-D19,"") | X19: =E18 -> 0 | Y19: =G18+H18-I18 -> 0
F20: =IF(E20>0,E20-D20,"") | X20: =E19 -> 0 | Y20: =G19+H19-I19 -> 0
F21: =IF(E21>0,E21-D21,"") | X21: =E20 -> 0 | Y21: =G20+H20-I20 -> 0
F22: =IF(E22>0,E22-D22,"") | X22: =E21 -> 0 | Y22: =G21+H21-I21 -> 0
F23: =IF(E23>0,E23-D23,"") | X23: =E22 -> 0 | Y23: =G22+H22-I22 -> 0
F24: =IF(E24>0,E24-D24,"") | X24: =E23 -> 0 | Y24: =G23+H23-I23 -> 0
F25: =IF(E25>0,E25-D25,"") | X25: =E24 -> 0 | Y25: =G24+H24-I24 -> 0
F26: =IF(E26>0,E26-D26,"") | X26: =E25 -> 0 | Y26: =G25+H25-I25 -> 0
F27: =IF(E27>0,E27-D27,"") | X27: =E26 -> 0 | Y27: =G26+H26-I26 -> 0
F28: =IF(E28>0,E28-D28,"") | X28: =E27 -> 0 | Y28: =G27+H27-I27 -> 0
... F52: =IF(E52>0,E52-D52,"") | X52: =E51 -> 0 | Y52: =G51+H51-I51 -> 0
D53: Viso: | G53: =SUM(G3:G52) -> 0 | H53: =SUM(H3:H52) -> 0.26 | I53: =SUM(I3:I52) -> 0

Sheet LVX0000UXVE6
A1: Loan ID | B1: LVX0000UXVE6 | D1: Data | G1: Paskola | K1: Grąžinimas
A2: Šalis | B2: Latvia | D2: Planuojama | E2: Reali | F2: Vėl./Anks. | G2: Principal | H2: Interest | I2: Mokestis | K2: Paskola | L2: Palūkanos | M2: Mokesčiai | N2: XIRR | O2: Data | P2: Vėluoja | Q2: Vėl./Anks. | X2: Data | Y2: Suma | Z2: Vėluoja
