Workbook

Sheet Apžvalga
A1: Paskola | H1: Grąžinimas | O1: Pinigai | S1: Grąžinta | U1: Vertė
A2: Nr. | B2: Data | C2: Pavadinimas | D2: Laikotarpis | E2: Reitingas | F2: Palūkanos | G2: Investuota | H2: Planuojamas | I2: Realus | J2: Liko | K2: Vėluoja | L2: Paskola | M2: Palūkanos | O2: Įnešta | P2: Investuota | Q2: Premijos | R2: Gryni | S2: Paskola | T2: Palūkanos | U2: Viso | V2: Eur. | W2: % | X2: XIRR | AC2: Vėluoja
A3: 1 | B3: ='Mesiheina tee 5 ir 8 (1)'!B4 -> 45716 | C3: ='Mesiheina tee 5 ir 8 (1)'!B2 -> Mesiheina tee 5 ir 8, Pärnu miestas, Estija (1 etapas) | D3: ='Mesiheina tee 5 ir 8 (1)'!B8 -> 14 | E3: ='Mesiheina tee 5 ir 8 (1)'!B5 -> B | F3: ='Mesiheina tee 5 ir 8 (1)'!B10 -> 0.13 | G3: ='Mesiheina tee 5 ir 8 (1)'!B11 -> 50 | H3: ='Mesiheina tee 5 ir 8 (1)'!B12 -> 46140 | I3: ='Mesiheina tee 5 ir 8 (1)'!R3 -> 46140 | J3: ='Mesiheina tee 5 ir 8 (1)'!B13 | K3: ='Mesiheina tee 5 ir 8 (1)'!S3 | L3: ='Mesiheina tee 5 ir 8 (1)'!N3 -> 50 | M3: ='Mesiheina tee 5 ir 8 (1)'!P3 -> 7.54 | O3: =Pinigai!I2 -> 854.83 | P3: =SUM(G3:G200)-S3 -> 1023.79 | Q3: =Pinigai!H2 -> 48.94 | R3: =U3-P3 -> 9.91 | S3: =SUM(L3:L200) -> 432.21 | T3: =SUM(M3:M200) -> 129.93 | U3: =O3+T3+Q3 -> 1033.7 | V3: =U3-O3 -> 178.87 | W3: =(U3-O3)/O3 -> 0.20924628 | X3: =XIRR(Pinigai!K2:K200,Pinigai!A2:A200) -> 0.14506028 | AC3: ='Mesiheina tee 5 ir 8 (1)'!AA2
A4: 2 | B4: ='Bistryčios g. 27 (3)'!B4 -> 45721 | C4: ='Bistryčios g. 27 (3)'!B2 -> Bistryčios g. 27, Vilnius, Lietuva (3 etapas) | D4: ='Bistryčios g. 27 (3)'!B8 -> 17 | E4: ='Bistryčios g. 27 (3)'!B5 -> B | F4: ='Bistryčios g. 27 (3)'!B10 -> 0.13 | G4: ='Bistryčios g. 27 (3)'!B11 -> 50 | H4: ='Bistryčios g. 27 (3)'!B12 -> 46213 | I4: ='Bistryčios g. 27 (3)'!R3 | J4: ='Bistryčios g. 27 (3)'!B13 -> -82 | K4: ='Bistryčios g. 27 (3)'!S3 | L4: ='Bistryčios g. 27 (3)'!N3 -> 0 | M4: ='Bistryčios g. 27 (3)'!P3 -> 9.13 | AC4: ='Bistryčios g. 27 (3)'!AA2
A5: 3 | B5: ='2 MW saulės elektrinių par. (9)'!B4 -> 45721 | C5: ='2 MW saulės elektrinių par. (9)'!B2 -> 2 MW saulės elektrinių parkas Narvydžių k. (9 etapas) | D5: ='2 MW saulės elektrinių par. (9)'!B8 -> 11 | E5: ='2 MW saulės elektrinių par. (9)'!B5 -> C | F5: ='2 MW saulės elektrinių par. (9)'!B10 -> 0.14 | G5: ='2 MW saulės elektrinių par. (9)'!B11 -> 50 | H5: ='2 MW saulės elektrinių par. (9)'!B12 -> 46028 | I5: ='2 MW saulės elektrinių par. (9)'!R3 | J5: ='2 MW saulės elektrinių par. (9)'!B13 -> -267 | K5: ='2 MW saulės elektrinių par. (9)'!S3 -> 390 | L5: ='2 MW saulės elektrinių par. (9)'!N3 -> 0 | M5: ='2 MW saulės elektrinių par. (9)'!P3 -> 2.93 | AC5: ='2 MW saulės elektrinių par. (9)'!AA2 -> +
A6: 4 | B6: ='Kvartalas "Asiūklės parkas” (2)'!B4 -> 45736 | C6: ='Kvartalas "Asiūklės parkas” (2)'!B2 -> Kvartalas "Asiūklės parkas” (2 etapas) | D6: ='Kvartalas "Asiūklės parkas” (2)'!B8 -> 24 | E6: ='Kvartalas "Asiūklės parkas” (2)'!B5 -> A | F6: ='Kvartalas "Asiūklės parkas” (2)'!B10 -> 0.11 | G6: ='Kvartalas "Asiūklės parkas” (2)'!B11 -> 50 | H6: ='Kvartalas "Asiūklės parkas” (2)'!B12 -> 46439 | I6: ='Kvartalas "Asiūklės parkas” (2)'!R3 | J6: ='Kvartalas "Asiūklės parkas” (2)'!B13 -> 144 | K6: ='Kvartalas "Asiūklės parkas” (2)'!S3 | L6: ='Kvartalas "Asiūklės parkas” (2)'!N3 -> 0.51 | M6: ='Kvartalas "Asiūklės parkas” (2)'!P3 -> 8.17 | AC6: ='Kvartalas "Asiūklės parkas” (2)'!AA2
A7: 5 | B7: ='Jono Puzino g. 21-1 (1)'!B4 -> 45772 | C7: ='Jono Puzino g. 21-1 (1)'!B2 -> Jono Puzino g. 21 - 1, Vilnius, Lietuva (1 etapas) | D7: ='Jono Puzino g. 21-1 (1)'!B8 -> 12 | E7: ='Jono Puzino g. 21-1 (1)'!B5 -> B | F7: ='Jono Puzino g. 21-1 (1)'!B10 -> 0.12 | G7: ='Jono Puzino g. 21-1 (1)'!B11 -> 50 | H7: ='Jono Puzino g. 21-1 (1)'!B12 -> 46137 | I7: ='Jono Puzino g. 21-1 (1)'!R3 -> 46125 | J7: ='Jono Puzino g. 21-1 (1)'!B13 | K7: ='Jono Puzino g. 21-1 (1)'!S3 | L7: ='Jono Puzino g. 21-1 (1)'!N3 -> 50 | M7: ='Jono Puzino g. 21-1 (1)'!P3 -> 5.61 | AC7: ='Jono Puzino g. 21-1 (1)'!AA2
A8: 6 | B8: ='Jono Puzino g. 21-1 (2)'!B4 -> 45777 | C8: ='Jono Puzino g. 21-1 (2)'!B2 -> Jono Puzino g. 21 - 1, Vilnius, Lietuva (2 etapas) | D8: ='Jono Puzino g. 21-1 (2)'!B8 -> 12 | E8: ='Jono Puzino g. 21-1 (2)'!B5 -> B | F8: ='Jono Puzino g. 21-1 (2)'!B10 -> 0.12 | G8: ='Jono Puzino g. 21-1 (2)'!B11 -> 54 | H8: ='Jono Puzino g. 21-1 (2)'!B12 -> 46137 | I8: ='Jono Puzino g. 21-1 (2)'!R3 -> 46125 | J8: ='Jono Puzino g. 21-1 (2)'!B13 | K8: ='Jono Puzino g. 21-1 (2)'!S3 | L8: ='Jono Puzino g. 21-1 (2)'!N3 -> 54 | M8: ='Jono Puzino g. 21-1 (2)'!P3 -> 6.09 | AC8: ='Jono Puzino g. 21-1 (2)'!AA2
A9: 7 | B9: ='Lubānas g. 133A, Ryga (7)'!B4 -> 45782 | C9: ='Lubānas g. 133A, Ryga (7)'!B2 -> Lubānas g. 133A, Ryga, Latvija (7 etapas) | D9: ='Lubānas g. 133A, Ryga (7)'!B8 -> 7 | E9: ='Lubānas g. 133A, Ryga (7)'!B5 -> B | F9: ='Lubānas g. 133A, Ryga (7)'!B10 -> 0.12 | G9: ='Lubānas g. 133A, Ryga (7)'!B11 -> 51 | H9: ='Lubānas g. 133A, Ryga (7)'!B12 -> 45983 | I9: ='Lubānas g. 133A, Ryga (7)'!R3 -> 46010 | J9: ='Lubānas g. 133A, Ryga (7)'!B13 | K9: ='Lubānas g. 133A, Ryga (7)'!S3 | L9: ='Lubānas g. 133A, Ryga (7)'!N3 -> 51 | M9: ='Lubānas g. 133A, Ryga (7)'!P3 -> 3.77 | AC9: ='Lubānas g. 133A, Ryga (7)'!AA2
A10: 8 | B10: ='Stoties g. 38, Panevėžys'!B4 -> 45807 | C10: ='Stoties g. 38, Panevėžys'!B2 -> Stoties g. 38, Panevėžys, Lietuva | D10: ='Stoties g. 38, Panevėžys'!B8 -> 12 | E10: ='Stoties g. 38, Panevėžys'!B5 -> B | F10: ='Stoties g. 38, Panevėžys'!B10 -> 0.13 | G10: ='Stoties g. 38, Panevėžys'!B11 -> 50 | H10: ='Stoties g. 38, Panevėžys'!B12 -> 46168 | I10: ='Stoties g. 38, Panevėžys'!R3 -> 46171 | J10: ='Stoties g. 38, Panevėžys'!B13 | K10: ='Stoties g. 38, Panevėžys'!S3 | L10: ='Stoties g. 38, Panevėžys'!N3 -> 50 | M10: ='Stoties g. 38, Panevėžys'!P3 -> 6.69 | AC10: ='Stoties g. 38, Panevėžys'!AA2
A11: 9 | B11: ='Vidiškių vs., Žemaitkiemio (2)'!B4 -> 45834 | C11: ='Vidiškių vs., Žemaitkiemio (2)'!B2 -> Vidiškių vs., Žemaitkiemio sen., Ukmergės r. (2 etapas) | D11: ='Vidiškių vs., Žemaitkiemio (2)'!B8 -> 24 | E11: ='Vidiškių vs., Žemaitkiemio (2)'!B5 -> C | F11: ='Vidiškių vs., Žemaitkiemio (2)'!B10 -> 0.15 | G11: ='Vidiškių vs., Žemaitkiemio (2)'!B11 -> 55 | H11: ='Vidiškių vs., Žemaitkiemio (2)'!B12 -> 46564 | I11: ='Vidiškių vs., Žemaitkiemio (2)'!R3 | J11: ='Vidiškių vs., Žemaitkiemio (2)'!B13 -> 269 | K11: ='Vidiškių vs., Žemaitkiemio (2)'!S3 | L11: ='Vidiškių vs., Žemaitkiemio (2)'!N3 -> 0 | M11: ='Vidiškių vs., Žemaitkiemio (2)'!P3 -> 11.51 | AC11: ='Vidiškių vs., Žemaitkiemio (2)'!AA2
A12: 10 | B12: ='Gyvenamasis kvar. Javų g. (1)'!B4 -> 45835 | C12: ='Gyvenamasis kvar. Javų g. (1)'!B2 -> Gyvenamasis kvartalas Javų g., Šiauliai, Lietuva (1 etapas) | D12: ='Gyvenamasis kvar. Javų g. (1)'!B8 -> 12 | E12: ='Gyvenamasis kvar. Javų g. (1)'!B5 -> C | F12: ='Gyvenamasis kvar. Javų g. (1)'!B10 -> 0.14 | G12: ='Gyvenamasis kvar. Javų g. (1)'!B11 -> 50 | H12: ='Gyvenamasis kvar. Javų g. (1)'!B12 -> 46383 | I12: ='Gyvenamasis kvar. Javų g. (1)'!R3 -> 46220 | J12: ='Gyvenamasis kvar. Javų g. (1)'!B13 | K12: ='Gyvenamasis kvar. Javų g. (1)'!S3 | L12: ='Gyvenamasis kvar. Javų g. (1)'!N3 -> 50 | M12: ='Gyvenamasis kvar. Javų g. (1)'!P3 -> 8.5 | AC12: ='Gyvenamasis kvar. Javų g. (1)'!AA2
A13: 11 | B13: ='Vilniaus g. 38 38A 38B (1)'!B4 -> 45842 | C13: ='Vilniaus g. 38 38A 38B (1)'!B2 -> Vilniaus g. 38/38A/38B, Putiniškių k. (1 etapas) | D13: ='Vilniaus g. 38 38A 38B (1)'!B8 -> 12 | E13: ='Vilniaus g. 38 38A 38B (1)'!B5 -> B | F13: ='Vilniaus g. 38 38A 38B (1)'!B10 -> 0.12 | G13: ='Vilniaus g. 38 38A 38B (1)'!B11 -> 52 | H13: ='Vilniaus g. 38 38A 38B (1)'!B12 -> 46207 | I13: ='Vilniaus g. 38 38A 38B (1)'!R3 | J13: ='Vilniaus g. 38 38A 38B (1)'!B13 -> -88 | K13: ='Vilniaus g. 38 38A 38B (1)'!S3 -> 118 | L13: ='Vilniaus g. 38 38A 38B (1)'!N3 -> 0 | M13: ='Vilniaus g. 38 38A 38B (1)'!P3 -> 5.17 | AC13: ='Vilniaus g. 38 38A 38B (1)'!AA2 -> +
A14: 12 | B14: ='Lubānas g. 133A, Ryga, (12)'!B4 -> 45859 | C14: ='Lubānas g. 133A, Ryga, (12)'!B2 -> Lubānas g. 133A, Ryga, Latvija (12 etapas) | D14: ='Lubānas g. 133A, Ryga, (12)'!B8 -> 5 | E14: ='Lubānas g. 133A, Ryga, (12)'!B5 -> B | F14: ='Lubānas g. 133A, Ryga, (12)'!B10 -> 0.11 | G14: ='Lubānas g. 133A, Ryga, (12)'!B11 -> 56 | H14: ='Lubānas g. 133A, Ryga, (12)'!B12 -> 45983 | I14: ='Lubānas g. 133A, Ryga, (12)'!R3 -> 46010 | J14: ='Lubānas g. 133A, Ryga, (12)'!B13 | K14: ='Lubānas g. 133A, Ryga, (12)'!S3 | L14: ='Lubānas g. 133A, Ryga, (12)'!N3 -> 56 | M14: ='Lubānas g. 133A, Ryga, (12)'!P3 -> 2.53 | AC14: ='Lubānas g. 133A, Ryga, (12)'!AA2
A15: 13 | B15: ='Viensėdžio g. 36A (3)'!B4 -> 45902 | C15: ='Viensėdžio g. 36A (3)'!B2 -> Viensėdžio g. 36A, Krikšioniškių k., (3 etapas) | D15: ='Viensėdžio g. 36A (3)'!B8 -> 12 | E15: ='Viensėdžio g. 36A (3)'!B5 -> A | F15: ='Viensėdžio g. 36A (3)'!B10 -> 0.11 | G15: ='Viensėdžio g. 36A (3)'!B11 -> 56 | H15: ='Viensėdžio g. 36A (3)'!B12 -> 46248 | I15: ='Viensėdžio g. 36A (3)'!R3 | J15: ='Viensėdžio g. 36A (3)'!B13 -> -47 | K15: ='Viensėdžio g. 36A (3)'!S3 -> 47 | L15: ='Viensėdžio g. 36A (3)'!N3 -> 0 | M15: ='Viensėdžio g. 36A (3)'!P3 -> 5.59 | AC15: ='Viensėdžio g. 36A (3)'!AA2 -> +
A16: 14 | B16: ='Šaltinio g. 7, Panevėžys (1)'!B4 -> 45908 | C16: ='Šaltinio g. 7, Panevėžys (1)'!B2 -> Šaltinio g. 7, Panevėžys, Lietuva (1 etapas) | D16: ='Šaltinio g. 7, Panevėžys (1)'!B8 -> 24 | E16: ='Šaltinio g. 7, Panevėžys (1)'!B5 -> A | F16: ='Šaltinio g. 7, Panevėžys (1)'!B10 -> 0.12 | G16: ='Šaltinio g. 7, Panevėžys (1)'!B11 -> 54 | H16: ='Šaltinio g. 7, Panevėžys (1)'!B12 -> 46638 | I16: ='Šaltinio g. 7, Panevėžys (1)'!R3 | J16: ='Šaltinio g. 7, Panevėžys (1)'!B13 -> 343 | K16: ='Šaltinio g. 7, Panevėžys (1)'!S3 | L16: ='Šaltinio g. 7, Panevėžys (1)'!N3 -> 0 | M16: ='Šaltinio g. 7, Panevėžys (1)'!P3 -> 6.46 | AC16: ='Šaltinio g. 7, Panevėžys (1)'!AA2
A17: 15 | B17: ='Mozūriškių g. 17 - 3, Vilnius'!B4 -> 45919 | C17: ='Mozūriškių g. 17 - 3, Vilnius'!B2 -> Mozūriškių g. 17 - 3, Vilnius, Lietuva | D17: ='Mozūriškių g. 17 - 3, Vilnius'!B8 -> 12 | E17: ='Mozūriškių g. 17 - 3, Vilnius'!B5 -> B | F17: ='Mozūriškių g. 17 - 3, Vilnius'!B10 -> 0.12 | G17: ='Mozūriškių g. 17 - 3, Vilnius'!B11 -> 53 | H17: ='Mozūriškių g. 17 - 3, Vilnius'!B12 -> 46284 | I17: ='Mozūriškių g. 17 - 3, Vilnius'!R3 | J17: ='Mozūriškių g. 17 - 3, Vilnius'!B13 -> -11 | K17: ='Mozūriškių g. 17 - 3, Vilnius'!S3 -> 73 | L17: ='Mozūriškių g. 17 - 3, Vilnius'!N3 -> 0 | M17: ='Mozūriškių g. 17 - 3, Vilnius'!P3 -> 4.83 | AC17: ='Mozūriškių g. 17 - 3, Vilnius'!AA2 -> +
A18: 16 | B18: ='Parko g. 21 Pergalės g. 36A (1)'!B4 -> 45959 | C18: ='Parko g. 21 Pergalės g. 36A (1)'!B2 -> Parko g. 21 / Pergalės g. 36A, Vilnius, Lietuva (1 etapas) | D18: ='Parko g. 21 Pergalės g. 36A (1)'!B8 -> 12 | E18: ='Parko g. 21 Pergalės g. 36A (1)'!B5 -> B | F18: ='Parko g. 21 Pergalės g. 36A (1)'!B10 -> 0.12 | G18: ='Parko g. 21 Pergalės g. 36A (1)'!B11 -> 54 | H18: ='Parko g. 21 Pergalės g. 36A (1)'!B12 -> 46323 | I18: ='Parko g. 21 Pergalės g. 36A (1)'!R3 | J18: ='Parko g. 21 Pergalės g. 36A (1)'!B13 -> 28 | K18: ='Parko g. 21 Pergalės g. 36A (1)'!S3 -> 121 | L18: ='Parko g. 21 Pergalės g. 36A (1)'!N3 -> 0 | M18: ='Parko g. 21 Pergalės g. 36A (1)'!P3 -> 3.45 | AC18: ='Parko g. 21 Pergalės g. 36A (1)'!AA2 -> +
A19: 17 | B19: ='Pienių g. 28A-28E (1)'!B4 -> 45960 | C19: ='Pienių g. 28A-28E (1)'!B2 -> Pienių g. 28A-28E, Užliedžių k., Užliedžių sen., (1 etapas) | D19: ='Pienių g. 28A-28E (1)'!B8 -> 12 | E19: ='Pienių g. 28A-28E (1)'!B5 -> C | F19: ='Pienių g. 28A-28E (1)'!B10 -> 0.14 | G19: ='Pienių g. 28A-28E (1)'!B11 -> 53 | H19: ='Pienių g. 28A-28E (1)'!B12 -> 46325 | I19: ='Pienių g. 28A-28E (1)'!R3 -> 46059 | J19: ='Pienių g. 28A-28E (1)'!B13 | K19: ='Pienių g. 28A-28E (1)'!S3 | L19: ='Pienių g. 28A-28E (1)'!N3 -> 53 | M19: ='Pienių g. 28A-28E (1)'!P3 -> 2.53 | AC19: ='Pienių g. 28A-28E (1)'!AA2
A20: 18 | B20: ='Baltų Avenue (1)'!B4 -> 45980 | C20: ='Baltų Avenue (1)'!B2 -> "Baltų Avenue" - Baltų pr. 87B ir 87C, Kaunas(1 etapas) | D20: ='Baltų Avenue (1)'!B8 -> 24 | E20: ='Baltų Avenue (1)'!B5 -> A | F20: ='Baltų Avenue (1)'!B10 -> 0.11 | G20: ='Baltų Avenue (1)'!B11 -> 77 | H20: ='Baltų Avenue (1)'!B12 -> 46709 | I20: ='Baltų Avenue (1)'!R3 | J20: ='Baltų Avenue (1)'!B13 -> 414 | K20: ='Baltų Avenue (1)'!S3 | L20: ='Baltų Avenue (1)'!N3 -> 0 | M20: ='Baltų Avenue (1)'!P3 -> 6.97 | AC20: ='Baltų Avenue (1)'!AA2
A21: 19 | B21: ='"Filleo Home", Palanga (3)'!B4 -> 46020 | C21: ='"Filleo Home", Palanga (3)'!B2 -> "Filleo Home" - Klevų 8-oji g., Palanga, Lietuva (3 etapas) | D21: ='"Filleo Home", Palanga (3)'!B8 -> 12 | E21: ='"Filleo Home", Palanga (3)'!B5 -> B | F21: ='"Filleo Home", Palanga (3)'!B10 -> 0.12 | G21: ='"Filleo Home", Palanga (3)'!B11 -> 66 | H21: ='"Filleo Home", Palanga (3)'!B12 -> 46371 | I21: ='"Filleo Home", Palanga (3)'!R3 | J21: ='"Filleo Home", Palanga (3)'!B13 -> 76 | K21: ='"Filleo Home", Palanga (3)'!S3 | L21: ='"Filleo Home", Palanga (3)'!N3 -> 0 | M21: ='"Filleo Home", Palanga (3)'!P3 -> 5.33 | AC21: ='"Filleo Home", Palanga (3)'!AA2
A22: 20 | B22: ='Sklypų masyvas Loo, Parnu (1)'!B4 -> 46029 | C22: ='Sklypų masyvas Loo, Parnu (1)'!B2 -> Sklypų masyvas Loo tee, Elu tee, Pärnu, Estija (1 etapas) | D22: ='Sklypų masyvas Loo, Parnu (1)'!B8 -> 14 | E22: ='Sklypų masyvas Loo, Parnu (1)'!B5 -> B | F22: ='Sklypų masyvas Loo, Parnu (1)'!B10 -> 0.13 | G22: ='Sklypų masyvas Loo, Parnu (1)'!B11 -> 60 | H22: ='Sklypų masyvas Loo, Parnu (1)'!B12 -> 46447 | I22: ='Sklypų masyvas Loo, Parnu (1)'!R3 | J22: ='Sklypų masyvas Loo, Parnu (1)'!B13 -> 152 | K22: ='Sklypų masyvas Loo, Parnu (1)'!S3 -> 54 | L22: ='Sklypų masyvas Loo, Parnu (1)'!N3 -> 17.7 | M22: ='Sklypų masyvas Loo, Parnu (1)'!P3 -> 4.29 | AC22: ='Sklypų masyvas Loo, Parnu (1)'!AA2 -> +
A23: 21 | B23: ='Liepų g. 3, Vyšniūnai (1)'!B4 -> 46065 | C23: ='Liepų g. 3, Vyšniūnai (1)'!B2 -> Liepų g. 3, Vyšniūnai, Stakliškių sen., Prienų r. (1 etapas) | D23: ='Liepų g. 3, Vyšniūnai (1)'!B8 -> 12 | E23: ='Liepų g. 3, Vyšniūnai (1)'!B5 -> A | F23: ='Liepų g. 3, Vyšniūnai (1)'!B10 -> 0.12 | G23: ='Liepų g. 3, Vyšniūnai (1)'!B11 -> 68 | H23: ='Liepų g. 3, Vyšniūnai (1)'!B12 -> 46429 | I23: ='Liepų g. 3, Vyšniūnai (1)'!R3 | J23: ='Liepų g. 3, Vyšniūnai (1)'!B13 -> 134 | K23: ='Liepų g. 3, Vyšniūnai (1)'!S3 -> 80 | L23: ='Liepų g. 3, Vyšniūnai (1)'!N3 -> 0 | M23: ='Liepų g. 3, Vyšniūnai (1)'!P3 -> 2.92 | AC23: ='Liepų g. 3, Vyšniūnai (1)'!AA2 -> +
A24: 22 | B24: ='Basliupio g. 14, Panevėžys (3)'!B4 -> 46090 | C24: ='Basliupio g. 14, Panevėžys (3)'!B2 -> Basliupio g. 14, Panevėžys, Lietuva (3 etapas) | D24: ='Basliupio g. 14, Panevėžys (3)'!B8 -> 24 | E24: ='Basliupio g. 14, Panevėžys (3)'!B5 -> B | F24: ='Basliupio g. 14, Panevėžys (3)'!B10 -> 0.13 | G24: ='Basliupio g. 14, Panevėžys (3)'!B11 -> 55 | H24: ='Basliupio g. 14, Panevėžys (3)'!B12 -> 46796 | I24: ='Basliupio g. 14, Panevėžys (3)'!R3 | J24: ='Basliupio g. 14, Panevėžys (3)'!B13 -> 501 | K24: ='Basliupio g. 14, Panevėžys (3)'!S3 | L24: ='Basliupio g. 14, Panevėžys (3)'!N3 -> 0 | M24: ='Basliupio g. 14, Panevėžys (3)'!P3 -> 3.56 | AC24: ='Basliupio g. 14, Panevėžys (3)'!AA2
A25: 23 | B25: ='Mėguvos g. 6 ir 8, Palanga (2)'!B4 -> 46127 | C25: ='Mėguvos g. 6 ir 8, Palanga (2)'!B2 -> Mėguvos g. 6 ir 8, Palanga, Lietuva (2 etapas) | D25: ='Mėguvos g. 6 ir 8, Palanga (2)'!B8 -> 12 | E25: ='Mėguvos g. 6 ir 8, Palanga (2)'!B5 -> B | F25: ='Mėguvos g. 6 ir 8, Palanga (2)'!B10 -> 0.12 | G25: ='Mėguvos g. 6 ir 8, Palanga (2)'!B11 -> 52 | H25: ='Mėguvos g. 6 ir 8, Palanga (2)'!B12 -> 46490 | I25: ='Mėguvos g. 6 ir 8, Palanga (2)'!R3 | J25: ='Mėguvos g. 6 ir 8, Palanga (2)'!B13 -> 195 | K25: ='Mėguvos g. 6 ir 8, Palanga (2)'!S3 -> 46 | L25: ='Mėguvos g. 6 ir 8, Palanga (2)'!N3 -> 0 | M25: ='Mėguvos g. 6 ir 8, Palanga (2)'!P3 -> 1.57 | AC25: ='Mėguvos g. 6 ir 8, Palanga (2)'!AA2 -> +
A26: 24 | B26: ='"Filleo Home", Palanga (10)'!B4 -> 46150 | C26: ='"Filleo Home", Palanga (10)'!B2 -> "Filleo Home" - Klevų 8-oji g., Palanga (10 etapas) | D26: ='"Filleo Home", Palanga (10)'!B8 -> 8 | E26: ='"Filleo Home", Palanga (10)'!B5 -> B | F26: ='"Filleo Home", Palanga (10)'!B10 -> 0.12 | G26: ='"Filleo Home", Palanga (10)'!B11 -> 75 | H26: ='"Filleo Home", Palanga (10)'!B12 -> 46371 | I26: ='"Filleo Home", Palanga (10)'!R3 | J26: ='"Filleo Home", Palanga (10)'!B13 -> 76 | K26: ='"Filleo Home", Palanga (10)'!S3 | L26: ='"Filleo Home", Palanga (10)'!N3 -> 0 | M26: ='"Filleo Home", Palanga (10)'!P3 -> 3.01 | AC26: ='"Filleo Home", Palanga (10)'!AA2
A27: 25 | B27: ='Baltų Avenue (11)'!B4 -> 46150 | C27: ='Baltų Avenue (11)'!B2 -> "Baltų Avenue" - Baltų pr. 87B ir 87C, Kaunas(11 etapas) | D27: ='Baltų Avenue (11)'!B8 -> 19 | E27: ='Baltų Avenue (11)'!B5 -> A | F27: ='Baltų Avenue (11)'!B10 -> 0.1 | G27: ='Baltų Avenue (11)'!B11 -> 53 | H27: ='Baltų Avenue (11)'!B12 -> 46709 | I27: ='Baltų Avenue (11)'!R3 | J27: ='Baltų Avenue (11)'!B13 -> 414 | K27: ='Baltų Avenue (11)'!S3 | L27: ='Baltų Avenue (11)'!N3 -> 0 | M27: ='Baltų Avenue (11)'!P3 -> 1.78 | AC27: ='Baltų Avenue (11)'!AA2
A28: 26 | B28: ='Plento g. 5A, Trakai (2)'!B3 -> 46171 | C28: ='Plento g. 5A, Trakai (2)'!B2 -> Plento g. 5A, Trakai, Lietuva (2 etapas) | D28: ='Plento g. 5A, Trakai (2)'!B8 -> 12 | E28: ='Plento g. 5A, Trakai (2)'!B5 -> B | F28: ='Plento g. 5A, Trakai (2)'!B10 -> 0.12 | G28: ='Plento g. 5A, Trakai (2)'!B11 -> 62 | H28: ='Plento g. 5A, Trakai (2)'!B12 -> 46561 | I28: ='Plento g. 5A, Trakai (2)'!R3 | J28: ='Plento g. 5A, Trakai (2)'!B13 -> 266 | K28: ='Plento g. 5A, Trakai (2)'!S3 -> 39 | L28: ='Plento g. 5A, Trakai (2)'!N3 -> 0 | M28: ='Plento g. 5A, Trakai (2)'!P3 -> 0 | AC28: ='Plento g. 5A, Trakai (2)'!AA2 -> +

Sheet Pinigai
A1: Data | B1: Įnešta | C1: Išimta | D1: Premija | F1: Įnešta | G1: Išimta | H1: Premija | I1: Skirtumas | K1: XIRR | L1: =XIRR(Pinigai!K2:K200,Pinigai!A2:A200) -> 0.14506028
A2: 45707 | B2: 100 | C2: 0 | D2: 0 | F2: =SUM(B2:B44) -> 950 | G2: =SUM(C2:C44) -> 95.17 | H2: =SUM(D2:D44) -> 48.94 | I2: =F2-G2 -> 854.83 | K2: =B2*-1 -> -100
A3: 45708 | B3: 100 | C3: 0 | D3: 0 | K3: =B3*-1 -> -100
A4: 45716 | B4: 0 | C4: 0 | D4: 0.64 | K4: =B4*-1 -> 0
A5: 45721 | B5: 0 | C5: 0 | D5: 1.49 | K5: =B5*-1 -> 0
A6: 45765 | B6: 100 | C6: 0 | D6: 0 | K6: =B6*-1 -> -100
A7: 45770 | B7: 0 | C7: 0 | D7: 0.43 | K7: =B7*-1 -> 0
A8: 45777 | B8: 50 | C8: 0 | D8: 0.46 | K8: =B8*-1 -> -50
A9: 45790 | B9: 50 | C9: 0 | D9: 0 | K9: =B9*-1 -> -50
A10: 45797 | B10: 50 | C10: 0 | D10: 0 | K10: =B10*-1 -> -50
A11: 45807 | B11: 0 | C11: 0 | D11: 0.43 | K11: =B11*-1 -> 0
A12: 45820 | B12: 50 | C12: 0 | D12: 0 | K12: =B12*-1 -> -50
A13: 45826 | B13: 50 | C13: 0 | D13: 0 | K13: =B13*-1 -> -50
A14: 45834 | B14: 0 | C14: 0 | D14: 1.87 | K14: =B14*-1 -> 0
... A37: 46225 | B37: 0 | C37: 0 | D37: 1.24 | K37: =B37*-1 -> 0
A38: 46254 | B38: 0 | C38: 94.17 | D38: 0 | K38: =C38 -> 94.17
A39: 46254 | B39: 0 | C39: 1 | D39: 0 | K39: 0
A200: =TODAY() -> 46295 | K200: =Apžvalga!U3 -> 1033.7

Sheet Plento g. 5A, Trakai (2)
A1: Paskola | B1: Project ID - (LT) | D1: Data | E1: Paskola | F1: Palūkanos | G1: Paskola | H1: Palūkanos | I1: Kompens. | J1: Data | K1: Vėlavimas | M1: Paskola | O1: Palūkanos | Q1: XIRR | R1: Grąžinta | S1: Vėluoja | Y1: Data | Z1: Suma | AA1: Vėlavimas
A2: Objektas | B2: Plento g. 5A, Trakai, Lietuva (2 etapas) | D2: 46256 | E2: 0 | F2: 0.63 | K2: =IF(J2>0,J2-D2,"") | M2: Suteikta | N2: Grąžinta | O2: Planuotos | P2: Realios | Y2: =B3 -> 46171 | Z2: =B11*-1 -> -62 | AA2: =IF(COUNTIFS(D:D,"<"&TODAY(),J:J,"")>0,"+","") -> +
A3: Investicijos data | B3: 46171 | D3: 46287 | E3: 0 | F3: 0.63 | K3: =IF(J3>0,J3-D3,"") | M3: =B11 -> 62 | N3: =G42 -> 0 | O3: =F42 -> 0 | P3: =H42+I42 -> 0 | Q3: =IF(M3=N3,XIRR(Z2:Z26,Y2:Y26),"") | R3: =IF(M3=N3,B14,"") | S3: =IF(COUNTIFS(D:D,"<"&TODAY(),J:J,"")=0,"",TODAY()-_xlfn.MINIFS(D:D,D:D,"<"&TODAY(),J:J,"")) -> 39 | Y3: =J2 -> 0 | Z3: =G2+H2+I2 -> 0
A4: Palūkanų pradžia | B4: 46225 | D4: 46317 | E4: 0 | F4: 0.61 | K4: =IF(J4>0,J4-D4,"") | Y4: =J3 -> 0 | Z4: =G3+H3+I3 -> 0
A5: Projekto reitingas | B5: B | D5: 46348 | E5: 0 | F5: 0.63 | K5: =IF(J5>0,J5-D5,"") | Y5: =J4 -> 0 | Z5: =G4+H4+I4 -> 0
A6: LTV, % | B6: 0.6 | D6: 46378 | E6: 0 | F6: 0.61 | K6: =IF(J6>0,J6-D6,"") | Y6: =J5 -> 0 | Z6: =G5+H5+I5 -> 0
A7: LTV max, % | B7: - | D7: 46409 | E7: 0 | F7: 0.63 | K7: =IF(J7>0,J7-D7,"") | Y7: =J6 -> 0 | Z7: =G6+H6+I6 -> 0
A8: Investicijos laikotarpis, mėn. | B8: 12 | D8: 46440 | E8: 0 | F8: 0.63 | K8: =IF(J8>0,J8-D8,"") | Y8: =J7 -> 0 | Z8: =G7+H7+I7 -> 0
A9: Palūkanų mokėjimas | B9: M | D9: 46468 | E9: 0 | F9: 0.57 | K9: =IF(J9>0,J9-D9,"") | Y9: =J8 -> 0 | Z9: =G8+H8+I8 -> 0
A10: Palūkanos, % | B10: 0.12 | D10: 46499 | E10: 0 | F10: 0.63 | K10: =IF(J10>0,J10-D10,"") | Y10: =J9 -> 0 | Z10: =G9+H9+I9 -> 0
A11: Investuota, Eur | B11: 62 | D11: 46529 | E11: 0 | F11: 0.61 | K11: =IF(J11>0,J11-D11,"") | Y11: =J10 -> 0 | Z11: =G10+H10+I10 -> 0
A12: Investicijos pabaiga | B12: 46561 | D12: 46560 | E12: 0 | F12: 0.63 | K12: =IF(J12>0,J12-D12,"") | Y12: =J11 -> 0 | Z12: =G11+H11+I11 -> 0
A13: Liko dienų | B13: =IF(B11<>N3,(TODAY()-B12)*-1,"") -> 266 | D13: 46561 | E13: 62 | F13: 0.03 | K13: =IF(J13>0,J13-D13,"") | Y13: =J12 -> 0 | Z13: =G12+H12+I12 -> 0
A14: Grąžinta | K14: =IF(J14>0,J14-D14,"") | Y14: =J13 -> 0 | Z14: =G13+H13+I13 -> 0
A15: Vėlavo/Anksčiau | B15: =IF(M3=N3,B14-B12,"") | K15: =IF(J15>0,J15-D15,"") | Y15: =J14 -> 0 | Z15: =G14+H14+I14 -> 0
K16: =IF(J16>0,J16-D16,"") | Y16: =J15 -> 0 | Z16: =G15+H15+I15 -> 0
K17: =IF(J17>0,J17-D17,"") | Y17: =J16 -> 0 | Z17: =G16+H16+I16 -> 0
K18: =IF(J18>0,J18-D18,"") | Y18: =J17 -> 0 | Z18: =G17+H17+I17 -> 0
K19: =IF(J19>0,J19-D19,"") | Y19: =J18 -> 0 | Z19: =G18+H18+I18 -> 0
K20: =IF(J20>0,J20-D20,"") | Y20: =J19 -> 0 | Z20: =G19+H19+I19 -> 0
K21: =IF(J21>0,J21-D21,"") | Y21: =J20 -> 0 | Z21: =G20+H20+I20 -> 0
K22: =IF(J22>0,J22-D22,"") | Y22: =J21 -> 0 | Z22: =G21+H21+I21 -> 0
K23: =IF(J23>0,J23-D23,"") | Y23: =J22 -> 0 | Z23: =G22+H22+I22 -> 0
K24: =IF(J24>0,J24-D24,"") | Y24: =J23 -> 0 | Z24: =G23+H23+I23 -> 0
K25: =IF(J25>0,J25-D25,"") | Y25: =J24 -> 0 | Z25: =G24+H24+I24 -> 0
K26: =IF(J26>0,J26-D26,"") | Y26: =J25 -> 0 | Z26: =G25+H25+I25 -> 0
D27: Viso: | E27: =SUM(E2:E26) -> 62 | F27: =SUM(F2:F26) -> 6.84 | G27: =SUM(G2:G26) -> 0 | H27: =SUM(H2:H26) -> 0 | I27: =SUM(I2:I26) -> 0 | Y27: =J26 -> 0 | Z27: =G26+H26+I26 -> 0
Y28: =J27 -> 0 | Z28: =G27+H27+I27 -> 0
Y29: =J28 -> 0 | Z29: =G28+H28+I28 -> 0
Y30: =J29 -> 0 | Z30: =G29+H29+I29 -> 0
Y31: =J30 -> 0 | Z31: =G30+H30+I30 -> 0
Y32: =J31 -> 0 | Z32: =G31+H31+I31 -> 0
Y33: =J32 -> 0 | Z33: =G32+H32+I32 -> 0
Y34: =J33 -> 0 | Z34: =G33+H33+I33 -> 0
Y35: =J34 -> 0 | Z35: =G34+H34+I34 -> 0
Y36: =J35 -> 0 | Z36: =G35+H35+I35 -> 0
Y37: =J36 -> 0 | Z37: =G36+H36+I36 -> 0
Y38: =J37 -> 0 | Z38: =G37+H37+I37 -> 0
Y39: =J38 -> 0 | Z39: =G38+H38+I38 -> 0
... Y41: =J40 -> 0 | Z41: =G40+H40+I40 -> 0

Sheet Baltų Avenue (11)
A1: Paskola | B1: Project ID - 1337 (LT) | D1: Data | E1: Paskola | F1: Palūkanos | G1: Paskola | H1: Palūkanos | I1: Kompens. | J1: Data | K1: Vėlavimas | M1: Paskola | O1: Palūkanos | Q1: XIRR | R1: Grąžinta | S1: Vėluoja | Y1: Data | Z1: Suma | AA1: Vėlavimas
A2: Objektas | B2: "Baltų Avenue" - Baltų pr. 87B ir 87C, Kaunas(11 etapas) | D2: 46181 | E2: 0 | F2: 0.45 | G2: 0 | H2: 0.45 | I2: 0 | J2: 46177 | K2: =IF(J2>0,J2-D2,"") -> -4 | M2: Suteikta | N2: Grąžinta | O2: Planuotos | P2: Realios | Y2: =B3 -> 46142 | Z2: =B11*-1 -> -53 | AA2: =IF(COUNTIFS(D:D,"<"&TODAY(),J:J,"")>0,"+","")
A3: Investicijos data | B3: 46142 | D3: 46211 | E3: 0 | F3: 0.43 | G3: 0 | H3: 0.43 | I3: 0 | J3: 46208 | K3: =IF(J3>0,J3-D3,"") -> -3 | M3: =B11 -> 53 | N3: =G42 -> 0 | O3: =F42 -> 8.11 | P3: =H42+I42 -> 1.78 | Q3: =IF(M3=N3,XIRR(Z2:Z26,Y2:Y26),"") | R3: =IF(M3=N3,B14,"") | S3: =IF(COUNTIFS(D:D,"<"&TODAY(),J:J,"")=0,"",TODAY()-_xlfn.MINIFS(D:D,D:D,"<"&TODAY(),J:J,"")) | Y3: =J2 -> 46177 | Z3: =G2+H2+I2 -> 0.45
A4: Palūkanų pradžia | B4: 46150 | D4: 46242 | E4: 0 | F4: 0.45 | G4: 0 | H4: 0.45 | I4: 0 | J4: 46238 | K4: =IF(J4>0,J4-D4,"") -> -4 | Y4: =J3 -> 46208 | Z4: =G3+H3+I3 -> 0.43
A5: Projekto reitingas | B5: A | D5: 46273 | E5: 0 | F5: 0.45 | G5: 0 | H5: 0.45 | I5: 0 | J5: 46272 | K5: =IF(J5>0,J5-D5,"") -> -1 | Y5: =J4 -> 46238 | Z5: =G4+H4+I4 -> 0.45
A6: LTV, % | B6: 0.6 | D6: 46303 | E6: 0 | F6: 0.43 | K6: =IF(J6>0,J6-D6,"") | Y6: =J5 -> 46272 | Z6: =G5+H5+I5 -> 0.45
A7: LTV max, % | B7: - | D7: 46334 | E7: 0 | F7: 0.45 | K7: =IF(J7>0,J7-D7,"") | Y7: =J6 -> 0 | Z7: =G6+H6+I6 -> 0
A8: Investicijos laikotarpis, mėn. | B8: 19 | D8: 46364 | E8: 0 | F8: 0.43 | K8: =IF(J8>0,J8-D8,"") | Y8: =J7 -> 0 | Z8: =G7+H7+I7 -> 0
A9: Palūkanų mokėjimas | B9: M | D9: 46395 | E9: 0 | F9: 0.45 | K9: =IF(J9>0,J9-D9,"") | Y9: =J8 -> 0 | Z9: =G8+H8+I8 -> 0
A10: Palūkanos, % | B10: 0.1 | D10: 46426 | E10: 0 | F10: 0.45 | K10: =IF(J10>0,J10-D10,"") | Y10: =J9 -> 0 | Z10: =G9+H9+I9 -> 0
A11: Investuota, Eur | B11: 53 | D11: 46454 | E11: 0 | F11: 0.4 | K11: =IF(J11>0,J11-D11,"") | Y11: =J10 -> 0 | Z11: =G10+H10+I10 -> 0
A12: Investicijos pabaiga | B12: 46709 | D12: 46485 | E12: 0 | F12: 0.45 | K12: =IF(J12>0,J12-D12,"") | Y12: =J11 -> 0 | Z12: =G11+H11+I11 -> 0
A13: Liko dienų | B13: =IF(B11<>N3,(TODAY()-B12)*-1,"") -> 414 | D13: 46515 | E13: 0 | F13: 0.43 | K13: =IF(J13>0,J13-D13,"") | Y13: =J12 -> 0 | Z13: =G12+H12+I12 -> 0
A14: Grąžinta | D14: 46546 | E14: 0 | F14: 0.45 | K14: =IF(J14>0,J14-D14,"") | Y14: =J13 -> 0 | Z14: =G13+H13+I13 -> 0
A15: Vėlavo/Anksčiau | B15: =IF(M3=N3,B14-B12,"") | D15: 46576 | E15: 0 | F15: 0.43 | K15: =IF(J15>0,J15-D15,"") | Y15: =J14 -> 0 | Z15: =G14+H14+I14 -> 0
D16: 46607 | E16: 0 | F16: 0.45 | K16: =IF(J16>0,J16-D16,"") | Y16: =J15 -> 0 | Z16: =G15+H15+I15 -> 0
D17: 46638 | E17: 0 | F17: 0.45 | K17: =IF(J17>0,J17-D17,"") | Y17: =J16 -> 0 | Z17: =G16+H16+I16 -> 0
D18: 46668 | E18: 0 | F18: 0.43 | K18: =IF(J18>0,J18-D18,"") | Y18: =J17 -> 0 | Z18: =G17+H17+I17 -> 0
D19: 46699 | E19: 0 | F19: 0.45 | K19: =IF(J19>0,J19-D19,"") | Y19: =J18 -> 0 | Z19: =G18+H18+I18 -> 0
D20: 46709 | E20: 53 | F20: 0.18 | K20: =IF(J20>0,J20-D20,"") | Y20: =J19 -> 0 | Z20: =G19+H19+I19 -> 0
K21: =IF(J21>0,J21-D21,"") | Y21: =J20 -> 0 | Z21: =G20+H20+I20 -> 0
K22: =IF(J22>0,J22-D22,"") | Y22: =J21 -> 0 | Z22: =G21+H21+I21 -> 0
K23: =IF(J23>0,J23-D23,"") | Y23: =J22 -> 0 | Z23: =G22+H22+I22 -> 0
K24: =IF(J24>0,J24-D24,"") | Y24: =J23 -> 0 | Z24: =G23+H23+I23 -> 0
K25: =IF(J25>0,J25-D25,"") | Y25: =J24 -> 0 | Z25: =G24+H24+I24 -> 0
K26: =IF(J26>0,J26-D26,"") | Y26: =J25 -> 0 | Z26: =G25+H25+I25 -> 0
K27: =IF(J27>0,J27-D27,"") | Y27: =J26 -> 0 | Z27: =G26+H26+I26 -> 0
K28: =IF(J28>0,J28-D28,"") | Y28: =J27 -> 0 | Z28: =G27+H27+I27 -> 0
K29: =IF(J29>0,J29-D29,"") | Y29: =J28 -> 0 | Z29: =G28+H28+I28 -> 0
K30: =IF(J30>0,J30-D30,"") | Y30: =J29 -> 0 | Z30: =G29+H29+I29 -> 0
K31: =IF(J31>0,J31-D31,"") | Y31: =J30 -> 0 | Z31: =G30+H30+I30 -> 0
K32: =IF(J32>0,J32-D32,"") | Y32: =J31 -> 0 | Z32: =G31+H31+I31 -> 0
... K41: =IF(J41>0,J41-D41,"") | Y41: =J40 -> 0 | Z41: =G40+H40+I40 -> 0
D42: Viso: | E42: =SUM(E2:E41) -> 53 | F42: =SUM(F2:F41) -> 8.11 | G42: =SUM(G2:G41) -> 0 | H42: =SUM(H2:H41) -> 1.78 | I42: =SUM(I2:I41) -> 0

Sheet "Filleo Home", Palanga (10)
A1: Paskola | B1: Project ID - 1314 (LT) | D1: Data | E1: Paskola | F1: Palūkanos | G1: Paskola | H1: Palūkanos | I1: Kompens. | J1: Data | K1: Vėlavimas | M1: Paskola | O1: Palūkanos | Q1: XIRR | R1: Grąžinta | S1: Vėluoja | Y1: Data | Z1: Suma | AA1: Vėlavimas
A2: Objektas | B2: "Filleo Home" - Klevų 8-oji g., Palanga (10 etapas) | D2: 46181 | E2: 0 | F2: 0.76 | G2: 0 | H2: 0.76 | I2: 0 | J2: 46181 | K2: =IF(J2>0,J2-D2,"") -> 0 | M2: Suteikta | N2: Grąžinta | O2: Planuotos | P2: Realios | Y2: =B3 -> 46128 | Z2: =B11*-1 -> -75 | AA2: =IF(COUNTIFS(D:D,"<"&TODAY(),J:J,"")>0,"+","")
A3: Investicijos data | B3: 46128 | D3: 46211 | E3: 0 | F3: 0.73 | G3: 0 | H3: 0.73 | I3: 0 | J3: 46212 | K3: =IF(J3>0,J3-D3,"") -> 1 | M3: =B11 -> 75 | N3: =G42 -> 0 | O3: =F42 -> 5.44 | P3: =H42+I42 -> 3.01 | Q3: =IF(M3=N3,XIRR(Z2:Z26,Y2:Y26),"") | R3: =IF(M3=N3,B14,"") | S3: =IF(COUNTIFS(D:D,"<"&TODAY(),J:J,"")=0,"",TODAY()-_xlfn.MINIFS(D:D,D:D,"<"&TODAY(),J:J,"")) | Y3: =J2 -> 46181 | Z3: =G2+H2+I2 -> 0.76
A4: Palūkanų pradžia | B4: 46150 | D4: 46242 | E4: 0 | F4: 0.76 | G4: 0 | H4: 0.76 | I4: 0 | J4: 46244 | K4: =IF(J4>0,J4-D4,"") -> 2 | Y4: =J3 -> 46212 | Z4: =G3+H3+I3 -> 0.73
A5: Projekto reitingas | B5: B | D5: 46273 | E5: 0 | F5: 0.76 | G5: 0 | H5: 0.76 | I5: 0 | J5: 46276 | K5: =IF(J5>0,J5-D5,"") -> 3 | Y5: =J4 -> 46244 | Z5: =G4+H4+I4 -> 0.76
A6: LTV, % | B6: 0.5 | D6: 46303 | E6: 0 | F6: 0.73 | K6: =IF(J6>0,J6-D6,"") | Y6: =J5 -> 46276 | Z6: =G5+H5+I5 -> 0.76
A7: LTV max, % | B7: - | D7: 46334 | E7: 0 | F7: 0.76 | K7: =IF(J7>0,J7-D7,"") | Y7: =J6 -> 0 | Z7: =G6+H6+I6 -> 0
A8: Investicijos laikotarpis, mėn. | B8: 8 | D8: 46364 | E8: 0 | F8: 0.73 | K8: =IF(J8>0,J8-D8,"") | Y8: =J7 -> 0 | Z8: =G7+H7+I7 -> 0
A9: Palūkanų mokėjimas | B9: M | D9: 46371 | E9: 75 | F9: 0.21 | K9: =IF(J9>0,J9-D9,"") | Y9: =J8 -> 0 | Z9: =G8+H8+I8 -> 0
A10: Palūkanos, % | B10: 0.12 | K10: =IF(J10>0,J10-D10,"") | Y10: =J9 -> 0 | Z10: =G9+H9+I9 -> 0
A11: Investuota, Eur | B11: 75 | K11: =IF(J11>0,J11-D11,"") | Y11: =J10 -> 0 | Z11: =G10+H10+I10 -> 0
A12: Investicijos pabaiga | B12: 46371 | K12: =IF(J12>0,J12-D12,"") | Y12: =J11 -> 0 | Z12: =G11+H11+I11 -> 0
A13: Liko dienų | B13: =IF(B11<>N3,(TODAY()-B12)*-1,"") -> 76 | K13: =IF(J13>0,J13-D13,"") | Y13: =J12 -> 0 | Z13: =G12+H12+I12 -> 0
A14: Grąžinta | K14: =IF(J14>0,J14-D14,"") | Y14: =J13 -> 0 | Z14: =G13+H13+I13 -> 0
A15: Vėlavo/Anksčiau | B15: =IF(M3=N3,B14-B12,"") | K15: =IF(J15>0,J15-D15,"") | Y15: =J14 -> 0 | Z15: =G14+H14+I14 -> 0
K16: =IF(J16>0,J16-D16,"") | Y16: =J15 -> 0 | Z16: =G15+H15+I15 -> 0
K17: =IF(J17>0,J17-D17,"") | Y17: =J16 -> 0 | Z17: =G16+H16+I16 -> 0
K18: =IF(J18>0,J18-D18,"") | Y18: =J17 -> 0 | Z18: =G17+H17+I17 -> 0
K19: =IF(J19>0,J19-D19,"") | Y19: =J18 -> 0 | Z19: =G18+H18+I18 -> 0
K20: =IF(J20>0,J20-D20,"") | Y20: =J19 -> 0 | Z20: =G19+H19+I19 -> 0
K21: =IF(J21>0,J21-D21,"") | Y21: =J20 -> 0 | Z21: =G20+H20+I20 -> 0
K22: =IF(J22>0,J22-D22,"") | Y22: =J21 -> 0 | Z22: =G21+H21+I21 -> 0
K23: =IF(J23>0,J23-D23,"") | Y23: =J22 -> 0 | Z23: =G22+H22+I22 -> 0
K24: =IF(J24>0,J24-D24,"") | Y24: =J23 -> 0 | Z24: =G23+H23+I23 -> 0
K25: =IF(J25>0,J25-D25,"") | Y25: =J24 -> 0 | Z25: =G24+H24+I24 -> 0
K26: =IF(J26>0,J26-D26,"") | Y26: =J25 -> 0 | Z26: =G25+H25+I25 -> 0
K27: =IF(J27>0,J27-D27,"") | Y27: =J26 -> 0 | Z27: =G26+H26+I26 -> 0
... K41: =IF(J41>0,J41-D41,"") | Y41: =J40 -> 0 | Z41: =G40+H40+I40 -> 0
D42: Viso: | E42: =SUM(E2:E41) -> 75 | F42: =SUM(F2:F41) -> 5.44 | G42: =SUM(G2:G41) -> 0 | H42: =SUM(H2:H41) -> 3.01 | I42: =SUM(I2:I41) -> 0

Sheet Mėguvos g. 6 ir 8, Palanga (2)
A1: Paskola | B1: Project ID - 1303 (LT) | D1: Data | E1: Paskola | F1: Palūkanos | G1: Paskola | H1: Palūkanos | I1: Kompens. | J1: Data | K1: Vėlavimas | M1: Paskola | O1: Palūkanos | Q1: XIRR | R1: Grąžinta | S1: Vėluoja | Y1: Data | Z1: Suma | AA1: Vėlavimas
A2: Objektas | B2: Mėguvos g. 6 ir 8, Palanga, Lietuva (2 etapas) | D2: 46157 | E2: 0 | F2: 0.51 | G2: 0 | H2: 0.51 | I2: 0 | J2: 46140 | K2: =IF(J2>0,J2-D2,"") -> -17 | M2: Suteikta | N2: Grąžinta | O2: Planuotos | P2: Realios | Y2: =B3 -> 46107 | Z2: =B11*-1 -> -52 | AA2: =IF(COUNTIFS(D:D,"<"&TODAY(),J:J,"")>0,"+","") -> +
A3: Investicijos data | B3: 46107 | D3: 46188 | E3: 0 | F3: 0.52 | G3: 0 | H3: 0.52 | I3: 0.01 | J3: 46196 | K3: =IF(J3>0,J3-D3,"") -> 8 | M3: =B11 -> 52 | N3: =G42 -> 0 | O3: =F42 -> 6.2 | P3: =H42+I42 -> 1.57 | Q3: =IF(M3=N3,XIRR(Z2:Z26,Y2:Y26),"") | R3: =IF(M3=N3,B14,"") | S3: =IF(COUNTIFS(D:D,"<"&TODAY(),J:J,"")=0,"",TODAY()-_xlfn.MINIFS(D:D,D:D,"<"&TODAY(),J:J,"")) -> 46 | Y3: =J2 -> 46140 | Z3: =G2+H2+I2 -> 0.51
A4: Palūkanų pradžia | B4: 46127 | D4: 46218 | E4: 0 | F4: 0.51 | G4: 0 | H4: 0.51 | I4: 0.02 | J4: 46237 | K4: =IF(J4>0,J4-D4,"") -> 19 | Y4: =J3 -> 46196 | Z4: =G3+H3+I3 -> 0.53
A5: Projekto reitingas | B5: B | D5: 46249 | E5: 0 | F5: 0.52 | K5: =IF(J5>0,J5-D5,"") | Y5: =J4 -> 46237 | Z5: =G4+H4+I4 -> 0.53
A6: LTV, % | B6: 0.51 | D6: 46280 | E6: 0 | F6: 0.52 | K6: =IF(J6>0,J6-D6,"") | Y6: =J5 -> 0 | Z6: =G5+H5+I5 -> 0
A7: LTV max, % | B7: - | D7: 46310 | E7: 0 | F7: 0.51 | K7: =IF(J7>0,J7-D7,"") | Y7: =J6 -> 0 | Z7: =G6+H6+I6 -> 0
A8: Investicijos laikotarpis, mėn. | B8: 12 | D8: 46341 | E8: 0 | F8: 0.52 | K8: =IF(J8>0,J8-D8,"") | Y8: =J7 -> 0 | Z8: =G7+H7+I7 -> 0
A9: Palūkanų mokėjimas | B9: M | D9: 46371 | E9: 0 | F9: 0.51 | K9: =IF(J9>0,J9-D9,"") | Y9: =J8 -> 0 | Z9: =G8+H8+I8 -> 0
A10: Palūkanos, % | B10: 0.12 | D10: 46402 | E10: 0 | F10: 0.52 | K10: =IF(J10>0,J10-D10,"") | Y10: =J9 -> 0 | Z10: =G9+H9+I9 -> 0
A11: Investuota, Eur | B11: 52 | D11: 46433 | E11: 0 | F11: 0.52 | K11: =IF(J11>0,J11-D11,"") | Y11: =J10 -> 0 | Z11: =G10+H10+I10 -> 0
A12: Investicijos pabaiga | B12: 46490 | D12: 46461 | E12: 0 | F12: 0.47 | K12: =IF(J12>0,J12-D12,"") | Y12: =J11 -> 0 | Z12: =G11+H11+I11 -> 0
A13: Liko dienų | B13: =IF(B11<>N3,(TODAY()-B12)*-1,"") -> 195 | D13: 46490 | E13: 52 | F13: 0.57 | K13: =IF(J13>0,J13-D13,"") | Y13: =J12 -> 0 | Z13: =G12+H12+I12 -> 0
A14: Grąžinta | K14: =IF(J14>0,J14-D14,"") | Y14: =J13 -> 0 | Z14: =G13+H13+I13 -> 0
A15: Vėlavo/Anksčiau | B15: =IF(M3=N3,B14-B12,"") | K15: =IF(J15>0,J15-D15,"") | Y15: =J14 -> 0 | Z15: =G14+H14+I14 -> 0
K16: =IF(J16>0,J16-D16,"") | Y16: =J15 -> 0 | Z16: =G15+H15+I15 -> 0
K17: =IF(J17>0,J17-D17,"") | Y17: =J16 -> 0 | Z17: =G16+H16+I16 -> 0
K18: =IF(J18>0,J18-D18,"") | Y18: =J17 -> 0 | Z18: =G17+H17+I17 -> 0
K19: =IF(J19>0,J19-D19,"") | Y19: =J18 -> 0 | Z19: =G18+H18+I18 -> 0
K20: =IF(J20>0,J20-D20,"") | Y20: =J19 -> 0 | Z20: =G19+H19+I19 -> 0
K21: =IF(J21>0,J21-D21,"") | Y21: =J20 -> 0 | Z21: =G20+H20+I20 -> 0
K22: =IF(J22>0,J22-D22,"") | Y22: =J21 -> 0 | Z22: =G21+H21+I21 -> 0
K23: =IF(J23>0,J23-D23,"") | Y23: =J22 -> 0 | Z23: =G22+H22+I22 -> 0
K24: =IF(J24>0,J24-D24,"") | Y24: =J23 -> 0 | Z24: =G23+H23+I23 -> 0
K25: =IF(J25>0,J25-D25,"") | Y25: =J24 -> 0 | Z25: =G24+H24+I24 -> 0
K26: =IF(J26>0,J26-D26,"") | Y26: =J25 -> 0 | Z26: =G25+H25+I25 -> 0
K27: =IF(J27>0,J27-D27,"") | Y27: =J26 -> 0 | Z27: =G26+H26+I26 -> 0
... K41: =IF(J41>0,J41-D41,"") | Y41: =J40 -> 0 | Z41: =G40+H40+I40 -> 0
D42: Viso: | E42: =SUM(E2:E41) -> 52 | F42: =SUM(F2:F41) -> 6.2 | G42: =SUM(G2:G41) -> 0 | H42: =SUM(H2:H41) -> 1.54 | I42: =SUM(I2:I41) -> 0.03

Sheet Basliupio g. 14, Panevėžys (3)
A1: Paskola | B1: Project ID - 1253 (LT) | D1: Data | E1: Paskola | F1: Palūkanos | G1: Paskola | H1: Palūkanos | I1: Kompens. | J1: Data | K1: Vėlavimas | M1: Paskola | O1: Palūkanos | Q1: XIRR | R1: Grąžinta | S1: Vėluoja | Y1: Data | Z1: Suma | AA1: Vėlavimas
A2: Objektas | B2: Basliupio g. 14, Panevėžys, Lietuva (3 etapas) | D2: 46121 | E2: 0 | F2: 0.6 | G2: 0 | H2: 0.6 | I2: 0 | J2: 46112 | K2: =IF(J2>0,J2-D2,"") -> -9 | M2: Suteikta | N2: Grąžinta | O2: Planuotos | P2: Realios | Y2: =B3 -> 46060 | Z2: =B11*-1 -> -55 | AA2: =IF(COUNTIFS(D:D,"<"&TODAY(),J:J,"")>0,"+","")
A3: Investicijos data | B3: 46060 | D3: 46151 | E3: 0 | F3: 0.58 | G3: 0 | H3: 0.58 | I3: 0 | J3: 46150 | K3: =IF(J3>0,J3-D3,"") -> -1 | M3: =B11 -> 55 | N3: =G42 -> 0 | O3: =F42 -> 13.82 | P3: =H42+I42 -> 3.56 | Q3: =IF(M3=N3,XIRR(Z2:Z26,Y2:Y26),"") | R3: =IF(M3=N3,B14,"") | S3: =IF(COUNTIFS(D:D,"<"&TODAY(),J:J,"")=0,"",TODAY()-_xlfn.MINIFS(D:D,D:D,"<"&TODAY(),J:J,"")) | Y3: =J2 -> 46112 | Z3: =G2+H2+I2 -> 0.6
A4: Palūkanų pradžia | B4: 46090 | D4: 46182 | E4: 0 | F4: 0.6 | G4: 0 | H4: 0.6 | I4: 0 | J4: 46181 | K4: =IF(J4>0,J4-D4,"") -> -1 | Y4: =J3 -> 46150 | Z4: =G3+H3+I3 -> 0.58
A5: Projekto reitingas | B5: B | D5: 46212 | E5: 0 | F5: 0.58 | G5: 0 | H5: 0.58 | I5: 0 | J5: 46210 | K5: =IF(J5>0,J5-D5,"") -> -2 | Y5: =J4 -> 46181 | Z5: =G4+H4+I4 -> 0.6
A6: LTV, % | B6: 0.61 | D6: 46243 | E6: 0 | F6: 0.6 | G6: 0 | H6: 0.6 | I6: 0 | J6: 46244 | K6: =IF(J6>0,J6-D6,"") -> 1 | Y6: =J5 -> 46210 | Z6: =G5+H5+I5 -> 0.58
A7: LTV max, % | B7: - | D7: 46274 | E7: 0 | F7: 0.6 | G7: 0 | H7: 0.6 | I7: 0 | J7: 46274 | K7: =IF(J7>0,J7-D7,"") -> 0 | Y7: =J6 -> 46244 | Z7: =G6+H6+I6 -> 0.6
A8: Investicijos laikotarpis, mėn. | B8: 24 | D8: 46304 | E8: 0 | F8: 0.58 | K8: =IF(J8>0,J8-D8,"") | Y8: =J7 -> 46274 | Z8: =G7+H7+I7 -> 0.6
A9: Palūkanų mokėjimas | B9: M | D9: 46335 | E9: 0 | F9: 0.6 | K9: =IF(J9>0,J9-D9,"") | Y9: =J8 -> 0 | Z9: =G8+H8+I8 -> 0
A10: Palūkanos, % | B10: 0.13 | D10: 46365 | E10: 0 | F10: 0.58 | K10: =IF(J10>0,J10-D10,"") | Y10: =J9 -> 0 | Z10: =G9+H9+I9 -> 0
A11: Investuota, Eur | B11: 55 | D11: 46396 | E11: 0 | F11: 0.6 | K11: =IF(J11>0,J11-D11,"") | Y11: =J10 -> 0 | Z11: =G10+H10+I10 -> 0
A12: Investicijos pabaiga | B12: 46796 | D12: 46427 | E12: 0 | F12: 0.6 | K12: =IF(J12>0,J12-D12,"") | Y12: =J11 -> 0 | Z12: =G11+H11+I11 -> 0
A13: Liko dienų | B13: =IF(B11<>N3,(TODAY()-B12)*-1,"") -> 501 | D13: 46455 | E13: 0 | F13: 0.54 | K13: =IF(J13>0,J13-D13,"") | Y13: =J12 -> 0 | Z13: =G12+H12+I12 -> 0
A14: Grąžinta | D14: 46486 | E14: 0 | F14: 0.6 | K14: =IF(J14>0,J14-D14,"") | Y14: =J13 -> 0 | Z14: =G13+H13+I13 -> 0
A15: Vėlavo/Anksčiau | B15: =IF(M3=N3,B14-B12,"") | D15: 46516 | E15: 0 | F15: 0.58 | K15: =IF(J15>0,J15-D15,"") | Y15: =J14 -> 0 | Z15: =G14+H14+I14 -> 0
D16: 46547 | E16: 0 | F16: 0.6 | K16: =IF(J16>0,J16-D16,"") | Y16: =J15 -> 0 | Z16: =G15+H15+I15 -> 0
D17: 46577 | E17: 0 | F17: 0.58 | K17: =IF(J17>0,J17-D17,"") | Y17: =J16 -> 0 | Z17: =G16+H16+I16 -> 0
D18: 46608 | E18: 0 | F18: 0.6 | K18: =IF(J18>0,J18-D18,"") | Y18: =J17 -> 0 | Z18: =G17+H17+I17 -> 0
D19: 46639 | E19: 0 | F19: 0.6 | K19: =IF(J19>0,J19-D19,"") | Y19: =J18 -> 0 | Z19: =G18+H18+I18 -> 0
D20: 46669 | E20: 0 | F20: 0.58 | K20: =IF(J20>0,J20-D20,"") | Y20: =J19 -> 0 | Z20: =G19+H19+I19 -> 0
D21: 46700 | E21: 0 | F21: 0.6 | K21: =IF(J21>0,J21-D21,"") | Y21: =J20 -> 0 | Z21: =G20+H20+I20 -> 0
D22: 46730 | E22: 0 | F22: 0.58 | K22: =IF(J22>0,J22-D22,"") | Y22: =J21 -> 0 | Z22: =G21+H21+I21 -> 0
D23: 46761 | E23: 0 | F23: 0.6 | K23: =IF(J23>0,J23-D23,"") | Y23: =J22 -> 0 | Z23: =G22+H22+I22 -> 0
D24: 46792 | E24: 0 | F24: 0.6 | K24: =IF(J24>0,J24-D24,"") | Y24: =J23 -> 0 | Z24: =G23+H23+I23 -> 0
D25: 46796 | E25: 55 | F25: 0.24 | K25: =IF(J25>0,J25-D25,"") | Y25: =J24 -> 0 | Z25: =G24+H24+I24 -> 0
K26: =IF(J26>0,J26-D26,"") | Y26: =J25 -> 0 | Z26: =G25+H25+I25 -> 0
K27: =IF(J27>0,J27-D27,"") | Y27: =J26 -> 0 | Z27: =G26+H26+I26 -> 0
K28: =IF(J28>0,J28-D28,"") | Y28: =J27 -> 0 | Z28: =G27+H27+I27 -> 0
K29: =IF(J29>0,J29-D29,"") | Y29: =J28 -> 0 | Z29: =G28+H28+I28 -> 0
K30: =IF(J30>0,J30-D30,"") | Y30: =J29 -> 0 | Z30: =G29+H29+I29 -> 0
K31: =IF(J31>0,J31-D31,"") | Y31: =J30 -> 0 | Z31: =G30+H30+I30 -> 0
K32: =IF(J32>0,J32-D32,"") | Y32: =J31 -> 0 | Z32: =G31+H31+I31 -> 0
K33: =IF(J33>0,J33-D33,"") | Y33: =J32 -> 0 | Z33: =G32+H32+I32 -> 0
K34: =IF(J34>0,J34-D34,"") | Y34: =J33 -> 0 | Z34: =G33+H33+I33 -> 0
K35: =IF(J35>0,J35-D35,"") | Y35: =J34 -> 0 | Z35: =G34+H34+I34 -> 0
K36: =IF(J36>0,J36-D36,"") | Y36: =J35 -> 0 | Z36: =G35+H35+I35 -> 0
K37: =IF(J37>0,J37-D37,"") | Y37: =J36 -> 0 | Z37: =G36+H36+I36 -> 0
... K41: =IF(J41>0,J41-D41,"") | Y41: =J40 -> 0 | Z41: =G40+H40+I40 -> 0
D42: Viso: | E42: =SUM(E2:E41) -> 55 | F42: =SUM(F2:F41) -> 13.82 | G42: =SUM(G2:G41) -> 0 | H42: =SUM(H2:H41) -> 3.56 | I42: =SUM(I2:I41) -> 0

Sheet Liepų g. 3, Vyšniūnai (1)
A1: Paskola | B1: Project ID - 1250 (LT) | D1: Data | E1: Paskola | F1: Palūkanos | G1: Paskola | H1: Palūkanos | I1: Kompens. | J1: Data | K1: Vėlavimas | M1: Paskola | O1: Palūkanos | Q1: XIRR | R1: Grąžinta | S1: Vėluoja | Y1: Data | Z1: Suma | AA1: Vėlavimas
A2: Objektas | B2: Liepų g. 3, Vyšniūnai, Stakliškių sen., Prienų r. (1 etapas) | D2: 46093 | E2: 0 | F2: 0.62 | G2: 0 | H2: 0.62 | I2: 0.04 | J2: 46122 | K2: =IF(J2>0,J2-D2,"") -> 29 | M2: Suteikta | N2: Grąžinta | O2: Planuotos | P2: Realios | Y2: =B3 -> 46056 | Z2: =B11*-1 -> -68 | AA2: =IF(COUNTIFS(D:D,"<"&TODAY(),J:J,"")>0,"+","") -> +
A3: Investicijos data | B3: 46056 | D3: 46124 | E3: 0 | F3: 0.69 | G3: 0 | H3: 0.69 | I3: 0.07 | J3: 46175 | K3: =IF(J3>0,J3-D3,"") -> 51 | M3: =B11 -> 68 | N3: =G42 -> 0 | O3: =F42 -> 8.13 | P3: =H42+I42 -> 2.92 | Q3: =IF(M3=N3,XIRR(Z2:Z26,Y2:Y26),"") | R3: =IF(M3=N3,B14,"") | S3: =IF(COUNTIFS(D:D,"<"&TODAY(),J:J,"")=0,"",TODAY()-_xlfn.MINIFS(D:D,D:D,"<"&TODAY(),J:J,"")) -> 80 | Y3: =J2 -> 46122 | Z3: =G2+H2+I2 -> 0.66
A4: Palūkanų pradžia | B4: 46065 | D4: 46154 | E4: 0 | F4: 0.67 | G4: 0 | H4: 0.67 | I4: 0.05 | J4: 46196 | K4: =IF(J4>0,J4-D4,"") -> 42 | Y4: =J3 -> 46175 | Z4: =G3+H3+I3 -> 0.76
A5: Projekto reitingas | B5: A | D5: 46185 | E5: 0 | F5: 0.69 | G5: 0 | H5: 0.69 | I5: 0.09 | J5: 46252 | K5: =IF(J5>0,J5-D5,"") -> 67 | Y5: =J4 -> 46196 | Z5: =G4+H4+I4 -> 0.72
A6: LTV, % | B6: 0.5 | D6: 46215 | E6: 0 | F6: 0.67 | K6: =IF(J6>0,J6-D6,"") | Y6: =J5 -> 46252 | Z6: =G5+H5+I5 -> 0.78
A7: LTV max, % | B7: - | D7: 46246 | E7: 0 | F7: 0.69 | K7: =IF(J7>0,J7-D7,"") | Y7: =J6 -> 0 | Z7: =G6+H6+I6 -> 0
A8: Investicijos laikotarpis, mėn. | B8: 12 | D8: 46277 | E8: 0 | F8: 0.69 | K8: =IF(J8>0,J8-D8,"") | Y8: =J7 -> 0 | Z8: =G7+H7+I7 -> 0
A9: Palūkanų mokėjimas | B9: M | D9: 46307 | E9: 0 | F9: 0.67 | K9: =IF(J9>0,J9-D9,"") | Y9: =J8 -> 0 | Z9: =G8+H8+I8 -> 0
A10: Palūkanos, % | B10: 0.12 | D10: 46338 | E10: 0 | F10: 0.69 | K10: =IF(J10>0,J10-D10,"") | Y10: =J9 -> 0 | Z10: =G9+H9+I9 -> 0
A11: Investuota, Eur | B11: 68 | D11: 46368 | E11: 0 | F11: 0.67 | K11: =IF(J11>0,J11-D11,"") | Y11: =J10 -> 0 | Z11: =G10+H10+I10 -> 0
A12: Investicijos pabaiga | B12: 46429 | D12: 46399 | E12: 0 | F12: 0.69 | K12: =IF(J12>0,J12-D12,"") | Y12: =J11 -> 0 | Z12: =G11+H11+I11 -> 0
A13: Liko dienų | B13: =IF(B11<>N3,(TODAY()-B12)*-1,"") -> 134 | D13: 46429 | E13: 68 | F13: 0.69 | K13: =IF(J13>0,J13-D13,"") | Y13: =J12 -> 0 | Z13: =G12+H12+I12 -> 0
A14: Grąžinta | K14: =IF(J14>0,J14-D14,"") | Y14: =J13 -> 0 | Z14: =G13+H13+I13 -> 0
A15: Vėlavo/Anksčiau | B15: =IF(M3=N3,B14-B12,"") | K15: =IF(J15>0,J15-D15,"") | Y15: =J14 -> 0 | Z15: =G14+H14+I14 -> 0
K16: =IF(J16>0,J16-D16,"") | Y16: =J15 -> 0 | Z16: =G15+H15+I15 -> 0
K17: =IF(J17>0,J17-D17,"") | Y17: =J16 -> 0 | Z17: =G16+H16+I16 -> 0
K18: =IF(J18>0,J18-D18,"") | Y18: =J17 -> 0 | Z18: =G17+H17+I17 -> 0
K19: =IF(J19>0,J19-D19,"") | Y19: =J18 -> 0 | Z19: =G18+H18+I18 -> 0
K20: =IF(J20>0,J20-D20,"") | Y20: =J19 -> 0 | Z20: =G19+H19+I19 -> 0
K21: =IF(J21>0,J21-D21,"") | Y21: =J20 -> 0 | Z21: =G20+H20+I20 -> 0
K22: =IF(J22>0,J22-D22,"") | Y22: =J21 -> 0 | Z22: =G21+H21+I21 -> 0
K23: =IF(J23>0,J23-D23,"") | Y23: =J22 -> 0 | Z23: =G22+H22+I22 -> 0
K24: =IF(J24>0,J24-D24,"") | Y24: =J23 -> 0 | Z24: =G23+H23+I23 -> 0
K25: =IF(J25>0,J25-D25,"") | Y25: =J24 -> 0 | Z25: =G24+H24+I24 -> 0
K26: =IF(J26>0,J26-D26,"") | Y26: =J25 -> 0 | Z26: =G25+H25+I25 -> 0
K27: =IF(J27>0,J27-D27,"") | Y27: =J26 -> 0 | Z27: =G26+H26+I26 -> 0
... K41: =IF(J41>0,J41-D41,"") | Y41: =J40 -> 0 | Z41: =G40+H40+I40 -> 0
D42: Viso: | E42: =SUM(E2:E41) -> 68 | F42: =SUM(F2:F41) -> 8.13 | G42: =SUM(G2:G41) -> 0 | H42: =SUM(H2:H41) -> 2.67 | I42: =SUM(I2:I41) -> 0.25

Sheet Sklypų masyvas Loo, Parnu (1)
A1: Paskola | B1: Project ID - 1198 (LT) | D1: Data | E1: Paskola | F1: Palūkanos | G1: Paskola | H1: Palūkanos | I1: Kompens. | J1: Data | K1: Vėlavimas | M1: Paskola | O1: Palūkanos | Q1: XIRR | R1: Grąžinta | S1: Vėluoja | Y1: Data | Z1: Suma | AA1: Vėlavimas
A2: Objektas | B2: Sklypų masyvas Loo tee, Elu tee, Pärnu, Estija (1 etapas) | D2: 46060 | E2: 0 | F2: 0.66 | G2: 0 | H2: 0.66 | I2: 0 | J2: 46062 | K2: =IF(J2>0,J2-D2,"") -> 2 | M2: Suteikta | N2: Grąžinta | O2: Planuotos | P2: Realios | Y2: =B3 -> 46010 | Z2: =B11*-1 -> -60 | AA2: =IF(COUNTIFS(D:D,"<"&TODAY(),J:J,"")>0,"+","") -> +
A3: Investicijos data | B3: 46010 | D3: 46088 | E3: 0 | F3: 0.59 | G3: 0 | H3: 0.59 | I3: 0 | J3: 46089 | K3: =IF(J3>0,J3-D3,"") -> 1 | M3: =B11 -> 60 | N3: =G42 -> 17.7 | O3: =F42 -> 8.93 | P3: =H42+I42 -> 4.29 | Q3: =IF(M3=N3,XIRR(Z2:Z26,Y2:Y26),"") | R3: =IF(M3=N3,B14,"") | S3: =IF(COUNTIFS(D:D,"<"&TODAY(),J:J,"")=0,"",TODAY()-_xlfn.MINIFS(D:D,D:D,"<"&TODAY(),J:J,"")) -> 54 | Y3: =J2 -> 46062 | Z3: =G2+H2+I2 -> 0.66
A4: Palūkanų pradžia | B4: 46029 | D4: 46119 | E4: 0 | F4: 0.66 | G4: 0 | H4: 0.66 | I4: 0 | J4: 46120 | K4: =IF(J4>0,J4-D4,"") -> 1 | Y4: =J3 -> 46089 | Z4: =G3+H3+I3 -> 0.59
A5: Projekto reitingas | B5: B | D5: 46149 | E5: 0 | F5: 0.64 | G5: 0 | H5: 0.64 | I5: 0 | J5: 46126 | K5: =IF(J5>0,J5-D5,"") -> -23 | Y5: =J4 -> 46120 | Z5: =G4+H4+I4 -> 0.66
A6: LTV, % | B6: 0.56 | D6: 46180 | E6: 0 | F6: 0.66 | G6: 7.61 | H6: 0.66 | I6: 0 | J6: 46177 | K6: =IF(J6>0,J6-D6,"") -> -3 | Y6: =J5 -> 46126 | Z6: =G5+H5+I5 -> 0.64
A7: LTV max, % | B7: - | D7: 46210 | E7: 0 | F7: 0.64 | G7: 10.09 | H7: 1.05 | I7: 0.03 | J7: 46237 | K7: =IF(J7>0,J7-D7,"") -> 27 | Y7: =J6 -> 46177 | Z7: =G6+H6+I6 -> 8.27
A8: Investicijos laikotarpis, mėn. | B8: 14 | D8: 46241 | E8: 0 | F8: 0.66 | K8: =IF(J8>0,J8-D8,"") | Y8: =J7 -> 46237 | Z8: =G7+H7+I7 -> 11.17
A9: Palūkanų mokėjimas | B9: M | D9: 46272 | E9: 0 | F9: 0.66 | K9: =IF(J9>0,J9-D9,"") | Y9: =J8 -> 0 | Z9: =G8+H8+I8 -> 0
A10: Palūkanos, % | B10: 0.13 | D10: 46302 | E10: 0 | F10: 0.64 | K10: =IF(J10>0,J10-D10,"") | Y10: =J9 -> 0 | Z10: =G9+H9+I9 -> 0
A11: Investuota, Eur | B11: 60 | D11: 46333 | E11: 0 | F11: 0.66 | K11: =IF(J11>0,J11-D11,"") | Y11: =J10 -> 0 | Z11: =G10+H10+I10 -> 0
A12: Investicijos pabaiga | B12: 46447 | D12: 46363 | E12: 0 | F12: 0.64 | K12: =IF(J12>0,J12-D12,"") | Y12: =J11 -> 0 | Z12: =G11+H11+I11 -> 0
A13: Liko dienų | B13: =IF(B11<>N3,(TODAY()-B12)*-1,"") -> 152 | D13: 46394 | E13: 0 | F13: 0.66 | K13: =IF(J13>0,J13-D13,"") | Y13: =J12 -> 0 | Z13: =G12+H12+I12 -> 0
A14: Grąžinta | D14: 46425 | E14: 0 | F14: 0.66 | K14: =IF(J14>0,J14-D14,"") | Y14: =J13 -> 0 | Z14: =G13+H13+I13 -> 0
A15: Vėlavo/Anksčiau | B15: =IF(M3=N3,B14-B12,"") | D15: 46447 | E15: 60 | F15: 0.5 | K15: =IF(J15>0,J15-D15,"") | Y15: =J14 -> 0 | Z15: =G14+H14+I14 -> 0
K16: =IF(J16>0,J16-D16,"") | Y16: =J15 -> 0 | Z16: =G15+H15+I15 -> 0
K17: =IF(J17>0,J17-D17,"") | Y17: =J16 -> 0 | Z17: =G16+H16+I16 -> 0
K18: =IF(J18>0,J18-D18,"") | Y18: =J17 -> 0 | Z18: =G17+H17+I17 -> 0
K19: =IF(J19>0,J19-D19,"") | Y19: =J18 -> 0 | Z19: =G18+H18+I18 -> 0
K20: =IF(J20>0,J20-D20,"") | Y20: =J19 -> 0 | Z20: =G19+H19+I19 -> 0
K21: =IF(J21>0,J21-D21,"") | Y21: =J20 -> 0 | Z21: =G20+H20+I20 -> 0
K22: =IF(J22>0,J22-D22,"") | Y22: =J21 -> 0 | Z22: =G21+H21+I21 -> 0
K23: =IF(J23>0,J23-D23,"") | Y23: =J22 -> 0 | Z23: =G22+H22+I22 -> 0
K24: =IF(J24>0,J24-D24,"") | Y24: =J23 -> 0 | Z24: =G23+H23+I23 -> 0
K25: =IF(J25>0,J25-D25,"") | Y25: =J24 -> 0 | Z25: =G24+H24+I24 -> 0
K26: =IF(J26>0,J26-D26,"") | Y26: =J25 -> 0 | Z26: =G25+H25+I25 -> 0
K27: =IF(J27>0,J27-D27,"") | Y27: =J26 -> 0 | Z27: =G26+H26+I26 -> 0
... K41: =IF(J41>0,J41-D41,"") | Y41: =J40 -> 0 | Z41: =G40+H40+I40 -> 0
D42: Viso: | E42: =SUM(E2:E41) -> 60 | F42: =SUM(F2:F41) -> 8.93 | G42: =SUM(G2:G41) -> 17.7 | H42: =SUM(H2:H41) -> 4.26 | I42: =SUM(I2:I41) -> 0.03

Sheet "Filleo Home", Palanga (3)
A1: Paskola | B1: Project ID - 1194 (LT) | D1: Data | E1: Paskola | F1: Palūkanos | G1: Paskola | H1: Palūkanos | I1: Kompens. | J1: Data | K1: Vėlavimas | M1: Paskola | O1: Palūkanos | Q1: XIRR | R1: Grąžinta | S1: Vėluoja | Y1: Data | Z1: Suma | AA1: Vėlavimas
A2: Objektas | B2: "Filleo Home" - Klevų 8-oji g., Palanga, Lietuva (3 etapas) | D2: 46051 | E2: 0 | F2: 0.67 | G2: 0 | H2: 0.67 | I2: 0 | J2: 46048 | K2: =IF(J2>0,J2-D2,"") -> -3 | M2: Suteikta | N2: Grąžinta | O2: Planuotos | P2: Realios | Y2: =B3 -> 46010 | Z2: =B11*-1 -> -66 | AA2: =IF(COUNTIFS(D:D,"<"&TODAY(),J:J,"")>0,"+","")
A3: Investicijos data | B3: 46010 | D3: 46082 | E3: 0 | F3: 0.67 | G3: 0 | H3: 0.67 | I3: 0 | J3: 46083 | K3: =IF(J3>0,J3-D3,"") -> 1 | M3: =B11 -> 66 | N3: =G42 -> 0 | O3: =F42 -> 7.61 | P3: =H42+I42 -> 5.33 | Q3: =IF(M3=N3,XIRR(Z2:Z26,Y2:Y26),"") | R3: =IF(M3=N3,B14,"") | S3: =IF(COUNTIFS(D:D,"<"&TODAY(),J:J,"")=0,"",TODAY()-_xlfn.MINIFS(D:D,D:D,"<"&TODAY(),J:J,"")) | Y3: =J2 -> 46048 | Z3: =G2+H2+I2 -> 0.67
A4: Palūkanų pradžia | B4: 46020 | D4: 46113 | E4: 0 | F4: 0.67 | G4: 0 | H4: 0.67 | I4: 0 | J4: 46114 | K4: =IF(J4>0,J4-D4,"") -> 1 | Y4: =J3 -> 46083 | Z4: =G3+H3+I3 -> 0.67
A5: Projekto reitingas | B5: B | D5: 46143 | E5: 0 | F5: 0.65 | G5: 0 | H5: 0.65 | I5: 0 | J5: 46146 | K5: =IF(J5>0,J5-D5,"") -> 3 | Y5: =J4 -> 46114 | Z5: =G4+H4+I4 -> 0.67
A6: LTV, % | B6: 0.5 | D6: 46174 | E6: 0 | F6: 0.67 | G6: 0 | H6: 0.67 | I6: 0 | J6: 46175 | K6: =IF(J6>0,J6-D6,"") -> 1 | Y6: =J5 -> 46146 | Z6: =G5+H5+I5 -> 0.65
A7: LTV max, % | B7: - | D7: 46204 | E7: 0 | F7: 0.65 | G7: 0 | H7: 0.65 | I7: 0 | J7: 46202 | K7: =IF(J7>0,J7-D7,"") -> -2 | Y7: =J6 -> 46175 | Z7: =G6+H6+I6 -> 0.67
A8: Investicijos laikotarpis, mėn. | B8: 12 | D8: 46235 | E8: 0 | F8: 0.67 | G8: 0 | H8: 0.67 | I8: 0 | J8: 46239 | K8: =IF(J8>0,J8-D8,"") -> 4 | Y8: =J7 -> 46202 | Z8: =G7+H7+I7 -> 0.65
A9: Palūkanų mokėjimas | B9: M | D9: 46266 | E9: 0 | F9: 0.67 | G9: 0 | H9: 0.67 | I9: 0.01 | J9: 46276 | K9: =IF(J9>0,J9-D9,"") -> 10 | Y9: =J8 -> 46239 | Z9: =G8+H8+I8 -> 0.67
A10: Palūkanos, % | B10: 0.12 | D10: 46296 | E10: 0 | F10: 0.65 | K10: =IF(J10>0,J10-D10,"") | Y10: =J9 -> 46276 | Z10: =G9+H9+I9 -> 0.68
A11: Investuota, Eur | B11: 66 | D11: 46327 | E11: 0 | F11: 0.67 | K11: =IF(J11>0,J11-D11,"") | Y11: =J10 -> 0 | Z11: =G10+H10+I10 -> 0
A12: Investicijos pabaiga | B12: 46371 | D12: 46357 | E12: 0 | F12: 0.65 | K12: =IF(J12>0,J12-D12,"") | Y12: =J11 -> 0 | Z12: =G11+H11+I11 -> 0
A13: Liko dienų | B13: =IF(B11<>N3,(TODAY()-B12)*-1,"") -> 76 | D13: 46371 | E13: 66 | F13: 0.32 | K13: =IF(J13>0,J13-D13,"") | Y13: =J12 -> 0 | Z13: =G12+H12+I12 -> 0
A14: Grąžinta | K14: =IF(J14>0,J14-D14,"") | Y14: =J13 -> 0 | Z14: =G13+H13+I13 -> 0
A15: Vėlavo/Anksčiau | B15: =IF(M3=N3,B14-B12,"") | K15: =IF(J15>0,J15-D15,"") | Y15: =J14 -> 0 | Z15: =G14+H14+I14 -> 0
K16: =IF(J16>0,J16-D16,"") | Y16: =J15 -> 0 | Z16: =G15+H15+I15 -> 0
K17: =IF(J17>0,J17-D17,"") | Y17: =J16 -> 0 | Z17: =G16+H16+I16 -> 0
K18: =IF(J18>0,J18-D18,"") | Y18: =J17 -> 0 | Z18: =G17+H17+I17 -> 0
K19: =IF(J19>0,J19-D19,"") | Y19: =J18 -> 0 | Z19: =G18+H18+I18 -> 0
K20: =IF(J20>0,J20-D20,"") | Y20: =J19 -> 0 | Z20: =G19+H19+I19 -> 0
K21: =IF(J21>0,J21-D21,"") | Y21: =J20 -> 0 | Z21: =G20+H20+I20 -> 0
K22: =IF(J22>0,J22-D22,"") | Y22: =J21 -> 0 | Z22: =G21+H21+I21 -> 0
K23: =IF(J23>0,J23-D23,"") | Y23: =J22 -> 0 | Z23: =G22+H22+I22 -> 0
K24: =IF(J24>0,J24-D24,"") | Y24: =J23 -> 0 | Z24: =G23+H23+I23 -> 0
K25: =IF(J25>0,J25-D25,"") | Y25: =J24 -> 0 | Z25: =G24+H24+I24 -> 0
K26: =IF(J26>0,J26-D26,"") | Y26: =J25 -> 0 | Z26: =G25+H25+I25 -> 0
K27: =IF(J27>0,J27-D27,"") | Y27: =J26 -> 0 | Z27: =G26+H26+I26 -> 0
... K41: =IF(J41>0,J41-D41,"") | Y41: =J40 -> 0 | Z41: =G40+H40+I40 -> 0
D42: Viso: | E42: =SUM(E2:E41) -> 66 | F42: =SUM(F2:F41) -> 7.61 | G42: =SUM(G2:G41) -> 0 | H42: =SUM(H2:H41) -> 5.32 | I42: =SUM(I2:I41) -> 0.01

Sheet Baltų Avenue (1)
A1: Paskola | B1: Project ID - 1152 (LT) | D1: Data | E1: Paskola | F1: Palūkanos | G1: Paskola | H1: Palūkanos | I1: Kompens. | J1: Data | K1: Vėlavimas | M1: Paskola | O1: Palūkanos | Q1: XIRR | R1: Grąžinta | S1: Vėluoja | Y1: Data | Z1: Suma | AA1: Vėlavimas
A2: Objektas | B2: "Baltų Avenue" - Baltų pr. 87B ir 87C, Kaunas(1 etapas) | D2: 46010 | E2: 0 | F2: 0.69 | G2: 0 | H2: 0.69 | I2: 0 | J2: 46011 | K2: =IF(J2>0,J2-D2,"") -> 1 | M2: Suteikta | N2: Grąžinta | O2: Planuotos | P2: Realios | Y2: =B3 -> 45948 | Z2: =B11*-1 -> -77 | AA2: =IF(COUNTIFS(D:D,"<"&TODAY(),J:J,"")>0,"+","")
A3: Investicijos data | B3: 45948 | D3: 46041 | E3: 0 | F3: 0.71 | G3: 0 | H3: 0.71 | I3: 0 | J3: 46040 | K3: =IF(J3>0,J3-D3,"") -> -1 | M3: =B11 -> 77 | N3: =G42 -> 0 | O3: =F42 -> 16.91 | P3: =H42+I42 -> 6.97 | Q3: =IF(M3=N3,XIRR(Z2:Z26,Y2:Y26),"") | R3: =IF(M3=N3,B14,"") | S3: =IF(COUNTIFS(D:D,"<"&TODAY(),J:J,"")=0,"",TODAY()-_xlfn.MINIFS(D:D,D:D,"<"&TODAY(),J:J,"")) | Y3: =J2 -> 46011 | Z3: =G2+H2+I2 -> 0.69
A4: Palūkanų pradžia | B4: 45980 | D4: 46072 | E4: 0 | F4: 0.71 | G4: 0 | H4: 0.71 | I4: 0 | J4: 46070 | K4: =IF(J4>0,J4-D4,"") -> -2 | Y4: =J3 -> 46040 | Z4: =G3+H3+I3 -> 0.71
A5: Projekto reitingas | B5: A | D5: 46100 | E5: 0 | F5: 0.64 | G5: 0 | H5: 0.64 | I5: 0 | J5: 46097 | K5: =IF(J5>0,J5-D5,"") -> -3 | Y5: =J4 -> 46070 | Z5: =G4+H4+I4 -> 0.71
A6: LTV, % | B6: 0.6 | D6: 46131 | E6: 0 | F6: 0.71 | G6: 0 | H6: 0.71 | I6: 0 | J6: 46128 | K6: =IF(J6>0,J6-D6,"") -> -3 | Y6: =J5 -> 46097 | Z6: =G5+H5+I5 -> 0.64
A7: LTV max, % | B7: - | D7: 46161 | E7: =SUM(E2:E6) -> 0 | F7: 0.69 | G7: 0 | H7: 0.69 | I7: 0 | J7: 46159 | K7: =IF(J7>0,J7-D7,"") -> -2 | Y7: =J6 -> 46128 | Z7: =G6+H6+I6 -> 0.71
A8: Investicijos laikotarpis, mėn. | B8: 24 | D8: 46192 | E8: =SUM(E3:E7) -> 0 | F8: 0.71 | G8: 0 | H8: 0.71 | I8: 0 | J8: 46188 | K8: =IF(J8>0,J8-D8,"") -> -4 | Y8: =J7 -> 46159 | Z8: =G7+H7+I7 -> 0.69
A9: Palūkanų mokėjimas | B9: M | D9: 46222 | E9: =SUM(E4:E8) -> 0 | F9: 0.69 | G9: 0 | H9: 0.69 | I9: 0 | J9: 46219 | K9: =IF(J9>0,J9-D9,"") -> -3 | Y9: =J8 -> 46188 | Z9: =G8+H8+I8 -> 0.71
A10: Palūkanos, % | B10: 0.11 | D10: 46253 | E10: =SUM(E5:E9) -> 0 | F10: 0.71 | G10: 0 | H10: 0.71 | I10: 0 | J10: 46251 | K10: =IF(J10>0,J10-D10,"") -> -2 | Y10: =J9 -> 46219 | Z10: =G9+H9+I9 -> 0.69
A11: Investuota, Eur | B11: 77 | D11: 46284 | E11: =SUM(E6:E10) -> 0 | F11: 0.71 | G11: 0 | H11: 0.71 | I11: 0 | J11: 46282 | K11: =IF(J11>0,J11-D11,"") -> -2 | Y11: =J10 -> 46251 | Z11: =G10+H10+I10 -> 0.71
A12: Investicijos pabaiga | B12: 46709 | D12: 46314 | E12: =SUM(E7:E11) -> 0 | F12: 0.69 | K12: =IF(J12>0,J12-D12,"") | Y12: =J11 -> 46282 | Z12: =G11+H11+I11 -> 0.71
A13: Liko dienų | B13: =IF(B11<>N3,(TODAY()-B12)*-1,"") -> 414 | D13: 46345 | E13: =SUM(E8:E12) -> 0 | F13: 0.71 | K13: =IF(J13>0,J13-D13,"") | Y13: =J12 -> 0 | Z13: =G12+H12+I12 -> 0
A14: Grąžinta | D14: 46375 | E14: =SUM(E9:E13) -> 0 | F14: 0.69 | K14: =IF(J14>0,J14-D14,"") | Y14: =J13 -> 0 | Z14: =G13+H13+I13 -> 0
A15: Vėlavo/Anksčiau | B15: =IF(M3=N3,B14-B12,"") | D15: 46406 | E15: =SUM(E10:E14) -> 0 | F15: 0.71 | K15: =IF(J15>0,J15-D15,"") | Y15: =J14 -> 0 | Z15: =G14+H14+I14 -> 0
D16: 46437 | E16: =SUM(E11:E15) -> 0 | F16: 0.71 | K16: =IF(J16>0,J16-D16,"") | Y16: =J15 -> 0 | Z16: =G15+H15+I15 -> 0
D17: 46465 | E17: =SUM(E12:E16) -> 0 | F17: 0.64 | K17: =IF(J17>0,J17-D17,"") | Y17: =J16 -> 0 | Z17: =G16+H16+I16 -> 0
D18: 46496 | E18: =SUM(E13:E17) -> 0 | F18: 0.71 | K18: =IF(J18>0,J18-D18,"") | Y18: =J17 -> 0 | Z18: =G17+H17+I17 -> 0
D19: 46526 | E19: =SUM(E14:E18) -> 0 | F19: 0.69 | K19: =IF(J19>0,J19-D19,"") | Y19: =J18 -> 0 | Z19: =G18+H18+I18 -> 0
D20: 46557 | E20: =SUM(E15:E19) -> 0 | F20: 0.71 | K20: =IF(J20>0,J20-D20,"") | Y20: =J19 -> 0 | Z20: =G19+H19+I19 -> 0
D21: 46587 | E21: =SUM(E16:E20) -> 0 | F21: 0.69 | K21: =IF(J21>0,J21-D21,"") | Y21: =J20 -> 0 | Z21: =G20+H20+I20 -> 0
D22: 46618 | E22: =SUM(E17:E21) -> 0 | F22: 0.71 | K22: =IF(J22>0,J22-D22,"") | Y22: =J21 -> 0 | Z22: =G21+H21+I21 -> 0
D23: 46649 | E23: =SUM(E18:E22) -> 0 | F23: 0.71 | K23: =IF(J23>0,J23-D23,"") | Y23: =J22 -> 0 | Z23: =G22+H22+I22 -> 0
D24: 46679 | E24: =SUM(E19:E23) -> 0 | F24: 0.69 | K24: =IF(J24>0,J24-D24,"") | Y24: =J23 -> 0 | Z24: =G23+H23+I23 -> 0
D25: 46709 | E25: 77 | F25: 0.88 | K25: =IF(J25>0,J25-D25,"") | Y25: =J24 -> 0 | Z25: =G24+H24+I24 -> 0
K26: =IF(J26>0,J26-D26,"") | Y26: =J25 -> 0 | Z26: =G25+H25+I25 -> 0
K27: =IF(J27>0,J27-D27,"") | Y27: =J26 -> 0 | Z27: =G26+H26+I26 -> 0
K28: =IF(J28>0,J28-D28,"") | Y28: =J27 -> 0 | Z28: =G27+H27+I27 -> 0
K29: =IF(J29>0,J29-D29,"") | Y29: =J28 -> 0 | Z29: =G28+H28+I28 -> 0
K30: =IF(J30>0,J30-D30,"") | Y30: =J29 -> 0 | Z30: =G29+H29+I29 -> 0
K31: =IF(J31>0,J31-D31,"") | Y31: =J30 -> 0 | Z31: =G30+H30+I30 -> 0
K32: =IF(J32>0,J32-D32,"") | Y32: =J31 -> 0 | Z32: =G31+H31+I31 -> 0
K33: =IF(J33>0,J33-D33,"") | Y33: =J32 -> 0 | Z33: =G32+H32+I32 -> 0
K34: =IF(J34>0,J34-D34,"") | Y34: =J33 -> 0 | Z34: =G33+H33+I33 -> 0
K35: =IF(J35>0,J35-D35,"") | Y35: =J34 -> 0 | Z35: =G34+H34+I34 -> 0
K36: =IF(J36>0,J36-D36,"") | Y36: =J35 -> 0 | Z36: =G35+H35+I35 -> 0
K37: =IF(J37>0,J37-D37,"") | Y37: =J36 -> 0 | Z37: =G36+H36+I36 -> 0
... K41: =IF(J41>0,J41-D41,"") | Y41: =J40 -> 0 | Z41: =G40+H40+I40 -> 0
D42: Viso: | E42: =SUM(E2:E41) -> 77 | F42: =SUM(F2:F41) -> 16.91 | G42: =SUM(G2:G41) -> 0 | H42: =SUM(H2:H41) -> 6.97 | I42: =SUM(I2:I41) -> 0

Sheet Pienių g. 28A-28E (1)
A1: Paskola | B1: Project ID - 1148 (LT) | D1: Data | E1: Paskola | F1: Palūkanos | G1: Paskola | H1: Palūkanos | I1: Kompens. | J1: Data | K1: Vėlavimas | M1: Paskola | O1: Palūkanos | Q1: XIRR | R1: Grąžinta | S1: Vėluoja | Y1: Data | Z1: Suma | AA1: Vėlavimas
A2: Objektas | B2: Pienių g. 28A-28E, Užliedžių k., Užliedžių sen., (1 etapas) | D2: 45991 | E2: 0 | F2: 0.63 | G2: 0 | H2: 0.63 | I2: 0.01 | J2: 46003 | K2: =IF(J2>0,J2-D2,"") -> 12 | M2: Suteikta | N2: Grąžinta | O2: Planuotos | P2: Realios | Y2: =B3 -> 45939 | Z2: =B11*-1 -> -53 | AA2: =IF(COUNTIFS(D:D,"<"&TODAY(),J:J,"")>0,"+","")
A3: Investicijos data | B3: 45939 | D3: 46021 | E3: 0 | F3: 0.6 | G3: 0 | H3: 0.6 | I3: 0.02 | J3: 46035 | K3: =IF(J3>0,J3-D3,"") -> 14 | M3: =B11 -> 53 | N3: =G42 -> 53 | O3: =F42 -> 7.41 | P3: =H42+I42 -> 2.53 | Q3: =IF(M3=N3,XIRR(Z2:Z26,Y2:Y26),"") -> 0.15365508 | R3: =IF(M3=N3,B14,"") -> 46059 | S3: =IF(COUNTIFS(D:D,"<"&TODAY(),J:J,"")=0,"",TODAY()-_xlfn.MINIFS(D:D,D:D,"<"&TODAY(),J:J,"")) | Y3: =J2 -> 46003 | Z3: =G2+H2+I2 -> 0.64
A4: Palūkanų pradžia | B4: 45960 | D4: 46052 | E4: 0 | F4: 0.63 | G4: 0 | H4: 0.63 | I4: 0.01 | J4: 46059 | K4: =IF(J4>0,J4-D4,"") -> 7 | Y4: =J3 -> 46035 | Z4: =G3+H3+I3 -> 0.62
A5: Projekto reitingas | B5: C | D5: 46083 | E5: 0 | F5: 0.63 | G5: 0 | H5: 0 | I5: 0 | J5: 46059 | K5: =IF(J5>0,J5-D5,"") -> -24 | Y5: =J4 -> 46059 | Z5: =G4+H4+I4 -> 0.64
A6: LTV, % | B6: 0.65 | D6: 46114 | E6: 0 | F6: 0.63 | G6: 0 | H6: 0 | I6: 0 | J6: 46059 | K6: =IF(J6>0,J6-D6,"") -> -55 | Y6: =J5 -> 46059 | Z6: =G5+H5+I5 -> 0
A7: LTV max, % | B7: - | D7: 46144 | E7: =SUM(E2:E6) -> 0 | F7: 0.6 | G7: 0 | H7: 0 | I7: 0 | J7: 46059 | K7: =IF(J7>0,J7-D7,"") -> -85 | Y7: =J6 -> 46059 | Z7: =G6+H6+I6 -> 0
A8: Investicijos laikotarpis, mėn. | B8: 12 | D8: 46175 | E8: =SUM(E3:E7) -> 0 | F8: 0.63 | G8: 0 | H8: 0 | I8: 0 | J8: 46059 | K8: =IF(J8>0,J8-D8,"") -> -116 | Y8: =J7 -> 46059 | Z8: =G7+H7+I7 -> 0
A9: Palūkanų mokėjimas | B9: M | D9: 46205 | E9: =SUM(E4:E8) -> 0 | F9: 0.6 | G9: 0 | H9: 0 | I9: 0 | J9: 46059 | K9: =IF(J9>0,J9-D9,"") -> -146 | Y9: =J8 -> 46059 | Z9: =G8+H8+I8 -> 0
A10: Palūkanos, % | B10: 0.14 | D10: 46236 | E10: =SUM(E5:E9) -> 0 | F10: 0.63 | G10: 0 | H10: 0 | I10: 0 | J10: 46059 | K10: =IF(J10>0,J10-D10,"") -> -177 | Y10: =J9 -> 46059 | Z10: =G9+H9+I9 -> 0
A11: Investuota, Eur | B11: 53 | D11: 46267 | E11: =SUM(E6:E10) -> 0 | F11: 0.63 | G11: 0 | H11: 0 | I11: 0 | J11: 46059 | K11: =IF(J11>0,J11-D11,"") -> -208 | Y11: =J10 -> 46059 | Z11: =G10+H10+I10 -> 0
A12: Investicijos pabaiga | B12: 46325 | D12: 46297 | E12: =SUM(E7:E11) -> 0 | F12: 0.6 | G12: 0 | H12: 0 | I12: 0 | J12: 46059 | K12: =IF(J12>0,J12-D12,"") -> -238 | Y12: =J11 -> 46059 | Z12: =G11+H11+I11 -> 0
A13: Liko dienų | B13: =IF(B11<>N3,(TODAY()-B12)*-1,"") | D13: 46325 | E13: 53 | F13: 0.6 | G13: 53 | H13: 0.63 | I13: 0 | J13: 46059 | K13: =IF(J13>0,J13-D13,"") -> -266 | Y13: =J12 -> 46059 | Z13: =G12+H12+I12 -> 0
A14: Grąžinta | B14: 46059 | K14: =IF(J14>0,J14-D14,"") | Y14: =J13 -> 46059 | Z14: =G13+H13+I13 -> 53.63
A15: Vėlavo/Anksčiau | B15: =IF(M3=N3,B14-B12,"") -> -266 | K15: =IF(J15>0,J15-D15,"") | Y15: =J14 -> 0 | Z15: =G14+H14+I14 -> 0
K16: =IF(J16>0,J16-D16,"") | Y16: =J15 -> 0 | Z16: =G15+H15+I15 -> 0
K17: =IF(J17>0,J17-D17,"") | Y17: =J16 -> 0 | Z17: =G16+H16+I16 -> 0
K18: =IF(J18>0,J18-D18,"") | Y18: =J17 -> 0 | Z18: =G17+H17+I17 -> 0
K19: =IF(J19>0,J19-D19,"") | Y19: =J18 -> 0 | Z19: =G18+H18+I18 -> 0
K20: =IF(J20>0,J20-D20,"") | Y20: =J19 -> 0 | Z20: =G19+H19+I19 -> 0
K21: =IF(J21>0,J21-D21,"") | Y21: =J20 -> 0 | Z21: =G20+H20+I20 -> 0
K22: =IF(J22>0,J22-D22,"") | Y22: =J21 -> 0 | Z22: =G21+H21+I21 -> 0
K23: =IF(J23>0,J23-D23,"") | Y23: =J22 -> 0 | Z23: =G22+H22+I22 -> 0
