Workbook

Sheet Overview
A1: Paskola | H1: Grąžinimas | O1: Pinigai | S1: Grąžinta | U1: Vertė
A2: Nr. | B2: Data | C2: Pavadinimas | D2: Laikotarpis | E2: Reitingas | F2: Palūkanos | G2: Investuota | H2: Planuojamas | I2: Realus | J2: Liko | K2: Vėluoja | L2: Paskola | M2: Palūkanos | O2: Įnešta | P2: Investuota | Q2: Premijos | R2: Gryni | S2: Paskola | T2: Palūkanos | U2: Viso | V2: Eur. | W2: % | X2: XIRR | AC2: Vėluoja
A3: 1 | B3: ='Ocean 11 South, II'!B4 -> 45705 | C3: ='Ocean 11 South, II'!B2 -> Ocean 11 South, II | D3: ='Ocean 11 South, II'!B8 -> 12 | E3: ='Ocean 11 South, II'!B5 -> A | F3: ='Ocean 11 South, II'!B10 -> 0.075 | G3: ='Ocean 11 South, II'!B11 -> 100 | H3: ='Ocean 11 South, II'!B12 -> 46068 | I3: ='Ocean 11 South, II'!R3 -> 46073 | J3: ='Ocean 11 South, II'!B13 | K3: ='Ocean 11 South, II'!S3 | L3: ='Ocean 11 South, II'!N3 -> 100 | M3: ='Ocean 11 South, II'!P3 -> 7.46 | O3: =Pinigai!I2 -> 1114.17 | P3: =SUM(G3:G200)-S3 -> 1199.34 | Q3: =Pinigai!H2 -> 20 | R3: =U3-P3 -> 50.72 | S3: =SUM(L3:L200) -> 1297.96 | T3: =SUM(M3:M200) -> 115.89 | U3: =O3+T3+Q3 -> 1250.06 | V3: =U3-O3 -> 135.89 | W3: =(U3-O3)/O3 -> 0.12196523 | X3: =XIRR(Pinigai!K2:K200,Pinigai!A2:A200) -> 0.096675783 | AC3: ='Ocean 11 South, II'!AA2
A4: 2 | B4: ='Bičių slėnis XVII'!B4 -> 45717 | C4: ='Bičių slėnis XVII'!B2 -> Namų kvartalas Bičių Slėnis XVII | D4: ='Bičių slėnis XVII'!B8 -> 12 | E4: ='Bičių slėnis XVII'!B5 -> A | F4: ='Bičių slėnis XVII'!B10 -> 0.085 | G4: ='Bičių slėnis XVII'!B11 -> 100 | H4: ='Bičių slėnis XVII'!B12 -> 46080 | I4: ='Bičių slėnis XVII'!R3 -> 45925 | J4: ='Bičių slėnis XVII'!B13 | K4: ='Bičių slėnis XVII'!S3 | L4: ='Bičių slėnis XVII'!N3 -> 100 | M4: ='Bičių slėnis XVII'!P3 -> 4.71 | AC4: ='Bičių slėnis XVII'!AA2
A5: 3 | B5: ='Piekrasta rezidence'!B4 -> 45733 | C5: ='Piekrasta rezidence'!B2 -> Piekrasta Rezidence, Ryga | D5: ='Piekrasta rezidence'!B8 -> 12 | E5: ='Piekrasta rezidence'!B5 -> A+ | F5: ='Piekrasta rezidence'!B10 -> 0.11 | G5: ='Piekrasta rezidence'!B11 -> 100 | H5: ='Piekrasta rezidence'!B12 -> 46098 | I5: ='Piekrasta rezidence'!R3 -> 46101 | J5: ='Piekrasta rezidence'!B13 | K5: ='Piekrasta rezidence'!S3 | L5: ='Piekrasta rezidence'!N3 -> 100 | M5: ='Piekrasta rezidence'!P3 -> 10.93 | AC5: ='Piekrasta rezidence'!AA2
A6: 4 | B6: ='Elfa loftai II'!B4 -> 45736 | C6: ='Elfa loftai II'!B2 -> Elfa Loftai II | D6: ='Elfa loftai II'!B8 -> 6 | E6: ='Elfa loftai II'!B5 -> A+ | F6: ='Elfa loftai II'!B10 -> 0.09 | G6: ='Elfa loftai II'!B11 -> 100 | H6: ='Elfa loftai II'!B12 -> 45918 | I6: ='Elfa loftai II'!R3 -> 45898 | J6: ='Elfa loftai II'!B13 | K6: ='Elfa loftai II'!S3 | L6: ='Elfa loftai II'!N3 -> 100 | M6: ='Elfa loftai II'!P3 -> 3.96 | AC6: ='Elfa loftai II'!AA2
A7: 5 | B7: ='Kęstučio salos'!B4 -> 45773 | C7: ='Kęstučio salos'!B2 -> Kęstučio salos | D7: ='Kęstučio salos'!B8 -> 12 | E7: ='Kęstučio salos'!B5 -> A+ | F7: ='Kęstučio salos'!B10 -> 0.086 | G7: ='Kęstučio salos'!B11 -> 100 | H7: ='Kęstučio salos'!B12 -> 46136 | I7: ='Kęstučio salos'!R3 -> 46162 | J7: ='Kęstučio salos'!B13 | K7: ='Kęstučio salos'!S3 | L7: ='Kęstučio salos'!N3 -> 100 | M7: ='Kęstučio salos'!P3 -> 10.48 | AC7: ='Kęstučio salos'!AA2
A8: 6 | B8: ='Twinhouse XIII'!B4 -> 45792 | C8: ='Twinhouse XIII'!B2 -> Twinhouse XIII | D8: ='Twinhouse XIII'!B8 -> 12 | E8: ='Twinhouse XIII'!B5 -> A+ | F8: ='Twinhouse XIII'!B10 -> 0.08 | G8: ='Twinhouse XIII'!B11 -> 100 | H8: ='Twinhouse XIII'!B12 -> 46155 | I8: ='Twinhouse XIII'!R3 -> 46156 | J8: ='Twinhouse XIII'!B13 | K8: ='Twinhouse XIII'!S3 | L8: ='Twinhouse XIII'!N3 -> 100 | M8: ='Twinhouse XIII'!P3 -> 7.95 | AC8: ='Twinhouse XIII'!AA2
A9: 7 | B9: ='Vyčio slėnis VIII'!B4 -> 45804 | C9: ='Vyčio slėnis VIII'!B2 -> Vyčio slėnis VIII | D9: ='Vyčio slėnis VIII'!B8 -> 12 | E9: ='Vyčio slėnis VIII'!B5 -> A | F9: ='Vyčio slėnis VIII'!B10 -> 0.09 | G9: ='Vyčio slėnis VIII'!B11 -> 100 | H9: ='Vyčio slėnis VIII'!B12 -> 46167 | I9: ='Vyčio slėnis VIII'!R3 -> 46077 | J9: ='Vyčio slėnis VIII'!B13 | K9: ='Vyčio slėnis VIII'!S3 | L9: ='Vyčio slėnis VIII'!N3 -> 100 | M9: ='Vyčio slėnis VIII'!P3 -> 6.07 | AC9: ='Vyčio slėnis VIII'!AA2
A10: 8 | B10: ='Dvibutis Upės g.'!B4 -> 45857 | C10: ='Dvibutis Upės g.'!B2 -> Dvibutis Upės g., Vilniaus r. | D10: ='Vyčio slėnis VIII'!B8 -> 12 | E10: ='Vyčio slėnis VIII'!B5 -> A | F10: ='Dvibutis Upės g.'!B10 -> 0.08 | G10: ='Dvibutis Upės g.'!B11 -> 110.5 | H10: ='Dvibutis Upės g.'!B12 -> 46220 | I10: ='Dvibutis Upės g.'!R3 -> 46139 | J10: ='Dvibutis Upės g.'!B13 | K10: ='Dvibutis Upės g.'!S3 | L10: ='Dvibutis Upės g.'!N3 -> 110.5 | M10: ='Dvibutis Upės g.'!P3 -> 6.71 | AC10: ='Dvibutis Upės g.'!AA2
A11: 9 | B11: ='Dvibutis Klevų g.'!B4 -> 45898 | C11: ='Dvibutis Klevų g.'!B2 -> Dvibutis Klevų g., Kauno r. | D11: ='Dvibutis Klevų g.'!B8 -> 12 | E11: ='Dvibutis Klevų g.'!B5 -> A+ | F11: ='Dvibutis Klevų g.'!B10 -> 0.08 | G11: ='Dvibutis Klevų g.'!B11 -> 103.7 | H11: ='Dvibutis Klevų g.'!B12 -> 46262 | I11: ='Dvibutis Klevų g.'!R3 -> 46093 | J11: ='Dvibutis Klevų g.'!B13 | K11: ='Dvibutis Klevų g.'!S3 | L11: ='Dvibutis Klevų g.'!N3 -> 103.7 | M11: ='Dvibutis Klevų g.'!P3 -> 2.47 | AC11: ='Dvibutis Klevų g.'!AA2
A12: 10 | B12: ='Dvibutis Upelio g., Vilniaus r.'!B4 -> 45909 | C12: ='Dvibutis Upelio g., Vilniaus r.'!B2 -> Dvibutis Upelio g., Vilniaus r. | D12: ='Dvibutis Upelio g., Vilniaus r.'!B8 -> 12 | E12: ='Dvibutis Upelio g., Vilniaus r.'!B5 -> A+ | F12: ='Dvibutis Upelio g., Vilniaus r.'!B10 -> 0.085 | G12: ='Dvibutis Upelio g., Vilniaus r.'!B11 -> 116.6 | H12: ='Dvibutis Upelio g., Vilniaus r.'!B12 -> 46272 | I12: ='Dvibutis Upelio g., Vilniaus r.'!R3 -> 46280 | J12: ='Dvibutis Upelio g., Vilniaus r.'!B13 | K12: ='Dvibutis Upelio g., Vilniaus r.'!S3 | L12: ='Dvibutis Upelio g., Vilniaus r.'!N3 -> 116.6 | M12: ='Dvibutis Upelio g., Vilniaus r.'!P3 -> 10.28 | AC12: ='Dvibutis Upelio g., Vilniaus r.'!AA2
A13: 11 | B13: ='Piekrasta Rezidence, Ryga XII'!B4 -> 45926 | C13: ='Piekrasta Rezidence, Ryga XII'!B2 -> Piekrasta Rezidence, Ryga XII | D13: ='Piekrasta Rezidence, Ryga XII'!B8 -> 12 | E13: ='Piekrasta Rezidence, Ryga XII'!B5 -> AA- | F13: ='Piekrasta Rezidence, Ryga XII'!B10 -> 0.085 | G13: ='Piekrasta Rezidence, Ryga XII'!B11 -> 101.9 | H13: ='Piekrasta Rezidence, Ryga XII'!B12 -> 46290 | I13: ='Piekrasta Rezidence, Ryga XII'!R3 -> 46293 | J13: ='Piekrasta Rezidence, Ryga XII'!B13 | K13: ='Piekrasta Rezidence, Ryga XII'!S3 | L13: ='Piekrasta Rezidence, Ryga XII'!N3 -> 101.9 | M13: ='Piekrasta Rezidence, Ryga XII'!P3 -> 8.61 | AC13: ='Piekrasta Rezidence, Ryga XII'!AA2
A14: 12 | B14: ='Dvibutis Didžiojoje Riešėje'!B4 -> 46003 | C14: ='Dvibutis Didžiojoje Riešėje'!B2 -> Dvibutis Didžiojoje Riešėje | D14: ='Dvibutis Didžiojoje Riešėje'!B8 -> 12 | E14: ='Dvibutis Didžiojoje Riešėje'!B5 -> A | F14: ='Dvibutis Didžiojoje Riešėje'!B10 -> 0.09 | G14: ='Dvibutis Didžiojoje Riešėje'!B11 -> 116.3 | H14: ='Dvibutis Didžiojoje Riešėje'!B12 -> 46367 | I14: ='Dvibutis Didžiojoje Riešėje'!R3 -> 46272 | J14: ='Dvibutis Didžiojoje Riešėje'!B13 | K14: ='Dvibutis Didžiojoje Riešėje'!S3 | L14: ='Dvibutis Didžiojoje Riešėje'!N3 -> 116.3 | M14: ='Dvibutis Didžiojoje Riešėje'!P3 -> 7.55 | AC14: ='Dvibutis Didžiojoje Riešėje'!AA2
A15: 13 | B15: ='Sklypas Kalnėnuose, Vilnius II'!B4 -> 46034 | C15: ='Sklypas Kalnėnuose, Vilnius II'!B2 -> Sklypas Kalnėnuose, Vilnius II | D15: ='Sklypas Kalnėnuose, Vilnius II'!B8 -> 12 | E15: ='Sklypas Kalnėnuose, Vilnius II'!B5 -> AA+ | F15: ='Sklypas Kalnėnuose, Vilnius II'!B10 -> 0.08 | G15: ='Sklypas Kalnėnuose, Vilnius II'!B11 -> 104.1 | H15: ='Sklypas Kalnėnuose, Vilnius II'!B12 -> 46398 | I15: ='Sklypas Kalnėnuose, Vilnius II'!R3 | J15: ='Sklypas Kalnėnuose, Vilnius II'!B13 -> 103 | K15: ='Sklypas Kalnėnuose, Vilnius II'!S3 | L15: ='Sklypas Kalnėnuose, Vilnius II'!N3 -> 0 | M15: ='Sklypas Kalnėnuose, Vilnius II'!P3 -> 4.54 | AC15: ='Sklypas Kalnėnuose, Vilnius II'!AA2
A16: 14 | B16: ='Golf Hills Vilos, Alikantė'!B4 -> 46062 | C16: ='Golf Hills Vilos, Alikantė'!B2 -> Golf Hills Vilos, Alikantė | D16: ='Golf Hills Vilos, Alikantė'!B8 -> 12 | E16: ='Golf Hills Vilos, Alikantė'!B5 -> AA | F16: ='Golf Hills Vilos, Alikantė'!B10 -> 0.096 | G16: ='Golf Hills Vilos, Alikantė'!B11 -> 102.9 | H16: ='Golf Hills Vilos, Alikantė'!B12 -> 46426 | I16: ='Golf Hills Vilos, Alikantė'!R3 | J16: ='Golf Hills Vilos, Alikantė'!B13 -> 131 | K16: ='Golf Hills Vilos, Alikantė'!S3 | L16: ='Golf Hills Vilos, Alikantė'!N3 -> 0 | M16: ='Golf Hills Vilos, Alikantė'!P3 -> 5.5 | AC16: ='Golf Hills Vilos, Alikantė'!AA2
A17: 15 | B17: ='Svajonių Daugiabutis, Kaunas'!B4 -> 46076 | C17: ='Svajonių Daugiabutis, Kaunas'!B2 -> Svajonių Daugiabutis, Kaunas | D17: ='Svajonių Daugiabutis, Kaunas'!B8 -> 12 | E17: ='Svajonių Daugiabutis, Kaunas'!B5 -> A- | F17: ='Svajonių Daugiabutis, Kaunas'!B10 -> 0.09 | G17: ='Svajonių Daugiabutis, Kaunas'!B11 -> 101.5 | H17: ='Svajonių Daugiabutis, Kaunas'!B12 -> 46440 | I17: ='Svajonių Daugiabutis, Kaunas'!R3 | J17: ='Svajonių Daugiabutis, Kaunas'!B13 -> 145 | K17: ='Svajonių Daugiabutis, Kaunas'!S3 | L17: ='Svajonių Daugiabutis, Kaunas'!N3 -> 0 | M17: ='Svajonių Daugiabutis, Kaunas'!P3 -> 4.7 | AC17: ='Svajonių Daugiabutis, Kaunas'!AA2
A18: 16 | B18: ='Brivibas 28, Jūrmala'!B4 -> 46107 | C18: ='Brivibas 28, Jūrmala'!B2 -> Brivibas 28, Jūrmala | D18: ='Brivibas 28, Jūrmala'!B8 -> 12 | E18: ='Brivibas 28, Jūrmala'!B5 -> A+ | F18: 0.091 | G18: ='Brivibas 28, Jūrmala'!B11 -> 135.7 | H18: ='Brivibas 28, Jūrmala'!B12 -> 46470 | I18: ='Brivibas 28, Jūrmala'!R3 | J18: ='Brivibas 28, Jūrmala'!B13 -> 175 | K18: ='Brivibas 28, Jūrmala'!S3 | L18: ='Brivibas 28, Jūrmala'!N3 -> 48.96 | M18: ='Brivibas 28, Jūrmala'!P3 -> 6.11 | AC18: ='Brivibas 28, Jūrmala'!AA2
A19: 17 | B19: ='Europos 70, Kaunas XX'!B4 -> 46139 | C19: ='Europos 70, Kaunas XX'!B2 -> Europos 70, Kaunas XX | D19: ='Europos 70, Kaunas XX'!B8 -> 12 | E19: ='Europos 70, Kaunas XX'!B5 -> A+ | F19: ='Europos 70, Kaunas XX'!B10 -> 0.082 | G19: ='Europos 70, Kaunas XX'!B11 -> 120.3 | H19: ='Europos 70, Kaunas XX'!B12 -> 46503 | I19: ='Europos 70, Kaunas XX'!R3 | J19: ='Europos 70, Kaunas XX'!B13 -> 208 | K19: ='Europos 70, Kaunas XX'!S3 | L19: ='Europos 70, Kaunas XX'!N3 -> 0 | M19: ='Europos 70, Kaunas XX'!P3 -> 2.99 | AC19: ='Europos 70, Kaunas XX'!AA2
A20: 18 | B20: ='Molėtų Oazė XII'!B3 -> 46156 | C20: ='Molėtų Oazė XII'!B2 -> Molėtų Oazė XII | D20: ='Molėtų Oazė XII'!B8 -> 12 | E20: ='Molėtų Oazė XII'!B5 -> A- | F20: ='Molėtų Oazė XII'!B10 -> 0.086 | G20: ='Molėtų Oazė XII'!B11 -> 105.2 | H20: ='Molėtų Oazė XII'!B12 -> 46520 | I20: ='Molėtų Oazė XII'!R3 | J20: ='Molėtų Oazė XII'!B13 -> 225 | K20: ='Molėtų Oazė XII'!S3 | L20: ='Molėtų Oazė XII'!N3 -> 0 | M20: ='Molėtų Oazė XII'!P3 -> 2.68 | AC20: ='Molėtų Oazė XII'!AA2
A21: 19 | B21: ='Dvibučių kvartalas Kauno r. II'!B3 -> 46164 | C21: ='Dvibučių kvartalas Kauno r. II'!B2 -> Dvibučių kvartalas Kauno r. II | D21: ='Dvibučių kvartalas Kauno r. II'!B8 -> 12 | E21: ='Dvibučių kvartalas Kauno r. II'!B5 -> A | F21: ='Dvibučių kvartalas Kauno r. II'!B10 -> 0.08 | G21: ='Dvibučių kvartalas Kauno r. II'!B11 -> 102.9 | H21: ='Dvibučių kvartalas Kauno r. II'!B12 -> 46531 | I21: ='Dvibučių kvartalas Kauno r. II'!R3 | J21: ='Dvibučių kvartalas Kauno r. II'!B13 -> 236 | K21: ='Dvibučių kvartalas Kauno r. II'!S3 | L21: ='Dvibučių kvartalas Kauno r. II'!N3 -> 0 | M21: ='Dvibučių kvartalas Kauno r. II'!P3 -> 2.19 | AC21: ='Dvibučių kvartalas Kauno r. II'!AA2
A22: 20 | B22: ='Senvagės loftai, Panevėžys VIII'!B3 -> 46254 | C22: ='Senvagės loftai, Panevėžys VIII'!B2 -> Senvagės loftai, Panevėžys VIII | D22: ='Senvagės loftai, Panevėžys VIII'!B8 -> 12 | E22: ='Senvagės loftai, Panevėžys VIII'!B5 -> A- | F22: ='Senvagės loftai, Panevėžys VIII'!B10 -> 0.093 | G22: ='Senvagės loftai, Panevėžys VIII'!B11 -> 122.1 | H22: ='Senvagės loftai, Panevėžys VIII'!B12 -> 46617 | I22: ='Senvagės loftai, Panevėžys VIII'!R3 | J22: ='Senvagės loftai, Panevėžys VIII'!B13 -> 322 | K22: ='Senvagės loftai, Panevėžys VIII'!S3 | L22: ='Senvagės loftai, Panevėžys VIII'!N3 -> 0 | M22: ='Senvagės loftai, Panevėžys VIII'!P3 -> 0
A23: 21 | B23: ='Daugiabučiai Lietaviškių g.'!B3 -> 46272 | C23: ='Daugiabučiai Lietaviškių g.'!B2 -> Daugiabučiai Lietaviškių g., Vilnius | D23: ='Daugiabučiai Lietaviškių g.'!B8 -> 18 | E23: ='Daugiabučiai Lietaviškių g.'!B5 -> A- | F23: ='Daugiabučiai Lietaviškių g.'!B10 -> 0.095 | G23: ='Daugiabučiai Lietaviškių g.'!B11 -> 131.8 | H23: ='Daugiabučiai Lietaviškių g.'!B12 -> 46828 | I23: ='Daugiabučiai Lietaviškių g.'!R3 | J23: ='Daugiabučiai Lietaviškių g.'!B13 -> 533 | K23: ='Daugiabučiai Lietaviškių g.'!S3 | L23: ='Daugiabučiai Lietaviškių g.'!N3 -> 0 | M23: ='Daugiabučiai Lietaviškių g.'!P3 -> 0
A24: 22 | B24: ='Daugiabutis Brivibas 140, Ryga'!B3 -> 46280 | C24: ='Daugiabutis Brivibas 140, Ryga'!B2 -> Daugiabutis Brivibas 140, Ryga | D24: ='Daugiabutis Brivibas 140, Ryga'!B8 -> 12 | E24: ='Daugiabutis Brivibas 140, Ryga'!B5 -> AA | F24: ='Daugiabutis Brivibas 140, Ryga'!B10 -> 0.09 | G24: ='Daugiabutis Brivibas 140, Ryga'!B11 -> 118.8 | H24: ='Daugiabutis Brivibas 140, Ryga'!B12 -> 46645 | I24: ='Daugiabutis Brivibas 140, Ryga'!R3 | J24: ='Daugiabutis Brivibas 140, Ryga'!B13 -> 350 | K24: ='Daugiabutis Brivibas 140, Ryga'!S3 | L24: ='Daugiabutis Brivibas 140, Ryga'!N3 -> 0 | M24: ='Daugiabutis Brivibas 140, Ryga'!P3 -> 0
A25: 23 | B25: ='Namas Laipu 2, Jūrmala'!B3 -> 46293 | C25: ='Namas Laipu 2, Jūrmala'!B2 -> Namas Laipu 2, Jūrmala | D25: ='Namas Laipu 2, Jūrmala'!B8 -> 18 | E25: ='Namas Laipu 2, Jūrmala'!B5 -> A+ | F25: ='Namas Laipu 2, Jūrmala'!B10 -> 0.085 | G25: ='Namas Laipu 2, Jūrmala'!B11 -> 103 | H25: ='Namas Laipu 2, Jūrmala'!B12 -> 0 | I25: ='Namas Laipu 2, Jūrmala'!R3 | J25: ='Namas Laipu 2, Jūrmala'!B13 -> -46295 | K25: ='Namas Laipu 2, Jūrmala'!S3 | L25: ='Namas Laipu 2, Jūrmala'!N3 -> 0 | M25: ='Namas Laipu 2, Jūrmala'!P3 -> 0

Sheet Pinigai
A1: Data | B1: Įnešta | C1: Išimta | D1: Premija | F1: Įnešta | G1: Išimta | H1: Premija | I1: Skirtumas | K1: XIRR | L1: =XIRR(K2:K200,A2:A200) -> 0.096675783
A2: 45702 | B2: 100 | C2: 0 | D2: 0 | F2: =SUM(B2:B36) -> 1114.17 | G2: =SUM(C2:C36) -> 0 | H2: =SUM(D2:D36) -> 20 | I2: =F2-G2 -> 1114.17 | K2: =B2*-1 -> -100
A3: 45714 | B3: 100 | C3: 0 | D3: 0 | K3: =B3*-1 -> -100
A4: 45728 | B4: 100 | C4: 0 | D4: 0 | K4: =B4*-1 -> -100
A5: 45730 | B5: 100 | C5: 0 | D5: 0 | K5: =B5*-1 -> -100
A6: 45771 | B6: 100 | C6: 0 | D6: 0 | K6: =B6*-1 -> -100
A7: 45790 | B7: 100 | C7: 0 | D7: 0 | K7: =B7*-1 -> -100
A8: 45798 | B8: 100 | C8: 0 | D8: 0 | K8: =B8*-1 -> -100
A9: 45854 | B9: 100 | C9: 0 | D9: 0 | K9: =B9*-1 -> -100
A10: 45908 | B10: 100 | C10: 0 | D10: 10 | K10: =B10*-1 -> -100
A11: 46003 | B11: 100 | C11: 0 | D11: 0 | K11: =B11*-1 -> -100
A12: 46059 | B12: 20 | C12: 0 | D12: 0 | K12: =B12*-1 -> -20
A13: 46254 | B13: 94.17 | C13: 0 | D13: 10 | K13: =B13*-1 -> -94.17
A200: =TODAY() -> 46295 | K200: =Overview!U3 -> 1250.06

Sheet Namas Laipu 2, Jūrmala
A1: Paskola | B1: Paskola P00001679 | D1: Data | E1: Paskola | F1: Palūkanos | G1: Paskola | H1: Palūkanos | I1: Papildomos | J1: Data | K1: Vėlavimas | M1: Paskola | O1: Palūkanos | Q1: XIRR | R1: Grąžinta | S1: Vėluoja | Y1: Data | Z1: Suma | AA1: Vėluoja
A2: Objektas | B2: Namas Laipu 2, Jūrmala | K2: =IF(J2>0,J2-D2,"") | M2: Suteikta | N2: Grąžinta | O2: Planuotos | P2: Realios | Y2: =B3 -> 46293 | Z2: =B11*-1 -> -103 | AA2: =IF(COUNTIFS(D:D,"<"&TODAY(),J:J,"")>0,"+","")
A3: Investicijos data | B3: 46293 | K3: =IF(J3>0,J3-D3,"") | M3: =B11 -> 103 | N3: =G42 -> 0 | O3: =F42 -> 0 | P3: =H42+I42 -> 0 | Q3: =IF(M3=N3,XIRR(Z2:Z41,Y2:Y41),"") | R3: =IF(M3=N3,B14,"") | S3: =IF(COUNTIFS(D:D,"<"&TODAY(),J:J,"")=0,"",TODAY()-_xlfn.MINIFS(D:D,D:D,"<"&TODAY(),J:J,"")) | Y3: =J2 -> 0 | Z3: =G2+H2+I2 -> 0
A4: Palūkanų pradžia | K4: =IF(J4>0,J4-D4,"") | Y4: =J3 -> 0 | Z4: =G3+H3+I3 -> 0
A5: Projekto reitingas | B5: A+ | K5: =IF(J5>0,J5-D5,"") | Y5: =J4 -> 0 | Z5: =G4+H4+I4 -> 0
A6: LTV, % | B6: 0.15 | K6: =IF(J6>0,J6-D6,"") | Y6: =J5 -> 0 | Z6: =G5+H5+I5 -> 0
A7: LTV max, % | B7: 0.57 | K7: =IF(J7>0,J7-D7,"") | Y7: =J6 -> 0 | Z7: =G6+H6+I6 -> 0
A8: Investicijos laikotarpis, mėn. | B8: 18 | K8: =IF(J8>0,J8-D8,"") | Y8: =J7 -> 0 | Z8: =G7+H7+I7 -> 0
A9: Palūkanų mokėjimas | B9: Kas ketvirtį | K9: =IF(J9>0,J9-D9,"") | Y9: =J8 -> 0 | Z9: =G8+H8+I8 -> 0
A10: Palūkanos, % | B10: 0.085 | K10: =IF(J10>0,J10-D10,"") | Y10: =J9 -> 0 | Z10: =G9+H9+I9 -> 0
A11: Investuota, Eur | B11: 103 | K11: =IF(J11>0,J11-D11,"") | Y11: =J10 -> 0 | Z11: =G10+H10+I10 -> 0
A12: Paskolos pabaiga | K12: =IF(J12>0,J12-D12,"") | Y12: =J11 -> 0 | Z12: =G11+H11+I11 -> 0
A13: Liko dienų | B13: =IF(B11<>N3,(TODAY()-B12)*-1,"") -> -46295 | K13: =IF(J13>0,J13-D13,"") | Y13: =J12 -> 0 | Z13: =G12+H12+I12 -> 0
A14: Grąžinta | K14: =IF(J14>0,J14-D14,"") | Y14: =J13 -> 0 | Z14: =G13+H13+I13 -> 0
A15: Vėlavo/Anksčiau | B15: =IF(M3=N3,B14-B12,"") | K15: =IF(J15>0,J15-D15,"") | Y15: =J14 -> 0 | Z15: =G14+H14+I14 -> 0
K16: =IF(J16>0,J16-D16,"") | Y16: =J15 -> 0 | Z16: =G15+H15+I15 -> 0
K17: =IF(J17>0,J17-D17,"") | Y17: =J16 -> 0 | Z17: =G16+H16+I16 -> 0
K18: =IF(J18>0,J18-D18,"") | Y18: =J17 -> 0 | Z18: =G17+H17+I17 -> 0
K19: =IF(J19>0,J19-D19,"") | Y19: =J18 -> 0 | Z19: =G18+H18+I18 -> 0
K20: =IF(J20>0,J20-D20,"") | Y20: =J19 -> 0 | Z20: =G19+H19+I19 -> 0
K21: =IF(J21>0,J21-D21,"") | Y21: =J20 -> 0 | Z21: =G20+H20+I20 -> 0
K22: =IF(J22>0,J22-D22,"") | Y22: =J21 -> 0 | Z22: =G21+H21+I21 -> 0
K23: =IF(J23>0,J23-D23,"") | Y23: =J22 -> 0 | Z23: =G22+H22+I22 -> 0
K24: =IF(J24>0,J24-D24,"") | Y24: =J23 -> 0 | Z24: =G23+H23+I23 -> 0
K25: =IF(J25>0,J25-D25,"") | Y25: =J24 -> 0 | Z25: =G24+H24+I24 -> 0
K26: =IF(J26>0,J26-D26,"") | Y26: =J25 -> 0 | Z26: =G25+H25+I25 -> 0
K27: =IF(J27>0,J27-D27,"") | Y27: =J26 -> 0 | Z27: =G26+H26+I26 -> 0
... K41: =IF(J41>0,J41-D41,"") | Y41: =J40 -> 0 | Z41: =G40+H40+I40 -> 0
D42: Viso: | E42: =SUM(E2:E41) -> 0 | F42: =SUM(F2:F41) -> 0 | G42: =SUM(G2:G41) -> 0 | H42: =SUM(H2:H41) -> 0 | I42: =SUM(I2:I41) -> 0

Sheet Daugiabutis Brivibas 140, Ryga
A1: Paskola | B1: Paskola P00001671 | D1: Data | E1: Paskola | F1: Palūkanos | G1: Paskola | H1: Palūkanos | I1: Papildomos | J1: Data | K1: Vėlavimas | M1: Paskola | O1: Palūkanos | Q1: XIRR | R1: Grąžinta | S1: Vėluoja | Y1: Data | Z1: Suma | AA1: Vėluoja
A2: Objektas | B2: Daugiabutis Brivibas 140, Ryga | D2: 46645 | E2: 118.8 | F2: 10.63 | K2: =IF(J2>0,J2-D2,"") | M2: Suteikta | N2: Grąžinta | O2: Planuotos | P2: Realios | Y2: =B3 -> 46280 | Z2: =B11*-1 -> -118.8 | AA2: =IF(COUNTIFS(D:D,"<"&TODAY(),J:J,"")>0,"+","")
A3: Investicijos data | B3: 46280 | K3: =IF(J3>0,J3-D3,"") | M3: =B11 -> 118.8 | N3: =G42 -> 0 | O3: =F42 -> 10.63 | P3: =H42+I42 -> 0 | Q3: =IF(M3=N3,XIRR(Z2:Z41,Y2:Y41),"") | R3: =IF(M3=N3,B14,"") | S3: =IF(COUNTIFS(D:D,"<"&TODAY(),J:J,"")=0,"",TODAY()-_xlfn.MINIFS(D:D,D:D,"<"&TODAY(),J:J,"")) | Y3: =J2 -> 0 | Z3: =G2+H2+I2 -> 0
A4: Palūkanų pradžia | B4: 46282 | K4: =IF(J4>0,J4-D4,"") | Y4: =J3 -> 0 | Z4: =G3+H3+I3 -> 0
A5: Projekto reitingas | B5: AA | K5: =IF(J5>0,J5-D5,"") | Y5: =J4 -> 0 | Z5: =G4+H4+I4 -> 0
A6: LTV, % | B6: 0.65 | K6: =IF(J6>0,J6-D6,"") | Y6: =J5 -> 0 | Z6: =G5+H5+I5 -> 0
A7: LTV max, % | B7: 0.65 | K7: =IF(J7>0,J7-D7,"") | Y7: =J6 -> 0 | Z7: =G6+H6+I6 -> 0
A8: Investicijos laikotarpis, mėn. | B8: 12 | K8: =IF(J8>0,J8-D8,"") | Y8: =J7 -> 0 | Z8: =G7+H7+I7 -> 0
A9: Palūkanų mokėjimas | B9: Termino pabaigoje | K9: =IF(J9>0,J9-D9,"") | Y9: =J8 -> 0 | Z9: =G8+H8+I8 -> 0
A10: Palūkanos, % | B10: 0.09 | K10: =IF(J10>0,J10-D10,"") | Y10: =J9 -> 0 | Z10: =G9+H9+I9 -> 0
A11: Investuota, Eur | B11: 118.8 | K11: =IF(J11>0,J11-D11,"") | Y11: =J10 -> 0 | Z11: =G10+H10+I10 -> 0
A12: Paskolos pabaiga | B12: 46645 | K12: =IF(J12>0,J12-D12,"") | Y12: =J11 -> 0 | Z12: =G11+H11+I11 -> 0
A13: Liko dienų | B13: =IF(B11<>N3,(TODAY()-B12)*-1,"") -> 350 | K13: =IF(J13>0,J13-D13,"") | Y13: =J12 -> 0 | Z13: =G12+H12+I12 -> 0
A14: Grąžinta | K14: =IF(J14>0,J14-D14,"") | Y14: =J13 -> 0 | Z14: =G13+H13+I13 -> 0
A15: Vėlavo/Anksčiau | B15: =IF(M3=N3,B14-B12,"") | K15: =IF(J15>0,J15-D15,"") | Y15: =J14 -> 0 | Z15: =G14+H14+I14 -> 0
K16: =IF(J16>0,J16-D16,"") | Y16: =J15 -> 0 | Z16: =G15+H15+I15 -> 0
K17: =IF(J17>0,J17-D17,"") | Y17: =J16 -> 0 | Z17: =G16+H16+I16 -> 0
K18: =IF(J18>0,J18-D18,"") | Y18: =J17 -> 0 | Z18: =G17+H17+I17 -> 0
K19: =IF(J19>0,J19-D19,"") | Y19: =J18 -> 0 | Z19: =G18+H18+I18 -> 0
K20: =IF(J20>0,J20-D20,"") | Y20: =J19 -> 0 | Z20: =G19+H19+I19 -> 0
K21: =IF(J21>0,J21-D21,"") | Y21: =J20 -> 0 | Z21: =G20+H20+I20 -> 0
K22: =IF(J22>0,J22-D22,"") | Y22: =J21 -> 0 | Z22: =G21+H21+I21 -> 0
K23: =IF(J23>0,J23-D23,"") | Y23: =J22 -> 0 | Z23: =G22+H22+I22 -> 0
K24: =IF(J24>0,J24-D24,"") | Y24: =J23 -> 0 | Z24: =G23+H23+I23 -> 0
K25: =IF(J25>0,J25-D25,"") | Y25: =J24 -> 0 | Z25: =G24+H24+I24 -> 0
K26: =IF(J26>0,J26-D26,"") | Y26: =J25 -> 0 | Z26: =G25+H25+I25 -> 0
K27: =IF(J27>0,J27-D27,"") | Y27: =J26 -> 0 | Z27: =G26+H26+I26 -> 0
... K41: =IF(J41>0,J41-D41,"") | Y41: =J40 -> 0 | Z41: =G40+H40+I40 -> 0
D42: Viso: | E42: =SUM(E2:E41) -> 118.8 | F42: =SUM(F2:F41) -> 10.63 | G42: =SUM(G2:G41) -> 0 | H42: =SUM(H2:H41) -> 0 | I42: =SUM(I2:I41) -> 0

Sheet Daugiabučiai Lietaviškių g.
A1: Paskola | B1: Paskola P00001680 | D1: Data | E1: Paskola | F1: Palūkanos | G1: Paskola | H1: Palūkanos | I1: Papildomos | J1: Data | K1: Vėlavimas | M1: Paskola | O1: Palūkanos | Q1: XIRR | R1: Grąžinta | S1: Vėluoja | Y1: Data | Z1: Suma | AA1: Vėluoja
A2: Objektas | B2: Daugiabučiai Lietaviškių g., Vilnius | D2: 46394 | E2: 0 | F2: 3.38 | K2: =IF(J2>0,J2-D2,"") | M2: Suteikta | N2: Grąžinta | O2: Planuotos | P2: Realios | Y2: =B3 -> 46272 | Z2: =B11*-1 -> -131.8 | AA2: =IF(COUNTIFS(D:D,"<"&TODAY(),J:J,"")>0,"+","")
A3: Investicijos data | B3: 46272 | D3: 46484 | E3: 0 | F3: 2.92 | K3: =IF(J3>0,J3-D3,"") | M3: =B11 -> 131.8 | N3: =G42 -> 0 | O3: =F42 -> 17.71 | P3: =H42+I42 -> 0 | Q3: =IF(M3=N3,XIRR(Z2:Z41,Y2:Y41),"") | R3: =IF(M3=N3,B14,"") | S3: =IF(COUNTIFS(D:D,"<"&TODAY(),J:J,"")=0,"",TODAY()-_xlfn.MINIFS(D:D,D:D,"<"&TODAY(),J:J,"")) | Y3: =J2 -> 0 | Z3: =G2+H2+I2 -> 0
A4: Palūkanų pradžia | B4: 46283 | D4: 46575 | E4: 0 | F4: 2.96 | K4: =IF(J4>0,J4-D4,"") | Y4: =J3 -> 0 | Z4: =G3+H3+I3 -> 0
A5: Projekto reitingas | B5: A- | D5: 46667 | E5: 0 | F5: 2.99 | K5: =IF(J5>0,J5-D5,"") | Y5: =J4 -> 0 | Z5: =G4+H4+I4 -> 0
A6: LTV, % | B6: 0.44 | D6: 46759 | E6: 0 | F6: 2.99 | K6: =IF(J6>0,J6-D6,"") | Y6: =J5 -> 0 | Z6: =G5+H5+I5 -> 0
A7: LTV max, % | B7: 0.85 | D7: 46828 | E7: 131.8 | F7: 2.47 | K7: =IF(J7>0,J7-D7,"") | Y7: =J6 -> 0 | Z7: =G6+H6+I6 -> 0
A8: Investicijos laikotarpis, mėn. | B8: 18 | K8: =IF(J8>0,J8-D8,"") | Y8: =J7 -> 0 | Z8: =G7+H7+I7 -> 0
A9: Palūkanų mokėjimas | B9: Q | K9: =IF(J9>0,J9-D9,"") | Y9: =J8 -> 0 | Z9: =G8+H8+I8 -> 0
A10: Palūkanos, % | B10: 0.095 | K10: =IF(J10>0,J10-D10,"") | Y10: =J9 -> 0 | Z10: =G9+H9+I9 -> 0
A11: Investuota, Eur | B11: 131.8 | K11: =IF(J11>0,J11-D11,"") | Y11: =J10 -> 0 | Z11: =G10+H10+I10 -> 0
A12: Paskolos pabaiga | B12: 46828 | K12: =IF(J12>0,J12-D12,"") | Y12: =J11 -> 0 | Z12: =G11+H11+I11 -> 0
A13: Liko dienų | B13: =IF(B11<>N3,(TODAY()-B12)*-1,"") -> 533 | K13: =IF(J13>0,J13-D13,"") | Y13: =J12 -> 0 | Z13: =G12+H12+I12 -> 0
A14: Grąžinta | K14: =IF(J14>0,J14-D14,"") | Y14: =J13 -> 0 | Z14: =G13+H13+I13 -> 0
A15: Vėlavo/Anksčiau | B15: =IF(M3=N3,B14-B12,"") | K15: =IF(J15>0,J15-D15,"") | Y15: =J14 -> 0 | Z15: =G14+H14+I14 -> 0
K16: =IF(J16>0,J16-D16,"") | Y16: =J15 -> 0 | Z16: =G15+H15+I15 -> 0
K17: =IF(J17>0,J17-D17,"") | Y17: =J16 -> 0 | Z17: =G16+H16+I16 -> 0
K18: =IF(J18>0,J18-D18,"") | Y18: =J17 -> 0 | Z18: =G17+H17+I17 -> 0
K19: =IF(J19>0,J19-D19,"") | Y19: =J18 -> 0 | Z19: =G18+H18+I18 -> 0
K20: =IF(J20>0,J20-D20,"") | Y20: =J19 -> 0 | Z20: =G19+H19+I19 -> 0
K21: =IF(J21>0,J21-D21,"") | Y21: =J20 -> 0 | Z21: =G20+H20+I20 -> 0
K22: =IF(J22>0,J22-D22,"") | Y22: =J21 -> 0 | Z22: =G21+H21+I21 -> 0
K23: =IF(J23>0,J23-D23,"") | Y23: =J22 -> 0 | Z23: =G22+H22+I22 -> 0
K24: =IF(J24>0,J24-D24,"") | Y24: =J23 -> 0 | Z24: =G23+H23+I23 -> 0
K25: =IF(J25>0,J25-D25,"") | Y25: =J24 -> 0 | Z25: =G24+H24+I24 -> 0
K26: =IF(J26>0,J26-D26,"") | Y26: =J25 -> 0 | Z26: =G25+H25+I25 -> 0
K27: =IF(J27>0,J27-D27,"") | Y27: =J26 -> 0 | Z27: =G26+H26+I26 -> 0
... K41: =IF(J41>0,J41-D41,"") | Y41: =J40 -> 0 | Z41: =G40+H40+I40 -> 0
D42: Viso: | E42: =SUM(E2:E41) -> 131.8 | F42: =SUM(F2:F41) -> 17.71 | G42: =SUM(G2:G41) -> 0 | H42: =SUM(H2:H41) -> 0 | I42: =SUM(I2:I41) -> 0

Sheet Senvagės loftai, Panevėžys VIII
A1: Paskola | B1: Paskola P00001423-8 | D1: Data | E1: Paskola | F1: Palūkanos | G1: Paskola | H1: Palūkanos | I1: Papildomos | J1: Data | K1: Vėlavimas | M1: Paskola | O1: Palūkanos | Q1: XIRR | R1: Grąžinta | S1: Vėluoja | Y1: Data | Z1: Suma | AA1: Vėluoja
A2: Objektas | B2: Senvagės loftai, Panevėžys VIII | D2: 46363 | E2: 0 | F2: 2.99 | K2: =IF(J2>0,J2-D2,"") | M2: Suteikta | N2: Grąžinta | O2: Planuotos | P2: Realios | Y2: =B3 -> 46254 | Z2: =B11*-1 -> -122.1 | AA2: =IF(COUNTIFS(D:D,"<"&TODAY(),J:J,"")>0,"+","")
A3: Investicijos data | B3: 46254 | D3: 46453 | E3: 0 | F3: 2.8 | K3: =IF(J3>0,J3-D3,"") | M3: =B11 -> 122.1 | N3: =G42 -> 0 | O3: =F42 -> 11.11 | P3: =H42+I42 -> 0 | Q3: =IF(M3=N3,XIRR(Z2:Z41,Y2:Y41),"") | R3: =IF(M3=N3,B14,"") | S3: =IF(COUNTIFS(D:D,"<"&TODAY(),J:J,"")=0,"",TODAY()-_xlfn.MINIFS(D:D,D:D,"<"&TODAY(),J:J,"")) | Y3: =J2 -> 0 | Z3: =G2+H2+I2 -> 0
A4: Palūkanų pradžia | B4: 46260 | D4: 46545 | E4: 0 | F4: 2.86 | K4: =IF(J4>0,J4-D4,"") | Y4: =J3 -> 0 | Z4: =G3+H3+I3 -> 0
A5: Projekto reitingas | B5: A- | D5: 46617 | E5: 122.1 | F5: 2.46 | K5: =IF(J5>0,J5-D5,"") | Y5: =J4 -> 0 | Z5: =G4+H4+I4 -> 0
A6: LTV, % | B6: 0.54 | K6: =IF(J6>0,J6-D6,"") | Y6: =J5 -> 0 | Z6: =G5+H5+I5 -> 0
A7: LTV max, % | B7: 0.8 | K7: =IF(J7>0,J7-D7,"") | Y7: =J6 -> 0 | Z7: =G6+H6+I6 -> 0
A8: Investicijos laikotarpis, mėn. | B8: 12 | K8: =IF(J8>0,J8-D8,"") | Y8: =J7 -> 0 | Z8: =G7+H7+I7 -> 0
A9: Palūkanų mokėjimas | B9: Q | K9: =IF(J9>0,J9-D9,"") | Y9: =J8 -> 0 | Z9: =G8+H8+I8 -> 0
A10: Palūkanos, % | B10: 0.093 | K10: =IF(J10>0,J10-D10,"") | Y10: =J9 -> 0 | Z10: =G9+H9+I9 -> 0
A11: Investuota, Eur | B11: 122.1 | K11: =IF(J11>0,J11-D11,"") | Y11: =J10 -> 0 | Z11: =G10+H10+I10 -> 0
A12: Paskolos pabaiga | B12: 46617 | K12: =IF(J12>0,J12-D12,"") | Y12: =J11 -> 0 | Z12: =G11+H11+I11 -> 0
A13: Liko dienų | B13: =IF(B11<>N3,(TODAY()-B12)*-1,"") -> 322 | K13: =IF(J13>0,J13-D13,"") | Y13: =J12 -> 0 | Z13: =G12+H12+I12 -> 0
A14: Grąžinta | K14: =IF(J14>0,J14-D14,"") | Y14: =J13 -> 0 | Z14: =G13+H13+I13 -> 0
A15: Vėlavo/Anksčiau | B15: =IF(M3=N3,B14-B12,"") | K15: =IF(J15>0,J15-D15,"") | Y15: =J14 -> 0 | Z15: =G14+H14+I14 -> 0
K16: =IF(J16>0,J16-D16,"") | Y16: =J15 -> 0 | Z16: =G15+H15+I15 -> 0
K17: =IF(J17>0,J17-D17,"") | Y17: =J16 -> 0 | Z17: =G16+H16+I16 -> 0
K18: =IF(J18>0,J18-D18,"") | Y18: =J17 -> 0 | Z18: =G17+H17+I17 -> 0
K19: =IF(J19>0,J19-D19,"") | Y19: =J18 -> 0 | Z19: =G18+H18+I18 -> 0
K20: =IF(J20>0,J20-D20,"") | Y20: =J19 -> 0 | Z20: =G19+H19+I19 -> 0
K21: =IF(J21>0,J21-D21,"") | Y21: =J20 -> 0 | Z21: =G20+H20+I20 -> 0
K22: =IF(J22>0,J22-D22,"") | Y22: =J21 -> 0 | Z22: =G21+H21+I21 -> 0
K23: =IF(J23>0,J23-D23,"") | Y23: =J22 -> 0 | Z23: =G22+H22+I22 -> 0
K24: =IF(J24>0,J24-D24,"") | Y24: =J23 -> 0 | Z24: =G23+H23+I23 -> 0
K25: =IF(J25>0,J25-D25,"") | Y25: =J24 -> 0 | Z25: =G24+H24+I24 -> 0
K26: =IF(J26>0,J26-D26,"") | Y26: =J25 -> 0 | Z26: =G25+H25+I25 -> 0
K27: =IF(J27>0,J27-D27,"") | Y27: =J26 -> 0 | Z27: =G26+H26+I26 -> 0
... K41: =IF(J41>0,J41-D41,"") | Y41: =J40 -> 0 | Z41: =G40+H40+I40 -> 0
D42: Viso: | E42: =SUM(E2:E41) -> 122.1 | F42: =SUM(F2:F41) -> 11.11 | G42: =SUM(G2:G41) -> 0 | H42: =SUM(H2:H41) -> 0 | I42: =SUM(I2:I41) -> 0

Sheet Dvibučių kvartalas Kauno r. II
A1: Paskola | B1: Paskola P00001402-2 | D1: Data | E1: Paskola | F1: Palūkanos | G1: Paskola | H1: Palūkanos | I1: Papildomos | J1: Data | K1: Vėlavimas | M1: Paskola | O1: Palūkanos | Q1: XIRR | R1: Grąžinta | S1: Vėluoja | Y1: Data | Z1: Suma | AA1: Vėluoja
A2: Objektas | B2: Dvibučių kvartalas Kauno r. II | D2: 46265 | E2: 0 | F2: 2.19 | G2: 0 | H2: 2.19 | I2: 0 | J2: 46265 | K2: =IF(J2>0,J2-D2,"") -> 0 | M2: Suteikta | N2: Grąžinta | O2: Planuotos | P2: Realios | Y2: =B3 -> 46164 | Z2: =B11*-1 -> -102.9 | AA2: =IF(COUNTIFS(D:D,"<"&TODAY(),J:J,"")>0,"+","")
A3: Investicijos data | B3: 46164 | D3: 46356 | E3: 0 | F3: 2.05 | K3: =IF(J3>0,J3-D3,"") | M3: =B11 -> 102.9 | N3: =G42 -> 0 | O3: =F42 -> 8.19 | P3: =H42+I42 -> 2.19 | Q3: =IF(M3=N3,XIRR(Z2:Z41,Y2:Y41),"") | R3: =IF(M3=N3,B14,"") | S3: =IF(COUNTIFS(D:D,"<"&TODAY(),J:J,"")=0,"",TODAY()-_xlfn.MINIFS(D:D,D:D,"<"&TODAY(),J:J,"")) | Y3: =J2 -> 46265 | Z3: =G2+H2+I2 -> 2.19
A4: Palūkanų pradžia | B4: 46168 | D4: 46446 | E4: 0 | F4: 2.03 | K4: =IF(J4>0,J4-D4,"") | Y4: =J3 -> 0 | Z4: =G3+H3+I3 -> 0
A5: Projekto reitingas | B5: A | D5: 46531 | E5: 102.9 | F5: 1.92 | K5: =IF(J5>0,J5-D5,"") | Y5: =J4 -> 0 | Z5: =G4+H4+I4 -> 0
A6: LTV, % | B6: 0.7 | K6: =IF(J6>0,J6-D6,"") | Y6: =J5 -> 0 | Z6: =G5+H5+I5 -> 0
A7: LTV max, % | B7: 0.85 | K7: =IF(J7>0,J7-D7,"") | Y7: =J6 -> 0 | Z7: =G6+H6+I6 -> 0
A8: Investicijos laikotarpis, mėn. | B8: 12 | K8: =IF(J8>0,J8-D8,"") | Y8: =J7 -> 0 | Z8: =G7+H7+I7 -> 0
A9: Palūkanų mokėjimas | B9: Q | K9: =IF(J9>0,J9-D9,"") | Y9: =J8 -> 0 | Z9: =G8+H8+I8 -> 0
A10: Palūkanos, % | B10: 0.08 | K10: =IF(J10>0,J10-D10,"") | Y10: =J9 -> 0 | Z10: =G9+H9+I9 -> 0
A11: Investuota, Eur | B11: 102.9 | K11: =IF(J11>0,J11-D11,"") | Y11: =J10 -> 0 | Z11: =G10+H10+I10 -> 0
A12: Paskolos pabaiga | B12: 46531 | K12: =IF(J12>0,J12-D12,"") | Y12: =J11 -> 0 | Z12: =G11+H11+I11 -> 0
A13: Liko dienų | B13: =IF(B11<>N3,(TODAY()-B12)*-1,"") -> 236 | K13: =IF(J13>0,J13-D13,"") | Y13: =J12 -> 0 | Z13: =G12+H12+I12 -> 0
A14: Grąžinta | K14: =IF(J14>0,J14-D14,"") | Y14: =J13 -> 0 | Z14: =G13+H13+I13 -> 0
A15: Vėlavo/Anksčiau | B15: =IF(M3=N3,B14-B12,"") | K15: =IF(J15>0,J15-D15,"") | Y15: =J14 -> 0 | Z15: =G14+H14+I14 -> 0
K16: =IF(J16>0,J16-D16,"") | Y16: =J15 -> 0 | Z16: =G15+H15+I15 -> 0
K17: =IF(J17>0,J17-D17,"") | Y17: =J16 -> 0 | Z17: =G16+H16+I16 -> 0
K18: =IF(J18>0,J18-D18,"") | Y18: =J17 -> 0 | Z18: =G17+H17+I17 -> 0
K19: =IF(J19>0,J19-D19,"") | Y19: =J18 -> 0 | Z19: =G18+H18+I18 -> 0
K20: =IF(J20>0,J20-D20,"") | Y20: =J19 -> 0 | Z20: =G19+H19+I19 -> 0
K21: =IF(J21>0,J21-D21,"") | Y21: =J20 -> 0 | Z21: =G20+H20+I20 -> 0
K22: =IF(J22>0,J22-D22,"") | Y22: =J21 -> 0 | Z22: =G21+H21+I21 -> 0
K23: =IF(J23>0,J23-D23,"") | Y23: =J22 -> 0 | Z23: =G22+H22+I22 -> 0
K24: =IF(J24>0,J24-D24,"") | Y24: =J23 -> 0 | Z24: =G23+H23+I23 -> 0
K25: =IF(J25>0,J25-D25,"") | Y25: =J24 -> 0 | Z25: =G24+H24+I24 -> 0
K26: =IF(J26>0,J26-D26,"") | Y26: =J25 -> 0 | Z26: =G25+H25+I25 -> 0
K27: =IF(J27>0,J27-D27,"") | Y27: =J26 -> 0 | Z27: =G26+H26+I26 -> 0
... K41: =IF(J41>0,J41-D41,"") | Y41: =J40 -> 0 | Z41: =G40+H40+I40 -> 0
D42: Viso: | E42: =SUM(E2:E41) -> 102.9 | F42: =SUM(F2:F41) -> 8.19 | G42: =SUM(G2:G41) -> 0 | H42: =SUM(H2:H41) -> 2.19 | I42: =SUM(I2:I41) -> 0

Sheet Molėtų Oazė XII
A1: Paskola | B1: Paskola P00001400-14 | D1: Data | E1: Paskola | F1: Palūkanos | G1: Paskola | H1: Palūkanos | I1: Papildomos | J1: Data | K1: Vėlavimas | M1: Paskola | O1: Palūkanos | Q1: XIRR | R1: Grąžinta | S1: Vėluoja | Y1: Data | Z1: Suma | AA1: Vėluoja
A2: Objektas | B2: Molėtų Oazė XII | D2: 46265 | E2: 0 | F2: 2.68 | G2: 0 | H2: 2.68 | I2: 0 | J2: 46265 | K2: =IF(J2>0,J2-D2,"") -> 0 | M2: Suteikta | N2: Grąžinta | O2: Planuotos | P2: Realios | Y2: =B3 -> 46156 | Z2: =B11*-1 -> -105.2 | AA2: =IF(COUNTIFS(D:D,"<"&TODAY(),J:J,"")>0,"+","")
A3: Investicijos data | B3: 46156 | D3: 46356 | E3: 0 | F3: 2.26 | K3: =IF(J3>0,J3-D3,"") | M3: =B11 -> 105.2 | N3: =G42 -> 0 | O3: =F42 -> 9 | P3: =H42+I42 -> 2.68 | Q3: =IF(M3=N3,XIRR(Z2:Z41,Y2:Y41),"") | R3: =IF(M3=N3,B14,"") | S3: =IF(COUNTIFS(D:D,"<"&TODAY(),J:J,"")=0,"",TODAY()-_xlfn.MINIFS(D:D,D:D,"<"&TODAY(),J:J,"")) | Y3: =J2 -> 46265 | Z3: =G2+H2+I2 -> 2.68
A4: Palūkanų pradžia | B4: 46156 | D4: 46446 | E4: 0 | F4: 2.23 | K4: =IF(J4>0,J4-D4,"") | Y4: =J3 -> 0 | Z4: =G3+H3+I3 -> 0
A5: Projekto reitingas | B5: A- | D5: 46520 | E5: 105.2 | F5: 1.83 | K5: =IF(J5>0,J5-D5,"") | Y5: =J4 -> 0 | Z5: =G4+H4+I4 -> 0
A6: LTV, % | B6: 0.59 | K6: =IF(J6>0,J6-D6,"") | Y6: =J5 -> 0 | Z6: =G5+H5+I5 -> 0
A7: LTV max, % | B7: 0.85 | K7: =IF(J7>0,J7-D7,"") | Y7: =J6 -> 0 | Z7: =G6+H6+I6 -> 0
A8: Investicijos laikotarpis, mėn. | B8: 12 | K8: =IF(J8>0,J8-D8,"") | Y8: =J7 -> 0 | Z8: =G7+H7+I7 -> 0
A9: Palūkanų mokėjimas | B9: Q | K9: =IF(J9>0,J9-D9,"") | Y9: =J8 -> 0 | Z9: =G8+H8+I8 -> 0
A10: Palūkanos, % | B10: 0.086 | K10: =IF(J10>0,J10-D10,"") | Y10: =J9 -> 0 | Z10: =G9+H9+I9 -> 0
A11: Investuota, Eur | B11: 105.2 | K11: =IF(J11>0,J11-D11,"") | Y11: =J10 -> 0 | Z11: =G10+H10+I10 -> 0
A12: Paskolos pabaiga | B12: 46520 | K12: =IF(J12>0,J12-D12,"") | Y12: =J11 -> 0 | Z12: =G11+H11+I11 -> 0
A13: Liko dienų | B13: =IF(B11<>N3,(TODAY()-B12)*-1,"") -> 225 | K13: =IF(J13>0,J13-D13,"") | Y13: =J12 -> 0 | Z13: =G12+H12+I12 -> 0
A14: Grąžinta | K14: =IF(J14>0,J14-D14,"") | Y14: =J13 -> 0 | Z14: =G13+H13+I13 -> 0
A15: Vėlavo/Anksčiau | B15: =IF(M3=N3,B14-B12,"") | K15: =IF(J15>0,J15-D15,"") | Y15: =J14 -> 0 | Z15: =G14+H14+I14 -> 0
K16: =IF(J16>0,J16-D16,"") | Y16: =J15 -> 0 | Z16: =G15+H15+I15 -> 0
K17: =IF(J17>0,J17-D17,"") | Y17: =J16 -> 0 | Z17: =G16+H16+I16 -> 0
K18: =IF(J18>0,J18-D18,"") | Y18: =J17 -> 0 | Z18: =G17+H17+I17 -> 0
K19: =IF(J19>0,J19-D19,"") | Y19: =J18 -> 0 | Z19: =G18+H18+I18 -> 0
K20: =IF(J20>0,J20-D20,"") | Y20: =J19 -> 0 | Z20: =G19+H19+I19 -> 0
K21: =IF(J21>0,J21-D21,"") | Y21: =J20 -> 0 | Z21: =G20+H20+I20 -> 0
K22: =IF(J22>0,J22-D22,"") | Y22: =J21 -> 0 | Z22: =G21+H21+I21 -> 0
K23: =IF(J23>0,J23-D23,"") | Y23: =J22 -> 0 | Z23: =G22+H22+I22 -> 0
K24: =IF(J24>0,J24-D24,"") | Y24: =J23 -> 0 | Z24: =G23+H23+I23 -> 0
K25: =IF(J25>0,J25-D25,"") | Y25: =J24 -> 0 | Z25: =G24+H24+I24 -> 0
K26: =IF(J26>0,J26-D26,"") | Y26: =J25 -> 0 | Z26: =G25+H25+I25 -> 0
K27: =IF(J27>0,J27-D27,"") | Y27: =J26 -> 0 | Z27: =G26+H26+I26 -> 0
... K41: =IF(J41>0,J41-D41,"") | Y41: =J40 -> 0 | Z41: =G40+H40+I40 -> 0
D42: Viso: | E42: =SUM(E2:E41) -> 105.2 | F42: =SUM(F2:F41) -> 9 | G42: =SUM(G2:G41) -> 0 | H42: =SUM(H2:H41) -> 2.68 | I42: =SUM(I2:I41) -> 0

Sheet Europos 70, Kaunas XX
A1: Paskola | B1: Paskola P00001398-20 | D1: Data | E1: Paskola | F1: Palūkanos | G1: Paskola | H1: Palūkanos | I1: Papildomos | J1: Data | K1: Vėlavimas | M1: Paskola | O1: Palūkanos | Q1: XIRR | R1: Grąžinta | S1: Vėluoja | Y1: Data | Z1: Suma | AA1: Vėluoja
A2: Objektas | B2: Europos 70, Kaunas XX | D2: 46234 | E2: 0 | F2: 2.54 | G2: 0 | H2: 2.54 | I2: 0.45 | J2: 46266 | K2: =IF(J2>0,J2-D2,"") -> 32 | M2: Suteikta | N2: Grąžinta | O2: Planuotos | P2: Realios | Y2: =B3 -> 46139 | Z2: =B11*-1 -> -120.3 | AA2: =IF(COUNTIFS(D:D,"<"&TODAY(),J:J,"")>0,"+","")
A3: Investicijos data | B3: 46139 | D3: 46326 | E3: 0 | F3: 2.49 | K3: =IF(J3>0,J3-D3,"") | M3: =B11 -> 120.3 | N3: =G42 -> 0 | O3: =F42 -> 9.82 | P3: =H42+I42 -> 2.99 | Q3: =IF(M3=N3,XIRR(Z2:Z41,Y2:Y41),"") | R3: =IF(M3=N3,B14,"") | S3: =IF(COUNTIFS(D:D,"<"&TODAY(),J:J,"")=0,"",TODAY()-_xlfn.MINIFS(D:D,D:D,"<"&TODAY(),J:J,"")) | Y3: =J2 -> 46266 | Z3: =G2+H2+I2 -> 2.99
A4: Palūkanų pradžia | B4: 46139 | D4: 46418 | E4: 0 | F4: 2.49 | K4: =IF(J4>0,J4-D4,"") | Y4: =J3 -> 0 | Z4: =G3+H3+I3 -> 0
A5: Projekto reitingas | B5: A+ | D5: 46503 | E5: 120.3 | F5: 2.3 | K5: =IF(J5>0,J5-D5,"") | Y5: =J4 -> 0 | Z5: =G4+H4+I4 -> 0
A6: LTV, % | B6: 0.56 | K6: =IF(J6>0,J6-D6,"") | Y6: =J5 -> 0 | Z6: =G5+H5+I5 -> 0
A7: LTV max, % | B7: 0.75 | K7: =IF(J7>0,J7-D7,"") | Y7: =J6 -> 0 | Z7: =G6+H6+I6 -> 0
A8: Investicijos laikotarpis, mėn. | B8: 12 | K8: =IF(J8>0,J8-D8,"") | Y8: =J7 -> 0 | Z8: =G7+H7+I7 -> 0
A9: Palūkanų mokėjimas | B9: Q | K9: =IF(J9>0,J9-D9,"") | Y9: =J8 -> 0 | Z9: =G8+H8+I8 -> 0
A10: Palūkanos, % | B10: 0.082 | K10: =IF(J10>0,J10-D10,"") | Y10: =J9 -> 0 | Z10: =G9+H9+I9 -> 0
A11: Investuota, Eur | B11: 120.3 | K11: =IF(J11>0,J11-D11,"") | Y11: =J10 -> 0 | Z11: =G10+H10+I10 -> 0
A12: Paskolos pabaiga | B12: 46503 | K12: =IF(J12>0,J12-D12,"") | Y12: =J11 -> 0 | Z12: =G11+H11+I11 -> 0
A13: Liko dienų | B13: =IF(B11<>N3,(TODAY()-B12)*-1,"") -> 208 | K13: =IF(J13>0,J13-D13,"") | Y13: =J12 -> 0 | Z13: =G12+H12+I12 -> 0
A14: Grąžinta | K14: =IF(J14>0,J14-D14,"") | Y14: =J13 -> 0 | Z14: =G13+H13+I13 -> 0
A15: Vėlavo/Anksčiau | B15: =IF(M3=N3,B14-B12,"") | K15: =IF(J15>0,J15-D15,"") | Y15: =J14 -> 0 | Z15: =G14+H14+I14 -> 0
K16: =IF(J16>0,J16-D16,"") | Y16: =J15 -> 0 | Z16: =G15+H15+I15 -> 0
K17: =IF(J17>0,J17-D17,"") | Y17: =J16 -> 0 | Z17: =G16+H16+I16 -> 0
K18: =IF(J18>0,J18-D18,"") | Y18: =J17 -> 0 | Z18: =G17+H17+I17 -> 0
K19: =IF(J19>0,J19-D19,"") | Y19: =J18 -> 0 | Z19: =G18+H18+I18 -> 0
K20: =IF(J20>0,J20-D20,"") | Y20: =J19 -> 0 | Z20: =G19+H19+I19 -> 0
K21: =IF(J21>0,J21-D21,"") | Y21: =J20 -> 0 | Z21: =G20+H20+I20 -> 0
K22: =IF(J22>0,J22-D22,"") | Y22: =J21 -> 0 | Z22: =G21+H21+I21 -> 0
K23: =IF(J23>0,J23-D23,"") | Y23: =J22 -> 0 | Z23: =G22+H22+I22 -> 0
K24: =IF(J24>0,J24-D24,"") | Y24: =J23 -> 0 | Z24: =G23+H23+I23 -> 0
K25: =IF(J25>0,J25-D25,"") | Y25: =J24 -> 0 | Z25: =G24+H24+I24 -> 0
K26: =IF(J26>0,J26-D26,"") | Y26: =J25 -> 0 | Z26: =G25+H25+I25 -> 0
K27: =IF(J27>0,J27-D27,"") | Y27: =J26 -> 0 | Z27: =G26+H26+I26 -> 0
... K41: =IF(J41>0,J41-D41,"") | Y41: =J40 -> 0 | Z41: =G40+H40+I40 -> 0
D42: Viso: | E42: =SUM(E2:E41) -> 120.3 | F42: =SUM(F2:F41) -> 9.82 | G42: =SUM(G2:G41) -> 0 | H42: =SUM(H2:H41) -> 2.54 | I42: =SUM(I2:I41) -> 0.45

Sheet Brivibas 28, Jūrmala
A1: Paskola | B1: Paskola P00001560 | D1: Data | E1: Paskola | F1: Palūkanos | G1: Paskola | H1: Palūkanos | I1: Papildomos | J1: Data | K1: Vėlavimas | M1: Paskola | O1: Palūkanos | Q1: XIRR | R1: Grąžinta | S1: Vėluoja | Y1: Data | Z1: Suma | AA1: Vėluoja
A2: Objektas | B2: Brivibas 28, Jūrmala | D2: 46142 | E2: 0 | F2: 1.18 | G2: 0 | H2: 1.18 | I2: 0 | J2: 46142 | K2: =IF(J2>0,J2-D2,"") -> 0 | M2: Suteikta | N2: Grąžinta | O2: Planuotos | P2: Realios | Y2: =B3 -> 46101 | Z2: =B11*-1 -> -135.7 | AA2: =IF(COUNTIFS(D:D,"<"&TODAY(),J:J,"")>0,"+","")
A3: Investicijos data | B3: 46101 | D3: 46173 | E3: 0 | F3: 1.05 | G3: 0 | H3: 1.05 | I3: 0 | J3: 46174 | K3: =IF(J3>0,J3-D3,"") -> 1 | M3: =B11 -> 135.7 | N3: =G42 -> 48.96 | O3: =F42 -> 13.28 | P3: =H42+I42 -> 6.11 | Q3: =IF(M3=N3,XIRR(Z2:Z41,Y2:Y41),"") | R3: =IF(M3=N3,B14,"") | S3: =IF(COUNTIFS(D:D,"<"&TODAY(),J:J,"")=0,"",TODAY()-_xlfn.MINIFS(D:D,D:D,"<"&TODAY(),J:J,"")) | Y3: =J2 -> 46142 | Z3: =G2+H2+I2 -> 1.18
A4: Palūkanų pradžia | B4: 46107 | D4: 46203 | E4: 0 | F4: 1.01 | G4: 0 | H4: 1.01 | I4: 0 | J4: 46203 | K4: =IF(J4>0,J4-D4,"") -> 0 | Y4: =J3 -> 46174 | Z4: =G3+H3+I3 -> 1.05
A5: Projekto reitingas | B5: A+ | D5: 46234 | E5: 0 | F5: 1.05 | G5: 0 | H5: 1.05 | I5: 0 | J5: 46234 | K5: =IF(J5>0,J5-D5,"") -> 0 | Y5: =J4 -> 46203 | Z5: =G4+H4+I4 -> 1.01
A6: LTV, % | B6: 0.71 | D6: 46265 | E6: 0 | F6: 1.05 | G6: 0 | H6: 1.05 | I6: 0 | J6: 46266 | K6: =IF(J6>0,J6-D6,"") -> 1 | Y6: =J5 -> 46234 | Z6: =G5+H5+I5 -> 1.05
A7: LTV max, % | B7: 0.71 | D7: 46280 | E7: 0 | F7: 0 | G7: 48.48 | H7: 0.12 | I7: 0 | J7: 46280 | K7: =IF(J7>0,J7-D7,"") -> 0 | Y7: =J6 -> 46266 | Z7: =G6+H6+I6 -> 1.05
A8: Investicijos laikotarpis, mėn. | B8: 12 | D8: 46283 | E8: 0 | F8: 1.01 | G8: 0.48 | H8: 0 | I8: 0 | J8: 46283 | K8: =IF(J8>0,J8-D8,"") -> 0 | Y8: =J7 -> 46280 | Z8: =G7+H7+I7 -> 48.6
A9: Palūkanų mokėjimas | B9: M | D9: 46295 | E9: 0 | F9: 1.01 | G9: 0 | H9: 0.65 | I9: 0 | J9: 46294 | K9: =IF(J9>0,J9-D9,"") -> -1 | Y9: =J8 -> 46283 | Z9: =G8+H8+I8 -> 0.48
A10: Palūkanos, % | B10: 0.095 | D10: 46326 | E10: 0 | F10: 1.05 | K10: =IF(J10>0,J10-D10,"") | Y10: =J9 -> 46294 | Z10: =G9+H9+I9 -> 0.65
A11: Investuota, Eur | B11: 135.7 | D11: 46356 | E11: 0 | F11: 1.01 | K11: =IF(J11>0,J11-D11,"") | Y11: =J10 -> 0 | Z11: =G10+H10+I10 -> 0
A12: Paskolos pabaiga | B12: 46470 | D12: 46387 | E12: 0 | F12: 1.05 | K12: =IF(J12>0,J12-D12,"") | Y12: =J11 -> 0 | Z12: =G11+H11+I11 -> 0
A13: Liko dienų | B13: =IF(B11<>N3,(TODAY()-B12)*-1,"") -> 175 | D13: 46418 | E13: 0 | F13: 1.05 | K13: =IF(J13>0,J13-D13,"") | Y13: =J12 -> 0 | Z13: =G12+H12+I12 -> 0
A14: Grąžinta | D14: 46446 | E14: 0 | F14: 0.95 | K14: =IF(J14>0,J14-D14,"") | Y14: =J13 -> 0 | Z14: =G13+H13+I13 -> 0
A15: Vėlavo/Anksčiau | B15: =IF(M3=N3,B14-B12,"") | D15: 46470 | E15: 135.7 | F15: 0.81 | K15: =IF(J15>0,J15-D15,"") | Y15: =J14 -> 0 | Z15: =G14+H14+I14 -> 0
K16: =IF(J16>0,J16-D16,"") | Y16: =J15 -> 0 | Z16: =G15+H15+I15 -> 0
K17: =IF(J17>0,J17-D17,"") | Y17: =J16 -> 0 | Z17: =G16+H16+I16 -> 0
K18: =IF(J18>0,J18-D18,"") | Y18: =J17 -> 0 | Z18: =G17+H17+I17 -> 0
K19: =IF(J19>0,J19-D19,"") | Y19: =J18 -> 0 | Z19: =G18+H18+I18 -> 0
K20: =IF(J20>0,J20-D20,"") | Y20: =J19 -> 0 | Z20: =G19+H19+I19 -> 0
K21: =IF(J21>0,J21-D21,"") | Y21: =J20 -> 0 | Z21: =G20+H20+I20 -> 0
K22: =IF(J22>0,J22-D22,"") | Y22: =J21 -> 0 | Z22: =G21+H21+I21 -> 0
K23: =IF(J23>0,J23-D23,"") | Y23: =J22 -> 0 | Z23: =G22+H22+I22 -> 0
K24: =IF(J24>0,J24-D24,"") | Y24: =J23 -> 0 | Z24: =G23+H23+I23 -> 0
K25: =IF(J25>0,J25-D25,"") | Y25: =J24 -> 0 | Z25: =G24+H24+I24 -> 0
K26: =IF(J26>0,J26-D26,"") | Y26: =J25 -> 0 | Z26: =G25+H25+I25 -> 0
K27: =IF(J27>0,J27-D27,"") | Y27: =J26 -> 0 | Z27: =G26+H26+I26 -> 0
... K41: =IF(J41>0,J41-D41,"") | Y41: =J40 -> 0 | Z41: =G40+H40+I40 -> 0
D42: Viso: | E42: =SUM(E2:E41) -> 135.7 | F42: =SUM(F2:F41) -> 13.28 | G42: =SUM(G2:G41) -> 48.96 | H42: =SUM(H2:H41) -> 6.11 | I42: =SUM(I2:I41) -> 0

Sheet Svajonių Daugiabutis, Kaunas
A1: Paskola | B1: Paskola P00001553 | D1: Data | E1: Paskola | F1: Palūkanos | G1: Paskola | H1: Palūkanos | I1: Papildomos | J1: Data | K1: Vėlavimas | M1: Paskola | O1: Palūkanos | Q1: XIRR | R1: Grąžinta | S1: Vėluoja | Y1: Data | Z1: Suma | AA1: Vėluoja
A2: Objektas | B2: Svajonių Daugiabutis, Kaunas | D2: 46173 | E2: 0 | F2: 2.4 | G2: 0 | H2: 2.4 | I2: 0 | J2: 46174 | K2: =IF(J2>0,J2-D2,"") -> 1 | M2: Suteikta | N2: Grąžinta | O2: Planuotos | P2: Realios | Y2: =B3 -> 46073 | Z2: =B11*-1 -> -101.5 | AA2: =IF(COUNTIFS(D:D,"<"&TODAY(),J:J,"")>0,"+","")
A3: Investicijos data | B3: 46073 | D3: 46265 | E3: 0 | F3: 2.3 | G3: 0 | H3: 2.3 | I3: 0 | J3: 46266 | K3: =IF(J3>0,J3-D3,"") -> 1 | M3: =B11 -> 101.5 | N3: =G42 -> 0 | O3: =F42 -> 9.08 | P3: =H42+I42 -> 4.7 | Q3: =IF(M3=N3,XIRR(Z2:Z41,Y2:Y41),"") | R3: =IF(M3=N3,B14,"") | S3: =IF(COUNTIFS(D:D,"<"&TODAY(),J:J,"")=0,"",TODAY()-_xlfn.MINIFS(D:D,D:D,"<"&TODAY(),J:J,"")) | Y3: =J2 -> 46174 | Z3: =G2+H2+I2 -> 2.4
A4: Palūkanų pradžia | B4: 46076 | D4: 46356 | E4: 0 | F4: 2.28 | K4: =IF(J4>0,J4-D4,"") | Y4: =J3 -> 46266 | Z4: =G3+H3+I3 -> 2.3
A5: Projekto reitingas | B5: A- | D5: 46440 | E5: 101.5 | F5: 2.1 | K5: =IF(J5>0,J5-D5,"") | Y5: =J4 -> 0 | Z5: =G4+H4+I4 -> 0
A6: LTV, % | B6: 0.6 | K6: =IF(J6>0,J6-D6,"") | Y6: =J5 -> 0 | Z6: =G5+H5+I5 -> 0
A7: LTV max, % | B7: 0.75 | K7: =IF(J7>0,J7-D7,"") | Y7: =J6 -> 0 | Z7: =G6+H6+I6 -> 0
A8: Investicijos laikotarpis, mėn. | B8: 12 | K8: =IF(J8>0,J8-D8,"") | Y8: =J7 -> 0 | Z8: =G7+H7+I7 -> 0
A9: Palūkanų mokėjimas | B9: Q | K9: =IF(J9>0,J9-D9,"") | Y9: =J8 -> 0 | Z9: =G8+H8+I8 -> 0
A10: Palūkanos, % | B10: 0.09 | K10: =IF(J10>0,J10-D10,"") | Y10: =J9 -> 0 | Z10: =G9+H9+I9 -> 0
A11: Investuota, Eur | B11: 101.5 | K11: =IF(J11>0,J11-D11,"") | Y11: =J10 -> 0 | Z11: =G10+H10+I10 -> 0
A12: Paskolos pabaiga | B12: 46440 | K12: =IF(J12>0,J12-D12,"") | Y12: =J11 -> 0 | Z12: =G11+H11+I11 -> 0
A13: Liko dienų | B13: =IF(B11<>N3,(TODAY()-B12)*-1,"") -> 145 | K13: =IF(J13>0,J13-D13,"") | Y13: =J12 -> 0 | Z13: =G12+H12+I12 -> 0
A14: Grąžinta | K14: =IF(J14>0,J14-D14,"") | Y14: =J13 -> 0 | Z14: =G13+H13+I13 -> 0
A15: Vėlavo/Anksčiau | B15: =IF(M3=N3,B14-B12,"") | K15: =IF(J15>0,J15-D15,"") | Y15: =J14 -> 0 | Z15: =G14+H14+I14 -> 0
K16: =IF(J16>0,J16-D16,"") | Y16: =J15 -> 0 | Z16: =G15+H15+I15 -> 0
K17: =IF(J17>0,J17-D17,"") | Y17: =J16 -> 0 | Z17: =G16+H16+I16 -> 0
K18: =IF(J18>0,J18-D18,"") | Y18: =J17 -> 0 | Z18: =G17+H17+I17 -> 0
K19: =IF(J19>0,J19-D19,"") | Y19: =J18 -> 0 | Z19: =G18+H18+I18 -> 0
K20: =IF(J20>0,J20-D20,"") | Y20: =J19 -> 0 | Z20: =G19+H19+I19 -> 0
K21: =IF(J21>0,J21-D21,"") | Y21: =J20 -> 0 | Z21: =G20+H20+I20 -> 0
K22: =IF(J22>0,J22-D22,"") | Y22: =J21 -> 0 | Z22: =G21+H21+I21 -> 0
K23: =IF(J23>0,J23-D23,"") | Y23: =J22 -> 0 | Z23: =G22+H22+I22 -> 0
K24: =IF(J24>0,J24-D24,"") | Y24: =J23 -> 0 | Z24: =G23+H23+I23 -> 0
K25: =IF(J25>0,J25-D25,"") | Y25: =J24 -> 0 | Z25: =G24+H24+I24 -> 0
K26: =IF(J26>0,J26-D26,"") | Y26: =J25 -> 0 | Z26: =G25+H25+I25 -> 0
K27: =IF(J27>0,J27-D27,"") | Y27: =J26 -> 0 | Z27: =G26+H26+I26 -> 0
... K41: =IF(J41>0,J41-D41,"") | Y41: =J40 -> 0 | Z41: =G40+H40+I40 -> 0
D42: Viso: | E42: =SUM(E2:E41) -> 101.5 | F42: =SUM(F2:F41) -> 9.08 | G42: =SUM(G2:G41) -> 0 | H42: =SUM(H2:H41) -> 4.7 | I42: =SUM(I2:I41) -> 0

Sheet Golf Hills Vilos, Alikantė
A1: Paskola | B1: Paskola P00001480 | D1: Data | E1: Paskola | F1: Palūkanos | G1: Paskola | H1: Palūkanos | I1: Papildomos | J1: Data | K1: Vėlavimas | M1: Paskola | O1: Palūkanos | Q1: XIRR | R1: Grąžinta | S1: Vėluoja | Y1: Data | Z1: Suma | AA1: Vėluoja
A2: Objektas | B2: Golf Hills Vilos, Alikantė | D2: 46173 | E2: 0 | F2: 2.98 | G2: 0 | H2: 2.98 | I2: 0.03 | J2: 46178 | K2: =IF(J2>0,J2-D2,"") -> 5 | M2: Suteikta | N2: Grąžinta | O2: Planuotos | P2: Realios | Y2: =B3 -> 46059 | Z2: =B11*-1 -> -102.9 | AA2: =IF(COUNTIFS(D:D,"<"&TODAY(),J:J,"")>0,"+","")
A3: Investicijos data | B3: 46059 | D3: 46265 | E3: 0 | F3: 2.49 | G3: 0 | H3: 2.49 | I3: 0 | J3: 46268 | K3: =IF(J3>0,J3-D3,"") -> 3 | M3: =B11 -> 102.9 | N3: =G42 -> 0 | O3: =F42 -> 9.82 | P3: =H42+I42 -> 5.5 | Q3: =IF(M3=N3,XIRR(Z2:Z41,Y2:Y41),"") | R3: =IF(M3=N3,B14,"") | S3: =IF(COUNTIFS(D:D,"<"&TODAY(),J:J,"")=0,"",TODAY()-_xlfn.MINIFS(D:D,D:D,"<"&TODAY(),J:J,"")) | Y3: =J2 -> 46178 | Z3: =G2+H2+I2 -> 3.01
A4: Palūkanų pradžia | B4: 46062 | D4: 46356 | E4: 0 | F4: 2.46 | K4: =IF(J4>0,J4-D4,"") | Y4: =J3 -> 46268 | Z4: =G3+H3+I3 -> 2.49
A5: Projekto reitingas | B5: AA | D5: 46426 | E5: 102.9 | F5: 1.89 | K5: =IF(J5>0,J5-D5,"") | Y5: =J4 -> 0 | Z5: =G4+H4+I4 -> 0
A6: LTV, % | B6: 0.43 | K6: =IF(J6>0,J6-D6,"") | Y6: =J5 -> 0 | Z6: =G5+H5+I5 -> 0
A7: LTV max, % | B7: 0.75 | K7: =IF(J7>0,J7-D7,"") | Y7: =J6 -> 0 | Z7: =G6+H6+I6 -> 0
A8: Investicijos laikotarpis, mėn. | B8: 12 | K8: =IF(J8>0,J8-D8,"") | Y8: =J7 -> 0 | Z8: =G7+H7+I7 -> 0
A9: Palūkanų mokėjimas | B9: Q | K9: =IF(J9>0,J9-D9,"") | Y9: =J8 -> 0 | Z9: =G8+H8+I8 -> 0
A10: Palūkanos, % | B10: 0.096 | K10: =IF(J10>0,J10-D10,"") | Y10: =J9 -> 0 | Z10: =G9+H9+I9 -> 0
A11: Investuota, Eur | B11: 102.9 | K11: =IF(J11>0,J11-D11,"") | Y11: =J10 -> 0 | Z11: =G10+H10+I10 -> 0
A12: Paskolos pabaiga | B12: 46426 | K12: =IF(J12>0,J12-D12,"") | Y12: =J11 -> 0 | Z12: =G11+H11+I11 -> 0
A13: Liko dienų | B13: =IF(B11<>N3,(TODAY()-B12)*-1,"") -> 131 | K13: =IF(J13>0,J13-D13,"") | Y13: =J12 -> 0 | Z13: =G12+H12+I12 -> 0
A14: Grąžinta | K14: =IF(J14>0,J14-D14,"") | Y14: =J13 -> 0 | Z14: =G13+H13+I13 -> 0
A15: Vėlavo/Anksčiau | B15: =IF(M3=N3,B14-B12,"") | K15: =IF(J15>0,J15-D15,"") | Y15: =J14 -> 0 | Z15: =G14+H14+I14 -> 0
K16: =IF(J16>0,J16-D16,"") | Y16: =J15 -> 0 | Z16: =G15+H15+I15 -> 0
K17: =IF(J17>0,J17-D17,"") | Y17: =J16 -> 0 | Z17: =G16+H16+I16 -> 0
K18: =IF(J18>0,J18-D18,"") | Y18: =J17 -> 0 | Z18: =G17+H17+I17 -> 0
K19: =IF(J19>0,J19-D19,"") | Y19: =J18 -> 0 | Z19: =G18+H18+I18 -> 0
K20: =IF(J20>0,J20-D20,"") | Y20: =J19 -> 0 | Z20: =G19+H19+I19 -> 0
K21: =IF(J21>0,J21-D21,"") | Y21: =J20 -> 0 | Z21: =G20+H20+I20 -> 0
K22: =IF(J22>0,J22-D22,"") | Y22: =J21 -> 0 | Z22: =G21+H21+I21 -> 0
K23: =IF(J23>0,J23-D23,"") | Y23: =J22 -> 0 | Z23: =G22+H22+I22 -> 0
K24: =IF(J24>0,J24-D24,"") | Y24: =J23 -> 0 | Z24: =G23+H23+I23 -> 0
K25: =IF(J25>0,J25-D25,"") | Y25: =J24 -> 0 | Z25: =G24+H24+I24 -> 0
K26: =IF(J26>0,J26-D26,"") | Y26: =J25 -> 0 | Z26: =G25+H25+I25 -> 0
K27: =IF(J27>0,J27-D27,"") | Y27: =J26 -> 0 | Z27: =G26+H26+I26 -> 0
... K41: =IF(J41>0,J41-D41,"") | Y41: =J40 -> 0 | Z41: =G40+H40+I40 -> 0
D42: Viso: | E42: =SUM(E2:E41) -> 102.9 | F42: =SUM(F2:F41) -> 9.82 | G42: =SUM(G2:G41) -> 0 | H42: =SUM(H2:H41) -> 5.47 | I42: =SUM(I2:I41) -> 0.03

Sheet Sklypas Kalnėnuose, Vilnius II
A1: Paskola | B1: Paskola P00001514-2 | D1: Data | E1: Paskola | F1: Palūkanos | G1: Paskola | H1: Palūkanos | I1: Papildomos | J1: Data | K1: Vėlavimas | M1: Paskola | O1: Palūkanos | Q1: XIRR | R1: Grąžinta | S1: Vėluoja | Y1: Data | Z1: Suma | AA1: Vėluoja
A2: Objektas | B2: Sklypas Kalnėnuose, Vilnius II | D2: 46142 | E2: 0 | F2: 2.44 | G2: 0 | H2: 2.44 | I2: 0 | J2: 46142 | K2: =IF(J2>0,J2-D2,"") -> 0 | M2: Suteikta | N2: Grąžinta | O2: Planuotos | P2: Realios | Y2: =B3 -> 46028 | Z2: =B11*-1 -> -104.1 | AA2: =IF(COUNTIFS(D:D,"<"&TODAY(),J:J,"")>0,"+","")
A3: Investicijos data | B3: 46028 | D3: 46234 | E3: 0 | F3: 2.1 | G3: 0 | H3: 2.1 | I3: 0 | J3: 46234 | K3: =IF(J3>0,J3-D3,"") -> 0 | M3: =B11 -> 104.1 | N3: =G42 -> 0 | O3: =F42 -> 8.28 | P3: =H42+I42 -> 4.54 | Q3: =IF(M3=N3,XIRR(Z2:Z41,Y2:Y41),"") | R3: =IF(M3=N3,B14,"") | S3: =IF(COUNTIFS(D:D,"<"&TODAY(),J:J,"")=0,"",TODAY()-_xlfn.MINIFS(D:D,D:D,"<"&TODAY(),J:J,"")) | Y3: =J2 -> 46142 | Z3: =G2+H2+I2 -> 2.44
A4: Palūkanų pradžia | B4: 46034 | D4: 46326 | E4: 0 | F4: 2.1 | K4: =IF(J4>0,J4-D4,"") | Y4: =J3 -> 46234 | Z4: =G3+H3+I3 -> 2.1
A5: Projekto reitingas | B5: AA+ | D5: 46398 | E5: 104.1 | F5: 1.64 | K5: =IF(J5>0,J5-D5,"") | Y5: =J4 -> 0 | Z5: =G4+H4+I4 -> 0
A6: LTV, % | B6: 0.55 | K6: =IF(J6>0,J6-D6,"") | Y6: =J5 -> 0 | Z6: =G5+H5+I5 -> 0
A7: LTV max, % | B7: 0.6 | K7: =IF(J7>0,J7-D7,"") | Y7: =J6 -> 0 | Z7: =G6+H6+I6 -> 0
A8: Investicijos laikotarpis, mėn. | B8: 12 | K8: =IF(J8>0,J8-D8,"") | Y8: =J7 -> 0 | Z8: =G7+H7+I7 -> 0
A9: Palūkanų mokėjimas | B9: Q | K9: =IF(J9>0,J9-D9,"") | Y9: =J8 -> 0 | Z9: =G8+H8+I8 -> 0
A10: Palūkanos, % | B10: 0.08 | K10: =IF(J10>0,J10-D10,"") | Y10: =J9 -> 0 | Z10: =G9+H9+I9 -> 0
A11: Investuota viso | B11: 104.1 | K11: =IF(J11>0,J11-D11,"") | Y11: =J10 -> 0 | Z11: =G10+H10+I10 -> 0
A12: Paskolos pabaiga | B12: 46398 | K12: =IF(J12>0,J12-D12,"") | Y12: =J11 -> 0 | Z12: =G11+H11+I11 -> 0
A13: Liko dienų | B13: =IF(B11<>N3,(TODAY()-B12)*-1,"") -> 103 | K13: =IF(J13>0,J13-D13,"") | Y13: =J12 -> 0 | Z13: =G12+H12+I12 -> 0
A14: Grąžinta | K14: =IF(J14>0,J14-D14,"") | Y14: =J13 -> 0 | Z14: =G13+H13+I13 -> 0
A15: Vėlavo/Anksčiau | B15: =IF(M3=N3,B14-B12,"") | K15: =IF(J15>0,J15-D15,"") | Y15: =J14 -> 0 | Z15: =G14+H14+I14 -> 0
K16: =IF(J16>0,J16-D16,"") | Y16: =J15 -> 0 | Z16: =G15+H15+I15 -> 0
K17: =IF(J17>0,J17-D17,"") | Y17: =J16 -> 0 | Z17: =G16+H16+I16 -> 0
K18: =IF(J18>0,J18-D18,"") | Y18: =J17 -> 0 | Z18: =G17+H17+I17 -> 0
K19: =IF(J19>0,J19-D19,"") | Y19: =J18 -> 0 | Z19: =G18+H18+I18 -> 0
K20: =IF(J20>0,J20-D20,"") | Y20: =J19 -> 0 | Z20: =G19+H19+I19 -> 0
K21: =IF(J21>0,J21-D21,"") | Y21: =J20 -> 0 | Z21: =G20+H20+I20 -> 0
K22: =IF(J22>0,J22-D22,"") | Y22: =J21 -> 0 | Z22: =G21+H21+I21 -> 0
K23: =IF(J23>0,J23-D23,"") | Y23: =J22 -> 0 | Z23: =G22+H22+I22 -> 0
K24: =IF(J24>0,J24-D24,"") | Y24: =J23 -> 0 | Z24: =G23+H23+I23 -> 0
K25: =IF(J25>0,J25-D25,"") | Y25: =J24 -> 0 | Z25: =G24+H24+I24 -> 0
K26: =IF(J26>0,J26-D26,"") | Y26: =J25 -> 0 | Z26: =G25+H25+I25 -> 0
K27: =IF(J27>0,J27-D27,"") | Y27: =J26 -> 0 | Z27: =G26+H26+I26 -> 0
... K41: =IF(J41>0,J41-D41,"") | Y41: =J40 -> 0 | Z41: =G40+H40+I40 -> 0
D42: Viso: | E42: =SUM(E2:E41) -> 104.1 | F42: =SUM(F2:F41) -> 8.28 | G42: =SUM(G2:G41) -> 0 | H42: =SUM(H2:H41) -> 4.54 | I42: =SUM(I2:I41) -> 0

Sheet Dvibutis Didžiojoje Riešėje
A1: Paskola | B1: Paskola P00001508 | D1: Data | E1: Paskola | F1: Palūkanos | G1: Paskola | H1: Palūkanos | I1: Papildomos | J1: Data | K1: Vėlavimas | M1: Paskola | O1: Palūkanos | Q1: XIRR | R1: Grąžinta | S1: Vėluoja | Y1: Data | Z1: Suma | AA1: Vėluoja
A2: Objektas | B2: Dvibutis Didžiojoje Riešėje | D2: 46112 | E2: 0 | F2: 3.1 | G2: 0 | H2: 3.1 | I2: 0 | J2: 46112 | K2: =IF(J2>0,J2-D2,"") -> 0 | M2: Suteikta | N2: Grąžinta | O2: Planuotos | P2: Realios | Y2: =B3 -> 46003 | Z2: =B11*-1 -> -116.3 | AA2: =IF(COUNTIFS(D:D,"<"&TODAY(),J:J,"")>0,"+","")
A3: Investicijos data | B3: 46003 | D3: 46203 | E3: 0 | F3: 2.61 | G3: 0 | H3: 2.61 | I3: 0 | J3: 46203 | K3: =IF(J3>0,J3-D3,"") -> 0 | M3: =B11 -> 116.3 | N3: =G42 -> 116.3 | O3: =F42 -> 10.41 | P3: =H42+I42 -> 7.55 | Q3: =IF(M3=N3,XIRR(Z2:Z41,Y2:Y41),"") -> 0.091050735 | R3: =IF(M3=N3,B14,"") -> 46272 | S3: =IF(COUNTIFS(D:D,"<"&TODAY(),J:J,"")=0,"",TODAY()-_xlfn.MINIFS(D:D,D:D,"<"&TODAY(),J:J,"")) | Y3: =J2 -> 46112 | Z3: =G2+H2+I2 -> 3.1
A4: Palūkanų pradžia | B4: 46003 | D4: 46295 | E4: 0 | F4: 2.64 | G4: 0 | H4: 0 | I4: 0 | J4: 46272 | K4: =IF(J4>0,J4-D4,"") -> -23 | Y4: =J3 -> 46203 | Z4: =G3+H3+I3 -> 2.61
A5: Projekto reitingas | B5: A | D5: 46367 | E5: 116.3 | F5: 2.06 | G5: 116.3 | H5: 1.84 | I5: 0 | J5: 46272 | K5: =IF(J5>0,J5-D5,"") -> -95 | Y5: =J4 -> 46272 | Z5: =G4+H4+I4 -> 0
A6: LTV, % | B6: 0.72 | K6: =IF(J6>0,J6-D6,"") | Y6: =J5 -> 46272 | Z6: =G5+H5+I5 -> 118.14
A7: LTV max, % | B7: 0.85 | K7: =IF(J7>0,J7-D7,"") | Y7: =J6 -> 0 | Z7: =G6+H6+I6 -> 0
A8: Investicijos laikotarpis, mėn. | B8: 12 | K8: =IF(J8>0,J8-D8,"") | Y8: =J7 -> 0 | Z8: =G7+H7+I7 -> 0
A9: Palūkanų mokėjimas | B9: Q | K9: =IF(J9>0,J9-D9,"") | Y9: =J8 -> 0 | Z9: =G8+H8+I8 -> 0
A10: Palūkanos, % | B10: 0.09 | K10: =IF(J10>0,J10-D10,"") | Y10: =J9 -> 0 | Z10: =G9+H9+I9 -> 0
A11: Investuota, Eur | B11: 116.3 | K11: =IF(J11>0,J11-D11,"") | Y11: =J10 -> 0 | Z11: =G10+H10+I10 -> 0
A12: Paskolos pabaiga | B12: 46367 | K12: =IF(J12>0,J12-D12,"") | Y12: =J11 -> 0 | Z12: =G11+H11+I11 -> 0
A13: Liko dienų | B13: =IF(B11<>N3,(TODAY()-B12)*-1,"") | K13: =IF(J13>0,J13-D13,"") | Y13: =J12 -> 0 | Z13: =G12+H12+I12 -> 0
A14: Grąžinta | B14: 46272 | K14: =IF(J14>0,J14-D14,"") | Y14: =J13 -> 0 | Z14: =G13+H13+I13 -> 0
A15: Vėlavo/Anksčiau | B15: =IF(M3=N3,B14-B12,"") -> -95 | K15: =IF(J15>0,J15-D15,"") | Y15: =J14 -> 0 | Z15: =G14+H14+I14 -> 0
K16: =IF(J16>0,J16-D16,"") | Y16: =J15 -> 0 | Z16: =G15+H15+I15 -> 0
K17: =IF(J17>0,J17-D17,"") | Y17: =J16 -> 0 | Z17: =G16+H16+I16 -> 0
K18: =IF(J18>0,J18-D18,"") | Y18: =J17 -> 0 | Z18: =G17+H17+I17 -> 0
K19: =IF(J19>0,J19-D19,"") | Y19: =J18 -> 0 | Z19: =G18+H18+I18 -> 0
K20: =IF(J20>0,J20-D20,"") | Y20: =J19 -> 0 | Z20: =G19+H19+I19 -> 0
K21: =IF(J21>0,J21-D21,"") | Y21: =J20 -> 0 | Z21: =G20+H20+I20 -> 0
K22: =IF(J22>0,J22-D22,"") | Y22: =J21 -> 0 | Z22: =G21+H21+I21 -> 0
K23: =IF(J23>0,J23-D23,"") | Y23: =J22 -> 0 | Z23: =G22+H22+I22 -> 0
K24: =IF(J24>0,J24-D24,"") | Y24: =J23 -> 0 | Z24: =G23+H23+I23 -> 0
K25: =IF(J25>0,J25-D25,"") | Y25: =J24 -> 0 | Z25: =G24+H24+I24 -> 0
K26: =IF(J26>0,J26-D26,"") | Y26: =J25 -> 0 | Z26: =G25+H25+I25 -> 0
K27: =IF(J27>0,J27-D27,"") | Y27: =J26 -> 0 | Z27: =G26+H26+I26 -> 0
... K41: =IF(J41>0,J41-D41,"") | Y41: =J40 -> 0 | Z41: =G40+H40+I40 -> 0
D42: Viso: | E42: =SUM(E2:E41) -> 116.3 | F42: =SUM(F2:F41) -> 10.41 | G42: =SUM(G2:G41) -> 116.3 | H42: =SUM(H2:H41) -> 7.55 | I42: =SUM(I2:I41) -> 0

Sheet Piekrasta Rezidence, Ryga XII
A1: Paskola | B1: Paskola P00001341-12 | D1: Data | E1: Paskola | F1: Palūkanos | G1: Paskola | H1: Palūkanos | I1: Papildomos | J1: Data | K1: Vėlavimas | M1: Paskola | O1: Palūkanos | Q1: XIRR | R1: Grąžinta | S1: Vėluoja | Y1: Data | Z1: Suma | AA1: Vėluoja
A2: Objektas | B2: Piekrasta Rezidence, Ryga XII | D2: 46022 | E2: 0 | F2: 2.25 | G2: 0 | H2: 2.25 | I2: 0 | J2: 46028 | K2: =IF(J2>0,J2-D2,"") -> 6 | M2: Suteikta | N2: Grąžinta | O2: Planuotos | P2: Realios | Y2: =B3 -> 45926 | Z2: =B11*-1 -> -101.9 | AA2: =IF(COUNTIFS(D:D,"<"&TODAY(),J:J,"")>0,"+","")
A3: Investicijos data | B3: 45926 | D3: 46112 | E3: 0 | F3: 2.14 | G3: 0 | H3: 2.14 | I3: 0 | J3: 46115 | K3: =IF(J3>0,J3-D3,"") -> 3 | M3: =B11 -> 101.9 | N3: =G42 -> 101.9 | O3: =F42 -> 8.61 | P3: =H42+I42 -> 8.61 | Q3: =IF(M3=N3,XIRR(Z2:Z41,Y2:Y41),"") -> 0.086675951 | R3: =IF(M3=N3,B14,"") -> 46293 | S3: =IF(COUNTIFS(D:D,"<"&TODAY(),J:J,"")=0,"",TODAY()-_xlfn.MINIFS(D:D,D:D,"<"&TODAY(),J:J,"")) | Y3: =J2 -> 46028 | Z3: =G2+H2+I2 -> 2.25
A4: Palūkanų pradžia | B4: 45926 | D4: 46203 | E4: 0 | F4: 2.16 | G4: 0 | H4: 2.16 | I4: 0 | J4: 46204 | K4: =IF(J4>0,J4-D4,"") -> 1 | Y4: =J3 -> 46115 | Z4: =G3+H3+I3 -> 2.14
A5: Projekto reitingas | B5: AA- | D5: 46290 | E5: 101.9 | F5: 2.06 | G5: 101.9 | H5: 2.06 | I5: 0 | J5: 46293 | K5: =IF(J5>0,J5-D5,"") -> 3 | Y5: =J4 -> 46204 | Z5: =G4+H4+I4 -> 2.16
A6: LTV, % | B6: 0.6 | K6: =IF(J6>0,J6-D6,"") | Y6: =J5 -> 46293 | Z6: =G5+H5+I5 -> 103.96
A7: LTV max, % | B7: 0.6 | K7: =IF(J7>0,J7-D7,"") | Y7: =J6 -> 0 | Z7: =G6+H6+I6 -> 0
A8: Investicijos laikotarpis, mėn. | B8: 12 | K8: =IF(J8>0,J8-D8,"") | Y8: =J7 -> 0 | Z8: =G7+H7+I7 -> 0
A9: Palūkanų mokėjimas | B9: Q | K9: =IF(J9>0,J9-D9,"") | Y9: =J8 -> 0 | Z9: =G8+H8+I8 -> 0
A10: Palūkanos, % | B10: 0.085 | K10: =IF(J10>0,J10-D10,"") | Y10: =J9 -> 0 | Z10: =G9+H9+I9 -> 0
A11: Investuota, Eur | B11: 101.9 | K11: =IF(J11>0,J11-D11,"") | Y11: =J10 -> 0 | Z11: =G10+H10+I10 -> 0
A12: Paskolos pabaiga | B12: 46290 | K12: =IF(J12>0,J12-D12,"") | Y12: =J11 -> 0 | Z12: =G11+H11+I11 -> 0
A13: Liko dienų | B13: =IF(B11<>N3,(TODAY()-B12)*-1,"") | K13: =IF(J13>0,J13-D13,"") | Y13: =J12 -> 0 | Z13: =G12+H12+I12 -> 0
A14: Grąžinta | B14: 46293 | K14: =IF(J14>0,J14-D14,"") | Y14: =J13 -> 0 | Z14: =G13+H13+I13 -> 0
A15: Vėlavo/Anksčiau | B15: =IF(M3=N3,B14-B12,"") -> 3 | K15: =IF(J15>0,J15-D15,"") | Y15: =J14 -> 0 | Z15: =G14+H14+I14 -> 0
K16: =IF(J16>0,J16-D16,"") | Y16: =J15 -> 0 | Z16: =G15+H15+I15 -> 0
K17: =IF(J17>0,J17-D17,"") | Y17: =J16 -> 0 | Z17: =G16+H16+I16 -> 0
K18: =IF(J18>0,J18-D18,"") | Y18: =J17 -> 0 | Z18: =G17+H17+I17 -> 0
K19: =IF(J19>0,J19-D19,"") | Y19: =J18 -> 0 | Z19: =G18+H18+I18 -> 0
K20: =IF(J20>0,J20-D20,"") | Y20: =J19 -> 0 | Z20: =G19+H19+I19 -> 0
K21: =IF(J21>0,J21-D21,"") | Y21: =J20 -> 0 | Z21: =G20+H20+I20 -> 0
K22: =IF(J22>0,J22-D22,"") | Y22: =J21 -> 0 | Z22: =G21+H21+I21 -> 0
K23: =IF(J23>0,J23-D23,"") | Y23: =J22 -> 0 | Z23: =G22+H22+I22 -> 0
K24: =IF(J24>0,J24-D24,"") | Y24: =J23 -> 0 | Z24: =G23+H23+I23 -> 0
K25: =IF(J25>0,J25-D25,"") | Y25: =J24 -> 0 | Z25: =G24+H24+I24 -> 0
K26: =IF(J26>0,J26-D26,"") | Y26: =J25 -> 0 | Z26: =G25+H25+I25 -> 0
K27: =IF(J27>0,J27-D27,"") | Y27: =J26 -> 0 | Z27: =G26+H26+I26 -> 0
... K41: =IF(J41>0,J41-D41,"") | Y41: =J40 -> 0 | Z41: =G40+H40+I40 -> 0
D42: Viso: | E42: =SUM(E2:E41) -> 101.9 | F42: =SUM(F2:F41) -> 8.61 | G42: =SUM(G2:G41) -> 101.9 | H42: =SUM(H2:H41) -> 8.61 | I42: =SUM(I2:I41) -> 0

Sheet Dvibutis Upelio g., Vilniaus r.
A1: Paskola | B1: P00001434 | D1: Data | E1: Paskola | F1: Palūkanos | G1: Paskola | H1: Palūkanos | I1: Papildomos | J1: Data | K1: Vėlavimas | M1: Paskola | O1: Palūkanos | Q1: XIRR | R1: Grąžinta | S1: Vėluoja | Y1: Data | Z1: Suma | AA1: Vėluoja
A2: Objektas | B2: Dvibutis Upelio g., Vilniaus r. | D2: 46022 | E2: 0 | F2: 3.07 | G2: 0 | H2: 3.07 | I2: 0 | J2: 46024 | K2: =IF(J2>0,J2-D2,"") -> 2 | M2: Suteikta | N2: Grąžinta | O2: Planuotos | P2: Realios | Y2: =B3 -> 45908 | Z2: =B11*-1 -> -116.6 | AA2: =IF(COUNTIFS(D:D,"<"&TODAY(),J:J,"")>0,"+","")
A3: Investicijos data | B3: 45908 | D3: 46112 | E3: 0 | F3: 2.44 | G3: 0 | H3: 2.44 | I3: 0.12 | J3: 46120 | K3: =IF(J3>0,J3-D3,"") -> 8 | M3: =B11 -> 116.6 | N3: =G42 -> 116.6 | O3: =F42 -> 9.85 | P3: =H42+I42 -> 10.28 | Q3: =IF(M3=N3,XIRR(Z2:Z41,Y2:Y41),"") -> 0.089228001 | R3: =IF(M3=N3,B14,"") -> 46280 | S3: =IF(COUNTIFS(D:D,"<"&TODAY(),J:J,"")=0,"",TODAY()-_xlfn.MINIFS(D:D,D:D,"<"&TODAY(),J:J,"")) | Y3: =J2 -> 46024 | Z3: =G2+H2+I2 -> 3.07
A4: Palūkanų pradžia | B4: 45909 | D4: 46203 | E4: 0 | F4: 2.47 | G4: 0 | H4: 2.47 | I4: 0 | J4: 46203 | K4: =IF(J4>0,J4-D4,"") -> 0 | Y4: =J3 -> 46120 | Z4: =G3+H3+I3 -> 2.56
A5: Projekto reitingas | B5: A+ | D5: 46272 | E5: 116.6 | F5: 1.87 | G5: 116.6 | H5: 1.87 | I5: 0.31 | J5: 46280 | K5: =IF(J5>0,J5-D5,"") -> 8 | Y5: =J4 -> 46203 | Z5: =G4+H4+I4 -> 2.47
A6: LTV, % | B6: 0.66 | K6: =IF(J6>0,J6-D6,"") | Y6: =J5 -> 46280 | Z6: =G5+H5+I5 -> 118.78
