Workbook

Sheet Apžvalga
A1: Data | B1: Viso: | F1: Mėnesio gale | V1: Dividendai | W1: Mokesčiai | AB1: XIRR | AC1: XIRR | AD1: XIRR | AS1: XIRR
B2: Inešta | C2: Išvesta | D2: Investuota | E2: Gryni | F2: NADQ | G2: QDVE | H2: VWCE | I2: XDEQ | J2: VUAA | K2: XDWT | L2: XAIX | M2: SPYL | N2: JEQP | O2: JGPI | P2: EXUS | Q2: IS3N | R2: VGLA | S2: Vertė | T2: Pelnas | U2: % | W2: Pirkimas | X2: Pardavimas | AB2: Aktyvūs | AC2: Parduoti | AD2: Viso | AS2: =XIRR(_xlfn.VSTACK(SPYL!AG5:AG200,EXUS!AG5:AG200,IS3N!AG5:AG200,VGLA!AG5:AG200,NADQ!AG5:AG200,QDVE!AG5:AG200,VWCE!AG5:AG200,XDEQ!AG5:AG200,VUAA!AG5:AG200,XDWT!AG5:AG200,XAIX!AG5:AG200,JEQP!AG5:AG200,JGPI!AG5:AG200),_xlfn.VSTACK(SPYL!AF5:AF200,EXUS!AF5:AF200,IS3N!AF5:AF200,VGLA!AF5:AF200,NADQ!AF5:AF200,QDVE!AF5:AF200,VWCE!AF5:AF200,XDEQ!AF5:AF200,VUAA!AF5:AF200,XDWT!AF5:AF200,XAIX!AF5:AF200,JEQP!AF5:AF200,JGPI!AF5:AF200)) -> 0.18461092
A3: ='2024.12'!Q2 -> 2024.12 | B3: ='2024.12'!Q5 -> 10 | C3: ='2024.12'!R5 -> 0 | D3: ='2024.12'!S5 -> 10 | E3: ='2024.12'!X5 -> 0 | F3: =NADQ!H5 -> 9.9700311 | G3: 0 | H3: 0 | I3: 0 | J3: 0 | K3: 0 | L3: 0 | M3: 0 | N3: 0 | O3: 0 | P3: 0 | Q3: 0 | R3: 0 | S3: =SUM(F3:O3)+E3 -> 9.9700311 | T3: =S3-B3 -> -0.029968912 | U3: =T3/B3 -> -0.0029968912 | V3: ='2024.12'!W5 -> 0 | W3: ='2024.12'!U5 -> 0 | X3: ='2024.12'!V5 -> 0 | AB3: =XIRR(_xlfn.VSTACK(SPYL!AG5:AG200,EXUS!AG5:AG200,IS3N!AG5:AG200,VGLA!AG5:AG200),_xlfn.VSTACK(SPYL!AF5:AF200,EXUS!AF5:AF200,IS3N!AF5:AF200,VGLA!AF5:AF200)) -> 0.17977149 | AC3: =XIRR(_xlfn.VSTACK(NADQ!AG5:AG200,QDVE!AG5:AG200,VWCE!AG5:AG200,XDEQ!AG5:AG200,VUAA!AG5:AG200,XDWT!AG5:AG200,XAIX!AG5:AG200,JEQP!AG5:AG200,JGPI!AG5:AG200),_xlfn.VSTACK(NADQ!AF5:AF200,QDVE!AF5:AF200,VWCE!AF5:AF200,XDEQ!AF5:AF200,VUAA!AF5:AF200,XDWT!AF5:AF200,XAIX!AF5:AF200,JEQP!AF5:AF200,JGPI!AF5:AF200)) -> 0.20060512 | AD3: =XIRR(_xlfn.VSTACK(SPYL!AG5:AG200,EXUS!AG5:AG200,IS3N!AG5:AG200,VGLA!AG5:AG200,NADQ!AG5:AG200,QDVE!AG5:AG200,VWCE!AG5:AG200,XDEQ!AG5:AG200,VUAA!AG5:AG200,XDWT!AG5:AG200,XAIX!AG5:AG200,JEQP!AG5:AG200,JGPI!AG5:AG200),_xlfn.VSTACK(SPYL!AF5:AF200,EXUS!AF5:AF200,IS3N!AF5:AF200,VGLA!AF5:AF200,NADQ!AF5:AF200,QDVE!AF5:AF200,VWCE!AF5:AF200,XDEQ!AF5:AF200,VUAA!AF5:AF200,XDWT!AF5:AF200,XAIX!AF5:AF200,JEQP!AF5:AF200,JGPI!AF5:AF200)) -> 0.18461092
A4: ='2025.01'!Q2 -> 2025.01 | B4: =B3+'2025.01'!Q5 -> 10 | C4: ='2025.01'!R5 -> 0 | D4: =D3+'2025.01'!S5 -> 10 | E4: =E3+'2025.01'!X5 -> 0 | F4: =NADQ!H6 -> 10.089902 | G4: 0 | H4: 0 | I4: 0 | J4: 0 | K4: 0 | L4: 0 | M4: 0 | N4: 0 | O4: 0 | P4: 0 | Q4: 0 | R4: 0 | S4: =SUM(F4:O4)+E4 -> 10.089902 | T4: =S4-B4 -> 0.089901982 | U4: =T4/B4 -> 0.0089901982 | V4: ='2025.01'!W5 -> 0 | W4: ='2025.01'!U5 -> 0 | X4: ='2025.01'!V5 -> 0
A5: ='2025.02'!Q2 -> 2025.02 | B5: =B4+'2025.02'!Q5 -> 10 | C5: ='2025.02'!R5 -> 0 | D5: =D4+'2025.02'!S5 -> 10 | E5: =E4+'2025.02'!X5 -> 0 | F5: =NADQ!H7 -> 9.6800357 | G5: 0 | H5: 0 | I5: 0 | J5: 0 | K5: 0 | L5: 0 | M5: 0 | N5: 0 | O5: 0 | P5: 0 | Q5: 0 | R5: 0 | S5: =SUM(F5:O5)+E5 -> 9.6800357 | T5: =S5-B5 -> -0.31996427 | U5: =T5/B5 -> -0.031996427 | V5: ='2025.02'!W5 -> 0 | W5: ='2025.02'!U5 -> 0 | X5: ='2025.02'!V5 -> 0
A6: ='2025.03'!Q2 -> 2025.03 | B6: =B5+'2025.03'!Q5 -> 10 | C6: ='2025.03'!R5 -> 0 | D6: =D5+'2025.03'!S5 -> 10 | E6: =E5+'2025.03'!X5 -> 0 | F6: =NADQ!H8 -> 8.6698929 | G6: 0 | H6: 0 | I6: 0 | J6: 0 | K6: 0 | L6: 0 | M6: 0 | N6: 0 | O6: 0 | P6: 0 | Q6: 0 | R6: 0 | S6: =SUM(F6:O6)+E6 -> 8.6698929 | T6: =S6-B6 -> -1.3301071 | U6: =T6/B6 -> -0.13301071 | V6: ='2025.03'!W5 -> 0 | W6: ='2025.03'!U5 -> 0 | X6: ='2025.03'!V5 -> 0
A7: ='2025.04'!Q2 -> 2025.04 | B7: =B6+'2025.04'!Q5 -> 20 | C7: ='2025.04'!R5 -> 0 | D7: =D6+'2025.04'!S5 -> 20 | E7: =E6+'2025.04'!X5 -> 0 | F7: =NADQ!H9 -> 8.4301511 | G7: =QDVE!H5 -> 11.391489 | H7: 0 | I7: 0 | J7: 0 | K7: 0 | L7: 0 | M7: 0 | N7: 0 | O7: 0 | P7: 0 | Q7: 0 | R7: 0 | S7: =SUM(F7:O7)+E7 -> 19.82164 | T7: =S7-B7 -> -0.1783599 | U7: =T7/B7 -> -0.0089179948 | V7: ='2025.04'!W5 -> 0 | W7: ='2025.04'!U5 -> 0 | X7: ='2025.04'!V5 -> 0
A8: ='2025.05'!Q2 -> 2025.05 | B8: =B7+'2025.05'!Q5 -> 40.07 | C8: ='2025.05'!R5 -> 0 | D8: =D7+'2025.05'!S5 -> 40.06 | E8: =E7+'2025.05'!X5 -> -1.9897278e-15 | F8: =NADQ!H10 -> 9.1401557 | G8: =QDVE!H6 -> 32.931464 | H8: 0 | I8: 0 | J8: 0 | K8: 0 | L8: 0 | M8: 0 | N8: 0 | O8: 0 | P8: 0 | Q8: 0 | R8: 0 | S8: =SUM(F8:O8)+E8 -> 42.071619 | T8: =S8-B8 -> 2.0016195 | U8: =T8/B8 -> 0.049953069 | V8: ='2025.05'!W5 -> 0 | W8: ='2025.05'!U5 -> 0.01 | X8: ='2025.05'!V5 -> 0
A9: ='2025.06'!Q2 -> 2025.06 | B9: =B8+'2025.06'!Q5 -> 50.07 | C9: ='2025.06'!R5 -> 0 | D9: =D8+'2025.06'!S5 -> 50.06 | E9: =E8+'2025.06'!X5 -> -1.9897278e-15 | F9: =NADQ!H11 -> 9.3702156 | G9: =QDVE!H7 -> 34.845429 | H9: =VWCE!H5 -> 10.010033 | I9: 0 | J9: 0 | K9: 0 | L9: 0 | M9: 0 | N9: 0 | O9: 0 | P9: 0 | Q9: 0 | R9: 0 | S9: =SUM(F9:O9)+E9 -> 54.225678 | T9: =S9-B9 -> 4.1556779 | U9: =T9/B9 -> 0.082997363 | V9: ='2025.06'!W5 -> 0 | W9: ='2025.06'!U5 -> 0 | X9: ='2025.06'!V5 -> 0
A10: ='2025.07'!Q2 -> 2025.07 | B10: =B9+'2025.07'!Q5 -> 100.07 | C10: ='2025.07'!R5 -> 0 | D10: =D9+'2025.07'!S5 -> 100.02 | E10: =E9+'2025.07'!X5 -> -2.8432118e-15 | F10: =NADQ!H12 -> 20.610275 | G10: =QDVE!H8 -> 48.716605 | H10: =VWCE!H6 -> 20.879924 | I10: =XDEQ!H5 -> 10.030745 | J10: =VUAA!H5 -> 10.119836 | K10: 0 | L10: 0 | M10: 0 | N10: 0 | O10: 0 | P10: 0 | Q10: 0 | R10: 0 | S10: =SUM(F10:O10)+E10 -> 110.35739 | T10: =S10-B10 -> 10.287386 | U10: =T10/B10 -> 0.1028019 | V10: ='2025.07'!W5 -> 0 | W10: ='2025.07'!U5 -> 0.04 | X10: ='2025.07'!V5 -> 0
A11: ='2025.08'!Q2 -> 2025.08 | B11: =B10+'2025.08'!Q5 -> 150.07 | C11: ='2025.08'!R5 -> 0 | D11: =D10+'2025.08'!S5 -> 149.98 | E11: =E10+'2025.08'!X5 -> -1.0802123e-14 | F11: =NADQ!H13 -> 20.239842 | G11: =QDVE!H9 -> 57.628722 | H11: =VWCE!H7 -> 20.920024 | I11: =XDEQ!H6 -> 10.039969 | J11: =VUAA!H6 -> 10.059916 | K11: =XDWT!H5 -> 19.900567 | L11: =XAIX!H5 -> 19.960142 | M11: 0 | N11: 0 | O11: 0 | P11: 0 | Q11: 0 | R11: 0 | S11: =SUM(F11:O11)+E11 -> 158.74918 | T11: =S11-B11 -> 8.6791825 | U11: =T11/B11 -> 0.057834227 | V11: ='2025.08'!W5 -> 0 | W11: ='2025.08'!U5 -> 0.04 | X11: ='2025.08'!V5 -> 0
A12: ='2025.09'!Q2 -> 2025.09 | B12: =B11+'2025.09'!Q5 -> 180.07 | C12: ='2025.09'!R5 -> 0 | D12: =D11+'2025.09'!S5 -> 179.96 | E12: =E11+'2025.09'!X5 -> -1.4781579e-14 | F12: =NADQ!H14 -> 21.24968 | G12: =QDVE!H10 -> 72.294238 | H12: =VWCE!H8 -> 21.589391 | I12: =XDEQ!H7 -> 20.498725 | J12: =VUAA!H7 -> 20.609137 | K12: =XDWT!H6 -> 21.190618 | L12: =XAIX!H6 -> 21.280046 | M12: 0 | N12: 0 | O12: 0 | P12: 0 | Q12: 0 | R12: 0 | S12: =SUM(F12:O12)+E12 -> 198.71184 | T12: =S12-B12 -> 18.641835 | U12: =T12/B12 -> 0.10352549 | V12: ='2025.09'!W5 -> 0 | W12: ='2025.09'!U5 -> 0.02 | X12: ='2025.09'!V5 -> 0
A13: ='2025.10'!Q2 -> 2025.10 | B13: =B12+'2025.10'!Q5 -> 230.07 | C13: ='2025.10'!R5 -> 0 | D13: =D12+'2025.10'!S5 -> 229.92 | E13: =E12+'2025.10'!X5 -> -1.521179e-14 | F13: =NADQ!H15 -> 22.670154 | G13: =QDVE!H11 -> 89.090093 | H13: =VWCE!H9 -> 32.709699 | I13: =XDEQ!H8 -> 21.068474 | J13: =VUAA!H8 -> 21.519504 | K13: =XDWT!H7 -> 33.790251 | L13: =XAIX!H7 -> 33.710689 | M13: =SPYL!H5 -> 10.34085 | N13: 0 | O13: 0 | P13: 0 | Q13: 0 | R13: 0 | S13: =SUM(F13:O13)+E13 -> 264.89971 | T13: =S13-B13 -> 34.829715 | U13: =T13/B13 -> 0.15138747 | V13: ='2025.10'!W5 -> 0 | W13: ='2025.10'!U5 -> 0.04 | X13: ='2025.10'!V5 -> 0
A14: ='2025.11'!Q2 -> 2025.11 | B14: =B13+'2025.11'!Q5 -> 336.46 | C14: ='2025.11'!R5 -> 0 | D14: =D13+'2025.11'!S5-'2025.11'!T5-'2025.11'!U5-'2025.11'!V5 -> 327.01 | E14: =E13+'2025.11'!X5 -> 7.8 | F14: 0 | G14: 0 | H14: 0 | I14: 0 | J14: 0 | K14: 0 | L14: 0 | M14: =SPYL!H6 -> 172.85058 | N14: =JEQP!H5 -> 91.2 | O14: =JGPI!H5 -> 92.96 | P14: 0 | Q14: 0 | R14: 0 | S14: =SUM(F14:O14)+E14 -> 364.81058 | T14: =S14-B14 -> 28.350584 | U14: =T14/B14 -> 0.084261381 | V14: ='2025.11'!W5 -> 0 | W14: ='2025.11'!U5 -> 0.43 | X14: ='2025.11'!V5 -> 0.32
A15: ='2025.12'!Q2 -> 2025.12 | B15: =B14+'2025.12'!Q5 -> 499.54 | C15: ='2025.12'!R5 -> 0 | D15: =D14+'2025.12'!S5-'2025.12'!T5-'2025.12'!U5-'2025.12'!V5 -> 388.3 | E15: =E14+'2025.12'!X5 -> 110.6 | F15: 0 | G15: 0 | H15: 0 | I15: 0 | J15: 0 | K15: 0 | L15: 0 | M15: =SPYL!H7 -> 187.72 | N15: =JEQP!H6 -> 113.45 | O15: =JGPI!H6 -> 114.75 | P15: 0 | Q15: 0 | R15: 0 | S15: =SUM(F15:O15)+E15 -> 526.52 | T15: =S15-B15 -> 26.98 | U15: =T15/B15 -> 0.054009689 | V15: ='2025.12'!W5 -> 1.13 | W15: ='2025.12'!U5 -> 0.06 | X15: ='2025.12'!V5 -> 0
A16: ='2026.01'!Q2 -> 2026.01 | B16: =B15+'2026.01'!Q5 -> 499.54 | C16: ='2026.01'!R5 -> 0 | D16: =D15+'2026.01'!S5-'2026.01'!T5-'2026.01'!V5 -> 477.76 | E16: =E15+'2026.01'!X5 -> 22.65 | F16: 0 | G16: 0 | H16: 0 | I16: 0 | J16: 0 | K16: 0 | L16: 0 | M16: =SPYL!H8 -> 230.4 | N16: =JEQP!H7 -> 135.72 | O16: =JGPI!H7 -> 136.92 | P16: 0 | Q16: 0 | R16: 0 | S16: =SUM(F16:O16)+E16 -> 525.69 | T16: =S16-B16 -> 26.15 | U16: =T16/B16 -> 0.05234816 | V16: ='2026.01'!W5 -> 1.57 | W16: ='2026.01'!U5 -> 0.06 | X16: ='2026.01'!V5 -> 0
A17: ='2026.02'!Q2 -> 2026.02 | B17: =B16+'2026.02'!Q5 -> 619.54 | C17: ='2026.02'!R5 -> 0 | D17: =D16+'2026.02'!S5-'2026.02'!T5-'2026.02'!U5-'2026.02'!V5 -> 580.11 | E17: =E16+'2026.02'!X5 -> 42.34 | F17: 0 | G17: 0 | H17: 0 | I17: 0 | J17: 0 | K17: 0 | L17: 0 | M17: =SPYL!H9 -> 286.6 | N17: =JEQP!H8 -> 154.28 | O17: =JGPI!H8 -> 167.23 | P17: 0 | Q17: 0 | R17: 0 | S17: =SUM(F17:O17)+E17 -> 650.45 | T17: =S17-B17 -> 30.91 | U17: =T17/B17 -> 0.049891855 | V17: ='2026.02'!W5 -> 2.2 | W17: ='2026.02'!U5 -> 0.08 | X17: ='2026.02'!V5 -> 0
A18: ='2026.03'!Q2 -> 2026.03 | B18: =B17+'2026.03'!Q5 -> 749.54 | C18: ='2026.03'!R5 -> 0 | D18: =D17+'2026.03'!S5-'2026.03'!T5-'2026.03'!U5-'2026.03'!V5 -> 697.11 | E18: 56.88 | F18: 0 | G18: 0 | H18: 0 | I18: 0 | J18: 0 | K18: 0 | L18: 0 | M18: =SPYL!H10 -> 348.25 | N18: =JEQP!H9 -> 173.44 | O18: =JGPI!H9 -> 185.76 | P18: 0 | Q18: 0 | R18: 0 | S18: =SUM(F18:O18)+E18 -> 764.33 | T18: =S18-B18 -> 14.79 | U18: =T18/B18 -> 0.019732102 | V18: ='2026.03'!W5 -> 2.31 | W18: ='2026.03'!U5 -> 0.04 | X18: ='2026.03'!V5 -> 0
A19: ='2026.04'!Q2 -> 2026.04 | B19: =B18+'2026.04'!Q5 -> 829.54 | C19: ='2026.04'!R5 -> 0 | D19: =D18+'2026.04'!S5-'2026.04'!T5-'2026.04'!U5-'2026.04'!V5 -> 826.79 | E19: =E18+'2026.04'!X5 -> 9.28 | F19: 0 | G19: 0 | H19: 0 | I19: 0 | J19: 0 | K19: 0 | L19: 0 | M19: =SPYL!H11 -> 469.96 | N19: =JEQP!H10 -> 205.92 | O19: =JGPI!H10 -> 200.7 | P19: 0 | Q19: 0 | R19: 0 | S19: =SUM(F19:O19)+E19 -> 885.86 | T19: =S19-B19 -> 56.32 | U19: =T19/B19 -> 0.067893049 | V19: ='2026.04'!W5 -> 2.16 | W19: ='2026.04'!U5 -> 0.04 | X19: ='2026.04'!V5 -> 0
A20: ='2026.05'!$Q$2 -> 2026.05 | B20: =B19+'2026.05'!$Q$5 -> 949.54 | C20: ='2026.05'!$R$5 -> 0 | D20: =D19+'2026.05'!$S$5-'2026.05'!$T$5-W20-X20 -> 940.43 | E20: =E19+'2026.05'!$X$5 -> 18.22 | F20: 0 | G20: 0 | H20: 0 | I20: 0 | J20: 0 | K20: 0 | L20: 0 | M20: =SPYL!H12 -> 577.728 | N20: 0 | O20: 0 | P20: =EXUS!H5 -> 231.174 | Q20: =IS3N!H5 -> 239.65 | R20: 0 | S20: =SUM(F20:R20)+E20 -> 1066.772 | T20: =S20-B20 -> 117.232 | U20: =T20/B20 -> 0.12346189 | V20: ='2026.05'!$W$5 -> 3.1 | W20: ='2026.05'!$U$5 -> 0.04 | X20: ='2026.05'!$V$5 -> 0.22
A21: ='2026.06'!$Q$2 -> 2026.06 | B21: =B20+'2026.06'!$Q$5 -> 1530 | C21: ='2026.06'!$R$5 -> 0 | D21: =D20+'2026.06'!$S$5-'2026.06'!$T$5-W21-X21 -> 1534.04 | E21: =E20+'2026.06'!$X$5 -> 5.03 | F21: 0 | G21: 0 | H21: 0 | I21: 0 | J21: 0 | K21: 0 | L21: 0 | M21: =SPYL!H13 -> 874.8432 | N21: 0 | O21: 0 | P21: =EXUS!H6 -> 394.325 | Q21: =IS3N!H6 -> 391.592 | R21: 0 | S21: =SUM(F21:R21)+E21 -> 1665.7902 | T21: =S21-B21 -> 135.7902 | U21: =T21/B21 -> 0.088751765 | V21: ='2026.06'!$W$5 -> 0 | W21: ='2026.06'!$U$5 -> 0.02 | X21: ='2026.06'!$V$5 -> 0
A22: ='2026.07'!$Q$2 -> 2026.07 | B22: =B21+'2026.07'!$Q$5 -> 1670 | C22: ='2026.07'!$R$5 -> 0 | D22: =D21+'2026.07'!$S$5-'2026.07'!$T$5-W22-X22 -> 1668.99 | E22: =E21+'2026.07'!$X$5 -> 9.98 | F22: 0 | G22: 0 | H22: 0 | I22: 0 | J22: 0 | K22: 0 | L22: 0 | M22: =SPYL!H14 -> 915.58245 | N22: 0 | O22: 0 | P22: =EXUS!H7 -> 438.603 | Q22: =IS3N!H7 -> 409.662 | R22: 0 | S22: =SUM(F22:R22)+E22 -> 1773.8274 | T22: =S22-B22 -> 103.82745 | U22: =T22/B22 -> 0.062172126 | V22: ='2026.07'!$W$5 -> 0 | W22: ='2026.07'!$U$5 -> 0.05 | X22: ='2026.07'!$V$5 -> 0
A23: ='2026.08'!$Q$2 -> 2026.08 | B23: =B22+'2026.08'!$Q$5 -> 1820 | C23: ='2026.08'!$R$5 -> 0 | D23: =D22+'2026.08'!$S$5-'2026.08'!$T$5-W23-X23 -> 1819.88 | E23: =E22+'2026.08'!$X$5 -> 9.09 | F23: 0 | G23: 0 | H23: 0 | I23: 0 | J23: 0 | K23: 0 | L23: 0 | M23: =SPYL!H15 -> 999.8693 | N23: 0 | O23: 0 | P23: =EXUS!H8 -> 484.53 | Q23: =IS3N!H8 -> 473.52 | R23: 0 | S23: =SUM(F23:R23)+E23 -> 1967.0093 | T23: =S23-B23 -> 147.0093 | U23: =T23/B23 -> 0.080774341 | V23: ='2026.08'!$W$5 -> 0 | W23: ='2026.08'!$U$5 -> 0 | X23: ='2026.08'!$V$5 -> 0
A24: ='2026.09'!$Q$2 -> 2026.09 | B24: =B23+'2026.09'!$Q$5 -> 1975 | C24: ='2026.09'!$R$5 -> 0 | D24: =D23+'2026.09'!$S$5-'2026.09'!$T$5-W24-X24 -> 1981.26 | E24: =E23+'2026.09'!$X$5 -> 2.71 | F24: 0 | G24: 0 | H24: 0 | I24: 0 | J24: 0 | K24: 0 | L24: 0 | M24: =SPYL!H16 -> 1087.892 | N24: 0 | O24: 0 | P24: =EXUS!H9 -> 517.1075 | Q24: =IS3N!H9 -> 531.63 | R24: =VGLA!H5 -> 8.686 | S24: =SUM(F24:R24)+E24 -> 2148.0255 | T24: =S24-B24 -> 173.0255 | U24: =T24/B24 -> 0.087607848 | V24: ='2026.09'!$W$5 -> 0 | W24: ='2026.09'!$U$5 -> 0 | X24: ='2026.09'!$V$5 -> 0

Sheet NADQ
A1: NADQ Amundi Nasdaq-100 II UCITS ETF (Dist)
A3: Data | B3: Suma, EUR | E3: Kiekis | G3: Mėnesio gale | K3: Mokesčiai | M3: Dividendai | O3: NADQ | P3: Įnešta | Q3: Kiekis | R3: Parduota | S3: Pelnas | V3: Mokesčiai | X3: Dividendai | Y3: Vid. Kaina | AC3: Suma | AD3: Kaina | AE3: Kiekis | AF3: Pirkimas/pardavimas
B4: Įnešta | C4: Mėn. Inv. | D4: Viso Inv. | E4: Mėnesio | F4: Viso | G4: Kaina | H4: Vertė gale | I4: Pelnas | J4: % | K4: Pirkimas | L4: Pardavimas | S4: Eur. | T4: % | U4: XIRR | V4: Pirkimas | W4: Pardavimas | AF4: Data | AG4: Suma
A5: ='2024.12'!Q2 -> 2024.12 | B5: ='2024.12'!B19 -> 10 | C5: ='2024.12'!C19 -> 10 | D5: =C5 -> 10 | E5: ='2024.12'!F19 -> 0.04610419 | F5: =E5 -> 0.04610419 | G5: 216.25 | H5: =F5*G5 -> 9.9700311 | I5: =H5-D5 -> -0.029968912 | J5: =(H5-D5)/H5 -> -0.0030058996 | K5: ='2024.12'!D19 -> 0 | L5: ='2024.12'!J19 -> 0 | M5: ='2024.12'!O19 -> 0 | O5: Viso: | P5: =SUM(B5:B61) -> 20 | Q5: =SUM(E5:E61) -> 0.09571928 | R5: ='2025.11'!I19-'2025.11'!J19 -> 22.13 | S5: =R5-P5 -> 2.13 | T5: =(R5-P5)/P5 -> 0.1065 | U5: =XIRR(AG5:AG7,AF5:AF7) -> 0.17580165 | V5: =SUM(K5:K16) -> 0.01 | W5: =SUM(L5:L16) -> 0 | X5: =SUM(M5:M16) -> 0 | Y5: {=SUMPRODUCT(IFERROR(AD5:AD200,0),IFERROR(AE5:AE200,0))/SUM(IFERROR(AE5:AE200,0))} -> 15.1714 | AC5: ='2024.12'!$C$19 -> 10 | AD5: ='2024.12'!$E$19 -> 216.90003 | AE5: ='2024.12'!$F$19 -> 0.04610419 | AF5: ='2024.12'!$A$15 -> 45645 | AG5: ='2024.12'!$B$15*-1 -> -10
A6: ='2025.01'!Q2 -> 2025.01 | B6: ='2025.01'!B19 -> 0 | C6: ='2025.01'!C18 -> 0 | D6: =D5+C6 -> 10 | E6: ='2025.01'!F18 -> 0 | F6: =F5+E6 -> 0.04610419 | G6: 218.85 | H6: =F6*G6 -> 10.089902 | I6: =H6-D6 -> 0.089901982 | J6: =(H6-D6)/H6 -> 0.0089100946 | K6: ='2025.01'!D19 -> 0 | L6: ='2025.01'!J19 -> 0 | M6: ='2025.01'!O19 -> 0 | AC6: ='2025.11'!$C$89 -> 163.15 | AD6: ='2025.11'!$E$89 -> 14.54264 | AE6: ='2025.11'!$F$89 -> 11.218734 | AF6: ='2025.07'!$A$15 -> 45839 | AG6: ='2025.07'!$B$15*-1 -> -10
A7: ='2025.02'!Q2 -> 2025.02 | B7: ='2025.02'!B19 -> 0 | C7: ='2025.02'!C18 -> 0 | D7: =D6+C7 -> 10 | E7: ='2025.02'!F18 -> 0 | F7: =F6+E7 -> 0.04610419 | G7: 209.96 | H7: =F7*G7 -> 9.6800357 | I7: =H7-D7 -> -0.31996427 | J7: =(H7-D7)/H7 -> -0.033054038 | K7: ='2025.02'!D19 -> 0 | L7: ='2025.02'!J19 -> 0 | M7: ='2025.02'!O19 -> 0 | AC7: ='2025.12'!$C$89 -> 15.45 | AD7: ='2025.12'!$E$89 -> 14.425189 | AE7: ='2025.12'!$F$89 -> 1.0710432 | AF7: ='2025.11'!$H$15 -> 45968 | AG7: ='2025.11'!$I$15-'2025.11'!J15 -> 22.13
A8: ='2025.03'!Q2 -> 2025.03 | B8: ='2025.03'!B19 -> 0 | C8: ='2025.03'!C18 -> 0 | D8: =D7+C8 -> 10 | E8: ='2025.03'!F18 -> 0 | F8: =F7+E8 -> 0.04610419 | G8: 188.05 | H8: =F8*G8 -> 8.6698929 | I8: =H8-D8 -> -1.3301071 | J8: =(H8-D8)/H8 -> -0.15341678 | K8: ='2025.03'!D19 -> 0 | L8: ='2025.03'!J19 -> 0 | M8: ='2025.03'!O19 -> 0 | AC8: ='2026.01'!$C$89 -> 43.38 | AD8: ='2026.01'!$E$89 -> 14.46 | AE8: ='2026.01'!$F$89 -> 3
A9: ='2025.04'!Q2 -> 2025.04 | B9: ='2025.04'!B19 -> 0 | C9: ='2025.04'!C19 -> 0 | D9: =D8+C9 -> 10 | E9: ='2025.04'!F19 -> 0 | F9: =F8+E9 -> 0.04610419 | G9: 182.85 | H9: =F9*G9 -> 8.4301511 | I9: =H9-D9 -> -1.5698489 | J9: =(H9-D9)/H9 -> -0.18621835 | K9: ='2025.04'!D19 -> 0 | L9: ='2025.04'!J19 -> 0 | M9: ='2025.04'!O19 -> 0 | AC9: ='2026.02'!$C$89 -> 57.13 | AD9: ='2026.02'!$E$89 -> 14.2825 | AE9: ='2026.02'!$F$89 -> 4
A10: ='2025.05'!Q2 -> 2025.05 | B10: ='2025.05'!B19 -> 0 | C10: ='2025.05'!C19 -> 0 | D10: =D9+C10 -> 10 | E10: ='2025.05'!F19 -> 0 | F10: =F9+E10 -> 0.04610419 | G10: 198.25 | H10: =F10*G10 -> 9.1401557 | I10: =H10-D10 -> -0.85984433 | J10: =(H10-D10)/H10 -> -0.09407327 | K10: ='2025.05'!D19 -> 0 | L10: ='2025.05'!J19 -> 0 | M10: ='2025.05'!O19 -> 0 | AC10: ='2026.03'!$C$89 -> 71.06 | AD10: ='2026.03'!$E$89 -> 14.212 | AE10: ='2026.03'!$F$89 -> 5
A11: ='2025.06'!Q2 -> 2025.06 | B11: ='2025.06'!B19 -> 0 | C11: ='2025.06'!C19 -> 0 | D11: =D10+C11 -> 10 | E11: ='2025.06'!F19 -> 0 | F11: =F10+E11 -> 0.04610419 | G11: 203.24 | H11: =F11*G11 -> 9.3702156 | I11: =H11-D11 -> -0.62978442 | J11: =(H11-D11)/H11 -> -0.067211306 | K11: ='2025.06'!D19 -> 0 | L11: ='2025.06'!J19 -> 0 | M11: ='2025.06'!O19 -> 0 | AC11: ='2026.04'!$C$89 -> 84.26 | AD11: ='2026.04'!$E$89 -> 14.043333 | AE11: ='2026.04'!$F$89 -> 6
A12: ='2025.07'!Q2 -> 2025.07 | B12: ='2025.07'!B19 -> 10 | C12: ='2025.07'!C19 -> 9.99 | D12: =D11+C12 -> 19.99 | E12: ='2025.07'!F19 -> 0.04961509 | F12: =F11+E12 -> 0.09571928 | G12: 215.32 | H12: =F12*G12 -> 20.610275 | I12: =H12-D12 -> 0.62027537 | J12: =(H12-D12)/H12 -> 0.030095443 | K12: ='2025.07'!D19 -> 0.01 | L12: ='2025.07'!J19 -> 0 | M12: ='2025.07'!O19 -> 0 | AC12: ='2026.05'!$C$89 -> 76.46 | AD12: ='2026.05'!$E$89 -> 15.292 | AE12: ='2026.05'!$F$89 -> 5
A13: ='2025.08'!Q2 -> 2025.08 | B13: ='2025.08'!B19 -> 0 | C13: ='2025.08'!C19 -> 0 | D13: =D12+C13 -> 19.99 | E13: ='2025.08'!F19 -> 0 | F13: =F12+E13 -> 0.09571928 | G13: 211.45 | H13: =F13*G13 -> 20.239842 | I13: =H13-D13 -> 0.24984176 | J13: =(H13-D13)/H13 -> 0.012344057 | K13: ='2025.08'!D19 -> 0 | L13: ='2025.08'!J19 -> 0 | M13: ='2025.08'!O19 -> 0 | AC13: ='2026.06'!$C$89 -> 288.29 | AD13: ='2026.06'!$E$89 -> 16.016111 | AE13: ='2026.06'!$F$89 -> 18
A14: ='2025.09'!Q2 -> 2025.09 | B14: ='2025.09'!B19 -> 0 | C14: ='2025.09'!C19 -> 0 | D14: =D13+C14 -> 19.99 | E14: ='2025.09'!F19 -> 0 | F14: =F13+E14 -> 0.09571928 | G14: 222 | H14: =F14*G14 -> 21.24968 | I14: =H14-D14 -> 1.2596802 | J14: =(H14-D14)/H14 -> 0.059279959 | K14: ='2025.09'!D19 -> 0 | L14: ='2025.09'!J19 -> 0 | M14: ='2025.09'!O19 -> 0
A15: ='2025.10'!Q2 -> 2025.10 | B15: ='2025.10'!B19 -> 0 | C15: ='2025.10'!C19 -> 0 | D15: =D14+C15 -> 19.99 | E15: ='2025.10'!F19 -> 0 | F15: =F14+E15 -> 0.09571928 | G15: 236.84 | H15: =F15*G15 -> 22.670154 | I15: =H15-D15 -> 2.6801543 | J15: =(H15-D15)/H15 -> 0.11822391 | K15: ='2025.10'!D19 -> 0 | L15: ='2025.10'!J19 -> 0 | M15: ='2025.10'!O19 -> 0
A16: ='2025.11'!Q2 -> 2025.11 | B16: ='2025.11'!B19 -> 0 | C16: ='2025.11'!C19 -> 0 | D16: =D15+C16 -> 19.99 | E16: ='2025.11'!F19 -> 0 | F16: =F15+E16 -> 0.09571928 | G16: 231.2 | H16: =F16*G16 -> 22.130298 | I16: =H16-D16 -> 2.1402975 | J16: =(H16-D16)/H16 -> 0.096713455 | K16: ='2025.11'!D19 -> 0 | L16: ='2025.11'!J19 -> 0 | M16: ='2025.11'!O19 -> 0

Sheet QDVE
A1: iShares S&P 500 Information Technology Sector UCITS ETF (Acc)
A3: Data | B3: Suma, EUR | E3: Kiekis | G3: Mėnesio gale | K3: Mokesčiai | M3: Dividendai | O3: QDVE | P3: Įnešta | Q3: Kiekis | R3: Parduota | S3: Pelnas | V3: Mokesčiai | X3: Dividendai | Y3: Vid. Kaina | AC3: Suma | AD3: Kaina | AE3: Kiekis | AF3: Pirkimas/pardavimas
B4: Įnešta | C4: Mėn. Inv. | D4: Viso Inv. | E4: Mėnesio | F4: Viso | G4: Kaina | H4: Vertė gale | I4: Pelnas | J4: % | K4: Pirkimas | L4: Pardavimas | S4: Eur. | T4: % | U4: XIRR | V4: Pirkimas | W4: Pardavimas | AF4: Data | AG4: Suma
A5: ='2025.04'!Q2 -> 2025.04 | B5: ='2025.04'!B29 -> 10 | C5: ='2025.04'!C29 -> 10 | D5: =C5 -> 10 | E5: ='2025.04'!F29 -> 0.4255319 | F5: =E5 -> 0.4255319 | G5: 26.77 | H5: =F5*G5 -> 11.391489 | I5: =H5-D5 -> 1.391489 | J5: =(H5-D5)/D5 -> 0.1391489 | K5: ='2025.04'!D29 -> 0 | L5: ='2025.04'!J29 -> 0 | M5: ='2025.04'!O29 -> 0 | O5: Viso: | P5: =SUM(B5:B55) -> 90.87 | Q5: =SUM(E5:E55) -> 2.8973029 | R5: ='2025.11'!I29-'2025.11'!J29 -> 107.22 | S5: =R5-P5 -> 16.35 | T5: =(R5-P5)/P5 -> 0.17992737 | U5: =XIRR(AG5:AG13,AF5:AF13) -> 0.79188799 | V5: =SUM(K5:K12) -> 0.06 | W5: =SUM(L5:L12) -> 0.11 | X5: =SUM(M5:M12) -> 0 | Y5: {=SUMPRODUCT(IFERROR(AD5:AD200,0),IFERROR(AE5:AE200,0))/SUM(IFERROR(AE5:AE200,0))} -> 31.342943 | AC5: ='2025.04'!$C$29 -> 10 | AD5: ='2025.04'!$E$29 -> 23.500001 | AE5: ='2025.04'!$F$29 -> 0.4255319 | AF5: ='2025.04'!$A$25 -> 45769 | AG5: ='2025.04'!$B$25*-1 -> -10
A6: ='2025.05'!Q2 -> 2025.05 | B6: ='2025.05'!B29 -> 20.07 | C6: ='2025.05'!C29 -> 20.06 | D6: =D5+C6 -> 30.06 | E6: ='2025.05'!F29 -> 0.70033011 | F6: =F5+E6 -> 1.125862 | G6: 29.25 | H6: =F6*G6 -> 32.931464 | I6: =H6-D6 -> 2.8714638 | J6: =(H6-D6)/D6 -> 0.095524411 | K6: ='2025.05'!D29 -> 0.01 | L6: ='2025.05'!J29 -> 0 | M6: ='2025.05'!O29 -> 0 | AC6: ='2025.05'!$C$29 -> 20.06 | AD6: ='2025.05'!$E$29 -> 28.643635 | AE6: ='2025.05'!$F$29 -> 0.70033011 | AF6: ='2025.05'!$A$25 -> 45782 | AG6: ='2025.05'!$B$25*-1 -> -10
A7: ='2025.06'!Q2 -> 2025.06 | B7: ='2025.06'!B29 -> 0 | C7: ='2025.06'!C29 -> 0 | D7: =D6+C7 -> 30.06 | E7: ='2025.06'!F29 -> 0 | F7: =F6+E7 -> 1.125862 | G7: 30.95 | H7: =F7*G7 -> 34.845429 | I7: =H7-D7 -> 4.7854292 | J7: =(H7-D7)/D7 -> 0.15919592 | K7: ='2025.06'!D29 -> 0 | L7: ='2025.06'!J29 -> 0 | M7: ='2025.06'!O29 -> 0 | AC7: ='2025.06'!$C$29 -> 0 | AD7: ='2025.06'!$E$29 -> 0.00 | AE7: ='2025.06'!$F$29 -> 0 | AF7: ='2025.05'!$A$26 -> 45806 | AG7: ='2025.05'!$B$26*-1 -> -10.07
A8: ='2025.07'!Q2 -> 2025.07 | B8: ='2025.07'!B29 -> 10 | C8: ='2025.07'!C29 -> 9.99 | D8: =D7+C8 -> 40.05 | E8: ='2025.07'!F29 -> 0.3266307 | F8: =F7+E8 -> 1.4524927 | G8: 33.54 | H8: =F8*G8 -> 48.716605 | I8: =H8-D8 -> 8.6666055 | J8: =(H8-D8)/D8 -> 0.21639464 | K8: ='2025.07'!D29 -> 0.01 | L8: ='2025.07'!J29 -> 0 | M8: ='2025.07'!O29 -> 0 | AC8: ='2025.07'!$C$29 -> 9.99 | AD8: ='2025.07'!$E$29 -> 30.585 | AE8: ='2025.07'!$F$29 -> 0.3266307 | AF8: ='2025.07'!$A$25 -> 45839 | AG8: ='2025.07'!$B$25*-1 -> -10
A9: ='2025.08'!Q2 -> 2025.08 | B9: ='2025.08'!B29 -> 10 | C9: ='2025.08'!C29 -> 9.99 | D9: =D8+C9 -> 50.04 | E9: ='2025.08'!F29 -> 0.30823819 | F9: =F8+E9 -> 1.7607309 | G9: 32.73 | H9: =F9*G9 -> 57.628722 | I9: =H9-D9 -> 7.5887224 | J9: =(H9-D9)/D9 -> 0.15165312 | K9: ='2025.08'!D29 -> 0.01 | L9: ='2025.08'!J29 -> 0 | M9: ='2025.08'!O29 -> 0 | AC9: ='2025.08'!$C$29 -> 9.99 | AD9: ='2025.08'!$E$29 -> 32.410001 | AE9: ='2025.08'!$F$29 -> 0.30823819 | AF9: ='2025.08'!$A$25 -> 45889 | AG9: ='2025.08'!$B$25*-1 -> -10
A10: ='2025.09'!Q2 -> 2025.09 | B10: ='2025.09'!B29 -> 10 | C10: ='2025.09'!C29 -> 10 | D10: =D9+C10 -> 60.04 | E10: ='2025.09'!F29 -> 0.30422877 | F10: =F9+E10 -> 2.0649597 | G10: 35.01 | H10: =F10*G10 -> 72.294238 | I10: =H10-D10 -> 12.254238 | J10: =(H10-D10)/D10 -> 0.20410123 | K10: ='2025.09'!D29 -> 0 | L10: ='2025.09'!J29 -> 0 | M10: ='2025.09'!O29 -> 0 | AC10: ='2025.09'!$C$29 -> 10 | AD10: ='2025.09'!$E$29 -> 32.870001 | AE10: ='2025.09'!$F$29 -> 0.30422877 | AF10: ='2025.09'!$A$25 -> 45908 | AG10: ='2025.09'!$B$25*-1 -> -10
A11: ='2025.10'!Q2 -> 2025.10 | B11: ='2025.10'!B29 -> 10 | C11: ='2025.10'!C29 -> 9.99 | D11: =D10+C11 -> 70.03 | E11: ='2025.10'!F29 -> 0.28136882 | F11: =F10+E11 -> 2.3463285 | G11: 37.97 | H11: =F11*G11 -> 89.090093 | I11: =H11-D11 -> 19.060093 | J11: =(H11-D11)/D11 -> 0.2721704 | K11: ='2025.10'!D29 -> 0.01 | L11: ='2025.10'!J29 -> 0 | M11: ='2025.10'!O29 -> 0 | AC11: ='2025.10'!$C$29 -> 9.99 | AD11: ='2025.10'!$E$29 -> 35.505 | AE11: ='2025.10'!$F$29 -> 0.28136882 | AF11: ='2025.10'!$A$25 -> 45933 | AG11: ='2025.10'!$B$25*-1 -> -10
A12: ='2025.11'!Q2 -> 2025.11 | B12: ='2025.11'!B29 -> 20.8 | C12: ='2025.11'!C29 -> 20.78 | D12: =D11+C12 -> 90.81 | E12: ='2025.11'!F29 -> 0.55097441 | F12: =F11+E12 -> 2.8973029 | G12: 37.04 | H12: =F12*G12 -> 107.3161 | I12: =H12-D12 -> 16.506099 | J12: =(H12-D12)/D12 -> 0.18176522 | K12: ='2025.11'!D29 -> 0.02 | L12: ='2025.11'!J29 -> 0.11 | M12: ='2025.11'!O29 -> 0 | AC12: ='2025.11'!$C$29 -> 20.78 | AD12: ='2025.11'!$E$29 -> 37.715 | AE12: ='2025.11'!$F$29 -> 0.55097441 | AF12: ='2025.11'!$A$25 -> 45965 | AG12: ='2025.11'!$B$25*-1 -> -20.8
AF13: ='2025.11'!$H$25 -> 45973 | AG13: ='2025.11'!$I$25-'2025.11'!J25 -> 107.22

Sheet VWCE
A1: Vanguard FTSE All-World UCITS ETF (Acc)
A3: Data | B3: Suma, EUR | E3: Kiekis | G3: Mėnesio gale | K3: Mokesčiai | M3: Dividendai | O3: VWCE | P3: Įnešta | Q3: Kiekis | R3: Parduota | S3: Pelnas | V3: Mokesčiai | X3: Dividendai | Y3: Vid. Kaina | AC3: Suma | AD3: Kaina | AE3: Kiekis | AF3: Pirkimas/pardavimas
B4: Įnešta | C4: Mėn. Inv. | D4: Viso Inv. | E4: Mėnesio | F4: Viso | G4: Kaina | H4: Vertė gale | I4: Pelnas | J4: % | K4: Pirkimas | L4: Pardavimas | S4: Eur. | T4: % | U4: XIRR | V4: Pirkimas | W4: Pardavimas | AF4: Data | AG4: Suma
A5: ='2025.06'!Q2 -> 2025.06 | B5: ='2025.06'!B39 -> 10 | C5: ='2025.06'!C39 -> 10 | D5: =C5 -> 10 | E5: ='2025.06'!F39 -> 0.07718431 | F5: =E5 -> 0.07718431 | G5: 129.69 | H5: =F5*G5 -> 10.010033 | I5: =H5-D5 -> 0.010033164 | J5: =(H5-D5)/D5 -> 0.0010033164 | K5: ='2025.06'!D39 -> 0 | L5: ='2025.06'!J39 -> 0 | M5: ='2025.06'!O39 -> 0 | O5: Viso: | P5: =SUM(B5:B43) -> 102.52 | Q5: =SUM(E5:E43) -> 0.72812536 | R5: ='2025.11'!I39-'2025.11'!J39 -> 106.12 | S5: =R5-P5 -> 3.6 | T5: =(R5-P5)/P5 -> 0.035115099 | U5: =XIRR(AG5:AG11,AF5:AF11) -> 0.42217914 | V5: =SUM(K5:K10) -> 0.09 | W5: =SUM(L5:L10) -> 0.11 | X5: =SUM(M5:M12) -> 0 | Y5: {=SUMPRODUCT(IFERROR(AD5:AD200,0),IFERROR(AE5:AE200,0))/SUM(IFERROR(AE5:AE200,0))} -> 140.67633 | AC5: ='2025.06'!$C$39 -> 10 | AD5: ='2025.06'!$E$39 -> 129.56001 | AE5: ='2025.06'!$F$39 -> 0.07718431 | AF5: ='2025.06'!$A$35 -> 45833 | AG5: ='2025.06'!$B$35*-1 -> -10
A6: ='2025.07'!Q2 -> 2025.07 | B6: ='2025.07'!B39 -> 10 | C6: ='2025.07'!C39 -> 9.99 | D6: =D5+C6 -> 19.99 | E6: ='2025.07'!F39 -> 0.07704766 | F6: =F5+E6 -> 0.15423197 | G6: 135.38 | H6: =F6*G6 -> 20.879924 | I6: =H6-D6 -> 0.8899241 | J6: =(H6-D6)/D6 -> 0.044518464 | K6: ='2025.07'!D39 -> 0.01 | L6: ='2025.07'!J39 -> 0 | M6: ='2025.07'!O39 -> 0 | AC6: ='2025.07'!$C$39 -> 9.99 | AD6: ='2025.07'!$E$39 -> 129.66001 | AE6: ='2025.07'!$F$39 -> 0.07704766 | AF6: ='2025.07'!$A$35 -> 45839 | AG6: ='2025.07'!$B$35*-1 -> -10
A7: ='2025.08'!Q2 -> 2025.08 | B7: ='2025.08'!B39 -> 0 | C7: ='2025.08'!C39 -> 0 | D7: =D6+C7 -> 19.99 | E7: ='2025.08'!F39 -> 0 | F7: =F6+E7 -> 0.15423197 | G7: 135.64 | H7: =F7*G7 -> 20.920024 | I7: =H7-D7 -> 0.93002441 | J7: =(H7-D7)/D7 -> 0.046524483 | K7: ='2025.08'!D39 -> 0 | L7: ='2025.08'!J39 -> 0 | M7: ='2025.08'!O39 -> 0 | AC7: ='2025.08'!$C$39 -> 0 | AD7: ='2025.08'!$E$39 -> 0.00 | AE7: ='2025.08'!$F$39 -> 0 | AF7: ='2025.10'!$A$35 -> 45933 | AG7: ='2025.10'!$B$35*-1 -> -10
A8: ='2025.09'!Q2 -> 2025.09 | B8: ='2025.09'!B39 -> 0 | C8: ='2025.09'!C39 -> 0 | D8: =D7+C8 -> 19.99 | E8: ='2025.09'!F39 -> 0 | F8: =F7+E8 -> 0.15423197 | G8: 139.98 | H8: =F8*G8 -> 21.589391 | I8: =H8-D8 -> 1.5993912 | J8: =(H8-D8)/D8 -> 0.080009563 | K8: ='2025.09'!D39 -> 0 | L8: ='2025.09'!J39 -> 0 | M8: ='2025.09'!O39 -> 0 | AC8: ='2025.09'!$C$39 -> 0 | AD8: ='2025.09'!$E$39 -> 0.00 | AE8: ='2025.09'!$F$39 -> 0 | AF8: ='2025.11'!$A$35 -> 45965 | AG8: ='2025.11'!$B$35*-1 -> -10
A9: ='2025.10'!Q2 -> 2025.10 | B9: ='2025.10'!B39 -> 10 | C9: ='2025.10'!C39 -> 9.99 | D9: =D8+C9 -> 29.98 | E9: ='2025.10'!F39 -> 0.07070063 | F9: =F8+E9 -> 0.2249326 | G9: 145.42 | H9: =F9*G9 -> 32.709699 | I9: =H9-D9 -> 2.7296987 | J9: =(H9-D9)/D9 -> 0.091050657 | K9: ='2025.10'!D39 -> 0.01 | L9: ='2025.10'!J39 -> 0 | M9: ='2025.10'!O39 -> 0 | AC9: ='2025.10'!$C$39 -> 9.99 | AD9: ='2025.10'!$E$39 -> 141.30001 | AE9: ='2025.10'!$F$39 -> 0.07070063 | AF9: ='2025.11'!$A$36 -> 45968 | AG9: ='2025.11'!$B$36*-1 -> -30
A10: ='2025.11'!Q2 -> 2025.11 | B10: ='2025.11'!B39 -> 72.52 | C10: ='2025.11'!C39 -> 72.45 | D10: =D9+C10 -> 102.43 | E10: ='2025.11'!F39 -> 0.50319276 | F10: =F9+E10 -> 0.72812536 | G10: 145.9 | H10: =F10*G10 -> 106.23349 | I10: =H10-D10 -> 3.80349 | J10: =(H10-D10)/D10 -> 0.037132579 | K10: ='2025.11'!D39 -> 0.07 | L10: ='2025.11'!J39 -> 0.11 | M10: ='2025.11'!O39 -> 0 | AC10: ='2025.11'!$C$39 -> 72.45 | AD10: ='2025.11'!$E$39 -> 143.98061 | AE10: ='2025.11'!$F$39 -> 0.50319276 | AF10: ='2025.11'!$A$37 -> 45968 | AG10: ='2025.11'!$B$37*-1 -> -32.52
AF11: ='2025.11'!$H$35 -> 45973 | AG11: ='2025.11'!$I$35-'2025.11'!J35 -> 106.12

Sheet XDEQ
A1: XDEQ Xtarckers MSCI World Quality UCITS ETF (Acc)
A3: Data | B3: Suma, EUR | E3: Kiekis | G3: Mėnesio gale | K3: Mokesčiai | M3: Dividendai | O3: XDEQ | P3: Įnešta | Q3: Kiekis | R3: Parduota | S3: Pelnas | V3: Mokesčiai | X3: Dividendai | Y3: Vid. Kaina | AC3: Suma | AD3: Kaina | AE3: Kiekis | AF3: Pirkimas/pardavimas
B4: Įnešta | C4: Mėn. Inv. | D4: Viso Inv. | E4: Mėnesio | F4: Viso | G4: Kaina | H4: Vertė gale | I4: Pelnas | J4: % | K4: Pirkimas | L4: Pardavimas | S4: Eur. | T4: % | U4: XIRR | V4: Pirkimas | W4: Pardavimas | AF4: Data | AG4: Suma
A5: ='2025.07'!Q2 -> 2025.07 | B5: ='2025.07'!B49 -> 10 | C5: ='2025.07'!C49 -> 10 | D5: =C5 -> 10 | E5: ='2025.07'!F49 -> 0.1537279 | F5: =E5 -> 0.1537279 | G5: 65.25 | H5: =F5*G5 -> 10.030745 | I5: =H5-D5 -> 0.030745475 | J5: =(H5-D5)/D5 -> 0.0030745475 | K5: ='2025.07'!D49 -> 0 | L5: ='2025.07'!J49 -> 0 | M5: ='2025.07'!O49 -> 0 | O5: Viso: | P5: =SUM(B5:B46) -> 20 | Q5: =SUM(E5:E46) -> 0.30631687 | R5: ='2025.11'!I49-'2025.11'!J49 -> 20.8 | S5: =R5-P5 -> 0.8 | T5: =(R5-P5)/P5 -> 0.04 | U5: =XIRR(AG5:AG7,AF5:AF7) -> 0.2011419 | V5: =SUM(K5:K9) -> 0.01 | W5: =SUM(L5:L9) -> 0.02 | X5: =SUM(M5:M12) -> 0 | Y5: {=SUMPRODUCT(IFERROR(AD5:AD200,0),IFERROR(AE5:AE200,0))/SUM(IFERROR(AE5:AE200,0))} -> 65.25922 | AC5: ='2025.07'!$C$49 -> 10 | AD5: ='2025.07'!$E$49 -> 65.050001 | AE5: ='2025.07'!$F$49 -> 0.1537279 | AF5: ='2025.07'!$A$45 -> 45866 | AG5: ='2025.07'!$B$45*-1 -> -10
A6: ='2025.08'!Q2 -> 2025.08 | B6: ='2025.08'!B49 -> 0 | C6: ='2025.08'!C49 -> 0 | D6: =D5+C6 -> 10 | E6: ='2025.08'!F49 -> 0 | F6: =F5+E6 -> 0.1537279 | G6: 65.31 | H6: =F6*G6 -> 10.039969 | I6: =H6-D6 -> 0.039969149 | J6: =(H6-D6)/D6 -> 0.0039969149 | K6: ='2025.08'!D49 -> 0 | L6: ='2025.08'!J49 -> 0 | M6: ='2025.08'!O49 -> 0 | AC6: ='2025.08'!$C$49 -> 0 | AD6: ='2025.08'!$E$49 -> 0.00 | AE6: ='2025.08'!$F$49 -> 0 | AF6: ='2025.09'!$A$45 -> 45908 | AG6: ='2025.09'!$B$45*-1 -> -10
A7: ='2025.09'!Q2 -> 2025.09 | B7: ='2025.09'!B49 -> 10 | C7: ='2025.09'!C49 -> 9.99 | D7: =D6+C7 -> 19.99 | E7: ='2025.09'!F49 -> 0.15258897 | F7: =F6+E7 -> 0.30631687 | G7: 66.92 | H7: =F7*G7 -> 20.498725 | I7: =H7-D7 -> 0.50872494 | J7: =(H7-D7)/D7 -> 0.025448972 | K7: ='2025.09'!D49 -> 0.01 | L7: ='2025.09'!J49 -> 0 | M7: ='2025.09'!O49 -> 0 | AC7: ='2025.09'!$C$49 -> 9.99 | AD7: ='2025.09'!$E$49 -> 65.470001 | AE7: ='2025.09'!$F$49 -> 0.15258897 | AF7: ='2025.11'!$H$45 -> 45965 | AG7: ='2025.11'!$I$45-'2025.11'!J45 -> 20.8
A8: ='2025.10'!Q2 -> 2025.10 | B8: ='2025.10'!B49 -> 0 | C8: ='2025.10'!C49 -> 0 | D8: =D7+C8 -> 19.99 | E8: ='2025.10'!F49 -> 0 | F8: =F7+E8 -> 0.30631687 | G8: 68.78 | H8: =F8*G8 -> 21.068474 | I8: =H8-D8 -> 1.0784743 | J8: =(H8-D8)/D8 -> 0.053950691 | K8: ='2025.10'!D49 -> 0 | L8: ='2025.10'!J49 -> 0 | M8: ='2025.10'!O49 -> 0 | AC8: ='2025.10'!$C$49 -> 0 | AD8: ='2025.10'!$E$49 -> 0.00 | AE8: ='2025.10'!$F$49 -> 0
A9: ='2025.11'!Q2 -> 2025.11 | B9: ='2025.11'!B49 -> 0 | C9: ='2025.11'!C49 -> 0 | D9: =D8+C9 -> 19.99 | E9: ='2025.11'!F49 -> 0 | F9: =F8+E9 -> 0.30631687 | G9: 67.97 | H9: =F9*G9 -> 20.820358 | I9: =H9-D9 -> 0.83035765 | J9: =(H9-D9)/D9 -> 0.041538652 | K9: ='2025.11'!D49 -> 0 | L9: ='2025.11'!J49 -> 0.02 | M9: ='2025.11'!O49 -> 0 | AC9: ='2025.11'!$C$49 -> 0 | AD9: ='2025.11'!$E$49 -> 0.00 | AE9: ='2025.11'!$F$49 -> 0

Sheet VUAA
A1: VUAA Vanguard S&P 500 UCITS ETF (Acc)
A3: Data | B3: Suma, EUR | E3: Kiekis | G3: Mėnesio gale | K3: Mokesčiai | M3: Dividendai | O3: VUAA | P3: Įnešta | Q3: Kiekis | R3: Parduota | S3: Pelnas | V3: Mokesčiai | X3: Dividendai | Y3: Vid. Kaina | AC3: Suma | AD3: Kaina | AE3: Kiekis | AF3: Pirkimas/pardavimas
B4: Įnešta | C4: Mėn. Inv. | D4: Viso Inv. | E4: Mėnesio | F4: Viso | G4: Kaina | H4: Vertė gale | I4: Pelnas | J4: % | K4: Pirkimas | L4: Pardavimas | S4: Eur. | T4: % | U4: XIRR | V4: Pirkimas | W4: Pardavimas | AF4: Data | AG4: Suma
A5: ='2025.07'!Q2 -> 2025.07 | B5: ='2025.07'!B59 -> 10 | C5: ='2025.07'!C59 -> 9.99 | D5: =C5 -> 9.99 | E5: ='2025.07'!F59 -> 0.09511124 | F5: =E5 -> 0.09511124 | G5: 106.4 | H5: =F5*G5 -> 10.119836 | I5: =H5-D5 -> 0.12983594 | J5: =(H5-D5)/D5 -> 0.01299659 | K5: ='2025.07'!D59 -> 0.01 | L5: ='2025.07'!J59 -> 0 | M5: ='2025.07'!O59 -> 0 | O5: Viso: | P5: =SUM(B5:B46) -> 20 | Q5: =SUM(E5:E46) -> 0.18926565 | R5: ='2025.11'!I59-'2025.11'!J59 -> 21.35 | S5: =R5-P5 -> 1.35 | T5: =(R5-P5)/P5 -> 0.0675 | U5: =XIRR(AG5:AG7,AF5:AF7) -> 0.35654556 | V5: =SUM(K5:K9) -> 0.02 | W5: =SUM(L5:L9) -> 0.02 | X5: =SUM(M5:M12) -> 0 | Y5: {=SUMPRODUCT(IFERROR(AD5:AD200,0),IFERROR(AE5:AE200,0))/SUM(IFERROR(AE5:AE200,0))} -> 105.56591 | AC5: ='2025.07'!$C$59 -> 9.99 | AD5: ='2025.07'!$E$59 -> 105.0349 | AE5: ='2025.07'!$F$59 -> 0.09511124 | AF5: ='2025.07'!$A$55 -> 45866 | AG5: ='2025.07'!$B$55*-1 -> -10
A6: ='2025.08'!Q2 -> 2025.08 | B6: ='2025.08'!B59 -> 0 | C6: ='2025.08'!C59 -> 0 | D6: =D5+C6 -> 9.99 | E6: ='2025.08'!F59 -> 0 | F6: =F5+E6 -> 0.09511124 | G6: 105.77 | H6: =F6*G6 -> 10.059916 | I6: =H6-D6 -> 0.069915855 | J6: =(H6-D6)/D6 -> 0.0069985841 | K6: ='2025.08'!D59 -> 0 | L6: ='2025.08'!J59 -> 0 | M6: ='2025.08'!O59 -> 0 | AC6: ='2025.08'!$C$59 -> 0 | AD6: ='2025.08'!$E$59 -> 0.00 | AE6: ='2025.08'!$F$59 -> 0 | AF6: ='2025.09'!$A$55 -> 45908 | AG6: ='2025.09'!$B$55*-1 -> -10
A7: ='2025.09'!Q2 -> 2025.09 | B7: ='2025.09'!B59 -> 10 | C7: ='2025.09'!C59 -> 9.99 | D7: =D6+C7 -> 19.98 | E7: ='2025.09'!F59 -> 0.09415441 | F7: =F6+E7 -> 0.18926565 | G7: 108.89 | H7: =F7*G7 -> 20.609137 | I7: =H7-D7 -> 0.62913663 | J7: =(H7-D7)/D7 -> 0.03148832 | K7: ='2025.09'!D59 -> 0.01 | L7: ='2025.09'!J59 -> 0 | M7: ='2025.09'!O59 -> 0 | AC7: ='2025.09'!$C$59 -> 9.99 | AD7: ='2025.09'!$E$59 -> 106.10231 | AE7: ='2025.09'!$F$59 -> 0.09415441 | AF7: ='2025.11'!$H$55 -> 45965 | AG7: ='2025.11'!$I$55-'2025.11'!$J$55 -> 21.35
A8: ='2025.10'!Q2 -> 2025.10 | B8: ='2025.10'!B59 -> 0 | C8: ='2025.10'!C59 -> 0 | D8: =D7+C8 -> 19.98 | E8: ='2025.10'!F59 -> 0 | F8: =F7+E8 -> 0.18926565 | G8: 113.7 | H8: =F8*G8 -> 21.519504 | I8: =H8-D8 -> 1.5395044 | J8: =(H8-D8)/D8 -> 0.077052273 | K8: ='2025.10'!D59 -> 0 | L8: ='2025.10'!J59 -> 0 | M8: ='2025.10'!O59 -> 0 | AC8: ='2025.10'!$C$59 -> 0 | AD8: ='2025.10'!$E$59 -> 0.00 | AE8: ='2025.10'!$F$59 -> 0
A9: ='2025.11'!Q2 -> 2025.11 | B9: ='2025.11'!B59 -> 0 | C9: ='2025.11'!C59 -> 0 | D9: =D8+C9 -> 19.98 | E9: ='2025.11'!F59 -> 0 | F9: =F8+E9 -> 0.18926565 | G9: 112.91 | H9: =F9*G9 -> 21.369985 | I9: =H9-D9 -> 1.3899845 | J9: =(H9-D9)/D9 -> 0.069568796 | K9: ='2025.11'!D59 -> 0 | L9: ='2025.11'!J59 -> 0.02 | M9: ='2025.11'!O59 -> 0 | AC9: ='2025.11'!$C$59 -> 0 | AD9: ='2025.11'!$E$59 -> 0.00 | AE9: ='2025.11'!$F$59 -> 0

Sheet XDWT
A1: XDWT Xtrackers MSCI World Information Technology ETF (Acc)
A3: Data | B3: Suma, EUR | E3: Kiekis | G3: Mėnesio gale | K3: Mokesčiai | M3: Dividendai | O3: XDWT | P3: Įnešta | Q3: Kiekis | R3: Parduota | S3: Pelnas | V3: Mokesčiai | X3: Dividendai | Y3: Vid. Kaina | AC3: Suma | AD3: Kaina | AE3: Kiekis | AF3: Pirkimas/pardavimas
B4: Įnešta | C4: Mėn. Inv. | D4: Viso Inv. | E4: Mėnesio | F4: Viso | G4: Kaina | H4: Vertė gale | I4: Pelnas | J4: % | K4: Pirkimas | L4: Pardavimas | S4: Eur. | T4: % | U4: XIRR | V4: Pirkimas | W4: Pardavimas | AF4: Data | AG4: Suma
A5: ='2025.08'!Q2 -> 2025.08 | B5: ='2025.08'!B69 -> 20 | C5: ='2025.08'!C69 -> 19.99 | D5: =C5 -> 19.99 | E5: ='2025.08'!F69 -> 0.21645167 | F5: =E5 -> 0.21645167 | G5: 91.94 | H5: =F5*G5 -> 19.900567 | I5: =H5-D5 -> -0.08943346 | J5: =(H5-D5)/D5 -> -0.00447391 | K5: ='2025.08'!D69 -> 0.01 | L5: ='2025.08'!J69 -> 0 | M5: ='2025.08'!O69 -> 0 | O5: Viso: | P5: =SUM(B5:B44) -> 30 | Q5: =SUM(E5:E44) -> 0.31683311 | R5: ='2025.11'!I69-'2025.11'!J69 -> 32.52 | S5: =R5-P5 -> 2.52 | T5: =(R5-P5)/P5 -> 0.084 | U5: =XIRR(AG5:AG8,AF5:AF8) -> 0.59511161 | V5: =SUM(K5:K8) -> 0.01 | W5: =SUM(L5:L8) -> 0.03 | X5: =SUM(M5:M12) -> 0 | Y5: {=SUMPRODUCT(IFERROR(AD5:AD200,0),IFERROR(AE5:AE200,0))/SUM(IFERROR(AE5:AE200,0))} -> 94.655511 | AC5: ='2025.08'!$C$69 -> 19.99 | AD5: ='2025.08'!$E$69 -> 92.35318 | AE5: ='2025.08'!$F$69 -> 0.21645167 | AF5: ='2025.08'!$A$65 -> 45887 | AG5: ='2025.08'!$B$65*-1 -> -10
A6: ='2025.09'!Q2 -> 2025.09 | B6: ='2025.09'!B69 -> 0 | C6: ='2025.09'!C69 -> 0 | D6: =D5+C6 -> 19.99 | E6: ='2025.09'!F69 -> 0 | F6: =F5+E6 -> 0.21645167 | G6: 97.9 | H6: =F6*G6 -> 21.190618 | I6: =H6-D6 -> 1.2006185 | J6: =(H6-D6)/D6 -> 0.060060955 | K6: ='2025.09'!D69 -> 0 | L6: ='2025.09'!J69 -> 0 | M6: ='2025.09'!O69 -> 0 | AC6: ='2025.09'!$C$69 -> 0 | AD6: ='2025.09'!$E$69 -> 0.00 | AE6: ='2025.09'!$F$69 -> 0 | AF6: ='2025.08'!$A$66 -> 45889 | AG6: ='2025.08'!$B$66*-1 -> -10
A7: ='2025.10'!Q2 -> 2025.10 | B7: ='2025.10'!B69 -> 10 | C7: ='2025.10'!C69 -> 10 | D7: =D6+C7 -> 29.99 | E7: ='2025.10'!F69 -> 0.10038144 | F7: =F6+E7 -> 0.31683311 | G7: 106.65 | H7: =F7*G7 -> 33.790251 | I7: =H7-D7 -> 3.8002512 | J7: =(H7-D7)/D7 -> 0.12671728 | K7: ='2025.10'!D69 -> 0 | L7: ='2025.10'!J69 -> 0 | M7: ='2025.10'!O69 -> 0 | AC7: ='2025.10'!$C$69 -> 10 | AD7: ='2025.10'!$E$69 -> 99.620009 | AE7: ='2025.10'!$F$69 -> 0.10038144 | AF7: ='2025.10'!$A$65 -> 45940 | AG7: ='2025.10'!$B$65*-1 -> -10
A8: ='2025.11'!Q2 -> 2025.11 | B8: ='2025.11'!B69 -> 0 | C8: ='2025.11'!C69 -> 0 | D8: =D7+C8 -> 29.99 | E8: ='2025.11'!F69 -> 0 | F8: =F7+E8 -> 0.31683311 | G8: 102.74 | H8: =F8*G8 -> 32.551434 | I8: =H8-D8 -> 2.5614337 | J8: =(H8-D8)/D8 -> 0.085409594 | K8: ='2025.11'!D69 -> 0 | L8: ='2025.11'!J69 -> 0.03 | M8: ='2025.11'!O69 -> 0 | AC8: ='2025.11'!$C$69 -> 0 | AD8: ='2025.11'!$E$69 -> 0.00 | AE8: ='2025.11'!$F$69 -> 0 | AF8: ='2025.11'!$H$65 -> 45968 | AG8: ='2025.11'!$I$65-'2025.11'!$J$65 -> 32.52

Sheet XAIX
A1: XAIX Xtrackers Artificial Intelligence and Big Data ETF (Acc)
A3: Data | B3: Suma, EUR | E3: Kiekis | G3: Mėnesio gale | K3: Mokesčiai | M3: Dividendai | O3: XAIX | P3: Įnešta | Q3: Kiekis | R3: Parduota | S3: Pelnas | V3: Mokesčiai | X3: Dividendai | Y3: Vid. Kaina | AC3: Suma | AD3: Kaina | AE3: Kiekis | AF3: Pirkimas/pardavimas
B4: Įnešta | C4: Mėn. Inv. | D4: Viso Inv. | E4: Mėnesio | F4: Viso | G4: Kaina | H4: Vertė gale | I4: Pelnas | J4: % | K4: Pirkimas | L4: Pardavimas | S4: Eur. | T4: % | U4: XIRR | V4: Pirkimas | W4: Pardavimas | AF4: Data | AG4: Suma
A5: ='2025.08'!Q2 -> 2025.08 | B5: ='2025.08'!B79 -> 20 | C5: ='2025.08'!C79 -> 19.98 | D5: =C5 -> 19.98 | E5: ='2025.08'!F79 -> 0.14300145 | F5: =E5 -> 0.14300145 | G5: 139.58 | H5: =F5*G5 -> 19.960142 | I5: =H5-D5 -> -0.019857609 | J5: =(H5-D5)/D5 -> -0.00099387432 | K5: ='2025.08'!D79 -> 0.02 | L5: ='2025.08'!J79 -> 0 | M5: ='2025.08'!O79 -> 0 | O5: Viso: | P5: =SUM(B5:B45) -> 30 | Q5: =SUM(E5:E45) -> 0.20953934 | R5: ='2025.11'!I79-'2025.11'!J79 -> 32.61 | S5: =R5-P5 -> 2.61 | T5: =(R5-P5)/P5 -> 0.087 | U5: =XIRR(AG5:AG8,AF5:AF8) -> 0.62067788 | V5: =SUM(K5:K8) -> 0.03 | W5: =SUM(L5:L8) -> 0.03 | X5: =SUM(M5:M12) -> 0 | Y5: {=SUMPRODUCT(IFERROR(AD5:AD200,0),IFERROR(AE5:AE200,0))/SUM(IFERROR(AE5:AE200,0))} -> 143.02803 | AC5: ='2025.08'!$C$79 -> 19.98 | AD5: ='2025.08'!$E$79 -> 139.71886 | AE5: ='2025.08'!$F$79 -> 0.14300145 | AF5: ='2025.08'!$A$75 -> 45887 | AG5: ='2025.08'!$B$75*-1 -> -10
A6: ='2025.09'!Q2 -> 2025.09 | B6: ='2025.09'!B79 -> 0 | C6: ='2025.09'!C79 -> 0 | D6: =D5+C6 -> 19.98 | E6: ='2025.09'!F79 -> 0 | F6: =F5+E6 -> 0.14300145 | G6: 148.81 | H6: =F6*G6 -> 21.280046 | I6: =H6-D6 -> 1.3000458 | J6: =(H6-D6)/D6 -> 0.065067356 | K6: ='2025.09'!D79 -> 0 | L6: ='2025.09'!J79 -> 0 | M6: ='2025.09'!O79 -> 0 | AC6: ='2025.09'!$C$79 -> 0 | AD6: ='2025.09'!$E$79 -> 0.00 | AE6: ='2025.09'!$F$79 -> 0 | AF6: ='2025.08'!$A$76 -> 45889 | AG6: ='2025.08'!$B$76*-1 -> -10
A7: ='2025.10'!Q2 -> 2025.10 | B7: ='2025.10'!B79 -> 10 | C7: ='2025.10'!C79 -> 9.99 | D7: =D6+C7 -> 29.97 | E7: ='2025.10'!F79 -> 0.06653789 | F7: =F6+E7 -> 0.20953934 | G7: 160.88 | H7: =F7*G7 -> 33.710689 | I7: =H7-D7 -> 3.740689 | J7: =(H7-D7)/D7 -> 0.12481445 | K7: ='2025.10'!D79 -> 0.01 | L7: ='2025.10'!J79 -> 0 | M7: ='2025.10'!O79 -> 0 | AC7: ='2025.10'!$C$79 -> 9.99 | AD7: ='2025.10'!$E$79 -> 150.14002 | AE7: ='2025.10'!$F$79 -> 0.06653789 | AF7: ='2025.10'!$A$75 -> 45940 | AG7: ='2025.10'!$B$75*-1 -> -10
A8: ='2025.11'!Q2 -> 2025.11 | B8: ='2025.11'!B79 -> 0 | C8: ='2025.11'!C79 -> 0 | D8: =D7+C8 -> 29.97 | E8: ='2025.11'!F79 -> 0 | F8: =F7+E8 -> 0.20953934 | G8: 155.77 | H8: =F8*G8 -> 32.639943 | I8: =H8-D8 -> 2.669943 | J8: =(H8-D8)/D8 -> 0.089087187 | K8: ='2025.11'!D79 -> 0 | L8: ='2025.11'!J79 -> 0.03 | M8: ='2025.11'!O79 -> 0 | AC8: ='2025.11'!$C$79 -> 0 | AD8: ='2025.11'!$E$79 -> 0.00 | AE8: ='2025.11'!$F$79 -> 0 | AF8: ='2025.11'!$H$75 -> 45968 | AG8: ='2025.11'!$I$75-'2025.11'!$J$75 -> 32.61

Sheet JEQP
A1: JEQP JPM Nasdaq Equity Premium Income Active UCITS ETF - USD (Dist)
A3: Data | B3: Suma, EUR | E3: Kiekis | G3: Mėnesio gale | K3: Mokesčiai | M3: Dividendai | O3: SPYL | P3: Įnešta | Q3: Kiekis | R3: Parduota | S3: Pelnas | V3: Mokesčiai | X3: Dividendai | Y3: Vid. Kaina | AC3: Suma | AD3: Kaina | AE3: Kiekis | AF3: Pirkimas/pardavimas
B4: Įnešta | C4: Mėn. Inv. | D4: Viso Inv. | E4: Mėnesio | F4: Viso | G4: Kaina | H4: Vertė gale | I4: Pelnas | J4: % | K4: Pirkimas | L4: Pardavimas | S4: Eur. | T4: % | U4: XIRR | V4: Pirkimas | W4: Pardavimas | AF4: Data | AG4: Suma
A5: ='2025.11'!Q2 -> 2025.11 | B5: ='2025.11'!B99 -> 91.99 | C5: ='2025.11'!C99 -> 91.9 | D5: =C5 -> 91.9 | E5: ='2025.11'!F99 -> 4 | F5: =E5 -> 4 | G5: 22.8 | H5: =F5*G5 -> 91.2 | I5: =H5-D5 -> -0.7 | J5: =(H5-D5)/D5 -> -0.007616975 | K5: ='2025.11'!D99 -> 0.09 | L5: ='2025.11'!J99 -> 0 | M5: ='2025.11'!O99 -> 0 | O5: Viso: | P5: =SUM(B5:B45) -> 227.48 | Q5: =SUM(E5:E45) -> 10 | R5: ='2026.05'!I99-'2026.05'!J99 -> 234.6 | S5: =R5-P5+X5 -> 14.24 | T5: =(R5-P5+X5)/P5 -> 0.06259891 | U5: =XIRR(AG5:AG20,AF5:AF20) -> 0.19327208 | V5: =SUM(K5:K45) -> 0.17 | W5: =SUM(L5:L45) -> 0 | X5: =SUM(M5:M45) -> 7.12 | Y5: {=SUMPRODUCT(IFERROR(AD5:AD200,0),IFERROR(AE5:AE200,0))/SUM(IFERROR(AE5:AE200,0))} -> 22.732 | AC5: ='2025.11'!$C$99 -> 91.9 | AD5: ='2025.11'!$E$99 -> 22.9775 | AE5: ='2025.11'!$F$99 -> 4 | AF5: ='2025.11'!$A$95 -> 45972 | AG5: ='2025.11'!$B$95*-1 -> -23.14
A6: ='2025.12'!Q2 -> 2025.12 | B6: ='2025.12'!B99 -> 22.73 | C6: ='2025.12'!C99 -> 22.71 | D6: =C6+D5 -> 114.61 | E6: ='2025.12'!F99 -> 1 | F6: =F5+E6 -> 5 | G6: 22.69 | H6: =F6*G6 -> 113.45 | I6: =H6-D6 -> -1.16 | J6: =(H6-D6)/D6 -> -0.010121281 | K6: ='2025.12'!D99 -> 0.02 | L6: ='2025.12'!J99 -> 0 | M6: ='2025.12'!O99 -> 0.59 | AC6: ='2025.12'!$C$99 -> 22.71 | AD6: ='2025.12'!$E$99 -> 22.71 | AE6: ='2025.12'!$F$99 -> 1 | AF6: ='2025.11'!$A$96 -> 45973 | AG6: ='2025.11'!$B$96*-1 -> -46.6
A7: ='2026.01'!Q2 -> 2026.01 | B7: ='2026.01'!B99 -> 22.99 | C7: ='2026.01'!C99 -> 22.99 | D7: =C7+D6 -> 137.6 | E7: ='2026.01'!F99 -> 1 | F7: =F6+E7 -> 6 | G7: 22.62 | H7: =F7*G7 -> 135.72 | I7: =H7-D7 -> -1.88 | J7: =(H7-D7)/D7 -> -0.013662791 | K7: ='2026.01'!D99 -> 0 | L7: ='2026.01'!J99 -> 0 | M7: ='2026.01'!O99 -> 0.9 | AC7: ='2026.01'!$C$99 -> 22.99 | AD7: ='2026.01'!$E$99 -> 22.99 | AE7: ='2026.01'!$F$99 -> 1 | AF7: ='2025.11'!$A$97 -> 45979 | AG7: ='2025.11'!$B$97*-1 -> -22.25
A8: ='2026.02'!Q2 -> 2026.02 | B8: ='2026.02'!B99 -> 22.5 | C8: ='2026.02'!C99 -> 22.5 | D8: =C8+D7 -> 160.1 | E8: ='2026.02'!F99 -> 1 | F8: =F7+E8 -> 7 | G8: 22.04 | H8: =F8*G8 -> 154.28 | I8: =H8-D8 -> -5.82 | J8: =(H8-D8)/D8 -> -0.03635228 | K8: ='2026.02'!D99 -> 0 | L8: ='2026.02'!J99 -> 0 | M8: ='2026.02'!O99 -> 1.39 | AC8: ='2026.02'!$C$99 -> 22.5 | AD8: ='2026.02'!$E$99 -> 22.5 | AE8: ='2026.02'!$F$99 -> 1 | AF8: ='2025.12'!$A$95 -> 45992 | AG8: ='2025.12'!$B$95*-1 -> -22.73
A9: ='2026.03'!Q2 -> 2026.03 | B9: ='2026.03'!B99 -> 22.01 | C9: ='2026.03'!C99 -> 21.99 | D9: =C9+D8 -> 182.09 | E9: ='2026.03'!F99 -> 1 | F9: =F8+E9 -> 8 | G9: 21.68 | H9: =F9*G9 -> 173.44 | I9: =H9-D9 -> -8.65 | J9: =(H9-D9)/D9 -> -0.047503982 | K9: ='2026.03'!D99 -> 0.02 | L9: ='2026.03'!J99 -> 0 | M9: ='2026.03'!O99 -> 1.36 | AC9: ='2026.03'!$C$99 -> 21.99 | AD9: ='2026.03'!$E$99 -> 21.99 | AE9: ='2026.03'!$F$99 -> 1 | AF9: ='2025.12'!$N$95 -> 46000 | AG9: ='2025.12'!$O$95 -> 0.59
A10: ='2026.04'!Q2 -> 2026.04 | B10: ='2026.04'!B99 -> 22 | C10: ='2026.04'!C99 -> 21.98 | D10: =C10+D9 -> 204.07 | E10: ='2026.04'!F99 -> 1 | F10: =F9+E10 -> 9 | G10: 22.88 | H10: =F10*G10 -> 205.92 | I10: =H10-D10 -> 1.85 | J10: =(H10-D10)/D10 -> 0.0090655167 | K10: ='2026.04'!D99 -> 0.02 | L10: ='2026.04'!J99 -> 0 | M10: ='2026.04'!O99 -> 1.24 | AC10: ='2026.04'!$C$99 -> 21.98 | AD10: ='2026.04'!$E$99 -> 21.98 | AE10: ='2026.04'!$F$99 -> 1 | AF10: ='2026.01'!$A$95 -> 46024 | AG10: ='2026.01'!$B$95*-1 -> -22.99
A11: ='2026.05'!Q2 -> 2026.05 | B11: ='2026.05'!B99 -> 23.26 | C11: ='2026.05'!C99 -> 23.24 | D11: =C11+D10 -> 227.31 | E11: ='2026.05'!F99 -> 1 | F11: =F10+E11 -> 10 | G11: 23.46 | H11: =F11*G11 -> 234.6 | I11: =H11-D11 -> 7.29 | J11: =(H11-D11)/D11 -> 0.03207074 | K11: ='2026.05'!D99 -> 0.02 | L11: ='2026.05'!J99 -> 0 | M11: ='2026.05'!O99 -> 1.64 | AC11: ='2026.05'!$C$99 -> 23.24 | AD11: ='2026.05'!$E$99 -> 23.24 | AE11: ='2026.05'!$F$99 -> 1 | AF11: ='2026.01'!$N$95 -> 46042 | AG11: ='2026.01'!$O$95 -> 0.9
AF12: ='2026.02'!$A$95 -> 46055 | AG12: ='2026.02'!$B$95*-1 -> -22.5
AF13: ='2026.02'!$N$95 -> 46063 | AG13: ='2026.02'!$O$95 -> 1.39
AF14: ='2026.03'!$A$95 -> 46083 | AG14: ='2026.03'!$B$95*-1 -> -22.01
AF15: ='2026.03'!$N$95 -> 46091 | AG15: ='2026.03'!$O$95 -> 1.36
AF16: ='2026.04'!$A$95 -> 46113 | AG16: ='2026.04'!$B$95*-1 -> -22
AF17: ='2026.04'!$N$95 -> 46121 | AG17: ='2026.04'!$O$95 -> 1.24
AF18: ='2026.05'!$A$95 -> 46146 | AG18: ='2026.05'!$B$95*-1 -> -23.26
AF19: ='2026.05'!$N$95 -> 46155 | AG19: ='2026.05'!$O$95 -> 1.64
AF20: ='2026.05'!$H$95 -> 46157 | AG20: ='2026.05'!$I$95-'2026.05'!$J$95 -> 234.6

Sheet JGPI
A1: JGPI JPM Global Equity Premium Income Active UCITS ETF - USD (Dist)
A3: Data | B3: Suma, EUR | E3: Kiekis | G3: Mėnesio gale | K3: Mokesčiai | M3: Dividendai | O3: JGPI | P3: Įnešta | Q3: Kiekis | R3: Parduota | S3: Pelnas | V3: Mokesčiai | X3: Dividendai | Y3: Vid. Kaina | AC3: Suma | AD3: Kaina | AE3: Kiekis | AF3: Pirkimas/pardavimas
B4: Įnešta | C4: Mėn. Inv. | D4: Viso Inv. | E4: Mėnesio | F4: Viso | G4: Kaina | H4: Vertė gale | I4: Pelnas | J4: % | K4: Pirkimas | L4: Pardavimas | S4: Eur. | T4: % | U4: XIRR | V4: Pirkimas | W4: Pardavimas | AF4: Data | AG4: Suma
A5: ='2025.11'!Q2 -> 2025.11 | B5: ='2025.11'!B109 -> 92.72 | C5: ='2025.11'!C109 -> 92.63 | D5: =C5 -> 92.63 | E5: ='2025.11'!F109 -> 4 | F5: =E5 -> 4 | G5: 23.24 | H5: =F5*G5 -> 92.96 | I5: =H5-D5 -> 0.33 | J5: =(H5-D5)/D5 -> 0.0035625607 | K5: ='2025.11'!D109 -> 0.09 | L5: ='2025.11'!J109 -> 0 | M5: ='2025.11'!O109 -> 0 | O5: Viso: | P5: =SUM(B5:B45) -> 231.86 | Q5: =SUM(E5:E45) -> 10 | R5: ='2026.05'!I109-'2026.05'!J109 -> 224.06 | S5: =R5-P5+X5 -> -2.45 | T5: =(R5-P5+X5)/P5 -> -0.010566721 | U5: =XIRR(AG5:AG19,AF5:AF19) -> -0.029616496 | V5: =SUM(K5:K45) -> 0.21 | W5: =SUM(L5:L45) -> 0.22 | X5: =SUM(M5:M45) -> 5.35 | Y5: {=SUMPRODUCT(IFERROR(AD5:AD200,0),IFERROR(AE5:AE200,0))/SUM(IFERROR(AE5:AE200,0))} -> 23.166 | AC5: ='2025.11'!$C$109 -> 92.63 | AD5: ='2025.11'!$E$109 -> 23.16 | AE5: ='2025.11'!$F$109 -> 4 | AF5: ='2025.11'!$A$105 -> 45972 | AG5: ='2025.11'!$B$105*-1 -> -23.12
A6: ='2025.12'!Q2 -> 2025.12 | B6: ='2025.12'!B109 -> 23.21 | C6: ='2025.12'!C109 -> 23.19 | D6: =C6+D5 -> 115.82 | E6: ='2025.12'!F109 -> 1 | F6: =F5+E6 -> 5 | G6: 22.95 | H6: =F6*G6 -> 114.75 | I6: =H6-D6 -> -1.07 | J6: =(H6-D6)/D6 -> -0.0092384735 | K6: ='2025.12'!D109 -> 0.02 | L6: ='2025.12'!J109 -> 0 | M6: ='2025.12'!O109 -> 0.54 | AC6: ='2025.12'!$C$109 -> 23.19 | AD6: ='2025.12'!$E$109 -> 23.19 | AE6: ='2025.12'!$F$109 -> 1 | AF6: ='2025.11'!$A$106 -> 45973 | AG6: ='2025.11'!$B$106*-1 -> -69.6
A7: ='2026.01'!Q2 -> 2026.01 | B7: ='2026.01'!B109 -> 23.11 | C7: ='2026.01'!C109 -> 23.09 | D7: =C7+D6 -> 138.91 | E7: ='2026.01'!F109 -> 1 | F7: =F6+E7 -> 6 | G7: 22.82 | H7: =F7*G7 -> 136.92 | I7: =H7-D7 -> -1.99 | J7: =(H7-D7)/D7 -> -0.014325822 | K7: ='2026.01'!D109 -> 0.02 | L7: ='2026.01'!J109 -> 0 | M7: ='2026.01'!O109 -> 0.67 | AC7: ='2026.01'!$C$109 -> 23.09 | AD7: ='2026.01'!$E$109 -> 23.09 | AE7: ='2026.01'!$F$109 -> 1 | AF7: ='2025.12'!$A$105 -> 45992 | AG7: ='2025.12'!$B$105*-1 -> -23.21
A8: ='2026.02'!Q2 -> 2026.02 | B8: ='2026.02'!B109 -> 22.82 | C8: ='2026.02'!C109 -> 22.8 | D8: =C8+D7 -> 161.71 | E8: ='2026.02'!F109 -> 1 | F8: =F7+E8 -> 7 | G8: 23.89 | H8: =F8*G8 -> 167.23 | I8: =H8-D8 -> 5.52 | J8: =(H8-D8)/D8 -> 0.03413518 | K8: ='2026.02'!D109 -> 0.02 | L8: ='2026.02'!J109 -> 0 | M8: ='2026.02'!O109 -> 0.81 | AC8: ='2026.02'!$C$109 -> 22.8 | AD8: ='2026.02'!$E$109 -> 22.8 | AE8: ='2026.02'!$F$109 -> 1 | AF8: ='2025.12'!$N$105 -> 46000 | AG8: ='2025.12'!$O$105 -> 0.54
A9: ='2026.03'!Q2 -> 2026.03 | B9: ='2026.03'!B109 -> 24.01 | C9: ='2026.03'!C109 -> 23.99 | D9: =C9+D8 -> 185.7 | E9: ='2026.03'!F109 -> 1 | F9: =F8+E9 -> 8 | G9: 23.22 | H9: =F9*G9 -> 185.76 | I9: =H9-D9 -> 0.06 | J9: =(H9-D9)/D9 -> 0.00032310178 | K9: ='2026.03'!D109 -> 0.02 | L9: ='2026.03'!J109 -> 0 | M9: ='2026.03'!O109 -> 0.95 | AC9: ='2026.03'!$C$109 -> 23.99 | AD9: ='2026.03'!$E$109 -> 23.99 | AE9: ='2026.03'!$F$109 -> 1 | AF9: ='2026.01'!$A$105 -> 46024 | AG9: ='2026.01'!$B$105*-1 -> -23.11
A10: ='2026.04'!Q2 -> 2026.04 | B10: ='2026.04'!B109 -> 23.5 | C10: ='2026.04'!C109 -> 23.48 | D10: =C10+D9 -> 209.18 | E10: ='2026.04'!F109 -> 1 | F10: =F9+E10 -> 9 | G10: 22.3 | H10: =F10*G10 -> 200.7 | I10: =H10-D10 -> -8.48 | J10: =(H10-D10)/D10 -> -0.040539248 | K10: ='2026.04'!D109 -> 0.02 | L10: ='2026.04'!J109 -> 0 | M10: ='2026.04'!O109 -> 0.92 | AC10: ='2026.04'!$C$109 -> 23.48 | AD10: ='2026.04'!$E$109 -> 23.48 | AE10: ='2026.04'!$F$109 -> 1 | AF10: ='2026.01'!$N$105 -> 46042 | AG10: ='2026.01'!$O$105 -> 0.67
A11: ='2026.05'!Q2 -> 2026.05 | B11: ='2026.05'!B109 -> 22.49 | C11: ='2026.05'!C109 -> 22.47 | D11: =C11+D10 -> 231.65 | E11: ='2026.05'!F109 -> 1 | F11: =F10+E11 -> 10 | G11: 22.43 | H11: =F11*G11 -> 224.3 | I11: =H11-D11 -> -7.35 | J11: =(H11-D11)/D11 -> -0.031728901 | K11: ='2026.05'!D109 -> 0.02 | L11: ='2026.05'!J109 -> 0.22 | M11: ='2026.05'!O109 -> 1.46 | AC11: ='2026.05'!$C$109 -> 22.47 | AD11: ='2026.05'!$E$109 -> 22.47 | AE11: ='2026.05'!$F$109 -> 1 | AF11: ='2026.02'!$A$105 -> 46055 | AG11: ='2026.02'!$B$105*-1 -> -22.82
AF12: ='2026.02'!$N$105 -> 46063 | AG12: ='2026.02'!$O$105 -> 0.81
AF13: ='2026.03'!$A$105 -> 46083 | AG13: ='2026.03'!$B$105*-1 -> -24.01
AF14: ='2026.03'!$N$105 -> 46091 | AG14: ='2026.03'!$O$105 -> 0.95
AF15: ='2026.04'!$A$105 -> 46113 | AG15: ='2026.04'!$B$105*-1 -> -23.5
AF16: ='2026.04'!$N$105 -> 46121 | AG16: ='2026.04'!$O$105 -> 0.92
AF17: ='2026.05'!$A$105 -> 46146 | AG17: ='2026.05'!$B$105*-1 -> -22.49
AF18: ='2026.05'!$N$105 -> 46155 | AG18: ='2026.05'!$O$105 -> 1.46
AF19: ='2026.05'!$H$105 -> 46161 | AG19: ='2026.05'!$I$105-'2026.05'!$J$105 -> 224.06

Sheet SPYL
A1: SPYL SPDR S&P 500 UCITS (Acc)
A3: Data | B3: Suma, EUR | E3: Kiekis | G3: Mėnesio gale | K3: Mokesčiai | M3: Dividendai | O3: SPYL | P3: Įnešta | Q3: Kiekis | R3: Parduota | S3: Pelnas | V3: Mokesčiai | X3: Dividendai | Y3: Vid. Kaina | AC3: Suma | AD3: Kaina | AE3: Kiekis | AF3: Pirkimas/pardavimas
B4: Įnešta | C4: Mėn. Inv. | D4: Viso Inv. | E4: Mėnesio | F4: Viso | G4: Kaina | H4: Vertė gale | I4: Pelnas | J4: % | K4: Pirkimas | L4: Pardavimas | S4: Eur. | T4: % | U4: XIRR | V4: Pirkimas | W4: Pardavimas | AF4: Data | AG4: Suma
A5: ='2025.10'!Q2 -> 2025.10 | B5: ='2025.10'!B89 -> 10 | C5: ='2025.10'!C89 -> 9.99 | D5: =C5 -> 9.99 | E5: ='2025.10'!F89 -> 0.71022323 | F5: =E5 -> 0.71022323 | G5: 14.56 | H5: =F5*G5 -> 10.34085 | I5: =H5-D5 -> 0.35085023 | J5: =(H5-D5)/D5 -> 0.035120143 | K5: ='2025.10'!D89 -> 0.01 | L5: ='2025.10'!J89 -> 0 | M5: ='2025.10'!O89 -> 0 | O5: Viso: | P5: =SUM(B5:B200) -> 988.28 | Q5: =SUM(E5:E200) -> 65 | R5: 0 | S5: =R5-P5+X5 -> -988.28 | T5: =(R5-P5+X5)/P5 -> -1 | U5: =XIRR(AG5:AG200,AF5:AF200) -> 0.22250761 | V5: =SUM(K5:K200) -> 0.36 | W5: =SUM(L5:L200) -> 0 | X5: =SUM(M5:M200) -> 0 | Y5: {=SUMPRODUCT(IFERROR(AD5:AD200,0),IFERROR(AE5:AE200,0))/SUM(IFERROR(AE5:AE200,0))} -> 15.198769 | AC5: ='2025.10'!$C$89 -> 9.99 | AD5: ='2025.10'!$E$89 -> 14.066 | AE5: ='2025.10'!$F$89 -> 0.71022323 | AF5: ='2025.10'!$A$85 -> 45943 | AG5: ='2025.10'!$B$85*-1 -> -10
A6: ='2025.11'!Q2 -> 2025.11 | B6: ='2025.11'!B89 -> 163.31 | C6: ='2025.11'!C89 -> 163.15 | D6: =C6+D5 -> 173.14 | E6: ='2025.11'!F89 -> 11.218734 | F6: =F5+E6 -> 11.928957 | G6: 14.49 | H6: =F6*G6 -> 172.85058 | I6: =H6-D6 -> -0.28941582 | J6: =(H6-D6)/D6 -> -0.0016715711 | K6: ='2025.11'!D89 -> 0.16 | L6: ='2025.11'!J89 -> 0 | M6: ='2025.11'!O89 -> 0 | AC6: ='2025.11'!$C$89 -> 163.15 | AD6: ='2025.11'!$E$89 -> 14.54264 | AE6: ='2025.11'!$F$89 -> 11.218734 | AF6: ='2025.11'!$A$85 -> 45965 | AG6: ='2025.11'!$B$85*-1 -> -10
A7: ='2025.12'!Q2 -> 2025.12 | B7: ='2025.12'!B89 -> 15.47 | C7: ='2025.12'!C89 -> 15.45 | D7: =C7+D6 -> 188.59 | E7: ='2025.12'!F89 -> 1.0710432 | F7: =F6+E7 -> 13 | G7: 14.44 | H7: =F7*G7 -> 187.72 | I7: =H7-D7 -> -0.87 | J7: =(H7-D7)/D7 -> -0.004613182 | K7: ='2025.12'!D89 -> 0.02 | L7: ='2025.12'!J89 -> 0 | M7: ='2025.12'!O89 -> 0 | AC7: ='2025.12'!$C$89 -> 15.45 | AD7: ='2025.12'!$E$89 -> 14.425189 | AE7: ='2025.12'!$F$89 -> 1.0710432 | AF7: ='2025.11'!$A$86 -> 45965 | AG7: ='2025.11'!$B$86*-1 -> -21.35
A8: ='2026.01'!Q2 -> 2026.01 | B8: ='2026.01'!B89 -> 43.42 | C8: ='2026.01'!C89 -> 43.38 | D8: =C8+D7 -> 231.97 | E8: ='2026.01'!F89 -> 3 | F8: =F7+E8 -> 16 | G8: 14.4 | H8: =F8*G8 -> 230.4 | I8: =H8-D8 -> -1.57 | J8: =(H8-D8)/D8 -> -0.0067681166 | K8: ='2026.01'!D89 -> 0.04 | L8: ='2026.01'!J89 -> 0 | M8: ='2026.01'!O89 -> 0 | AC8: ='2026.01'!$C$89 -> 43.38 | AD8: ='2026.01'!$E$89 -> 14.46 | AE8: ='2026.01'!$F$89 -> 3 | AF8: ='2025.11'!$A$87 -> 45968 | AG8: ='2025.11'!$B$87*-1 -> -24.74
A9: ='2026.02'!Q2 -> 2026.02 | B9: ='2026.02'!B89 -> 57.19 | C9: ='2026.02'!C89 -> 57.13 | D9: =C9+D8 -> 289.1 | E9: ='2026.02'!F89 -> 4 | F9: =F8+E9 -> 20 | G9: 14.33 | H9: =F9*G9 -> 286.6 | I9: =H9-D9 -> -2.5 | J9: =(H9-D9)/D9 -> -0.0086475268 | K9: ='2026.02'!D89 -> 0.06 | L9: ='2026.02'!J89 -> 0 | M9: ='2026.02'!O89 -> 0 | AC9: ='2026.02'!$C$89 -> 57.13 | AD9: ='2026.02'!$E$89 -> 14.2825 | AE9: ='2026.02'!$F$89 -> 4 | AF9: ='2025.11'!$A$88 -> 45973 | AG9: ='2025.11'!$B$88*-1 -> -107.22
A10: ='2026.03'!Q2 -> 2026.03 | B10: ='2026.03'!B89 -> 71.06 | C10: ='2026.03'!C89 -> 71.06 | D10: =C10+D9 -> 360.16 | E10: ='2026.03'!F89 -> 5 | F10: =F9+E10 -> 25 | G10: 13.93 | H10: =F10*G10 -> 348.25 | I10: =H10-D10 -> -11.91 | J10: =(H10-D10)/D10 -> -0.033068636 | K10: ='2026.03'!D89 -> 0 | L10: ='2026.03'!J89 -> 0 | M10: ='2026.03'!O89 -> 0 | AC10: ='2026.03'!$C$89 -> 71.06 | AD10: ='2026.03'!$E$89 -> 14.212 | AE10: ='2026.03'!$F$89 -> 5 | AF10: ='2025.12'!$A$85 -> 45992 | AG10: ='2025.12'!$B$85*-1 -> -15.47
A11: ='2026.04'!Q2 -> 2026.04 | B11: ='2026.04'!B89 -> 84.26 | C11: ='2026.04'!C89 -> 84.26 | D11: =C11+D10 -> 444.42 | E11: ='2026.04'!F89 -> 6 | F11: =F10+E11 -> 31 | G11: 15.16 | H11: =F11*G11 -> 469.96 | I11: =H11-D11 -> 25.54 | J11: =(H11-D11)/D11 -> 0.057468161 | K11: ='2026.04'!D89 -> 0 | L11: ='2026.04'!J89 -> 0 | M11: ='2026.04'!O89 -> 0 | AC11: ='2026.04'!$C$89 -> 84.26 | AD11: ='2026.04'!$E$89 -> 14.043333 | AE11: ='2026.04'!$F$89 -> 6 | AF11: ='2026.01'!$A$85 -> 46024 | AG11: ='2026.01'!$B$85*-1 -> -43.42
A12: ='2026.05'!$Q$2 -> 2026.05 | B12: ='2026.05'!$B$89 -> 76.46 | C12: ='2026.05'!$C$89 -> 76.46 | D12: =C12+D11 -> 520.88 | E12: ='2026.05'!$F$89 -> 5 | F12: =F11+E12 -> 36 | G12: 16.048 | H12: =F12*G12 -> 577.728 | I12: =H12-D12 -> 56.848 | J12: =(H12-D12)/D12 -> 0.10913838 | K12: ='2026.05'!$D$89 -> 0 | L12: ='2026.05'!$J$89 -> 0 | M12: ='2026.05'!$O$89 -> 0 | AC12: ='2026.05'!$C$89 -> 76.46 | AD12: ='2026.05'!$E$89 -> 15.292 | AE12: ='2026.05'!$F$89 -> 5 | AF12: ='2026.02'!$A$85 -> 46055 | AG12: ='2026.02'!$B$85*-1 -> -57.19
A13: ='2026.06'!$Q$2 -> 2026.06 | B13: ='2026.06'!$B$89 -> 288.31 | C13: ='2026.06'!$C$89 -> 288.29 | D13: =C13+D12 -> 809.17 | E13: ='2026.06'!$F$89 -> 18 | F13: =F12+E13 -> 54 | G13: 16.2008 | H13: =F13*G13 -> 874.8432 | I13: =H13-D13 -> 65.6732 | J13: =(H13-D13)/D13 -> 0.08116119 | K13: ='2026.06'!$D$89 -> 0.02 | L13: ='2026.06'!$J$89 -> 0 | M13: ='2026.06'!$O$89 -> 0 | AC13: ='2026.06'!$C$89 -> 288.29 | AD13: ='2026.06'!$E$89 -> 16.016111 | AE13: ='2026.06'!$F$89 -> 18 | AF13: ='2026.03'!$A$85 -> 46083 | AG13: ='2026.03'!$B$85*-1 -> -71.06
A14: ='2026.07'!$Q$2 -> 2026.07 | B14: ='2026.07'!$B$89 -> 48.65 | C14: ='2026.07'!$C$89 -> 48.6 | D14: =C14+D13 -> 857.77 | E14: ='2026.07'!$F$89 -> 3 | F14: =F13+E14 -> 57 | G14: 16.06285 | H14: =F14*G14 -> 915.58245 | I14: =H14-D14 -> 57.81245 | J14: =(H14-D14)/D14 -> 0.067398545 | K14: ='2026.07'!$D$89 -> 0.05 | L14: ='2026.07'!$J$89 -> 0 | M14: ='2026.07'!$O$89 -> 0 | AC14: ='2026.07'!$C$89 -> 48.6 | AD14: ='2026.07'!$E$89 -> 16.2 | AE14: ='2026.07'!$F$89 -> 3 | AF14: ='2026.04'!$A$85 -> 46113 | AG14: ='2026.04'!$B$85*-1 -> -84.26
A15: ='2026.08'!$Q$2 -> 2026.08 | B15: ='2026.08'!$B$89 -> 64.83 | C15: ='2026.08'!$C$89 -> 64.83 | D15: =C15+D14 -> 922.6 | E15: ='2026.08'!$F$89 -> 4 | F15: =F14+E15 -> 61 | G15: 16.3913 | H15: =F15*G15 -> 999.8693 | I15: =H15-D15 -> 77.2693 | J15: =(H15-D15)/D15 -> 0.08375168 | K15: ='2026.08'!$D$89 -> 0 | L15: ='2026.08'!$J$89 -> 0 | M15: ='2026.08'!$O$89 -> 0 | AC15: ='2026.08'!$C$89 -> 64.83 | AD15: ='2026.08'!$E$89 -> 16.2075 | AE15: ='2026.08'!$F$89 -> 4 | AF15: ='2026.05'!$A$85 -> 46146 | AG15: ='2026.05'!$B$85*-1 -> -76.46
A16: ='2026.09'!$Q$2 -> 2026.09 | B16: ='2026.09'!$B$89 -> 65.32 | C16: ='2026.09'!$C$89 -> 65.32 | D16: =C16+D15 -> 987.92 | E16: ='2026.09'!$F$89 -> 4 | F16: =F15+E16 -> 65 | G16: 16.7368 | H16: =F16*G16 -> 1087.892 | I16: =H16-D16 -> 99.972 | J16: =(H16-D16)/D16 -> 0.10119443 | K16: ='2026.09'!$D$89 -> 0 | L16: ='2026.09'!$J$89 -> 0 | M16: ='2026.09'!$O$89 -> 0 | AC16: ='2026.09'!$C$89 -> 65.32 | AD16: ='2026.09'!$E$89 -> 16.33 | AE16: ='2026.09'!$F$89 -> 4 | AF16: ='2026.06'!$A$85 -> 46175 | AG16: ='2026.06'!$B$85*-1 -> -16.14
AF17: ='2026.06'!$A$86 -> 46190 | AG17: ='2026.06'!$B$86*-1 -> -272.17
AF18: ='2026.07'!$A$85 -> 46205 | AG18: ='2026.07'!$B$85*-1 -> -48.65
AF19: ='2026.08'!$A$85 -> 46237 | AG19: ='2026.08'!$B$85*-1 -> -64.83
AF20: ='2026.09'!$A$85 -> 46267 | AG20: ='2026.09'!$B$85*-1 -> -65.32
AF200: =TODAY() -> 46296 | AG200: {=LOOKUP(2,1/(H:H>0),H:H)} -> 1087.892

Sheet EXUS
A1: EXUS Xtrackers MSCI World ex USA UCITS ETF 1C 1C
A3: Data | B3: Suma, EUR | E3: Kiekis | G3: Mėnesio gale | K3: Mokesčiai | M3: Dividendai | O3: EXUS | P3: Įnešta | Q3: Kiekis | R3: Parduota | S3: Pelnas | V3: Mokesčiai | X3: Dividendai | Y3: Vid. Kaina | AC3: Suma | AD3: Kaina | AE3: Kiekis | AF3: Pirkimas/pardavimas
B4: Įnešta | C4: Mėn. Inv. | D4: Viso Inv. | E4: Mėnesio | F4: Viso | G4: Kaina | H4: Vertė gale | I4: Pelnas | J4: % | K4: Pirkimas | L4: Pardavimas | S4: Eur. | T4: % | U4: XIRR | V4: Pirkimas | W4: Pardavimas | AF4: Data | AG4: Suma
