Workbook

Sheet Apžvalga
A1: Data | B1: Viso: | D1: Mėnesio gale | AL1: Dividendai | AM1: Mokestis
B2: Inešta | C2: Investuota | D2: Gryni | E2: XDWI | F2: WELK | G2: PRAR | H2: LKOR | I2: QDV7 | J2: AMEL | K2: 79U0 | L2: LYTR | M2: PRAJ | N2: LEMA | O2: AEYH | P2: EMBH | Q2: LYMS | R2: EBUY | S2: TRDE | T2: PRAC | U2: LYP6 | V2: UBUD | W2: 2B72 | X2: LYP5 | Y2: LGQK | Z2: XDWT | AA2: IS3K | AB2: QDVY | AC2: IBCD | AD2: IS3Q | AE2: IUSU | AF2: EXI2 | AG2: DBXJ | AH2: Viso | AI2: Vertė | AJ2: Pelnas | AK2: %
A3: ='2024.02'!A1 -> 2024.02 | B3: ='2024.02'!B9 -> 100 | C3: ='2024.02'!C9 -> 98 | D3: =Cash!B2 -> 2 | E3: 0 | F3: 0 | G3: 0 | H3: 0 | I3: 0 | J3: 0 | K3: 0 | L3: 0 | M3: 0 | N3: 0 | O3: 0 | P3: 0 | Q3: 0 | R3: 0 | S3: 0 | T3: 0 | U3: 0 | V3: 0 | W3: 0 | X3: 0 | Y3: 0 | Z3: =XDWT!G5 -> 9.9699821 | AA3: =IS3K!G5 -> 15.089491 | AB3: =QDVY!G5 -> 12.117869 | AC3: =IBCD!G5 -> 10.979773 | AD3: =IS3Q!G5 -> 19.938859 | AE3: =IUSU!G5 -> 10.030405 | AF3: ='EXI2'!G5 -> 14.890466 | AG3: =DBXJ!G5 -> 5.0200898 | AH3: =SUM(Z3:AG3) -> 98.036936 | AI3: =AH3+D3 -> 100.03694 | AJ3: =AI3-B3 -> 0.036935575 | AK3: =AJ3/B3 -> 0.00036935575 | AL3: ='2024.02'!E9 -> 0 | AM3: ='2024.02'!F9 -> 0
A4: ='2024.03'!A1 -> 2024.03 | B4: =B3+'2024.03'!B9 -> 100 | C4: =C3+'2024.03'!$C$9-'2024.03'!$C$9+'2024.03'!$C$9 -> 98 | D4: =Cash!B3 -> 1.95 | E4: 0 | F4: 0 | G4: 0 | H4: 0 | I4: 0 | J4: 0 | K4: 0 | L4: 0 | M4: 0 | N4: 0 | O4: 0 | P4: 0 | Q4: 0 | R4: 0 | S4: 0 | T4: 0 | U4: 0 | V4: 0 | W4: 0 | X4: 0 | Y4: 0 | Z4: =XDWT!G6 -> 10.200573 | AA4: =IS3K!G6 -> 15.089491 | AB4: =QDVY!G6 -> 12.194242 | AC4: =IBCD!G6 -> 11.080088 | AD4: =IS3Q!G6 -> 20.570652 | AE4: =IUSU!G6 -> 9.869973 | AF4: ='EXI2'!G6 -> 15.389452 | AG4: =DBXJ!G6 -> 5.1897103 | AH4: =SUM(Z4:AG4) -> 99.584181 | AI4: =AH4+D4 -> 101.53418 | AJ4: =AI4-B4 -> 1.5341814 | AK4: =AJ4/B4 -> 0.015341814 | AL4: ='2024.03'!E9 -> 0.01 | AM4: ='2024.03'!F9 -> 0.06
A5: ='2024.04'!A1 -> 2024.04 | B5: =B4+'2024.04'!B9 -> 100 | C5: =C4+'2024.04'!C9 -> 98 | D5: =Cash!B4 -> 2.23 | E5: 0 | F5: 0 | G5: 0 | H5: 0 | I5: 0 | J5: 0 | K5: 0 | L5: 0 | M5: 0 | N5: 0 | O5: 0 | P5: 0 | Q5: 0 | R5: 0 | S5: 0 | T5: 0 | U5: 0 | V5: 0 | W5: 0 | X5: 0 | Y5: 0 | Z5: =XDWT!G7 -> 9.7898757 | AA5: =IS3K!G7 -> 15.340421 | AB5: =QDVY!G7 -> 12.168785 | AC5: =IBCD!G7 -> 10.789642 | AD5: =IS3Q!G7 -> 20.01019 | AE5: =IUSU!G7 -> 9.9299241 | AF5: ='EXI2'!G7 -> 15.129817 | AG5: =DBXJ!G7 -> 4.9698821 | AH5: =SUM(Z5:AG5) -> 98.128537 | AI5: =AH5+D5 -> 100.35854 | AJ5: =AI5-B5 -> 0.35853669 | AK5: =AJ5/B5 -> 0.0035853669 | AL5: ='2024.04'!E9 -> 0.33 | AM5: ='2024.04'!F9 -> 0.05
A6: ='2024.05'!A1 -> 2024.05 | B6: =B5+'2024.05'!B9 -> 100 | C6: =C5+'2024.05'!C9 -> 98 | D6: =Cash!B5 -> 2.19 | E6: 0 | F6: 0 | G6: 0 | H6: 0 | I6: 0 | J6: 0 | K6: 0 | L6: 0 | M6: 0 | N6: 0 | O6: 0 | P6: 0 | Q6: 0 | R6: 0 | S6: 0 | T6: 0 | U6: 0 | V6: 0 | W6: 0 | X6: 0 | Y6: 0 | Z6: =XDWT!G8 -> 10.230591 | AA6: =IS3K!G8 -> 15.209338 | AB6: =QDVY!G8 -> 11.710546 | AC6: =IBCD!G8 -> 10.909786 | AD6: =IS3Q!G8 -> 20.591032 | AE6: =IUSU!G8 -> 9.8497079 | AF6: ='EXI2'!G8 -> 15.470588 | AG6: =DBXJ!G8 -> 4.9800593 | AH6: =SUM(Z6:AG6) -> 98.951648 | AI6: =AH6+D6 -> 101.14165 | AJ6: =AI6-B6 -> 1.1416485 | AK6: =AJ6/B6 -> 0.011416485 | AL6: ='2024.05'!E9 -> 0 | AM6: ='2024.05'!F9 -> 0.04
A7: ='2024.06'!A1 -> 2024.06 | B7: =B6+'2024.06'!B9 -> 100 | C7: =C6+'2024.06'!C9 -> 98 | D7: =Cash!B6 -> 3 | E7: 0 | F7: 0 | G7: 0 | H7: 0 | I7: 0 | J7: 0 | K7: 0 | L7: 0 | M7: 0 | N7: 0 | O7: 0 | P7: 0 | Q7: 0 | R7: 0 | S7: 0 | T7: 0 | U7: 0 | V7: 0 | W7: 0 | X7: 0 | Y7: 0 | Z7: =XDWT!G9 -> 11.499522 | AA7: =IS3K!G9 -> 15.05953 | AB7: =QDVY!G9 -> 11.88875 | AC7: =IBCD!G9 -> 11.02993 | AD7: =IS3Q!G9 -> 21.480978 | AE7: =IUSU!G9 -> 10.049826 | AF7: ='EXI2'!G9 -> 16.819472 | AG7: =DBXJ!G9 -> 5.0397658 | AH7: =SUM(Z7:AG7) -> 102.86777 | AI7: =AH7+D7 -> 105.86777 | AJ7: =AI7-B7 -> 5.8677742 | AK7: =AJ7/B7 -> 0.058677742 | AL7: ='2024.06'!E9 -> 0.86 | AM7: ='2024.06'!F9 -> 0.05
A8: ='2024.07'!A1 -> 2024.07 | B8: =B7+'2024.07'!B9 -> 100 | C8: =C7+'2024.07'!C9 -> 98.93 | D8: =Cash!B7 -> 2.15 | E8: 0 | F8: 0 | G8: 0 | H8: 0 | I8: 0 | J8: 0 | K8: 0 | L8: 0 | M8: 0 | N8: 0 | O8: 0 | P8: 0 | Q8: 0 | R8: 0 | S8: 0 | T8: 0 | U8: 0 | V8: 0 | W8: 0 | X8: 0 | Y8: 0 | Z8: =XDWT!G10 -> 11.080638 | AA8: =IS3K!G10 -> 15.079411 | AB8: =QDVY!G10 -> 12.839783 | AC8: =IBCD!G10 -> 11.130245 | AD8: =IS3Q!G10 -> 21.379076 | AE8: =IUSU!G10 -> 10.039694 | AF8: ='EXI2'!G10 -> 16.519269 | AG8: =DBXJ!G10 -> 5.1998876 | AH8: =SUM(Z8:AG8) -> 103.268 | AI8: =AH8+D8 -> 105.418 | AJ8: =AI8-B8 -> 5.4180032 | AK8: =AJ8/B8 -> 0.054180032 | AL8: ='2024.07'!E9 -> 0.13 | AM8: ='2024.07'!F9 -> 0.05
A9: ='2024.08'!A1 -> 2024.08 | B9: =B8+'2024.08'!B9 -> 100 | C9: =C8+'2024.08'!C9 -> 98.93 | D9: =Cash!B8 -> 2.1 | E9: 0 | F9: 0 | G9: 0 | H9: 0 | I9: 0 | J9: 0 | K9: 0 | L9: 0 | M9: 0 | N9: 0 | O9: 0 | P9: 0 | Q9: 0 | R9: 0 | S9: 0 | T9: 0 | U9: 0 | V9: 0 | W9: 0 | X9: 0 | Y9: 0 | Z9: =XDWT!G11 -> 10.949652 | AA9: =IS3K!G11 -> 14.939542 | AB9: =QDVY!G11 -> 12.405456 | AC9: =IBCD!G11 -> 11.060258 | AD9: =IS3Q!G11 -> 21.599864 | AE9: =IUSU!G11 -> 9.9197915 | AF9: ='EXI2'!G11 -> 16.34077 | AG9: =DBXJ!G11 -> 5.1598571 | AH9: =SUM(Z9:AG9) -> 102.37519 | AI9: =AH9+D9 -> 104.47519 | AJ9: =AI9-B9 -> 4.4751904 | AK9: =AJ9/B9 -> 0.044751904 | AL9: ='2024.08'!E9 -> 0 | AM9: ='2024.08'!F9 -> 0.05
A10: ='2024.09'!A1 -> 2024.09 | B10: =B9+'2024.09'!B9 -> 100 | C10: =C9+'2024.09'!C9 -> 98.93 | D10: =Cash!B9 -> 2.39 | E10: 0 | F10: 0 | G10: 0 | H10: 0 | I10: 0 | J10: 0 | K10: 0 | L10: 0 | M10: 0 | N10: 0 | O10: 0 | P10: 0 | Q10: 0 | R10: 0 | S10: 0 | T10: 0 | U10: 0 | V10: 0 | W10: 0 | X10: 0 | Y10: 0 | Z10: =XDWT!G12 -> 11.080638 | AA10: =IS3K!G12 -> 15.009476 | AB10: =QDVY!G12 -> 12.378311 | AC10: =IBCD!G12 -> 11.019432 | AD10: =IS3Q!G12 -> 21.599864 | AE10: =IUSU!G12 -> 9.7399383 | AF10: ='EXI2'!G12 -> 16.440162 | AG10: =DBXJ!G12 -> 5.0797962 | AH10: =SUM(Z10:AG10) -> 102.34762 | AI10: =AH10+D10 -> 104.73762 | AJ10: =AI10-B10 -> 4.7376178 | AK10: =AJ10/B10 -> 0.047376178 | AL10: ='2024.09'!E9 -> 0.34 | AM10: ='2024.09'!F9 -> 0.05
A11: ='2024.10'!A1 -> 2024.10 | B11: =B10+'2024.10'!B9 -> 100 | C11: =C10+'2024.10'!C9 -> 98.93 | D11: =Cash!B10 -> 2.34 | E11: 0 | F11: 0 | G11: 0 | H11: 0 | I11: 0 | J11: 0 | K11: 0 | L11: 0 | M11: 0 | N11: 0 | O11: 0 | P11: 0 | Q11: 0 | R11: 0 | S11: 0 | T11: 0 | U11: 0 | V11: 0 | W11: 0 | X11: 0 | Y11: 0 | Z11: =XDWT!G13 -> 11.330331 | AA11: =IS3K!G13 -> 15.510359 | AB11: =QDVY!G13 -> 12.839783 | AC11: =IBCD!G13 -> 11.04976 | AD11: =IS3Q!G13 -> 21.698369 | AE11: =IUSU!G13 -> 9.9197915 | AF11: ='EXI2'!G13 -> 16.80933 | AG11: =DBXJ!G13 -> 4.9502061 | AH11: =SUM(Z11:AG11) -> 104.10793 | AI11: =AH11+D11 -> 106.44793 | AJ11: =AI11-B11 -> 6.4479303 | AK11: =AJ11/B11 -> 0.064479303 | AL11: ='2024.10'!E9 -> 0 | AM11: ='2024.10'!F9 -> 0.05
A12: ='2024.11'!A1 -> 2024.11 | B12: =B11+'2024.11'!B9 -> 100 | C12: =C11+'2024.11'!C9 -> 98.93 | D12: =Cash!B11 -> 2.67 | E12: 0 | F12: 0 | G12: 0 | H12: 0 | I12: 0 | J12: 0 | K12: 0 | L12: 0 | M12: 0 | N12: 0 | O12: 0 | P12: 0 | Q12: 0 | R12: 0 | S12: 0 | T12: 0 | U12: 0 | V12: 0 | W12: 0 | X12: 0 | Y12: 0 | Z12: =XDWT!G14 -> 12.229499 | AA12: =IS3K!G14 -> 15.969659 | AB12: =QDVY!G14 -> 12.866928 | AC12: =IBCD!G14 -> 11.530337 | AD12: =IS3Q!G14 -> 23.040081 | AE12: =IUSU!G14 -> 10.210259 | AF12: ='EXI2'!G14 -> 17.839756 | AG12: =DBXJ!G14 -> 5.2100648 | AH12: =SUM(Z12:AG12) -> 108.89658 | AI12: =AH12+D12 -> 111.56658 | AJ12: =AI12-B12 -> 11.566584 | AK12: =AJ12/B12 -> 0.11566584 | AL12: ='2024.11'!E9 -> 0.39 | AM12: ='2024.11'!F9 -> 0.06
A13: ='2024.12'!A1 -> 2024.12 | B13: =B12+'2024.12'!B9 -> 110 | C13: =C12+'2024.12'!C9 -> 109.09 | D13: =Cash!B12 -> 2.6 | E13: 0 | F13: 0 | G13: 0 | H13: 0 | I13: 0 | J13: 0 | K13: 0 | L13: 0 | M13: 0 | N13: 0 | O13: 0 | P13: 0 | Q13: 0 | R13: 0 | S13: 0 | T13: 0 | U13: 0 | V13: 0 | W13: 0 | X13: 0 | Y13: 0 | Z13: =XDWT!G15 -> 12.670214 | AA13: =IS3K!G15 -> 18.200802 | AB13: =QDVY!G15 -> 14.535281 | AC13: =IBCD!G15 -> 13.289739 | AD13: =IS3Q!G15 -> 24.040547 | AE13: =IUSU!G15 -> 12.069911 | AF13: ='EXI2'!G15 -> 18.600405 | AG13: =DBXJ!G15 -> 6.2196482 | AH13: =SUM(Z13:AG13) -> 119.62655 | AI13: =AH13+D13 -> 122.22655 | AJ13: =AI13-B13 -> 12.226548 | AK13: =AJ13/B13 -> 0.11115043 | AL13: ='2024.12'!E9 -> 0.15 | AM13: ='2024.12'!F9 -> 0.06
A14: ='2025.01'!A1 -> 2025.01 | B14: =B13+'2025.01'!B9 -> 110 | C14: =C13+'2025.01'!C9 -> 109.09 | D14: =Cash!B13 -> 3.04 | E14: 0 | F14: 0 | G14: 0 | H14: 0 | I14: 0 | J14: 0 | K14: 0 | L14: 0 | M14: 0 | N14: 0 | O14: 0 | P14: 0 | Q14: 0 | R14: 0 | S14: 0 | T14: 0 | U14: 0 | V14: 0 | W14: 0 | X14: 0 | Y14: 0 | Z14: =XDWT!G16 -> 12.420521 | AA14: =IS3K!G16 -> 18.690391 | AB14: =QDVY!G16 -> 14.715844 | AC14: =IBCD!G16 -> 13.540672 | AD14: =IS3Q!G16 -> 24.68 | AE14: =IUSU!G16 -> 12.270009 | AF14: ='EXI2'!G16 -> 18.969573 | AG14: =DBXJ!G16 -> 6.3499831 | AH14: =SUM(Z14:AG14) -> 121.63699 | AI14: =AH14+D14 -> 124.67699 | AJ14: =AI14-B14 -> 14.676993 | AK14: =AJ14/B14 -> 0.1334272 | AL14: ='2025.01'!E9 -> 0.5 | AM14: ='2025.01'!F9 -> 0.06
A15: ='2025.02'!A1 -> 2025.02 | B15: =B14+'2025.02'!B9 -> 110 | C15: =C14+'2025.02'!C9 -> 109.09 | D15: =Cash!B14 -> 2.97 | E15: 0 | F15: 0 | G15: 0 | H15: 0 | I15: 0 | J15: 0 | K15: 0 | L15: 0 | M15: 0 | N15: 0 | O15: 0 | P15: 0 | Q15: 0 | R15: 0 | S15: 0 | T15: 0 | U15: 0 | V15: 0 | W15: 0 | X15: 0 | Y15: 0 | Z15: =XDWT!G17 -> 11.929322 | AA15: =IS3K!G17 -> 18.549248 | AB15: =QDVY!G17 -> 14.68575 | AC15: =IBCD!G17 -> 13.769423 | AD15: =IS3Q!G17 -> 24.421345 | AE15: =IUSU!G17 -> 12.339993 | AF15: ='EXI2'!G17 -> 18.259634 | AG15: =DBXJ!G17 -> 6.3297448 | AH15: =SUM(Z15:AG15) -> 120.28446 | AI15: =AH15+D15 -> 123.25446 | AJ15: =AI15-B15 -> 13.25446 | AK15: =AJ15/B15 -> 0.12049509 | AL15: ='2025.02'!E9 -> 0 | AM15: ='2025.02'!F9 -> 0.07
A16: ='2025.03'!A1 -> 2025.03 | B16: =B15+'2025.03'!B9 -> 120 | C16: =C15+'2025.03'!C9 -> 119.42 | D16: =Cash!B15 -> 3 | E16: 0 | F16: 0 | G16: 0 | H16: 0 | I16: 0 | J16: 0 | K16: 0 | L16: 0 | M16: 0 | N16: 0 | O16: 0 | P16: 0 | Q16: 0 | R16: 0 | S16: 0 | T16: 0 | U16: 0 | V16: 0 | W16: 0 | X16: 0 | Y16: 0 | Z16: =XDWT!G18 -> 12.199969 | AA16: =IS3K!G18 -> 18.869626 | AB16: =QDVY!G18 -> 15.216158 | AC16: =IBCD!G18 -> 13.829684 | AD16: =IS3Q!G18 -> 25.028696 | AE16: =IUSU!G18 -> 12.679602 | AF16: ='EXI2'!G18 -> 18.601066 | AG16: =DBXJ!G18 -> 6.1303802 | AH16: =SUM(Z16:AG16) -> 122.55518 | AI16: =AH16+D16 -> 125.55518 | AJ16: =AI16-B16 -> 5.5551815 | AK16: =AJ16/B16 -> 0.046293179 | AL16: ='2025.03'!E9 -> 0.42 | AM16: ='2025.03'!F9 -> 0.06
A17: ='2025.04'!A1 -> 2025.04 | B17: =B16+'2025.04'!B9 -> 183.94 | C17: =C16+'2025.04'!C9 -> 182.36 | D17: =Cash!B16 -> 3.93 | E17: 0 | F17: 0 | G17: 0 | H17: 0 | I17: 0 | J17: 0 | K17: 0 | L17: 0 | M17: 0 | N17: 0 | O17: 0 | P17: 0 | Q17: 0 | R17: 0 | S17: 0 | T17: 0 | U17: 0 | V17: 0 | W17: 0 | X17: 0 | Y17: 0 | Z17: =XDWT!G19 -> 18.719979 | AA17: =IS3K!G19 -> 27.471463 | AB17: =QDVY!G19 -> 21.994051 | AC17: =IBCD!G19 -> 20.199129 | AD17: =IS3Q!G19 -> 37.408456 | AE17: =IUSU!G19 -> 18.33988 | AF17: ='EXI2'!G19 -> 27.709309 | AG17: =DBXJ!G19 -> 9.2702677 | AH17: =SUM(Z17:AG17) -> 181.11253 | AI17: =AH17+D17 -> 185.04253 | AJ17: =AI17-B17 -> 1.1025348 | AK17: =AJ17/B17 -> 0.0059939918 | AL17: ='2025.04'!E9 -> 0 | AM17: ='2025.04'!F9 -> 0.07
A18: ='2025.05'!A1 -> 2025.05 | B18: =B17+'2025.05'!B9 -> 198.59 | C18: =C17+'2025.05'!C9 -> 196.79 | D18: =Cash!B17 -> 4.05 | E18: 0 | F18: 0 | G18: 0 | H18: 0 | I18: 0 | J18: 0 | K18: 0 | L18: 0 | M18: 0 | N18: 0 | O18: 0 | P18: 0 | Q18: 0 | R18: 0 | S18: 0 | T18: 0 | U18: 0 | V18: 0 | W18: 0 | X18: 0 | Y18: 0 | Z18: =XDWT!G20 -> 21.510184 | AA18: =IS3K!G20 -> 30.241004 | AB18: =QDVY!G20 -> 23.561083 | AC18: =IBCD!G20 -> 22.180552 | AD18: =IS3Q!G20 -> 41.272675 | AE18: =IUSU!G20 -> 20.030881 | AF18: ='EXI2'!G20 -> 31.628755 | AG18: =DBXJ!G20 -> 10.329952 | AH18: =SUM(Z18:AG18) -> 200.75508 | AI18: =AH18+D18 -> 204.80508 | AJ18: =AI18-B18 -> 6.2150849 | AK18: =AJ18/B18 -> 0.031296062 | AL18: ='2025.05'!E9 -> 0 | AM18: ='2025.05'!F9 -> 0.1
A19: ='2025.06'!A1 -> 2025.06 | B19: =B18+'2025.06'!B12 -> 223.59 | C19: =C18+'2025.06'!C12 -> 221.1 | D19: =Cash!B18 -> 5.63 | E19: 0 | F19: 0 | G19: 0 | H19: 0 | I19: 0 | J19: 0 | K19: 0 | L19: 0 | M19: 0 | N19: 0 | O19: 0 | P19: 0 | Q19: 0 | R19: 0 | S19: 0 | T19: 0 | U19: 0 | V19: 0 | W19: 0 | X19: 0 | Y19: 0 | Z19: =XDWT!G21 -> 24.379979 | AA19: =IS3K!G21 -> 32.668329 | AB19: =QDVY!G21 -> 26.686087 | AC19: =IBCD!G21 -> 24.510161 | AD19: =IS3Q!G21 -> 45.879984 | AE19: =IUSU!G21 -> 22.229697 | AF19: ='EXI2'!G21 -> 35.250343 | AG19: =DBXJ!G21 -> 11.259772 | AH19: =SUM(Z19:AG19) -> 222.86435 | AI19: =AH19+D19 -> 228.49435 | AJ19: =AI19-B19 -> 4.9043539 | AK19: =AJ19/B19 -> 0.021934585 | AL19: ='2025.06'!E12 -> 1.01 | AM19: ='2025.06'!F12 -> 0.12
A20: ='2025.07'!A1 -> 2025.07 | B20: =B19+'2025.07'!B12 -> 255.17 | C20: =C19+'2025.07'!C12 -> 253.76 | D20: =Cash!B19 -> 5.5 | E20: 0 | F20: 0 | G20: 0 | H20: 0 | I20: 0 | J20: 0 | K20: 0 | L20: 0 | M20: 0 | N20: 0 | O20: 0 | P20: 0 | Q20: 0 | R20: 0 | S20: 0 | T20: 0 | U20: 0 | V20: 0 | W20: 0 | X20: 0 | Y20: 0 | Z20: =XDWT!G22 -> 27.201027 | AA20: =IS3K!G22 -> 40.910941 | AB20: =QDVY!G22 -> 32.661646 | AC20: =IBCD!G22 -> 29.859767 | AD20: =IS3Q!G22 -> 53.548977 | AE20: =IUSU!G22 -> 27.15054 | AF20: ='EXI2'!G22 -> 40.577761 | AG20: =DBXJ!G22 -> 13.560642 | AH20: =SUM(Z20:AG20) -> 265.4713 | AI20: =AH20+D20 -> 270.9713 | AJ20: =AI20-B20 -> 15.8013 | AK20: =AJ20/B20 -> 0.0619246 | AL20: ='2025.07'!E12 -> 1.08 | AM20: ='2025.07'!F12 -> 0.13
A21: ='2025.08'!A1 -> 2025.08 | B21: =B20+'2025.08'!B12 -> 283.15 | C21: =C20+'2025.08'!C12 -> 278.53 | D21: =Cash!B20 -> 8.56 | E21: 0 | F21: 0 | G21: 0 | H21: 0 | I21: 0 | J21: 0 | K21: 0 | L21: 0 | M21: 0 | N21: 0 | O21: 0 | P21: 0 | Q21: 0 | R21: 0 | S21: 0 | T21: 0 | U21: 0 | V21: 0 | W21: 0 | X21: 0 | Y21: 0 | Z21: =XDWT!G23 -> 29.01107 | AA21: =IS3K!G23 -> 44.411458 | AB21: =QDVY!G23 -> 35.353259 | AC21: =IBCD!G23 -> 32.22882 | AD21: =IS3Q!G23 -> 58.645587 | AE21: =IUSU!G23 -> 29.510547 | AF21: ='EXI2'!G23 -> 44.298481 | AG21: =DBXJ!G23 -> 14.780304 | AH21: =SUM(Z21:AG21) -> 288.23952 | AI21: =AH21+D21 -> 296.79952 | AJ21: =AI21-B21 -> 13.649525 | AK21: =AJ21/B21 -> 0.048205985 | AL21: ='2025.08'!E12 -> 0 | AM21: ='2025.08'!F12 -> 0.15
A22: ='2025.09'!A1 -> 2025.09 | B22: =B21+'2025.09'!B12 -> 298.15 | C22: =C21+'2025.09'!C12 -> 295.62 | D22: =Cash!B21 -> 7.35 | E22: 0 | F22: 0 | G22: 0 | H22: 0 | I22: 0 | J22: 0 | K22: 0 | L22: 0 | M22: 0 | N22: 0 | O22: 0 | P22: 0 | Q22: 0 | R22: 0 | S22: 0 | T22: 0 | U22: 0 | V22: 0 | W22: 0 | X22: 0 | Y22: 0 | Z22: =XDWT!G24 -> 33.150336 | AA22: =IS3K!G24 -> 46.997682 | AB22: =QDVY!G24 -> 37.445211 | AC22: =IBCD!G24 -> 34.511749 | AD22: =IS3Q!G24 -> 63.607564 | AE22: =IUSU!G24 -> 30.560588 | AF22: ='EXI2'!G24 -> 48.95969 | AG22: =DBXJ!G24 -> 15.910504 | AH22: =SUM(Z22:AG22) -> 311.14332 | AI22: =AH22+D22 -> 318.49332 | AJ22: =AI22-B22 -> 20.343324 | AK22: =AJ22/B22 -> 0.068231844 | AL22: ='2025.09'!E12 -> 1.04 | AM22: ='2025.09'!F12 -> 0.16
A23: ='2025.10'!A1 -> 2025.10 | B23: =B22+'2025.10'!B12 -> 313.15 | C23: =C22+'2025.10'!C12 -> 311.05 | D23: =Cash!B22 -> 6.75 | E23: 0 | F23: 0 | G23: 0 | H23: 0 | I23: 0 | J23: 0 | K23: 0 | L23: 0 | M23: 0 | N23: 0 | O23: 0 | P23: 0 | Q23: 0 | R23: 0 | S23: 0 | T23: 0 | U23: 0 | V23: 0 | W23: 0 | X23: 0 | Y23: 0 | Z23: =XDWT!G25 -> 36.359617 | AA23: =IS3K!G25 -> 50.890237 | AB23: =QDVY!G25 -> 40.810385 | AC23: =IBCD!G25 -> 37.360132 | AD23: =IS3Q!G25 -> 68.619375 | AE23: =IUSU!G25 -> 33.950433 | AF23: ='EXI2'!G25 -> 53.371952 | AG23: =DBXJ!G25 -> 17.630169 | AH23: =SUM(Z23:AG23) -> 338.9923 | AI23: =AH23+D23 -> 345.7423 | AJ23: =AI23-B23 -> 32.592299 | AK23: =AJ23/B23 -> 0.10407887 | AL23: ='2025.10'!E12 -> 0 | AM23: ='2025.10'!F12 -> 0.17
A24: ='2025.11'!A1 -> 2025.11 | B24: =B23+'2025.11'!B12 -> 328.15 | C24: =C23+'2025.11'!C12 -> 325.26 | D24: =Cash!B23 -> 7.35 | E24: 0 | F24: 0 | G24: 0 | H24: 0 | I24: 0 | J24: 0 | K24: 0 | L24: 0 | M24: 0 | N24: 0 | O24: 0 | P24: 0 | Q24: 0 | R24: 0 | S24: 0 | T24: 0 | U24: 0 | V24: 0 | W24: 0 | X24: 0 | Y24: 0 | Z24: =XDWT!G26 -> 34.491175 | AA24: =IS3K!G26 -> 54.108288 | AB24: =QDVY!G26 -> 42.041489 | AC24: =IBCD!G26 -> 39.781256 | AD24: =IS3Q!G26 -> 72.479224 | AE24: =IUSU!G26 -> 36.009865 | AF24: ='EXI2'!G26 -> 53.427562 | AG24: =DBXJ!G26 -> 17.859873 | AH24: =SUM(Z24:AG24) -> 350.19873 | AI24: =AH24+D24 -> 357.54873 | AJ24: =AI24-B24 -> 29.398731 | AK24: =AJ24/B24 -> 0.089589306 | AL24: ='2025.11'!E12 -> 0 | AM24: ='2025.11'!F12 -> 0.19
A25: ='2025.12'!A1 -> 2025.12 | B25: =B24+'2025.12'!B12 -> 343.15 | C25: =C24+'2025.12'!C12 -> 339.84 | D25: =Cash!B24 -> 10.89 | E25: 0 | F25: 0 | G25: 0 | H25: 0 | I25: 0 | J25: 0 | K25: 0 | L25: 0 | M25: 0 | N25: 0 | O25: 0 | P25: 0 | Q25: 0 | R25: 0 | S25: 0 | T25: 0 | U25: 0 | V25: 0 | W25: 0 | X25: 0 | Y25: 0 | Z25: =XDWT!G27 -> 37.24916 | AA25: =IS3K!G27 -> 53.506908 | AB25: =QDVY!G27 -> 44.073996 | AC25: =IBCD!G27 -> 39.779332 | AD25: =IS3Q!G27 -> 74.983071 | AE25: =IUSU!G27 -> 36.749314 | AF25: ='EXI2'!G27 -> 55.669016 | AG25: =DBXJ!G27 -> 18.729746 | AH25: =SUM(Z25:AG25) -> 360.74054 | AI25: =AH25+D25 -> 371.63054 | AJ25: =AI25-B25 -> 28.480542 | AK25: =AJ25/B25 -> 0.082997354 | AL25: ='2025.12'!E12 -> 3.31 | AM25: ='2025.12'!F12 -> 0.19
A26: ='2026.01'!A1 -> 2026.01 | B26: =B25+'2026.01'!B12 -> 358.15 | C26: =C25+'2026.01'!C12 -> 353.45 | D26: =Cash!B25 -> 12.08 | E26: 0 | F26: 0 | G26: 0 | H26: 0 | I26: 0 | J26: 0 | K26: 0 | L26: 0 | M26: 0 | N26: 0 | O26: 0 | P26: 0 | Q26: 0 | R26: 0 | S26: 0 | T26: 0 | U26: 0 | V26: 0 | W26: 0 | X26: 0 | Y26: 0 | Z26: =XDWT!G28 -> 37.460966 | AA26: =IS3K!G28 -> 57.552962 | AB26: =QDVY!G28 -> 43.97102 | AC26: =IBCD!G28 -> 42.200188 | AD26: =IS3Q!G28 -> 78.882348 | AE26: =IUSU!G28 -> 36.461662 | AF26: ='EXI2'!G28 -> 57.902763 | AG26: =DBXJ!G28 -> 20.230484 | AH26: =SUM(Z26:AG26) -> 374.66239 | AI26: =AH26+D26 -> 386.74239 | AJ26: =AI26-B26 -> 28.592394 | AK26: =AJ26/B26 -> 0.079833572 | AL26: ='2026.01'!E12 -> 0 | AM26: ='2026.01'!F12 -> 0.2
A27: ='2026.02'!A1 -> 2026.02 | B27: =B26+'2026.02'!B12 -> 373.15 | C27: =C26+'2026.02'!C12 -> 367.96 | D27: =Cash!B26 -> 12.36 | E27: 0 | F27: 0 | G27: 0 | H27: 0 | I27: 0 | J27: 0 | K27: 0 | L27: 0 | M27: 0 | N27: 0 | O27: 0 | P27: 0 | Q27: 0 | R27: 0 | S27: 0 | T27: 0 | U27: 0 | V27: 0 | W27: 0 | X27: 0 | Y27: 0 | Z27: =XDWT!G29 -> 38.921662 | AA27: =IS3K!G29 -> 60.227987 | AB27: =QDVY!G29 -> 46.075689 | AC27: =IBCD!G29 -> 44.788859 | AD27: =IS3Q!G29 -> 81.672327 | AE27: =IUSU!G29 -> 38.531014 | AF27: ='EXI2'!G29 -> 59.777684 | AG27: =DBXJ!G29 -> 21.819782 | AH27: =SUM(Z27:AG27) -> 391.815 | AI27: =AH27+D27 -> 404.175 | AJ27: =AI27-B27 -> 31.025005 | AK27: =AJ27/B27 -> 0.083143521 | AL27: ='2026.02'!E12 -> 0 | AM27: ='2026.02'!F12 -> 0.21
A28: ='2026.03'!A1 -> 2026.03 | B28: =B27+'2026.03'!B12 -> 388.15 | C28: =C27+'2026.03'!C12 -> 382.35 | D28: =Cash!B27 -> 12.8 | E28: 0 | F28: 0 | G28: 0 | H28: 0 | I28: 0 | J28: 0 | K28: 0 | L28: 0 | M28: 0 | N28: 0 | O28: 0 | P28: 0 | Q28: 0 | R28: 0 | S28: 0 | T28: 0 | U28: 0 | V28: 0 | W28: 0 | X28: 0 | Y28: 0 | Z28: =XDWT!G30 -> 41.380298 | AA28: =IS3K!G30 -> 62.410454 | AB28: =QDVY!G30 -> 49.091201 | AC28: =IBCD!G30 -> 45.141351 | AD28: =IS3Q!G30 -> 79.799368 | AE28: =IUSU!G30 -> 39.639958 | AF28: ='EXI2'!G30 -> 60.882655 | AG28: =DBXJ!G30 -> 20.400846 | AH28: =SUM(Z28:AG28) -> 398.74613 | AI28: =AH28+D28 -> 411.54613 | AJ28: =AI28-B28 -> 23.396132 | AK28: =AJ28/B28 -> 0.060276005 | AL28: ='2026.03'!E12 -> 0.03 | AM28: ='2026.03'!F12 -> 0.2
A29: ='2026.04'!N2 -> 2026.04 | B29: =B28+'2026.04'!O13 -> 403.15 | C29: =C28+'2026.04'!P13-'2026.04'!Q13 -> 407.79038 | D29: =Cash!B28 -> 4.04 | E29: =XDWI!G5 -> 9.9302208 | F29: =WELK!G5 -> 9.9977025 | G29: =PRAR!G5 -> 38.979188 | H29: 0 | I29: ='QDV7'!G5 -> 6.324471 | J29: =AMEL!G5 -> 9.3402169 | K29: ='79U0'!G5 -> 67.200687 | L29: 0 | M29: =PRAJ!G5 -> 17.649215 | N29: =LEMA!G5 -> 25.159264 | O29: =AEYH!G5 -> 15.677662 | P29: =EMBH!G5 -> 24.961208 | Q29: =LYMS!G5 -> 40.302052 | R29: =EBUY!G5 -> 11.080555 | S29: =TRDE!G5 -> 33.364755 | T29: =PRAC!G5 -> 36.833916 | U29: ='LYP6'!G5 -> 64.288926 | V29: =UBUD!G5 -> 5.8805483 | W29: ='2B72'!G5 -> 9.8471713 | X29: ='LYP5'!G5 -> 10.319967 | Y29: =LGQK!G5 -> 2.1600713 | Z29: 0 | AA29: 0 | AB29: 0 | AC29: 0 | AD29: 0 | AE29: 0 | AF29: 0 | AG29: 0 | AH29: =SUM(E29:AG29) -> 439.2978 | AI29: =AH29+D29 -> 443.3378 | AJ29: =AI29-B29 -> 40.187796 | AK29: =AJ29/B29 -> 0.099684475 | AL29: ='2026.04'!$S$13 -> 2.44 | AM29: ='2026.04'!$T$13 -> 0.22
A30: ='2026.05'!$N$2 -> 2026.05 | B30: =B29+'2026.05'!$O$13 -> 418.15 | C30: =C29+'2026.05'!$P$13-'2026.05'!$Q$13+'2026.05'!$S$13 -> 422.05038 | D30: =Cash!B29 -> 4.55 | E30: =XDWI!G6 -> 14.040395 | F30: =WELK!G6 -> 14.129963 | G30: =PRAR!G6 -> 30.718122 | H30: =LKOR!G5 -> 3.5200771 | I30: ='QDV7'!G6 -> 9.397458 | J30: =AMEL!G6 -> 13.920855 | K30: ='79U0'!G6 -> 80.730101 | L30: =LYTR!G5 -> 9.369936 | M30: =PRAJ!G6 -> 18.998237 | N30: =LEMA!G6 -> 29.808795 | O30: =AEYH!G6 -> 18.867642 | P30: =EMBH!G6 -> 30.780443 | Q30: =LYMS!G6 -> 47.538849 | R30: =EBUY!G6 -> 14.491562 | S30: =TRDE!G6 -> 30.76142 | T30: =PRAC!G6 -> 33.099044 | U30: ='LYP6'!G6 -> 68.190388 | V30: =UBUD!G6 -> 0 | W30: ='2B72'!G6 -> 0 | X30: ='LYP5'!G6 -> 0 | Y30: =LGQK!G6 -> 0 | Z30: 0 | AA30: 0 | AB30: 0 | AC30: 0 | AD30: 0 | AE30: 0 | AF30: 0 | AG30: 0 | AH30: =SUM(E30:AG30) -> 468.36329 | AI30: =AH30+D30 -> 472.91329 | AJ30: =AI30-B30 -> 54.763288 | AK30: =AJ30/B30 -> 0.13096565 | AL30: ='2026.05'!$S$13 -> 0 | AM30: ='2026.05'!$T$13 -> 0.23
A31: ='2026.06'!$N$2 -> 2026.06 | B31: =B30+'2026.06'!$O$13 -> 433.15 | C31: =C30+'2026.06'!$P$13-'2026.06'!$Q$13+'2026.06'!$S$5 -> 436.67038 | D31: =Cash!B30 -> 4.93 | E31: =XDWI!G7 -> 14.589618 | F31: =WELK!G7 -> 14.656655 | G31: =PRAR!G7 -> 31.787912 | H31: =LKOR!G6 -> 3.740003 | I31: ='QDV7'!G7 -> 9.7937801 | J31: =AMEL!G7 -> 14.648683 | K31: ='79U0'!G7 -> 83.179497 | L31: =LYTR!G6 -> 9.799338 | M31: =PRAJ!G7 -> 19.500789 | N31: =LEMA!G7 -> 30.699283 | O31: =AEYH!G7 -> 19.554854 | P31: =EMBH!G7 -> 31.780642 | Q31: =LYMS!G7 -> 49.13136 | R31: =EBUY!G7 -> 15.056941 | S31: =TRDE!G7 -> 31.730975 | T31: =PRAC!G7 -> 34.172677 | U31: ='LYP6'!G7 -> 70.720433 | V31: =UBUD!G7 -> 0 | W31: ='2B72'!G7 -> 0 | X31: ='LYP5'!G7 -> 0 | Y31: =LGQK!G7 -> 0 | Z31: 0 | AA31: 0 | AB31: 0 | AC31: 0 | AD31: 0 | AE31: 0 | AF31: 0 | AG31: 0 | AH31: =SUM(E31:AG31) -> 484.54344 | AI31: =AH31+D31 -> 489.47344 | AJ31: =AI31-B31 -> 56.323439 | AK31: =AJ31/B31 -> 0.13003218 | AL31: ='2026.06'!$S$13 -> 0 | AM31: ='2026.06'!$T$13 -> 0
B34: Uždaryta 2026-06-17 išmokėta 490.16

Sheet Cash
A1: Cash | B1: Suma, EUR
A2: ='2024.02'!A1 -> 2024.02 | B2: ='2024.02'!D9 -> 2
A3: ='2024.03'!A1 -> 2024.03 | B3: =Cash!B2-'2024.03'!F9+'2024.03'!E9-D2 -> 1.95
A4: ='2024.04'!A1 -> 2024.04 | B4: =B3-'2024.04'!F9+'2024.04'!E9-D2 -> 2.23
A5: ='2024.05'!A1 -> 2024.05 | B5: =B4-'2024.05'!F9+'2024.05'!E9-D2 -> 2.19
A6: ='2024.06'!A1 -> 2024.06 | B6: =B5-'2024.06'!F9+'2024.06'!E9-D2 -> 3
A7: ='2024.07'!A1 -> 2024.07 | B7: =B6-'2024.07'!F9+'2024.07'!E9+'2024.07'!D9-D2 -> 2.15
A8: ='2024.08'!A1 -> 2024.08 | B8: =B7-'2024.08'!F9+'2024.08'!E9+'2024.08'!D9-D2 -> 2.1
A9: ='2024.09'!A1 -> 2024.09 | B9: =B8-'2024.09'!F9+'2024.09'!E9+'2024.09'!D9-D2 -> 2.39
A10: ='2024.10'!A1 -> 2024.10 | B10: =B9-'2024.10'!F9+'2024.10'!E9+'2024.10'!D9-D2 -> 2.34
A11: ='2024.11'!A1 -> 2024.11 | B11: =B10-'2024.11'!F9+'2024.11'!E9+'2024.11'!D9-D2 -> 2.67
A12: ='2024.12'!A1 -> 2024.12 | B12: =B11-'2024.12'!F9+'2024.12'!E9+'2024.12'!D9-D2 -> 2.6
A13: ='2025.01'!A1 -> 2025.01 | B13: =B12-'2025.01'!F9+'2025.01'!E9+'2025.01'!D9-D2 -> 3.04
A14: ='2025.02'!A1 -> 2025.02 | B14: =B13-'2025.02'!F9+'2025.02'!E9+'2025.02'!D9-D2 -> 2.97
A15: ='2025.03'!A1 -> 2025.03 | B15: =B14-'2025.03'!F9+'2025.03'!E9+'2025.03'!D9-D2 -> 3
A16: ='2025.04'!A1 -> 2025.04 | B16: =B15-'2025.04'!F9+'2025.04'!E9+'2025.04'!D9-D2 -> 3.93
A17: ='2025.05'!A1 -> 2025.05 | B17: =B16-'2025.05'!F9+'2025.05'!E9+'2025.05'!D9-D3 -> 4.05
A18: ='2025.06'!A1 -> 2025.06 | B18: =B17-'2025.06'!F12+'2025.06'!E12+'2025.06'!D12-D4 -> 5.63
A19: ='2025.07'!A1 -> 2025.07 | B19: =B18-'2025.07'!F12+'2025.07'!E12+'2025.07'!D12-D4 -> 5.5
A20: ='2025.08'!A1 -> 2025.08 | B20: =B19-'2025.08'!F12+'2025.08'!E12+'2025.08'!D12-D4 -> 8.56
A21: ='2025.09'!A1 -> 2025.09 | B21: =B20-'2025.09'!F12+'2025.09'!E12+'2025.09'!D12-D4 -> 7.35
A22: ='2025.10'!A1 -> 2025.10 | B22: =B21-'2025.10'!F12+'2025.10'!E12+'2025.10'!D12-D5 -> 6.75
A23: ='2025.11'!A1 -> 2025.11 | B23: =B22-'2025.11'!F12+'2025.11'!E12+'2025.11'!D12-D1 -> 7.35
A24: ='2025.12'!A1 -> 2025.12 | B24: =B23-'2025.12'!F12+'2025.12'!E12+'2025.12'!D12-D6 -> 10.89
A25: ='2026.01'!A1 -> 2026.01 | B25: =B24-'2026.01'!F12+'2026.01'!E12+'2026.01'!D12-D6 -> 12.08
A26: ='2026.02'!A1 -> 2026.02 | B26: =B25-'2026.02'!F12+'2026.02'!E12+'2026.02'!D12-D7 -> 12.36
A27: ='2026.03'!A1 -> 2026.03 | B27: =B26-'2026.03'!F12+'2026.03'!E12+'2026.03'!D12-D7 -> 12.8
A28: ='2026.04'!N2 -> 2026.04 | B28: 4.04
A29: ='2026.05'!$N$2 -> 2026.05 | B29: =B28+'2026.05'!R13-'2026.05'!T13 -> 4.55
A30: ='2026.06'!$N$2 -> 2026.06 | B30: =B29+'2026.06'!$R$13-'2026.06'!$T$14 -> 4.93

Sheet XDWI
A1: XDWI Xtrackers MSCI World Industrials UCITS ETF (Acc)
A3: Data | B3: Suma, EUR | D3: Kiekis | F3: Mėnesio gale | J3: Dividendai | L3: XDWI | M3: Įnešta | N3: Be dividendų | P3: Su dividendais | R3: Kiekis | S3: Dividendai
B4: Įnešta | C4: Viso | D4: Mėnesio | E4: Viso | F4: Kaina | G4: Vertė | H4: Pelnas | I4: % | N4: Vertė | O4: Pelnas | P4: Vertė | Q4: Pelnas
A5: ='2026.04'!N2 -> 2026.04 | B5: ='2026.04'!B138-'2026.04'!G138 -> 9.56 | C5: =B5 -> 9.56 | D5: ='2026.04'!D138-'2026.04'!I138 -> 0.13554765 | E5: =D5 -> 0.13554765 | F5: 73.26 | G5: =E5*F5 -> 9.9302208 | H5: =G5-C5 -> 0.37022084 | I5: =(G5-C5)/C5 -> 0.038726029 | J5: ='2026.04'!L138 -> 0 | L5: Viso: | M5: =SUM(B5:B200) -> 14.32 | N5: =INDEX(G5:G200,MATCH(9.99999999999999E+307,G5:G200)) -> 14.589618 | O5: =INDEX(I5:I200,MATCH(9.99999999999999E+307,I5:I200)) -> 0.018828056 | P5: =N5+S5 -> 14.589618 | Q5: =(P5-M5)/M5 -> 0.018828056 | R5: =SUM(D5:D200) -> 0.20007704 | S5: =SUM(J5:J200) -> 0
A6: ='2026.05'!$N$2 -> 2026.05 | B6: ='2026.05'!$B$138-'2026.05'!$G$138 -> 4.11 | C6: =C5+B6 -> 13.67 | D6: ='2026.05'!$D$138-'2026.05'!$I$138 -> 0.05560817 | E6: =E5+D6 -> 0.19115582 | F6: 73.45 | G6: =E6*F6 -> 14.040395 | H6: =G6-C6 -> 0.37039498 | I6: =(G6-C6)/C6 -> 0.027095463 | J6: ='2026.05'!$L$138 -> 0
A7: ='2026.06'!$N$2 -> 2026.06 | B7: ='2026.06'!$B$138-'2026.06'!$G$138 -> 0.65 | C7: =C6+B7 -> 14.32 | D7: ='2026.06'!$D$138-'2026.06'!$I$138 -> 0.00892122 | E7: =E6+D7 -> 0.20007704 | F7: 72.92 | G7: =E7*F7 -> 14.589618 | H7: =G7-C7 -> 0.26961776 | I7: =(G7-C7)/C7 -> 0.018828056 | J7: ='2026.06'!$L$138 -> 0

Sheet WELK
A1: WELK Amundi S&P Global Financials ESG Acc UCITS ETF
A3: Data | B3: Suma, EUR | D3: Kiekis | F3: Mėnesio gale | J3: Dividendai | L3: WELK | M3: Įnešta | N3: Be dividendų | P3: Su dividendais | R3: Kiekis | S3: Dividendai
B4: Įnešta | C4: Viso | D4: Mėnesio | E4: Viso | F4: Kaina | G4: Vertė | H4: Pelnas | I4: % | N4: Vertė | O4: Pelnas | P4: Vertė | Q4: Pelnas
A5: ='2026.04'!N2 -> 2026.04 | B5: ='2026.04'!B152-'2026.04'!G152 -> 9.72 | C5: =B5 -> 9.72 | D5: ='2026.04'!D152 -> 0.5619844 | E5: =D5 -> 0.5619844 | F5: 17.79 | G5: =E5*F5 -> 9.9977025 | H5: =G5-C5 -> 0.27770248 | I5: =(G5-C5)/C5 -> 0.028570214 | J5: ='2026.04'!L152 -> 0 | L5: Viso: | M5: =SUM(B5:B200) -> 14.32 | N5: =INDEX(G5:G200,MATCH(9.99999999999999E+307,G5:G200)) -> 14.656655 | O5: =INDEX(I5:I200,MATCH(9.99999999999999E+307,I5:I200)) -> 0.02350941 | P5: =N5+S5 -> 14.656655 | Q5: =(P5-M5)/M5 -> 0.02350941 | R5: =SUM(D5:D200) -> 0.81789368 | S5: =SUM(J5:J200) -> 0
A6: ='2026.05'!$N$2 -> 2026.05 | B6: ='2026.05'!$B$152-'2026.05'!$G$152 -> 4.05 | C6: =C5+B6 -> 13.77 | D6: ='2026.05'!$D$152-'2026.05'!$I$152 -> 0.22520018 | E6: =E5+D6 -> 0.78718458 | F6: 17.95 | G6: =E6*F6 -> 14.129963 | H6: =G6-C6 -> 0.35996321 | I6: =(G6-C6)/C6 -> 0.026141119 | J6: ='2026.05'!$L$152 -> 0
A7: ='2026.06'!$N$2 -> 2026.06 | B7: ='2026.06'!$B$152-'2026.06'!$G$152 -> 0.55 | C7: =C6+B7 -> 14.32 | D7: ='2026.06'!$D$152-'2026.06'!$I$152 -> 0.0307091 | E7: =E6+D7 -> 0.81789368 | F7: 17.92 | G7: =E7*F7 -> 14.656655 | H7: =G7-C7 -> 0.33665475 | I7: =(G7-C7)/C7 -> 0.02350941 | J7: ='2026.06'!$L$152 -> 0

Sheet PRAR
A1: PRAR Amundi Prime Euro Govies UCITS ETF DR (Acc)
A3: Data | B3: Suma, EUR | D3: Kiekis | F3: Mėnesio gale | J3: Dividendai | L3: PRAR | M3: Įnešta | N3: Be dividendų | P3: Su dividendais | R3: Kiekis | S3: Dividendai
B4: Įnešta | C4: Viso | D4: Mėnesio | E4: Viso | F4: Kaina | G4: Vertė | H4: Pelnas | I4: % | N4: Vertė | O4: Pelnas | P4: Vertė | Q4: Pelnas
A5: ='2026.04'!N2 -> 2026.04 | B5: ='2026.04'!B166-'2026.04'!G166 -> 39.06 | C5: =B5 -> 39.06 | D5: ='2026.04'!D166-'2026.04'!I166 -> 2.1715425 | E5: =D5 -> 2.1715425 | F5: 17.95 | G5: =E5*F5 -> 38.979188 | H5: =G5-C5 -> -0.080812125 | I5: =(G5-C5)/C5 -> -0.0020689228 | J5: ='2026.04'!$L$166 -> 0 | L5: Viso: | M5: =SUM(B5:B200) -> 31.54 | N5: =INDEX(G5:G200,MATCH(9.99999999999999E+307,G5:G200)) -> 31.787912 | O5: =INDEX(I5:I200,MATCH(9.99999999999999E+307,I5:I200)) -> 0.0078602283 | P5: =N5+S5 -> 31.787912 | Q5: =(P5-M5)/M5 -> 0.0078602283 | R5: =SUM(D5:D200) -> 1.7562382 | S5: =SUM(J5:J200) -> 0
A6: ='2026.05'!$N$2 -> 2026.05 | B6: ='2026.05'!$B$166-'2026.05'!$G$166 -> -8.64 | C6: =C5+B6 -> 30.42 | D6: ='2026.05'!$D$166-'2026.05'!$I$166 -> -0.47721695 | E6: =E5+D6 -> 1.6943256 | F6: 18.13 | G6: =E6*F6 -> 30.718122 | H6: =G6-C6 -> 0.29812222 | I6: =(G6-C6)/C6 -> 0.0098002045 | J6: ='2026.05'!$L$166 -> 0
A7: ='2026.06'!$N$2 -> 2026.06 | B7: ='2026.06'!$B$166-'2026.06'!$G$166 -> 1.12 | C7: =C6+B7 -> 31.54 | D7: ='2026.06'!$D$166-'2026.06'!$I$166 -> 0.06191266 | E7: =E6+D7 -> 1.7562382 | F7: 18.1 | G7: =E7*F7 -> 31.787912 | H7: =G7-C7 -> 0.2479116 | I7: =(G7-C7)/C7 -> 0.0078602283 | J7: ='2026.06'!$L$166 -> 0

Sheet LKOR
A1: LKOR Amundi MSCI Korea UCITS ETF (Acc)
A3: Data | B3: Suma, EUR | D3: Kiekis | F3: Mėnesio gale | J3: Dividendai | L3: LKOR | M3: Įnešta | N3: Be dividendų | P3: Su dividendais | R3: Kiekis | S3: Dividendai
B4: Įnešta | C4: Viso | D4: Mėnesio | E4: Viso | F4: Kaina | G4: Vertė | H4: Pelnas | I4: % | N4: Vertė | O4: Pelnas | P4: Vertė | Q4: Pelnas
A5: ='2026.05'!$N$2 -> 2026.05 | B5: ='2026.05'!$B$404-'2026.05'!$G$404 -> 3.53 | C5: =B5 -> 3.53 | D5: ='2026.05'!$D$404-'2026.05'!$I$404 -> 0.0180415 | E5: =D5 -> 0.0180415 | F5: 195.11 | G5: =E5*F5 -> 3.5200771 | H5: =G5-C5 -> -0.009922935 | I5: =(G5-C5)/C5 -> -0.0028110297 | J5: ='2026.06'!$L$404 -> 0 | L5: Viso: | M5: =SUM(B5:B200) -> 3.53 | N5: =INDEX(G5:G200,MATCH(9.99999999999999E+307,G5:G200)) -> 3.740003 | O5: =INDEX(I5:I200,MATCH(9.99999999999999E+307,I5:I200)) -> 0.059490921 | P5: =N5+S5 -> 3.740003 | Q5: =(P5-M5)/M5 -> 0.059490921 | R5: =SUM(D5:D200) -> 0.0180415 | S5: =SUM(J5:J200) -> 0
A6: ='2026.06'!$N$2 -> 2026.06 | B6: ='2026.06'!$B$404-'2026.06'!$G$404 -> 0 | C6: =C5+B6 -> 3.53 | D6: ='2026.06'!$D$404-'2026.06'!$I$404 -> 0 | E6: =E5+D6 -> 0.0180415 | F6: 207.3 | G6: =E6*F6 -> 3.740003 | H6: =G6-C6 -> 0.21000295 | I6: =(G6-C6)/C6 -> 0.059490921 | J6: ='2026.06'!$L$404 -> 0

Sheet QDV7
A1: QDV7 iShares J.P. Morgan Emerging Markets Local Government Bond ETF (Acc)
A3: Data | B3: Suma, EUR | D3: Kiekis | F3: Mėnesio gale | J3: Dividendai | L3: QDV7 | M3: Įnešta | N3: Be dividendų | P3: Su dividendais | R3: Kiekis | S3: Dividendai
B4: Įnešta | C4: Viso | D4: Mėnesio | E4: Viso | F4: Kaina | G4: Vertė | H4: Pelnas | I4: % | N4: Vertė | O4: Pelnas | P4: Vertė | Q4: Pelnas
A5: ='2026.04'!$N$2 -> 2026.04 | B5: ='2026.04'!$B$180-'2026.04'!$G$180 -> 6.41 | C5: =B5 -> 6.41 | D5: ='2026.04'!$D$180-'2026.04'!$I$180 -> 1.3148588 | E5: =D5 -> 1.3148588 | F5: 4.81 | G5: =E5*F5 -> 6.324471 | H5: =G5-C5 -> -0.08552898 | I5: =(G5-C5)/C5 -> -0.013343055 | J5: ='2026.04'!$L$180 -> 0 | L5: Viso: | M5: =SUM(B5:B200) -> 9.82 | N5: =INDEX(G5:G200,MATCH(9.99999999999999E+307,G5:G200)) -> 9.7937801 | O5: =INDEX(I5:I200,MATCH(9.99999999999999E+307,I5:I200)) -> -0.0026700468 | P5: =N5+S5 -> 9.7937801 | Q5: =(P5-M5)/M5 -> -0.0026700468 | R5: =SUM(D5:D200) -> 2.0069222 | S5: =SUM(J5:J200) -> 0
A6: ='2026.05'!$N$2 -> 2026.05 | B6: ='2026.05'!$B$180-'2026.05'!$G$180 -> 3.03 | C6: =C5+B6 -> 9.44 | D6: ='2026.05'!$D$180-'2026.05'!$I$180 -> 0.61480399 | E6: =E5+D6 -> 1.9296628 | F6: 4.87 | G6: =E6*F6 -> 9.397458 | H6: =G6-C6 -> -0.042542018 | I6: =(G6-C6)/C6 -> -0.0045065697 | J6: ='2026.05'!$L$180 -> 0
A7: ='2026.06'!$N$2 -> 2026.06 | B7: ='2026.06'!$B$180-'2026.06'!$G$180 -> 0.38 | C7: =C6+B7 -> 9.82 | D7: ='2026.06'!$D$180-'2026.06'!$I$180 -> 0.07725933 | E7: =E6+D7 -> 2.0069222 | F7: 4.88 | G7: =E7*F7 -> 9.7937801 | H7: =G7-C7 -> -0.026219859 | I7: =(G7-C7)/C7 -> -0.0026700468 | J7: ='2026.06'!$L$180 -> 0

Sheet AMEL
A1: AMEL Amundi MSCI Emerging Markets Latin America UCITS ETF EUR (Acc)
A3: Data | B3: Suma, EUR | D3: Kiekis | F3: Mėnesio gale | J3: Dividendai | L3: AMEL | M3: Įnešta | N3: Be dividendų | P3: Su dividendais | R3: Kiekis | S3: Dividendai
B4: Įnešta | C4: Viso | D4: Mėnesio | E4: Viso | F4: Kaina | G4: Vertė | H4: Pelnas | I4: % | N4: Vertė | O4: Pelnas | P4: Vertė | Q4: Pelnas
A5: ='2026.04'!$N$2 -> 2026.04 | B5: ='2026.04'!$B$194-'2026.04'!$G$194 -> 9.38 | C5: =B5 -> 9.38 | D5: ='2026.04'!$D$194-'2026.04'!$I$194 -> 0.43382336 | E5: =D5 -> 0.43382336 | F5: 21.53 | G5: =E5*F5 -> 9.3402169 | H5: =G5-C5 -> -0.039783059 | I5: =(G5-C5)/C5 -> -0.0042412643 | J5: ='2026.04'!$L$194 -> 0 | L5: Viso: | M5: =SUM(B5:B200) -> 15.14 | N5: =INDEX(G5:G200,MATCH(9.99999999999999E+307,G5:G200)) -> 14.648683 | O5: =INDEX(I5:I200,MATCH(9.99999999999999E+307,I5:I200)) -> -0.032451576 | P5: =N5+S5 -> 14.648683 | Q5: =(P5-M5)/M5 -> -0.032451576 | R5: =SUM(D5:D200) -> 0.70972302 | S5: =SUM(J5:J200) -> 0
A6: ='2026.05'!$N$2 -> 2026.05 | B6: ='2026.05'!$B$194-'2026.05'!$G$194 -> 5.13 | C6: =C5+B6 -> 14.51 | D6: ='2026.05'!$D$194-'2026.05'!$I$194 -> 0.24524273 | E6: =E5+D6 -> 0.67906609 | F6: 20.5 | G6: =E6*F6 -> 13.920855 | H6: =G6-C6 -> -0.58914515 | I6: =(G6-C6)/C6 -> -0.040602698 | J6: ='2026.05'!$L$194 -> 0
A7: ='2026.06'!$N$2 -> 2026.06 | B7: ='2026.06'!$B$194-'2026.06'!$G$194 -> 0.63 | C7: =C6+B7 -> 15.14 | D7: ='2026.06'!$D$194-'2026.06'!$I$194 -> 0.03065693 | E7: =E6+D7 -> 0.70972302 | F7: 20.64 | G7: =E7*F7 -> 14.648683 | H7: =G7-C7 -> -0.49131687 | I7: =(G7-C7)/C7 -> -0.032451576 | J7: ='2026.06'!$L$194 -> 0

Sheet 79U0
A1: 79U0 Amundi S&P 500 II EUR Hedged ETF (Acc)
A3: Data | B3: Suma, EUR | D3: Kiekis | F3: Mėnesio gale | J3: Dividendai | L3: 79U0 | M3: Įnešta | N3: Be dividendų | P3: Su dividendais | R3: Kiekis | S3: Dividendai
B4: Įnešta | C4: Viso | D4: Mėnesio | E4: Viso | F4: Kaina | G4: Vertė | H4: Pelnas | I4: % | N4: Vertė | O4: Pelnas | P4: Vertė | Q4: Pelnas
A5: ='2026.04'!$N$2 -> 2026.04 | B5: ='2026.04'!$B$208-'2026.04'!$G$208 -> 62.07 | C5: =B5 -> 62.07 | D5: ='2026.04'!$D$208-'2026.04'!$I$208 -> 0.33706519 | E5: =D5 -> 0.33706519 | F5: 199.37 | G5: =E5*F5 -> 67.200687 | H5: =G5-C5 -> 5.1306869 | I5: =(G5-C5)/C5 -> 0.08265969 | J5: ='2026.04'!$L$208 -> 0 | L5: Viso: | M5: =SUM(B5:B200) -> 74.46 | N5: =INDEX(G5:G200,MATCH(9.99999999999999E+307,G5:G200)) -> 83.179497 | O5: =INDEX(I5:I200,MATCH(9.99999999999999E+307,I5:I200)) -> 0.11710311 | P5: =N5+S5 -> 83.179497 | Q5: =(P5-M5)/M5 -> 0.11710311 | R5: =SUM(D5:D200) -> 0.39622492 | S5: =SUM(J5:J200) -> 0
A6: ='2026.05'!$N$2 -> 2026.05 | B6: ='2026.05'!$B$208-'2026.05'!$G$208 -> 10.1 | C6: =C5+B6 -> 72.17 | D6: ='2026.05'!$D$208-'2026.05'!$I$208 -> 0.04824457 | E6: =E5+D6 -> 0.38530976 | F6: 209.52 | G6: =E6*F6 -> 80.730101 | H6: =G6-C6 -> 8.5601009 | I6: =(G6-C6)/C6 -> 0.11861024 | J6: ='2026.05'!$L$208 -> 0
A7: ='2026.06'!$N$2 -> 2026.06 | B7: ='2026.06'!$B$208-'2026.06'!$G$208 -> 2.29 | C7: =C6+B7 -> 74.46 | D7: ='2026.06'!$D$208-'2026.06'!$I$208 -> 0.01091516 | E7: =E6+D7 -> 0.39622492 | F7: 209.93 | G7: =E7*F7 -> 83.179497 | H7: =G7-C7 -> 8.7194975 | I7: =(G7-C7)/C7 -> 0.11710311 | J7: ='2026.06'!$L$208 -> 0

Sheet LYTR
A1: LYTR Amundi Bloomberg Equal-weight Commodity ex-Agriculture (Acc) ETF
A3: Data | B3: Suma, EUR | D3: Kiekis | F3: Mėnesio gale | J3: Dividendai | L3: LYTR | M3: Įnešta | N3: Be dividendų | P3: Su dividendais | R3: Kiekis | S3: Dividendai
B4: Įnešta | C4: Viso | D4: Mėnesio | E4: Viso | F4: Kaina | G4: Vertė | H4: Pelnas | I4: % | N4: Vertė | O4: Pelnas | P4: Vertė | Q4: Pelnas
A5: ='2026.05'!$N$2 -> 2026.05 | B5: ='2026.05'!$B$418-'2026.05'!$G$418 -> 9.42 | C5: =B5 -> 9.42 | D5: ='2026.05'!$D$418-'2026.05'!$I$418 -> 0.25713326 | E5: =D5 -> 0.25713326 | F5: 36.44 | G5: =E5*F5 -> 9.369936 | H5: =G5-C5 -> -0.050064006 | I5: =(G5-C5)/C5 -> -0.0053146503 | J5: ='2026.05'!$L$418 -> 0 | L5: Viso: | M5: =SUM(B5:B200) -> 9.71 | N5: =INDEX(G5:G200,MATCH(9.99999999999999E+307,G5:G200)) -> 9.799338 | O5: =INDEX(I5:I200,MATCH(9.99999999999999E+307,I5:I200)) -> 0.0092006144 | P5: =N5+S5 -> 9.799338 | Q5: =(P5-M5)/M5 -> 0.0092006144 | R5: =SUM(D5:D200) -> 0.26499021 | S5: =SUM(J5:J200) -> 0
A6: ='2026.06'!$N$2 -> 2026.06 | B6: ='2026.06'!$B$418-'2026.06'!$G$418 -> 0.29 | C6: =C5+B6 -> 9.71 | D6: ='2026.06'!$D$418-'2026.06'!$I$418 -> 0.00785695 | E6: =E5+D6 -> 0.26499021 | F6: 36.98 | G6: =E6*F6 -> 9.799338 | H6: =G6-C6 -> 0.089337966 | I6: =(G6-C6)/C6 -> 0.0092006144 | J6: ='2026.06'!$L$418 -> 0

Sheet PRAJ
A1: PRAJ Amundi Prime Japan UCITS ETF DR (Acc)
A3: Data | B3: Suma, EUR | D3: Kiekis | F3: Mėnesio gale | J3: Dividendai | L3: PRAJ | M3: Įnešta | N3: Be dividendų | P3: Su dividendais | R3: Kiekis | S3: Dividendai
B4: Įnešta | C4: Viso | D4: Mėnesio | E4: Viso | F4: Kaina | G4: Vertė | H4: Pelnas | I4: % | N4: Vertė | O4: Pelnas | P4: Vertė | Q4: Pelnas
A5: ='2026.04'!$N$2 -> 2026.04 | B5: ='2026.04'!$B$222-'2026.04'!$G$222 -> 17.34 | C5: =B5 -> 17.34 | D5: ='2026.04'!$D$222-'2026.04'!$I$222 -> 0.52293969 | E5: =D5 -> 0.52293969 | F5: 33.75 | G5: =E5*F5 -> 17.649215 | H5: =G5-C5 -> 0.30921454 | I5: =(G5-C5)/C5 -> 0.017832442 | J5: ='2026.04'!$L$222 -> 0 | L5: Viso: | M5: =SUM(B5:B200) -> 18.37 | N5: =INDEX(G5:G200,MATCH(9.99999999999999E+307,G5:G200)) -> 19.500789 | O5: =INDEX(I5:I200,MATCH(9.99999999999999E+307,I5:I200)) -> 0.061556298 | P5: =N5+S5 -> 19.500789 | Q5: =(P5-M5)/M5 -> 0.061556298 | R5: =SUM(D5:D200) -> 0.5519612 | S5: =SUM(J5:J200) -> 0
A6: ='2026.05'!$N$2 -> 2026.05 | B6: ='2026.05'!$B$222-'2026.05'!$G$222 -> 0.5 | C6: =C5+B6 -> 17.84 | D6: ='2026.05'!$D$222-'2026.05'!$I$222 -> 0.01403706 | E6: =E5+D6 -> 0.53697675 | F6: 35.38 | G6: =E6*F6 -> 18.998237 | H6: =G6-C6 -> 1.1582374 | I6: =(G6-C6)/C6 -> 0.064923622 | J6: ='2026.05'!$L$222 -> 0
A7: ='2026.06'!$N$2 -> 2026.06 | B7: ='2026.06'!$B$222-'2026.06'!$G$222 -> 0.53 | C7: =C6+B7 -> 18.37 | D7: ='2026.06'!$D$222-'2026.06'!$I$222 -> 0.01498445 | E7: =E6+D7 -> 0.5519612 | F7: 35.33 | G7: =E7*F7 -> 19.500789 | H7: =G7-C7 -> 1.1307892 | I7: =(G7-C7)/C7 -> 0.061556298 | J7: ='2026.06'!$L$222 -> 0

Sheet LEMA
A1: LEMA Amundi MSCI Emerging Markets ETF (Acc)
A3: Data | B3: Suma, EUR | D3: Kiekis | F3: Mėnesio gale | J3: Dividendai | L3: LEMA | M3: Įnešta | N3: Be dividendų | P3: Su dividendais | R3: Kiekis | S3: Dividendai
B4: Įnešta | C4: Viso | D4: Mėnesio | E4: Viso | F4: Kaina | G4: Vertė | H4: Pelnas | I4: % | N4: Vertė | O4: Pelnas | P4: Vertė | Q4: Pelnas
A5: ='2026.04'!$N$2 -> 2026.04 | B5: ='2026.04'!$B$236-'2026.04'!$G$236 -> 22.95 | C5: =B5 -> 22.95 | D5: ='2026.04'!$D$236-'2026.04'!$I$236 -> 0.36169154 | E5: =D5 -> 0.36169154 | F5: 69.56 | G5: =E5*F5 -> 25.159264 | H5: =G5-C5 -> 2.2092635 | I5: =(G5-C5)/C5 -> 0.096264206 | J5: ='2026.04'!$L$236 -> 0 | L5: Viso: | M5: =SUM(B5:B200) -> 25.77 | N5: =INDEX(G5:G200,MATCH(9.99999999999999E+307,G5:G200)) -> 30.699283 | O5: =INDEX(I5:I200,MATCH(9.99999999999999E+307,I5:I200)) -> 0.19127989 | P5: =N5+S5 -> 30.699283 | Q5: =(P5-M5)/M5 -> 0.19127989 | R5: =SUM(D5:D200) -> 0.39884738 | S5: =SUM(J5:J200) -> 0
A6: ='2026.05'!$N$2 -> 2026.05 | B6: ='2026.05'!$B$236-'2026.05'!$G$236 -> 2.54 | C6: =C5+B6 -> 25.49 | D6: ='2026.05'!$D$236-'2026.05'!$I$236 -> 0.03349333 | E6: =E5+D6 -> 0.39518487 | F6: 75.43 | G6: =E6*F6 -> 29.808795 | H6: =G6-C6 -> 4.3187947 | I6: =(G6-C6)/C6 -> 0.16943094 | J6: ='2026.05'!$L$236 -> 0
A7: ='2026.06'!$N$2 -> 2026.06 | B7: ='2026.06'!$B$236-'2026.06'!$G$236 -> 0.28 | C7: =C6+B7 -> 25.77 | D7: ='2026.06'!$D$236-'2026.06'!$I$236 -> 0.00366251 | E7: =E6+D7 -> 0.39884738 | F7: 76.97 | G7: =E7*F7 -> 30.699283 | H7: =G7-C7 -> 4.9292828 | I7: =(G7-C7)/C7 -> 0.19127989 | J7: ='2026.06'!$L$236 -> 0

Sheet AEYH
A1: AEHY Amundi EUR High Yield Corporate Bond ETF (Acc)
A3: Data | B3: Suma, EUR | D3: Kiekis | F3: Mėnesio gale | J3: Dividendai | L3: AEYH | M3: Įnešta | N3: Be dividendų | P3: Su dividendais | R3: Kiekis | S3: Dividendai
B4: Įnešta | C4: Viso | D4: Mėnesio | E4: Viso | F4: Kaina | G4: Vertė | H4: Pelnas | I4: % | N4: Vertė | O4: Pelnas | P4: Vertė | Q4: Pelnas
A5: ='2026.04'!$N$2 -> 2026.04 | B5: ='2026.04'!$B$250-'2026.04'!$G$250 -> 15.62 | C5: =B5 -> 15.62 | D5: ='2026.04'!$D$250-'2026.04'!$I$250 -> 1.5340178 | E5: =D5 -> 1.5340178 | F5: 10.22 | G5: =E5*F5 -> 15.677662 | H5: =G5-C5 -> 0.057661609 | I5: =(G5-C5)/C5 -> 0.0036915243 | J5: ='2026.04'!$L$250 -> 0 | L5: Viso: | M5: =SUM(B5:B200) -> 19.36 | N5: =INDEX(G5:G200,MATCH(9.99999999999999E+307,G5:G200)) -> 19.554854 | O5: =INDEX(I5:I200,MATCH(9.99999999999999E+307,I5:I200)) -> 0.010064748 | P5: =N5+S5 -> 19.554854 | Q5: =(P5-M5)/M5 -> 0.010064748 | R5: =SUM(D5:D200) -> 1.8930158 | S5: =SUM(J5:J200) -> 0
A6: ='2026.05'!$N$2 -> 2026.05 | B6: ='2026.05'!$B$250-'2026.05'!$G$250 -> 3.03 | C6: =C5+B6 -> 18.65 | D6: ='2026.05'!$D$250-'2026.05'!$I$250 -> 0.29070585 | E6: =E5+D6 -> 1.8247236 | F6: 10.34 | G6: =E6*F6 -> 18.867642 | H6: =G6-C6 -> 0.21764223 | I6: =(G6-C6)/C6 -> 0.011669825 | J6: ='2026.05'!$L$250 -> 0
A7: ='2026.06'!$N$2 -> 2026.06 | B7: ='2026.06'!$B$250-'2026.06'!$G$250 -> 0.71 | C7: =C6+B7 -> 19.36 | D7: ='2026.06'!$D$250-'2026.06'!$I$250 -> 0.06829221 | E7: =E6+D7 -> 1.8930158 | F7: 10.33 | G7: =E7*F7 -> 19.554854 | H7: =G7-C7 -> 0.19485352 | I7: =(G7-C7)/C7 -> 0.010064748 | J7: ='2026.06'!$L$250 -> 0

Sheet EMBH
A1: EMBH Amundi USD Emerging Markets Government Bond UCITS ETF EUR Hedged (Dist)
A3: Data | B3: Suma, EUR | D3: Kiekis | F3: Mėnesio gale | J3: Dividendai | L3: EMBH | M3: Įnešta | N3: Be dividendų | P3: Su dividendais | R3: Kiekis | S3: Dividendai
B4: Įnešta | C4: Viso | D4: Mėnesio | E4: Viso | F4: Kaina | G4: Vertė | H4: Pelnas | I4: % | N4: Vertė | O4: Pelnas | P4: Vertė | Q4: Pelnas
A5: ='2026.04'!$N$2 -> 2026.04 | B5: ='2026.04'!$B$264-'2026.04'!$G$264 -> 24.74 | C5: =B5 -> 24.74 | D5: ='2026.04'!$D$264-'2026.04'!$I$264 -> 0.38260589 | E5: =D5 -> 0.38260589 | F5: 65.24 | G5: =E5*F5 -> 24.961208 | H5: =G5-C5 -> 0.22120826 | I5: =(G5-C5)/C5 -> 0.0089413203 | J5: ='2026.04'!$L$264 -> 0 | L5: Viso: | M5: =SUM(B5:B200) -> 31.31 | N5: =INDEX(G5:G200,MATCH(9.99999999999999E+307,G5:G200)) -> 31.780642 | O5: =INDEX(I5:I200,MATCH(9.99999999999999E+307,I5:I200)) -> 0.015031697 | P5: =N5+S5 -> 31.780642 | Q5: =(P5-M5)/M5 -> 0.015031697 | R5: =SUM(D5:D200) -> 0.48240198 | S5: =SUM(J5:J200) -> 0
A6: ='2026.05'!$N$2 -> 2026.05 | B6: ='2026.05'!$B$264-'2026.05'!$G$264 -> 5.56 | C6: =C5+B6 -> 30.3 | D6: ='2026.05'!$D$264-'2026.05'!$I$264 -> 0.08447216 | E6: =E5+D6 -> 0.46707805 | F6: 65.9 | G6: =E6*F6 -> 30.780443 | H6: =G6-C6 -> 0.4804435 | I6: =(G6-C6)/C6 -> 0.015856221 | J6: ='2026.05'!$L$264 -> 0
A7: ='2026.06'!$N$2 -> 2026.06 | B7: ='2026.06'!$B$264-'2026.06'!$G$264 -> 1.01 | C7: =C6+B7 -> 31.31 | D7: ='2026.06'!$D$264-'2026.06'!$I$264 -> 0.01532393 | E7: =E6+D7 -> 0.48240198 | F7: 65.88 | G7: =E7*F7 -> 31.780642 | H7: =G7-C7 -> 0.47064244 | I7: =(G7-C7)/C7 -> 0.015031697 | J7: ='2026.06'!$L$264 -> 0

Sheet LYMS
A1: LYMS Amundi Nasdaq-100 II UCITS ETF (Acc)
A3: Data | B3: Suma, EUR | D3: Kiekis | F3: Mėnesio gale | J3: Dividendai | L3: LYMS | M3: Įnešta | N3: Be dividendų | P3: Su dividendais | R3: Kiekis | S3: Dividendai
B4: Įnešta | C4: Viso | D4: Mėnesio | E4: Viso | F4: Kaina | G4: Vertė | H4: Pelnas | I4: % | N4: Vertė | O4: Pelnas | P4: Vertė | Q4: Pelnas
A5: ='2026.04'!$N$2 -> 2026.04 | B5: ='2026.04'!$B$292-'2026.04'!$G$292 -> 36.05 | C5: =B5 -> 36.05 | D5: ='2026.04'!$D$292-'2026.04'!$I$292 -> 0.42365239 | E5: =D5 -> 0.42365239 | F5: 95.13 | G5: =E5*F5 -> 40.302052 | H5: =G5-C5 -> 4.2520519 | I5: =(G5-C5)/C5 -> 0.11794873 | J5: ='2026.04'!$L$292 -> 0 | L5: Viso: | M5: =SUM(B5:B200) -> 39.98 | N5: =INDEX(G5:G200,MATCH(9.99999999999999E+307,G5:G200)) -> 49.13136 | O5: =INDEX(I5:I200,MATCH(9.99999999999999E+307,I5:I200)) -> 0.22889845 | P5: =N5+S5 -> 49.13136 | Q5: =(P5-M5)/M5 -> 0.22889845 | R5: =SUM(D5:D200) -> 0.46072168 | S5: =SUM(J5:J200) -> 0
A6: ='2026.05'!$N$2 -> 2026.05 | B6: ='2026.05'!$B$292-'2026.05'!$G$292 -> 2.71 | C6: =C5+B6 -> 38.76 | D6: ='2026.05'!$D$292-'2026.05'!$I$292 -> 0.02559018 | E6: =E5+D6 -> 0.44924257 | F6: 105.82 | G6: =E6*F6 -> 47.538849 | H6: =G6-C6 -> 8.7788488 | I6: =(G6-C6)/C6 -> 0.22649249 | J6: ='2026.05'!$L$292 -> 0
A7: ='2026.06'!$N$2 -> 2026.06 | B7: ='2026.06'!$B$292-'2026.06'!$G$292 -> 1.22 | C7: =C6+B7 -> 39.98 | D7: ='2026.06'!$D$292-'2026.06'!$I$292 -> 0.01147911 | E7: =E6+D7 -> 0.46072168 | F7: 106.64 | G7: =E7*F7 -> 49.13136 | H7: =G7-C7 -> 9.15136 | I7: =(G7-C7)/C7 -> 0.22889845 | J7: ='2026.06'!$L$292 -> 0

Sheet EBUY
A1: EBUY Amundi MSCI Digital Economy and Metaverse ESG Screened UCITS ETF (Acc)
A3: Data | B3: Suma, EUR | D3: Kiekis | F3: Mėnesio gale | J3: Dividendai | L3: EBUY | M3: Įnešta | N3: Be dividendų | P3: Su dividendais | R3: Kiekis | S3: Dividendai
B4: Įnešta | C4: Viso | D4: Mėnesio | E4: Viso | F4: Kaina | G4: Vertė | H4: Pelnas | I4: % | N4: Vertė | O4: Pelnas | P4: Vertė | Q4: Pelnas
A5: ='2026.04'!$N$2 -> 2026.04 | B5: ='2026.04'!$B$278-'2026.04'!$G$278 -> 9.69 | C5: =B5 -> 9.69 | D5: ='2026.04'!$D$278-'2026.04'!$I$278 -> 0.61320171 | E5: =D5 -> 0.61320171 | F5: 18.07 | G5: =E5*F5 -> 11.080555 | H5: =G5-C5 -> 1.3905549 | I5: =(G5-C5)/C5 -> 0.14350412 | J5: ='2026.04'!$L$278 -> 0 | L5: Viso: | M5: =SUM(B5:B200) -> 11.82 | N5: =INDEX(G5:G200,MATCH(9.99999999999999E+307,G5:G200)) -> 15.056941 | O5: =INDEX(I5:I200,MATCH(9.99999999999999E+307,I5:I200)) -> 0.27385285 | P5: =N5+S5 -> 15.056941 | Q5: =(P5-M5)/M5 -> 0.27385285 | R5: =SUM(D5:D200) -> 0.71905161 | S5: =SUM(J5:J200) -> 0
A6: ='2026.05'!$N$2 -> 2026.05 | B6: ='2026.05'!$B$278-'2026.05'!$G$278 -> 2.03 | C6: =C5+B6 -> 11.72 | D6: ='2026.05'!$D$278-'2026.05'!$I$278 -> 0.10102015 | E6: =E5+D6 -> 0.71422186 | F6: 20.29 | G6: =E6*F6 -> 14.491562 | H6: =G6-C6 -> 2.7715615 | I6: =(G6-C6)/C6 -> 0.23648136 | J6: ='2026.05'!$L$278 -> 0
A7: ='2026.06'!$N$2 -> 2026.06 | B7: ='2026.06'!$B$278-'2026.06'!$G$278 -> 0.1 | C7: =C6+B7 -> 11.82 | D7: ='2026.06'!$D$278-'2026.06'!$I$278 -> 0.00482975 | E7: =E6+D7 -> 0.71905161 | F7: 20.94 | G7: =E7*F7 -> 15.056941 | H7: =G7-C7 -> 3.2369407 | I7: =(G7-C7)/C7 -> 0.27385285 | J7: ='2026.06'!$L$278 -> 0

Sheet TRDE
A1: TRDE Invesco US Treasury Bond 7-10 Year EUR-hedged Dist ETF
A3: Data | B3: Suma, EUR | D3: Kiekis | F3: Mėnesio gale | J3: Dividendai | L3: TRDE | M3: Įnešta | N3: Be dividendų | P3: Su dividendais | R3: Kiekis | S3: Dividendai
B4: Įnešta | C4: Viso | D4: Mėnesio | E4: Viso | F4: Kaina | G4: Vertė | H4: Pelnas | I4: % | N4: Vertė | O4: Pelnas | P4: Vertė | Q4: Pelnas
A5: ='2026.04'!$N$2 -> 2026.04 | B5: ='2026.04'!$B$320-'2026.04'!$G$320 -> 33.49 | C5: =B5 -> 33.49 | D5: ='2026.04'!$D$320-'2026.04'!$I$320 -> 1.0892835 | E5: =D5 -> 1.0892835 | F5: 30.63 | G5: =E5*F5 -> 33.364755 | H5: =G5-C5 -> -0.12524548 | I5: =(G5-C5)/C5 -> -0.0037397873 | J5: ='2026.04'!$L$320 -> 0 | L5: Viso: | M5: =SUM(B5:B200) -> 32.07 | N5: =INDEX(G5:G200,MATCH(9.99999999999999E+307,G5:G200)) -> 31.730975 | O5: =INDEX(I5:I200,MATCH(9.99999999999999E+307,I5:I200)) -> -0.01057142 | P5: =N5+S5 -> 31.730975 | Q5: =(P5-M5)/M5 -> -0.01057142 | R5: =SUM(D5:D200) -> 1.0420681 | S5: =SUM(J5:J200) -> 0
A6: ='2026.05'!$N$2 -> 2026.05 | B6: ='2026.05'!$B$320-'2026.05'!$G$320 -> -2.52 | C6: =C5+B6 -> 30.97 | D6: ='2026.05'!$D$320-'2026.05'!$I$320 -> -0.08335088 | E6: =E5+D6 -> 1.0059326 | F6: 30.58 | G6: =E6*F6 -> 30.76142 | H6: =G6-C6 -> -0.20857956 | I6: =(G6-C6)/C6 -> -0.0067348906 | J6: ='2026.05'!$L$320 -> 0
A7: ='2026.06'!$N$2 -> 2026.06 | B7: ='2026.06'!$B$320-'2026.06'!$G$320 -> 1.1 | C7: =C6+B7 -> 32.07 | D7: ='2026.06'!$D$320-'2026.06'!$I$320 -> 0.03613548 | E7: =E6+D7 -> 1.0420681 | F7: 30.45 | G7: =E7*F7 -> 31.730975 | H7: =G7-C7 -> -0.33902544 | I7: =(G7-C7)/C7 -> -0.01057142 | J7: ='2026.06'!$L$320 -> 0

Sheet PRAC
A1: PRAC Amundi EUR Corporate Bond UCITS ETF DR – EUR (Acc)
A3: Data | B3: Suma, EUR | D3: Kiekis | F3: Mėnesio gale | J3: Dividendai | L3: PRAC | M3: Įnešta | N3: Be dividendų | P3: Su dividendais | R3: Kiekis | S3: Dividendai
B4: Įnešta | C4: Viso | D4: Mėnesio | E4: Viso | F4: Kaina | G4: Vertė | H4: Pelnas | I4: % | N4: Vertė | O4: Pelnas | P4: Vertė | Q4: Pelnas
A5: ='2026.04'!$N$2 -> 2026.04 | B5: ='2026.04'!$B$334-'2026.04'!$G$334 -> 36.66 | C5: =B5 -> 36.66 | D5: ='2026.04'!$D$334-'2026.04'!$I$334 -> 1.8307115 | E5: =D5 -> 1.8307115 | F5: 20.12 | G5: =E5*F5 -> 36.833916 | H5: =G5-C5 -> 0.17391639 | I5: =(G5-C5)/C5 -> 0.0047440367 | J5: ='2026.04'!$L$334 -> 0 | L5: Viso: | M5: =SUM(B5:B200) -> 33.78 | N5: =INDEX(G5:G200,MATCH(9.99999999999999E+307,G5:G200)) -> 34.172677 | O5: =INDEX(I5:I200,MATCH(9.99999999999999E+307,I5:I200)) -> 0.011624535 | P5: =N5+S5 -> 34.172677 | Q5: =(P5-M5)/M5 -> 0.011624535 | R5: =SUM(D5:D200) -> 1.6883734 | S5: =SUM(J5:J200) -> 0
A6: ='2026.05'!$N$2 -> 2026.05 | B6: ='2026.05'!$B$334-'2026.05'!$G$334 -> -4.07 | C6: =C5+B6 -> 32.59 | D6: ='2026.05'!$D$334-'2026.05'!$I$334 -> -0.20101958 | E6: =E5+D6 -> 1.629692 | F6: 20.31 | G6: =E6*F6 -> 33.099044 | H6: =G6-C6 -> 0.50904391 | I6: =(G6-C6)/C6 -> 0.015619635 | J6: ='2026.05'!$L$334 -> 0
A7: ='2026.06'!$N$2 -> 2026.06 | B7: ='2026.06'!$B$334-'2026.06'!$G$334 -> 1.19 | C7: =C6+B7 -> 33.78 | D7: ='2026.06'!$D$334-'2026.06'!$I$334 -> 0.05868139 | E7: =E6+D7 -> 1.6883734 | F7: 20.24 | G7: =E7*F7 -> 34.172677 | H7: =G7-C7 -> 0.39267681 | I7: =(G7-C7)/C7 -> 0.011624535 | J7: ='2026.06'!$L$334 -> 0

Sheet LYP6
A1: LYP6 Amundi Stoxx Europe 600 UCITS ETF (Acc)
A3: Data | B3: Suma, EUR | D3: Kiekis | F3: Mėnesio gale | J3: Dividendai | L3: LYP6 | M3: Įnešta | N3: Be dividendų | P3: Su dividendais | R3: Kiekis | S3: Dividendai
B4: Įnešta | C4: Viso | D4: Mėnesio | E4: Viso | F4: Kaina | G4: Vertė | H4: Pelnas | I4: % | N4: Vertė | O4: Pelnas | P4: Vertė | Q4: Pelnas
A5: ='2026.04'!$N$2 -> 2026.04 | B5: ='2026.04'!$B$362-'2026.04'!$G$362 -> 62.86 | C5: =B5 -> 62.86 | D5: ='2026.04'!$D$362-'2026.04'!$I$362 -> 0.21564058 | E5: =D5 -> 0.21564058 | F5: 298.13 | G5: =E5*F5 -> 64.288926 | H5: =G5-C5 -> 1.4289261 | I5: =(G5-C5)/C5 -> 0.022731882 | J5: ='2026.04'!$L$362 -> 0 | L5: Viso: | M5: =SUM(B5:B200) -> 67.5 | N5: =INDEX(G5:G200,MATCH(9.99999999999999E+307,G5:G200)) -> 70.720433 | O5: =INDEX(I5:I200,MATCH(9.99999999999999E+307,I5:I200)) -> 0.047710117 | P5: =N5+S5 -> 70.720433 | Q5: =(P5-M5)/M5 -> 0.047710117 | R5: =SUM(D5:D200) -> 0.23118052 | S5: =SUM(J5:J200) -> 0
A6: ='2026.05'!$N$2 -> 2026.05 | B6: ='2026.05'!$B$362-'2026.05'!$G$362 -> 2.07 | C6: =C5+B6 -> 64.93 | D6: ='2026.05'!$D$362-'2026.05'!$I$362 -> 0.00711647 | E6: =E5+D6 -> 0.22275705 | F6: 306.12 | G6: =E6*F6 -> 68.190388 | H6: =G6-C6 -> 3.2603881 | I6: =(G6-C6)/C6 -> 0.050213894 | J6: ='2026.05'!$L$362 -> 0
A7: ='2026.06'!$N$2 -> 2026.06 | B7: ='2026.06'!$B$362-'2026.06'!$G$362 -> 2.57 | C7: =C6+B7 -> 67.5 | D7: ='2026.06'!$D$362-'2026.06'!$I$362 -> 0.00842347 | E7: =E6+D7 -> 0.23118052 | F7: 305.91 | G7: =E7*F7 -> 70.720433 | H7: =G7-C7 -> 3.2204329 | I7: =(G7-C7)/C7 -> 0.047710117 | J7: ='2026.06'!$L$362 -> 0

Sheet UBUD
A1: UBUD UBS Solactive Global Pure Gold Miners UCITS ETF (Dist)
A3: Data | B3: Suma, EUR | D3: Kiekis | F3: Mėnesio gale | J3: Dividendai | L3: UBUD | M3: Įnešta | N3: Be dividendų | P3: Su dividendais | R3: Kiekis | S3: Dividendai
B4: Įnešta | C4: Viso | D4: Mėnesio | E4: Viso | F4: Kaina | G4: Vertė | H4: Pelnas | I4: % | N4: Vertė | O4: Pelnas | P4: Vertė | Q4: Pelnas
A5: ='2026.04'!$N$2 -> 2026.04 | B5: ='2026.04'!$B$306-'2026.04'!$G$306 -> 6.37 | C5: =B5 -> 6.37 | D5: ='2026.04'!$D$306-'2026.04'!$I$306 -> 0.12975614 | E5: =D5 -> 0.12975614 | F5: 45.32 | G5: =E5*F5 -> 5.8805483 | H5: =G5-C5 -> -0.48945174 | I5: =(G5-C5)/C5 -> -0.076837007 | J5: ='2026.04'!$L$306 -> 0 | L5: Viso: | M5: 7.51 | N5: 6.45 | O5: =INDEX(I5:I100,MATCH(9.99999999999999E+307,I5:I100)) -> -1 | P5: =N5+S5 -> 6.45 | Q5: =(P5-M5)/M5 -> -0.14114514 | R5: 0.15515585 | S5: =SUM(J5:J67) -> 0
A6: ='2026.05'!$N$2 -> 2026.05 | B6: ='2026.05'!$B$306-'2026.05'!$G$306 -> -5.33 | C6: =C5+B6 -> 1.04 | D6: ='2026.05'!$D$306-'2026.05'!$I$306 -> -0.12975614 | E6: =E5+D6 -> 0 | F6: 41.57 | G6: =E6*F6 -> 0 | H6: =G6-C6 -> -1.04 | I6: =(G6-C6)/C6 -> -1 | J6: ='2026.05'!$L$306 -> 0

Sheet 2B72
A1: 2B72 iShares MSCI Europe Mid Cap ETF (Acc)
A3: Data | B3: Suma, EUR | D3: Kiekis | F3: Mėnesio gale | J3: Dividendai | L3: 2B72 | M3: Įnešta | N3: Be dividendų | P3: Su dividendais | R3: Kiekis | S3: Dividendai
B4: Įnešta | C4: Viso | D4: Mėnesio | E4: Viso | F4: Kaina | G4: Vertė | H4: Pelnas | I4: % | N4: Vertė | O4: Pelnas | P4: Vertė | Q4: Pelnas
A5: ='2026.04'!$N$2 -> 2026.04 | B5: ='2026.04'!$B$348-'2026.04'!$G$348 -> 9.72 | C5: =B5 -> 9.72 | D5: ='2026.04'!$D$348-'2026.04'!$I$348 -> 1.0089315 | E5: =D5 -> 1.0089315 | F5: 9.76 | G5: =E5*F5 -> 9.8471713 | H5: =G5-C5 -> 0.12717134 | I5: =(G5-C5)/C5 -> 0.013083471 | J5: ='2026.04'!$L$348 -> 0 | L5: Viso: | M5: 9.72 | N5: 10 | O5: =INDEX(I5:I100,MATCH(9.99999999999999E+307,I5:I100)) -> -1 | P5: =N5+S5 -> 10 | Q5: =(P5-M5)/M5 -> 0.028806584 | R5: 1.0089315 | S5: =SUM(J5:J67) -> 0
A6: ='2026.05'!$N$2 -> 2026.05 | B6: ='2026.05'!$B$348-'2026.05'!$G$348 -> -10 | C6: =C5+B6 -> -0.28 | D6: ='2026.05'!$D$348-'2026.05'!$I$348 -> -1.0089315 | E6: =E5+D6 -> 0 | F6: 9.91 | G6: =E6*F6 -> 0 | H6: =G6-C6 -> 0.28 | I6: =(G6-C6)/C6 -> -1 | J6: ='2026.05'!$L$348 -> 0

Sheet LYP5
A1: LYP5 Amundi S&P 500 II ETF (Acc)
A3: Data | B3: Suma, EUR | D3: Kiekis | F3: Mėnesio gale | J3: Dividendai | L3: LYP5 | M3: Įnešta | N3: Be dividendų | P3: Su dividendais | R3: Kiekis | S3: Dividendai
B4: Įnešta | C4: Viso | D4: Mėnesio | E4: Viso | F4: Kaina | G4: Vertė | H4: Pelnas | I4: % | N4: Vertė | O4: Pelnas | P4: Vertė | Q4: Pelnas
A5: ='2026.04'!$N$2 -> 2026.04 | B5: ='2026.04'!$B$376-'2026.04'!$G$376 -> 9.43 | C5: =B5 -> 9.43 | D5: ='2026.04'!$D$376-'2026.04'!$I$376 -> 0.02316283 | E5: =D5 -> 0.02316283 | F5: 445.54 | G5: =E5*F5 -> 10.319967 | H5: =G5-C5 -> 0.88996728 | I5: =(G5-C5)/C5 -> 0.094376169 | J5: ='2026.04'!$L$376 -> 0 | L5: Viso: | M5: 9.43 | N5: 10.85 | O5: =INDEX(I5:I100,MATCH(9.99999999999999E+307,I5:I100)) -> -1 | P5: =N5+S5 -> 10.85 | Q5: =(P5-M5)/M5 -> 0.15058324 | R5: 0.02316283 | S5: =SUM(J5:J67) -> 0
A6: ='2026.05'!$N$2 -> 2026.05 | B6: ='2026.05'!$B$376-'2026.05'!$G$376 -> -10.85 | C6: =C5+B6 -> -1.42 | D6: ='2026.05'!$D$376-'2026.05'!$I$376 -> -0.02316283 | E6: =E5+D6 -> 0 | F6: 468.42 | G6: =E6*F6 -> 0 | H6: =G6-C6 -> 1.42 | I6: =(G6-C6)/C6 -> -1 | J6: ='2026.05'!$L$376 -> 0

Sheet LGQK
A1: LGQK Amundi MSCI Pacific Ex Japan UCITS ETF (Dist)
A3: Data | B3: Suma, EUR | D3: Kiekis | F3: Mėnesio gale | J3: Dividendai | L3: LGQK | M3: Įnešta | N3: Be dividendų | P3: Su dividendais | R3: Kiekis | S3: Dividendai
B4: Įnešta | C4: Viso | D4: Mėnesio | E4: Viso | F4: Kaina | G4: Vertė | H4: Pelnas | I4: % | N4: Vertė | O4: Pelnas | P4: Vertė | Q4: Pelnas
A5: ='2026.04'!$N$2 -> 2026.04 | B5: ='2026.04'!$B$390-'2026.04'!$G$390 -> 2.11 | C5: =B5 -> 2.11 | D5: ='2026.04'!$D$390-'2026.04'!$I$390 -> 0.02070819 | E5: =D5 -> 0.02070819 | F5: 104.31 | G5: =E5*F5 -> 2.1600713 | H5: =G5-C5 -> 0.050071299 | I5: =(G5-C5)/C5 -> 0.023730473 | J5: ='2026.04'!$L$390 -> 0 | L5: Viso: | M5: 2.11 | N5: 2.14 | O5: =INDEX(I5:I100,MATCH(9.99999999999999E+307,I5:I100)) -> -1 | P5: =N5+S5 -> 2.14 | Q5: =(P5-M5)/M5 -> 0.014218009 | R5: 0.20070819 | S5: =SUM(J5:J67) -> 0
A6: ='2026.05'!$N$2 -> 2026.05 | B6: ='2026.05'!$B$390-'2026.05'!$G$390 -> -2.14 | C6: =C5+B6 -> -0.03 | D6: ='2026.05'!$D$390-'2026.05'!$I$390 -> -0.02070819 | E6: =E5+D6 -> 0 | F6: 103.34 | G6: =E6*F6 -> 0 | H6: =G6-C6 -> 0.03 | I6: =(G6-C6)/C6 -> -1 | J6: ='2026.05'!$L$390 -> 0

Sheet XDWT
A1: XDWT Xtrackers MSCI World Inform. (Acc)
A3: Data | B3: Suma, EUR | D3: Kiekis | F3: Mėnesio gale | J3: Dividendai | L3: XDWT | M3: Įnešta | N3: Be dividendų | P3: Su dividendais | R3: Kiekis | S3: Dividendai
B4: Įnešta | C4: Viso | D4: Mėnesio | E4: Viso | F4: Kaina | G4: Vertė | H4: Pelnas | I4: % | N4: Vertė | O4: Pelnas | P4: Vertė | Q4: Pelnas
A5: ='2024.02'!A1 -> 2024.02 | B5: ='2024.02'!B18 -> 10 | C5: =B5 -> 10 | D5: ='2024.02'!D18 -> 0.13644426 | E5: =D5 -> 0.13644426 | F5: 73.07 | G5: =E5*F5 -> 9.9699821 | H5: =G5-C5 -> -0.030017922 | I5: =(G5-C5)/C5 -> -0.0030017922 | J5: ='2024.02'!E18 -> 0 | L5: Viso: | M5: =SUM(B5:B67) -> 38.17 | N5: =INDEX(G5:G100,MATCH(9.99999999999999E+307,G5:G100)) -> 42.120533 | O5: =INDEX(I5:I100,MATCH(9.99999999999999E+307,I5:I100)) -> 0.10349839 | P5: =N5+S5 -> 42.120533 | Q5: =(P5-M5)/M5 -> 0.10349839 | R5: =SUM(D5:D67) -> 0.45882934 | S5: =SUM(J5:J67) -> 0
A6: ='2024.03'!A1 -> 2024.03 | B6: ='2024.03'!B18 -> 0 | C6: =C5+B6 -> 10 | D6: ='2024.03'!D18 -> 0 | E6: =E5+D6 -> 0.13644426 | F6: 74.76 | G6: =E6*F6 -> 10.200573 | H6: =G6-C6 -> 0.20057288 | I6: =(G6-C6)/C6 -> 0.020057288 | J6: ='2024.03'!E18 -> 0
A7: ='2024.04'!A1 -> 2024.04 | B7: ='2024.04'!B18 -> 0 | C7: =C6+B7 -> 10 | D7: ='2024.04'!D18 -> 0 | E7: =E6+D7 -> 0.13644426 | F7: 71.75 | G7: =E7*F7 -> 9.7898757 | H7: =G7-C7 -> -0.21012434 | I7: =(G7-C7)/C7 -> -0.021012434 | J7: ='2024.04'!E18 -> 0
A8: ='2024.05'!A1 -> 2024.05 | B8: ='2024.05'!B18 -> 0 | C8: =C7+B8 -> 10 | D8: ='2024.05'!D18 -> 0 | E8: =E7+D8 -> 0.13644426 | F8: 74.98 | G8: =E8*F8 -> 10.230591 | H8: =G8-C8 -> 0.23059061 | I8: =(G8-C8)/C8 -> 0.023059061 | J8: ='2024.05'!E18 -> 0
A9: ='2024.06'!A1 -> 2024.06 | B9: ='2024.06'!B18 -> 0 | C9: =C8+B9 -> 10 | D9: ='2024.06'!D18 -> 0 | E9: =E8+D9 -> 0.13644426 | F9: 84.28 | G9: =E9*F9 -> 11.499522 | H9: =G9-C9 -> 1.4995222 | I9: =(G9-C9)/C9 -> 0.14995222 | J9: ='2024.06'!E18 -> 0
A10: ='2024.07'!A1 -> 2024.07 | B10: ='2024.07'!B18 -> 0 | C10: =C9+B10 -> 10 | D10: ='2024.07'!D18 -> 0 | E10: =E9+D10 -> 0.13644426 | F10: 81.21 | G10: =E10*F10 -> 11.080638 | H10: =G10-C10 -> 1.0806384 | I10: =(G10-C10)/C10 -> 0.10806384 | J10: ='2024.07'!E18 -> 0
A11: ='2024.08'!A1 -> 2024.08 | B11: ='2024.08'!B18 -> 0 | C11: =C10+B11 -> 10 | D11: ='2024.08'!D18 -> 0 | E11: =E10+D11 -> 0.13644426 | F11: 80.25 | G11: =E11*F11 -> 10.949652 | H11: =G11-C11 -> 0.94965187 | I11: =(G11-C11)/C11 -> 0.094965187 | J11: ='2024.08'!E18 -> 0
A12: ='2024.09'!A1 -> 2024.09 | B12: ='2024.09'!B18 -> 0 | C12: =C11+B12 -> 10 | D12: ='2024.09'!D18 -> 0 | E12: =E11+D12 -> 0.13644426 | F12: 81.21 | G12: =E12*F12 -> 11.080638 | H12: =G12-C12 -> 1.0806384 | I12: =(G12-C12)/C12 -> 0.10806384 | J12: ='2024.09'!E18 -> 0
A13: ='2024.10'!A1 -> 2024.10 | B13: ='2024.10'!B18 -> 0 | C13: =C12+B13 -> 10 | D13: ='2024.10'!D18 -> 0 | E13: =E12+D13 -> 0.13644426 | F13: 83.04 | G13: =E13*F13 -> 11.330331 | H13: =G13-C13 -> 1.3303314 | I13: =(G13-C13)/C13 -> 0.13303314 | J13: ='2024.10'!E18 -> 0
A14: ='2024.11'!A1 -> 2024.11 | B14: ='2024.11'!B18 -> 0 | C14: =C13+B14 -> 10 | D14: ='2024.11'!D18 -> 0 | E14: =E13+D14 -> 0.13644426 | F14: 89.63 | G14: =E14*F14 -> 12.229499 | H14: =G14-C14 -> 2.229499 | I14: =(G14-C14)/C14 -> 0.2229499 | J14: ='2024.11'!E18 -> 0
