Workbook

Sheet Apžvalga
A1: Data | B1: Viso: | E1: Mėnesio gale | P1: Dividendai | Q1: Mokesčiai | AA1: XIRR | AS1: XIRR
B2: Inešta | C2: Išvesta | D2: Investuota | E2: Active 55 | F2: Active 80 | G2: Artificial | H2: Glob. Yield | I2: Glob.Ex.UD | J2: Eur.Ex.UC | K2: US.Ex.UD | L2: Eur.Ex.UD | M2: Vertė | N2: Pelnas | O2: % | Q2: Pirkimas | R2: Pardavimas | S2: Laikymas | AA2: =XIRR(_xlfn.VSTACK('SEB Active 55'!AG5:AG200,'SEB Active 80'!AG5:AG200),_xlfn.VSTACK('SEB Active 55'!AF5:AF200,'SEB Active 80'!AF5:AF200)) -> 0.182 | AS2: =XIRR(_xlfn.VSTACK('SEB Active 55'!AG5:AG200,'SEB Active 80'!AG5:AG200),_xlfn.VSTACK('SEB Active 55'!AF5:AF200,'SEB Active 80'!AF5:AF200)) -> 0.182
A3: ='2025.03'!Q2 -> 2025.03 | B3: ='2025.03'!Q5 -> 60 | C3: ='2025.03'!R5 -> 0 | D3: ='2025.03'!S5 -> 60 | E3: ='SEB Active 55'!H5 -> 29.58 | F3: ='SEB Active 80'!H5 -> 29.36 | G3: 0 | H3: 0 | I3: 0 | J3: 0 | K3: 0 | L3: 0 | M3: =SUM(E3:L3) -> 58.94 | N3: =M3-B3 -> -1.06 | O3: =N3/B3 -> -0.0177 | P3: ='2025.03'!X5 -> 0 | Q3: ='2025.03'!U5 -> 0 | R3: ='2025.03'!W5 -> 0 | S3: ='2025.03'!V5 -> 0
A4: ='2025.04'!Q2 -> 2025.04 | B4: =B3+'2025.04'!Q5 -> 90 | C4: ='2025.04'!R5 -> 0 | D4: =D3+'2025.04'!S5 -> 90 | E4: ='SEB Active 55'!H6 -> 43.89 | F4: ='SEB Active 80'!H6 -> 43.37 | G4: 0 | H4: 0 | I4: 0 | J4: 0 | K4: 0 | L4: 0 | M4: =SUM(E4:L4) -> 87.26 | N4: =M4-B4 -> -2.74 | O4: =N4/B4 -> -0.0304 | P4: ='2025.04'!X5 -> 0 | Q4: ='2025.04'!U5 -> 0 | R4: ='2025.04'!W5 -> 0 | S4: ='2025.04'!V5 -> 0
A5: ='2025.05'!Q2 -> 2025.05 | B5: =B4+'2025.05'!Q5 -> 120 | C5: ='2025.05'!R5 -> 0 | D5: =D4+'2025.05'!S5 -> 120 | E5: ='SEB Active 55'!H7 -> 60.69 | F5: ='SEB Active 80'!H7 -> 61.01 | G5: 0 | H5: 0 | I5: 0 | J5: 0 | K5: 0 | L5: 0 | M5: =SUM(E5:L5) -> 121.7 | N5: =M5-B5 -> 1.7 | O5: =N5/B5 -> 0.0142 | P5: ='2025.05'!X5 -> 0 | Q5: ='2025.05'!U5 -> 0 | R5: ='2025.05'!W5 -> 0 | S5: ='2025.05'!V5 -> 0.02
A6: ='2025.06'!Q2 -> 2025.06 | B6: =B5+'2025.06'!Q5 -> 150 | C6: ='2025.06'!R5 -> 0 | D6: =D5+'2025.06'!S5 -> 150 | E6: ='SEB Active 55'!H8 -> 75.84 | F6: ='SEB Active 80'!H8 -> 75.81 | G6: 0 | H6: 0 | I6: 0 | J6: 0 | K6: 0 | L6: 0 | M6: =SUM(E6:L6) -> 151.65 | N6: =M6-B6 -> 1.65 | O6: =N6/B6 -> 0.011 | P6: ='2025.06'!X5 -> 0 | Q6: ='2025.06'!U5 -> 0 | R6: ='2025.06'!W5 -> 0 | S6: ='2025.06'!V5 -> 0.04
A7: ='2025.07'!Q2 -> 2025.07 | B7: =B6+'2025.07'!Q5 -> 180 | C7: ='2025.07'!R5 -> 0 | D7: =D6+'2025.07'!S5 -> 180 | E7: ='SEB Active 55'!H9 -> 91.88 | F7: ='SEB Active 80'!H9 -> 92.22 | G7: 0 | H7: 0 | I7: 0 | J7: 0 | K7: 0 | L7: 0 | M7: =SUM(E7:L7) -> 184.1 | N7: =M7-B7 -> 4.1 | O7: =N7/B7 -> 0.0228 | P7: ='2025.07'!X5 -> 0 | Q7: ='2025.07'!U5 -> 0 | R7: ='2025.07'!W5 -> 0 | S7: ='2025.07'!V5 -> 0.04
A8: ='2025.08'!Q2 -> 2025.08 | B8: =B7+'2025.08'!Q5 -> 210 | C8: ='2025.08'!R5 -> 0 | D8: =D7+'2025.08'!S5 -> 210 | E8: ='SEB Active 55'!H10 -> 107.17 | F8: ='SEB Active 80'!H10 -> 107.46 | G8: 0 | H8: 0 | I8: 0 | J8: 0 | K8: 0 | L8: 0 | M8: =SUM(E8:L8) -> 214.63 | N8: =M8-B8 -> 4.63 | O8: =N8/B8 -> 0.022 | P8: ='2025.08'!X5 -> 0 | Q8: ='2025.08'!U5 -> 0 | R8: ='2025.08'!W5 -> 0 | S8: ='2025.08'!V5 -> 0.06
A9: ='2025.09'!Q2 -> 2025.09 | B9: =B8+'2025.09'!Q5 -> 240 | C9: ='2025.09'!R5 -> 0 | D9: =D8+'2025.09'!S5 -> 240 | E9: ='SEB Active 55'!H11 -> 122.91 | F9: ='SEB Active 80'!H11 -> 123.1 | G9: 0 | H9: 0 | I9: 0 | J9: 0 | K9: 0 | L9: 0 | M9: =SUM(E9:L9) -> 246.01 | N9: =M9-B9 -> 6.01 | O9: =N9/B9 -> 0.025 | P9: ='2025.09'!X5 -> 0 | Q9: ='2025.09'!U5 -> 0 | R9: ='2025.09'!W5 -> 0 | S9: ='2025.09'!V5 -> 0.06
A10: ='2025.10'!Q2 -> 2025.1 | B10: =B9+'2025.10'!Q5 -> 270 | C10: ='2025.10'!R5 -> 0 | D10: =D9+'2025.10'!S5 -> 270 | E10: ='SEB Active 55'!H12 -> 141.52 | F10: ='SEB Active 80'!H12 -> 143.22 | G10: 0 | H10: 0 | I10: 0 | J10: 0 | K10: 0 | L10: 0 | M10: =SUM(E10:L10) -> 284.74 | N10: =M10-B10 -> 14.74 | O10: =N10/B10 -> 0.0546 | P10: ='2025.10'!X5 -> 0 | Q10: ='2025.10'!U5 -> 0 | R10: ='2025.10'!W5 -> 0 | S10: ='2025.10'!V5 -> 0
A11: ='2025.11'!Q2 -> 2025.11 | B11: =B10+'2025.11'!Q5 -> 300 | C11: ='2025.11'!R5 -> 0 | D11: =D10+'2025.11'!S5 -> 300 | E11: ='SEB Active 55'!H13 -> 155.82 | F11: ='SEB Active 80'!H13 -> 157.29 | G11: 0 | H11: 0 | I11: 0 | J11: 0 | K11: 0 | L11: 0 | M11: =SUM(E11:L11) -> 313.11 | N11: =M11-B11 -> 13.11 | O11: =N11/B11 -> 0.0437 | P11: ='2025.11'!X5 -> 0 | Q11: ='2025.11'!U5 -> 0 | R11: ='2025.11'!W5 -> 0 | S11: ='2025.11'!V5 -> 0.16
A12: ='2025.12'!Q2 -> 2025.12 | B12: =B11+'2025.12'!Q5 -> 300 | C12: ='2025.12'!R5 -> 0 | D12: =D11+'2025.12'!S5 -> 300 | E12: ='SEB Active 55'!H14 -> 157.8 | F12: ='SEB Active 80'!H14 -> 160.05 | G12: 0 | H12: 0 | I12: 0 | J12: 0 | K12: 0 | L12: 0 | M12: =SUM(E12:L12) -> 317.85 | N12: =M12-B12 -> 17.85 | O12: =N12/B12 -> 0.0595 | P12: ='2025.12'!X5 -> 0 | Q12: ='2025.12'!U5 -> 0 | R12: ='2025.12'!W5 -> 0 | S12: ='2025.12'!V5 -> 0.1
A13: ='2026.01'!Q2 -> 2026.01 | B13: =B12+'2026.01'!Q5 -> 360 | C13: ='2026.01'!R5 -> 0 | D13: =D12+'2026.01'!S5 -> 360 | E13: ='SEB Active 55'!H15 -> 191.65 | F13: ='SEB Active 80'!H15 -> 194.74 | G13: 0 | H13: 0 | I13: 0 | J13: 0 | K13: 0 | L13: 0 | M13: =SUM(E13:L13) -> 386.39 | N13: =M13-B13 -> 26.39 | O13: =N13/B13 -> 0.0733 | P13: ='2026.01'!X5 -> 0 | Q13: ='2026.01'!U5 -> 0 | R13: ='2026.01'!W5 -> 0 | S13: ='2026.01'!V5 -> 0.11
A14: ='2026.02'!Q2 -> 2026.02 | B14: =B13+'2026.02'!Q5 -> 390 | C14: ='2026.02'!R5 -> 0 | D14: =D13+'2026.02'!S5 -> 390 | E14: ='SEB Active 55'!H16 -> 208.94 | F14: ='SEB Active 80'!H16 -> 212.48 | G14: 0 | H14: 0 | I14: 0 | J14: 0 | K14: 0 | L14: 0 | M14: =SUM(E14:L14) -> 421.42 | N14: =M14-B14 -> 31.42 | O14: =N14/B14 -> 0.0806 | P14: ='2026.02'!X5 -> 0 | Q14: ='2026.02'!U5 -> 0 | R14: ='2026.02'!W5 -> 0 | S14: ='2026.02'!V5 -> 0.12
A15: ='2026.03'!Q2 -> 2026.03 | B15: =B14+'2026.03'!Q5 -> 420 | C15: ='2026.03'!R5 -> 0 | D15: =D14+'2026.03'!S5 -> 420 | E15: ='SEB Active 55'!H17 -> 209.2 | F15: ='SEB Active 80'!H17 -> 209.48 | G15: 0 | H15: 0 | I15: 0 | J15: 0 | K15: 0 | L15: 0 | M15: =SUM(E15:L15) -> 418.68 | N15: =M15-B15 -> -1.32 | O15: =N15/B15 -> -0.0031 | P15: ='2026.03'!X5 -> 0 | Q15: ='2026.03'!U5 -> 0 | R15: ='2026.03'!W5 -> 0 | S15: ='2026.03'!V5 -> 0.14
A16: ='2026.04'!$Q$2 -> 2026.04 | B16: =B15+'2026.04'!$Q$5 -> 450 | C16: ='2026.04'!$R$5 -> 0 | D16: =D15+'2026.04'!$S$5 -> 450 | E16: ='SEB Active 55'!H18 -> 236.3 | F16: ='SEB Active 80'!H18 -> 240.29 | G16: 0 | H16: 0 | I16: 0 | J16: 0 | K16: 0 | L16: 0 | M16: =SUM(E16:L16) -> 476.59 | N16: =M16-B16 -> 26.59 | O16: =N16/B16 -> 0.0591 | P16: ='2026.04'!$X$5 -> 0 | Q16: ='2026.04'!$U$5 -> 0 | R16: ='2026.04'!$W$5 -> 0 | S16: ='2026.04'!$V$5 -> 0.14
A17: ='2026.05'!$Q$2 -> 2026.05 | B17: =B16+'2026.05'!$Q$5 -> 480 | C17: ='2026.05'!$R$5 -> 0 | D17: =D16+'2026.05'!$S$5 -> 480 | E17: ='SEB Active 55'!H19 -> 260.44 | F17: ='SEB Active 80'!H19 -> 266.63 | G17: 0 | H17: 0 | I17: 0 | J17: 0 | K17: 0 | L17: 0 | M17: =SUM(E17:L17) -> 527.07 | N17: =M17-B17 -> 47.07 | O17: =N17/B17 -> 0.0981 | P17: ='2026.05'!$X$5 -> 0 | Q17: ='2026.05'!$U$5 -> 0 | R17: ='2026.05'!$W$5 -> 0 | S17: ='2026.05'!$V$5 -> 0.16
A18: ='2026.06'!$Q$2 -> 2026.06 | B18: =B17+'2026.06'!$Q$5 -> 510 | C18: ='2026.06'!$R$5 -> 0 | D18: =D17+'2026.06'!$S$5 -> 510 | E18: ='SEB Active 55'!H20 -> 277.18 | F18: ='SEB Active 80'!H20 -> 283.62 | G18: 0 | H18: 0 | I18: 0 | J18: 0 | K18: 0 | L18: 0 | M18: =SUM(E18:L18) -> 560.8 | N18: =M18-B18 -> 50.8 | O18: =N18/B18 -> 0.0996 | P18: ='2026.06'!$X$5 -> 0 | Q18: ='2026.06'!$U$5 -> 0 | R18: ='2026.06'!$W$5 -> 0 | S18: ='2026.06'!$V$5 -> 0.18
A19: ='2026.07'!$Q$2 -> 2026.07 | B19: =B18+'2026.07'!$Q$5 -> 540 | C19: ='2026.07'!$R$5 -> 0 | D19: =D18+'2026.07'!$S$5 -> 540 | E19: ='SEB Active 55'!H21 -> 292.59 | F19: ='SEB Active 80'!H21 -> 300.48 | G19: 0 | H19: 0 | I19: 0 | J19: 0 | K19: 0 | L19: 0 | M19: =SUM(E19:L19) -> 593.07 | N19: =M19-B19 -> 53.07 | O19: =N19/B19 -> 0.0983 | P19: ='2026.07'!$X$5 -> 0 | Q19: ='2026.07'!$U$5 -> 0 | R19: ='2026.07'!$W$5 -> 0 | S19: ='2026.07'!$V$5 -> 0.18
A20: ='2026.08'!$Q$2 -> 2026.08 | B20: =B19+'2026.08'!$Q$5 -> 570 | C20: ='2026.08'!$R$5 -> 0 | D20: =D19+'2026.08'!$S$5 -> 570 | E20: ='SEB Active 55'!H22 -> 313.74 | F20: ='SEB Active 80'!H22 -> 323.61 | G20: 0 | H20: 0 | I20: 0 | J20: 0 | K20: 0 | L20: 0 | M20: =SUM(E20:L20) -> 637.35 | N20: =M20-B20 -> 67.35 | O20: =N20/B20 -> 0.1182 | P20: ='2026.08'!$X$5 -> 0 | Q20: ='2026.08'!$U$5 -> 0 | R20: ='2026.08'!$W$5 -> 0 | S20: ='2026.08'!$V$5 -> 0.2
A21: ='2026.09'!$Q$2 -> 2026.09 | B21: =B20+'2026.09'!$Q$5 -> 600 | C21: ='2026.09'!$R$5 -> 0 | D21: =D20+'2026.09'!$S$5 -> 600 | E21: ='SEB Active 55'!H23 -> 325.17 | F21: ='SEB Active 80'!H23 -> 335.05 | G21: 0 | H21: 0 | I21: 0 | J21: 0 | K21: 0 | L21: 0 | M21: =SUM(E21:L21) -> 660.22 | N21: =M21-B21 -> 60.22 | O21: =N21/B21 -> 0.1004 | P21: ='2026.09'!$X$5 -> 0 | Q21: ='2026.09'!$U$5 -> 0 | R21: ='2026.09'!$W$5 -> 0 | S21: ='2026.09'!$V$5 -> 0.21

Sheet SEB Active 55
A1: SESA5FE SS „SEB Active 55“ SE0016076046
A3: Data | B3: Suma, EUR | E3: Kiekis | G3: Mėnesio gale | K3: Mokesčiai | M3: Dividendai | O3: Active 55 | P3: Įnešta | Q3: Kiekis | R3: Parduota | S3: Pelnas | V3: Mokesčiai | X3: Dividendai | Y3: Vid. Kaina | AC3: Suma | AD3: Kaina | AE3: Kiekis | AF3: Pirkimas/pardavimas
B4: Įnešta | C4: Mėn. Inv. | D4: Viso Inv. | E4: Mėnesio | F4: Viso | G4: Kaina | H4: Vertė gale | I4: Pelnas | J4: % | K4: Pirkimas | L4: Pardavimas | S4: Eur. | T4: % | U4: XIRR | V4: Pirkimas | W4: Pardavimas | AF4: Data | AG4: Suma
A5: ='2025.03'!Q2 -> 2025.03 | B5: ='2025.03'!B19 -> 30 | C5: ='2025.03'!C19 -> 30 | D5: =C5 -> 30 | E5: ='2025.03'!F19 -> 0.2276 | F5: =E5 -> 0.2276 | G5: 129.9751 | H5: =F5*G5 -> 29.58 | I5: =H5-D5 -> -0.42 | J5: =(H5-D5)/D5 -> -0.014 | K5: ='2025.03'!D19 -> 0 | L5: ='2025.03'!J19 -> 0 | M5: ='2025.03'!O19 -> 0 | O5: Viso: | P5: =SUM(B5:B100) -> 300 | Q5: =SUM(E5:E100) -> 2.159 | S5: =R5-P5+X5 -> -300 | T5: =(R5-P5+X5)/P5 -> -1 | U5: =XIRR(AG5:AG85,AF5:AF85) -> 0.1624 | V5: =SUM(K5:K100) -> 0 | W5: =SUM(L5:L100) -> 0 | X5: =SUM(M5:M100) -> 0 | Y5: {=SUMPRODUCT(IFERROR(AD5:AD200,0),IFERROR(AE5:AE200,0))/SUM(IFERROR(AE5:AE200,0))} -> 138.68 | AC5: ='2025.03'!$C$19 -> 30 | AD5: ='2025.03'!$E$19 -> 131.81 | AE5: ='2025.03'!$F$19 -> 0.228 | AF5: ='2025.03'!$A$15 -> 45743 | AG5: ='2025.03'!$B$15*-1 -> -15
A6: ='2025.04'!Q2 -> 2025.04 | B6: ='2025.04'!B19 -> 15 | C6: ='2025.04'!C19 -> 15 | D6: =D5+B6 -> 45 | E6: ='2025.04'!F19 -> 0.1192 | F6: =F5+E6 -> 0.3468 | G6: 126.5641 | H6: =F6*G6 -> 43.89 | I6: =H6-D6 -> -1.11 | J6: =(H6-D6)/D6 -> -0.0247 | K6: ='2025.04'!D19 -> 0 | L6: ='2025.04'!J19 -> 0 | M6: ='2025.04'!O19 -> 0 | AC6: ='2025.04'!$C$19 -> 15 | AD6: ='2025.04'!$E$19 -> 125.84 | AE6: ='2025.04'!$F$19 -> 0.119 | AF6: ='2025.03'!$A$16 -> 45743 | AG6: ='2025.03'!$B$16*-1 -> -15
A7: ='2025.05'!Q2 -> 2025.05 | B7: ='2025.05'!B19 -> 15 | C7: ='2025.05'!C19 -> 15 | D7: =D6+B7 -> 60 | E7: ='2025.05'!F19 -> 0.1143 | F7: =F6+E7 -> 0.4611 | G7: 131.6247 | H7: =F7*G7 -> 60.69 | I7: =H7-D7 -> 0.69 | J7: =(H7-D7)/D7 -> 0.0115 | K7: ='2025.05'!D19 -> 0 | L7: ='2025.05'!J19 -> 0 | M7: ='2025.05'!O19 -> 0 | AC7: ='2025.05'!$C$19 -> 15 | AD7: ='2025.05'!$E$19 -> 131.23 | AE7: ='2025.05'!$F$19 -> 0.114 | AF7: ='2025.04'!$A$15 -> 45776 | AG7: ='2025.04'!$B$15*-1 -> -15
A8: ='2025.06'!Q2 -> 2025.06 | B8: ='2025.06'!B19 -> 15 | C8: ='2025.06'!C19 -> 15 | D8: =D7+B8 -> 75 | E8: ='2025.06'!F19 -> 0.1147 | F8: =F7+E8 -> 0.5758 | G8: 131.7073 | H8: =F8*G8 -> 75.84 | I8: =H8-D8 -> 0.84 | J8: =(H8-D8)/D8 -> 0.0112 | K8: ='2025.06'!D19 -> 0 | L8: ='2025.06'!J19 -> 0 | M8: ='2025.06'!O19 -> 0 | AC8: ='2025.06'!$C$19 -> 15 | AD8: ='2025.06'!$E$19 -> 130.78 | AE8: ='2025.06'!$F$19 -> 0.115 | AF8: ='2025.05'!$A$15 -> 45807 | AG8: ='2025.05'!$B$15*-1 -> -15
A9: ='2025.07'!Q2 -> 2025.07 | B9: ='2025.07'!B19 -> 15 | C9: ='2025.07'!C19 -> 15 | D9: =D8+B9 -> 90 | E9: ='2025.07'!F19 -> 0.1125 | F9: =F8+E9 -> 0.6883 | G9: 133.4857 | H9: =F9*G9 -> 91.88 | I9: =H9-D9 -> 1.88 | J9: =(H9-D9)/D9 -> 0.0209 | K9: ='2025.07'!D19 -> 0 | L9: ='2025.07'!J19 -> 0 | M9: ='2025.07'!O19 -> 0 | AC9: ='2025.07'!$C$19 -> 15 | AD9: ='2025.07'!$E$19 -> 133.33 | AE9: ='2025.07'!$F$19 -> 0.113 | AF9: ='2025.06'!$A$15 -> 45838 | AG9: ='2025.06'!$B$15*-1 -> -15
A10: ='2025.08'!Q2 -> 2025.08 | B10: ='2025.08'!B19 -> 15 | C10: ='2025.08'!C19 -> 15 | D10: =D9+B10 -> 105 | E10: ='2025.08'!F19 -> 0.1118 | F10: =F9+E10 -> 0.8001 | G10: 133.9509 | H10: =F10*G10 -> 107.17 | I10: =H10-D10 -> 2.17 | J10: =(H10-D10)/D10 -> 0.0207 | K10: ='2025.08'!D19 -> 0 | L10: ='2025.08'!J19 -> 0 | M10: ='2025.08'!O19 -> 0 | AC10: ='2025.08'!$C$19 -> 15 | AD10: ='2025.08'!$E$19 -> 134.17 | AE10: ='2025.08'!$F$19 -> 0.112 | AF10: ='2025.07'!$A$15 -> 45867 | AG10: ='2025.07'!$B$15*-1 -> -15
A11: ='2025.09'!Q2 -> 2025.09 | B11: ='2025.09'!B19 -> 15 | C11: ='2025.09'!C19 -> 15 | D11: =D10+B11 -> 120 | E11: ='2025.09'!F19 -> 0.1116 | F11: =F10+E11 -> 0.9117 | G11: 134.8165 | H11: =F11*G11 -> 122.91 | I11: =H11-D11 -> 2.91 | J11: =(H11-D11)/D11 -> 0.0243 | K11: ='2025.09'!D19 -> 0 | L11: ='2025.09'!J19 -> 0 | M11: ='2025.09'!O19 -> 0 | AC11: ='2025.09'!$C$19 -> 15 | AD11: ='2025.09'!$E$19 -> 134.41 | AE11: ='2025.09'!$F$19 -> 0.112 | AF11: ='2025.08'!$A$15 -> 45897 | AG11: ='2025.08'!$B$15*-1 -> -15
A12: ='2025.10'!Q2 -> 2025.1 | B12: ='2025.10'!B19 -> 15 | C12: ='2025.10'!C19 -> 15 | D12: =D11+B12 -> 135 | E12: ='2025.10'!F19 -> 0.1081 | F12: =F11+E12 -> 1.0198 | G12: 138.7693 | H12: =F12*G12 -> 141.52 | I12: =H12-D12 -> 6.52 | J12: =(H12-D12)/D12 -> 0.0483 | K12: ='2025.10'!D19 -> 0 | L12: ='2025.10'!J19 -> 0 | M12: ='2025.10'!O19 -> 0 | AC12: ='2025.10'!$C$19 -> 15 | AD12: ='2025.10'!$E$19 -> 138.76 | AE12: ='2025.10'!$F$19 -> 0.108 | AF12: ='2025.09'!$A$15 -> 45929 | AG12: ='2025.09'!$B$15*-1 -> -15
A13: ='2025.11'!Q2 -> 2025.11 | B13: ='2025.11'!B19 -> 15 | C13: ='2025.11'!C19 -> 15 | D13: =D12+B13 -> 150 | E13: ='2025.11'!F19 -> 0.1096 | F13: =F12+E13 -> 1.1294 | G13: 137.9687 | H13: =F13*G13 -> 155.82 | I13: =H13-D13 -> 5.82 | J13: =(H13-D13)/D13 -> 0.0388 | K13: ='2025.11'!D19 -> 0 | L13: ='2025.11'!J19 -> 0 | M13: ='2025.11'!O19 -> 0 | AC13: ='2025.11'!$C$19 -> 15 | AD13: ='2025.11'!$E$19 -> 136.86 | AE13: ='2025.11'!$F$19 -> 0.11 | AF13: ='2025.10'!$A$15 -> 45959 | AG13: ='2025.10'!$B$15*-1 -> -15
A14: ='2025.12'!Q2 -> 2025.12 | B14: ='2025.12'!B19 -> 0 | C14: ='2025.12'!C19 -> 0 | D14: =D13+B14 -> 150 | E14: ='2025.12'!F19 -> 0 | F14: =F13+E14 -> 1.1294 | G14: 139.7187 | H14: =F14*G14 -> 157.8 | I14: =H14-D14 -> 7.8 | J14: =(H14-D14)/D14 -> 0.052 | K14: ='2025.12'!D19 -> 0 | L14: ='2025.12'!J19 -> 0 | M14: ='2025.12'!O19 -> 0 | AC14: ='2025.12'!$C$19 -> 0 | AD14: ='2025.12'!$E$19 -> 0.00 | AE14: ='2025.12'!$F$19 -> 0 | AF14: ='2025.11'!$A$15 -> 45988 | AG14: ='2025.11'!$B$15*-1 -> -15
A15: ='2026.01'!Q2 -> 2026.01 | B15: ='2026.01'!B19 -> 30 | C15: ='2026.01'!C19 -> 30 | D15: =D14+B15 -> 180 | E15: ='2026.01'!F19 -> 0.2119 | F15: =F14+E15 -> 1.3413 | G15: 142.8867 | H15: =F15*G15 -> 191.65 | I15: =H15-D15 -> 11.65 | J15: =(H15-D15)/D15 -> 0.0647 | K15: ='2026.01'!D19 -> 0 | L15: ='2026.01'!J19 -> 0 | M15: ='2026.01'!O19 -> 0 | AC15: ='2026.01'!$C$19 -> 30 | AD15: ='2026.01'!$E$19 -> 141.58 | AE15: ='2026.01'!$F$19 -> 0.212 | AF15: ='2026.01'!$A$15 -> 46027 | AG15: ='2026.01'!$B$15*-1 -> -15
A16: ='2026.02'!Q2 -> 2026.02 | B16: ='2026.02'!B19 -> 15 | C16: ='2026.02'!C19 -> 15 | D16: =D15+B16 -> 195 | E16: ='2026.02'!F19 -> 0.1037 | F16: =F15+E16 -> 1.445 | G16: 144.5928 | H16: =F16*G16 -> 208.94 | I16: =H16-D16 -> 13.94 | J16: =(H16-D16)/D16 -> 0.0715 | K16: ='2026.02'!D19 -> 0 | L16: ='2026.02'!J19 -> 0 | M16: ='2026.02'!O19 -> 0 | AC16: ='2026.02'!$C$19 -> 15 | AD16: ='2026.02'!$E$19 -> 144.65 | AE16: ='2026.02'!$F$19 -> 0.104 | AF16: ='2026.01'!$A$16 -> 46051 | AG16: ='2026.01'!$B$16*-1 -> -15
A17: ='2026.03'!Q2 -> 2026.03 | B17: ='2026.03'!B19 -> 15 | C17: ='2026.03'!C19 -> 15 | D17: =D16+B17 -> 210 | E17: ='2026.03'!F19 -> 0.1096 | F17: =F16+E17 -> 1.5546 | G17: 134.5698 | H17: =F17*G17 -> 209.2 | I17: =H17-D17 -> -0.8 | J17: =(H17-D17)/D17 -> -0.0038 | K17: ='2026.03'!D19 -> 0 | L17: ='2026.03'!J19 -> 0 | M17: ='2026.03'!O19 -> 0 | AC17: ='2026.03'!$C$19 -> 15 | AD17: ='2026.03'!$E$19 -> 136.86 | AE17: ='2026.03'!$F$19 -> 0.11 | AF17: ='2026.02'!$A$15 -> 46080 | AG17: ='2026.02'!$B$15*-1 -> -15
A18: ='2026.04'!$Q$2 -> 2026.04 | B18: ='2026.04'!$B$19 -> 15 | C18: ='2026.04'!$C$19 -> 15 | D18: =D17+B18 -> 225 | E18: ='2026.04'!$F$19 -> 0.1046 | F18: =F17+E18 -> 1.6592 | G18: 142.4155 | H18: =F18*G18 -> 236.3 | I18: =H18-D18 -> 11.3 | J18: =(H18-D18)/D18 -> 0.0502 | K18: ='2026.04'!$D$19 -> 0 | L18: ='2026.04'!$J$19 -> 0 | M18: ='2026.04'!$O$19 -> 0 | AC18: ='2026.04'!$C$19 -> 15 | AD18: ='2026.04'!$E$19 -> 143.4 | AE18: ='2026.04'!$F$19 -> 0.105 | AF18: ='2026.03'!$A$15 -> 46108 | AG18: ='2026.03'!$B$15*-1 -> -15
A19: ='2026.05'!$Q$2 -> 2026.05 | B19: ='2026.05'!$B$19 -> 15 | C19: ='2026.05'!$C$19 -> 15 | D19: =D18+B19 -> 240 | E19: ='2026.05'!$F$19 -> 0.1009 | F19: =F18+E19 -> 1.7601 | G19: 147.9679 | H19: =F19*G19 -> 260.44 | I19: =H19-D19 -> 20.44 | J19: =(H19-D19)/D19 -> 0.0852 | K19: ='2026.05'!$D$19 -> 0 | L19: ='2026.05'!$J$19 -> 0 | M19: ='2026.05'!$O$19 -> 0 | AC19: ='2026.05'!$C$19 -> 15 | AD19: ='2026.05'!$E$19 -> 148.66 | AE19: ='2026.05'!$F$19 -> 0.101 | AF19: ='2026.04'!$A$15 -> 46141 | AG19: ='2026.04'!$B$15*-1 -> -15
A20: ='2026.06'!$Q$2 -> 2026.06 | B20: ='2026.06'!$B$19 -> 15 | C20: ='2026.06'!$C$19 -> 15 | D20: =D19+B20 -> 255 | E20: ='2026.06'!$F$19 -> 0.1008 | F20: =F19+E20 -> 1.8609 | G20: 148.9513 | H20: =F20*G20 -> 277.18 | I20: =H20-D20 -> 22.18 | J20: =(H20-D20)/D20 -> 0.087 | K20: ='2026.06'!$D$19 -> 0 | L20: ='2026.06'!$J$19 -> 0 | M20: ='2026.06'!$O$19 -> 0 | AC20: ='2026.06'!$C$19 -> 15 | AD20: ='2026.06'!$E$19 -> 148.81 | AE20: ='2026.06'!$F$19 -> 0.101 | AF20: ='2026.05'!$A$15 -> 46171 | AG20: ='2026.05'!$B$15*-1 -> -15
A21: ='2026.07'!$Q$2 -> 2026.07 | B21: ='2026.07'!$B$19 -> 15 | C21: ='2026.07'!$C$19 -> 15 | D21: =D20+B21 -> 270 | E21: ='2026.07'!$F$19 -> 0.1002 | F21: =F20+E21 -> 1.9611 | G21: 149.1989 | H21: =F21*G21 -> 292.59 | I21: =H21-D21 -> 22.59 | J21: =(H21-D21)/D21 -> 0.0837 | K21: ='2026.07'!$D$19 -> 0 | L21: ='2026.07'!$J$19 -> 0 | M21: ='2026.07'!$O$19 -> 0 | AC21: ='2026.06'!$C$19 -> 15 | AD21: ='2026.06'!$E$19 -> 148.81 | AE21: ='2026.06'!$F$19 -> 0.101 | AF21: ='2026.05'!$A$15 -> 46171 | AG21: ='2026.05'!$B$15*-1 -> -15
A22: ='2026.08'!$Q$2 -> 2026.08 | B22: ='2026.08'!$B$19 -> 15 | C22: ='2026.08'!$C$19 -> 15 | D22: =D21+B22 -> 285 | E22: ='2026.08'!$F$19 -> 0.0986 | F22: =F21+E22 -> 2.0597 | G22: 152.3216 | H22: =F22*G22 -> 313.74 | I22: =H22-D22 -> 28.74 | J22: =(H22-D22)/D22 -> 0.1008 | K22: ='2026.08'!$D$19 -> 0 | L22: ='2026.08'!$J$19 -> 0 | M22: ='2026.08'!$O$19 -> 0 | AC22: ='2026.06'!$C$19 -> 15 | AD22: ='2026.06'!$E$19 -> 148.81 | AE22: ='2026.06'!$F$19 -> 0.101 | AF22: ='2026.05'!$A$15 -> 46171 | AG22: ='2026.05'!$B$15*-1 -> -15
A23: ='2026.09'!$Q$2 -> 2026.09 | B23: ='2026.09'!$B$19 -> 15 | C23: ='2026.09'!$C$19 -> 15 | D23: =D22+B23 -> 300 | E23: ='2026.09'!$F$19 -> 0.0992 | F23: =F22+E23 -> 2.1589 | G23: 150.6192 | H23: =F23*G23 -> 325.17 | I23: =H23-D23 -> 25.17 | J23: =(H23-D23)/D23 -> 0.0839 | K23: ='2026.09'!$D$19 -> 0 | L23: ='2026.09'!$J$19 -> 0 | M23: ='2026.09'!$O$19 -> 0 | AC23: ='2026.06'!$C$19 -> 15 | AD23: ='2026.06'!$E$19 -> 148.81 | AE23: ='2026.06'!$F$19 -> 0.101 | AF23: ='2026.05'!$A$15 -> 46171 | AG23: ='2026.05'!$B$15*-1 -> -15
AF69: =TODAY() -> 46296 | AG69: {=LOOKUP(2,1/(H:H>0),H:H)} -> 325.17

Sheet SEB Active 80
A1: SESA8FE SS „SEB Active 80“ SE0016076111
A3: Data | B3: Suma, EUR | E3: Kiekis | G3: Mėnesio gale | K3: Mokesčiai | M3: Dividendai | O3: Active 80 | P3: Įnešta | Q3: Kiekis | R3: Parduota | S3: Pelnas | V3: Mokesčiai | X3: Dividendai | Y3: Vid. Kaina | AC3: Suma | AD3: Kaina | AE3: Kiekis | AF3: Pirkimas/pardavimas
B4: Įnešta | C4: Mėn. Inv. | D4: Viso Inv. | E4: Mėnesio | F4: Viso | G4: Kaina | H4: Vertė gale | I4: Pelnas | J4: % | K4: Pirkimas | L4: Pardavimas | S4: Eur. | T4: % | U4: XIRR | V4: Pirkimas | W4: Pardavimas | AF4: Data | AG4: Suma
A5: ='2025.03'!Q2 -> 2025.03 | B5: ='2025.03'!B29 -> 30 | C5: ='2025.03'!C29 -> 30 | D5: =C5 -> 30 | E5: ='2025.03'!F29 -> 0.2022 | F5: =E5 -> 0.2022 | G5: 145.1853 | H5: =F5*G5 -> 29.36 | I5: =H5-D5 -> -0.64 | J5: =(H5-D5)/D5 -> -0.0213 | K5: ='2025.03'!D29 -> 0 | L5: ='2025.03'!J29 -> 0 | M5: ='2025.03'!O29 -> 0 | O5: Viso: | P5: =SUM(B5:B54) -> 300 | Q5: =SUM(E5:E54) -> 1.91 | S5: =R5-P5+X5 -> -300 | T5: =(R5-P5+X5)/P5 -> -1 | U5: =XIRR(AG5:AG85,AF5:AF85) -> 0.2015 | V5: =SUM(K5:K54) -> 0 | W5: =SUM(L5:L54) -> 0 | X5: =SUM(M5:M54) -> 0 | Y5: {=SUMPRODUCT(IFERROR(AD5:AD200,0),IFERROR(AE5:AE200,0))/SUM(IFERROR(AE5:AE200,0))} -> 156.73 | AC5: ='2025.03'!$C$29 -> 30 | AD5: ='2025.03'!$E$29 -> 148.37 | AE5: ='2025.03'!$F$29 -> 0.202 | AF5: ='2025.03'!$A$25 -> 45743 | AG5: ='2025.03'!$B$25*-1 -> -15
A6: ='2025.04'!Q2 -> 2025.04 | B6: ='2025.04'!B29 -> 15 | C6: ='2025.04'!C29 -> 15 | D6: =D5+B6 -> 45 | E6: ='2025.04'!F29 -> 0.1093 | F6: =F5+E6 -> 0.3115 | G6: 139.227 | H6: =F6*G6 -> 43.37 | I6: =H6-D6 -> -1.63 | J6: =(H6-D6)/D6 -> -0.0362 | K6: ='2025.04'!D29 -> 0 | L6: ='2025.04'!J29 -> 0 | M6: ='2025.04'!O29 -> 0 | AC6: ='2025.04'!$C$29 -> 15 | AD6: ='2025.04'!$E$29 -> 137.27 | AE6: ='2025.04'!$F$29 -> 0.109 | AF6: ='2025.03'!$A$26 -> 45743 | AG6: ='2025.03'!$B$26*-1 -> -15
A7: ='2025.05'!Q2 -> 2025.05 | B7: ='2025.05'!B29 -> 15 | C7: ='2025.05'!C29 -> 15 | D7: =D6+B7 -> 60 | E7: ='2025.05'!F29 -> 0.1025 | F7: =F6+E7 -> 0.414 | G7: 147.3631 | H7: =F7*G7 -> 61.01 | I7: =H7-D7 -> 1.01 | J7: =(H7-D7)/D7 -> 0.0168 | K7: ='2025.05'!D29 -> 0 | L7: ='2025.05'!J29 -> 0 | M7: ='2025.05'!O29 -> 0 | AC7: ='2025.05'!$C$29 -> 15 | AD7: ='2025.05'!$E$29 -> 146.34 | AE7: ='2025.05'!$F$29 -> 0.103 | AF7: ='2025.04'!$A$25 -> 45775 | AG7: ='2025.04'!$B$25*-1 -> -15
A8: ='2025.06'!Q2 -> 2025.06 | B8: ='2025.06'!B29 -> 15 | C8: ='2025.06'!C29 -> 15 | D8: =D7+B8 -> 75 | E8: ='2025.06'!F29 -> 0.1026 | F8: =F7+E8 -> 0.5166 | G8: 146.7454 | H8: =F8*G8 -> 75.81 | I8: =H8-D8 -> 0.81 | J8: =(H8-D8)/D8 -> 0.0108 | K8: ='2025.06'!D29 -> 0 | L8: ='2025.06'!J29 -> 0 | M8: ='2025.06'!O29 -> 0 | AC8: ='2025.06'!$C$29 -> 15 | AD8: ='2025.06'!$E$29 -> 146.2 | AE8: ='2025.06'!$F$29 -> 0.103 | AF8: ='2025.05'!$A$25 -> 45805 | AG8: ='2025.05'!$B$25*-1 -> -15
A9: ='2025.07'!Q2 -> 2025.07 | B9: ='2025.07'!B29 -> 15 | C9: ='2025.07'!C29 -> 15 | D9: =D8+B9 -> 90 | E9: ='2025.07'!F29 -> 0.1004 | F9: =F8+E9 -> 0.617 | G9: 149.4614 | H9: =F9*G9 -> 92.22 | I9: =H9-D9 -> 2.22 | J9: =(H9-D9)/D9 -> 0.0247 | K9: ='2025.07'!D29 -> 0 | L9: ='2025.07'!J29 -> 0 | M9: ='2025.07'!O29 -> 0 | AC9: ='2025.07'!$C$29 -> 15 | AD9: ='2025.07'!$E$29 -> 149.4 | AE9: ='2025.07'!$F$29 -> 0.1 | AF9: ='2025.06'!$A$25 -> 45835 | AG9: ='2025.06'!$B$25*-1 -> -15
A10: ='2025.08'!Q2 -> 2025.08 | B10: ='2025.08'!B29 -> 15 | C10: ='2025.08'!C29 -> 15 | D10: =D9+B10 -> 105 | E10: ='2025.08'!F29 -> 0.0998 | F10: =F9+E10 -> 0.7168 | G10: 149.9168 | H10: =F10*G10 -> 107.46 | I10: =H10-D10 -> 2.46 | J10: =(H10-D10)/D10 -> 0.0234 | K10: ='2025.08'!D29 -> 0 | L10: ='2025.08'!J29 -> 0 | M10: ='2025.08'!O29 -> 0 | AC10: ='2025.08'!$C$29 -> 15 | AD10: ='2025.08'!$E$29 -> 150.3 | AE10: ='2025.08'!$F$29 -> 0.1 | AF10: ='2025.07'!$A$25 -> 45866 | AG10: ='2025.07'!$B$25*-1 -> -15
A11: ='2025.09'!Q2 -> 2025.09 | B11: ='2025.09'!B29 -> 15 | C11: ='2025.09'!C29 -> 15 | D11: =D10+B11 -> 120 | E11: ='2025.09'!F29 -> 0.0992 | F11: =F10+E11 -> 0.816 | G11: 150.8638 | H11: =F11*G11 -> 123.1 | I11: =H11-D11 -> 3.1 | J11: =(H11-D11)/D11 -> 0.0258 | K11: ='2025.09'!D29 -> 0 | L11: ='2025.09'!J29 -> 0 | M11: ='2025.09'!O29 -> 0 | AC11: ='2025.09'!$C$29 -> 15 | AD11: ='2025.09'!$E$29 -> 151.21 | AE11: ='2025.09'!$F$29 -> 0.099 | AF11: ='2025.08'!$A$25 -> 45897 | AG11: ='2025.08'!$B$25*-1 -> -15
A12: ='2025.10'!Q2 -> 2025.1 | B12: ='2025.10'!B29 -> 15 | C12: ='2025.10'!C29 -> 15 | D12: =D11+B12 -> 135 | E12: ='2025.10'!F29 -> 0.0961 | F12: =F11+E12 -> 0.9121 | G12: 157.024 | H12: =F12*G12 -> 143.22 | I12: =H12-D12 -> 8.22 | J12: =(H12-D12)/D12 -> 0.0609 | K12: ='2025.10'!D29 -> 0 | L12: ='2025.10'!J29 -> 0 | M12: ='2025.10'!O29 -> 0 | AC12: ='2025.10'!$C$29 -> 15 | AD12: ='2025.10'!$E$29 -> 156.09 | AE12: ='2025.10'!$F$29 -> 0.096 | AF12: ='2025.09'!$A$25 -> 45926 | AG12: ='2025.09'!$B$25*-1 -> -15
A13: ='2025.11'!Q2 -> 2025.11 | B13: ='2025.11'!B29 -> 15 | C13: ='2025.11'!C29 -> 15 | D13: =D12+B13 -> 150 | E13: ='2025.11'!F29 -> 0.0974 | F13: =F12+E13 -> 1.0095 | G13: 155.8114 | H13: =F13*G13 -> 157.29 | I13: =H13-D13 -> 7.29 | J13: =(H13-D13)/D13 -> 0.0486 | K13: ='2025.11'!D29 -> 0 | L13: ='2025.11'!J29 -> 0 | M13: ='2025.11'!O29 -> 0 | AC13: ='2025.11'!$C$29 -> 15 | AD13: ='2025.11'!$E$29 -> 154 | AE13: ='2025.11'!$F$29 -> 0.097 | AF13: ='2025.10'!$A$25 -> 45958 | AG13: ='2025.10'!$B$25*-1 -> -15
A14: ='2025.12'!Q2 -> 2025.12 | B14: ='2025.12'!B29 -> 0 | C14: ='2025.12'!C29 -> 0 | D14: =D13+B14 -> 150 | E14: ='2025.12'!F29 -> 0 | F14: =F13+E14 -> 1.0095 | G14: 158.5456 | H14: =F14*G14 -> 160.05 | I14: =H14-D14 -> 10.05 | J14: =(H14-D14)/D14 -> 0.067 | K14: ='2025.12'!D29 -> 0 | L14: ='2025.12'!J29 -> 0 | M14: ='2025.12'!O29 -> 0 | AC14: ='2025.12'!$C$29 -> 0 | AD14: ='2025.12'!$E$29 -> 0.00 | AE14: ='2025.12'!$F$29 -> 0 | AF14: ='2025.11'!$A$25 -> 45988 | AG14: ='2025.11'!$B$25*-1 -> -15
A15: ='2026.01'!Q2 -> 2026.01 | B15: ='2026.01'!B29 -> 30 | C15: ='2026.01'!C29 -> 30 | D15: =D14+B15 -> 180 | E15: ='2026.01'!F29 -> 0.1869 | F15: =F14+E15 -> 1.1964 | G15: 162.772 | H15: =F15*G15 -> 194.74 | I15: =H15-D15 -> 14.74 | J15: =(H15-D15)/D15 -> 0.0819 | K15: ='2026.01'!D29 -> 0 | L15: ='2026.01'!J29 -> 0 | M15: ='2026.01'!O29 -> 0 | AC15: ='2026.01'!$C$29 -> 30 | AD15: ='2026.01'!$E$29 -> 160.51 | AE15: ='2026.01'!$F$29 -> 0.187 | AF15: ='2026.01'!$A$25 -> 46024 | AG15: ='2026.01'!$B$25*-1 -> -15
A16: ='2026.02'!Q2 -> 2026.02 | B16: ='2026.02'!B29 -> 15 | C16: ='2026.02'!C29 -> 15 | D16: =D15+B16 -> 195 | E16: ='2026.02'!F29 -> 0.0915 | F16: =F15+E16 -> 1.2879 | G16: 164.9843 | H16: =F16*G16 -> 212.48 | I16: =H16-D16 -> 17.48 | J16: =(H16-D16)/D16 -> 0.0896 | K16: ='2026.02'!D29 -> 0 | L16: ='2026.02'!J29 -> 0 | M16: ='2026.02'!O29 -> 0 | AC16: ='2026.02'!$C$29 -> 15 | AD16: ='2026.02'!$E$29 -> 163.93 | AE16: ='2026.02'!$F$29 -> 0.092 | AF16: ='2026.01'!$A$26 -> 46050 | AG16: ='2026.01'!$B$26*-1 -> -15
A17: ='2026.03'!Q2 -> 2026.03 | B17: ='2026.03'!B29 -> 15 | C17: ='2026.03'!C29 -> 15 | D17: =D16+B17 -> 210 | E17: ='2026.03'!F29 -> 0.0984 | F17: =F16+E17 -> 1.3863 | G17: 151.1097 | H17: =F17*G17 -> 209.48 | I17: =H17-D17 -> -0.52 | J17: =(H17-D17)/D17 -> -0.0025 | K17: ='2026.03'!D29 -> 0 | L17: ='2026.03'!J29 -> 0 | M17: ='2026.03'!O29 -> 0 | AC17: ='2026.03'!$C$29 -> 15 | AD17: ='2026.03'!$E$29 -> 152.44 | AE17: ='2026.03'!$F$29 -> 0.098 | AF17: ='2026.02'!$A$25 -> 46079 | AG17: ='2026.02'!$B$25*-1 -> -15
A18: ='2026.04'!$Q$2 -> 2026.04 | B18: ='2026.04'!$B$29 -> 15 | C18: ='2026.04'!$C$29 -> 15 | D18: =D17+B18 -> 225 | E18: ='2026.04'!$F$29 -> 0.0916 | F18: =F17+E18 -> 1.4779 | G18: 162.5891 | H18: =F18*G18 -> 240.29 | I18: =H18-D18 -> 15.29 | J18: =(H18-D18)/D18 -> 0.068 | K18: ='2026.04'!$D$29 -> 0 | L18: ='2026.04'!$J$29 -> 0 | M18: ='2026.04'!$O$29 -> 0 | AC18: ='2026.04'!$C$29 -> 15 | AD18: ='2026.04'!$E$29 -> 163.76 | AE18: ='2026.04'!$F$29 -> 0.092 | AF18: ='2026.03'!$A$25 -> 46107 | AG18: ='2026.03'!$B$25*-1 -> -15
A19: ='2026.05'!$Q$2 -> 2026.05 | B19: ='2026.05'!$B$29 -> 15 | C19: ='2026.05'!$C$29 -> 15 | D19: =D18+B19 -> 240 | E19: ='2026.05'!$F$29 -> 0.0875 | F19: =F18+E19 -> 1.5654 | G19: 170.3272 | H19: =F19*G19 -> 266.63 | I19: =H19-D19 -> 26.63 | J19: =(H19-D19)/D19 -> 0.111 | K19: ='2026.05'!$D$29 -> 0 | L19: ='2026.05'!$J$29 -> 0 | M19: ='2026.05'!$O$29 -> 0 | AC19: ='2026.05'!$C$29 -> 15 | AD19: ='2026.05'!$E$29 -> 171.43 | AE19: ='2026.05'!$F$29 -> 0.088 | AF19: ='2026.04'!$A$25 -> 46140 | AG19: ='2026.04'!$B$25*-1 -> -15
A20: ='2026.06'!$Q$2 -> 2026.06 | B20: ='2026.06'!$B$29 -> 15 | C20: ='2026.06'!$C$29 -> 15 | D20: =D19+B20 -> 255 | E20: ='2026.06'!$F$29 -> 0.0872 | F20: =F19+E20 -> 1.6526 | G20: 171.6225 | H20: =F20*G20 -> 283.62 | I20: =H20-D20 -> 28.62 | J20: =(H20-D20)/D20 -> 0.1122 | K20: ='2026.06'!$D$29 -> 0 | L20: ='2026.06'!$J$29 -> 0 | M20: ='2026.06'!$O$29 -> 0 | AC20: ='2026.06'!$C$29 -> 15 | AD20: ='2026.06'!$E$29 -> 172.02 | AE20: ='2026.06'!$F$29 -> 0.087 | AF20: ='2026.05'!$A$25 -> 46171 | AG20: ='2026.05'!$B$25*-1 -> -15
A21: ='2026.07'!$Q$2 -> 2026.07 | B21: ='2026.07'!$B$29 -> 15 | C21: ='2026.07'!$C$29 -> 15 | D21: =D20+B21 -> 270 | E21: ='2026.07'!$F$29 -> 0.087 | F21: =F20+E21 -> 1.7396 | G21: 172.7268 | H21: =F21*G21 -> 300.48 | I21: =H21-D21 -> 30.48 | J21: =(H21-D21)/D21 -> 0.1129 | K21: ='2026.07'!$D$29 -> 0 | L21: ='2026.07'!$J$29 -> 0 | M21: ='2026.07'!$O$29 -> 0 | AC21: ='2026.06'!$C$29 -> 15 | AD21: ='2026.06'!$E$29 -> 172.02 | AE21: ='2026.06'!$F$29 -> 0.087 | AF21: ='2026.05'!$A$25 -> 46171 | AG21: ='2026.05'!$B$25*-1 -> -15
A22: ='2026.08'!$Q$2 -> 2026.08 | B22: ='2026.08'!$B$29 -> 15 | C22: ='2026.08'!$C$29 -> 15 | D22: =D21+B22 -> 285 | E22: ='2026.08'!$F$29 -> 0.0848 | F22: =F21+E22 -> 1.8244 | G22: 177.3781 | H22: =F22*G22 -> 323.61 | I22: =H22-D22 -> 38.61 | J22: =(H22-D22)/D22 -> 0.1355 | K22: ='2026.08'!$D$29 -> 0 | L22: ='2026.08'!$J$29 -> 0 | M22: ='2026.08'!$O$29 -> 0 | AC22: ='2026.06'!$C$29 -> 15 | AD22: ='2026.06'!$E$29 -> 172.02 | AE22: ='2026.06'!$F$29 -> 0.087 | AF22: ='2026.05'!$A$25 -> 46171 | AG22: ='2026.05'!$B$25*-1 -> -15
A23: ='2026.09'!$Q$2 -> 2026.09 | B23: ='2026.09'!$B$29 -> 15 | C23: ='2026.09'!$C$29 -> 15 | D23: =D22+B23 -> 300 | E23: ='2026.09'!$F$29 -> 0.0855 | F23: =F22+E23 -> 1.9099 | G23: 175.4266 | H23: =F23*G23 -> 335.05 | I23: =H23-D23 -> 35.05 | J23: =(H23-D23)/D23 -> 0.1168 | K23: ='2026.09'!$D$29 -> 0 | L23: ='2026.09'!$J$29 -> 0 | M23: ='2026.09'!$O$29 -> 0 | AC23: ='2026.06'!$C$29 -> 15 | AD23: ='2026.06'!$E$29 -> 172.02 | AE23: ='2026.06'!$F$29 -> 0.087 | AF23: ='2026.05'!$A$25 -> 46171 | AG23: ='2026.05'!$B$25*-1 -> -15
AF69: =TODAY() -> 46296 | AG69: {=LOOKUP(2,1/(H:H>0),H:H)} -> 335.05

Sheet SEB Artificial Intelligence Fun
A1: SESTUDI LX „SEB Artificial Intelligence Fund" LU2249630257
A3: Data | B3: Suma, EUR | E3: Kiekis | G3: Mėnesio gale | K3: Mokesčiai | M3: Dividendai | O3: Artificial | P3: Įnešta | Q3: Kiekis | R3: Parduota | S3: Pelnas | T3: % | U3: Mokesčiai | W3: Dividendai | Y3: Valiutos keitimas
B4: Įnešta | C4: Mėn. Inv. | D4: Viso Inv. | E4: Mėnesio | F4: Viso | G4: Kaina | H4: Vertė gale | I4: Pelnas | J4: % | K4: Pirkimas | L4: Pardavimas | U4: Pirkimas | V4: Pardavimas | Y4: Kursas | Z4: Suma, EUR | AA4: Viso suma | AB4: Kursas | AC4: Vertė gale | AD4: %
A5: =#REF! -> #REF! | B5: =#REF! -> #REF! | C5: =#REF! -> #REF! | D5: =B5 -> #REF! | E5: =#REF! -> #REF! | F5: =E5 -> #REF! | G5: 106.242 | H5: =F5*G5 -> #REF! | I5: =H5-D5 -> #REF! | J5: =(H5-D5)/D5 -> #REF! | K5: =#REF! -> #REF! | L5: =#REF! -> #REF! | M5: =#REF! -> #REF! | O5: Viso: | P5: =SUM(B5:B69) -> #REF! | Q5: =SUM(E5:E69) -> #REF! | R5: 45.63 | S5: =R5-P5 -> #REF! | T5: =(R5-P5)/P5 -> #REF! | U5: =SUM(K5:K69) -> #REF! | V5: =SUM(L5:L69) -> #REF! | W5: =SUM(M5:M69) -> #REF! | Y5: 1.0562 | Z5: =B5/Y5 -> #REF! | AA5: =Z5 -> #REF! | AB5: 1.0573 | AC5: =H5/AB5 -> #REF! | AD5: =(AC5-AA5)*100/AA5 -> #REF!
A6: =#REF! -> #REF! | B6: =#REF! -> #REF! | C6: =#REF! -> #REF! | D6: =D5+B6 -> #REF! | E6: =#REF! -> #REF! | F6: =F5+E6 -> #REF! | G6: 111.016 | H6: =F6*G6 -> #REF! | I6: =H6-D6 -> #REF! | J6: =(H6-D6)/D6 -> #REF! | K6: =#REF! -> #REF! | L6: =#REF! -> #REF! | M6: =#REF! -> #REF! | Z6: 0 | AA6: =AA5+Z6 -> #REF! | AB6: 1.0549 | AC6: =H6/AB6 -> #REF! | AD6: =(AC6-AA6)*100/AA6 -> #REF!
A7: =#REF! -> #REF! | B7: =#REF! -> #REF! | C7: =#REF! -> #REF! | D7: =D6+B7 -> #REF! | E7: =#REF! -> #REF! | F7: =F6+E7 -> #REF! | G7: 114.927 | H7: =F7*G7 -> #REF! | I7: =H7-D7 -> #REF! | J7: =(H7-D7)/D7 -> #REF! | K7: =#REF! -> #REF! | L7: =#REF! -> #REF! | M7: =#REF! -> #REF! | Z7: 0 | AA7: =AA6+Z7 -> #REF! | AB7: 1.0498 | AC7: =H7/AB7 -> #REF! | AD7: =(AC7-AA7)*100/AA7 -> #REF!
A8: =#REF! -> #REF! | B8: =#REF! -> #REF! | C8: =#REF! -> #REF! | D8: =D7+B8 -> #REF! | E8: =#REF! -> #REF! | F8: =F7+E8 -> #REF! | G8: 110.498 | H8: =F8*G8 -> #REF! | I8: =H8-D8 -> #REF! | J8: =(H8-D8)/D8 -> #REF! | K8: =#REF! -> #REF! | L8: =#REF! -> #REF! | M8: =#REF! -> #REF! | Z8: 0 | AA8: =AA7+Z8 -> #REF! | AB8: 1.0412 | AC8: =H8/AB8 -> #REF! | AD8: =(AC8-AA8)*100/AA8 -> #REF!
A9: =#REF! -> #REF! | B9: =#REF! -> #REF! | C9: =#REF! -> #REF! | D9: =D8+B9 -> #REF! | E9: =#REF! -> #REF! | F9: =F8+E9 -> #REF! | G9: 114.82 | H9: =F9*G9 -> #REF! | I9: =H9-D9 -> #REF! | J9: =(H9-D9)/D9 -> #REF! | K9: =#REF! -> #REF! | L9: =#REF! -> #REF! | M9: =#REF! -> #REF! | Y9: 1.0535 | Z9: =B9/Y9 -> #REF! | AA9: =AA8+Z9 -> #REF! | AB9: 1.0577 | AC9: =H9/AB9 -> #REF! | AD9: =(AC9-AA9)*100/AA9 -> #REF!
A10: =#REF! -> #REF! | B10: =#REF! -> #REF! | C10: =#REF! -> #REF! | D10: =D9+B10 -> #REF! | E10: =#REF!+#REF! -> #REF! | F10: =F9+E10 -> #REF! | G10: 125.885 | H10: =F10*G10 -> #REF! | I10: =H10-D10 -> #REF! | J10: =(H10-D10)/D10 -> #REF! | K10: =#REF! -> #REF! | L10: =#REF! -> #REF! | M10: =#REF! -> #REF! | Z10: 0 | AA10: =AA9+Z10 -> #REF! | AB10: 1.0404 | AC10: =H10/AB10 -> #REF! | AD10: =(AC10-AA10)*100/AA10 -> #REF!
A11: =#REF! -> #REF! | B11: =#REF! -> #REF! | C11: =#REF! -> #REF! | D11: =D10+B11 -> #REF! | E11: =#REF! -> #REF! | F11: =F10+E11 -> #REF! | G11: 117.775 | H11: =F11*G11 -> #REF! | I11: =H11-D11 -> #REF! | J11: =(H11-D11)/D11 -> #REF! | K11: =#REF! -> #REF! | L11: =#REF! -> #REF! | M11: =#REF! -> #REF! | Z11: 0 | AA11: =AA10+Z11 -> #REF! | AB11: 1.0543 | AC11: =H11/AB11 -> #REF! | AD11: =(AC11-AA11)*100/AA11 -> #REF!
A12: =#REF! -> #REF! | B12: =#REF! -> #REF! | C12: =#REF! -> #REF! | D12: =D11+B12 -> #REF! | E12: =#REF! -> #REF! | F12: =F11+E12 -> #REF! | G12: 121.56 | H12: =F12*G12 -> #REF! | I12: =H12-D12 -> #REF! | J12: =(H12-D12)/D12 -> #REF! | K12: =#REF! -> #REF! | L12: =#REF! -> #REF! | M12: =#REF! -> #REF! | Z12: 0 | AA12: =AA11+Z12 -> #REF! | AB12: 1.0762 | AC12: =H12/AB12 -> #REF! | AD12: =(AC12-AA12)*100/AA12 -> #REF!
A13: =#REF! -> #REF! | B13: =#REF! -> #REF! | C13: =#REF! -> #REF! | D13: =D12+B13 -> #REF! | E13: =#REF! -> #REF! | F13: =F12+E13 -> #REF! | G13: 127.174 | H13: =F13*G13 -> #REF! | I13: =H13-D13 -> #REF! | J13: =(H13-D13)/D13 -> #REF! | K13: =#REF! -> #REF! | L13: =#REF! -> #REF! | M13: =#REF! -> #REF! | Z13: 0 | AA13: =AA12+Z13 -> #REF! | AB13: 1.0861 | AC13: =H13/AB13 -> #REF! | AD13: =(AC13-AA13)*100/AA13 -> #REF!
A14: =#REF! -> #REF! | B14: =#REF! -> #REF! | C14: =#REF! -> #REF! | D14: =D13+B14 -> #REF! | E14: =#REF! -> #REF! | F14: =F13+E14 -> #REF! | G14: 130.377 | H14: =F14*G14 -> #REF! | I14: =H14-D14 -> #REF! | J14: =(H14-D14)/D14 -> #REF! | K14: =#REF! -> #REF! | L14: =#REF! -> #REF! | M14: =#REF! -> #REF! | Z14: 0 | AA14: =AA13+Z14 -> #REF! | AB14: 1.0563 | AC14: =H14/AB14 -> #REF! | AD14: =(AC14-AA14)*100/AA14 -> #REF!
A15: =#REF! -> #REF! | B15: =#REF! -> #REF! | C15: =#REF! -> #REF! | D15: =D14+B15 -> #REF! | E15: =#REF! -> #REF! | F15: =F14+E15 -> #REF! | G15: 130.641 | H15: =F15*G15 -> #REF! | I15: =H15-D15 -> #REF! | J15: =(H15-D15)/D15 -> #REF! | K15: =#REF! -> #REF! | L15: =#REF! -> #REF! | M15: =#REF! -> #REF! | Z15: 0 | AA15: =AA14+Z15 -> #REF! | AB15: 1.0269 | AC15: =H15/AB15 -> #REF! | AD15: =(AC15-AA15)*100/AA15 -> #REF!
A16: =#REF! -> #REF! | B16: =#REF! -> #REF! | C16: =#REF! -> #REF! | D16: =D15+B16 -> #REF! | E16: =#REF! -> #REF! | F16: =F15+E16 -> #REF! | G16: 136.173 | H16: =F16*G16 -> #REF! | I16: =H16-D16 -> #REF! | J16: =(H16-D16)/D16 -> #REF! | K16: =#REF! -> #REF! | L16: =#REF! -> #REF! | M16: =#REF! -> #REF! | Z16: 0 | AA16: =AA15+Z16 -> #REF! | AB16: 1.0104 | AC16: =H16/AB16 -> #REF! | AD16: =(AC16-AA16)*100/AA16 -> #REF!
A17: =#REF! -> #REF! | B17: =#REF! -> #REF! | C17: =#REF! -> #REF! | D17: =D16+B17 -> #REF! | E17: =#REF! -> #REF! | F17: =F16+E17 -> #REF! | G17: 137.074 | H17: =F17*G17 -> #REF! | I17: =H17-D17 -> #REF! | J17: =(H17-D17)/D17 -> #REF! | K17: =#REF! -> #REF! | L17: =#REF! -> #REF! | M17: =#REF! -> #REF! | Z17: 0 | AA17: =AA16+Z17 -> #REF! | AB17: 1.01 | AC17: =H17/AB17 -> #REF! | AD17: =(AC17-AA17)*100/AA17 -> #REF!
A18: =#REF! -> #REF! | B18: =#REF! -> #REF! | C18: =#REF! -> #REF! | D18: =D17+B18 -> #REF! | E18: =#REF! -> #REF! | F18: =F17+E18 -> #REF! | G18: 127.603 | H18: =F18*G18 -> #REF! | I18: =H18-D18 -> #REF! | J18: =(H18-D18)/D18 -> #REF! | K18: =#REF! -> #REF! | L18: =#REF! -> #REF! | M18: =#REF! -> #REF! | Z18: 0 | AA18: =AA17+Z18 -> #REF! | AB18: 1.0123 | AC18: =H18/AB18 -> #REF! | AD18: =(AC18-AA18)*100/AA18 -> #REF!
A19: =#REF! -> #REF! | B19: =#REF! -> #REF! | C19: =#REF! -> #REF! | D19: =D18+B19 -> #REF! | E19: =#REF! -> #REF! | F19: =F18+E19 -> #REF! | G19: 117.657 | H19: =F19*G19 -> #REF! | I19: =H19-D19 -> #REF! | J19: =(H19-D19)/D19 -> #REF! | K19: =#REF! -> #REF! | L19: =#REF! -> #REF! | M19: =#REF! -> #REF! | Z19: 0 | AA19: =AA18+Z19 -> #REF! | AB19: 1.051 | AC19: =H19/AB19 -> #REF! | AD19: =(AC19-AA19)*100/AA19 -> #REF!
A20: =#REF! -> #REF! | B20: =#REF! -> #REF! | C20: =#REF! -> #REF! | D20: =D19+B20 -> #REF! | E20: =#REF! -> #REF! | F20: =F19+E20 -> #REF! | G20: 122.41 | H20: =F20*G20 -> #REF! | I20: =H20-D20 -> #REF! | J20: =(H20-D20)/D20 -> #REF! | K20: =#REF! -> #REF! | L20: =#REF! -> #REF! | M20: =#REF! -> #REF! | Z20: 0 | AA20: =AA19+Z20 -> #REF! | AB20: 1.1061 | AC20: =H20/AB20 -> #REF! | AD20: =(AC20-AA20)*100/AA20 -> #REF!
A21: =#REF! -> #REF! | B21: =#REF! -> #REF! | C21: =#REF! -> #REF! | D21: =D20+B21 -> #REF! | E21: =#REF! -> #REF! | F21: =F20+E21 -> #REF! | G21: 133.588 | H21: =F21*G21 -> #REF! | I21: =H21-D21 -> #REF! | J21: =(H21-D21)/D21 -> #REF! | K21: =#REF! -> #REF! | L21: =#REF! -> #REF! | M21: =#REF! -> #REF! | Z21: 0 | AA21: =AA20+Z21 -> #REF! | AB21: 1.1041 | AC21: =H21/AB21 -> #REF! | AD21: =(AC21-AA21)*100/AA21 -> #REF!
A22: =#REF! -> #REF! | B22: =#REF! -> #REF! | C22: =#REF! -> #REF! | D22: =D21+B22 -> #REF! | E22: =#REF!+#REF! -> #REF! | F22: =F21+E22 -> #REF! | G22: 142.799 | H22: =F22*G22 -> #REF! | I22: =H22-D22 -> #REF! | J22: =(H22-D22)/D22 -> #REF! | K22: =#REF! -> #REF! | L22: =#REF! -> #REF! | M22: =#REF! -> #REF! | Z22: 0 | AA22: =AA21+Z22 -> #REF! | AB22: 1.2038 | AC22: =H22/AB22 -> #REF! | AD22: =(AC22-AA22)*100/AA22 -> #REF!
A23: =#REF! -> #REF! | B23: =#REF! -> #REF! | C23: =#REF! -> #REF! | D23: =D22+B23 -> #REF! | E23: =#REF! -> #REF! | F23: =F22+E23 -> #REF! | G23: 149.327 | H23: =F23*G23 -> #REF! | I23: =H23-D23 -> #REF! | J23: =(H23-D23)/D23 -> #REF! | K23: =#REF! -> #REF! | L23: =#REF! -> #REF! | M23: =#REF! -> #REF! | Z23: 0 | AA23: =AA22+Z23 -> #REF! | AB23: 1.1727 | AC23: =H23/AB23 -> #REF! | AD23: =(AC23-AA23)*100/AA23 -> #REF!
A24: =#REF! -> #REF! | B24: =#REF! -> #REF! | C24: =#REF! -> #REF! | D24: =D23+B24 -> #REF! | E24: =#REF! -> #REF! | F24: =F23+E24 -> #REF! | G24: 145.919 | H24: =F24*G24 -> #REF! | I24: =H24-D24 -> #REF! | J24: =(H24-D24)/D24 -> #REF! | K24: =#REF! -> #REF! | L24: =#REF! -> #REF! | M24: =#REF! -> #REF! | Z24: 0 | AA24: =AA23+Z24 -> #REF! | AB24: 1.1658 | AC24: =H24/AB24 -> #REF! | AD24: =(AC24-AA24)*100/AA24 -> #REF!
A25: =#REF! -> #REF! | B25: =#REF! -> #REF! | C25: =#REF! -> #REF! | D25: =D24+B25 -> #REF! | E25: =#REF! -> #REF! | F25: =F24+E25 -> #REF! | G25: 150.13 | H25: =F25*G25 -> #REF! | I25: =H25-D25 -> #REF! | J25: =(H25-D25)/D25 -> #REF! | K25: =#REF! -> #REF! | L25: =#REF! -> #REF! | M25: =#REF! -> #REF! | Z25: 0 | AA25: =AA24+Z25 -> #REF! | AB25: 1.1741 | AC25: =H25/AB25 -> #REF! | AD25: =(AC25-AA25)*100/AA25 -> #REF!
A26: =#REF! -> #REF! | B26: =#REF! -> #REF! | C26: =#REF! -> #REF! | D26: =D25+B26 -> #REF! | E26: =#REF! -> #REF! | F26: =F25+E26 -> #REF! | G26: 160.237 | H26: =F26*G26 -> #REF! | I26: =H26-D26 -> #REF! | J26: =(H26-D26)/D26 -> #REF! | K26: =#REF! -> #REF! | L26: =#REF! -> #REF! | M26: =#REF! -> #REF! | Z26: 0 | AA26: =AA25+Z26 -> #REF! | AB26: 1.155 | AC26: =H26/AB26 -> #REF! | AD26: =(AC26-AA26)*100/AA26 -> #REF!
A27: =#REF! -> #REF! | B27: =#REF! -> #REF! | C27: =#REF! -> #REF! | D27: =D26+B27 -> #REF! | E27: =#REF! -> #REF! | F27: =F26+E27 -> #REF! | G27: 145.667 | H27: =F27*G27 -> #REF! | I27: =H27-D27 -> #REF! | J27: =(H27-D27)/D27 -> #REF! | K27: =#REF! -> #REF! | L27: =#REF! -> #REF! | M27: =#REF! -> #REF! | Z27: 0 | AA27: =AA26+Z27 -> #REF! | AB27: 1.1843 | AC27: =H27/AB27 -> #REF! | AD27: =(AC27-AA27)*100/AA27 -> #REF!

Sheet SEB Global High Yield Fund
A1: SEHYUCE LX „SEB Global High Yield Fund" LY1791749010
A3: Data | B3: Suma, EUR | E3: Kiekis | G3: Mėnesio gale | K3: Mokesčiai | M3: Dividendai | O3: Global | P3: Įnešta | Q3: Kiekis | R3: Parduota | S3: Pelnas | T3: % | U3: Mokesčiai | W3: Dividendai
B4: Įnešta | C4: Mėn. Inv. | D4: Viso Inv. | E4: Mėnesio | F4: Viso | G4: Kaina | H4: Vertė gale | I4: Pelnas | J4: % | K4: Pirkimas | L4: Pardavimas | U4: Pirkimas | V4: Pardavimas
A5: =#REF! -> #REF! | B5: =#REF! -> #REF! | C5: =#REF! -> #REF! | D5: =B5 -> #REF! | E5: =#REF! -> #REF! | F5: =E5 -> #REF! | G5: 1110.609 | H5: =F5*G5 -> #REF! | I5: =H5-D5 -> #REF! | J5: =(H5-D5)/D5 -> #REF! | K5: =#REF! -> #REF! | L5: =#REF! -> #REF! | M5: =#REF! -> #REF! | O5: Viso: | P5: =SUM(B5:B42) -> #REF! | Q5: =SUM(E5:E42) -> #REF! | R5: 21.1 | S5: =R5-P5 -> #REF! | T5: =(R5-P5)/P5 -> #REF! | U5: =SUM(K5:K42) -> #REF! | V5: =SUM(L5:L42) -> #REF! | W5: =SUM(M5:M42) -> #REF!
A6: =#REF! -> #REF! | B6: =#REF! -> #REF! | C6: =#REF! -> #REF! | D6: =D5+B6 -> #REF! | E6: =#REF! -> #REF! | F6: =F5+E6 -> #REF! | G6: 1110.242 | H6: =F6*G6 -> #REF! | I6: =H6-D6 -> #REF! | J6: =(H6-D6)/D6 -> #REF! | K6: =#REF! -> #REF! | L6: =#REF! -> #REF! | M6: =#REF! -> #REF!
A7: =#REF! -> #REF! | B7: =#REF! -> #REF! | C7: =#REF! -> #REF! | D7: =D6+B7 -> #REF! | E7: =#REF! -> #REF! | F7: =F6+E7 -> #REF! | G7: 1121.548 | H7: =F7*G7 -> #REF! | I7: =H7-D7 -> #REF! | J7: =(H7-D7)/D7 -> #REF! | K7: =#REF! -> #REF! | L7: =#REF! -> #REF! | M7: =#REF! -> #REF!
A8: =#REF! -> #REF! | B8: =#REF! -> #REF! | C8: =#REF! -> #REF! | D8: =D7+B8 -> #REF! | E8: =#REF! -> #REF! | F8: =F7+E8 -> #REF! | G8: 1128.577 | H8: =F8*G8 -> #REF! | I8: =H8-D8 -> #REF! | J8: =(H8-D8)/D8 -> #REF! | K8: =#REF! -> #REF! | L8: =#REF! -> #REF! | M8: =#REF! -> #REF!
A9: =#REF! -> #REF! | B9: =#REF! -> #REF! | C9: =#REF! -> #REF! | D9: =D8+B9 -> #REF! | E9: =#REF! -> #REF! | F9: =F8+E9 -> #REF! | G9: 1118.974 | H9: =F9*G9 -> #REF! | I9: =H9-D9 -> #REF! | J9: =(H9-D9)/D9 -> #REF! | K9: =#REF! -> #REF! | L9: =#REF! -> #REF! | M9: =#REF! -> #REF!
A10: =#REF! -> #REF! | B10: =#REF! -> #REF! | C10: =#REF! -> #REF! | D10: =D9+B10 -> #REF! | E10: =#REF! -> #REF! | F10: =F9+E10 -> #REF! | G10: 1123.033 | H10: =F10*G10 -> #REF! | I10: =H10-D10 -> #REF! | J10: =(H10-D10)/D10 -> #REF! | K10: =#REF! -> #REF! | L10: =#REF! -> #REF! | M10: =#REF! -> #REF!
A11: =#REF! -> #REF! | B11: =#REF! -> #REF! | C11: =#REF! -> #REF! | D11: =D10+B11 -> #REF! | E11: =#REF! -> #REF! | F11: =F10+E11 -> #REF! | G11: 1133.532 | H11: =F11*G11 -> #REF! | I11: =H11-D11 -> #REF! | J11: =(H11-D11)/D11 -> #REF! | K11: =#REF! -> #REF! | L11: =#REF! -> #REF! | M11: =#REF! -> #REF!
A12: =#REF! -> #REF! | B12: =#REF! -> #REF! | C12: =#REF! -> #REF! | D12: =D11+B12 -> #REF! | E12: =#REF! -> #REF! | F12: =F11+E12 -> #REF! | G12: 1147.257 | H12: =F12*G12 -> #REF! | I12: =H12-D12 -> #REF! | J12: =(H12-D12)/D12 -> #REF! | K12: =#REF! -> #REF! | L12: =#REF! -> #REF! | M12: =#REF! -> #REF!
A13: =#REF! -> #REF! | B13: =#REF! -> #REF! | C13: =#REF! -> #REF! | D13: =D12+B13 -> #REF! | E13: =#REF! -> #REF! | F13: =F12+E13 -> #REF! | G13: 1155.331 | H13: =F13*G13 -> #REF! | I13: =H13-D13 -> #REF! | J13: =(H13-D13)/D13 -> #REF! | K13: =#REF! -> #REF! | L13: =#REF! -> #REF! | M13: =#REF! -> #REF!
A14: =#REF! -> #REF! | B14: =#REF! -> #REF! | C14: =#REF! -> #REF! | D14: =D13+B14 -> #REF! | E14: =#REF! -> #REF! | F14: =F13+E14 -> #REF! | G14: 1162.254 | H14: =F14*G14 -> #REF! | I14: =H14-D14 -> #REF! | J14: =(H14-D14)/D14 -> #REF! | K14: =#REF! -> #REF! | L14: =#REF! -> #REF! | M14: =#REF! -> #REF!
A15: =#REF! -> #REF! | B15: =#REF! -> #REF! | C15: =#REF! -> #REF! | D15: =D14+B15 -> #REF! | E15: =#REF! -> #REF! | F15: =F14+E15 -> #REF! | G15: 1167.074 | H15: =F15*G15 -> #REF! | I15: =H15-D15 -> #REF! | J15: =(H15-D15)/D15 -> #REF! | K15: =#REF! -> #REF! | L15: =#REF! -> #REF! | M15: =#REF! -> #REF!
A16: =#REF! -> #REF! | B16: =#REF! -> #REF! | C16: =#REF! -> #REF! | D16: =D15+B16 -> #REF! | E16: =#REF! -> #REF! | F16: =F15+E16 -> #REF! | G16: 1173.674 | H16: =F16*G16 -> #REF! | I16: =H16-D16 -> #REF! | J16: =(H16-D16)/D16 -> #REF! | K16: =#REF! -> #REF! | L16: =#REF! -> #REF! | M16: =#REF! -> #REF!
A17: =#REF! -> #REF! | B17: =#REF! -> #REF! | C17: =#REF! -> #REF! | D17: =D16+B17 -> #REF! | E17: =#REF! -> #REF! | F17: =F16+E17 -> #REF! | G17: 1172.381 | H17: =F17*G17 -> #REF! | I17: =H17-D17 -> #REF! | J17: =(H17-D17)/D17 -> #REF! | K17: =#REF! -> #REF! | L17: =#REF! -> #REF! | M17: =#REF! -> #REF!

Sheet SEB Global Exposure fund UD
A1: SEBGEUD "SEB Global Exposure fund" UD-mok. LU2625197160
A3: Data | B3: Suma, EUR | E3: Kiekis | G3: Mėnesio gale | K3: Mokesčiai | M3: Dividendai | O3: Global | P3: Įnešta | Q3: Kiekis | R3: Parduota | S3: Pelnas | T3: % | U3: Mokesčiai | W3: Dividendai
B4: Įnešta | C4: Mėn. Inv. | D4: Viso Inv. | E4: Mėnesio | F4: Viso | G4: Kaina | H4: Vertė gale | I4: Pelnas | J4: % | K4: Pirkimas | L4: Pardavimas | U4: Pirkimas | V4: Pardavimas
A5: =#REF! -> #REF! | B5: =#REF! -> #REF! | C5: =#REF! -> #REF! | D5: =B5 -> #REF! | E5: =#REF! -> #REF! | F5: =E5 -> #REF! | G5: 140.276 | H5: =F5*G5 -> #REF! | I5: =H5-D5 -> #REF! | J5: =(H5-D5)/D5 -> #REF! | K5: =#REF! -> #REF! | L5: =#REF! -> #REF! | M5: =#REF! -> #REF! | O5: Viso: | P5: =SUM(B5:B15) -> #REF! | Q5: =SUM(E5:E15) -> #REF! | R5: 31.26 | S5: =R5-P5 -> #REF! | T5: =(R5-P5)/P5 -> #REF! | U5: =SUM(K5:K15) -> #REF! | V5: =SUM(L5:L15) -> #REF! | W5: =SUM(M5:M15) -> #REF!
A6: =#REF! -> #REF! | B6: =#REF! -> #REF! | C6: =#REF! -> #REF! | D6: =D5+B6 -> #REF! | E6: =#REF! -> #REF! | F6: =F5+E6 -> #REF! | G6: 137.489 | H6: =F6*G6 -> #REF! | I6: =H6-D6 -> #REF! | J6: =(H6-D6)/D6 -> #REF! | K6: =#REF! -> #REF! | L6: =#REF! -> #REF! | M6: =#REF! -> #REF!
A7: =#REF! -> #REF! | B7: =#REF! -> #REF! | C7: =#REF! -> #REF! | D7: =D6+B7 -> #REF! | E7: =#REF! -> #REF! | F7: =F6+E7 -> #REF! | G7: 127.217 | H7: =F7*G7 -> #REF! | I7: =H7-D7 -> #REF! | J7: =(H7-D7)/D7 -> #REF! | K7: =#REF! -> #REF! | L7: =#REF! -> #REF! | M7: =#REF! -> #REF!
A8: =#REF! -> #REF! | B8: =#REF! -> #REF! | C8: =#REF! -> #REF! | D8: =D7+B8 -> #REF! | E8: =#REF! -> #REF! | F8: =F7+E8 -> #REF! | G8: 121.389 | H8: =F8*G8 -> #REF! | I8: =H8-D8 -> #REF! | J8: =(H8-D8)/D8 -> #REF! | K8: =#REF! -> #REF! | L8: =#REF! -> #REF! | M8: =#REF! -> #REF!
A9: =#REF! -> #REF! | B9: =#REF! -> #REF! | C9: =#REF! -> #REF! | D9: =D8+B9 -> #REF! | E9: =#REF! -> #REF! | F9: =F8+E9 -> #REF! | G9: 122.663 | H9: =F9*G9 -> #REF! | I9: =H9-D9 -> #REF! | J9: =(H9-D9)/D9 -> #REF! | K9: =#REF! -> #REF! | L9: =#REF! -> #REF! | M9: =#REF! -> #REF!
A10: =#REF! -> #REF! | B10: =#REF! -> #REF! | C10: =#REF! -> #REF! | D10: =D9+B10 -> #REF! | E10: =#REF!+#REF! -> #REF! | F10: =F9+E10 -> #REF! | G10: 123.142 | H10: =F10*G10 -> #REF! | I10: =H10-D10 -> #REF! | J10: =(H10-D10)/D10 -> #REF! | K10: =#REF! -> #REF! | L10: =#REF! -> #REF! | M10: =#REF! -> #REF!
A11: =#REF! -> #REF! | B11: =#REF! -> #REF! | C11: =#REF! -> #REF! | D11: =D10+B11 -> #REF! | E11: =#REF! -> #REF! | F11: =F10+E11 -> #REF! | G11: 128.973 | H11: =F11*G11 -> #REF! | I11: =H11-D11 -> #REF! | J11: =(H11-D11)/D11 -> #REF! | K11: =#REF! -> #REF! | L11: =#REF! -> #REF! | M11: =#REF! -> #REF!
A12: =#REF! -> #REF! | B12: =#REF! -> #REF! | C12: =#REF! -> #REF! | D12: =D11+B12 -> #REF! | E12: =#REF! -> #REF! | F12: =F11+E12 -> #REF! | G12: 130.775 | H12: =F12*G12 -> #REF! | I12: =H12-D12 -> #REF! | J12: =(H12-D12)/D12 -> #REF! | K12: =#REF! -> #REF! | L12: =#REF! -> #REF! | M12: =#REF! -> #REF!
A13: =#REF! -> #REF! | B13: =#REF! -> #REF! | C13: =#REF! -> #REF! | D13: =D12+B13 -> #REF! | E13: =#REF! -> #REF! | F13: =F12+E13 -> #REF! | G13: 132.906 | H13: =F13*G13 -> #REF! | I13: =H13-D13 -> #REF! | J13: =(H13-D13)/D13 -> #REF! | K13: =#REF! -> #REF! | L13: =#REF! -> #REF! | M13: =#REF! -> #REF!
A14: =#REF! -> #REF! | B14: =#REF! -> #REF! | C14: =#REF! -> #REF! | D14: =D13+B14 -> #REF! | E14: =#REF! -> #REF! | F14: =F13+E14 -> #REF! | G14: 138.825 | H14: =F14*G14 -> #REF! | I14: =H14-D14 -> #REF! | J14: =(H14-D14)/D14 -> #REF! | K14: =#REF! -> #REF! | L14: =#REF! -> #REF! | M14: =#REF! -> #REF!
A15: =#REF! -> #REF! | B15: =#REF! -> #REF! | C15: =#REF! -> #REF! | D15: =D14+B15 -> #REF! | E15: =#REF! -> #REF! | F15: =F14+E15 -> #REF! | G15: 136.499 | H15: =F15*G15 -> #REF! | I15: =H15-D15 -> #REF! | J15: =(H15-D15)/D15 -> #REF! | K15: =#REF! -> #REF! | L15: =#REF! -> #REF! | M15: =#REF! -> #REF!

Sheet SEB Europe Exposure Fund UC
A1: SEBEEUD "SEB Europe Exposure fund" LU2625195974
A3: Data | B3: Suma, EUR | E3: Kiekis | G3: Mėnesio gale | K3: Mokesčiai | M3: Dividendai | O3: Europe | P3: Įnešta | Q3: Kiekis | R3: Parduota | S3: Pelnas | T3: % | U3: Mokesčiai | W3: Dividendai
B4: Įnešta | C4: Mėn. Inv. | D4: Viso Inv. | E4: Mėnesio | F4: Viso | G4: Kaina | H4: Vertė gale | I4: Pelnas | J4: % | K4: Pirkimas | L4: Pardavimas | U4: Pirkimas | V4: Pardavimas
A5: =#REF! -> #REF! | B5: =#REF! -> #REF! | C5: =#REF! -> #REF! | D5: =B5 -> #REF! | E5: =#REF! -> #REF! | F5: =E5 -> #REF! | G5: 125.816 | H5: =F5*G5 -> #REF! | I5: =H5-D5 -> #REF! | J5: =(H5-D5)/D5 -> #REF! | K5: =#REF! -> #REF! | L5: =#REF! -> #REF! | M5: =#REF! -> #REF! | O5: Viso: | P5: =SUM(B5:B13) -> #REF! | Q5: =SUM(E5:E13) -> #REF! | R5: 53.24 | S5: =R5-P5 -> #REF! | T5: =(R5-P5)/P5 -> #REF! | U5: =SUM(K5:K13) -> #REF! | V5: =SUM(L5:L13) -> #REF! | W5: =SUM(M5:M13) -> #REF!
A6: =#REF! -> #REF! | B6: =#REF! -> #REF! | C6: =#REF! -> #REF! | D6: =D5+B6 -> #REF! | E6: =#REF! -> #REF! | F6: =F5+E6 -> #REF! | G6: 122.913 | H6: =F6*G6 -> #REF! | I6: =H6-D6 -> #REF! | J6: =(H6-D6)/D6 -> #REF! | K6: =#REF! -> #REF! | L6: =#REF! -> #REF! | M6: =#REF! -> #REF!
A7: =#REF! -> #REF! | B7: =#REF! -> #REF! | C7: =#REF! -> #REF! | D7: =D6+B7 -> #REF! | E7: =#REF! -> #REF! | F7: =F6+E7 -> #REF! | G7: 129.372 | H7: =F7*G7 -> #REF! | I7: =H7-D7 -> #REF! | J7: =(H7-D7)/D7 -> #REF! | K7: =#REF! -> #REF! | L7: =#REF! -> #REF! | M7: =#REF! -> #REF!
A8: =#REF! -> #REF! | B8: =#REF! -> #REF! | C8: =#REF! -> #REF! | D8: =D7+B8 -> #REF! | E8: =#REF! -> #REF! | F8: =F7+E8 -> #REF! | G8: 126.086 | H8: =F8*G8 -> #REF! | I8: =H8-D8 -> #REF! | J8: =(H8-D8)/D8 -> #REF! | K8: =#REF! -> #REF! | L8: =#REF! -> #REF! | M8: =#REF! -> #REF!
A9: =#REF! -> #REF! | B9: =#REF! -> #REF! | C9: =#REF! -> #REF! | D9: =D8+B9 -> #REF! | E9: =#REF! -> #REF! | F9: =F8+E9 -> #REF! | G9: 128.824 | H9: =F9*G9 -> #REF! | I9: =H9-D9 -> #REF! | J9: =(H9-D9)/D9 -> #REF! | K9: =#REF! -> #REF! | L9: =#REF! -> #REF! | M9: =#REF! -> #REF!
A10: =#REF! -> #REF! | B10: =#REF! -> #REF! | C10: =#REF! -> #REF! | D10: =D9+B10 -> #REF! | E10: =#REF! -> #REF! | F10: =F9+E10 -> #REF! | G10: 130.194 | H10: =F10*G10 -> #REF! | I10: =H10-D10 -> #REF! | J10: =(H10-D10)/D10 -> #REF! | K10: =#REF! -> #REF! | L10: =#REF! -> #REF! | M10: =#REF! -> #REF!
A11: =#REF! -> #REF! | B11: =#REF! -> #REF! | C11: =#REF! -> #REF! | D11: =D10+B11 -> #REF! | E11: =#REF! -> #REF! | F11: =F10+E11 -> #REF! | G11: 129.7 | H11: =F11*G11 -> #REF! | I11: =H11-D11 -> #REF! | J11: =(H11-D11)/D11 -> #REF! | K11: =#REF! -> #REF! | L11: =#REF! -> #REF! | M11: =#REF! -> #REF!
A12: =#REF! -> #REF! | B12: =#REF! -> #REF! | C12: =#REF! -> #REF! | D12: =D11+B12 -> #REF! | E12: =#REF! -> #REF! | F12: =F11+E12 -> #REF! | G12: 134.83 | H12: =F12*G12 -> #REF! | I12: =H12-D12 -> #REF! | J12: =(H12-D12)/D12 -> #REF! | K12: =#REF! -> #REF! | L12: =#REF! -> #REF! | M12: =#REF! -> #REF!
A13: =#REF! -> #REF! | B13: =#REF! -> #REF! | C13: =#REF! -> #REF! | D13: =D12+B13 -> #REF! | E13: =#REF! -> #REF! | F13: =F12+E13 -> #REF! | G13: 136.17 | H13: =F13*G13 -> #REF! | I13: =H13-D13 -> #REF! | J13: =(H13-D13)/D13 -> #REF! | K13: =#REF! -> #REF! | L13: =#REF! -> #REF! | M13: =#REF! -> #REF!

Sheet SEB US Exposure Fund UD
A1: SE3UUDE "SEB US Exposure fund" UD-mok. LU2625197327
A3: Data | B3: Suma, EUR | E3: Kiekis | G3: Mėnesio gale | K3: Mokesčiai | M3: Dividendai | O3: Europe | P3: Įnešta | Q3: Kiekis | R3: Parduota | S3: Pelnas | T3: % | U3: Mokesčiai | W3: Dividendai
B4: Įnešta | C4: Mėn. Inv. | D4: Viso Inv. | E4: Mėnesio | F4: Viso | G4: Kaina | H4: Vertė gale | I4: Pelnas | J4: % | K4: Pirkimas | L4: Pardavimas | U4: Pirkimas | V4: Pardavimas
A5: =#REF! -> #REF! | B5: =#REF! -> #REF! | C5: =#REF! -> #REF! | D5: =B5 -> #REF! | E5: =#REF! -> #REF! | F5: =E5 -> #REF! | G5: 120.238 | H5: =F5*G5 -> #REF! | I5: =H5-D5 -> #REF! | J5: =(H5-D5)/D5 -> #REF! | K5: =#REF! -> #REF! | L5: =#REF! -> #REF! | M5: =#REF! -> #REF! | O5: Viso: | P5: =SUM(B5:B12) -> #REF! | Q5: =SUM(E5:E12) -> #REF! | R5: 24.86 | S5: =R5-P5 -> #REF! | T5: =(R5-P5)/P5 -> #REF! | U5: =SUM(K5:K12) -> #REF! | V5: =SUM(L5:L12) -> #REF! | W5: =SUM(M5:M12) -> #REF!
A6: =#REF! -> #REF! | B6: =#REF! -> #REF! | C6: =#REF! -> #REF! | D6: =D5+B6 -> #REF! | E6: =#REF! -> #REF! | F6: =F5+E6 -> #REF! | G6: 125.993 | H6: =F6*G6 -> #REF! | I6: =H6-D6 -> #REF! | J6: =(H6-D6)/D6 -> #REF! | K6: =#REF! -> #REF! | L6: =#REF! -> #REF! | M6: =#REF! -> #REF!
A7: =#REF! -> #REF! | B7: =#REF! -> #REF! | C7: =#REF! -> #REF! | D7: =D6+B7 -> #REF! | E7: =#REF!+#REF! -> #REF! | F7: =F6+E7 -> #REF! | G7: 127.189 | H7: =F7*G7 -> #REF! | I7: =H7-D7 -> #REF! | J7: =(H7-D7)/D7 -> #REF! | K7: =#REF! -> #REF! | L7: =#REF! -> #REF! | M7: =#REF! -> #REF!
A8: =#REF! -> #REF! | B8: =#REF! -> #REF! | C8: =#REF! -> #REF! | D8: =D7+B8 -> #REF! | E8: =#REF! -> #REF! | F8: =F7+E8 -> #REF! | G8: 134.321 | H8: =F8*G8 -> #REF! | I8: =H8-D8 -> #REF! | J8: =(H8-D8)/D8 -> #REF! | K8: =#REF! -> #REF! | L8: =#REF! -> #REF! | M8: =#REF! -> #REF!
A9: =#REF! -> #REF! | B9: =#REF! -> #REF! | C9: =#REF! -> #REF! | D9: =D8+B9 -> #REF! | E9: =#REF! -> #REF! | F9: =F8+E9 -> #REF! | G9: 135.985 | H9: =F9*G9 -> #REF! | I9: =H9-D9 -> #REF! | J9: =(H9-D9)/D9 -> #REF! | K9: =#REF! -> #REF! | L9: =#REF! -> #REF! | M9: =#REF! -> #REF!
A10: =#REF! -> #REF! | B10: =#REF! -> #REF! | C10: =#REF! -> #REF! | D10: =D9+B10 -> #REF! | E10: =#REF! -> #REF! | F10: =F9+E10 -> #REF! | G10: 138.511 | H10: =F10*G10 -> #REF! | I10: =H10-D10 -> #REF! | J10: =(H10-D10)/D10 -> #REF! | K10: =#REF! -> #REF! | L10: =#REF! -> #REF! | M10: =#REF! -> #REF!
A11: =#REF! -> #REF! | B11: =#REF! -> #REF! | C11: =#REF! -> #REF! | D11: =D10+B11 -> #REF! | E11: =#REF! -> #REF! | F11: =F10+E11 -> #REF! | G11: 144.612 | H11: =F11*G11 -> #REF! | I11: =H11-D11 -> #REF! | J11: =(H11-D11)/D11 -> #REF! | K11: =#REF! -> #REF! | L11: =#REF! -> #REF! | M11: =#REF! -> #REF!
A12: =#REF! -> #REF! | B12: =#REF! -> #REF! | C12: =#REF! -> #REF! | D12: =D11+B12 -> #REF! | E12: =#REF! -> #REF! | F12: =F11+E12 -> #REF! | G12: 141.227 | H12: =F12*G12 -> #REF! | I12: =H12-D12 -> #REF! | J12: =(H12-D12)/D12 -> #REF! | K12: =#REF! -> #REF! | L12: =#REF! -> #REF! | M12: =#REF! -> #REF!

Sheet SEB Europe Exposure Fund UD
A1: SEBEUDI "SEB Europe Exposure Fund" UD-mok. LU2625196196
A3: Data | B3: Suma, EUR | E3: Kiekis | G3: Mėnesio gale | K3: Mokesčiai | M3: Dividendai | O3: Europe | P3: Įnešta | Q3: Kiekis | R3: Parduota | S3: Pelnas | T3: % | U3: Mokesčiai | W3: Dividendai
B4: Įnešta | C4: Mėn. Inv. | D4: Viso Inv. | E4: Mėnesio | F4: Viso | G4: Kaina | H4: Vertė gale | I4: Pelnas | J4: % | K4: Pirkimas | L4: Pardavimas | U4: Pirkimas | V4: Pardavimas
A5: =#REF! -> #REF! | B5: =#REF! -> #REF! | C5: =#REF! -> #REF! | D5: =B5 -> #REF! | E5: =#REF! -> #REF! | F5: =E5 -> #REF! | G5: 121.49 | H5: =F5*G5 -> #REF! | I5: =H5-D5 -> #REF! | J5: =(H5-D5)/D5 -> #REF! | K5: =#REF! -> #REF! | L5: =#REF! -> #REF! | M5: =#REF! -> #REF! | O5: Viso: | P5: =SUM(B5:B32) -> #REF! | Q5: =SUM(E5:E32) -> #REF! | R5: 10.73 | S5: =R5-P5 -> #REF! | T5: =(R5-P5)/P5 -> #REF! | U5: =SUM(K5:K32) -> #REF! | V5: =SUM(L5:L32) -> #REF! | W5: =SUM(M5:M32) -> #REF!
A6: =#REF! -> #REF! | B6: =#REF! -> #REF! | C6: =#REF! -> #REF! | D6: =D5+B6 -> #REF! | E6: =#REF!+#REF! -> #REF! | F6: =F5+E6 -> #REF! | G6: 118.405 | H6: =F6*G6 -> #REF! | I6: =H6-D6 -> #REF! | J6: =(H6-D6)/D6 -> #REF! | K6: =#REF! -> #REF! | L6: =#REF! -> #REF! | M6: =#REF! -> #REF!
A7: =#REF! -> #REF! | B7: =#REF! -> #REF! | C7: =#REF! -> #REF! | D7: =D6+B7 -> #REF! | E7: =#REF! -> #REF! | F7: =F6+E7 -> #REF! | G7: 120.976 | H7: =F7*G7 -> #REF! | I7: =H7-D7 -> #REF! | J7: =(H7-D7)/D7 -> #REF! | K7: =#REF! -> #REF! | L7: =#REF! -> #REF! | M7: =#REF! -> #REF!
A8: =#REF! -> #REF! | B8: =#REF! -> #REF! | C8: =#REF! -> #REF! | D8: =D7+B8 -> #REF! | E8: =#REF! -> #REF! | F8: =F7+E8 -> #REF! | G8: 122.263 | H8: =F8*G8 -> #REF! | I8: =H8-D8 -> #REF! | J8: =(H8-D8)/D8 -> #REF! | K8: =#REF! -> #REF! | L8: =#REF! -> #REF! | M8: =#REF! -> #REF!
A9: =#REF! -> #REF! | B9: =#REF! -> #REF! | C9: =#REF! -> #REF! | D9: =D8+B9 -> #REF! | E9: =#REF! -> #REF! | F9: =F8+E9 -> #REF! | G9: 121.799 | H9: =F9*G9 -> #REF! | I9: =H9-D9 -> #REF! | J9: =(H9-D9)/D9 -> #REF! | K9: =#REF! -> #REF! | L9: =#REF! -> #REF! | M9: =#REF! -> #REF!
A10: =#REF! -> #REF! | B10: =#REF! -> #REF! | C10: =#REF! -> #REF! | D10: =D9+B10 -> #REF! | E10: =#REF! -> #REF! | F10: =F9+E10 -> #REF! | G10: 126.616 | H10: =F10*G10 -> #REF! | I10: =H10-D10 -> #REF! | J10: =(H10-D10)/D10 -> #REF! | K10: =#REF! -> #REF! | L10: =#REF! -> #REF! | M10: =#REF! -> #REF!
A11: =#REF! -> #REF! | B11: =#REF! -> #REF! | C11: =#REF! -> #REF! | D11: =D10+B11 -> #REF! | E11: =#REF! -> #REF! | F11: =F10+E11 -> #REF! | G11: 127.756 | H11: =F11*G11 -> #REF! | I11: =H11-D11 -> #REF! | J11: =(H11-D11)/D11 -> #REF! | K11: =#REF! -> #REF! | L11: =#REF! -> #REF! | M11: =#REF! -> #REF!

Sheet 2026.09
Q2: 2026.09
Q3: Įnešta | R3: Išvesta | S3: Investuota | T3: Parduota | U3: Mokesčiai | X3: Dividendai
U4: Pirkimas | V4: Saugojimas | W4: Pardavimas
Q5: =(B19+B29+B39+B49+B59+B69+B79+B89+B99+B109)-T5 -> 30 | R5: 0 | S5: =(C19+C29+C39+C49+C59+C69+C79+C89+C99+C109)-T5 -> 30 | T5: =(I19+I29+I39+I49+I59+I69+I79+I89+I99+I109)-W5 -> 0 | U5: =D19+D29+D39+D49+D59+D69+D79+D89+D99+D109 -> 0 | V5: 0.21 | W5: =J19+J29+J39+J49+J59+J69+J79+J89+J99+J109 -> 0 | X5: =O19+O29+O39+O49+O59+O69+O79+O89+O99+O109 -> 0
A12: SESA5FE SS „SEB Active 55“ SE0016076046
A13: Pirkimas | H13: Pardavimas | N13: Dividendai
A14: Data | B14: Suma, EUR | C14: Invest. | D14: Mokestis | E14: Kaina | F14: Kiekis | H14: Data | I14: Suma,EUR | J14: Mokestis | K14: Kaina | L14: Kiekis | N14: Data | O14: Suma,EUR
A15: 46294 | B15: 15 | C15: 15 | D15: =B15-C15 -> 0 | E15: 151.20968 | F15: =B15/E15 -> 0.0992
A19: Viso: | B19: =SUM(B15:B18) -> 15 | C19: =SUM(C15:C18) -> 15 | D19: =SUM(D15:D18) -> 0 | E19: =IF(B19>0,SUMPRODUCT(E15:E18,F15:F18)/SUM(F15:F18),"0.00") -> 151.20968 | F19: =SUM(F15:F18) -> 0.0992 | H19: Viso: | I19: =SUM(I15:I18) -> 0 | J19: =SUM(J15:J18) -> 0 | L19: =SUM(L15:L18) -> 0 | N19: Viso: | O19: =SUM(O15:O18) -> 0
A22: SESA8FE SS „SEB Active 80“ SE0016076111
A23: Pirkimas | H23: Pardavimas | N23: Dividendai
A24: Data | B24: Suma, EUR | C24: Invest. | D24: Mokestis | E24: Kaina | F24: Kiekis | H24: Data | I24: Suma,EUR | J24: Mokestis | K24: Kaina | L24: Kiekis | N24: Data | O24: Suma,EUR
A25: 46293 | B25: 15 | C25: 15 | D25: =B25-C25 -> 0 | E25: 175.4386 | F25: =C25/E25 -> 0.0855
A29: Viso: | B29: =SUM(B25:B28) -> 15 | C29: =SUM(C25:C28) -> 15 | D29: =SUM(D25:D28) -> 0 | E29: =IF(B29>0,SUMPRODUCT(E25:E28,F25:F28)/SUM(F25:F28),"0.00") -> 175.4386 | F29: =SUM(F25:F28) -> 0.0855 | H29: Viso: | I29: =SUM(I25:I28) -> 0 | J29: =SUM(J25:J28) -> 0 | L29: =SUM(L25:L28) -> 0 | N29: Viso: | O29: =SUM(O25:O28) -> 0

Sheet 2026.08
Q2: 2026.08
