Workbook

Sheet Apžvalga
A1: Data | B1: Viso: | E1: Mėnesio gale | P1: Dividendai | Q1: Mokesčiai
B2: Inešta | C2: Išvesta | D2: Investuota | E2: Active 55 | F2: Active 80 | G2: Artificial | H2: Glob. Yield | I2: Glob.Ex.UD | J2: Eur.Ex.UC | K2: US.Ex.UD | L2: Eur.Ex.UD | M2: Vertė | N2: Pelnas | O2: % | Q2: Pirkimas | R2: Pardavimas | S2: Laikymas
A3: ='2021.06'!Q2 -> 2021.06 | B3: ='2021.06'!Q5 -> 63 | C3: ='2021.06'!R5 -> 0 | D3: ='2021.06'!S5 -> 63 | E3: ='SEB Active 55'!H5 -> 59.88 | F3: ='SEB Active 80'!H5 -> 3 | G3: 0 | H3: 0 | I3: 0 | J3: 0 | K3: 0 | L3: 0 | M3: =SUM(E3:L3) -> 62.88 | N3: =M3-B3 -> -0.12 | O3: =N3/B3 -> -0.0019 | P3: ='2021.06'!X5 -> 0 | Q3: ='2021.06'!U5 -> 0 | R3: ='2021.06'!W5 -> 0 | S3: ='2021.06'!V5 -> 0
A4: ='2021.07'!Q2 -> 2021.07 | B4: =B3+'2021.07'!Q5 -> 81 | C4: ='2021.07'!R5 -> 0 | D4: =D3+'2021.07'!S5 -> 81 | E4: ='SEB Active 55'!H6 -> 71.34 | F4: ='SEB Active 80'!H6 -> 10.96 | G4: 0 | H4: 0 | I4: 0 | J4: 0 | K4: 0 | L4: 0 | M4: =SUM(E4:L4) -> 82.3 | N4: =M4-B4 -> 1.3 | O4: =N4/B4 -> 0.016 | P4: ='2021.07'!X5 -> 0 | Q4: ='2021.07'!U5 -> 0 | R4: ='2021.07'!W5 -> 0 | S4: ='2021.07'!V5 -> 0.01
A5: ='2021.08'!Q2 -> 2021.08 | B5: =B4+'2021.08'!Q15 -> 81 | C5: ='2021.08'!R15 -> 0 | D5: =D4+'2021.08'!S15 -> 81 | E5: ='SEB Active 55'!H7 -> 81.34 | F5: ='SEB Active 80'!H7 -> 17.45 | G5: 0 | H5: 0 | I5: 0 | J5: 0 | K5: 0 | L5: 0 | M5: =SUM(E5:L5) -> 98.79 | N5: =M5-B5 -> 17.79 | O5: =N5/B5 -> 0.2196 | P5: ='2021.08'!X15 -> 0 | Q5: ='2021.08'!U15 -> 0 | R5: ='2021.08'!W15 -> 0 | S5: ='2021.08'!V15 -> 0
A6: ='2021.09'!Q2 -> 2021.09 | B6: =B5+'2021.09'!Q5 -> 137 | C6: ='2021.09'!R5 -> 0 | D6: =D5+'2021.09'!S5 -> 137 | E6: ='SEB Active 55'!H8 -> 91.34 | F6: ='SEB Active 80'!H8 -> 62.93 | G6: 0 | H6: 0 | I6: 0 | J6: 0 | K6: 0 | L6: 0 | M6: =SUM(E6:L6) -> 154.27 | N6: =M6-B6 -> 17.27 | O6: =N6/B6 -> 0.1261 | P6: ='2021.09'!X5 -> 0 | Q6: ='2021.09'!U5 -> 0 | R6: ='2021.09'!W5 -> 0 | S6: ='2021.09'!V5 -> 0.03
A7: ='2021.10'!Q2 -> 2021.1 | B7: =B6+'2021.10'!Q5 -> 174 | C7: ='2021.10'!R5 -> 0 | D7: =D6+'2021.10'!S5 -> 174 | E7: ='SEB Active 55'!H9 -> 100.24 | F7: ='SEB Active 80'!H9 -> 89.47 | G7: 0 | H7: 0 | I7: 0 | J7: 0 | K7: 0 | L7: 0 | M7: =SUM(E7:L7) -> 189.71 | N7: =M7-B7 -> 15.71 | O7: =N7/B7 -> 0.0903 | P7: ='2021.10'!X5 -> 0 | Q7: ='2021.10'!U5 -> 0 | R7: ='2021.10'!W5 -> 0 | S7: ='2021.10'!V5 -> 0.04
A8: ='2021.11'!Q2 -> 2021.11 | B8: =B7+'2021.11'!Q5 -> 183 | C8: ='2021.11'!R5 -> 0 | D8: =D7+'2021.11'!S5 -> 183 | E8: ='SEB Active 55'!H10 -> 100.88 | F8: ='SEB Active 80'!H10 -> 99.14 | G8: 0 | H8: 0 | I8: 0 | J8: 0 | K8: 0 | L8: 0 | M8: =SUM(E8:L8) -> 200.02 | N8: =M8-B8 -> 17.02 | O8: =N8/B8 -> 0.093 | P8: ='2021.11'!X5 -> 0 | Q8: ='2021.11'!U5 -> 0 | R8: ='2021.11'!W5 -> 0 | S8: ='2021.11'!V5 -> 0.06
A9: ='2021.12'!Q2 -> 2021.12 | B9: =B8+'2021.12'!Q5 -> 228 | C9: ='2021.12'!R5 -> 0 | D9: =D8+'2021.12'!S5 -> 228 | E9: ='SEB Active 55'!H11 -> 137.59 | F9: ='SEB Active 80'!H11 -> 111.04 | G9: 0 | H9: 0 | I9: 0 | J9: 0 | K9: 0 | L9: 0 | M9: =SUM(E9:L9) -> 248.63 | N9: =M9-B9 -> 20.63 | O9: =N9/B9 -> 0.0905 | P9: ='2021.12'!X5 -> 0 | Q9: ='2021.12'!U5 -> 0 | R9: ='2021.12'!W5 -> 0 | S9: ='2021.12'!V5 -> 0.08
A10: ='2022.01'!Q2 -> 2022.01 | B10: =B9+'2022.01'!Q5 -> 256 | C10: ='2022.01'!R5 -> 0 | D10: =D9+'2022.01'!S5 -> 256 | E10: ='SEB Active 55'!H12 -> 156.23 | F10: ='SEB Active 80'!H12 -> 101.62 | G10: 0 | H10: 0 | I10: 0 | J10: 0 | K10: 0 | L10: 0 | M10: =SUM(E10:L10) -> 257.85 | N10: =M10-B10 -> 1.85 | O10: =N10/B10 -> 0.0072 | P10: ='2022.01'!X5 -> 0 | Q10: ='2022.01'!U5 -> 0 | R10: ='2022.01'!W5 -> 0 | S10: ='2022.01'!V5 -> 0.08
A11: ='2022.02'!Q2 -> 2022.02 | B11: =B10+'2022.02'!Q5 -> 266 | C11: ='2022.02'!R5 -> 0 | D11: =D10+'2022.02'!S5 -> 266 | E11: ='SEB Active 55'!H13 -> 163.12 | F11: ='SEB Active 80'!H13 -> 99.5 | G11: 0 | H11: 0 | I11: 0 | J11: 0 | K11: 0 | L11: 0 | M11: =SUM(E11:L11) -> 262.62 | N11: =M11-B11 -> -3.38 | O11: =N11/B11 -> -0.0127 | P11: ='2022.02'!X5 -> 0 | Q11: ='2022.02'!U5 -> 0 | R11: ='2022.02'!W5 -> 0 | S11: ='2022.02'!V5 -> 0.09
A12: ='2022.03'!Q2 -> 2022.03 | B12: =B11+'2022.03'!Q5 -> 276 | C12: ='2022.03'!R5 -> 0 | D12: =D11+'2022.03'!S5 -> 276 | E12: ='SEB Active 55'!H14 -> 177.1 | F12: ='SEB Active 80'!H14 -> 103.48 | G12: 0 | H12: 0 | I12: 0 | J12: 0 | K12: 0 | L12: 0 | M12: =SUM(E12:L12) -> 280.58 | N12: =M12-B12 -> 4.58 | O12: =N12/B12 -> 0.0166 | P12: ='2022.03'!X5 -> 0 | Q12: ='2022.03'!U5 -> 0 | R12: ='2022.03'!W5 -> 0 | S12: ='2022.03'!V5 -> 0.1
A13: ='2022.04'!Q2 -> 2022.04 | B13: =B12+'2022.04'!Q5 -> 286 | C13: ='2022.04'!R5 -> 0 | D13: =D12+'2022.04'!S5 -> 286 | E13: ='SEB Active 55'!H15 -> 180.79 | F13: ='SEB Active 80'!H15 -> 98.73 | G13: 0 | H13: 0 | I13: 0 | J13: 0 | K13: 0 | L13: 0 | M13: =SUM(E13:L13) -> 279.52 | N13: =M13-B13 -> -6.48 | O13: =N13/B13 -> -0.0227 | P13: ='2022.04'!X5 -> 0 | Q13: ='2022.04'!U5 -> 0 | R13: ='2022.04'!W5 -> 0 | S13: ='2022.04'!V5 -> 0.09
A14: ='2022.05'!Q2 -> 2022.05 | B14: =B13+'2022.05'!Q5 -> 296 | C14: ='2022.05'!R5 -> 0 | D14: =D13+'2022.05'!S5 -> 296 | E14: ='SEB Active 55'!H16 -> 188.67 | F14: ='SEB Active 80'!H16 -> 97.22 | G14: 0 | H14: 0 | I14: 0 | J14: 0 | K14: 0 | L14: 0 | M14: =SUM(E14:L14) -> 285.89 | N14: =M14-B14 -> -10.11 | O14: =N14/B14 -> -0.0342 | P14: ='2022.05'!X5 -> 0 | Q14: ='2022.05'!U5 -> 0 | R14: ='2022.05'!W5 -> 0 | S14: ='2022.05'!V5 -> 0.1
A15: ='2022.06'!Q2 -> 2022.06 | B15: =B14+'2022.06'!Q5 -> 306 | C15: ='2022.06'!R5 -> 0 | D15: =D14+'2022.06'!S5 -> 306 | E15: ='SEB Active 55'!H17 -> 189.19 | F15: ='SEB Active 80'!H17 -> 90.91 | G15: 0 | H15: 0 | I15: 0 | J15: 0 | K15: 0 | L15: 0 | M15: =SUM(E15:L15) -> 280.1 | N15: =M15-B15 -> -25.9 | O15: =N15/B15 -> -0.0846 | P15: ='2022.06'!X5 -> 0 | Q15: ='2022.06'!U5 -> 0 | R15: ='2022.06'!W5 -> 0 | S15: ='2022.06'!V5 -> 0.09
A16: ='2022.07'!Q2 -> 2022.07 | B16: =B15+'2022.07'!Q5 -> 316 | C16: ='2022.07'!R5 -> 0 | D16: =D15+'2022.07'!S5 -> 316 | E16: ='SEB Active 55'!H18 -> 208.78 | F16: ='SEB Active 80'!H18 -> 96.53 | G16: 0 | H16: 0 | I16: 0 | J16: 0 | K16: 0 | L16: 0 | M16: =SUM(E16:L16) -> 305.31 | N16: =M16-B16 -> -10.69 | O16: =N16/B16 -> -0.0338 | P16: ='2022.07'!X5 -> 0 | Q16: ='2022.07'!U5 -> 0 | R16: ='2022.07'!W5 -> 0 | S16: ='2022.07'!V5 -> 0.1
A17: ='2022.08'!Q2 -> 2022.08 | B17: =B16+'2022.08'!Q5 -> 326 | C17: ='2022.08'!R5 -> 0 | D17: =D16+'2022.08'!S5 -> 326 | E17: ='SEB Active 55'!H19 -> 214.27 | F17: ='SEB Active 80'!H19 -> 94.52 | G17: 0 | H17: 0 | I17: 0 | J17: 0 | K17: 0 | L17: 0 | M17: =SUM(E17:L17) -> 308.79 | N17: =M17-B17 -> -17.21 | O17: =N17/B17 -> -0.0528 | P17: ='2022.08'!X5 -> 0 | Q17: ='2022.08'!U5 -> 0 | R17: ='2022.08'!W5 -> 0 | S17: ='2022.08'!V5 -> 0.1
A18: ='2022.09'!Q2 -> 2022.09 | B18: =B17+'2022.09'!Q5 -> 336 | C18: ='2022.09'!R5 -> 0 | D18: =D17+'2022.09'!S5 -> 336 | E18: ='SEB Active 55'!H20 -> 208.51 | F18: ='SEB Active 80'!H20 -> 86.13 | G18: 0 | H18: 0 | I18: 0 | J18: 0 | K18: 0 | L18: 0 | M18: =SUM(E18:L18) -> 294.64 | N18: =M18-B18 -> -41.36 | O18: =N18/B18 -> -0.1231 | P18: ='2022.09'!X5 -> 0 | Q18: ='2022.09'!U5 -> 0 | R18: ='2022.09'!W5 -> 0 | S18: ='2022.09'!V5 -> 0.11
A19: ='2022.10'!Q2 -> 2022.1 | B19: =B18+'2022.10'!Q5 -> 346 | C19: ='2022.10'!R5 -> 0 | D19: =D18+'2022.10'!S5 -> 346 | E19: ='SEB Active 55'!H21 -> 224.92 | F19: ='SEB Active 80'!H21 -> 89.63 | G19: 0 | H19: 0 | I19: 0 | J19: 0 | K19: 0 | L19: 0 | M19: =SUM(E19:L19) -> 314.55 | N19: =M19-B19 -> -31.45 | O19: =N19/B19 -> -0.0909 | P19: ='2022.10'!X5 -> 0 | Q19: ='2022.10'!U5 -> 0 | R19: ='2022.10'!W5 -> 0 | S19: ='2022.10'!V5 -> 0.1
A20: ='2022.11'!Q2 -> 2022.11 | B20: =B19+'2022.11'!Q5 -> 356 | C20: ='2022.11'!R5 -> 0 | D20: =D19+'2022.11'!S5 -> 356 | E20: ='SEB Active 55'!H22 -> 239.94 | F20: ='SEB Active 80'!H22 -> 92.16 | G20: 0 | H20: 0 | I20: 0 | J20: 0 | K20: 0 | L20: 0 | M20: =SUM(E20:L20) -> 332.1 | N20: =M20-B20 -> -23.9 | O20: =N20/B20 -> -0.0671 | P20: ='2022.11'!X5 -> 0 | Q20: ='2022.11'!U5 -> 0 | R20: ='2022.11'!W5 -> 0 | S20: ='2022.11'!V5 -> 0.11
A21: ='2022.12'!Q2 -> 2022.12 | B21: =B20+'2022.12'!Q5 -> 366 | C21: ='2022.12'!R5 -> 0 | D21: =D20+'2022.12'!S5 -> 366 | E21: ='SEB Active 55'!H23 -> 245.93 | F21: ='SEB Active 80'!H23 -> 90.27 | G21: 0 | H21: 0 | I21: 0 | J21: 0 | K21: 0 | L21: 0 | M21: =SUM(E21:L21) -> 336.2 | N21: =M21-B21 -> -29.8 | O21: =N21/B21 -> -0.0814 | P21: ='2022.12'!X5 -> 0 | Q21: ='2022.12'!U5 -> 0 | R21: ='2022.12'!W5 -> 0 | S21: ='2022.12'!V5 -> 0.11
A22: ='2023.01'!Q2 -> 2023.01 | B22: =B21+'2023.01'!Q5 -> 376 | C22: ='2023.01'!R5 -> 0 | D22: =D21+'2023.01'!S5 -> 376 | E22: ='SEB Active 55'!H24 -> 265.53 | F22: ='SEB Active 80'!H24 -> 94.55 | G22: 0 | H22: 0 | I22: 0 | J22: 0 | K22: 0 | L22: 0 | M22: =SUM(E22:L22) -> 360.08 | N22: =M22-B22 -> -15.92 | O22: =N22/B22 -> -0.0423 | P22: ='2023.01'!X5 -> 0 | Q22: ='2023.01'!U5 -> 0 | R22: ='2023.01'!W5 -> 0 | S22: ='2023.01'!V5 -> 0.12
A23: ='2023.02'!Q2 -> 2023.02 | B23: =B22+'2023.02'!Q5 -> 386 | C23: ='2023.02'!R5 -> 0 | D23: =D22+'2023.02'!S5 -> 386 | E23: ='SEB Active 55'!H25 -> 274.08 | F23: ='SEB Active 80'!H25 -> 94.68 | G23: 0 | H23: 0 | I23: 0 | J23: 0 | K23: 0 | L23: 0 | M23: =SUM(E23:L23) -> 368.76 | N23: =M23-B23 -> -17.24 | O23: =N23/B23 -> -0.0447 | P23: ='2023.02'!X5 -> 0 | Q23: ='2023.02'!U5 -> 0 | R23: ='2023.02'!W5 -> 0 | S23: ='2023.02'!V5 -> 0.12
A24: ='2023.03'!Q2 -> 2023.03 | B24: =B23+'2023.03'!Q5 -> 396 | C24: ='2023.03'!R5 -> 0 | D24: =D23+'2023.03'!S5 -> 396 | E24: ='SEB Active 55'!H26 -> 281.24 | F24: ='SEB Active 80'!H26 -> 92.95 | G24: 0 | H24: 0 | I24: 0 | J24: 0 | K24: 0 | L24: 0 | M24: =SUM(E24:L24) -> 374.19 | N24: =M24-B24 -> -21.81 | O24: =N24/B24 -> -0.0551 | P24: ='2023.03'!X5 -> 0 | Q24: ='2023.03'!U5 -> 0 | R24: ='2023.03'!W5 -> 0 | S24: ='2023.03'!V5 -> 0.12
A25: ='2023.04'!Q2 -> 2023.04 | B25: =B24+'2023.04'!Q5 -> 406 | C25: ='2023.04'!R5 -> 0 | D25: =D24+'2023.04'!S5 -> 406 | E25: ='SEB Active 55'!H27 -> 293.06 | F25: ='SEB Active 80'!H27 -> 93.7 | G25: 0 | H25: 0 | I25: 0 | J25: 0 | K25: 0 | L25: 0 | M25: =SUM(E25:L25) -> 386.76 | N25: =M25-B25 -> -19.24 | O25: =N25/B25 -> -0.0474 | P25: ='2023.04'!X5 -> 0 | Q25: ='2023.04'!U5 -> 0 | R25: ='2023.04'!W5 -> 0 | S25: ='2023.04'!V5 -> 0.13
A26: ='2023.05'!Q2 -> 2023.05 | B26: =B25+'2023.05'!Q5 -> 416 | C26: ='2023.05'!R5 -> 0 | D26: =D25+'2023.05'!S5 -> 416 | E26: ='SEB Active 55'!H28 -> 306 | F26: ='SEB Active 80'!H28 -> 95.04 | G26: 0 | H26: 0 | I26: 0 | J26: 0 | K26: 0 | L26: 0 | M26: =SUM(E26:L26) -> 401.04 | N26: =M26-B26 -> -14.96 | O26: =N26/B26 -> -0.036 | P26: ='2023.05'!X5 -> 0 | Q26: ='2023.05'!U5 -> 0 | R26: ='2023.05'!W5 -> 0 | S26: ='2023.05'!V5 -> 0.13
A27: ='2023.06'!Q2 -> 2023.06 | B27: =B26+'2023.06'!Q5 -> 426 | C27: ='2023.06'!R5 -> 0 | D27: =D26+'2023.06'!S5 -> 426 | E27: ='SEB Active 55'!H29 -> 317.57 | F27: ='SEB Active 80'!H29 -> 95.88 | G27: 0 | H27: 0 | I27: 0 | J27: 0 | K27: 0 | L27: 0 | M27: =SUM(E27:L27) -> 413.45 | N27: =M27-B27 -> -12.55 | O27: =N27/B27 -> -0.0295 | P27: ='2023.06'!X5 -> 0 | Q27: ='2023.06'!U5 -> 0 | R27: ='2023.06'!W5 -> 0 | S27: ='2023.06'!V5 -> 0.13
A28: ='2023.07'!Q2 -> 2023.07 | B28: =B27+'2023.07'!Q5 -> 436 | C28: ='2023.07'!R5 -> 0 | D28: =D27+'2023.07'!S5 -> 436 | E28: ='SEB Active 55'!H30 -> 332.8 | F28: ='SEB Active 80'!H30 -> 97.72 | G28: 0 | H28: 0 | I28: 0 | J28: 0 | K28: 0 | L28: 0 | M28: =SUM(E28:L28) -> 430.52 | N28: =M28-B28 -> -5.48 | O28: =N28/B28 -> -0.0126 | P28: ='2023.07'!X5 -> 0 | Q28: ='2023.07'!U5 -> 0 | R28: ='2023.07'!W5 -> 0 | S28: ='2023.07'!V5 -> 0.14
A29: ='2023.08'!Q2 -> 2023.08 | B29: =B28+'2023.08'!Q5 -> 446 | C29: ='2023.08'!R5 -> 0 | D29: =D28+'2023.08'!S5 -> 446 | E29: ='SEB Active 55'!H31 -> 339.38 | F29: ='SEB Active 80'!H31 -> 96.3 | G29: 0 | H29: 0 | I29: 0 | J29: 0 | K29: 0 | L29: 0 | M29: =SUM(E29:L29) -> 435.68 | N29: =M29-B29 -> -10.32 | O29: =N29/B29 -> -0.0231 | P29: ='2023.08'!X5 -> 0 | Q29: ='2023.08'!U5 -> 0 | R29: ='2023.08'!W5 -> 0 | S29: ='2023.08'!V5 -> 0.14
A30: ='2023.09'!Q2 -> 2023.09 | B30: =B29+'2023.09'!Q5 -> 456 | C30: ='2023.09'!R5 -> 0 | D30: =D29+'2023.09'!S5 -> 456 | E30: ='SEB Active 55'!H32 -> 344.22 | F30: ='SEB Active 80'!H32 -> 94.78 | G30: 0 | H30: 0 | I30: 0 | J30: 0 | K30: 0 | L30: 0 | M30: =SUM(E30:L30) -> 439 | N30: =M30-B30 -> -17 | O30: =N30/B30 -> -0.0373 | P30: ='2023.09'!X5 -> 0 | Q30: ='2023.09'!U5 -> 0 | R30: ='2023.09'!W5 -> 0 | S30: ='2023.09'!V5 -> 0.15
A31: ='2023.10'!Q2 -> 2023.1 | B31: =B30+'2023.10'!Q5 -> 466 | C31: ='2023.10'!R5 -> 0 | D31: =D30+'2023.10'!S5 -> 466 | E31: ='SEB Active 55'!H33 -> 344.15 | F31: ='SEB Active 80'!H33 -> 90.9 | G31: 0 | H31: 0 | I31: 0 | J31: 0 | K31: 0 | L31: 0 | M31: =SUM(E31:L31) -> 435.05 | N31: =M31-B31 -> -30.95 | O31: =N31/B31 -> -0.0664 | P31: ='2023.10'!X5 -> 0 | Q31: ='2023.10'!U5 -> 0 | R31: ='2023.10'!W5 -> 0 | S31: ='2023.10'!V5 -> 0.15
A32: ='2023.11'!Q2 -> 2023.11 | B32: =B31+'2023.11'!Q5 -> 476 | C32: ='2023.11'!R5 -> 0 | D32: =D31+'2023.11'!S5 -> 476 | E32: ='SEB Active 55'!H34 -> 375.17 | F32: ='SEB Active 80'!H34 -> 97.88 | G32: 0 | H32: 0 | I32: 0 | J32: 0 | K32: 0 | L32: 0 | M32: =SUM(E32:L32) -> 473.05 | N32: =M32-B32 -> -2.95 | O32: =N32/B32 -> -0.0062 | P32: ='2023.11'!X5 -> 0 | Q32: ='2023.11'!U5 -> 0 | R32: ='2023.11'!W5 -> 0 | S32: ='2023.11'!V5 -> 0.15
A33: ='2023.12'!Q2 -> 2023.12 | B33: =B32+'2023.12'!Q5 -> 486 | C33: ='2023.12'!R5 -> 0 | D33: =D32+'2023.12'!S5 -> 486 | E33: ='SEB Active 55'!H35 -> 401.01 | F33: ='SEB Active 80'!H35 -> 102.86 | G33: 0 | H33: 0 | I33: 0 | J33: 0 | K33: 0 | L33: 0 | M33: =SUM(E33:L33) -> 503.87 | N33: =M33-B33 -> 17.87 | O33: =N33/B33 -> 0.0368 | P33: ='2023.12'!X5 -> 0 | Q33: ='2023.12'!U5 -> 0 | R33: ='2023.12'!W5 -> 0 | S33: ='2023.12'!V5 -> 0.16
A34: ='2024.01'!Q2 -> 2024.01 | B34: =B33+'2024.01'!Q5 -> 524.94 | C34: ='2024.01'!R5 -> 0 | D34: =D33+'2024.01'!S5 -> 524.94 | E34: ='SEB Active 55'!H36 -> 416.97 | F34: ='SEB Active 80'!H36 -> 114.77 | G34: ='SEB Artificial Intelligence Fun'!AN5 -> 19.1 | H34: 0 | I34: 0 | J34: 0 | K34: 0 | L34: 0 | M34: =SUM(E34:L34) -> 550.84 | N34: =M34-B34 -> 25.9 | O34: =N34/B34 -> 0.0493 | P34: ='2024.01'!X5 -> 0 | Q34: ='2024.01'!U5 -> 0 | R34: ='2024.01'!W5 -> 0 | S34: ='2024.01'!V5 -> 0.18
A35: ='2024.02'!Q2 -> 2024.02 | B35: =B34+'2024.02'!Q5 -> 549.94 | C35: ='2024.02'!R5 -> 0 | D35: =D34+'2024.02'!S5 -> 549.94 | E35: ='SEB Active 55'!H37 -> 440.74 | F35: ='SEB Active 80'!H37 -> 128.23 | G35: ='SEB Artificial Intelligence Fun'!AN6 -> 19.99 | H35: 0 | I35: 0 | J35: 0 | K35: 0 | L35: 0 | M35: =SUM(E35:L35) -> 588.96 | N35: =M35-B35 -> 39.02 | O35: =N35/B35 -> 0.071 | P35: ='2024.02'!X5 -> 0 | Q35: ='2024.02'!U5 -> 0 | R35: ='2024.02'!W5 -> 0 | S35: ='2024.02'!V5 -> 0.18
A36: ='2024.03'!Q2 -> 2024.03 | B36: =B35+'2024.03'!Q5 -> 564.94 | C36: ='2024.03'!R5 -> 0 | D36: =D35+'2024.03'!S5 -> 564.94 | E36: ='SEB Active 55'!H38 -> 466.86 | F36: ='SEB Active 80'!H38 -> 132.08 | G36: ='SEB Artificial Intelligence Fun'!AN7 -> 20.8 | H36: 0 | I36: 0 | J36: 0 | K36: 0 | L36: 0 | M36: =SUM(E36:L36) -> 619.74 | N36: =M36-B36 -> 54.8 | O36: =N36/B36 -> 0.097 | P36: ='2024.03'!X5 -> 0 | Q36: ='2024.03'!U5 -> 0 | R36: ='2024.03'!W5 -> 0 | S36: ='2024.03'!V5 -> 0.2
A37: ='2024.04'!Q2 -> 2024.04 | B37: =B36+'2024.04'!Q5 -> 589.94 | C37: ='2024.04'!R5 -> 0 | D37: =D36+'2024.04'!S5 -> 589.94 | E37: ='SEB Active 55'!H39 -> 475.3 | F37: ='SEB Active 80'!H39 -> 139.88 | G37: ='SEB Artificial Intelligence Fun'!AN8 -> 20.16 | H37: 0 | I37: 0 | J37: 0 | K37: 0 | L37: 0 | M37: =SUM(E37:L37) -> 635.34 | N37: =M37-B37 -> 45.4 | O37: =N37/B37 -> 0.077 | P37: ='2024.04'!X5 -> 0 | Q37: ='2024.04'!U5 -> 0 | R37: ='2024.04'!W5 -> 0 | S37: ='2024.04'!V5 -> 0.22
A38: ='2024.05'!Q2 -> 2024.05 | B38: =B37+'2024.05'!Q5 -> 643.92 | C38: ='2024.05'!R5 -> 0 | D38: =D37+'2024.05'!S5 -> 643.92 | E38: ='SEB Active 55'!H40 -> 500.88 | F38: ='SEB Active 80'!H40 -> 163.98 | G38: ='SEB Artificial Intelligence Fun'!AN9 -> 39.51 | H38: 0 | I38: 0 | J38: 0 | K38: 0 | L38: 0 | M38: =SUM(E38:L38) -> 704.37 | N38: =M38-B38 -> 60.45 | O38: =N38/B38 -> 0.0939 | P38: ='2024.05'!X5 -> 0 | Q38: ='2024.05'!U5 -> 0 | R38: ='2024.05'!W5 -> 0 | S38: ='2024.05'!V5 -> 0.22
A39: ='2024.06'!Q2 -> 2024.06 | B39: =B38+'2024.06'!Q5 -> 658.92 | C39: ='2024.06'!R5 -> 0 | D39: =D38+'2024.06'!S5 -> 658.92 | E39: ='SEB Active 55'!H41 -> 525.42 | F39: ='SEB Active 80'!H41 -> 167.45 | G39: ='SEB Artificial Intelligence Fun'!AN10 -> 44.41 | H39: 0 | I39: 0 | J39: 0 | K39: 0 | L39: 0 | M39: =SUM(E39:L39) -> 737.28 | N39: =M39-B39 -> 78.36 | O39: =N39/B39 -> 0.1189 | P39: ='2024.06'!X5 -> 0 | Q39: ='2024.06'!U5 -> 0 | R39: ='2024.06'!W5 -> 0 | S39: ='2024.06'!V5 -> 0.23
A40: ='2024.07'!Q2 -> 2024.07 | B40: =B39+'2024.07'!Q5 -> 693.92 | C40: ='2024.07'!R5 -> 0 | D40: =D39+'2024.07'!S5 -> 693.92 | E40: ='SEB Active 55'!H42 -> 538 | F40: ='SEB Active 80'!H42 -> 185.76 | G40: ='SEB Artificial Intelligence Fun'!AN11 -> 40.99 | H40: 0 | I40: 0 | J40: 0 | K40: 0 | L40: 0 | M40: =SUM(E40:L40) -> 764.75 | N40: =M40-B40 -> 70.83 | O40: =N40/B40 -> 0.1021 | P40: ='2024.07'!X5 -> 0 | Q40: ='2024.07'!U5 -> 0 | R40: ='2024.07'!W5 -> 0 | S40: ='2024.07'!V5 -> 0.25
...

Sheet SEB Active 55
A1: SESA5FE SS „SEB Active 55“ SE0016076046
A3: Data | B3: Suma, EUR | E3: Kiekis | G3: Mėnesio gale | K3: Mokesčiai | M3: Dividendai | O3: Active 55 | P3: Įnešta | Q3: Kiekis | R3: Parduota | S3: Pelnas | V3: Mokesčiai | X3: Dividendai | Y3: Vid. Kaina | AC3: Suma | AD3: Kaina | AE3: Kiekis | AF3: Pirkimas/pardavimas
B4: Įnešta | C4: Mėn. Inv. | D4: Viso Inv. | E4: Mėnesio | F4: Viso | G4: Kaina | H4: Vertė gale | I4: Pelnas | J4: % | K4: Pirkimas | L4: Pardavimas | S4: Eur. | T4: % | U4: XIRR | V4: Pirkimas | W4: Pardavimas | AF4: Data | AG4: Suma
A5: ='2021.06'!Q2 -> 2021.06 | B5: ='2021.06'!B19 -> 60 | C5: ='2021.06'!C19 -> 60 | D5: =C5 -> 60 | E5: ='2021.06'!F19 -> 0.503 | F5: =E5 -> 0.503 | G5: 119.0476 | H5: =F5*G5 -> 59.88 | I5: =H5-D5 -> -0.12 | J5: =(H5-D5)/D5 -> -0.002 | K5: ='2021.06'!D19 -> 0 | L5: ='2021.06'!J19 -> 0 | M5: ='2021.06'!O19 -> 0 | O5: Viso: | P5: =SUM(B5:B100) -> 913 | Q5: =SUM(E5:E100) -> 7.415 | R5: 1112.62 | S5: =R5-P5+X5 -> 199.62 | T5: =(R5-P5+X5)/P5 -> 0.2186 | U5: =XIRR(AG5:AG85,AF5:AF85) -> 0.0809 | V5: =SUM(K5:K100) -> 0 | W5: =SUM(L5:L100) -> 0 | X5: =SUM(M5:M100) -> 0 | Y5: {=SUMPRODUCT(IFERROR(AD5:AD200,0),IFERROR(AE5:AE200,0))/SUM(IFERROR(AE5:AE200,0))} -> 122.65 | AC5: ='2021.06'!$C$19 -> 60 | AD5: ='2021.06'!$E$19 -> 119.28 | AE5: ='2021.06'!$F$19 -> 0.503 | AF5: ='2021.06'!$A$15 -> 44363 | AG5: ='2021.06'!$B$15*-1 -> -50
A6: ='2021.07'!Q2 -> 2021.07 | B6: ='2021.07'!B19 -> 10 | C6: ='2021.07'!C19 -> 10 | D6: =D5+B6 -> 70 | E6: ='2021.07'!F19 -> 0.082 | F6: =F5+E6 -> 0.585 | G6: 121.9512 | H6: =F6*G6 -> 71.34 | I6: =H6-D6 -> 1.34 | J6: =(H6-D6)/D6 -> 0.0191 | K6: ='2021.07'!D19 -> 0 | L6: ='2021.07'!J19 -> 0 | M6: ='2021.07'!O19 -> 0 | AC6: ='2021.07'!$C$19 -> 10 | AD6: ='2021.07'!$E$19 -> 121.95 | AE6: ='2021.07'!$F$19 -> 0.082 | AF6: ='2021.06'!$A$16 -> 44365 | AG6: ='2021.06'!$B$16*-1 -> -10
A7: ='2021.08'!Q2 -> 2021.08 | B7: ='2021.08'!B19 -> 10 | C7: ='2021.08'!C19 -> 10 | D7: =D6+B7 -> 80 | E7: ='2021.08'!F19 -> 0.082 | F7: =F6+E7 -> 0.667 | G7: 121.9512 | H7: =F7*G7 -> 81.34 | I7: =H7-D7 -> 1.34 | J7: =(H7-D7)/D7 -> 0.0168 | K7: ='2021.08'!D19 -> 0 | L7: ='2021.08'!J19 -> 0 | M7: ='2021.08'!O19 -> 0 | AC7: ='2021.08'!$C$19 -> 10 | AD7: ='2021.08'!$E$19 -> 121.95 | AE7: ='2021.08'!$F$19 -> 0.082 | AF7: ='2021.07'!$A$15 -> 44393 | AG7: ='2021.07'!$B$15*-1 -> -10
A8: ='2021.09'!Q2 -> 2021.09 | B8: ='2021.09'!B19 -> 10 | C8: ='2021.09'!C19 -> 10 | D8: =D7+B8 -> 90 | E8: ='2021.09'!F19 -> 0.082 | F8: =F7+E8 -> 0.749 | G8: 121.9512 | H8: =F8*G8 -> 91.34 | I8: =H8-D8 -> 1.34 | J8: =(H8-D8)/D8 -> 0.0149 | K8: ='2021.09'!D19 -> 0 | L8: ='2021.09'!J19 -> 0 | M8: ='2021.09'!O19 -> 0 | AC8: ='2021.09'!$C$19 -> 10 | AD8: ='2021.09'!$E$19 -> 121.95 | AE8: ='2021.09'!$F$19 -> 0.082 | AF8: ='2021.08'!$A$15 -> 44426 | AG8: ='2021.08'!$B$15*-1 -> -10
A9: ='2021.10'!Q2 -> 2021.1 | B9: ='2021.10'!B19 -> 10 | C9: ='2021.10'!C19 -> 10 | D9: =D8+B9 -> 100 | E9: ='2021.10'!F19 -> 0.083 | F9: =F8+E9 -> 0.832 | G9: 120.4819 | H9: =F9*G9 -> 100.24 | I9: =H9-D9 -> 0.24 | J9: =(H9-D9)/D9 -> 0.0024 | K9: ='2021.10'!D19 -> 0 | L9: ='2021.10'!J19 -> 0 | M9: ='2021.10'!O19 -> 0 | AC9: ='2021.10'!$C$19 -> 10 | AD9: ='2021.10'!$E$19 -> 120.48 | AE9: ='2021.10'!$F$19 -> 0.083 | AF9: ='2021.09'!$A$15 -> 44456 | AG9: ='2021.09'!$B$15*-1 -> -10
A10: ='2021.11'!Q2 -> 2021.11 | B10: ='2021.11'!B19 -> 0 | C10: ='2021.11'!C19 -> 0 | D10: =D9+B10 -> 100 | E10: ='2021.11'!F19 -> 0 | F10: =F9+E10 -> 0.832 | G10: 121.2505 | H10: =F10*G10 -> 100.88 | I10: =H10-D10 -> 0.88 | J10: =(H10-D10)/D10 -> 0.0088 | K10: ='2021.11'!D19 -> 0 | L10: ='2021.11'!J19 -> 0 | M10: ='2021.11'!O19 -> 0 | AC10: ='2021.11'!$C$19 -> 0 | AD10: ='2021.11'!$E$19 -> 0.00 | AE10: ='2021.11'!$F$19 -> 0 | AF10: ='2021.10'!$A$15 -> 44487 | AG10: ='2021.10'!$B$15*-1 -> -10
A11: ='2021.12'!Q2 -> 2021.12 | B11: ='2021.12'!B19 -> 35 | C11: ='2021.12'!C19 -> 35 | D11: =D10+B11 -> 135 | E11: ='2021.12'!F19 -> 0.2874 | F11: =F10+E11 -> 1.1194 | G11: 122.9097 | H11: =F11*G11 -> 137.59 | I11: =H11-D11 -> 2.59 | J11: =(H11-D11)/D11 -> 0.0192 | K11: ='2021.12'!D19 -> 0 | L11: ='2021.12'!J19 -> 0 | M11: ='2021.12'!O19 -> 0 | AC11: ='2021.12'!$C$19 -> 35 | AD11: ='2021.12'!$E$19 -> 121.78 | AE11: ='2021.12'!$F$19 -> 0.287 | AF11: ='2021.12'!$A$15 -> 44545 | AG11: ='2021.12'!$B$15*-1 -> -10
A12: ='2022.01'!Q2 -> 2022.01 | B12: ='2022.01'!B19 -> 28 | C12: ='2022.01'!C19 -> 28 | D12: =D11+B12 -> 163 | E12: ='2022.01'!F19 -> 0.2348 | F12: =F11+E12 -> 1.3542 | G12: 115.3698 | H12: =F12*G12 -> 156.23 | I12: =H12-D12 -> -6.77 | J12: =(H12-D12)/D12 -> -0.0415 | K12: ='2022.01'!D19 -> 0 | L12: ='2022.01'!J19 -> 0 | M12: ='2022.01'!O19 -> 0 | AC12: ='2022.01'!$C$19 -> 28 | AD12: ='2022.01'!$E$19 -> 119.25 | AE12: ='2022.01'!$F$19 -> 0.235 | AF12: ='2021.12'!$A$16 -> 44546 | AG12: ='2021.12'!$B$16*-1 -> -10
A13: ='2022.02'!Q2 -> 2022.02 | B13: ='2022.02'!B19 -> 10 | C13: ='2022.02'!C19 -> 10 | D13: =D12+B13 -> 173 | E13: ='2022.02'!F19 -> 0.0865 | F13: =F12+E13 -> 1.4407 | G13: 113.221 | H13: =F13*G13 -> 163.12 | I13: =H13-D13 -> -9.88 | J13: =(H13-D13)/D13 -> -0.0571 | K13: ='2022.02'!D19 -> 0 | L13: ='2022.02'!J19 -> 0 | M13: ='2022.02'!O19 -> 0 | AC13: ='2022.02'!$C$19 -> 10 | AD13: ='2022.02'!$E$19 -> 115.61 | AE13: ='2022.02'!$F$19 -> 0.087 | AF13: ='2021.12'!$A$17 -> 44559 | AG13: ='2021.12'!$B$17*-1 -> -15
A14: ='2022.03'!Q2 -> 2022.03 | B14: ='2022.03'!B19 -> 10 | C14: ='2022.03'!C19 -> 10 | D14: =D13+B14 -> 183 | E14: ='2022.03'!F19 -> 0.0901 | F14: =F13+E14 -> 1.5308 | G14: 115.694 | H14: =F14*G14 -> 177.1 | I14: =H14-D14 -> -5.9 | J14: =(H14-D14)/D14 -> -0.0322 | K14: ='2022.03'!D19 -> 0 | L14: ='2022.03'!J19 -> 0 | M14: ='2022.03'!O19 -> 0 | AC14: ='2022.03'!$C$19 -> 10 | AD14: ='2022.03'!$E$19 -> 110.99 | AE14: ='2022.03'!$F$19 -> 0.09 | AF14: ='2022.01'!$A$15 -> 44578 | AG14: ='2022.01'!$B$15*-1 -> -10
A15: ='2022.04'!Q2 -> 2022.04 | B15: ='2022.04'!B19 -> 10 | C15: ='2022.04'!C19 -> 10 | D15: =D14+B15 -> 193 | E15: ='2022.04'!F19 -> 0.0874 | F15: =F14+E15 -> 1.6182 | G15: 111.724 | H15: =F15*G15 -> 180.79 | I15: =H15-D15 -> -12.21 | J15: =(H15-D15)/D15 -> -0.0633 | K15: ='2022.04'!D19 -> 0 | L15: ='2022.04'!J19 -> 0 | M15: ='2022.04'!O19 -> 0 | AC15: ='2022.04'!$C$19 -> 10 | AD15: ='2022.04'!$E$19 -> 114.42 | AE15: ='2022.04'!$F$19 -> 0.087 | AF15: ='2022.01'!$A$16 -> 44581 | AG15: ='2022.01'!$B$16*-1 -> -18
A16: ='2022.05'!Q2 -> 2022.05 | B16: ='2022.05'!B19 -> 10 | C16: ='2022.05'!C19 -> 10 | D16: =D15+B16 -> 203 | E16: ='2022.05'!F19 -> 0.0925 | F16: =F15+E16 -> 1.7107 | G16: 110.2858 | H16: =F16*G16 -> 188.67 | I16: =H16-D16 -> -14.33 | J16: =(H16-D16)/D16 -> -0.0706 | K16: ='2022.05'!D19 -> 0 | L16: ='2022.05'!J19 -> 0 | M16: ='2022.05'!O19 -> 0 | AC16: ='2022.05'!$C$19 -> 10 | AD16: ='2022.05'!$E$19 -> 108.11 | AE16: ='2022.05'!$F$19 -> 0.093 | AF16: ='2022.02'!$A$15 -> 44609 | AG16: ='2022.02'!$B$15*-1 -> -10
A17: ='2022.06'!Q2 -> 2022.06 | B17: ='2022.06'!B19 -> 10 | C17: ='2022.06'!C19 -> 10 | D17: =D16+B17 -> 213 | E17: ='2022.06'!F19 -> 0.0962 | F17: =F16+E17 -> 1.8069 | G17: 104.7044 | H17: =F17*G17 -> 189.19 | I17: =H17-D17 -> -23.81 | J17: =(H17-D17)/D17 -> -0.1118 | K17: ='2022.06'!D19 -> 0 | L17: ='2022.06'!J19 -> 0 | M17: ='2022.06'!O19 -> 0 | AC17: ='2022.06'!$C$19 -> 10 | AD17: ='2022.06'!$E$19 -> 103.95 | AE17: ='2022.06'!$F$19 -> 0.096 | AF17: ='2022.03'!$A$15 -> 44637 | AG17: ='2022.03'!$B$15*-1 -> -10
A18: ='2022.07'!Q2 -> 2022.07 | B18: ='2022.07'!B19 -> 10 | C18: ='2022.07'!C19 -> 10 | D18: =D17+B18 -> 223 | E18: ='2022.07'!F19 -> 0.0942 | F18: =F17+E18 -> 1.9011 | G18: 109.8231 | H18: =F18*G18 -> 208.78 | I18: =H18-D18 -> -14.22 | J18: =(H18-D18)/D18 -> -0.0638 | K18: ='2022.07'!D19 -> 0 | L18: ='2022.07'!J19 -> 0 | M18: ='2022.07'!O19 -> 0 | AC18: ='2022.07'!$C$19 -> 10 | AD18: ='2022.07'!$E$19 -> 106.16 | AE18: ='2022.07'!$F$19 -> 0.094 | AF18: ='2022.04'!$A$15 -> 44670 | AG18: ='2022.04'!$B$15*-1 -> -10
A19: ='2022.08'!Q2 -> 2022.08 | B19: ='2022.08'!B19 -> 10 | C19: ='2022.08'!C19 -> 10 | D19: =D18+B19 -> 233 | E19: ='2022.08'!F19 -> 0.0893 | F19: =F18+E19 -> 1.9904 | G19: 107.6514 | H19: =F19*G19 -> 214.27 | I19: =H19-D19 -> -18.73 | J19: =(H19-D19)/D19 -> -0.0804 | K19: ='2022.08'!D19 -> 0 | L19: ='2022.08'!J19 -> 0 | M19: ='2022.08'!O19 -> 0 | AC19: ='2022.08'!$C$19 -> 10 | AD19: ='2022.08'!$E$19 -> 111.98 | AE19: ='2022.08'!$F$19 -> 0.089 | AF19: ='2022.05'!$A$15 -> 44698 | AG19: ='2022.05'!$B$15*-1 -> -10
A20: ='2022.09'!Q2 -> 2022.09 | B20: ='2022.09'!B19 -> 10 | C20: ='2022.09'!C19 -> 10 | D20: =D19+B20 -> 243 | E20: ='2022.09'!F19 -> 0.0933 | F20: =F19+E20 -> 2.0837 | G20: 100.0686 | H20: =F20*G20 -> 208.51 | I20: =H20-D20 -> -34.49 | J20: =(H20-D20)/D20 -> -0.1419 | K20: ='2022.09'!D19 -> 0 | L20: ='2022.09'!J19 -> 0 | M20: ='2022.09'!O19 -> 0 | AC20: ='2022.09'!$C$19 -> 10 | AD20: ='2022.09'!$E$19 -> 107.18 | AE20: ='2022.09'!$F$19 -> 0.093 | AF20: ='2022.06'!$A$15 -> 44728 | AG20: ='2022.06'!$B$15*-1 -> -10
A21: ='2022.10'!Q2 -> 2022.1 | B21: ='2022.10'!B19 -> 10 | C21: ='2022.10'!C19 -> 10 | D21: =D20+B21 -> 253 | E21: ='2022.10'!F19 -> 0.1001 | F21: =F20+E21 -> 2.1838 | G21: 102.9935 | H21: =F21*G21 -> 224.92 | I21: =H21-D21 -> -28.08 | J21: =(H21-D21)/D21 -> -0.111 | K21: ='2022.10'!D19 -> 0 | L21: ='2022.10'!J19 -> 0 | M21: ='2022.10'!O19 -> 0 | AC21: ='2022.10'!$C$19 -> 10 | AD21: ='2022.10'!$E$19 -> 99.9 | AE21: ='2022.10'!$F$19 -> 0.1 | AF21: ='2022.07'!$A$15 -> 44757 | AG21: ='2022.07'!$B$15*-1 -> -10
A22: ='2022.11'!Q2 -> 2022.11 | B22: ='2022.11'!B19 -> 10 | C22: ='2022.11'!C19 -> 10 | D22: =D21+B22 -> 263 | E22: ='2022.11'!F19 -> 0.0946 | F22: =F21+E22 -> 2.2784 | G22: 105.3106 | H22: =F22*G22 -> 239.94 | I22: =H22-D22 -> -23.06 | J22: =(H22-D22)/D22 -> -0.0877 | K22: ='2022.11'!D19 -> 0 | L22: ='2022.11'!J19 -> 0 | M22: ='2022.11'!O19 -> 0 | AC22: ='2022.11'!$C$19 -> 10 | AD22: ='2022.11'!$E$19 -> 105.71 | AE22: ='2022.11'!$F$19 -> 0.095 | AF22: ='2022.08'!$A$15 -> 44790 | AG22: ='2022.08'!$B$15*-1 -> -10
A23: ='2022.12'!Q2 -> 2022.12 | B23: ='2022.12'!B19 -> 10 | C23: ='2022.12'!C19 -> 10 | D23: =D22+B23 -> 273 | E23: ='2022.12'!F19 -> 0.0935 | F23: =F22+E23 -> 2.3719 | G23: 103.6851 | H23: =F23*G23 -> 245.93 | I23: =H23-D23 -> -27.07 | J23: =(H23-D23)/D23 -> -0.0992 | K23: ='2022.12'!D19 -> 0 | L23: ='2022.12'!J19 -> 0 | M23: ='2022.12'!O19 -> 0 | AC23: ='2022.12'!$C$19 -> 10 | AD23: ='2022.12'!$E$19 -> 106.95 | AE23: ='2022.12'!$F$19 -> 0.094 | AF23: ='2022.09'!$A$15 -> 44819 | AG23: ='2022.09'!$B$15*-1 -> -10
A24: ='2023.01'!Q2 -> 2023.01 | B24: ='2023.01'!B19 -> 10 | C24: ='2023.01'!C19 -> 10 | D24: =D23+B24 -> 283 | E24: ='2023.01'!F19 -> 0.0938 | F24: =F23+E24 -> 2.4657 | G24: 107.6885 | H24: =F24*G24 -> 265.53 | I24: =H24-D24 -> -17.47 | J24: =(H24-D24)/D24 -> -0.0617 | K24: ='2023.01'!D19 -> 0 | L24: ='2023.01'!J19 -> 0 | M24: ='2023.01'!O19 -> 0 | AC24: ='2023.01'!$C$19 -> 10 | AD24: ='2023.01'!$E$19 -> 106.61 | AE24: ='2023.01'!$F$19 -> 0.094 | AF24: ='2022.10'!$A$15 -> 44851 | AG24: ='2022.10'!$B$15*-1 -> -10
A25: ='2023.02'!Q2 -> 2023.02 | B25: ='2023.02'!B19 -> 10 | C25: ='2023.02'!C19 -> 10 | D25: =D24+B25 -> 293 | E25: ='2023.02'!F19 -> 0.0919 | F25: =F24+E25 -> 2.5576 | G25: 107.1614 | H25: =F25*G25 -> 274.08 | I25: =H25-D25 -> -18.92 | J25: =(H25-D25)/D25 -> -0.0646 | K25: ='2023.02'!D19 -> 0 | L25: ='2023.02'!J19 -> 0 | M25: ='2023.02'!O19 -> 0 | AC25: ='2023.02'!$C$19 -> 10 | AD25: ='2023.02'!$E$19 -> 108.81 | AE25: ='2023.02'!$F$19 -> 0.092 | AF25: ='2022.11'!$A$15 -> 44882 | AG25: ='2022.11'!$B$15*-1 -> -10
A26: ='2023.03'!Q2 -> 2023.03 | B26: ='2023.03'!B19 -> 10 | C26: ='2023.03'!C19 -> 10 | D26: =D25+B26 -> 303 | E26: ='2023.03'!F19 -> 0.0953 | F26: =F25+E26 -> 2.6529 | G26: 106.0126 | H26: =F26*G26 -> 281.24 | I26: =H26-D26 -> -21.76 | J26: =(H26-D26)/D26 -> -0.0718 | K26: ='2023.03'!D19 -> 0 | L26: ='2023.03'!J19 -> 0 | M26: ='2023.03'!O19 -> 0 | AC26: ='2023.03'!$C$19 -> 10 | AD26: ='2023.03'!$E$19 -> 104.93 | AE26: ='2023.03'!$F$19 -> 0.095 | AF26: ='2022.12'!$A$15 -> 44910 | AG26: ='2022.12'!$B$15*-1 -> -10
A27: ='2023.04'!Q2 -> 2023.04 | B27: ='2023.04'!B19 -> 10 | C27: ='2023.04'!C19 -> 10 | D27: =D26+B27 -> 313 | E27: ='2023.04'!F19 -> 0.0936 | F27: =F26+E27 -> 2.7465 | G27: 106.7021 | H27: =F27*G27 -> 293.06 | I27: =H27-D27 -> -19.94 | J27: =(H27-D27)/D27 -> -0.0637 | K27: ='2023.04'!D19 -> 0 | L27: ='2023.04'!J19 -> 0 | M27: ='2023.04'!O19 -> 0 | AC27: ='2023.04'!$C$19 -> 10 | AD27: ='2023.04'!$E$19 -> 106.84 | AE27: ='2023.04'!$F$19 -> 0.094 | AF27: ='2023.01'!$A$15 -> 44943 | AG27: ='2023.01'!$B$15*-1 -> -10
A28: ='2023.05'!Q2 -> 2023.05 | B28: ='2023.05'!B19 -> 10 | C28: ='2023.05'!C19 -> 10 | D28: =D27+B28 -> 323 | E28: ='2023.05'!F19 -> 0.0927 | F28: =F27+E28 -> 2.8392 | G28: 107.7767 | H28: =F28*G28 -> 306 | I28: =H28-D28 -> -17 | J28: =(H28-D28)/D28 -> -0.0526 | K28: ='2023.05'!D19 -> 0 | L28: ='2023.05'!J19 -> 0 | M28: ='2023.05'!O19 -> 0 | AC28: ='2023.05'!$C$19 -> 10 | AD28: ='2023.05'!$E$19 -> 107.87 | AE28: ='2023.05'!$F$19 -> 0.093 | AF28: ='2023.02'!$A$15 -> 44974 | AG28: ='2023.02'!$B$15*-1 -> -10
A29: ='2023.06'!Q2 -> 2023.06 | B29: ='2023.06'!B19 -> 10 | C29: ='2023.06'!C19 -> 10 | D29: =D28+B29 -> 333 | E29: ='2023.06'!F19 -> 0.0912 | F29: =F28+E29 -> 2.9304 | G29: 108.3708 | H29: =F29*G29 -> 317.57 | I29: =H29-D29 -> -15.43 | J29: =(H29-D29)/D29 -> -0.0463 | K29: ='2023.06'!D19 -> 0 | L29: ='2023.06'!J19 -> 0 | M29: ='2023.06'!O19 -> 0 | AC29: ='2023.06'!$C$19 -> 10 | AD29: ='2023.06'!$E$19 -> 109.65 | AE29: ='2023.06'!$F$19 -> 0.091 | AF29: ='2023.03'!$A$15 -> 45001 | AG29: ='2023.03'!$B$15*-1 -> -10
A30: ='2023.07'!Q2 -> 2023.07 | B30: ='2023.07'!B19 -> 10 | C30: ='2023.07'!C19 -> 10 | D30: =D29+B30 -> 343 | E30: ='2023.07'!F19 -> 0.0914 | F30: =F29+E30 -> 3.0218 | G30: 110.1314 | H30: =F30*G30 -> 332.8 | I30: =H30-D30 -> -10.2 | J30: =(H30-D30)/D30 -> -0.0297 | K30: ='2023.07'!D19 -> 0 | L30: ='2023.07'!J19 -> 0 | M30: ='2023.07'!O19 -> 0 | AC30: ='2023.07'!$C$19 -> 10 | AD30: ='2023.07'!$E$19 -> 109.41 | AE30: ='2023.07'!$F$19 -> 0.091 | AF30: ='2023.04'!$A$15 -> 45033 | AG30: ='2023.04'!$B$15*-1 -> -10
A31: ='2023.08'!Q2 -> 2023.08 | B31: ='2023.08'!B19 -> 10 | C31: ='2023.08'!C19 -> 10 | D31: =D30+B31 -> 353 | E31: ='2023.08'!F19 -> 0.0922 | F31: =F30+E31 -> 3.114 | G31: 108.9837 | H31: =F31*G31 -> 339.38 | I31: =H31-D31 -> -13.62 | J31: =(H31-D31)/D31 -> -0.0386 | K31: ='2023.08'!D19 -> 0 | L31: ='2023.08'!J19 -> 0 | M31: ='2023.08'!O19 -> 0 | AC31: ='2023.08'!$C$19 -> 10 | AD31: ='2023.08'!$E$19 -> 108.46 | AE31: ='2023.08'!$F$19 -> 0.092 | AF31: ='2023.05'!$A$15 -> 45063 | AG31: ='2023.05'!$B$15*-1 -> -10
A32: ='2023.09'!Q2 -> 2023.09 | B32: ='2023.09'!B19 -> 10 | C32: ='2023.09'!C19 -> 10 | D32: =D31+B32 -> 363 | E32: ='2023.09'!F19 -> 0.092 | F32: =F31+E32 -> 3.206 | G32: 107.3659 | H32: =F32*G32 -> 344.22 | I32: =H32-D32 -> -18.78 | J32: =(H32-D32)/D32 -> -0.0517 | K32: ='2023.09'!D19 -> 0 | L32: ='2023.09'!J19 -> 0 | M32: ='2023.09'!O19 -> 0 | AC32: ='2023.09'!$C$19 -> 10 | AD32: ='2023.09'!$E$19 -> 108.7 | AE32: ='2023.09'!$F$19 -> 0.092 | AF32: ='2023.06'!$A$15 -> 45092 | AG32: ='2023.06'!$B$15*-1 -> -10
A33: ='2023.10'!Q2 -> 2023.1 | B33: ='2023.10'!B19 -> 10 | C33: ='2023.10'!C19 -> 10 | D33: =D32+B33 -> 373 | E33: ='2023.10'!F19 -> 0.0922 | F33: =F32+E33 -> 3.2982 | G33: 104.3443 | H33: =F33*G33 -> 344.15 | I33: =H33-D33 -> -28.85 | J33: =(H33-D33)/D33 -> -0.0773 | K33: ='2023.10'!D19 -> 0 | L33: ='2023.10'!J19 -> 0 | M33: ='2023.10'!O19 -> 0 | AC33: ='2023.10'!$C$19 -> 10 | AD33: ='2023.10'!$E$19 -> 108.49 | AE33: ='2023.10'!$F$19 -> 0.092 | AF33: ='2023.07'!$A$15 -> 45124 | AG33: ='2023.07'!$B$15*-1 -> -10
A34: ='2023.11'!Q2 -> 2023.11 | B34: ='2023.11'!B19 -> 10 | C34: ='2023.11'!C19 -> 10 | D34: =D33+B34 -> 383 | E34: ='2023.11'!F19 -> 0.0919 | F34: =F33+E34 -> 3.3901 | G34: 110.6673 | H34: =F34*G34 -> 375.17 | I34: =H34-D34 -> -7.83 | J34: =(H34-D34)/D34 -> -0.0204 | K34: ='2023.11'!D19 -> 0 | L34: ='2023.11'!J19 -> 0 | M34: ='2023.11'!O19 -> 0 | AC34: ='2023.11'!$C$19 -> 10 | AD34: ='2023.11'!$E$19 -> 108.81 | AE34: ='2023.11'!$F$19 -> 0.092 | AF34: ='2023.08'!$A$15 -> 45155 | AG34: ='2023.08'!$B$15*-1 -> -10
A35: ='2023.12'!Q2 -> 2023.12 | B35: ='2023.12'!B19 -> 10 | C35: ='2023.12'!C19 -> 10 | D35: =D34+B35 -> 393 | E35: ='2023.12'!F19 -> 0.0881 | F35: =F34+E35 -> 3.4782 | G35: 115.2916 | H35: =F35*G35 -> 401.01 | I35: =H35-D35 -> 8.01 | J35: =(H35-D35)/D35 -> 0.0204 | K35: ='2023.12'!D19 -> 0 | L35: ='2023.12'!J19 -> 0 | M35: ='2023.12'!O19 -> 0 | AC35: ='2023.12'!$C$19 -> 10 | AD35: ='2023.12'!$E$19 -> 113.51 | AE35: ='2023.12'!$F$19 -> 0.088 | AF35: ='2023.09'!$A$15 -> 45184 | AG35: ='2023.09'!$B$15*-1 -> -10
A36: ='2024.01'!Q2 -> 2024.01 | B36: ='2024.01'!B19 -> 10 | C36: ='2024.01'!C19 -> 10 | D36: =D35+B36 -> 403 | E36: ='2024.01'!F19 -> 0.0868 | F36: =F35+E36 -> 3.565 | G36: 116.9617 | H36: =F36*G36 -> 416.97 | I36: =H36-D36 -> 13.97 | J36: =(H36-D36)/D36 -> 0.0347 | K36: ='2024.01'!D19 -> 0 | L36: ='2024.01'!J19 -> 0 | M36: ='2024.01'!O19 -> 0 | AC36: ='2024.01'!$C$19 -> 10 | AD36: ='2024.01'!$E$19 -> 115.21 | AE36: ='2024.01'!$F$19 -> 0.087 | AF36: ='2023.10'!$A$15 -> 45216 | AG36: ='2023.10'!$B$15*-1 -> -10
A37: ='2024.02'!Q2 -> 2024.02 | B37: ='2024.02'!B19 -> 15 | C37: ='2024.02'!C19 -> 15 | D37: =D36+B37 -> 418 | E37: ='2024.02'!F19 -> 0.1276 | F37: =F36+E37 -> 3.6926 | G37: 119.3578 | H37: =F37*G37 -> 440.74 | I37: =H37-D37 -> 22.74 | J37: =(H37-D37)/D37 -> 0.0544 | K37: ='2024.02'!D19 -> 0 | L37: ='2024.02'!J19 -> 0 | M37: ='2024.02'!O19 -> 0 | AC37: ='2024.02'!$C$19 -> 15 | AD37: ='2024.02'!$E$19 -> 117.55 | AE37: ='2024.02'!$F$19 -> 0.128 | AF37: ='2023.11'!$A$15 -> 45246 | AG37: ='2023.11'!$B$15*-1 -> -10
A38: ='2024.03'!Q2 -> 2024.03 | B38: ='2024.03'!B19 -> 15 | C38: ='2024.03'!C19 -> 15 | D38: =D37+B38 -> 433 | E38: ='2024.03'!F19 -> 0.1234 | F38: =F37+E38 -> 3.816 | G38: 122.3433 | H38: =F38*G38 -> 466.86 | I38: =H38-D38 -> 33.86 | J38: =(H38-D38)/D38 -> 0.0782 | K38: ='2024.03'!D19 -> 0 | L38: ='2024.03'!J19 -> 0 | M38: ='2024.03'!O19 -> 0 | AC38: ='2024.03'!$C$19 -> 15 | AD38: ='2024.03'!$E$19 -> 121.56 | AE38: ='2024.03'!$F$19 -> 0.123 | AF38: ='2023.12'!$A$15 -> 45275 | AG38: ='2023.12'!$B$15*-1 -> -10
A39: ='2024.04'!Q2 -> 2024.04 | B39: ='2024.04'!B19 -> 15 | C39: ='2024.04'!C19 -> 15 | D39: =D38+B39 -> 448 | E39: ='2024.04'!F19 -> 0.1236 | F39: =F38+E39 -> 3.9396 | G39: 120.6469 | H39: =F39*G39 -> 475.3 | I39: =H39-D39 -> 27.3 | J39: =(H39-D39)/D39 -> 0.0609 | K39: ='2024.04'!D19 -> 0 | L39: ='2024.04'!J19 -> 0 | M39: ='2024.04'!O19 -> 0 | AC39: ='2024.04'!$C$19 -> 15 | AD39: ='2024.04'!$E$19 -> 121.36 | AE39: ='2024.04'!$F$19 -> 0.124 | AF39: ='2024.01'!$A$15 -> 45308 | AG39: ='2024.01'!$B$15*-1 -> -10
A40: ='2024.05'!Q2 -> 2024.05 | B40: ='2024.05'!B19 -> 15 | C40: ='2024.05'!C19 -> 15 | D40: =D39+B40 -> 463 | E40: ='2024.05'!F19 -> 0.1218 | F40: =F39+E40 -> 4.0614 | G40: 123.3263 | H40: =F40*G40 -> 500.88 | I40: =H40-D40 -> 37.88 | J40: =(H40-D40)/D40 -> 0.0818 | K40: ='2024.05'!D19 -> 0 | L40: ='2024.05'!J19 -> 0 | M40: ='2024.05'!O19 -> 0 | AC40: ='2024.05'!$C$19 -> 15 | AD40: ='2024.05'!$E$19 -> 123.15 | AE40: ='2024.05'!$F$19 -> 0.122 | AF40: ='2024.02'!$A$15 -> 45337 | AG40: ='2024.02'!$B$15*-1 -> -15
A41: ='2024.06'!Q2 -> 2024.06 | B41: ='2024.06'!B19 -> 15 | C41: ='2024.06'!C19 -> 15 | D41: =D40+B41 -> 478 | E41: ='2024.06'!F19 -> 0.1194 | F41: =F40+E41 -> 4.1808 | G41: 125.6736 | H41: =F41*G41 -> 525.42 | I41: =H41-D41 -> 47.42 | J41: =(H41-D41)/D41 -> 0.0992 | K41: ='2024.06'!D19 -> 0 | L41: ='2024.06'!J19 -> 0 | M41: ='2024.06'!O19 -> 0 | AC41: ='2024.06'!$C$19 -> 15 | AD41: ='2024.06'!$E$19 -> 125.63 | AE41: ='2024.06'!$F$19 -> 0.119 | AF41: ='2024.03'!$A$15 -> 45366 | AG41: ='2024.03'!$B$15*-1 -> -15
...

Sheet SEB Active 80
A1: SESA8FE SS „SEB Active 80“ SE0016076111
A3: Data | B3: Suma, EUR | E3: Kiekis | G3: Mėnesio gale | K3: Mokesčiai | M3: Dividendai | O3: Active 80 | P3: Įnešta | Q3: Kiekis | R3: Parduota | S3: Pelnas | V3: Mokesčiai | X3: Dividendai | Y3: Vid. Kaina | AC3: Suma | AD3: Kaina | AE3: Kiekis | AF3: Pirkimas/pardavimas
B4: Įnešta | C4: Mėn. Inv. | D4: Viso Inv. | E4: Mėnesio | F4: Viso | G4: Kaina | H4: Vertė gale | I4: Pelnas | J4: % | K4: Pirkimas | L4: Pardavimas | S4: Eur. | T4: % | U4: XIRR | V4: Pirkimas | W4: Pardavimas | AF4: Data | AG4: Suma
A5: ='2021.06'!Q2 -> 2021.06 | B5: ='2021.06'!B29 -> 3 | C5: ='2021.06'!C29 -> 3 | D5: =C5 -> 3 | E5: ='2021.06'!F29 -> 0.023 | F5: =E5 -> 0.023 | G5: 130.4348 | H5: =F5*G5 -> 3 | I5: =H5-D5 -> 0 | J5: =(H5-D5)/D5 -> 0 | K5: ='2021.06'!D29 -> 0 | L5: ='2021.06'!J29 -> 0 | M5: ='2021.06'!O29 -> 0 | O5: Viso: | P5: =SUM(B5:B99) -> 534 | Q5: =SUM(E5:E99) -> 3.6583 | R5: 630.18 | S5: =R5-P5+X5 -> 96.18 | T5: =(R5-P5+X5)/P5 -> 0.1801 | U5: =XIRR(AG5:AG65,AF5:AF65) -> 0.0843 | V5: =SUM(K5:K99) -> 0 | W5: =SUM(L5:L99) -> 0 | X5: =SUM(M5:M99) -> 0 | Y5: {=SUMPRODUCT(IFERROR(AD5:AD200,0),IFERROR(AE5:AE200,0))/SUM(IFERROR(AE5:AE200,0))} -> 145.97 | AC5: ='2021.06'!$C$29 -> 3 | AD5: ='2021.06'!$E$29 -> 130.43 | AE5: ='2021.06'!$F$29 -> 0.023 | AF5: ='2021.06'!$A$25 -> 44376 | AG5: ='2021.06'!$B$25*-1 -> -3
A6: ='2021.07'!Q2 -> 2021.07 | B6: ='2021.07'!B29 -> 8 | C6: ='2021.07'!C29 -> 8 | D6: =D5+B6 -> 11 | E6: ='2021.07'!F29 -> 0.061 | F6: =F5+E6 -> 0.084 | G6: 130.4348 | H6: =F6*G6 -> 10.96 | I6: =H6-D6 -> -0.04 | J6: =(H6-D6)/D6 -> -0.0036 | K6: ='2021.07'!D29 -> 0 | L6: ='2021.07'!J29 -> 0 | M6: ='2021.07'!O29 -> 0 | AC6: ='2021.07'!$C$29 -> 8 | AD6: ='2021.07'!$E$29 -> 131.15 | AE6: ='2021.07'!$F$29 -> 0.061 | AF6: ='2021.07'!$A$25 -> 44379 | AG6: ='2021.07'!$B$25*-1 -> -5
A7: ='2021.08'!Q2 -> 2021.08 | B7: ='2021.08'!B29 -> 6 | C7: ='2021.08'!C29 -> 6 | D7: =D6+B7 -> 17 | E7: ='2021.08'!F29 -> 0.044 | F7: =F6+E7 -> 0.128 | G7: 136.3636 | H7: =F7*G7 -> 17.45 | I7: =H7-D7 -> 0.45 | J7: =(H7-D7)/D7 -> 0.0265 | K7: ='2021.08'!D29 -> 0 | L7: ='2021.08'!J29 -> 0 | M7: ='2021.08'!O29 -> 0 | AC7: ='2021.08'!$C$29 -> 6 | AD7: ='2021.08'!$E$29 -> 136.36 | AE7: ='2021.08'!$F$29 -> 0.044 | AF7: ='2021.07'!$A$26 -> 44397 | AG7: ='2021.07'!$B$26*-1 -> -3
A8: ='2021.09'!Q2 -> 2021.09 | B8: ='2021.09'!B29 -> 46 | C8: ='2021.09'!C29 -> 46 | D8: =D7+B8 -> 63 | E8: ='2021.09'!F29 -> 0.344 | F8: =F7+E8 -> 0.472 | G8: 133.3333 | H8: =F8*G8 -> 62.93 | I8: =H8-D8 -> -0.07 | J8: =(H8-D8)/D8 -> -0.0011 | K8: ='2021.09'!D29 -> 0 | L8: ='2021.09'!J29 -> 0 | M8: ='2021.09'!O29 -> 0 | AC8: ='2021.09'!$C$29 -> 46 | AD8: ='2021.09'!$E$29 -> 133.72 | AE8: ='2021.09'!$F$29 -> 0.344 | AF8: ='2021.08'!$A$25 -> 44424 | AG8: ='2021.08'!$B$25*-1 -> -3
A9: ='2021.10'!Q2 -> 2021.1 | B9: ='2021.10'!B29 -> 27 | C9: ='2021.10'!C29 -> 27 | D9: =D8+B9 -> 90 | E9: ='2021.10'!F29 -> 0.204 | F9: =F8+E9 -> 0.676 | G9: 132.3529 | H9: =F9*G9 -> 89.47 | I9: =H9-D9 -> -0.53 | J9: =(H9-D9)/D9 -> -0.0059 | K9: ='2021.10'!D29 -> 0 | L9: ='2021.10'!J29 -> 0 | M9: ='2021.10'!O29 -> 0 | AC9: ='2021.10'!$C$29 -> 27 | AD9: ='2021.10'!$E$29 -> 132.35 | AE9: ='2021.10'!$F$29 -> 0.204 | AF9: ='2021.08'!$A$26 -> 44438 | AG9: ='2021.08'!$B$26*-1 -> -3
A10: ='2021.11'!Q2 -> 2021.11 | B10: ='2021.11'!B29 -> 9 | C10: ='2021.11'!C29 -> 9 | D10: =D9+B10 -> 99 | E10: ='2021.11'!F29 -> 0.0664 | F10: =F9+E10 -> 0.7424 | G10: 133.5353 | H10: =F10*G10 -> 99.14 | I10: =H10-D10 -> 0.14 | J10: =(H10-D10)/D10 -> 0.0014 | K10: ='2021.11'!D29 -> 0 | L10: ='2021.11'!J29 -> 0 | M10: ='2021.11'!O29 -> 0 | AC10: ='2021.11'!$C$29 -> 9 | AD10: ='2021.11'!$E$29 -> 135.54 | AE10: ='2021.11'!$F$29 -> 0.066 | AF10: ='2021.09'!$A$25 -> 44448 | AG10: ='2021.09'!$B$25*-1 -> -9
A11: ='2021.12'!Q2 -> 2021.12 | B11: ='2021.12'!B29 -> 10 | C11: ='2021.12'!C29 -> 10 | D11: =D10+B11 -> 109 | E11: ='2021.12'!F29 -> 0.0749 | F11: =F10+E11 -> 0.8173 | G11: 135.8624 | H11: =F11*G11 -> 111.04 | I11: =H11-D11 -> 2.04 | J11: =(H11-D11)/D11 -> 0.0187 | K11: ='2021.12'!D29 -> 0 | L11: ='2021.12'!J29 -> 0 | M11: ='2021.12'!O29 -> 0 | AC11: ='2021.12'!$C$29 -> 10 | AD11: ='2021.12'!$E$29 -> 133.51 | AE11: ='2021.12'!$F$29 -> 0.075 | AF11: ='2021.09'!$A$26 -> 44455 | AG11: ='2021.09'!$B$26*-1 -> -19
A12: ='2022.01'!Q2 -> 2022.01 | B12: ='2022.01'!B29 -> 0 | C12: ='2022.01'!C29 -> 0 | D12: =D11+B12 -> 109 | E12: ='2022.01'!F29 -> 0 | F12: =F11+E12 -> 0.8173 | G12: 124.3419 | H12: =F12*G12 -> 101.62 | I12: =H12-D12 -> -7.38 | J12: =(H12-D12)/D12 -> -0.0677 | K12: ='2022.01'!D29 -> 0 | L12: ='2022.01'!J29 -> 0 | M12: ='2022.01'!O29 -> 0 | AC12: ='2022.01'!$C$29 -> 0 | AD12: ='2022.01'!$E$29 -> 0.00 | AE12: ='2022.01'!$F$29 -> 0 | AF12: ='2021.09'!$A$27 -> 44461 | AG12: ='2021.09'!$B$27*-1 -> -12
A13: ='2022.02'!Q2 -> 2022.02 | B13: ='2022.02'!B29 -> 0 | C13: ='2022.02'!C29 -> 0 | D13: =D12+B13 -> 109 | E13: ='2022.02'!F29 -> 0 | F13: =F12+E13 -> 0.8173 | G13: 121.7458 | H13: =F13*G13 -> 99.5 | I13: =H13-D13 -> -9.5 | J13: =(H13-D13)/D13 -> -0.0872 | K13: ='2022.02'!D29 -> 0 | L13: ='2022.02'!J29 -> 0 | M13: ='2022.02'!O29 -> 0 | AC13: ='2022.02'!$C$29 -> 0 | AD13: ='2022.02'!$E$29 -> 0.00 | AE13: ='2022.02'!$F$29 -> 0 | AF13: ='2021.09'!$A$28 -> 44466 | AG13: ='2021.09'!$B$28*-1 -> -6
A14: ='2022.03'!Q2 -> 2022.03 | B14: ='2022.03'!B29 -> 0 | C14: ='2022.03'!C29 -> 0 | D14: =D13+B14 -> 109 | E14: ='2022.03'!F29 -> 0 | F14: =F13+E14 -> 0.8173 | G14: 126.6065 | H14: =F14*G14 -> 103.48 | I14: =H14-D14 -> -5.52 | J14: =(H14-D14)/D14 -> -0.0506 | K14: ='2022.03'!D29 -> 0 | L14: ='2022.03'!J29 -> 0 | M14: ='2022.03'!O29 -> 0 | AC14: ='2022.03'!$C$29 -> 0 | AD14: ='2022.03'!$E$29 -> 0.00 | AE14: ='2022.03'!$F$29 -> 0 | AF14: ='2021.10'!$A$25 -> 44470 | AG14: ='2021.10'!$B$25*-1 -> -9
A15: ='2022.04'!Q2 -> 2022.04 | B15: ='2022.04'!B29 -> 0 | C15: ='2022.04'!C29 -> 0 | D15: =D14+B15 -> 109 | E15: ='2022.04'!F29 -> 0 | F15: =F14+E15 -> 0.8173 | G15: 120.7949 | H15: =F15*G15 -> 98.73 | I15: =H15-D15 -> -10.27 | J15: =(H15-D15)/D15 -> -0.0942 | K15: ='2022.04'!D29 -> 0 | L15: ='2022.04'!J29 -> 0 | M15: ='2022.04'!O29 -> 0 | AC15: ='2022.04'!$C$29 -> 0 | AD15: ='2022.04'!$E$29 -> 0.00 | AE15: ='2022.04'!$F$29 -> 0 | AF15: ='2021.10'!$A$26 -> 44489 | AG15: ='2021.10'!$B$26*-1 -> -18
A16: ='2022.05'!Q2 -> 2022.05 | B16: ='2022.05'!B29 -> 0 | C16: ='2022.05'!C29 -> 0 | D16: =D15+B16 -> 109 | E16: ='2022.05'!F29 -> 0 | F16: =F15+E16 -> 0.8173 | G16: 118.9531 | H16: =F16*G16 -> 97.22 | I16: =H16-D16 -> -11.78 | J16: =(H16-D16)/D16 -> -0.1081 | K16: ='2022.05'!D29 -> 0 | L16: ='2022.05'!J29 -> 0 | M16: ='2022.05'!O29 -> 0 | AC16: ='2022.05'!$C$29 -> 0 | AD16: ='2022.05'!$E$29 -> 0.00 | AE16: ='2022.05'!$F$29 -> 0 | AF16: ='2021.11'!$A$25 -> 44503 | AG16: ='2021.11'!$B$25*-1 -> -3
A17: ='2022.06'!Q2 -> 2022.06 | B17: ='2022.06'!B29 -> 0 | C17: ='2022.06'!C29 -> 0 | D17: =D16+B17 -> 109 | E17: ='2022.06'!F29 -> 0 | F17: =F16+E17 -> 0.8173 | G17: 111.2377 | H17: =F17*G17 -> 90.91 | I17: =H17-D17 -> -18.09 | J17: =(H17-D17)/D17 -> -0.166 | K17: ='2022.06'!D29 -> 0 | L17: ='2022.06'!J29 -> 0 | M17: ='2022.06'!O29 -> 0 | AC17: ='2022.06'!$C$29 -> 0 | AD17: ='2022.06'!$E$29 -> 0.00 | AE17: ='2022.06'!$F$29 -> 0 | AF17: ='2021.11'!$A$26 -> 44529 | AG17: ='2021.11'!$B$26*-1 -> -6
A18: ='2022.07'!Q2 -> 2022.07 | B18: ='2022.07'!B29 -> 0 | C18: ='2022.07'!C29 -> 0 | D18: =D17+B18 -> 109 | E18: ='2022.07'!F29 -> 0 | F18: =F17+E18 -> 0.8173 | G18: 118.109 | H18: =F18*G18 -> 96.53 | I18: =H18-D18 -> -12.47 | J18: =(H18-D18)/D18 -> -0.1144 | K18: ='2022.07'!D29 -> 0 | L18: ='2022.07'!J29 -> 0 | M18: ='2022.07'!O29 -> 0 | AC18: ='2022.07'!$C$29 -> 0 | AD18: ='2022.07'!$E$29 -> 0.00 | AE18: ='2022.07'!$F$29 -> 0 | AF18: ='2021.12'!$A$25 -> 44545 | AG18: ='2021.12'!$B$25*-1 -> -10
A19: ='2022.08'!Q2 -> 2022.08 | B19: ='2022.08'!B29 -> 0 | C19: ='2022.08'!C29 -> 0 | D19: =D18+B19 -> 109 | E19: ='2022.08'!F29 -> 0 | F19: =F18+E19 -> 0.8173 | G19: 115.6462 | H19: =F19*G19 -> 94.52 | I19: =H19-D19 -> -14.48 | J19: =(H19-D19)/D19 -> -0.1328 | K19: ='2022.08'!D29 -> 0 | L19: ='2022.08'!J29 -> 0 | M19: ='2022.08'!O29 -> 0 | AC19: ='2022.08'!$C$29 -> 0 | AD19: ='2022.08'!$E$29 -> 0.00 | AE19: ='2022.08'!$F$29 -> 0 | AF19: ='2024.01'!$A$25 -> 45322 | AG19: ='2024.01'!$B$25*-1 -> -10
A20: ='2022.09'!Q2 -> 2022.09 | B20: ='2022.09'!B29 -> 0 | C20: ='2022.09'!C29 -> 0 | D20: =D19+B20 -> 109 | E20: ='2022.09'!F29 -> 0 | F20: =F19+E20 -> 0.8173 | G20: 105.3827 | H20: =F20*G20 -> 86.13 | I20: =H20-D20 -> -22.87 | J20: =(H20-D20)/D20 -> -0.2098 | K20: ='2022.09'!D29 -> 0 | L20: ='2022.09'!J29 -> 0 | M20: ='2022.09'!O29 -> 0 | AC20: ='2022.09'!$C$29 -> 0 | AD20: ='2022.09'!$E$29 -> 0.00 | AE20: ='2022.09'!$F$29 -> 0 | AF20: ='2024.02'!$A$25 -> 45351 | AG20: ='2024.02'!$B$25*-1 -> -10
A21: ='2022.10'!Q2 -> 2022.1 | B21: ='2022.10'!B29 -> 0 | C21: ='2022.10'!C29 -> 0 | D21: =D20+B21 -> 109 | E21: ='2022.10'!F29 -> 0 | F21: =F20+E21 -> 0.8173 | G21: 109.6615 | H21: =F21*G21 -> 89.63 | I21: =H21-D21 -> -19.37 | J21: =(H21-D21)/D21 -> -0.1777 | K21: ='2022.10'!D29 -> 0 | L21: ='2022.10'!J29 -> 0 | M21: ='2022.10'!O29 -> 0 | AC21: ='2022.10'!$C$29 -> 0 | AD21: ='2022.10'!$E$29 -> 0.00 | AE21: ='2022.10'!$F$29 -> 0 | AF21: ='2024.04'!$A$25 -> 45384 | AG21: ='2024.04'!$B$25*-1 -> -10
A22: ='2022.11'!Q2 -> 2022.11 | B22: ='2022.11'!B29 -> 0 | C22: ='2022.11'!C29 -> 0 | D22: =D21+B22 -> 109 | E22: ='2022.11'!F29 -> 0 | F22: =F21+E22 -> 0.8173 | G22: 112.7624 | H22: =F22*G22 -> 92.16 | I22: =H22-D22 -> -16.84 | J22: =(H22-D22)/D22 -> -0.1545 | K22: ='2022.11'!D29 -> 0 | L22: ='2022.11'!J29 -> 0 | M22: ='2022.11'!O29 -> 0 | AC22: ='2022.11'!$C$29 -> 0 | AD22: ='2022.11'!$E$29 -> 0.00 | AE22: ='2022.11'!$F$29 -> 0 | AF22: ='2024.05'!$A$25 -> 45414 | AG22: ='2024.05'!$B$25*-1 -> -10
A23: ='2022.12'!Q2 -> 2022.12 | B23: ='2022.12'!B29 -> 0 | C23: ='2022.12'!C29 -> 0 | D23: =D22+B23 -> 109 | E23: ='2022.12'!F29 -> 0 | F23: =F22+E23 -> 0.8173 | G23: 110.4483 | H23: =F23*G23 -> 90.27 | I23: =H23-D23 -> -18.73 | J23: =(H23-D23)/D23 -> -0.1718 | K23: ='2022.12'!D29 -> 0 | L23: ='2022.12'!J29 -> 0 | M23: ='2022.12'!O29 -> 0 | AC23: ='2022.12'!$C$29 -> 0 | AD23: ='2022.12'!$E$29 -> 0.00 | AE23: ='2022.12'!$F$29 -> 0 | AF23: ='2024.05'!$A$26 -> 45442 | AG23: ='2024.05'!$B$26*-1 -> -10
A24: ='2023.01'!Q2 -> 2023.01 | B24: ='2023.01'!B29 -> 0 | C24: ='2023.01'!C29 -> 0 | D24: =D23+B24 -> 109 | E24: ='2023.01'!F29 -> 0 | F24: =F23+E24 -> 0.8173 | G24: 115.6853 | H24: =F24*G24 -> 94.55 | I24: =H24-D24 -> -14.45 | J24: =(H24-D24)/D24 -> -0.1326 | K24: ='2023.01'!D29 -> 0 | L24: ='2023.01'!J29 -> 0 | M24: ='2023.01'!O29 -> 0 | AC24: ='2023.01'!$C$29 -> 0 | AD24: ='2023.01'!$E$29 -> 0.00 | AE24: ='2023.01'!$F$29 -> 0 | AF24: ='2024.07'!$A$25 -> 45474 | AG24: ='2024.07'!$B$25*-1 -> -10
A25: ='2023.02'!Q2 -> 2023.02 | B25: ='2023.02'!B29 -> 0 | C25: ='2023.02'!C29 -> 0 | D25: =D24+B25 -> 109 | E25: ='2023.02'!F29 -> 0 | F25: =F24+E25 -> 0.8173 | G25: 115.8505 | H25: =F25*G25 -> 94.68 | I25: =H25-D25 -> -14.32 | J25: =(H25-D25)/D25 -> -0.1314 | K25: ='2023.02'!D29 -> 0 | L25: ='2023.02'!J29 -> 0 | M25: ='2023.02'!O29 -> 0 | AC25: ='2023.02'!$C$29 -> 0 | AD25: ='2023.02'!$E$29 -> 0.00 | AE25: ='2023.02'!$F$29 -> 0 | AF25: ='2024.07'!$A$26 -> 45504 | AG25: ='2024.07'!$B$26*-1 -> -10
A26: ='2023.03'!Q2 -> 2023.03 | B26: ='2023.03'!B29 -> 0 | C26: ='2023.03'!C29 -> 0 | D26: =D25+B26 -> 109 | E26: ='2023.03'!F29 -> 0 | F26: =F25+E26 -> 0.8173 | G26: 113.7257 | H26: =F26*G26 -> 92.95 | I26: =H26-D26 -> -16.05 | J26: =(H26-D26)/D26 -> -0.1472 | K26: ='2023.03'!D29 -> 0 | L26: ='2023.03'!J29 -> 0 | M26: ='2023.03'!O29 -> 0 | AC26: ='2023.03'!$C$29 -> 0 | AD26: ='2023.03'!$E$29 -> 0.00 | AE26: ='2023.03'!$F$29 -> 0 | AF26: ='2024.08'!$A$25 -> 45533 | AG26: ='2024.08'!$B$25*-1 -> -10
A27: ='2023.04'!Q2 -> 2023.04 | B27: ='2023.04'!B29 -> 0 | C27: ='2023.04'!C29 -> 0 | D27: =D26+B27 -> 109 | E27: ='2023.04'!F29 -> 0 | F27: =F26+E27 -> 0.8173 | G27: 114.6463 | H27: =F27*G27 -> 93.7 | I27: =H27-D27 -> -15.3 | J27: =(H27-D27)/D27 -> -0.1404 | K27: ='2023.04'!D29 -> 0 | L27: ='2023.04'!J29 -> 0 | M27: ='2023.04'!O29 -> 0 | AC27: ='2023.04'!$C$29 -> 0 | AD27: ='2023.04'!$E$29 -> 0.00 | AE27: ='2023.04'!$F$29 -> 0 | AF27: ='2024.10'!$A$25 -> 45566 | AG27: ='2024.10'!$B$25*-1 -> -10
A28: ='2023.05'!Q2 -> 2023.05 | B28: ='2023.05'!B29 -> 0 | C28: ='2023.05'!C29 -> 0 | D28: =D27+B28 -> 109 | E28: ='2023.05'!F29 -> 0 | F28: =F27+E28 -> 0.8173 | G28: 116.2896 | H28: =F28*G28 -> 95.04 | I28: =H28-D28 -> -13.96 | J28: =(H28-D28)/D28 -> -0.1281 | K28: ='2023.05'!D29 -> 0 | L28: ='2023.05'!J29 -> 0 | M28: ='2023.05'!O29 -> 0 | AC28: ='2023.05'!$C$29 -> 0 | AD28: ='2023.05'!$E$29 -> 0.00 | AE28: ='2023.05'!$F$29 -> 0 | AF28: ='2024.10'!$A$26 -> 45596 | AG28: ='2024.10'!$B$26*-1 -> -10
A29: ='2023.06'!Q2 -> 2023.06 | B29: ='2023.06'!B29 -> 0 | C29: ='2023.06'!C29 -> 0 | D29: =D28+B29 -> 109 | E29: ='2023.06'!F29 -> 0 | F29: =F28+E29 -> 0.8173 | G29: 117.3088 | H29: =F29*G29 -> 95.88 | I29: =H29-D29 -> -13.12 | J29: =(H29-D29)/D29 -> -0.1204 | K29: ='2023.06'!D29 -> 0 | L29: ='2023.06'!J29 -> 0 | M29: ='2023.06'!O29 -> 0 | AC29: ='2023.06'!$C$29 -> 0 | AD29: ='2023.06'!$E$29 -> 0.00 | AE29: ='2023.06'!$F$29 -> 0 | AF29: ='2024.11'!$A$25 -> 45625 | AG29: ='2024.11'!$B$25*-1 -> -10
A30: ='2023.07'!Q2 -> 2023.07 | B30: ='2023.07'!B29 -> 0 | C30: ='2023.07'!C29 -> 0 | D30: =D29+B30 -> 109 | E30: ='2023.07'!F29 -> 0 | F30: =F29+E30 -> 0.8173 | G30: 119.5659 | H30: =F30*G30 -> 97.72 | I30: =H30-D30 -> -11.28 | J30: =(H30-D30)/D30 -> -0.1035 | K30: ='2023.07'!D29 -> 0 | L30: ='2023.07'!J29 -> 0 | M30: ='2023.07'!O29 -> 0 | AC30: ='2023.07'!$C$29 -> 0 | AD30: ='2023.07'!$E$29 -> 0.00 | AE30: ='2023.07'!$F$29 -> 0 | AF30: ='2025.01'!$A$25 -> 45660 | AG30: ='2025.01'!$B$25*-1 -> -10
A31: ='2023.08'!Q2 -> 2023.08 | B31: ='2023.08'!B29 -> 0 | C31: ='2023.08'!C29 -> 0 | D31: =D30+B31 -> 109 | E31: ='2023.08'!F29 -> 0 | F31: =F30+E31 -> 0.8173 | G31: 117.8245 | H31: =F31*G31 -> 96.3 | I31: =H31-D31 -> -12.7 | J31: =(H31-D31)/D31 -> -0.1165 | K31: ='2023.08'!D29 -> 0 | L31: ='2023.08'!J29 -> 0 | M31: ='2023.08'!O29 -> 0 | AC31: ='2023.08'!$C$29 -> 0 | AD31: ='2023.08'!$E$29 -> 0.00 | AE31: ='2023.08'!$F$29 -> 0 | AF31: ='2025.01'!$A$26 -> 45687 | AG31: ='2025.01'!$B$26*-1 -> -10
A32: ='2023.09'!Q2 -> 2023.09 | B32: ='2023.09'!B29 -> 0 | C32: ='2023.09'!C29 -> 0 | D32: =D31+B32 -> 109 | E32: ='2023.09'!F29 -> 0 | F32: =F31+E32 -> 0.8173 | G32: 115.9676 | H32: =F32*G32 -> 94.78 | I32: =H32-D32 -> -14.22 | J32: =(H32-D32)/D32 -> -0.1305 | K32: ='2023.09'!D29 -> 0 | L32: ='2023.09'!J29 -> 0 | M32: ='2023.09'!O29 -> 0 | AC32: ='2023.09'!$C$29 -> 0 | AD32: ='2023.09'!$E$29 -> 0.00 | AE32: ='2023.09'!$F$29 -> 0 | AF32: ='2025.03'!$A$25 -> 45719 | AG32: ='2025.03'!$B$25*-1 -> -10
A33: ='2023.10'!Q2 -> 2023.1 | B33: ='2023.10'!B29 -> 0 | C33: ='2023.10'!C29 -> 0 | D33: =D32+B33 -> 109 | E33: ='2023.10'!F29 -> 0 | F33: =F32+E33 -> 0.8173 | G33: 111.2227 | H33: =F33*G33 -> 90.9 | I33: =H33-D33 -> -18.1 | J33: =(H33-D33)/D33 -> -0.1661 | K33: ='2023.10'!D29 -> 0 | L33: ='2023.10'!J29 -> 0 | M33: ='2023.10'!O29 -> 0 | AC33: ='2023.10'!$C$29 -> 0 | AD33: ='2023.10'!$E$29 -> 0.00 | AE33: ='2023.10'!$F$29 -> 0 | AF33: ='2025.03'!$A$26 -> 45747 | AG33: ='2025.03'!$B$26*-1 -> -15
A34: ='2023.11'!Q2 -> 2023.11 | B34: ='2023.11'!B29 -> 0 | C34: ='2023.11'!C29 -> 0 | D34: =D33+B34 -> 109 | E34: ='2023.11'!F29 -> 0 | F34: =F33+E34 -> 0.8173 | G34: 119.7561 | H34: =F34*G34 -> 97.88 | I34: =H34-D34 -> -11.12 | J34: =(H34-D34)/D34 -> -0.102 | K34: ='2023.11'!D29 -> 0 | L34: ='2023.11'!J29 -> 0 | M34: ='2023.11'!O29 -> 0 | AC34: ='2023.11'!$C$29 -> 0 | AD34: ='2023.11'!$E$29 -> 0.00 | AE34: ='2023.11'!$F$29 -> 0 | AF34: ='2025.05'!$A$25 -> 45779 | AG34: ='2025.05'!$B$25*-1 -> -15
A35: ='2023.12'!Q2 -> 2023.12 | B35: ='2023.12'!B29 -> 0 | C35: ='2023.12'!C29 -> 0 | D35: =D34+B35 -> 109 | E35: ='2023.12'!F29 -> 0 | F35: =F34+E35 -> 0.8173 | G35: 125.855 | H35: =F35*G35 -> 102.86 | I35: =H35-D35 -> -6.14 | J35: =(H35-D35)/D35 -> -0.0563 | K35: ='2023.12'!D29 -> 0 | L35: ='2023.12'!J29 -> 0 | M35: ='2023.12'!O29 -> 0 | AC35: ='2023.12'!$C$29 -> 0 | AD35: ='2023.12'!$E$29 -> 0.00 | AE35: ='2023.12'!$F$29 -> 0 | AF35: ='2025.05'!$A$26 -> 45807 | AG35: ='2025.05'!$B$26*-1 -> -15
A36: ='2024.01'!Q2 -> 2024.01 | B36: ='2024.01'!B29 -> 10 | C36: ='2024.01'!C29 -> 10 | D36: =D35+B36 -> 119 | E36: ='2024.01'!F29 -> 0.078 | F36: =F35+E36 -> 0.8953 | G36: 128.1957 | H36: =F36*G36 -> 114.77 | I36: =H36-D36 -> -4.23 | J36: =(H36-D36)/D36 -> -0.0355 | K36: ='2024.01'!D29 -> 0 | L36: ='2024.01'!J29 -> 0 | M36: ='2024.01'!O29 -> 0 | AC36: ='2024.01'!$C$29 -> 10 | AD36: ='2024.01'!$E$29 -> 128.21 | AE36: ='2024.01'!$F$29 -> 0.078 | AF36: ='2025.07'!$A$25 -> 45839 | AG36: ='2025.07'!$B$25*-1 -> -20
A37: ='2024.02'!Q2 -> 2024.02 | B37: ='2024.02'!B29 -> 10 | C37: ='2024.02'!C29 -> 10 | D37: =D36+B37 -> 129 | E37: ='2024.02'!F29 -> 0.0757 | F37: =F36+E37 -> 0.971 | G37: 132.0575 | H37: =F37*G37 -> 128.23 | I37: =H37-D37 -> -0.77 | J37: =(H37-D37)/D37 -> -0.006 | K37: ='2024.02'!D29 -> 0 | L37: ='2024.02'!J29 -> 0 | M37: ='2024.02'!O29 -> 0 | AC37: ='2024.02'!$C$29 -> 10 | AD37: ='2024.02'!$E$29 -> 132.1 | AE37: ='2024.02'!$F$29 -> 0.076 | AF37: ='2025.07'!$A$26 -> 45869 | AG37: ='2025.07'!$B$26*-1 -> -20
A38: ='2024.03'!Q2 -> 2024.03 | B38: ='2024.03'!B29 -> 0 | C38: ='2024.03'!C29 -> 0 | D38: =D37+B38 -> 129 | E38: ='2024.03'!F29 -> 0 | F38: =F37+E38 -> 0.971 | G38: 136.0219 | H38: =F38*G38 -> 132.08 | I38: =H38-D38 -> 3.08 | J38: =(H38-D38)/D38 -> 0.0239 | K38: ='2024.03'!D29 -> 0 | L38: ='2024.03'!J29 -> 0 | M38: ='2024.03'!O29 -> 0 | AC38: ='2024.03'!$C$29 -> 0 | AD38: ='2024.03'!$E$29 -> 0.00 | AE38: ='2024.03'!$F$29 -> 0 | AF38: ='2025.08'!$A$25 -> 45898 | AG38: ='2025.08'!$B$25*-1 -> -20
A39: ='2024.04'!Q2 -> 2024.04 | B39: ='2024.04'!B29 -> 10 | C39: ='2024.04'!C29 -> 10 | D39: =D38+B39 -> 139 | E39: ='2024.04'!F29 -> 0.0735 | F39: =F38+E39 -> 1.0445 | G39: 133.9217 | H39: =F39*G39 -> 139.88 | I39: =H39-D39 -> 0.88 | J39: =(H39-D39)/D39 -> 0.0063 | K39: ='2024.04'!D29 -> 0 | L39: ='2024.04'!J29 -> 0 | M39: ='2024.04'!O29 -> 0 | AC39: ='2024.04'!$C$29 -> 10 | AD39: ='2024.04'!$E$29 -> 136.05 | AE39: ='2024.04'!$F$29 -> 0.074 | AF39: ='2025.10'!$A$25 -> 45931 | AG39: ='2025.10'!$B$25*-1 -> -20
A40: ='2024.05'!Q2 -> 2024.05 | B40: ='2024.05'!B29 -> 20 | C40: ='2024.05'!C29 -> 20 | D40: =D39+B40 -> 159 | E40: ='2024.05'!F29 -> 0.1469 | F40: =F39+E40 -> 1.1914 | G40: 137.6376 | H40: =F40*G40 -> 163.98 | I40: =H40-D40 -> 4.98 | J40: =(H40-D40)/D40 -> 0.0313 | K40: ='2024.05'!D29 -> 0 | L40: ='2024.05'!J29 -> 0 | M40: ='2024.05'!O29 -> 0 | AC40: ='2024.05'!$C$29 -> 20 | AD40: ='2024.05'!$E$29 -> 136.15 | AE40: ='2024.05'!$F$29 -> 0.147 | AF40: ='2025.10'!$A$26 -> 45960 | AG40: ='2025.10'!$B$26*-1 -> -20
A41: ='2024.06'!Q2 -> 2024.06 | B41: ='2024.06'!B29 -> 0 | C41: ='2024.06'!C29 -> 0 | D41: =D40+B41 -> 159 | E41: ='2024.06'!F29 -> 0 | F41: =F40+E41 -> 1.1914 | G41: 140.5487 | H41: =F41*G41 -> 167.45 | I41: =H41-D41 -> 8.45 | J41: =(H41-D41)/D41 -> 0.0531 | K41: ='2024.06'!D29 -> 0 | L41: ='2024.06'!J29 -> 0 | M41: ='2024.06'!O29 -> 0 | AC41: ='2024.06'!$C$29 -> 0 | AD41: ='2024.06'!$E$29 -> 0.00 | AE41: ='2024.06'!$F$29 -> 0 | AF41: ='2025.12'!$A$25 -> 45992 | AG41: ='2025.12'!$B$25*-1 -> -20
...

Sheet SEB Artificial Intelligence Fun
A1: SESTUDI LX „SEB Artificial Intelligence Fund" LU2249630257
A3: Data | B3: Suma, EUR | E3: Kiekis | G3: Mėnesio gale | K3: Mokesčiai | M3: Dividendai | O3: Artificial | P3: Įnešta | Q3: Kiekis | R3: Parduota | S3: Pelnas | V3: Mokesčiai | X3: Dividendai | Y3: Vid. Kaina | AC3: Suma | AD3: Kaina | AE3: Kiekis | AF3: Pirkimas/pardavimas | AJ3: Valiutos keitimas
B4: Įnešta | C4: Mėn. Inv. | D4: Viso Inv. | E4: Mėnesio | F4: Viso | G4: Kaina | H4: Vertė gale | I4: Pelnas | J4: % | K4: Pirkimas | L4: Pardavimas | S4: Eur. | T4: % | U4: XIRR | V4: Pirkimas | W4: Pardavimas | AF4: Data | AG4: Suma | AJ4: Kursas | AK4: Suma, EUR | AL4: Viso suma | AM4: Kursas | AN4: Vertė gale | AO4: %
A5: ='2024.01'!Q2 -> 2024.01 | B5: ='2024.01'!B39 -> 18.94 | C5: ='2024.01'!C39 -> 18.94 | D5: =B5 -> 18.94 | E5: ='2024.01'!F39 -> 0.19 | F5: =E5 -> 0.19 | G5: 106.242 | H5: =F5*G5 -> 20.19 | I5: =H5-D5 -> 1.25 | J5: =(H5-D5)/D5 -> 0.066 | K5: ='2024.01'!D39 -> 0 | L5: ='2024.01'!J39 -> 0 | M5: ='2024.01'!O39 -> 0 | O5: Viso: | P5: =SUM(B5:B69) -> 37.92 | Q5: =SUM(E5:E69) -> 0.371 | R5: 45.63 | S5: =R5-P5+X5 -> 7.71 | T5: =(R5-P5+X5)/P5 -> 0.2033 | U5: =XIRR(AG5:AG65,AF5:AF65) -> 0.1163 | V5: =SUM(K5:K69) -> 0 | W5: =SUM(L5:L69) -> 0 | X5: =SUM(M5:M69) -> 0 | Y5: {=SUMPRODUCT(IFERROR(AD5:AD200,0),IFERROR(AE5:AE200,0))/SUM(IFERROR(AE5:AE200,0))} -> 109.89 | AC5: ='2024.01'!$C$39 -> 18.94 | AD5: ='2024.01'!$E$39 -> 105.26 | AE5: ='2024.01'!$F$39 -> 0.19 | AF5: ='2024.01'!$A$25 -> 45322 | AG5: ='2024.01'!$B$39*-1 -> -18.94 | AJ5: 1.0562 | AK5: =B5/AJ5 -> 17.93 | AL5: =AK5 -> 17.93 | AM5: 1.0573 | AN5: =H5/AM5 -> 19.1 | AO5: =(AN5-AL5)*100/AL5 -> 6.53
A6: ='2024.02'!Q2 -> 2024.02 | B6: ='2024.02'!B39 -> 0 | C6: ='2024.02'!C39 -> 0 | D6: =D5+B6 -> 18.94 | E6: ='2024.02'!F39 -> 0 | F6: =F5+E6 -> 0.19 | G6: 111.016 | H6: =F6*G6 -> 21.09 | I6: =H6-D6 -> 2.15 | J6: =(H6-D6)/D6 -> 0.1135 | K6: ='2024.02'!D39 -> 0 | L6: ='2024.02'!J39 -> 0 | M6: ='2024.02'!O39 -> 0 | AC6: ='2024.02'!$C$39 -> 0 | AD6: ='2024.02'!$E$39 -> 0.00 | AE6: ='2024.02'!$F$39 -> 0 | AF6: ='2024.05'!$A$25 -> 45414 | AG6: ='2024.05'!$B$39*-1 -> -18.98 | AK6: 0 | AL6: =AL5+AK6 -> 17.93 | AM6: 1.0549 | AN6: =H6/AM6 -> 19.99 | AO6: =(AN6-AL6)*100/AL6 -> 11.49
A7: ='2024.03'!Q2 -> 2024.03 | B7: ='2024.03'!B39 -> 0 | C7: ='2024.03'!C39 -> 0 | D7: =D6+B7 -> 18.94 | E7: ='2024.03'!F39 -> 0 | F7: =F6+E7 -> 0.19 | G7: 114.927 | H7: =F7*G7 -> 21.84 | I7: =H7-D7 -> 2.9 | J7: =(H7-D7)/D7 -> 0.1531 | K7: ='2024.03'!D39 -> 0 | L7: ='2024.03'!J39 -> 0 | M7: ='2024.03'!O39 -> 0 | AC7: ='2024.03'!$C$39 -> 0 | AD7: ='2024.03'!$E$39 -> 0.00 | AE7: ='2024.03'!$F$39 -> 0 | AK7: 0 | AL7: =AL6+AK7 -> 17.93 | AM7: 1.0498 | AN7: =H7/AM7 -> 20.8 | AO7: =(AN7-AL7)*100/AL7 -> 16.01
A8: ='2024.04'!Q2 -> 2024.04 | B8: ='2024.04'!B39 -> 0 | C8: ='2024.04'!C39 -> 0 | D8: =D7+B8 -> 18.94 | E8: ='2024.04'!F39 -> 0 | F8: =F7+E8 -> 0.19 | G8: 110.498 | H8: =F8*G8 -> 20.99 | I8: =H8-D8 -> 2.05 | J8: =(H8-D8)/D8 -> 0.1082 | K8: ='2024.04'!D39 -> 0 | L8: ='2024.04'!J39 -> 0 | M8: ='2024.04'!O39 -> 0 | AC8: ='2024.04'!$C$39 -> 0 | AD8: ='2024.04'!$E$39 -> 0.00 | AE8: ='2024.04'!$F$39 -> 0 | AK8: 0 | AL8: =AL7+AK8 -> 17.93 | AM8: 1.0412 | AN8: =H8/AM8 -> 20.16 | AO8: =(AN8-AL8)*100/AL8 -> 12.44
