Workbook

Sheet Apžvalga
A1: Data | B1: Viso: | E1: Mėnesio gale | U1: Dividendai | V1: Mokesčiai | AS1: XIRR | AT1: XIRR akt. | AU1: XIRR pard.
B2: Inešta | C2: Išvesta | D2: Investuota | E2: SLMC | F2: AYEM | G2: SGAJ | H2: WEBN | I2: XNAS | J2: SGAS | K2: SLMG | L2: SECA | M2: AYE2 | N2: ECRP | O2: IUSN | P2: ECR3 | Q2: SPYL | R2: Vertė | S2: Pelnas | T2: % | V2: Pirkimas | W2: Pardavimas | X2: Laikymas | AS2: =XIRR(_xlfn.VSTACK(SLMC!AG5:AG200,AYEM!AG5:AG200,SGAJ!AG5:AG200,WEBN!AG5:AG200,XNAS!AG5:AG200,SGAS!AG5:AG200,SLMG!AG5:AG200,SECA!AG5:AG200,'AYE2'!AG5:AG200,ECRP!AG5:AG200,IUSN!AG5:AG200,'ECR3'!AG5:AG200,SPYL!AG5:AG200),_xlfn.VSTACK(SLMC!AF5:AF200,AYEM!AF5:AF200,SGAJ!AF5:AF200,WEBN!AF5:AF200,XNAS!AF5:AF200,SGAS!AF5:AF200,SLMG!AF5:AF200,SECA!AF5:AF200,'AYE2'!AF5:AF200,ECRP!AF5:AF200,IUSN!AF5:AF200,'ECR3'!AF5:AF200,SPYL!AF5:AF200)) -> 0.17500184 | AT2: =XIRR(_xlfn.VSTACK(SLMC!AG5:AG200,AYEM!AG5:AG200,SGAJ!AG5:AG200,WEBN!AG5:AG200,XNAS!AG5:AG200),_xlfn.VSTACK(SLMC!AF5:AF200,AYEM!AF5:AF200,SGAJ!AF5:AF200,WEBN!AF5:AF200,XNAS!AF5:AF200)) -> 0.18108578 | AU2: =XIRR(_xlfn.VSTACK(SGAS!AG5:AG200,SLMG!AG5:AG200,SECA!AG5:AG200,'AYE2'!AG5:AG200,ECRP!AG5:AG200,IUSN!AG5:AG200,'ECR3'!AG5:AG200,SPYL!AG5:AG200),_xlfn.VSTACK(SGAS!AF5:AF200,SLMG!AF5:AF200,SECA!AF5:AF200,'AYE2'!AF5:AF200,ECRP!AF5:AF200,IUSN!AF5:AF200,'ECR3'!AF5:AF200,SPYL!AF5:AF200)) -> 0.10157467
A3: ='2024.05'!Q2 -> 2024.05 | B3: ='2024.05'!Q5 -> 29.96 | C3: ='2024.05'!R5 -> 0 | D3: ='2024.05'!S5 -> 29.9 | E3: =SLMC!H5 -> 9.8584031 | F3: =AYEM!H5 -> 9.630255 | G3: 0 | H3: 0 | I3: 0 | J3: =SGAS!H5 -> 9.7695471 | K3: 0 | L3: 0 | M3: 0 | N3: 0 | O3: 0 | P3: 0 | Q3: 0 | R3: =SUM(E3:Q3)-X3 -> 29.258205 | S3: =R3-B3 -> -0.70179484 | T3: =S3/B3 -> -0.023424394 | U3: ='2024.05'!X5 -> 0 | V3: ='2024.05'!U5 -> 0.06 | W3: ='2024.05'!W5 -> 0 | X3: ='2024.05'!V5 -> 0
A4: ='2024.06'!Q2 -> 2024.06 | B4: =B3+'2024.06'!Q5 -> 39.94 | C4: ='2024.06'!R5 -> 0 | D4: =D3+'2024.06'!S5 -> 39.86 | E4: =SLMC!H6 -> 9.7930074 | F4: =AYEM!H6 -> 10.160848 | G4: =SGAJ!H5 -> 10.049133 | H4: 0 | I4: 0 | J4: =SGAS!H6 -> 10.492392 | K4: 0 | L4: 0 | M4: 0 | N4: 0 | O4: 0 | P4: 0 | Q4: 0 | R4: =SUM(E4:Q4)-X4 -> 40.49538 | S4: =R4-B4 -> 0.55538026 | T4: =S4/B4 -> 0.013905365 | U4: ='2024.06'!X5 -> 0 | V4: ='2024.06'!U5 -> 0.02 | W4: ='2024.06'!W5 -> 0 | X4: ='2024.06'!V5 -> 0
A5: ='2024.07'!Q2 -> 2024.07 | B5: =B4+'2024.07'!Q5 -> 39.94 | C5: ='2024.07'!R5 -> 0 | D5: =D4+'2024.07'!S5 -> 39.86 | E5: =SLMC!H7 -> 9.9109532 | F5: =AYEM!H7 -> 10.139292 | G5: =SGAJ!H6 -> 10.304935 | H5: 0 | I5: 0 | J5: =SGAS!H7 -> 10.425575 | K5: 0 | L5: 0 | M5: 0 | N5: 0 | O5: 0 | P5: 0 | Q5: 0 | R5: =SUM(E5:Q5)-X5 -> 40.770755 | S5: =R5-B5 -> 0.83075514 | T5: =S5/B5 -> 0.020800079 | U5: ='2024.07'!X5 -> 0 | V5: ='2024.07'!U5 -> 0 | W5: ='2024.07'!W5 -> 0 | X5: ='2024.07'!V5 -> 0.01
A6: ='2024.08'!Q2 -> 2024.08 | B6: =B5+'2024.08'!Q5 -> 39.94 | C6: ='2024.08'!R5 -> 0 | D6: =D5+'2024.08'!S5 -> 39.86 | E6: =SLMC!H8 -> 10.068604 | F6: =AYEM!H8 -> 10.016593 | G6: =SGAJ!H7 -> 10.207795 | H6: 0 | I6: 0 | J6: =SGAS!H8 -> 10.338509 | K6: 0 | L6: 0 | M6: 0 | N6: 0 | O6: 0 | P6: 0 | Q6: 0 | R6: =SUM(E6:Q6)-X6 -> 40.621501 | S6: =R6-B6 -> 0.68150059 | T6: =S6/B6 -> 0.017063109 | U6: ='2024.08'!X5 -> 0 | V6: ='2024.08'!U5 -> 0 | W6: ='2024.08'!W5 -> 0 | X6: ='2024.08'!V5 -> 0.01
A7: ='2024.09'!Q2 -> 2024.09 | B7: =B6+'2024.09'!Q5 -> 39.94 | C7: ='2024.09'!R5 -> 0 | D7: =D6+'2024.09'!S5 -> 39.86 | E7: =SLMC!H9 -> 10.030067 | F7: =AYEM!H9 -> 10.528946 | G7: =SGAJ!H8 -> 10.078275 | H7: 0 | I7: 0 | J7: =SGAS!H9 -> 10.543012 | K7: 0 | L7: 0 | M7: 0 | N7: 0 | O7: 0 | P7: 0 | Q7: 0 | R7: =SUM(E7:Q7)-X7 -> 41.1703 | S7: =R7-B7 -> 1.2302997 | T7: =S7/B7 -> 0.030803698 | U7: ='2024.09'!X5 -> 0 | V7: ='2024.09'!U5 -> 0 | W7: ='2024.09'!W5 -> 0 | X7: ='2024.09'!V5 -> 0.01
A8: ='2024.10'!Q2 -> 2024.1 | B8: =B7+'2024.10'!Q5 -> 39.94 | C8: ='2024.10'!R5 -> 0 | D8: =D7+'2024.10'!S5 -> 39.86 | E8: =SLMC!H10 -> 9.7147661 | F8: =AYEM!H10 -> 10.320025 | G8: =SGAJ!H9 -> 9.777141 | H8: 0 | I8: 0 | J8: =SGAS!H10 -> 10.842679 | K8: 0 | L8: 0 | M8: 0 | N8: 0 | O8: 0 | P8: 0 | Q8: 0 | R8: =SUM(E8:Q8)-X8 -> 40.644611 | S8: =R8-B8 -> 0.70461109 | T8: =S8/B8 -> 0.01764174 | U8: ='2024.10'!X5 -> 0 | V8: ='2024.10'!U5 -> 0 | W8: ='2024.10'!W5 -> 0 | X8: ='2024.10'!V5 -> 0.01
A9: ='2024.11'!Q2 -> 2024.11 | B9: =B8+'2024.11'!Q5 -> 59.92 | C9: ='2024.11'!R5 -> 0 | D9: =D8+'2024.11'!S5 -> 59.8 | E9: =SLMC!H11 -> 9.8151952 | F9: =AYEM!H11 -> 10.404588 | G9: =SGAJ!H10 -> 10.298459 | H9: 0 | I9: 0 | J9: =SGAS!H11 -> 11.82672 | K9: =SLMG!H5 -> 10.089047 | L9: =SECA!H5 -> 10.111128 | M9: 0 | N9: 0 | O9: 0 | P9: 0 | Q9: 0 | R9: =SUM(E9:Q9)-X9 -> 62.535138 | S9: =R9-B9 -> 2.6151383 | T9: =S9/B9 -> 0.04364383 | U9: ='2024.11'!X5 -> 0 | V9: ='2024.11'!U5 -> 0.04 | W9: ='2024.11'!W5 -> 0 | X9: ='2024.11'!V5 -> 0.01
A10: ='2024.12'!Q2 -> 2024.12 | B10: =B9+'2024.12'!Q5 -> 59.92 | C10: ='2024.12'!R5 -> 0 | D10: =D9+'2024.12'!S5 -> 59.8 | E10: =SLMC!H12 -> 9.7591418 | F10: =AYEM!H12 -> 10.371426 | G10: =SGAJ!H11 -> 10.28065 | H10: 0 | I10: 0 | J10: =SGAS!H12 -> 11.765977 | K10: =SLMG!H6 -> 9.9002595 | L10: =SECA!H6 -> 9.9393498 | M10: 0 | N10: 0 | O10: 0 | P10: 0 | Q10: 0 | R10: =SUM(E10:Q10)-X10 -> 62.006804 | S10: =R10-B10 -> 2.0868044 | T10: =S10/B10 -> 0.034826508 | U10: ='2024.12'!X5 -> 0 | V10: ='2024.12'!U5 -> 0 | W10: ='2024.12'!W5 -> 0 | X10: ='2024.12'!V5 -> 0.01
A11: ='2025.01'!Q2 -> 2025.01 | B11: =B10+'2025.01'!Q5 -> 59.92 | C11: ='2025.01'!R5 -> 0 | D11: =D10+'2025.01'!S5 -> 59.8 | E11: =SLMC!H13 -> 10.390911 | F11: =AYEM!H13 -> 10.729576 | G11: =SGAJ!H12 -> 10.602831 | H11: 0 | I11: 0 | J11: =SGAS!H13 -> 12.257998 | K11: =SLMG!H7 -> 10.062173 | L11: =SECA!H7 -> 9.9498715 | M11: 0 | N11: 0 | O11: 0 | P11: 0 | Q11: 0 | R11: =SUM(E11:Q11)-X11 -> 63.98336 | S11: =R11-B11 -> 4.0633604 | T11: =S11/B11 -> 0.067813091 | U11: ='2025.01'!X5 -> 0 | V11: ='2025.01'!U5 -> 0 | W11: ='2025.01'!W5 -> 0 | X11: ='2025.01'!V5 -> 0.01
A12: ='2025.02'!Q2 -> 2025.02 | B12: =B11+'2025.02'!Q5 -> 69.91 | C12: ='2025.02'!R5 -> 0 | D12: =D11+'2025.02'!S5 -> 69.77 | E12: =SLMC!H14 -> 10.733071 | F12: =AYEM!H14 -> 10.6218 | G12: =SGAJ!H13 -> 10.521881 | H12: 0 | I12: 0 | J12: =SGAS!H14 -> 11.709283 | K12: =SLMG!H8 -> 10.195435 | L12: =SECA!H8 -> 10.000193 | M12: ='AYE2'!H5 -> 10.001067 | N12: 0 | O12: 0 | P12: 0 | Q12: 0 | R12: =SUM(E12:Q12)-X12 -> 73.772729 | S12: =R12-B12 -> 3.8627293 | T12: =S12/B12 -> 0.055252886 | U12: ='2025.02'!X5 -> 0 | V12: ='2025.02'!U5 -> 0.02 | W12: ='2025.02'!W5 -> 0 | X12: ='2025.02'!V5 -> 0.01
A13: ='2025.03'!Q2 -> 2025.03 | B13: =B12+'2025.03'!Q5 -> 139.69 | C13: ='2025.03'!R5 -> 0 | D13: =D12+'2025.03'!S5 -> 139.41 | E13: =SLMC!H15 -> 10.262455 | F13: =AYEM!H15 -> 10.248727 | G13: =SGAJ!H14 -> 10.110655 | H13: =WEBN!H5 -> 9.4229832 | I13: =XNAS!H5 -> 9.1212623 | J13: =SGAS!H15 -> 10.545037 | K13: =SLMG!H9 -> 10.083495 | L13: =SECA!H9 -> 9.8158342 | M13: ='AYE2'!H6 -> 9.8828696 | N13: =ECRP!H5 -> 9.962091 | O13: =IUSN!H5 -> 9.597717 | P13: ='ECR3'!H5 -> 9.9218797 | Q13: =SPYL!H5 -> 18.903584 | R13: =SUM(E13:Q13)-X13 -> 137.86859 | S13: =R13-B13 -> -1.8214108 | T13: =S13/B13 -> -0.013038949 | U13: ='2025.03'!X5 -> 0 | V13: ='2025.03'!U5 -> 0.14 | W13: ='2025.03'!W5 -> 0 | X13: ='2025.03'!V5 -> 0.01
A14: ='2025.04'!Q2 -> 2025.04 | B14: =B13+'2025.04'!Q5 -> 139.69 | C14: ='2025.04'!R5 -> 0 | D14: =D13+'2025.04'!S5 -> 139.41 | E14: =SLMC!H16 -> 10.207569 | F14: =AYEM!H16 -> 9.8839445 | G14: =SGAJ!H15 -> 10.003801 | H14: =WEBN!H6 -> 9.052805 | I14: =XNAS!H6 -> 8.8244264 | J14: =SGAS!H16 -> 10.03783 | K14: =SLMG!H10 -> 10.105927 | L14: =SECA!H10 -> 10.014603 | M14: ='AYE2'!H7 -> 9.9403614 | N14: =ECRP!H6 -> 10.060558 | O14: =IUSN!H6 -> 9.195606 | P14: ='ECR3'!H6 -> 9.9718801 | Q14: =SPYL!H6 -> 17.897281 | R14: =SUM(E14:Q14)-X14 -> 135.17659 | S14: =R14-B14 -> -4.5134072 | T14: =S14/B14 -> -0.032310167 | U14: ='2025.04'!X5 -> 0 | V14: ='2025.04'!U5 -> 0 | W14: ='2025.04'!W5 -> 0 | X14: ='2025.04'!V5 -> 0.02
A15: ='2025.05'!Q2 -> 2025.05 | B15: =B14+'2025.05'!Q5 -> 149.67 | C15: ='2025.05'!R5 -> 0 | D15: =D14+'2025.05'!S5 -> 149.37 | E15: =SLMC!H17 -> 10.663004 | F15: =AYEM!H17 -> 10.341581 | G15: =SGAJ!H16 -> 10.382647 | H15: =WEBN!H7 -> 19.461867 | I15: =XNAS!H7 -> 9.7082132 | J15: =SGAS!H17 -> 10.785985 | K15: =SLMG!H11 -> 10.166784 | L15: =SECA!H11 -> 10.042737 | M15: ='AYE2'!H8 -> 10.094268 | N15: =ECRP!H7 -> 10.120056 | O15: =IUSN!H7 -> 9.74511 | P15: ='ECR3'!H7 -> 10.007971 | Q15: =SPYL!H7 -> 19.13181 | R15: =SUM(E15:Q15)-X15 -> 150.63203 | S15: =R15-B15 -> 0.96203156 | T15: =S15/B15 -> 0.0064276846 | U15: ='2025.05'!X5 -> 0 | V15: ='2025.05'!U5 -> 0.02 | W15: ='2025.05'!W5 -> 0 | X15: ='2025.05'!V5 -> 0.02
A16: ='2025.06'!Q2 -> 2025.06 | B16: =B15+'2025.06'!Q5 -> 149.67 | C16: ='2025.06'!R5 -> 0 | D16: =D15+'2025.06'!S5 -> 149.37 | E16: =SLMC!H18 -> 10.547394 | F16: =AYEM!H18 -> 10.651646 | G16: =SGAJ!H17 -> 10.233699 | H16: =WEBN!H8 -> 19.658849 | I16: =XNAS!H8 -> 9.9692047 | J16: =SGAS!H18 -> 10.990487 | K16: =SLMG!H12 -> 10.369786 | L16: =SECA!H12 -> 10.003624 | M16: ='AYE2'!H9 -> 10.134619 | N16: =ECRP!H8 -> 10.153132 | O16: =IUSN!H8 -> 9.863883 | P16: ='ECR3'!H8 -> 10.039174 | Q16: =SPYL!H8 -> 19.421047 | R16: =SUM(E16:Q16)-X16 -> 152.01654 | S16: =R16-B16 -> 2.3465442 | T16: =S16/B16 -> 0.01567812 | U16: ='2025.06'!X5 -> 0 | V16: ='2025.06'!U5 -> 0 | W16: ='2025.06'!W5 -> 0 | X16: ='2025.06'!V5 -> 0.02
A17: ='2025.07'!Q2 -> 2025.07 | B17: =B16+'2025.07'!Q5 -> 159.65 | C17: ='2025.07'!R5 -> 0 | D17: =D16+'2025.07'!S5 -> 159.33 | E17: =SLMC!H19 -> 10.648991 | F17: =AYEM!H19 -> 11.089384 | G17: =SGAJ!H18 -> 10.342172 | H17: =WEBN!H9 -> 20.631942 | I17: =XNAS!H9 -> 10.606562 | J17: =SGAS!H19 -> 11.687011 | K17: =SLMG!H13 -> 10.446412 | L17: =SECA!H13 -> 9.9830378 | M17: ='AYE2'!H10 -> 10.232462 | N17: =ECRP!H9 -> 10.199134 | O17: =IUSN!H9 -> 10.298907 | P17: ='ECR3'!H9 -> 10.056843 | Q17: =SPYL!H9 -> 31.067088 | R17: =SUM(E17:Q17)-X17 -> 167.26995 | S17: =R17-B17 -> 7.6199458 | T17: =S17/B17 -> 0.047729069 | U17: ='2025.07'!X5 -> 0 | V17: ='2025.07'!U5 -> 0.02 | W17: ='2025.07'!W5 -> 0 | X17: ='2025.07'!V5 -> 0.02
A18: ='2025.08'!Q2 -> 2025.08 | B18: =B17+'2025.08'!Q5 -> 159.65 | C18: ='2025.08'!R5 -> 0 | D18: =D17+'2025.08'!S5 -> 159.33 | E18: =SLMC!H20 -> 10.745916 | F18: =AYEM!H20 -> 11.062855 | G18: =SGAJ!H19 -> 10.719399 | H18: =WEBN!H10 -> 20.553149 | I18: =XNAS!H10 -> 10.363492 | J18: =SGAS!H20 -> 11.533128 | K18: =SLMG!H14 -> 10.577231 | L18: =SECA!H14 -> 9.9269983 | M18: ='AYE2'!H11 -> 10.232105 | N18: =ECRP!H10 -> 10.203316 | O18: =IUSN!H10 -> 10.525005 | P18: ='ECR3'!H10 -> 10.070753 | Q18: =SPYL!H10 -> 30.726278 | R18: =SUM(E18:Q18)-X18 -> 167.21963 | S18: =R18-B18 -> 7.569626 | T18: =S18/B18 -> 0.04741388 | U18: ='2025.08'!X5 -> 0 | V18: ='2025.08'!U5 -> 0 | W18: ='2025.08'!W5 -> 0 | X18: ='2025.08'!V5 -> 0.02
A19: ='2025.09'!Q2 -> 2025.09 | B19: =B18+'2025.09'!Q5 -> 159.65 | C19: ='2025.09'!R5 -> 0 | D19: =D18+'2025.09'!S5 -> 159.33 | E19: =SLMC!H21 -> 10.900063 | F19: =AYEM!H21 -> 11.664746 | G19: =SGAJ!H20 -> 10.907203 | H19: =WEBN!H11 -> 21.144097 | I19: =XNAS!H11 -> 10.851871 | J19: =SGAS!H21 -> 11.895563 | K19: =SLMG!H15 -> 10.73559 | L19: =SECA!H15 -> 9.9782344 | M19: ='AYE2'!H12 -> 10.303524 | N19: =ECRP!H11 -> 10.238863 | O19: =IUSN!H11 -> 10.633761 | P19: ='ECR3'!H11 -> 10.091054 | Q19: =SPYL!H11 -> 31.590799 | R19: =SUM(E19:Q19)-X19 -> 170.91537 | S19: =R19-B19 -> 11.265368 | T19: =S19/B19 -> 0.070562908 | U19: ='2025.09'!X5 -> 0 | V19: ='2025.09'!U5 -> 0 | W19: ='2025.09'!W5 -> 0 | X19: ='2025.09'!V5 -> 0.02
A20: ='2025.10'!Q2 -> 2025.1 | B20: =B19+'2025.10'!Q5 -> 159.65 | C20: ='2025.10'!R5 -> 0 | D20: =D19+'2025.10'!S5 -> 159.33 | E20: =SLMC!H22 -> 11.244559 | F20: =AYEM!H22 -> 12.323012 | G20: =SGAJ!H21 -> 11.558041 | H20: =WEBN!H12 -> 22.160526 | I20: =XNAS!H12 -> 11.611323 | J20: =SGAS!H22 -> 12.490847 | K20: =SLMG!H16 -> 10.912163 | L20: =SECA!H16 -> 10.076132 | M20: ='AYE2'!H13 -> 10.365658 | N20: =ECRP!H12 -> 10.298932 | O20: =IUSN!H12 -> 10.935702 | P20: ='ECR3'!H12 -> 10.121505 | Q20: =SPYL!H12 -> 33.090362 | R20: =SUM(E20:Q20)-X20 -> 177.16876 | S20: =R20-B20 -> 17.518762 | T20: =S20/B20 -> 0.1097323 | U20: ='2025.10'!X5 -> 0 | V20: ='2025.10'!U5 -> 0 | W20: ='2025.10'!W5 -> 0 | X20: ='2025.10'!V5 -> 0.02
A21: ='2025.11'!Q2 -> 2025.11 | B21: =B20+'2025.11'!Q5 -> 346.02 | C21: ='2025.11'!R5 -> 0 | D21: =D20+'2025.11'!S5 -> 344.98 | E21: =SLMC!H23 -> 21.450327 | F21: =AYEM!H23 -> 89.313584 | G21: =SGAJ!H22 -> 21.568384 | H21: =WEBN!H13 -> 212.53926 | I21: =XNAS!H13 -> 21.403904 | R21: =SUM(E21:Q21)-X21 -> 366.25546 | S21: =R21-B21 -> 20.235463 | T21: =S21/B21 -> 0.058480617 | U21: ='2025.11'!X5 -> 0 | V21: ='2025.11'!U5 -> 0.72 | W21: ='2025.11'!W5 -> 0.29 | X21: ='2025.11'!V5 -> 0.02
A22: ='2025.12'!$Q$2 -> 2025.12 | B22: =B21+'2025.12'!$Q$5 -> 356 | C22: ='2025.12'!$R$5 -> 0 | D22: =D21+'2025.12'!$S$5 -> 354.94 | E22: =SLMC!H24 -> 22.059194 | F22: =AYEM!H24 -> 89.765464 | G22: =SGAJ!H23 -> 21.67224 | H22: =WEBN!H14 -> 223.73495 | I22: =XNAS!H14 -> 21.260083 | R22: =SUM(E22:Q22)-X22 -> 378.44193 | S22: =R22-B22 -> 22.441929 | T22: =S22/B22 -> 0.063039128 | U22: ='2025.12'!X5 -> 0 | V22: ='2025.12'!U5 -> 0.02 | W22: ='2025.12'!W5 -> 0 | X22: ='2025.12'!$V$5 -> 0.05
A23: ='2026.01'!$Q$2 -> 2026.01 | B23: =B22+'2026.01'!$Q$5 -> 395.97 | C23: ='2026.01'!$R$5 -> 0 | D23: =D22+'2026.01'!$S$5 -> 394.82 | E23: =SLMC!H25 -> 22.754724 | F23: =AYEM!H25 -> 106.61927 | G23: =SGAJ!H24 -> 22.600832 | H23: =WEBN!H15 -> 255.59073 | I23: =XNAS!H15 -> 21.196633 | R23: =SUM(E23:Q23)-X23 -> 428.7122 | S23: =R23-B23 -> 32.742197 | T23: =S23/B23 -> 0.08268858 | U23: ='2026.01'!$X$5 -> 0 | V23: ='2026.01'!$U$5 -> 0.09 | W23: ='2026.01'!$W$5 -> 0 | X23: ='2026.01'!$V$5 -> 0.05
A24: ='2026.02'!$Q$2 -> 2026.02 | B24: =B23+'2026.02'!$Q$5 -> 435.95 | C24: ='2026.02'!$R$5 -> 0 | D24: =D23+'2026.02'!$S$5 -> 434.71 | E24: =SLMC!H26 -> 23.510252 | F24: =AYEM!H26 -> 123.68794 | G24: =SGAJ!H25 -> 24.43358 | H24: =WEBN!H16 -> 291.64733 | I24: =XNAS!H16 -> 20.773631 | R24: =SUM(E24:Q24)-X24 -> 483.99273 | S24: =R24-B24 -> 48.042731 | T24: =S24/B24 -> 0.11020239 | U24: ='2026.02'!$X$5 -> 0 | V24: ='2026.02'!$U$5 -> 0.09 | W24: ='2026.02'!$W$5 -> 0 | X24: ='2026.02'!$V$5 -> 0.06
A25: ='2026.03'!$Q$2 -> 2026.03 | B25: =B24+'2026.03'!$Q$5 -> 475.9 | C25: ='2026.03'!$R$5 -> 0 | D25: =D24+'2026.03'!$S$5 -> 474.58 | E25: =SLMC!H27 -> 31.332467 | F25: =AYEM!H27 -> 120.20367 | G25: =SGAJ!H26 -> 32.047517 | H25: =WEBN!H17 -> 274.82636 | I25: =XNAS!H17 -> 29.292035 | R25: =SUM(E25:Q25)-X25 -> 487.64205 | S25: =R25-B25 -> 11.742053 | T25: =S25/B25 -> 0.024673361 | U25: ='2026.03'!$X$5 -> 0 | V25: ='2026.03'!$U$5 -> 0.08 | W25: ='2026.03'!$W$5 -> 0 | X25: ='2026.03'!$V$5 -> 0.06
A26: ='2026.04'!$Q$2 -> 2026.04 | B26: =B25+'2026.04'!$Q$5 -> 525.87 | C26: ='2026.04'!$R$5 -> 0 | D26: =D25+'2026.04'!$S$5 -> 524.55 | E26: =SLMC!H28 -> 42.228922 | F26: =AYEM!H28 -> 154.69311 | G26: =SGAJ!H27 -> 43.328743 | H26: =WEBN!H18 -> 297.18717 | I26: =XNAS!H18 -> 43.798575 | R26: =SUM(E26:Q26)-X26 -> 581.17652 | S26: =R26-B26 -> 55.306519 | T26: =S26/B26 -> 0.10517147 | U26: ='2026.04'!$X$5 -> 0 | V26: ='2026.04'!$U$5 -> 0 | W26: ='2026.04'!$W$5 -> 0 | X26: ='2026.04'!$V$5 -> 0.06
A27: ='2026.05'!$Q$2 -> 2026.05 | B27: =B26+'2026.05'!$Q$5 -> 575.7 | C27: ='2026.05'!$R$5 -> 0 | D27: =D26+'2026.05'!$S$5 -> 574.28 | E27: =SLMC!H29 -> 54.576062 | F27: =AYEM!H29 -> 180.29367 | G27: =SGAJ!H28 -> 56.797324 | H27: =WEBN!H19 -> 326.83996 | I27: =XNAS!H19 -> 59.38373 | R27: =SUM(E27:Q27)-X27 -> 677.81075 | S27: =R27-B27 -> 102.11075 | T27: =S27/B27 -> 0.17736798 | U27: ='2026.05'!$X$5 -> 0 | V27: ='2026.05'!$U$5 -> 0.1 | W27: ='2026.05'!$W$5 -> 0 | X27: ='2026.05'!$V$5 -> 0.08
A28: ='2026.06'!$Q$2 -> 2026.06 | B28: =B27+'2026.06'!$Q$5 -> 2394.58 | C28: ='2026.06'!$R$5 -> 0 | D28: =D27+'2026.06'!$S$5 -> 2388.61 | E28: =SLMC!H30 -> 277.66162 | F28: =AYEM!H30 -> 284.57391 | G28: =SGAJ!H29 -> 259.31932 | H28: =WEBN!H20 -> 1434.7982 | I28: =XNAS!H20 -> 262.21045 | R28: =SUM(E28:Q28)-X28 -> 2518.4735 | S28: =R28-B28 -> 123.89347 | T28: =S28/B28 -> 0.051739122 | U28: ='2026.06'!$X$5 -> 0 | V28: ='2026.06'!$U$5 -> 4.55 | W28: ='2026.06'!$W$5 -> 0 | X28: ='2026.06'!$V$5 -> 0.09
A29: ='2026.07'!$Q$2 -> 2026.07 | B29: =B28+'2026.07'!$Q$5 -> 2994.57 | C29: ='2026.07'!$R$5 -> 0 | D29: =D28+'2026.07'!$S$5 -> 2987.1 | E29: =SLMC!H31 -> 381.26116 | F29: =AYEM!H31 -> 355.23979 | G29: =SGAJ!H30 -> 354.46044 | H29: =WEBN!H21 -> 1601.4585 | I29: =XNAS!H21 -> 336.33101 | R29: =SUM(E29:Q29)-X29 -> 3028.5709 | S29: =R29-B29 -> 34.000861 | T29: =S29/B29 -> 0.011354171 | U29: ='2026.07'!$X$5 -> 0 | V29: ='2026.07'!$U$5 -> 1.5 | W29: ='2026.07'!$W$5 -> 0 | X29: ='2026.07'!$V$5 -> 0.18
A30: ='2026.08'!$Q$2 -> 2026.08 | B30: =B29+'2026.08'!$Q$5 -> 3094.42 | C30: ='2026.08'!$R$5 -> 0 | D30: =D29+'2026.08'!$S$5 -> 3086.72 | E30: =SLMC!H32 -> 392.68104 | F30: =AYEM!H32 -> 385.67235 | G30: =SGAJ!H31 -> 373.77267 | H30: =WEBN!H22 -> 1707.9645 | I30: =XNAS!H22 -> 360.16937 | R30: =SUM(E30:Q30)-X30 -> 3219.8599 | S30: =R30-B30 -> 125.4399 | T30: =S30/B30 -> 0.04053745 | U30: ='2026.08'!$X$5 -> 0 | V30: ='2026.08'!$U$5 -> 0.23 | W30: ='2026.08'!$W$5 -> 0 | X30: ='2026.08'!$V$5 -> 0.4
A31: ='2026.09'!$Q$2 -> 2026.09 | B31: =B30+'2026.09'!$Q$5 -> 3194.34 | C31: ='2026.09'!$R$5 -> 0 | D31: =D30+'2026.09'!$S$5 -> 3186.41 | E31: =SLMC!H33 -> 393.30373 | F31: =AYEM!H33 -> 403.76213 | G31: =SGAJ!H32 -> 401.76065 | H31: =WEBN!H23 -> 1801.9112 | I31: =XNAS!H23 -> 394.76441 | R31: =SUM(E31:Q31)-X31 -> 3395.0821 | S31: =R31-B31 -> 200.74208 | T31: =S31/B31 -> 0.062843053 | U31: ='2026.09'!$X$5 -> 0 | V31: ='2026.09'!$U$5 -> 0.23 | W31: ='2026.09'!$W$5 -> 0 | X31: ='2026.09'!$V$5 -> 0.42

Sheet SLMC
A1: SLMC GY iShares MSCI Europe ESG Screened
A3: Data | B3: Suma, EUR | E3: Kiekis | G3: Mėnesio gale | K3: Mokesčiai | M3: Dividendai | O3: SLMC | P3: Įnešta | Q3: Kiekis | R3: Parduota | S3: Pelnas | V3: Mokesčiai | X3: Dividendai | Y3: Vid. Kaina | AC3: Suma | AD3: Kaina | AE3: Kiekis | AF3: Pirkimas/pardavimas
B4: Įnešta | C4: Mėn. Inv. | D4: Viso Inv. | E4: Mėnesio | F4: Viso | G4: Kaina | H4: Vertė | I4: Pelnas | J4: % | K4: Pirkimas | L4: Pardavimas | S4: Eur. | T4: % | U4: XIRR | V4: Pirkimas | W4: Pardavimas | AF4: Data | AG4: Suma
A5: ='2024.05'!Q2 -> 2024.05 | B5: ='2024.05'!B29 -> 9.98 | C5: ='2024.05'!C29 -> 9.96 | D5: =C5 -> 9.96 | E5: ='2024.05'!F29 -> 1.1677805 | F5: =E5 -> 1.1677805 | G5: 8.442 | H5: =F5*G5 -> 9.8584031 | I5: =H5-D5 -> -0.1015969 | J5: =(H5-D5)/D5 -> -0.010200492 | K5: ='2024.05'!D29 -> 0.02 | L5: ='2024.05'!I29 -> 0 | M5: ='2024.05'!O29 -> 0 | O5: Viso: | P5: =SUM(B5:B500) -> 389.78 | Q5: =SUM(E5:E500) -> 36.229157 | S5: =R5-P5+X5 -> -389.78 | T5: =(R5-P5+X5)/P5 -> -1 | U5: =XIRR(AG5:AG200,AF5:AF200) -> 0.028506061 | V5: =SUM(K5:K500) -> 0.92 | W5: =SUM(L5:L500) -> 0 | X5: =SUM(M5:M500) -> 0 | Y5: {=SUMPRODUCT(IFERROR(AD5:AD200,0),IFERROR(AE5:AE200,0))/SUM(IFERROR(AE5:AE200,0))} -> 10.733344 | AC5: ='2024.05'!$C$29 -> 9.96 | AD5: ='2024.05'!$E$29 -> 8.529 | AE5: ='2024.05'!$F$29 -> 1.1677805 | AF5: ='2024.05'!$A$25 -> 45443 | AG5: ='2024.05'!$B$25*-1 -> -9.98
A6: ='2024.06'!Q2 -> 2024.06 | B6: ='2024.06'!B29 -> 0 | C6: ='2024.06'!C29 -> 0 | D6: =D5+C6 -> 9.96 | E6: ='2024.06'!F29 -> 0 | F6: =F5+E6 -> 1.1677805 | G6: 8.386 | H6: =F6*G6 -> 9.7930074 | I6: =H6-D6 -> -0.16699261 | J6: =(H6-D6)/D6 -> -0.016766327 | K6: ='2024.06'!D29 -> 0 | L6: ='2024.06'!I29 -> 0 | M6: ='2024.06'!O29 -> 0 | AC6: ='2024.06'!$C$29 -> 0 | AD6: ='2024.06'!$E$29 -> 0.00 | AE6: ='2024.06'!$F$29 -> 0 | AF6: ='2025.11'!$A$25 -> 45989 | AG6: ='2025.11'!$B$25*-1 -> -9.97
A7: ='2024.07'!Q2 -> 2024.07 | B7: ='2024.07'!B29 -> 0 | C7: ='2024.07'!C29 -> 0 | D7: =D6+C7 -> 9.96 | E7: ='2024.07'!F29 -> 0 | F7: =F6+E7 -> 1.1677805 | G7: 8.487 | H7: =F7*G7 -> 9.9109532 | I7: =H7-D7 -> -0.049046782 | J7: =(H7-D7)/D7 -> -0.0049243757 | K7: ='2024.07'!D29 -> 0 | L7: ='2024.07'!I29 -> 0 | M7: ='2024.07'!O29 -> 0 | AC7: ='2024.07'!$C$29 -> 0 | AD7: ='2024.07'!$E$29 -> 0.00 | AE7: ='2024.07'!$F$29 -> 0 | AF7: ='2026.03'!$A$25 -> 46100 | AG7: ='2026.03'!$B$25*-1 -> -9.99
A8: ='2024.08'!Q2 -> 2024.08 | B8: ='2024.08'!B29 -> 0 | C8: ='2024.08'!C29 -> 0 | D8: =D7+C8 -> 9.96 | E8: ='2024.08'!F29 -> 0 | F8: =F7+E8 -> 1.1677805 | G8: 8.622 | H8: =F8*G8 -> 10.068604 | I8: =H8-D8 -> 0.10860359 | J8: =(H8-D8)/D8 -> 0.010903975 | K8: ='2024.08'!D29 -> 0 | L8: ='2024.08'!I29 -> 0 | M8: ='2024.08'!O29 -> 0 | AC8: ='2024.08'!$C$29 -> 0 | AD8: ='2024.08'!$E$29 -> 0.00 | AE8: ='2024.08'!$F$29 -> 0 | AF8: ='2026.04'!$A$25 -> 46133 | AG8: ='2026.04'!$B$25*-1 -> -9.99
A9: ='2024.09'!Q2 -> 2024.09 | B9: ='2024.09'!B29 -> 0 | C9: ='2024.09'!C29 -> 0 | D9: =D8+C9 -> 9.96 | E9: ='2024.09'!F29 -> 0 | F9: =F8+E9 -> 1.1677805 | G9: 8.589 | H9: =F9*G9 -> 10.030067 | I9: =H9-D9 -> 0.070066831 | J9: =(H9-D9)/D9 -> 0.0070348224 | K9: ='2024.09'!D29 -> 0 | L9: ='2024.09'!I29 -> 0 | M9: ='2024.09'!O29 -> 0 | AC9: ='2024.09'!$C$29 -> 0 | AD9: ='2024.09'!$E$29 -> 0.00 | AE9: ='2024.09'!$F$29 -> 0 | AF9: ='2026.05'!$A$25 -> 46162 | AG9: ='2026.05'!$B$25*-1 -> -9.98
A10: ='2024.10'!Q2 -> 2024.1 | B10: ='2024.10'!B29 -> 0 | C10: ='2024.10'!C29 -> 0 | D10: =D9+C10 -> 9.96 | E10: ='2024.10'!F29 -> 0 | F10: =F9+E10 -> 1.1677805 | G10: 8.319 | H10: =F10*G10 -> 9.7147661 | I10: =H10-D10 -> -0.24523391 | J10: =(H10-D10)/D10 -> -0.024621878 | K10: ='2024.10'!D29 -> 0 | L10: ='2024.10'!I29 -> 0 | M10: ='2024.10'!O29 -> 0 | AC10: ='2024.10'!$C$29 -> 0 | AD10: ='2024.10'!$E$29 -> 0.00 | AE10: ='2024.10'!$F$29 -> 0 | AF10: ='2026.06'!$A$25 -> 46198 | AG10: ='2026.06'!$B$25*-1 -> -99.91
A11: ='2024.11'!Q2 -> 2024.11 | B11: ='2024.11'!B29 -> 0 | C11: ='2024.11'!C29 -> 0 | D11: =D10+C11 -> 9.96 | E11: ='2024.11'!F29 -> 0 | F11: =F10+E11 -> 1.1677805 | G11: 8.405 | H11: =F11*G11 -> 9.8151952 | I11: =H11-D11 -> -0.14480478 | J11: =(H11-D11)/D11 -> -0.014538633 | K11: ='2024.11'!D29 -> 0 | L11: ='2024.11'!I29 -> 0 | M11: ='2024.11'!O29 -> 0 | AC11: ='2024.11'!$C$29 -> 0 | AD11: ='2024.11'!$E$29 -> 0.00 | AE11: ='2024.11'!$F$29 -> 0 | AF11: ='2026.06'!$A$26 -> 46203 | AG11: ='2026.06'!$B$26*-1 -> -119.99
A12: ='2024.12'!Q2 -> 2024.12 | B12: ='2024.12'!B29 -> 0 | C12: ='2024.12'!C29 -> 0 | D12: =D11+C12 -> 9.96 | E12: ='2024.12'!F19 -> 0 | F12: =F11+E12 -> 1.1677805 | G12: 8.357 | H12: =F12*G12 -> 9.7591418 | I12: =H12-D12 -> -0.20085825 | J12: =(H12-D12)/D12 -> -0.020166491 | K12: ='2024.12'!D29 -> 0 | L12: ='2024.12'!I29 -> 0 | M12: ='2024.12'!O29 -> 0 | AC12: ='2024.12'!$C$29 -> 0 | AD12: ='2024.12'!$E$29 -> 0.00 | AE12: ='2024.12'!$F$29 -> 0 | AF12: ='2026.07'!$A$25 -> 46224 | AG12: ='2026.07'!$B$25*-1 -> -100
A13: ='2025.01'!Q2 -> 2025.01 | B13: ='2025.01'!B29 -> 0 | C13: ='2025.01'!C29 -> 0 | D13: =D12+C13 -> 9.96 | E13: ='2025.01'!F29 -> 0 | F13: =F12+E13 -> 1.1677805 | G13: 8.898 | H13: =F13*G13 -> 10.390911 | I13: =H13-D13 -> 0.43091101 | J13: =(H13-D13)/D13 -> 0.043264158 | K13: ='2025.01'!D29 -> 0 | L13: ='2025.01'!I29 -> 0 | M13: ='2025.01'!O29 -> 0 | AC13: ='2025.01'!$C$29 -> 0 | AD13: ='2025.01'!$E$29 -> 0.00 | AE13: ='2025.01'!$F$29 -> 0 | AF13: ='2026.08'!$A$25 -> 46251 | AG13: ='2026.08'!$B$25*-1 -> -9.98
A14: ='2025.02'!Q2 -> 2025.02 | B14: ='2025.02'!B29 -> 0 | C14: ='2025.02'!C29 -> 0 | D14: =D13+C14 -> 9.96 | E14: ='2025.02'!F29 -> 0 | F14: =F13+E14 -> 1.1677805 | G14: 9.191 | H14: =F14*G14 -> 10.733071 | I14: =H14-D14 -> 0.7730707 | J14: =(H14-D14)/D14 -> 0.07761754 | K14: ='2025.02'!D29 -> 0 | L14: ='2025.02'!I29 -> 0 | M14: ='2025.02'!O29 -> 0 | AC14: ='2025.02'!$C$29 -> 0 | AD14: ='2025.02'!$E$29 -> 0.00 | AE14: ='2025.02'!$F$29 -> 0 | AF14: ='2026.09'!$A$25 -> 46275 | AG14: ='2026.09'!$B$25*-1 -> -9.99
A15: ='2025.03'!Q2 -> 2025.03 | B15: ='2025.03'!B29 -> 0 | C15: ='2025.03'!C29 -> 0 | D15: =D14+C15 -> 9.96 | E15: ='2025.03'!F29 -> 0 | F15: =F14+E15 -> 1.1677805 | G15: 8.788 | H15: =F15*G15 -> 10.262455 | I15: =H15-D15 -> 0.30245515 | J15: =(H15-D15)/D15 -> 0.030366983 | K15: ='2025.03'!D29 -> 0 | L15: ='2025.03'!I29 -> 0 | M15: ='2025.03'!O29 -> 0 | AC15: ='2025.03'!$C$29 -> 0 | AD15: ='2025.03'!$E$29 -> 0.00 | AE15: ='2025.03'!$F$29 -> 0
A16: ='2025.04'!Q2 -> 2025.04 | B16: ='2025.04'!B29 -> 0 | C16: ='2025.04'!C29 -> 0 | D16: =D15+C16 -> 9.96 | E16: ='2025.04'!F29 -> 0 | F16: =F15+E16 -> 1.1677805 | G16: 8.741 | H16: =F16*G16 -> 10.207569 | I16: =H16-D16 -> 0.24756947 | J16: =(H16-D16)/D16 -> 0.024856372 | K16: ='2025.04'!D29 -> 0 | L16: ='2025.04'!I29 -> 0 | M16: ='2025.04'!O29 -> 0 | AC16: ='2025.04'!$C$29 -> 0 | AD16: ='2025.04'!$E$29 -> 0.00 | AE16: ='2025.04'!$F$29 -> 0
A17: ='2025.05'!Q2 -> 2025.05 | B17: ='2025.05'!B29 -> 0 | C17: ='2025.05'!C29 -> 0 | D17: =D16+C17 -> 9.96 | E17: ='2025.05'!F29 -> 0 | F17: =F16+E17 -> 1.1677805 | G17: 9.131 | H17: =F17*G17 -> 10.663004 | I17: =H17-D17 -> 0.70300387 | J17: =(H17-D17)/D17 -> 0.070582718 | K17: ='2025.05'!D29 -> 0 | L17: ='2025.05'!I29 -> 0 | M17: ='2025.05'!O29 -> 0 | AC17: ='2025.05'!$C$29 -> 0 | AD17: ='2025.05'!$E$29 -> 0.00 | AE17: ='2025.05'!$F$29 -> 0
A18: ='2025.06'!Q2 -> 2025.06 | B18: ='2025.06'!B29 -> 0 | C18: ='2025.06'!C29 -> 0 | D18: =D17+C18 -> 9.96 | E18: ='2025.06'!F29 -> 0 | F18: =F17+E18 -> 1.1677805 | G18: 9.032 | H18: =F18*G18 -> 10.547394 | I18: =H18-D18 -> 0.5873936 | J18: =(H18-D18)/D18 -> 0.058975261 | K18: ='2025.06'!D29 -> 0 | L18: ='2025.06'!I29 -> 0 | M18: ='2025.06'!O29 -> 0 | AC18: ='2025.06'!$C$29 -> 0 | AD18: ='2025.06'!$E$29 -> 0.00 | AE18: ='2025.06'!$F$29 -> 0
A19: ='2025.07'!Q2 -> 2025.07 | B19: ='2025.07'!B29 -> 0 | C19: ='2025.07'!C29 -> 0 | D19: =D18+C19 -> 9.96 | E19: ='2025.07'!F29 -> 0 | F19: =F18+E19 -> 1.1677805 | G19: 9.119 | H19: =F19*G19 -> 10.648991 | I19: =H19-D19 -> 0.6889905 | J19: =(H19-D19)/D19 -> 0.069175753 | K19: ='2025.07'!D29 -> 0 | L19: ='2025.07'!I29 -> 0 | M19: ='2025.07'!O29 -> 0 | AC19: ='2025.07'!$C$29 -> 0 | AD19: ='2025.07'!$E$29 -> 0.00 | AE19: ='2025.07'!$F$29 -> 0
A20: ='2025.08'!Q2 -> 2025.08 | B20: ='2025.08'!B29 -> 0 | C20: ='2025.08'!C29 -> 0 | D20: =D19+C20 -> 9.96 | E20: ='2025.08'!F29 -> 0 | F20: =F19+E20 -> 1.1677805 | G20: 9.202 | H20: =F20*G20 -> 10.745916 | I20: =H20-D20 -> 0.78591629 | J20: =(H20-D20)/D20 -> 0.078907258 | K20: ='2025.08'!D29 -> 0 | L20: ='2025.08'!I29 -> 0 | M20: ='2025.08'!O29 -> 0 | AC20: ='2025.08'!$C$29 -> 0 | AD20: ='2025.08'!$E$29 -> 0.00 | AE20: ='2025.08'!$F$29 -> 0
A21: ='2025.09'!Q2 -> 2025.09 | B21: ='2025.09'!B29 -> 0 | C21: ='2025.09'!C29 -> 0 | D21: =D20+C21 -> 9.96 | E21: ='2025.09'!F29 -> 0 | F21: =F20+E21 -> 1.1677805 | G21: 9.334 | H21: =F21*G21 -> 10.900063 | I21: =H21-D21 -> 0.94006331 | J21: =(H21-D21)/D21 -> 0.094383867 | K21: ='2025.09'!D29 -> 0 | L21: ='2025.09'!I29 -> 0 | M21: ='2025.09'!O29 -> 0 | AC21: ='2025.09'!$C$29 -> 0 | AD21: ='2025.09'!$E$29 -> 0.00 | AE21: ='2025.09'!$F$29 -> 0
A22: ='2025.10'!Q2 -> 2025.1 | B22: ='2025.10'!B29 -> 0 | C22: ='2025.10'!C29 -> 0 | D22: =D21+C22 -> 9.96 | E22: ='2025.10'!F29 -> 0 | F22: =F21+E22 -> 1.1677805 | G22: 9.629 | H22: =F22*G22 -> 11.244559 | I22: =H22-D22 -> 1.2845586 | J22: =(H22-D22)/D22 -> 0.12897174 | K22: ='2025.10'!D29 -> 0 | L22: ='2025.10'!I29 -> 0 | M22: ='2025.10'!O29 -> 0 | AC22: ='2025.10'!$C$29 -> 0 | AD22: ='2025.10'!$E$29 -> 0.00 | AE22: ='2025.10'!$F$29 -> 0
A23: ='2025.11'!Q2 -> 2025.11 | B23: ='2025.11'!B29 -> 9.97 | C23: ='2025.11'!C29 -> 9.95 | D23: =D22+C23 -> 19.91 | E23: ='2025.11'!F29 -> 1.0543605 | F23: =F22+E23 -> 2.222141 | G23: 9.653 | H23: =F23*G23 -> 21.450327 | I23: =H23-D23 -> 1.5403272 | J23: =(H23-D23)/D23 -> 0.077364498 | K23: ='2025.11'!D29 -> 0.02 | L23: ='2025.11'!I29 -> 0 | M23: ='2025.11'!O29 -> 0 | AC23: ='2025.11'!$C$29 -> 9.95 | AD23: ='2025.11'!$E$29 -> 9.437 | AE23: ='2025.11'!$F$29 -> 1.0543605
A24: ='2025.12'!Q2 -> 2025.12 | B24: ='2025.12'!B29 -> 0 | C24: ='2025.12'!C29 -> 0 | D24: =D23+C24 -> 19.91 | E24: ='2025.12'!F29 -> 0 | F24: =F23+E24 -> 2.222141 | G24: 9.927 | H24: =F24*G24 -> 22.059194 | I24: =H24-D24 -> 2.1491938 | J24: =(H24-D24)/D24 -> 0.10794544 | K24: ='2025.12'!D29 -> 0 | L24: ='2025.12'!I29 -> 0 | M24: ='2025.12'!O29 -> 0 | AC24: ='2025.12'!$C$29 -> 0 | AD24: ='2025.12'!$E$29 -> 0.00 | AE24: ='2025.12'!$F$29 -> 0
A25: ='2026.01'!$Q$2 -> 2026.01 | B25: ='2026.01'!$B$29 -> 0 | C25: ='2026.01'!$C$29 -> 0 | D25: =D24+C25 -> 19.91 | E25: ='2026.01'!$F$29 -> 0 | F25: =F24+E25 -> 2.222141 | G25: 10.24 | H25: =F25*G25 -> 22.754724 | I25: =H25-D25 -> 2.8447239 | J25: =(H25-D25)/D25 -> 0.14287915 | K25: ='2026.01'!$D$29 -> 0 | L25: ='2026.01'!$I$29 -> 0 | M25: ='2026.01'!$O$29 -> 0 | AC25: ='2026.01'!$C$29 -> 0 | AD25: ='2026.01'!$E$29 -> 0.00 | AE25: ='2026.01'!$F$29 -> 0
A26: ='2026.02'!$Q$2 -> 2026.02 | B26: ='2026.02'!$B$29 -> 0 | C26: ='2026.02'!$C$29 -> 0 | D26: =D25+C26 -> 19.91 | E26: ='2026.02'!$F$29 -> 0 | F26: =F25+E26 -> 2.222141 | G26: 10.58 | H26: =F26*G26 -> 23.510252 | I26: =H26-D26 -> 3.6002519 | J26: =(H26-D26)/D26 -> 0.18082631 | K26: ='2026.02'!$D$29 -> 0 | L26: ='2026.02'!$I$29 -> 0 | M26: ='2026.02'!$O$29 -> 0 | AC26: ='2026.02'!$C$29 -> 0 | AD26: ='2026.02'!$E$29 -> 0.00 | AE26: ='2026.02'!$F$29 -> 0
A27: ='2026.03'!$Q$2 -> 2026.03 | B27: ='2026.03'!$B$29 -> 9.99 | C27: ='2026.03'!$C$29 -> 9.97 | D27: =D26+C27 -> 29.88 | E27: ='2026.03'!$F$29 -> 0.99441452 | F27: =F26+E27 -> 3.2165555 | G27: 9.741 | H27: =F27*G27 -> 31.332467 | I27: =H27-D27 -> 1.4524674 | J27: =(H27-D27)/D27 -> 0.048610021 | K27: ='2026.03'!$D$29 -> 0.02 | L27: ='2026.03'!$I$29 -> 0 | M27: ='2026.03'!$O$29 -> 0 | AC27: ='2026.03'!$C$29 -> 9.97 | AD27: ='2026.03'!$E$29 -> 10.026 | AE27: ='2026.03'!$F$29 -> 0.99441452
A28: ='2026.04'!$Q$2 -> 2026.04 | B28: ='2026.04'!$B$29 -> 9.99 | C28: ='2026.04'!$C$29 -> 9.99 | D28: =D27+C28 -> 39.87 | E28: ='2026.04'!$F$29 -> 0.95379034 | F28: =F27+E28 -> 4.1703459 | G28: 10.126 | H28: =F28*G28 -> 42.228922 | I28: =H28-D28 -> 2.3589223 | J28: =(H28-D28)/D28 -> 0.059165344 | K28: ='2026.04'!$D$29 -> 0 | L28: ='2026.04'!$I$29 -> 0 | M28: ='2026.04'!$O$29 -> 0 | AC28: ='2026.04'!$C$29 -> 9.99 | AD28: ='2026.04'!$E$29 -> 10.474 | AE28: ='2026.04'!$F$29 -> 0.95379034
A29: ='2026.05'!$Q$2 -> 2026.05 | B29: ='2026.05'!$B$29 -> 9.98 | C29: ='2026.05'!$C$29 -> 9.96 | D29: =D28+C29 -> 49.83 | E29: ='2026.05'!$F$29 -> 0.95898325 | F29: =F28+E29 -> 5.1293291 | G29: 10.64 | H29: =F29*G29 -> 54.576062 | I29: =H29-D29 -> 4.7460618 | J29: =(H29-D29)/D29 -> 0.095245069 | K29: ='2026.05'!$D$29 -> 0.02 | L29: ='2026.05'!$I$29 -> 0 | M29: ='2026.05'!$O$29 -> 0 | AC29: ='2026.05'!$C$29 -> 9.96 | AD29: ='2026.05'!$E$29 -> 10.386 | AE29: ='2026.05'!$F$29 -> 0.95898325
A30: ='2026.06'!$Q$2 -> 2026.06 | B30: ='2026.06'!$B$29 -> 219.9 | C30: ='2026.06'!$C$29 -> 219.35 | D30: =D29+C30 -> 269.18 | E30: ='2026.06'!$F$29 -> 20.154009 | F30: =F29+E30 -> 25.283338 | G30: 10.982 | H30: =F30*G30 -> 277.66162 | I30: =H30-D30 -> 8.4816191 | J30: =(H30-D30)/D30 -> 0.031509098 | K30: ='2026.06'!$D$29 -> 0.55 | L30: ='2026.06'!$I$29 -> 0 | M30: ='2026.06'!$O$29 -> 0 | AC30: ='2026.06'!$C$29 -> 219.35 | AD30: ='2026.06'!$E$29 -> 10.883691 | AE30: ='2026.06'!$F$29 -> 20.154009
A31: ='2026.07'!$Q$2 -> 2026.07 | B31: ='2026.07'!$B$29 -> 100 | C31: ='2026.07'!$C$29 -> 99.75 | D31: =D30+C31 -> 368.93 | E31: ='2026.07'!$F$29 -> 9.1513761 | F31: =F30+E31 -> 34.434714 | G31: 11.072 | H31: =F31*G31 -> 381.26116 | I31: =H31-D31 -> 12.331156 | J31: =(H31-D31)/D31 -> 0.033424108 | K31: ='2026.07'!$D$29 -> 0.25 | L31: ='2026.07'!$I$29 -> 0 | M31: ='2026.07'!$O$29 -> 0 | AC31: ='2026.07'!$C$29 -> 99.75 | AD31: ='2026.07'!$E$29 -> 10.9 | AE31: ='2026.07'!$F$29 -> 9.1513761
A32: ='2026.08'!$Q$2 -> 2026.08 | B32: ='2026.08'!$B$29 -> 9.98 | C32: ='2026.08'!$C$29 -> 9.96 | D32: =D31+C32 -> 378.89 | E32: ='2026.08'!$F$29 -> 0.89103596 | F32: =F31+E32 -> 35.32575 | G32: 11.116 | H32: =F32*G32 -> 392.68104 | I32: =H32-D32 -> 13.791039 | J32: =(H32-D32)/D32 -> 0.036398531 | K32: ='2026.08'!$D$29 -> 0.02 | L32: ='2026.08'!$I$29 -> 0 | M32: ='2026.08'!$O$29 -> 0 | AC32: ='2026.08'!$C$29 -> 9.96 | AD32: ='2026.08'!$E$29 -> 11.178 | AE32: ='2026.08'!$F$29 -> 0.89103596
A33: ='2026.09'!$Q$2 -> 2026.09 | B33: ='2026.09'!$B$29 -> 9.99 | C33: ='2026.09'!$C$29 -> 9.97 | D33: =D32+C33 -> 388.86 | E33: ='2026.09'!$F$29 -> 0.90340703 | F33: =F32+E33 -> 36.229157 | G33: 10.856 | H33: =F33*G33 -> 393.30373 | I33: =H33-D33 -> 4.4437311 | J33: =(H33-D33)/D33 -> 0.011427586 | K33: ='2026.09'!$D$29 -> 0.02 | L33: ='2026.09'!$I$29 -> 0 | M33: ='2026.09'!$O$29 -> 0 | AC33: ='2026.09'!$C$29 -> 9.97 | AD33: ='2026.09'!$E$29 -> 11.036 | AE33: ='2026.09'!$F$29 -> 0.90340703
AF200: =TODAY() -> 46296 | AG200: {=LOOKUP(2,1/(H:H>0),H:H)} -> 393.30373

Sheet AYEM
A1: AYEM GY iShares MSCI EM IMI ESG Screened
A3: Data | B3: Suma, EUR | E3: Kiekis | G3: Mėnesio gale | K3: Mokesčiai | M3: Dividendai | O3: AYEM | P3: Įnešta | Q3: Kiekis | R3: Parduota | S3: Pelnas | V3: Mokesčiai | X3: Dividendai | Y3: Vid. Kaina | AC3: Suma | AD3: Kaina | AE3: Kiekis | AF3: Pirkimas/pardavimas
B4: Įnešta | C4: Mėn. Inv. | D4: Viso Inv. | E4: Mėnesio | F4: Viso | G4: Kaina | H4: Vertė gale | I4: Pelnas | J4: % | K4: Pirkimas | L4: Pardavimas | S4: Eur. | T4: % | U4: XIRR | V4: Pirkimas | W4: Pardavimas | AF4: Data | AG4: Suma
A5: ='2024.05'!Q2 -> 2024.05 | B5: ='2024.05'!B39 -> 9.99 | C5: ='2024.05'!C39 -> 9.97 | D5: =C5 -> 9.97 | E5: ='2024.05'!F39 -> 1.6581017 | F5: =E5 -> 1.6581017 | G5: 5.808 | H5: =F5*G5 -> 9.630255 | I5: =H5-D5 -> -0.33974505 | J5: =(H5-D5)/D5 -> -0.034076735 | K5: ='2024.05'!D39 -> 0.02 | L5: ='2024.05'!I39 -> 0 | M5: ='2024.05'!O39 -> 0 | O5: Viso: | P5: =SUM(B5:B500) -> 367.72 | Q5: =SUM(E5:E500) -> 43.480738 | S5: =R5-P5+X5 -> -367.72 | T5: =(R5-P5+X5)/P5 -> -1 | U5: =XIRR(AG5:AG200,AF5:AF200) -> 0.21358649 | V5: =SUM(K5:K500) -> 0.84 | W5: =SUM(L5:L500) -> 0 | X5: =SUM(M5:M500) -> 0 | Y5: {=SUMPRODUCT(IFERROR(AD5:AD200,0),IFERROR(AE5:AE200,0))/SUM(IFERROR(AE5:AE200,0))} -> 8.4377593 | AC5: ='2024.05'!$C$39 -> 9.97 | AD5: ='2024.05'!$E$39 -> 6.0129 | AE5: ='2024.05'!$F$39 -> 1.6581017 | AF5: ='2024.05'!$A$35 -> 45442 | AG5: ='2024.05'!$B$35*-1 -> -9.99
A6: ='2024.06'!Q2 -> 2024.06 | B6: ='2024.06'!B39 -> 0 | C6: ='2024.06'!C39 -> 0 | D6: =D5+C6 -> 9.97 | E6: ='2024.06'!F39 -> 0 | F6: =F5+E6 -> 1.6581017 | G6: 6.128 | H6: =F6*G6 -> 10.160848 | I6: =H6-D6 -> 0.19084751 | J6: =(H6-D6)/D6 -> 0.019142178 | K6: ='2024.06'!D39 -> 0 | L6: ='2024.06'!I39 -> 0 | M6: ='2024.06'!O39 -> 0 | AC6: ='2024.06'!$C$39 -> 0 | AD6: ='2024.06'!$E$39 -> 0.00 | AE6: ='2024.06'!$F$39 -> 0 | AF6: ='2025.11'!$A$35 -> 45974 | AG6: ='2025.11'!$B$35*-1 -> -62.23
A7: ='2024.07'!Q2 -> 2024.07 | B7: ='2024.07'!B39 -> 0 | C7: ='2024.07'!C39 -> 0 | D7: =D6+C7 -> 9.97 | E7: ='2024.07'!F39 -> 0 | F7: =F6+E7 -> 1.6581017 | G7: 6.115 | H7: =F7*G7 -> 10.139292 | I7: =H7-D7 -> 0.16929219 | J7: =(H7-D7)/D7 -> 0.016980159 | K7: ='2024.07'!D39 -> 0 | L7: ='2024.07'!I39 -> 0 | M7: ='2024.07'!O39 -> 0 | AC7: ='2024.07'!$C$39 -> 0 | AD7: ='2024.07'!$E$39 -> 0.00 | AE7: ='2024.07'!$F$39 -> 0 | AF7: ='2025.11'!$A$36 -> 45988 | AG7: ='2025.11'!$B$36*-1 -> -15.59
A8: ='2024.08'!Q2 -> 2024.08 | B8: ='2024.08'!B39 -> 0 | C8: ='2024.08'!C39 -> 0 | D8: =D7+C8 -> 9.97 | E8: ='2024.08'!F39 -> 0 | F8: =F7+E8 -> 1.6581017 | G8: 6.041 | H8: =F8*G8 -> 10.016593 | I8: =H8-D8 -> 0.046592659 | J8: =(H8-D8)/D8 -> 0.0046732858 | K8: ='2024.08'!D39 -> 0 | L8: ='2024.08'!I39 -> 0 | M8: ='2024.08'!O39 -> 0 | AC8: ='2024.08'!$C$39 -> 0 | AD8: ='2024.08'!$E$39 -> 0.00 | AE8: ='2024.08'!$F$39 -> 0 | AF8: ='2026.01'!$A$35 -> 46030 | AG8: ='2026.01'!$B$35*-1 -> -9.99
A9: ='2024.09'!Q2 -> 2024.09 | B9: ='2024.09'!B39 -> 0 | C9: ='2024.09'!C39 -> 0 | D9: =D8+C9 -> 9.97 | E9: ='2024.09'!F39 -> 0 | F9: =F8+E9 -> 1.6581017 | G9: 6.35 | H9: =F9*G9 -> 10.528946 | I9: =H9-D9 -> 0.5589461 | J9: =(H9-D9)/D9 -> 0.056062798 | K9: ='2024.09'!D39 -> 0 | L9: ='2024.09'!I39 -> 0 | M9: ='2024.09'!O39 -> 0 | AC9: ='2024.09'!$C$39 -> 0 | AD9: ='2024.09'!$E$39 -> 0.00 | AE9: ='2024.09'!$F$39 -> 0 | AF9: ='2026.02'!$A$35 -> 46030 | AG9: ='2026.02'!$B$35*-1 -> -9.99
A10: ='2024.10'!Q2 -> 2024.1 | B10: ='2024.10'!B39 -> 0 | C10: ='2024.10'!C39 -> 0 | D10: =D9+C10 -> 9.97 | E10: ='2024.10'!F39 -> 0 | F10: =F9+E10 -> 1.6581017 | G10: 6.224 | H10: =F10*G10 -> 10.320025 | I10: =H10-D10 -> 0.35002528 | J10: =(H10-D10)/D10 -> 0.035107851 | K10: ='2024.10'!D39 -> 0 | L10: ='2024.10'!I39 -> 0 | M10: ='2024.10'!O39 -> 0 | AC10: ='2024.10'!$C$39 -> 0 | AD10: ='2024.10'!$E$39 -> 0.00 | AE10: ='2024.10'!$F$39 -> 0 | AF10: ='2026.03'!$A$35 -> 46100 | AG10: ='2026.03'!$B$35*-1 -> -9.99
A11: ='2024.11'!Q2 -> 2024.11 | B11: ='2024.11'!B39 -> 0 | C11: ='2024.11'!C39 -> 0 | D11: =D10+C11 -> 9.97 | E11: ='2024.11'!F39 -> 0 | F11: =F10+E11 -> 1.6581017 | G11: 6.275 | H11: =F11*G11 -> 10.404588 | I11: =H11-D11 -> 0.43458847 | J11: =(H11-D11)/D11 -> 0.043589616 | K11: ='2024.11'!D39 -> 0 | L11: ='2024.11'!I39 -> 0 | M11: ='2024.11'!O39 -> 0 | AC11: ='2024.11'!$C$39 -> 0 | AD11: ='2024.11'!$E$39 -> 0.00 | AE11: ='2024.11'!$F$39 -> 0 | AF11: ='2026.04'!$A$35 -> 46133 | AG11: ='2026.04'!$B$35*-1 -> -20
A12: ='2024.12'!Q2 -> 2024.12 | B12: ='2024.12'!B39 -> 0 | C12: ='2024.12'!C39 -> 0 | D12: =D11+C12 -> 9.97 | E12: ='2024.12'!F39 -> 0 | F12: =F11+E12 -> 1.6581017 | G12: 6.255 | H12: =F12*G12 -> 10.371426 | I12: =H12-D12 -> 0.40142643 | J12: =(H12-D12)/D12 -> 0.040263434 | K12: ='2024.12'!D39 -> 0 | L12: ='2024.12'!I39 -> 0 | M12: ='2024.12'!O39 -> 0 | AC12: ='2024.12'!$C$39 -> 0 | AD12: ='2024.12'!$E$39 -> 0.00 | AE12: ='2024.12'!$F$39 -> 0 | AF12: ='2026.05'!$A$35 -> 46162 | AG12: ='2026.05'!$B$35*-1 -> -9.98
A13: ='2025.01'!Q2 -> 2025.01 | B13: ='2025.01'!B39 -> 0 | C13: ='2025.01'!C39 -> 0 | D13: =D12+C13 -> 9.97 | E13: ='2025.01'!F39 -> 0 | F13: =F12+E13 -> 1.6581017 | G13: 6.471 | H13: =F13*G13 -> 10.729576 | I13: =H13-D13 -> 0.75957641 | J13: =(H13-D13)/D13 -> 0.0761862 | K13: ='2025.01'!D39 -> 0 | L13: ='2025.01'!I39 -> 0 | M13: ='2025.01'!O39 -> 0 | AC13: ='2025.01'!$C$39 -> 0 | AD13: ='2025.01'!$E$39 -> 0.00 | AE13: ='2025.01'!$F$39 -> 0 | AF13: ='2026.06'!$A$35 -> 46203 | AG13: ='2026.06'!$B$35*-1 -> -100
A14: ='2025.02'!Q2 -> 2025.02 | B14: ='2025.02'!B39 -> 0 | C14: ='2025.02'!C39 -> 0 | D14: =D13+C14 -> 9.97 | E14: ='2025.02'!F39 -> 0 | F14: =F13+E14 -> 1.6581017 | G14: 6.406 | H14: =F14*G14 -> 10.6218 | I14: =H14-D14 -> 0.6517998 | J14: =(H14-D14)/D14 -> 0.065376108 | K14: ='2025.02'!D39 -> 0 | L14: ='2025.02'!I39 -> 0 | M14: ='2025.02'!O39 -> 0 | AC14: ='2025.02'!$C$39 -> 0 | AD14: ='2025.02'!$E$39 -> 0.00 | AE14: ='2025.02'!$F$39 -> 0 | AF14: ='2026.07'!$A$35 -> 46224 | AG14: ='2026.07'!$B$35*-1 -> -100
A15: ='2025.03'!Q2 -> 2025.03 | B15: ='2025.03'!B39 -> 0 | C15: ='2025.03'!C39 -> 0 | D15: =D14+C15 -> 9.97 | E15: ='2025.03'!F39 -> 0 | F15: =F14+E15 -> 1.6581017 | G15: 6.181 | H15: =F15*G15 -> 10.248727 | I15: =H15-D15 -> 0.2787269 | J15: =(H15-D15)/D15 -> 0.02795656 | K15: ='2025.03'!D39 -> 0 | L15: ='2025.03'!I39 -> 0 | M15: ='2025.03'!O39 -> 0 | AC15: ='2025.03'!$C$39 -> 0 | AD15: ='2025.03'!$E$39 -> 0.00 | AE15: ='2025.03'!$F$39 -> 0 | AF15: ='2026.08'!$A$35 -> 46251 | AG15: ='2026.08'!$B$35*-1 -> -9.98
A16: ='2025.04'!Q2 -> 2025.04 | B16: ='2025.04'!B39 -> 0 | C16: ='2025.04'!C39 -> 0 | D16: =D15+C16 -> 9.97 | E16: ='2025.04'!F39 -> 0 | F16: =F15+E16 -> 1.6581017 | G16: 5.961 | H16: =F16*G16 -> 9.8839445 | I16: =H16-D16 -> -0.086055481 | J16: =(H16-D16)/D16 -> -0.0086314424 | K16: ='2025.04'!D39 -> 0 | L16: ='2025.04'!I39 -> 0 | M16: ='2025.04'!O39 -> 0 | AC16: ='2025.04'!$C$39 -> 0 | AD16: ='2025.04'!$E$39 -> 0.00 | AE16: ='2025.04'!$F$39 -> 0 | AF16: ='2026.09'!$A$35 -> 46275 | AG16: ='2026.09'!$B$35*-1 -> -9.98
A17: ='2025.05'!Q2 -> 2025.05 | B17: ='2025.05'!B39 -> 0 | C17: ='2025.05'!C39 -> 0 | D17: =D16+C17 -> 9.97 | E17: ='2025.05'!F39 -> 0 | F17: =F16+E17 -> 1.6581017 | G17: 6.237 | H17: =F17*G17 -> 10.341581 | I17: =H17-D17 -> 0.3715806 | J17: =(H17-D17)/D17 -> 0.03726987 | K17: ='2025.05'!D39 -> 0 | L17: ='2025.05'!I39 -> 0 | M17: ='2025.05'!O39 -> 0 | AC17: ='2025.05'!$C$39 -> 0 | AD17: ='2025.05'!$E$39 -> 0.00 | AE17: ='2025.05'!$F$39 -> 0
A18: ='2025.06'!Q2 -> 2025.06 | B18: ='2025.06'!B39 -> 0 | C18: ='2025.06'!C39 -> 0 | D18: =D17+C18 -> 9.97 | E18: ='2025.06'!F39 -> 0 | F18: =F17+E18 -> 1.6581017 | G18: 6.424 | H18: =F18*G18 -> 10.651646 | I18: =H18-D18 -> 0.68164563 | J18: =(H18-D18)/D18 -> 0.068369672 | K18: ='2025.06'!D39 -> 0 | L18: ='2025.06'!I39 -> 0 | M18: ='2025.06'!O39 -> 0 | AC18: ='2025.06'!$C$39 -> 0 | AD18: ='2025.06'!$E$39 -> 0.00 | AE18: ='2025.06'!$F$39 -> 0
A19: ='2025.07'!Q2 -> 2025.07 | B19: ='2025.07'!B39 -> 0 | C19: ='2025.07'!C39 -> 0 | D19: =D18+C19 -> 9.97 | E19: ='2025.07'!F39 -> 0 | F19: =F18+E19 -> 1.6581017 | G19: 6.688 | H19: =F19*G19 -> 11.089384 | I19: =H19-D19 -> 1.1193845 | J19: =(H19-D19)/D19 -> 0.11227527 | K19: ='2025.07'!D39 -> 0 | L19: ='2025.07'!I39 -> 0 | M19: ='2025.07'!O39 -> 0 | AC19: ='2025.07'!$C$39 -> 0 | AD19: ='2025.07'!$E$39 -> 0.00 | AE19: ='2025.07'!$F$39 -> 0
A20: ='2025.08'!Q2 -> 2025.08 | B20: ='2025.08'!B39 -> 0 | C20: ='2025.08'!C39 -> 0 | D20: =D19+C20 -> 9.97 | E20: ='2025.08'!F39 -> 0 | F20: =F19+E20 -> 1.6581017 | G20: 6.672 | H20: =F20*G20 -> 11.062855 | I20: =H20-D20 -> 1.0928549 | J20: =(H20-D20)/D20 -> 0.10961433 | K20: ='2025.08'!D39 -> 0 | L20: ='2025.08'!I39 -> 0 | M20: ='2025.08'!O39 -> 0 | AC20: ='2025.08'!$C$39 -> 0 | AD20: ='2025.08'!$E$39 -> 0.00 | AE20: ='2025.08'!$F$39 -> 0
A21: ='2025.09'!Q2 -> 2025.09 | B21: ='2025.09'!B39 -> 0 | C21: ='2025.09'!C39 -> 0 | D21: =D20+C21 -> 9.97 | E21: ='2025.09'!F39 -> 0 | F21: =F20+E21 -> 1.6581017 | G21: 7.035 | H21: =F21*G21 -> 11.664746 | I21: =H21-D21 -> 1.6947458 | J21: =(H21-D21)/D21 -> 0.16998453 | K21: ='2025.09'!D39 -> 0 | L21: ='2025.09'!I39 -> 0 | M21: ='2025.09'!O39 -> 0 | AC21: ='2025.09'!$C$39 -> 0 | AD21: ='2025.09'!$E$39 -> 0.00 | AE21: ='2025.09'!$F$39 -> 0
A22: ='2025.10'!Q2 -> 2025.1 | B22: ='2025.10'!B39 -> 0 | C22: ='2025.10'!C39 -> 0 | D22: =D21+C22 -> 9.97 | E22: ='2025.10'!F39 -> 0 | F22: =F21+E22 -> 1.6581017 | G22: 7.432 | H22: =F22*G22 -> 12.323012 | I22: =H22-D22 -> 2.3530122 | J22: =(H22-D22)/D22 -> 0.23600925 | K22: ='2025.10'!D39 -> 0 | L22: ='2025.10'!I39 -> 0 | M22: ='2025.10'!O39 -> 0 | AC22: ='2025.10'!$C$39 -> 0 | AD22: ='2025.10'!$E$39 -> 0.00 | AE22: ='2025.10'!$F$39 -> 0
A23: ='2025.11'!Q2 -> 2025.11 | B23: ='2025.11'!B39 -> 77.82 | C23: ='2025.11'!C39 -> 77.62 | D23: =D22+C23 -> 87.59 | E23: ='2025.11'!F39 -> 10.554887 | F23: =F22+E23 -> 12.212988 | G23: 7.313 | H23: =F23*G23 -> 89.313584 | I23: =H23-D23 -> 1.7235835 | J23: =(H23-D23)/D23 -> 0.019677857 | K23: ='2025.11'!D39 -> 0.2 | L23: ='2025.11'!I39 -> 0 | M23: ='2025.11'!O39 -> 0 | AC23: ='2025.11'!$C$39 -> 77.62 | AD23: ='2025.11'!$E$39 -> 7.3539398 | AE23: ='2025.11'!$F$39 -> 10.554887
A24: ='2025.12'!Q2 -> 2025.12 | B24: ='2025.12'!B39 -> 0 | C24: ='2025.12'!C39 -> 0 | D24: =D23+C24 -> 87.59 | E24: ='2025.12'!F39 -> 0 | F24: =F23+E24 -> 12.212988 | G24: 7.35 | H24: =F24*G24 -> 89.765464 | I24: =H24-D24 -> 2.1754641 | J24: =(H24-D24)/D24 -> 0.0248369 | K24: ='2025.12'!D39 -> 0 | L24: ='2025.12'!I39 -> 0 | M24: ='2025.12'!O39 -> 0 | AC24: ='2025.12'!$C$39 -> 0 | AD24: ='2025.12'!$E$39 -> 0.00 | AE24: ='2025.12'!$F$39 -> 0
A25: ='2026.01'!$Q$2 -> 2026.01 | B25: ='2026.01'!$B$39 -> 9.99 | C25: ='2026.01'!$C$39 -> 9.97 | D25: =D24+C25 -> 97.56 | E25: ='2026.01'!$F$39 -> 1.2985152 | F25: =F24+E25 -> 13.511504 | G25: 7.891 | H25: =F25*G25 -> 106.61927 | I25: =H25-D25 -> 9.0592745 | J25: =(H25-D25)/D25 -> 0.092858492 | K25: ='2026.01'!$D$39 -> 0.02 | L25: ='2026.01'!$I$39 -> 0 | M25: ='2026.01'!$O$39 -> 0 | AC25: ='2026.01'!$C$39 -> 9.97 | AD25: ='2026.01'!$E$39 -> 7.678 | AE25: ='2026.01'!$F$39 -> 1.2985152
A26: ='2026.02'!$Q$2 -> 2026.02 | B26: ='2026.02'!$B$39 -> 9.99 | C26: ='2026.02'!$C$39 -> 9.97 | D26: =D25+C26 -> 107.53 | E26: ='2026.02'!$F$39 -> 1.2272884 | F26: =F25+E26 -> 14.738792 | G26: 8.392 | H26: =F26*G26 -> 123.68794 | I26: =H26-D26 -> 16.157942 | J26: =(H26-D26)/D26 -> 0.1502645 | K26: ='2026.02'!$D$39 -> 0.02 | L26: ='2026.02'!$I$39 -> 0 | M26: ='2026.02'!$O$39 -> 0 | AC26: ='2026.02'!$C$39 -> 9.97 | AD26: ='2026.02'!$E$39 -> 8.1236 | AE26: ='2026.02'!$F$39 -> 1.2272884
A27: ='2026.03'!$Q$2 -> 2026.03 | B27: ='2026.03'!$B$39 -> 9.99 | C27: ='2026.03'!$C$39 -> 9.97 | D27: =D26+C27 -> 117.5 | E27: ='2026.03'!$F$39 -> 1.2542458 | F27: =F26+E27 -> 15.993038 | G27: 7.516 | H27: =F27*G27 -> 120.20367 | I27: =H27-D27 -> 2.7036718 | J27: =(H27-D27)/D27 -> 0.023009973 | K27: ='2026.03'!$D$39 -> 0.02 | L27: ='2026.03'!$I$39 -> 0 | M27: ='2026.03'!$O$39 -> 0 | AC27: ='2026.03'!$C$39 -> 9.97 | AD27: ='2026.03'!$E$39 -> 7.949 | AE27: ='2026.03'!$F$39 -> 1.2542458
A28: ='2026.04'!$Q$2 -> 2026.04 | B28: ='2026.04'!$B$39 -> 20 | C28: ='2026.04'!$C$39 -> 20 | D28: =D27+C28 -> 137.5 | E28: ='2026.04'!$F$39 -> 2.3703423 | F28: =F27+E28 -> 18.36338 | G28: 8.424 | H28: =F28*G28 -> 154.69311 | I28: =H28-D28 -> 17.193113 | J28: =(H28-D28)/D28 -> 0.12504083 | K28: ='2026.04'!$D$39 -> 0 | L28: ='2026.04'!$I$39 -> 0 | M28: ='2026.04'!$O$39 -> 0 | AC28: ='2026.04'!$C$39 -> 20 | AD28: ='2026.04'!$E$39 -> 8.4376 | AE28: ='2026.04'!$F$39 -> 2.3703423
A29: ='2026.05'!$Q$2 -> 2026.05 | B29: ='2026.05'!$B$39 -> 9.98 | C29: ='2026.05'!$C$39 -> 9.96 | D29: =D28+C29 -> 147.46 | E29: ='2026.05'!$F$39 -> 1.1489214 | F29: =F28+E29 -> 19.512301 | G29: 9.24 | H29: =F29*G29 -> 180.29367 | I29: =H29-D29 -> 32.833666 | J29: =(H29-D29)/D29 -> 0.22266151 | K29: ='2026.05'!$D$39 -> 0.02 | L29: ='2026.05'!$I$39 -> 0 | M29: ='2026.05'!$O$39 -> 0 | AC29: ='2026.05'!$C$39 -> 9.96 | AD29: ='2026.05'!$E$39 -> 8.669 | AE29: ='2026.05'!$F$39 -> 1.1489214
A30: ='2026.06'!$Q$2 -> 2026.06 | B30: ='2026.06'!$B$39 -> 100 | C30: ='2026.06'!$C$39 -> 99.75 | D30: =D29+C30 -> 247.21 | E30: ='2026.06'!$F$39 -> 10.646019 | F30: =F29+E30 -> 30.15832 | G30: 9.436 | H30: =F30*G30 -> 284.57391 | I30: =H30-D30 -> 37.363908 | J30: =(H30-D30)/D30 -> 0.15114238 | K30: ='2026.06'!$D$39 -> 0.25 | L30: ='2026.06'!$I$39 -> 0 | M30: ='2026.06'!$O$39 -> 0 | AC30: ='2026.06'!$C$39 -> 99.75 | AD30: ='2026.06'!$E$39 -> 9.3697 | AE30: ='2026.06'!$F$39 -> 10.646019
A31: ='2026.07'!$Q$2 -> 2026.07 | B31: ='2026.07'!$B$39 -> 100 | C31: ='2026.07'!$C$39 -> 99.75 | D31: =D30+C31 -> 346.96 | E31: ='2026.07'!$F$39 -> 11.139028 | F31: =F30+E31 -> 41.297349 | G31: 8.602 | H31: =F31*G31 -> 355.23979 | I31: =H31-D31 -> 8.2797919 | J31: =(H31-D31)/D31 -> 0.023863823 | K31: ='2026.07'!$D$39 -> 0.25 | L31: ='2026.07'!$I$39 -> 0 | M31: ='2026.07'!$O$39 -> 0 | AC31: ='2026.07'!$C$39 -> 99.75 | AD31: ='2026.07'!$E$39 -> 8.955 | AE31: ='2026.07'!$F$39 -> 11.139028
A32: ='2026.08'!$Q$2 -> 2026.08 | B32: ='2026.08'!$B$39 -> 9.98 | C32: ='2026.08'!$C$39 -> 9.96 | D32: =D31+C32 -> 356.92 | E32: ='2026.08'!$F$39 -> 1.1075281 | F32: =F31+E32 -> 42.404877 | G32: 9.095 | H32: =F32*G32 -> 385.67235 | I32: =H32-D32 -> 28.752353 | J32: =(H32-D32)/D32 -> 0.080556855 | K32: ='2026.08'!$D$39 -> 0.02 | L32: ='2026.08'!$I$39 -> 0 | M32: ='2026.08'!$O$39 -> 0 | AC32: ='2026.08'!$C$39 -> 9.96 | AD32: ='2026.08'!$E$39 -> 8.993 | AE32: ='2026.08'!$F$39 -> 1.1075281
A33: ='2026.09'!$Q$2 -> 2026.09 | B33: ='2026.09'!$B$39 -> 9.98 | C33: ='2026.09'!$C$39 -> 9.96 | D33: =D32+C33 -> 366.88 | E33: ='2026.09'!$F$39 -> 1.0758612 | F33: =F32+E33 -> 43.480738 | G33: 9.286 | H33: =F33*G33 -> 403.76213 | I33: =H33-D33 -> 36.882131 | J33: =(H33-D33)/D33 -> 0.10052914 | K33: ='2026.09'!$D$39 -> 0.02 | L33: ='2026.09'!$I$39 -> 0 | M33: ='2026.09'!$O$39 -> 0 | AC33: ='2026.09'!$C$39 -> 9.96 | AD33: ='2026.09'!$E$39 -> 9.2577 | AE33: ='2026.09'!$F$39 -> 1.0758612
AF200: =TODAY() -> 46296 | AG200: {=LOOKUP(2,1/(H:H>0),H:H)} -> 403.76213

Sheet SGAJ
A1: SGAJ GY iShares MSCI Japan ESG Screened
A3: Data | B3: Suma, EUR | E3: Kiekis | G3: Mėnesio gale | K3: Mokesčiai | M3: Dividendai | O3: SGAJ | P3: Įnešta | Q3: Kiekis | R3: Parduota | S3: Pelnas | V3: Mokesčiai | X3: Dividendai | Y3: Vid. Kaina | AC3: Suma | AD3: Kaina | AE3: Kiekis | AF3: Pirkimas/pardavimas
B4: Įnešta | C4: Mėn. Inv. | D4: Viso Inv. | E4: Mėnesio | F4: Viso | G4: Kaina | H4: Vertė gale | I4: Pelnas | J4: % | K4: Pirkimas | L4: Pardavimas | S4: Eur. | T4: % | U4: XIRR | V4: Pirkimas | W4: Pardavimas | AF4: Data | AG4: Suma
A5: ='2024.06'!Q2 -> 2024.06 | B5: ='2024.06'!B49 -> 9.98 | C5: ='2024.06'!C49 -> 9.96 | D5: =C5 -> 9.96 | E5: ='2024.06'!F49 -> 1.619 | F5: =E5 -> 1.619 | G5: 6.207 | H5: =F5*G5 -> 10.049133 | I5: =H5-D5 -> 0.089133 | J5: =(H5-D5)/D5 -> 0.0089490964 | K5: ='2024.06'!D49 -> 0.02 | L5: ='2024.06'!I49 -> 0 | M5: ='2024.06'!O49 -> 0 | O5: Viso: | P5: =SUM(B5:B500) -> 369.38 | Q5: =SUM(E5:E500) -> 44.640072 | S5: =R5-P5+X5 -> -369.38 | T5: =(R5-P5+X5)/P5 -> -1 | U5: =XIRR(AG5:AG200,AF5:AF200) -> 0.28066184 | V5: =SUM(K5:K500) -> 0.87 | W5: =SUM(L5:L500) -> 0 | X5: =SUM(M5:M500) -> 0 | Y5: {=SUMPRODUCT(IFERROR(AD5:AD200,0),IFERROR(AE5:AE200,0))/SUM(IFERROR(AE5:AE200,0))} -> 8.2552498 | AC5: ='2024.06'!$C$49 -> 9.96 | AD5: ='2024.06'!$E$49 -> 6.155 | AE5: ='2024.06'!$F$49 -> 1.619 | AF5: ='2024.06'!$A$45 -> 45449 | AG5: ='2024.06'!$B$45*-1 -> -9.98
A6: ='2024.07'!Q2 -> 2024.07 | B6: ='2024.07'!B49 -> 0 | C6: ='2024.07'!C49 -> 0 | D6: =D5+C6 -> 9.96 | E6: ='2024.07'!F49 -> 0 | F6: =F5+E6 -> 1.619 | G6: 6.365 | H6: =F6*G6 -> 10.304935 | I6: =H6-D6 -> 0.344935 | J6: =(H6-D6)/D6 -> 0.034632028 | K6: ='2024.07'!D49 -> 0 | L6: ='2024.07'!I49 -> 0 | M6: ='2024.07'!O49 -> 0 | AC6: ='2024.07'!$C$49 -> 0 | AD6: ='2024.07'!$E$49 -> 0.00 | AE6: ='2024.07'!$F$49 -> 0 | AF6: ='2025.11'!$A$45 -> 45988 | AG6: ='2025.11'!$B$45*-1 -> -9.97
A7: ='2024.08'!Q2 -> 2024.08 | B7: ='2024.08'!B49 -> 0 | C7: ='2024.08'!C49 -> 0 | D7: =D6+C7 -> 9.96 | E7: ='2024.08'!F49 -> 0 | F7: =F6+E7 -> 1.619 | G7: 6.305 | H7: =F7*G7 -> 10.207795 | I7: =H7-D7 -> 0.247795 | J7: =(H7-D7)/D7 -> 0.024879016 | K7: ='2024.08'!D49 -> 0 | L7: ='2024.08'!I49 -> 0 | M7: ='2024.08'!O49 -> 0 | AC7: ='2024.08'!$C$49 -> 0 | AD7: ='2024.08'!$E$49 -> 0.00 | AE7: ='2024.08'!$F$49 -> 0 | AF7: ='2026.03'!$A$45 -> 46100 | AG7: ='2026.03'!$B$45*-1 -> -9.99
A8: ='2024.09'!Q2 -> 2024.09 | B8: ='2024.09'!B49 -> 0 | C8: ='2024.09'!C49 -> 0 | D8: =D7+C8 -> 9.96 | E8: ='2024.09'!F49 -> 0 | F8: =F7+E8 -> 1.619 | G8: 6.225 | H8: =F8*G8 -> 10.078275 | I8: =H8-D8 -> 0.118275 | J8: =(H8-D8)/D8 -> 0.011875 | K8: ='2024.09'!D49 -> 0 | L8: ='2024.09'!I49 -> 0 | M8: ='2024.09'!O49 -> 0 | AC8: ='2024.09'!$C$49 -> 0 | AD8: ='2024.09'!$E$49 -> 0.00 | AE8: ='2024.09'!$F$49 -> 0 | AF8: ='2026.04'!$A$45 -> 46133 | AG8: ='2026.04'!$B$45*-1 -> -9.99
A9: ='2024.10'!Q2 -> 2024.1 | B9: ='2024.10'!B49 -> 0 | C9: ='2024.10'!C49 -> 0 | D9: =D8+C9 -> 9.96 | E9: ='2024.10'!F49 -> 0 | F9: =F8+E9 -> 1.619 | G9: 6.039 | H9: =F9*G9 -> 9.777141 | I9: =H9-D9 -> -0.182859 | J9: =(H9-D9)/D9 -> -0.018359337 | K9: ='2024.10'!D49 -> 0 | L9: ='2024.10'!I49 -> 0 | M9: ='2024.10'!O49 -> 0 | AC9: ='2024.10'!$C$49 -> 0 | AD9: ='2024.10'!$E$49 -> 0.00 | AE9: ='2024.10'!$F$49 -> 0 | AF9: ='2026.05'!$A$45 -> 46162 | AG9: ='2026.05'!$B$45*-1 -> -9.96
A10: ='2024.11'!Q2 -> 2024.11 | B10: ='2024.11'!B49 -> 0 | C10: ='2024.11'!C49 -> 0 | D10: =D9+C10 -> 9.96 | E10: ='2024.11'!F49 -> 0 | F10: =F9+E10 -> 1.619 | G10: 6.361 | H10: =F10*G10 -> 10.298459 | I10: =H10-D10 -> 0.338459 | J10: =(H10-D10)/D10 -> 0.033981827 | K10: ='2024.11'!D49 -> 0 | L10: ='2024.11'!I49 -> 0 | M10: ='2024.11'!O49 -> 0 | AC10: ='2024.11'!$C$49 -> 0 | AD10: ='2024.11'!$E$49 -> 0.00 | AE10: ='2024.11'!$F$49 -> 0 | AF10: ='2026.06'!$A$45 -> 46198 | AG10: ='2026.06'!$B$45*-1 -> -99.54
A11: ='2024.12'!Q2 -> 2024.12 | B11: ='2024.12'!B49 -> 0 | C11: ='2024.12'!C49 -> 0 | D11: =D10+C11 -> 9.96 | E11: ='2024.12'!F49 -> 0 | F11: =F10+E11 -> 1.619 | G11: 6.35 | H11: =F11*G11 -> 10.28065 | I11: =H11-D11 -> 0.32065 | J11: =(H11-D11)/D11 -> 0.032193775 | K11: ='2024.12'!D49 -> 0 | L11: ='2024.12'!I49 -> 0 | M11: ='2024.12'!O49 -> 0 | AC11: ='2024.12'!$C$49 -> 0 | AD11: ='2024.12'!$E$49 -> 0.00 | AE11: ='2024.12'!$F$49 -> 0 | AF11: ='2026.06'!$A$46 -> 46203 | AG11: ='2026.06'!$B$46*-1 -> -100
A12: ='2025.01'!Q2 -> 2025.01 | B12: ='2025.01'!B49 -> 0 | C12: ='2025.01'!C49 -> 0 | D12: =D11+C12 -> 9.96 | E12: ='2025.01'!F49 -> 0 | F12: =F11+E12 -> 1.619 | G12: 6.549 | H12: =F12*G12 -> 10.602831 | I12: =H12-D12 -> 0.642831 | J12: =(H12-D12)/D12 -> 0.064541265 | K12: ='2025.01'!D49 -> 0 | L12: ='2025.01'!I49 -> 0 | M12: ='2025.01'!O49 -> 0 | AC12: ='2025.01'!$C$49 -> 0 | AD12: ='2025.01'!$E$49 -> 0.00 | AE12: ='2025.01'!$F$49 -> 0 | AF12: ='2026.07'!$A$45 -> 46224 | AG12: ='2026.07'!$B$45*-1 -> -100
A13: ='2025.02'!Q2 -> 2025.02 | B13: ='2025.02'!B49 -> 0 | C13: ='2025.02'!C49 -> 0 | D13: =D12+C13 -> 9.96 | E13: ='2025.02'!F49 -> 0 | F13: =F12+E13 -> 1.619 | G13: 6.499 | H13: =F13*G13 -> 10.521881 | I13: =H13-D13 -> 0.561881 | J13: =(H13-D13)/D13 -> 0.056413755 | K13: ='2025.02'!D49 -> 0 | L13: ='2025.02'!I49 -> 0 | M13: ='2025.02'!O49 -> 0 | AC13: ='2025.02'!$C$49 -> 0 | AD13: ='2025.02'!$E$49 -> 0.00 | AE13: ='2025.02'!$F$49 -> 0 | AF13: ='2026.08'!$A$45 -> 46251 | AG13: ='2026.08'!$B$45*-1 -> -9.97
A14: ='2025.03'!Q2 -> 2025.03 | B14: ='2025.03'!B49 -> 0 | C14: ='2025.03'!C49 -> 0 | D14: =D13+C14 -> 9.96 | E14: ='2025.03'!F49 -> 0 | F14: =F13+E14 -> 1.619 | G14: 6.245 | H14: =F14*G14 -> 10.110655 | I14: =H14-D14 -> 0.150655 | J14: =(H14-D14)/D14 -> 0.015126004 | K14: ='2025.03'!D49 -> 0 | L14: ='2025.03'!I49 -> 0 | M14: ='2025.03'!O49 -> 0 | AC14: ='2025.03'!$C$49 -> 0 | AD14: ='2025.03'!$E$49 -> 0.00 | AE14: ='2025.03'!$F$49 -> 0 | AF14: ='2026.09'!$A$45 -> 46275 | AG14: ='2026.09'!$B$45*-1 -> -9.98
A15: ='2025.04'!Q2 -> 2025.04 | B15: ='2025.04'!B49 -> 0 | C15: ='2025.04'!C49 -> 0 | D15: =D14+C15 -> 9.96 | E15: ='2025.04'!F49 -> 0 | F15: =F14+E15 -> 1.619 | G15: 6.179 | H15: =F15*G15 -> 10.003801 | I15: =H15-D15 -> 0.043801 | J15: =(H15-D15)/D15 -> 0.0043976908 | K15: ='2025.04'!D49 -> 0 | L15: ='2025.04'!I49 -> 0 | M15: ='2025.04'!O49 -> 0 | AC15: ='2025.04'!$C$49 -> 0 | AD15: ='2025.04'!$E$49 -> 0.00 | AE15: ='2025.04'!$F$49 -> 0
A16: ='2025.05'!Q2 -> 2025.05 | B16: ='2025.05'!B49 -> 0 | C16: ='2025.05'!C49 -> 0 | D16: =D15+C16 -> 9.96 | E16: ='2025.05'!F49 -> 0 | F16: =F15+E16 -> 1.619 | G16: 6.413 | H16: =F16*G16 -> 10.382647 | I16: =H16-D16 -> 0.422647 | J16: =(H16-D16)/D16 -> 0.042434438 | K16: ='2025.05'!D49 -> 0 | L16: ='2025.05'!I49 -> 0 | M16: ='2025.05'!O49 -> 0 | AC16: ='2025.05'!$C$49 -> 0 | AD16: ='2025.05'!$E$49 -> 0.00 | AE16: ='2025.05'!$F$49 -> 0
A17: ='2025.06'!Q2 -> 2025.06 | B17: ='2025.06'!B49 -> 0 | C17: ='2025.06'!C49 -> 0 | D17: =D16+C17 -> 9.96 | E17: ='2025.06'!F49 -> 0 | F17: =F16+E17 -> 1.619 | G17: 6.321 | H17: =F17*G17 -> 10.233699 | I17: =H17-D17 -> 0.273699 | J17: =(H17-D17)/D17 -> 0.027479819 | K17: ='2025.06'!D49 -> 0 | L17: ='2025.06'!I49 -> 0 | M17: ='2025.06'!O49 -> 0 | AC17: ='2025.06'!$C$49 -> 0 | AD17: ='2025.06'!$E$49 -> 0.00 | AE17: ='2025.06'!$F$49 -> 0
A18: ='2025.07'!Q2 -> 2025.07 | B18: ='2025.07'!B49 -> 0 | C18: ='2025.07'!C49 -> 0 | D18: =D17+C18 -> 9.96 | E18: ='2025.07'!F49 -> 0 | F18: =F17+E18 -> 1.619 | G18: 6.388 | H18: =F18*G18 -> 10.342172 | I18: =H18-D18 -> 0.382172 | J18: =(H18-D18)/D18 -> 0.038370683 | K18: ='2025.07'!D49 -> 0 | L18: ='2025.07'!I49 -> 0 | M18: ='2025.07'!O49 -> 0 | AC18: ='2025.07'!$C$49 -> 0 | AD18: ='2025.07'!$E$49 -> 0.00 | AE18: ='2025.07'!$F$49 -> 0
A19: ='2025.08'!Q2 -> 2025.08 | B19: ='2025.08'!B49 -> 0 | C19: ='2025.08'!C49 -> 0 | D19: =D18+C19 -> 9.96 | E19: ='2025.08'!F49 -> 0 | F19: =F18+E19 -> 1.619 | G19: 6.621 | H19: =F19*G19 -> 10.719399 | I19: =H19-D19 -> 0.759399 | J19: =(H19-D19)/D19 -> 0.07624488 | K19: ='2025.08'!D49 -> 0 | L19: ='2025.08'!I49 -> 0 | M19: ='2025.08'!O49 -> 0 | AC19: ='2025.08'!$C$49 -> 0 | AD19: ='2025.08'!$E$49 -> 0.00 | AE19: ='2025.08'!$F$49 -> 0
A20: ='2025.09'!Q2 -> 2025.09 | B20: ='2025.09'!B49 -> 0 | C20: ='2025.09'!C49 -> 0 | D20: =D19+C20 -> 9.96 | E20: ='2025.09'!F49 -> 0 | F20: =F19+E20 -> 1.619 | G20: 6.737 | H20: =F20*G20 -> 10.907203 | I20: =H20-D20 -> 0.947203 | J20: =(H20-D20)/D20 -> 0.095100703 | K20: ='2025.09'!D49 -> 0 | L20: ='2025.09'!I49 -> 0 | M20: ='2025.09'!O49 -> 0 | AC20: ='2025.09'!$C$49 -> 0 | AD20: ='2025.09'!$E$49 -> 0.00 | AE20: ='2025.09'!$F$49 -> 0
A21: ='2025.10'!Q2 -> 2025.1 | B21: ='2025.10'!B49 -> 0 | C21: ='2025.10'!C49 -> 0 | D21: =D20+C21 -> 9.96 | E21: ='2025.10'!F49 -> 0 | F21: =F20+E21 -> 1.619 | G21: 7.139 | H21: =F21*G21 -> 11.558041 | I21: =H21-D21 -> 1.598041 | J21: =(H21-D21)/D21 -> 0.16044588 | K21: ='2025.10'!D49 -> 0 | L21: ='2025.10'!I49 -> 0 | M21: ='2025.10'!O49 -> 0 | AC21: ='2025.10'!$C$49 -> 0 | AD21: ='2025.10'!$E$49 -> 0.00 | AE21: ='2025.10'!$F$49 -> 0
A22: ='2025.11'!Q2 -> 2025.11 | B22: ='2025.11'!B49 -> 9.97 | C22: ='2025.11'!C49 -> 9.95 | D22: =D21+C22 -> 19.91 | E22: ='2025.11'!F49 -> 1.4355793 | F22: =F21+E22 -> 3.0545793 | G22: 7.061 | H22: =F22*G22 -> 21.568384 | I22: =H22-D22 -> 1.6583843 | J22: =(H22-D22)/D22 -> 0.083294039 | K22: ='2025.11'!D49 -> 0.02 | L22: ='2025.11'!I49 -> 0 | M22: ='2025.11'!O49 -> 0 | AC22: ='2025.11'!$C$49 -> 9.95 | AD22: ='2025.11'!$E$49 -> 6.931 | AE22: ='2025.11'!$F$49 -> 1.4355793
A23: ='2025.12'!Q2 -> 2025.12 | B23: ='2025.12'!B49 -> 0 | C23: ='2025.12'!C49 -> 0 | D23: =D22+C23 -> 19.91 | E23: ='2025.12'!F49 -> 0 | F23: =F22+E23 -> 3.0545793 | G23: 7.095 | H23: =F23*G23 -> 21.67224 | I23: =H23-D23 -> 1.76224 | J23: =(H23-D23)/D23 -> 0.088510296 | K23: ='2025.12'!D49 -> 0 | L23: ='2025.12'!I49 -> 0 | M23: ='2025.12'!O49 -> 0 | AC23: ='2025.12'!$C$49 -> 0 | AD23: ='2025.12'!$E$49 -> 0.00 | AE23: ='2025.12'!$F$49 -> 0
A24: ='2026.01'!$Q$2 -> 2026.01 | B24: ='2026.01'!$B$49 -> 0 | C24: ='2026.01'!$C$49 -> 0 | D24: =D23+C24 -> 19.91 | E24: ='2026.01'!$F$49 -> 0 | F24: =F23+E24 -> 3.0545793 | G24: 7.399 | H24: =F24*G24 -> 22.600832 | I24: =H24-D24 -> 2.6908321 | J24: =(H24-D24)/D24 -> 0.13514978 | K24: ='2026.01'!$D$49 -> 0 | L24: ='2026.01'!$I$49 -> 0 | M24: ='2026.01'!$O$49 -> 0 | AC24: ='2026.01'!$C$49 -> 0 | AD24: ='2026.01'!$E$49 -> 0.00 | AE24: ='2026.01'!$F$49 -> 0
A25: ='2026.02'!$Q$2 -> 2026.02 | B25: ='2026.02'!$B$49 -> 0 | C25: ='2026.02'!$C$49 -> 0 | D25: =D24+C25 -> 19.91 | E25: ='2026.02'!$F$49 -> 0 | F25: =F24+E25 -> 3.0545793 | G25: 7.999 | H25: =F25*G25 -> 24.43358 | I25: =H25-D25 -> 4.5235797 | J25: =(H25-D25)/D25 -> 0.22720139 | K25: ='2026.02'!$D$49 -> 0 | L25: ='2026.02'!$I$49 -> 0 | M25: ='2026.02'!$O$49 -> 0 | AC25: ='2026.02'!$C$49 -> 0 | AD25: ='2026.02'!$E$49 -> 0.00 | AE25: ='2026.02'!$F$49 -> 0
A26: ='2026.03'!$Q$2 -> 2026.03 | B26: ='2026.03'!$B$49 -> 9.99 | C26: ='2026.03'!$C$49 -> 9.97 | D26: =D25+C26 -> 29.88 | E26: ='2026.03'!$F$49 -> 1.3312859 | F26: =F25+E26 -> 4.3858652 | G26: 7.307 | H26: =F26*G26 -> 32.047517 | I26: =H26-D26 -> 2.1675168 | J26: =(H26-D26)/D26 -> 0.072540722 | K26: ='2026.03'!$D$49 -> 0.02 | L26: ='2026.03'!$I$49 -> 0 | M26: ='2026.03'!$O$49 -> 0 | AC26: ='2026.03'!$C$49 -> 9.97 | AD26: ='2026.03'!$E$49 -> 7.489 | AE26: ='2026.03'!$F$49 -> 1.3312859
A27: ='2026.04'!$Q$2 -> 2026.04 | B27: ='2026.04'!$B$49 -> 9.99 | C27: ='2026.04'!$C$49 -> 9.99 | D27: =D26+C27 -> 39.87 | E27: ='2026.04'!$F$49 -> 1.2928692 | F27: =F26+E27 -> 5.6787343 | G27: 7.63 | H27: =F27*G27 -> 43.328743 | I27: =H27-D27 -> 3.4587429 | J27: =(H27-D27)/D27 -> 0.086750512 | K27: ='2026.04'!$D$49 -> 0 | L27: ='2026.04'!$I$49 -> 0 | M27: ='2026.04'!$O$49 -> 0 | AC27: ='2026.04'!$C$49 -> 9.99 | AD27: ='2026.04'!$E$49 -> 7.727 | AE27: ='2026.04'!$F$49 -> 1.2928692
