Workbook

Sheet Apžvalga
A1: Data | B1: Viso: | D1: Mėnesio gale | N1: Dividendai | O1: Mokestis
B2: Inešta | C2: Investuota | D2: Gryni | E2: SGAS | F2: SLMC | G2: AYEM | H2: SGAJ | I2: EDMU | J2: Viso | K2: Vertė | L2: Pelnas | M2: %
A3: ='2025.04'!$N$2 -> 2025.04 | B3: ='2025.04'!$O$9 -> 110 | C3: ='2025.04'!$P$9-'2025.04'!$Q$9 -> 109.96 | D3: ='2025.04'!$R$9 -> 0.04 | E3: =SGAS!G5 -> 37.48163 | F3: =SLMC!G5 -> 20.605742 | G3: =AYEM!G5 -> 14.511535 | H3: =SGAJ!G5 -> 6.5275304 | I3: =EDMU!G5 -> 36.985457 | J3: =SUM(E3:I3) -> 116.1119 | K3: =J3+D3-O3 -> 116.1519 | L3: =K3-B3 -> 6.1518955 | M3: =L3/B3 -> 0.055926322 | N3: ='2025.04'!$S$9 -> 0 | O3: ='2025.04'!$T$9 -> 0
A4: ='2025.05'!$N$2 -> 2025.05 | B4: =B3+'2025.05'!$O$9 -> 155.48 | C4: =C3+'2025.05'!$P$9-'2025.05'!$Q$9 -> 155.45 | D4: =D3+'2025.05'!$R$9 -> 0.03 | E4: =SGAS!G6 -> 55.214403 | F4: =SLMC!G6 -> 29.411253 | G4: =AYEM!G6 -> 20.626473 | H4: =SGAJ!G6 -> 9.2886097 | I4: =EDMU!G6 -> 54.190422 | J4: =SUM(E4:I4) -> 168.73116 | K4: =J4+D4-O4 -> 168.71116 | L4: =K4-B4 -> 13.23116 | M4: =L4/B4 -> 0.085098793 | N4: ='2025.05'!$S$9 -> 0 | O4: ='2025.05'!$T$9 -> 0.05
A5: ='2025.06'!$N$2 -> 2025.06 | B5: =B4+'2025.06'!$O$9 -> 165.48 | C5: =C4+'2025.06'!$P$9-'2025.06'!$Q$9 -> 165.47 | D5: =D4+'2025.06'!$R$9 -> 0.01 | E5: =SGAS!G7 -> 59.612264 | F5: =SLMC!G7 -> 30.83711 | G5: =AYEM!G7 -> 22.479892 | H5: =SGAJ!G7 -> 9.7093703 | I5: =EDMU!G7 -> 58.0948 | J5: =SUM(E5:I5) -> 180.73344 | K5: =J5+D5-O5 -> 180.64344 | L5: =K5-B5 -> 15.163437 | M5: =L5/B5 -> 0.091633049 | N5: ='2025.06'!$S$9 -> 0 | O5: ='2025.06'!$T$9 -> 0.1
A6: ='2025.07'!$N$2 -> 2025.07 | B6: =B5+'2025.07'!$O$9 -> 180.48 | C6: =C5+'2025.07'!$P$9-'2025.07'!$Q$9 -> 180.44 | D6: =D5+'2025.07'!$R$9 -> 0.04 | E6: =SGAS!G8 -> 68.687859 | F6: =SLMC!G8 -> 33.695351 | G6: =AYEM!G8 -> 25.293018 | H6: =SGAJ!G8 -> 10.645194 | I6: =EDMU!G8 -> 66.802662 | J6: =SUM(E6:I6) -> 205.12408 | K6: =J6+D6-O6 -> 205.03408 | L6: =K6-B6 -> 24.554085 | M6: =L6/B6 -> 0.13604878 | N6: ='2025.07'!$S$9 -> 0 | O6: ='2025.07'!$T$9 -> 0.13
A7: ='2025.08'!$N$2 -> 2025.08 | B7: =B6+'2025.08'!$O$9 -> 195.48 | C7: =C6+'2025.08'!$P$9-'2025.08'!$Q$9 -> 195.45 | D7: =D6+'2025.08'!$R$9 -> 0.03 | E7: =SGAS!G9 -> 72.81895 | F7: =SLMC!G9 -> 36.530064 | G7: =AYEM!G9 -> 27.069668 | H7: =SGAJ!G9 -> 11.865981 | I7: =EDMU!G9 -> 70.864644 | J7: =SUM(E7:I7) -> 219.14931 | K7: =J7+D7-O7 -> 219.02931 | L7: =K7-B7 -> 23.549306 | M7: =L7/B7 -> 0.12046913 | N7: ='2025.08'!$S$9 -> 0 | O7: ='2025.08'!$T$9 -> 0.15
A8: ='2025.09'!$N$2 -> 2025.09 | B8: =B7+'2025.09'!$O$9 -> 210.48 | C8: =C7+'2025.09'!$P$9-'2025.09'!$Q$9 -> 210.44 | D8: =D7+'2025.09'!$R$9 -> 0.04 | E8: =SGAS!G10 -> 80.278309 | F8: =SLMC!G10 -> 39.581462 | G8: =AYEM!G10 -> 30.458868 | H8: =SGAJ!G10 -> 12.908365 | I8: =EDMU!G10 -> 77.706705 | J8: =SUM(E8:I8) -> 240.93371 | K8: =J8+D8-O8 -> 240.81371 | L8: =K8-B8 -> 30.333709 | M8: =L8/B8 -> 0.14411682 | N8: ='2025.09'!$S$9 -> 0 | O8: ='2025.09'!$T$9 -> 0.16
A9: ='2025.10'!$N$2 -> 2025.10 | B9: =B8+'2025.10'!$O$9 -> 230.48 | C9: =C8+'2025.10'!$P$9-'2025.10'!$Q$9 -> 230.47 | D9: =D8+'2025.10'!$R$9 -> 0.01 | E9: =SGAS!G11 -> 91.185151 | F9: =SLMC!G11 -> 44.158718 | G9: =AYEM!G11 -> 34.746153 | H9: =SGAJ!G11 -> 14.825934 | I9: =EDMU!G11 -> 87.77107 | J9: =SUM(E9:I9) -> 272.68703 | K9: =J9+D9-O9 -> 272.51703 | L9: =K9-B9 -> 42.037027 | M9: =L9/B9 -> 0.18238904 | N9: ='2025.10'!$S$9 -> 0 | O9: ='2025.10'!$T$9 -> 0.18
A10: ='2025.11'!$N$2 -> 2025.11 | B10: =B9+'2025.11'!$O$9 -> 250.48 | C10: =C9+'2025.11'!$P$9-'2025.11'!$Q$9 -> 250.44 | D10: =D9+'2025.11'!$R$9 -> 0.04 | E10: =SGAS!G12 -> 97.293505 | F10: =SLMC!G12 -> 47.543553 | G10: =AYEM!G12 -> 36.679378 | H10: =SGAJ!G12 -> 15.753226 | I10: =EDMU!G12 -> 93.709706 | J10: =SUM(E10:I10) -> 290.97937 | K10: =J10+D10-O10 -> 290.83937 | L10: =K10-B10 -> 40.359368 | M10: =L10/B10 -> 0.16112811 | N10: ='2025.11'!$S$9 -> 0 | O10: ='2025.11'!$T$9 -> 0.18
A11: ='2025.12'!$N$2 -> 2025.12 | B11: =B10+'2025.12'!$O$9 -> 270.48 | C11: =C10+'2025.12'!$P$9-'2025.12'!$Q$9 -> 270.46 | D11: =D10+'2025.12'!$R$9 -> 0.02 | E11: =SGAS!G13 -> 103.70075 | F11: =SLMC!G13 -> 52.260386 | G11: =AYEM!G13 -> 39.374486 | H11: =SGAJ!G13 -> 16.929316 | I11: =EDMU!G13 -> 99.840647 | J11: =SUM(E11:I11) -> 312.10558 | K11: =J11+D11-O11 -> 311.90558 | L11: =K11-B11 -> 41.425582 | M11: =L11/B11 -> 0.1531558 | N11: ='2025.12'!$S$9 -> 0 | O11: ='2025.12'!$T$9 -> 0.22
A12: ='2026.01'!$N$2 -> 2026.01 | B12: =B11+'2026.01'!$O$9 -> 290.48 | C12: =C11+'2026.01'!$P$9-'2026.01'!$Q$9 -> 290.46 | D12: =D11+'2026.01'!$R$9 -> 0.02 | E12: =SGAS!G14 -> 109.06746 | F12: =SLMC!G14 -> 57.301275 | G12: =AYEM!G14 -> 44.903681 | H12: =SGAJ!G14 -> 18.769147 | I12: =EDMU!G14 -> 104.92023 | J12: =SUM(E12:I12) -> 334.96179 | K12: =J12+D12-O12 -> 334.75179 | L12: =K12-B12 -> 44.27179 | M12: =L12/B12 -> 0.15240908 | N12: ='2026.01'!$S$9 -> 0 | O12: ='2026.01'!$T$9 -> 0.23
A13: ='2026.02'!$N$2 -> 2026.02 | B13: =B12+'2026.02'!$O$9 -> 310.48 | C13: =C12+'2026.02'!$P$9-'2026.02'!$Q$9 -> 310.43 | D13: =D12+'2026.02'!$R$9 -> 0.05 | E13: =SGAS!G15 -> 115.06856 | F13: =SLMC!G15 -> 62.670603 | G13: =AYEM!G15 -> 50.504304 | H13: =SGAJ!G15 -> 21.470468 | I13: =EDMU!G15 -> 113.05628 | J13: =SUM(E13:I13) -> 362.77022 | K13: =J13+D13-O13 -> 362.60022 | L13: =K13-B13 -> 52.120219 | M13: =L13/B13 -> 0.16786981 | N13: ='2026.02'!$S$9 -> 0 | O13: ='2026.02'!$T$9 -> 0.22
A14: ='2026.03'!$N$2 -> 2026.03 | B14: =B13+'2026.03'!$O$9 -> 330.48 | C14: =C13+'2026.03'!$P$9-'2026.03'!$Q$9 -> 330.41 | D14: =D13+'2026.03'!$R$9 -> 0.07 | E14: =SGAS!G16 -> 115.5752 | F14: =SLMC!G16 -> 60.99466 | G14: =AYEM!G16 -> 47.805439 | H14: =SGAJ!G16 -> 20.753814 | I14: =EDMU!G16 -> 111.80852 | J14: =SUM(E14:I14) -> 356.93763 | K14: =J14+D14-O14 -> 356.75763 | L14: =K14-B14 -> 26.277634 | M14: =L14/B14 -> 0.079513537 | N14: ='2026.03'!$S$9 -> 0 | O14: ='2026.03'!$T$9 -> 0.25
A15: ='2026.04'!$N$2 -> 2026.04 | B15: =B14+'2026.04'!$O$9 -> 350.48 | C15: =C14+'2026.04'!$P$9-'2026.04'!$Q$9 -> 350.48 | D15: =D14+'2026.04'!$R$9 -> 3.5527137e-15 | E15: =SGAS!G17 -> 134.58105 | F15: =SLMC!G17 -> 66.89046 | G15: =AYEM!G17 -> 56.475571 | H15: =SGAJ!G17 -> 22.872634 | I15: =EDMU!G17 -> 129.16302 | J15: =SUM(E15:I15) -> 409.98274 | K15: =J15+D15-O15 -> 409.71274 | L15: =K15-B15 -> 59.232739 | M15: =L15/B15 -> 0.16900462 | N15: ='2026.04'!$S$9 -> 0 | O15: ='2026.04'!$T$9 -> 0.27
A16: ='2026.05'!$N$2 -> 2026.05 | B16: =B15+'2026.05'!$O$9 -> 370.48 | C16: =C15+'2026.05'!$P$9-'2026.05'!$Q$9 -> 370.45 | D16: =D15+'2026.05'!$R$9 -> 0.03 | E16: =SGAS!G18 -> 151.0757 | F16: =SLMC!G18 -> 73.649015 | G16: =AYEM!G18 -> 64.889565 | H16: =SGAJ!G18 -> 25.800626 | I16: =EDMU!G18 -> 144.56707 | J16: =SUM(E16:I16) -> 459.98197 | K16: =J16+D16-O16 -> 459.71197 | L16: =K16-B16 -> 89.231972 | M16: =L16/B16 -> 0.24085503 | N16: ='2026.05'!$S$9 -> 0 | O16: ='2026.05'!$T$9 -> 0.3
A17: ='2026.06'!$N$2 -> 2026.06 | B17: =B16+'2026.06'!$O$9 -> 390.48 | C17: =C16+'2026.06'!$P$9-'2026.06'!$Q$9 -> 390.47 | D17: =D16+'2026.06'!$R$9 -> 0.01 | E17: =SGAS!G19 -> 159.05986 | F17: =SLMC!G19 -> 79.269743 | G17: =AYEM!G19 -> 69.091934 | H17: =SGAJ!G19 -> 27.877211 | I17: =EDMU!G19 -> 152.52818 | J17: =SUM(E17:I17) -> 487.82692 | K17: =J17+D17-O17 -> 487.52692 | L17: =K17-B17 -> 97.046925 | M17: =L17/B17 -> 0.24853238 | N17: ='2026.06'!$S$9 -> 0 | O17: ='2026.06'!$T$9 -> 0.31
A18: ='2026.07'!$N$2 -> 2026.07 | B18: =B17+'2026.06'!$O$9 -> 410.48 | C18: =C17+'2026.06'!$P$9-'2026.06'!$Q$9 -> 410.49 | D18: =D17+'2026.06'!$R$9 -> -0.01 | E18: =SGAS!G20 -> 166.31016 | F18: =SLMC!G20 -> 81.654265 | G18: =AYEM!G20 -> 68.322605 | H18: =SGAJ!G20 -> 29.108288 | I18: =EDMU!G20 -> 159.4109 | J18: =SUM(E18:I18) -> 504.80621 | K18: =J18+D18-O18 -> 504.79621 | L18: =K18-B18 -> 94.316212 | M18: =L18/B18 -> 0.22977054 | N18: ='2026.07'!$S$9 -> 0 | O18: ='2026.07'!$T$9 -> 0

Sheet SGAS
A1: SGAS GY iShares MSCI USA ESG Screened
A3: Data | B3: Suma, EUR | D3: Kiekis | F3: Mėnesio gale | J3: Dividendai | L3: SGAS | M3: Įnešta | N3: Kiekis | O3: Parduota | P3: Pelnas | Q3: % | R3: Dividendai | S3: Vid. Kaina | AA3: Suma | AB3: Kaina | AC3: Kiekis
B4: Įnešta | C4: Viso | D4: Mėnesio | E4: Viso | F4: Kaina | G4: Vertė | H4: Pelnas | I4: %
A5: ='2025.04'!$N$2 -> 2025.04 | B5: ='2025.04'!$B$20-'2025.04'!$G$20 -> 35.99 | C5: =B5 -> 35.99 | D5: ='2025.04'!$D$20-'2025.04'!$I$20 -> 3.7802955 | E5: =D5 -> 3.7802955 | F5: 9.915 | G5: =E5*F5 -> 37.48163 | H5: =G5-C5 -> 1.4916303 | I5: =(G5-C5)/C5 -> 0.041445688 | J5: ='2025.04'!$L$20 -> 0 | L5: Viso: | M5: =SUM(B5:B200) -> 135.16 | N5: =SUM(D5:D200) -> 12.132343 | O5: 166.31 | P5: =IF(O5>0,O5-M5,"") -> 31.15 | Q5: =IF(O5>0,(O5-M5)/M5,"") -> 0.23046759 | R5: =SUM(J5:J200) -> 0 | S5: {=SUMPRODUCT(IFERROR(AB5:AB200,0),IFERROR(AC5:AC200,0))/SUM(IFERROR(AC5:AC200,0))} -> 11.034516 | AA5: ='2025.04'!$B$20 -> 35.99 | AB5: ='2025.04'!$C$20 -> 9.5204197 | AC5: ='2025.04'!$D$20 -> 3.7802955
A6: ='2025.05'!$N$2 -> 2025.05 | B6: ='2025.05'!$B$20-'2025.05'!$G$20 -> 14.96 | C6: =C5+B6 -> 50.95 | D6: ='2025.05'!$D$20-'2025.05'!$I$20 -> 1.402209 | E6: =E5+D6 -> 5.1825045 | F6: 10.654 | G6: =E6*F6 -> 55.214403 | H6: =G6-C6 -> 4.2644029 | I6: =(G6-C6)/C6 -> 0.0836978 | J6: ='2025.05'!$L$20 -> 0 | AA6: ='2025.05'!$B$20 -> 14.96 | AB6: ='2025.05'!$C$20 -> 10.668881 | AC6: ='2025.05'!$D$20 -> 1.402209
A7: ='2025.06'!$N$2 -> 2025.06 | B7: ='2025.06'!$B$20-'2025.06'!$G$20 -> 3.28 | C7: =C6+B7 -> 54.23 | D7: ='2025.06'!$D$20-'2025.06'!$I$20 -> 0.30867683 | E7: =E6+D7 -> 5.4911813 | F7: 10.856 | G7: =E7*F7 -> 59.612264 | H7: =G7-C7 -> 5.3822645 | I7: =(G7-C7)/C7 -> 0.099248838 | J7: ='2025.06'!$L$20 -> 0 | AA7: ='2025.06'!$B$20 -> 3.28 | AB7: ='2025.06'!$C$20 -> 10.626 | AC7: ='2025.06'!$D$20 -> 0.30867683
A8: ='2025.07'!$N$2 -> 2025.07 | B8: ='2025.07'!$B$20-'2025.07'!$G$20 -> 4.97 | C8: =C7+B8 -> 59.2 | D8: ='2025.07'!$D$20-'2025.07'!$I$20 -> 0.45891043 | E8: =E7+D8 -> 5.9500918 | F8: 11.544 | G8: =E8*F8 -> 68.687859 | H8: =G8-C8 -> 9.4878593 | I8: =(G8-C8)/C8 -> 0.16026789 | J8: ='2025.07'!$L$20 -> 0 | AA8: ='2025.07'!$B$20 -> 4.97 | AB8: ='2025.07'!$C$20 -> 10.83 | AC8: ='2025.07'!$D$20 -> 0.45891043
A9: ='2025.08'!$N$2 -> 2025.08 | B9: ='2025.08'!$B$20-'2025.08'!$G$20 -> 5.01 | C9: =C8+B9 -> 64.21 | D9: ='2025.08'!$D$20-'2025.08'!$I$20 -> 0.44202112 | E9: =E8+D9 -> 6.3921129 | F9: 11.392 | G9: =E9*F9 -> 72.81895 | H9: =G9-C9 -> 8.60895 | I9: =(G9-C9)/C9 -> 0.13407491 | J9: ='2025.08'!$L$20 -> 0 | AA9: ='2025.08'!$B$20 -> 5.01 | AB9: ='2025.08'!$C$20 -> 11.3343 | AC9: ='2025.08'!$D$20 -> 0.44202112
A10: ='2025.09'!$N$2 -> 2025.09 | B10: ='2025.09'!$B$20-'2025.09'!$G$20 -> 5.01 | C10: =C9+B10 -> 69.22 | D10: ='2025.09'!$D$20-'2025.09'!$I$20 -> 0.44008362 | E10: =E9+D10 -> 6.8321965 | F10: 11.75 | G10: =E10*F10 -> 80.278309 | H10: =G10-C10 -> 11.058309 | I10: =(G10-C10)/C10 -> 0.15975598 | J10: ='2025.09'!$L$20 -> 0 | AA10: ='2025.09'!$B$20 -> 5.01 | AB10: ='2025.09'!$C$20 -> 11.3842 | AC10: ='2025.09'!$D$20 -> 0.44008362
A11: ='2025.10'!$N$2 -> 2025.10 | B11: ='2025.10'!$B$20-'2025.10'!$G$20 -> 6.68 | C11: =C10+B11 -> 75.9 | D11: ='2025.10'!$D$20-'2025.10'!$I$20 -> 0.5583977 | E11: =E10+D11 -> 7.3905942 | F11: 12.338 | G11: =E11*F11 -> 91.185151 | H11: =G11-C11 -> 15.285151 | I11: =(G11-C11)/C11 -> 0.20138539 | J11: ='2025.10'!$L$20 -> 0 | AA11: ='2025.10'!$B$20 -> 6.68 | AB11: ='2025.10'!$C$20 -> 11.9628 | AC11: ='2025.10'!$D$20 -> 0.5583977
A12: ='2025.11'!$N$2 -> 2025.11 | B12: ='2025.11'!$B$20-'2025.11'!$G$20 -> 6.71 | C12: =C11+B12 -> 82.61 | D12: ='2025.11'!$D$20-'2025.11'!$I$20 -> 0.54784455 | E12: =E11+D12 -> 7.9384388 | F12: 12.256 | G12: =E12*F12 -> 97.293505 | H12: =G12-C12 -> 14.683505 | I12: =(G12-C12)/C12 -> 0.17774489 | J12: ='2025.11'!$L$20 -> 0 | AA12: ='2025.11'!$B$20 -> 6.71 | AB12: ='2025.11'!$C$20 -> 12.248 | AC12: ='2025.11'!$D$20 -> 0.54784455
A13: ='2025.12'!$N$2 -> 2025.12 | B13: ='2025.12'!$B$20-'2025.12'!$G$20 -> 6.71 | C13: =C12+B13 -> 89.32 | D13: ='2025.12'!$D$20-'2025.12'!$I$20 -> 0.54909984 | E13: =E12+D13 -> 8.4875386 | F13: 12.218 | G13: =E13*F13 -> 103.70075 | H13: =G13-C13 -> 14.380746 | I13: =(G13-C13)/C13 -> 0.16100254 | J13: ='2025.12'!$L$20 -> 0 | AA13: ='2025.12'!$B$20 -> 6.71 | AB13: ='2025.12'!$C$20 -> 12.22 | AC13: ='2025.12'!$D$20 -> 0.54909984
A14: ='2026.01'!$N$2 -> 2026.01 | B14: ='2026.01'!$B$20-'2026.01'!$G$20 -> 6.63 | C14: =C13+B14 -> 95.95 | D14: ='2026.01'!$D$20-'2026.01'!$I$20 -> 0.54122449 | E14: =E13+D14 -> 9.0287631 | F14: 12.08 | G14: =E14*F14 -> 109.06746 | H14: =G14-C14 -> 13.117458 | I14: =(G14-C14)/C14 -> 0.13671139 | J14: ='2026.01'!$L$20 -> 0 | AA14: ='2026.01'!$B$20 -> 6.63 | AB14: ='2026.01'!$C$20 -> 12.25 | AC14: ='2026.01'!$D$20 -> 0.54122449
A15: ='2026.02'!$N$2 -> 2026.02 | B15: ='2026.02'!$B$20-'2026.02'!$G$20 -> 6.55 | C15: =C14+B15 -> 102.5 | D15: ='2026.02'!$D$20-'2026.02'!$I$20 -> 0.53478119 | E15: =E14+D15 -> 9.5635443 | F15: 12.032 | G15: =E15*F15 -> 115.06856 | H15: =G15-C15 -> 12.568565 | I15: =(G15-C15)/C15 -> 0.12262014 | J15: ='2026.02'!$L$20 -> 0 | AA15: ='2026.02'!$B$20 -> 6.55 | AB15: ='2026.02'!$C$20 -> 12.248 | AC15: ='2026.02'!$D$20 -> 0.53478119
A16: ='2026.03'!$N$2 -> 2026.03 | B16: ='2026.03'!$B$20-'2026.03'!$G$20 -> 6.44 | C16: =C15+B16 -> 108.94 | D16: ='2026.03'!$D$20-'2026.03'!$I$20 -> 0.53918285 | E16: =E15+D16 -> 10.102727 | F16: 11.44 | G16: =E16*F16 -> 115.5752 | H16: =G16-C16 -> 6.6351983 | I16: =(G16-C16)/C16 -> 0.060906905 | J16: ='2026.03'!$L$20 -> 0 | AA16: ='2026.03'!$B$20 -> 6.44 | AB16: ='2026.03'!$C$20 -> 11.944 | AC16: ='2026.03'!$D$20 -> 0.53918285
A17: ='2026.04'!$N$2 -> 2026.04 | B17: ='2026.04'!$B$20-'2026.04'!$G$20 -> 6.52 | C17: =C16+B17 -> 115.46 | D17: ='2026.04'!$D$20-'2026.04'!$I$20 -> 0.55631399 | E17: =E16+D17 -> 10.659041 | F17: 12.626 | G17: =E17*F17 -> 134.58105 | H17: =G17-C17 -> 19.121053 | I17: =(G17-C17)/C17 -> 0.1656076 | J17: ='2026.04'!$L$20 -> 0 | AA17: ='2026.04'!$B$20 -> 6.52 | AB17: ='2026.04'!$C$20 -> 11.72 | AC17: ='2026.04'!$D$20 -> 0.55631399
A18: ='2026.05'!$N$2 -> 2026.05 | B18: ='2026.05'!$B$19-'2026.05'!$G$19 -> 6.56 | C18: =C17+B18 -> 122.02 | D18: ='2026.05'!$D$19-'2026.05'!$I$19 -> 0.51189213 | E18: =E17+D18 -> 11.170933 | F18: 13.524 | G18: =E18*F18 -> 151.0757 | H18: =G18-C18 -> 29.055701 | I18: =(G18-C18)/C18 -> 0.23812245 | J18: ='2026.05'!$L$19 -> 0 | AA18: ='2026.05'!$B$19 -> 6.56 | AB18: ='2026.05'!$C$19 -> 12.8152 | AC18: ='2026.05'!$D$19 -> 0.51189213
A19: ='2026.06'!$N$2 -> 2026.06 | B19: ='2026.06'!$B$19-'2026.06'!$G$19 -> 6.6 | C19: =C18+B19 -> 128.62 | D19: ='2026.06'!$D$19-'2026.06'!$I$19 -> 0.48521919 | E19: =E18+D19 -> 11.656152 | F19: 13.646 | G19: =E19*F19 -> 159.05986 | H19: =G19-C19 -> 30.439856 | I19: =(G19-C19)/C19 -> 0.23666503 | J19: ='2026.06'!$L$19 -> 0 | AA19: ='2026.06'!$B$19 -> 6.6 | AB19: ='2026.06'!$C$19 -> 13.6021 | AC19: ='2026.06'!$D$19 -> 0.48521919
A20: ='2026.07'!$N$2 -> 2026.07 | B20: ='2026.07'!$B$19 -> 6.54 | C20: =C19+B20 -> 135.16 | D20: ='2026.07'!$D$19 -> 0.47619048 | E20: =E19+D20 -> 12.132343 | F20: 13.708 | G20: =E20*F20 -> 166.31016 | H20: =G20-C20 -> 31.150157 | I20: =(G20-C20)/C20 -> 0.23046875 | J20: ='2026.07'!$L$19 -> 0

Sheet SLMC
A1: SLMC GY iShares MSCI Europe ESG Screened
A3: Data | B3: Suma, EUR | D3: Kiekis | F3: Mėnesio gale | J3: Dividendai | L3: SLMC | M3: Įnešta | N3: Kiekis | O3: Parduota | P3: Pelnas | Q3: % | R3: Dividendai | S3: Vid. Kaina | AA3: Suma | AB3: Kaina | AC3: Kiekis
B4: Įnešta | C4: Viso | D4: Mėnesio | E4: Viso | F4: Kaina | G4: Vertė | H4: Pelnas | I4: %
A5: ='2025.04'!$N$2 -> 2025.04 | B5: ='2025.04'!$B$30-'2025.04'!$G$30 -> 18.71 | C5: =B5 -> 18.71 | D5: ='2025.04'!$D$30-'2025.04'!$I$30 -> 2.3573667 | E5: =D5 -> 2.3573667 | F5: 8.741 | G5: =E5*F5 -> 20.605742 | H5: =G5-C5 -> 1.8957423 | I5: =(G5-C5)/C5 -> 0.10132241 | J5: ='2025.04'!$L$30 -> 0 | L5: Viso: | M5: =SUM(B5:B200) -> 68.88 | N5: =SUM(D5:D200) -> 7.5107864 | O5: 81.65 | P5: =IF(O5>0,O5-M5,"") -> 12.77 | Q5: =IF(O5>0,(O5-M5)/M5,"") -> 0.18539489 | R5: =SUM(J5:J200) -> 0 | S5: {=SUMPRODUCT(IFERROR(AB5:AB200,0),IFERROR(AC5:AC200,0))/SUM(IFERROR(AC5:AC200,0))} -> 9.0923552 | AA5: ='2025.04'!$B$30 -> 18.71 | AB5: ='2025.04'!$C$30 -> 7.9368221 | AC5: ='2025.04'!$D$30 -> 2.3573667
A6: ='2025.05'!$N$2 -> 2025.05 | B6: ='2025.05'!$B$30-'2025.05'!$G$30 -> 7.89 | C6: =C5+B6 -> 26.6 | D6: ='2025.05'!$D$30-'2025.05'!$I$30 -> 0.86366634 | E6: =E5+D6 -> 3.221033 | F6: 9.131 | G6: =E6*F6 -> 29.411253 | H6: =G6-C6 -> 2.8112526 | I6: =(G6-C6)/C6 -> 0.10568619 | J6: ='2025.05'!$L$30 -> 0 | AA6: ='2025.05'!$B$30 -> 7.89 | AB6: ='2025.05'!$C$30 -> 9.1354724 | AC6: ='2025.05'!$D$30 -> 0.86366634
A7: ='2025.06'!$N$2 -> 2025.06 | B7: ='2025.06'!$B$30-'2025.06'!$G$30 -> 1.76 | C7: =C6+B7 -> 28.36 | D7: ='2025.06'!$D$30-'2025.06'!$I$30 -> 0.19317309 | E7: =E6+D7 -> 3.4142061 | F7: 9.032 | G7: =E7*F7 -> 30.83711 | H7: =G7-C7 -> 2.4771097 | I7: =(G7-C7)/C7 -> 0.087345192 | J7: ='2025.06'!$L$30 -> 0 | AA7: ='2025.06'!$B$30 -> 1.76 | AB7: ='2025.06'!$C$30 -> 9.111 | AC7: ='2025.06'!$D$30 -> 0.19317309
A8: ='2025.07'!$N$2 -> 2025.07 | B8: ='2025.07'!$B$30-'2025.07'!$G$30 -> 2.54 | C8: =C7+B8 -> 30.9 | D8: ='2025.07'!$D$30-'2025.07'!$I$30 -> 0.28086471 | E8: =E7+D8 -> 3.6950708 | F8: 9.119 | G8: =E8*F8 -> 33.695351 | H8: =G8-C8 -> 2.7953509 | I8: =(G8-C8)/C8 -> 0.090464429 | J8: ='2025.07'!$L$30 -> 0 | AA8: ='2025.07'!$B$30 -> 2.54 | AB8: ='2025.07'!$C$30 -> 9.0435 | AC8: ='2025.07'!$D$30 -> 0.28086471
A9: ='2025.08'!$N$2 -> 2025.08 | B9: ='2025.08'!$B$30-'2025.08'!$G$30 -> 2.48 | C9: =C8+B9 -> 33.38 | D9: ='2025.08'!$D$30-'2025.08'!$I$30 -> 0.27472527 | E9: =E8+D9 -> 3.9697961 | F9: 9.202 | G9: =E9*F9 -> 36.530064 | H9: =G9-C9 -> 3.1500637 | I9: =(G9-C9)/C9 -> 0.094369794 | J9: ='2025.08'!$L$30 -> 0 | AA9: ='2025.08'!$B$30 -> 2.48 | AB9: ='2025.08'!$C$30 -> 9.0272 | AC9: ='2025.08'!$D$30 -> 0.27472527
A10: ='2025.09'!$N$2 -> 2025.09 | B10: ='2025.09'!$B$30-'2025.09'!$G$30 -> 2.48 | C10: =C9+B10 -> 35.86 | D10: ='2025.09'!$D$30-'2025.09'!$I$30 -> 0.27077192 | E10: =E9+D10 -> 4.240568 | F10: 9.334 | G10: =E10*F10 -> 39.581462 | H10: =G10-C10 -> 3.7214619 | I10: =(G10-C10)/C10 -> 0.10377752 | J10: ='2025.09'!$L$30 -> 0 | AA10: ='2025.09'!$B$30 -> 2.48 | AB10: ='2025.09'!$C$30 -> 9.159 | AC10: ='2025.09'!$D$30 -> 0.27077192
A11: ='2025.10'!$N$2 -> 2025.10 | B11: ='2025.10'!$B$30-'2025.10'!$G$30 -> 3.3 | C11: =C10+B11 -> 39.16 | D11: ='2025.10'!$D$30-'2025.10'!$I$30 -> 0.34544484 | E11: =E10+D11 -> 4.5860129 | F11: 9.629 | G11: =E11*F11 -> 44.158718 | H11: =G11-C11 -> 4.9987178 | I11: =(G11-C11)/C11 -> 0.12764857 | J11: ='2025.10'!$L$30 -> 0 | AA11: ='2025.10'!$B$30 -> 3.3 | AB11: ='2025.10'!$C$30 -> 9.5529 | AC11: ='2025.10'!$D$30 -> 0.34544484
A12: ='2025.11'!$N$2 -> 2025.11 | B12: ='2025.11'!$B$30-'2025.11'!$G$30 -> 3.2 | C12: =C11+B12 -> 42.36 | D12: ='2025.11'!$D$30-'2025.11'!$I$30 -> 0.33924899 | E12: =E11+D12 -> 4.9252618 | F12: 9.653 | G12: =E12*F12 -> 47.543553 | H12: =G12-C12 -> 5.1835526 | I12: =(G12-C12)/C12 -> 0.12236904 | J12: ='2025.11'!$L$30 -> 0 | AA12: ='2025.11'!$B$30 -> 3.2 | AB12: ='2025.11'!$C$30 -> 9.4326 | AC12: ='2025.11'!$D$30 -> 0.33924899
A13: ='2025.12'!$N$2 -> 2025.12 | B13: ='2025.12'!$B$30-'2025.12'!$G$30 -> 3.28 | C13: =C12+B13 -> 45.64 | D13: ='2025.12'!$D$30-'2025.12'!$I$30 -> 0.33920741 | E13: =E12+D13 -> 5.2644693 | F13: 9.927 | G13: =E13*F13 -> 52.260386 | H13: =G13-C13 -> 6.6203863 | I13: =(G13-C13)/C13 -> 0.14505667 | J13: ='2025.12'!$L$30 -> 0 | AA13: ='2025.12'!$B$30 -> 3.28 | AB13: ='2025.12'!$C$30 -> 9.6696 | AC13: ='2025.12'!$D$30 -> 0.33920741
A14: ='2026.01'!$N$2 -> 2026.01 | B14: ='2026.01'!$B$30-'2026.01'!$G$30 -> 3.35 | C14: =C13+B14 -> 48.99 | D14: ='2026.01'!$D$30-'2026.01'!$I$30 -> 0.33135837 | E14: =E13+D14 -> 5.5958276 | F14: 10.24 | G14: =E14*F14 -> 57.301275 | H14: =G14-C14 -> 8.3112749 | I14: =(G14-C14)/C14 -> 0.16965248 | J14: ='2026.01'!$L$30 -> 0 | AA14: ='2026.01'!$B$30 -> 3.35 | AB14: ='2026.01'!$C$30 -> 10.1099 | AC14: ='2026.01'!$D$30 -> 0.33135837
A15: ='2026.02'!$N$2 -> 2026.02 | B15: ='2026.02'!$B$30-'2026.02'!$G$30 -> 3.4 | C15: =C14+B15 -> 52.39 | D15: ='2026.02'!$D$30-'2026.02'!$I$30 -> 0.32766979 | E15: =E14+D15 -> 5.9234974 | F15: 10.58 | G15: =E15*F15 -> 62.670603 | H15: =G15-C15 -> 10.280603 | I15: =(G15-C15)/C15 -> 0.19623216 | J15: ='2026.02'!$L$30 -> 0 | AA15: ='2026.02'!$B$30 -> 3.4 | AB15: ='2026.02'!$C$30 -> 10.3763 | AC15: ='2026.02'!$D$30 -> 0.32766979
A16: ='2026.03'!$N$2 -> 2026.03 | B16: ='2026.03'!$B$30-'2026.03'!$G$30 -> 3.42 | C16: =C15+B16 -> 55.81 | D16: ='2026.03'!$D$30-'2026.03'!$I$30 -> 0.33814515 | E16: =E15+D16 -> 6.2616426 | F16: 9.741 | G16: =E16*F16 -> 60.99466 | H16: =G16-C16 -> 5.1846602 | I16: =(G16-C16)/C16 -> 0.092898409 | J16: ='2026.03'!$L$30 -> 0 | AA16: ='2026.03'!$B$30 -> 3.42 | AB16: ='2026.03'!$C$30 -> 10.114 | AC16: ='2026.03'!$D$30 -> 0.33814515
A17: ='2026.04'!$N$2 -> 2026.04 | B17: ='2026.04'!$B$30-'2026.04'!$G$30 -> 3.43 | C17: =C16+B17 -> 59.24 | D17: ='2026.04'!$D$30-'2026.04'!$I$30 -> 0.34417018 | E17: =E16+D17 -> 6.6058127 | F17: 10.126 | G17: =E17*F17 -> 66.89046 | H17: =G17-C17 -> 7.6504598 | I17: =(G17-C17)/C17 -> 0.12914348 | J17: ='2026.04'!$L$30 -> 0 | AA17: ='2026.04'!$B$30 -> 3.43 | AB17: ='2026.04'!$C$30 -> 9.966 | AC17: ='2026.04'!$D$30 -> 0.34417018
A18: ='2026.05'!$N$2 -> 2026.05 | B18: ='2026.05'!$B$29-'2026.05'!$G$29 -> 3.23 | C18: =C17+B18 -> 62.47 | D18: ='2026.05'!$D$29-'2026.05'!$I$29 -> 0.31608717 | E18: =E17+D18 -> 6.9218999 | F18: 10.64 | G18: =E18*F18 -> 73.649015 | H18: =G18-C18 -> 11.179015 | I18: =(G18-C18)/C18 -> 0.17895014 | J18: ='2026.05'!$L$29 -> 0 | AA18: ='2026.05'!$B$29 -> 3.23 | AB18: ='2026.05'!$C$29 -> 10.2187 | AC18: ='2026.05'!$D$29 -> 0.31608717
A19: ='2026.06'!$N$2 -> 2026.06 | B19: ='2026.06'!$B$29-'2026.06'!$G$29 -> 3.16 | C19: =C18+B19 -> 65.63 | D19: ='2026.06'!$D$29-'2026.06'!$I$29 -> 0.29625185 | E19: =E18+D19 -> 7.2181518 | F19: 10.982 | G19: =E19*F19 -> 79.269743 | H19: =G19-C19 -> 13.639743 | I19: =(G19-C19)/C19 -> 0.20782786 | J19: ='2026.06'!$L$29 -> 0 | AA19: ='2026.06'!$B$29 -> 3.16 | AB19: ='2026.06'!$C$29 -> 10.6666 | AC19: ='2026.06'!$D$29 -> 0.29625185
A20: ='2026.07'!$N$2 -> 2026.07 | B20: ='2026.07'!$B$29 -> 3.25 | C20: =C19+B20 -> 68.88 | D20: ='2026.07'!$D$29 -> 0.29263461 | E20: =E19+D20 -> 7.5107864 | F20: 10.8716 | G20: =E20*F20 -> 81.654265 | H20: =G20-C20 -> 12.774265 | I20: =(G20-C20)/C20 -> 0.18545681 | J20: ='2026.07'!$L$29 -> 0

Sheet AYEM
A1: AYEM GY iShares MSCI EM IMI ESG Screened
A3: Data | B3: Suma, EUR | D3: Kiekis | F3: Mėnesio gale | J3: Dividendai | L3: AYEM | M3: Įnešta | N3: Kiekis | O3: Parduota | P3: Pelnas | Q3: % | R3: Dividendai | S3: Vid. Kaina | AA3: Suma | AB3: Kaina | AC3: Kiekis
B4: Įnešta | C4: Viso | D4: Mėnesio | E4: Viso | F4: Kaina | G4: Vertė | H4: Pelnas | I4: %
A5: ='2025.04'!$N$2 -> 2025.04 | B5: ='2025.04'!$B$40-'2025.04'!$G$40 -> 13.59 | C5: =B5 -> 13.59 | D5: ='2025.04'!$D$40-'2025.04'!$I$40 -> 2.4344129 | E5: =D5 -> 2.4344129 | F5: 5.961 | G5: =E5*F5 -> 14.511535 | H5: =G5-C5 -> 0.92153523 | I5: =(G5-C5)/C5 -> 0.067809804 | J5: ='2025.04'!$L$40 -> 0 | L5: Viso: | M5: =SUM(B5:B200) -> 52.18 | N5: =SUM(D5:D200) -> 7.6244398 | O5: 68.32 | P5: =IF(O5>0,O5-M5,"") -> 16.14 | Q5: =IF(O5>0,(O5-M5)/M5,"") -> 0.30931391 | R5: =SUM(J5:J200) -> 0 | S5: {=SUMPRODUCT(IFERROR(AB5:AB200,0),IFERROR(AC5:AC200,0))/SUM(IFERROR(AC5:AC200,0))} -> 6.7480056 | AA5: ='2025.04'!$B$40 -> 13.59 | AB5: ='2025.04'!$C$40 -> 5.5824548 | AC5: ='2025.04'!$D$40 -> 2.4344129
A6: ='2025.05'!$N$2 -> 2025.05 | B6: ='2025.05'!$B$40-'2025.05'!$G$40 -> 5.51 | C6: =C5+B6 -> 19.1 | D6: ='2025.05'!$D$40-'2025.05'!$I$40 -> 0.8727016 | E6: =E5+D6 -> 3.3071145 | F6: 6.237 | G6: =E6*F6 -> 20.626473 | H6: =G6-C6 -> 1.5264731 | I6: =(G6-C6)/C6 -> 0.079920058 | J6: ='2025.05'!$L$40 -> 0 | AA6: ='2025.05'!$B$40 -> 5.51 | AB6: ='2025.05'!$C$40 -> 6.3137274 | AC6: ='2025.05'!$D$40 -> 0.8727016
A7: ='2025.06'!$N$2 -> 2025.06 | B7: ='2025.06'!$B$40-'2025.06'!$G$40 -> 1.2 | C7: =C6+B7 -> 20.3 | D7: ='2025.06'!$D$40-'2025.06'!$I$40 -> 0.19224607 | E7: =E6+D7 -> 3.4993606 | F7: 6.424 | G7: =E7*F7 -> 22.479892 | H7: =G7-C7 -> 2.1798923 | I7: =(G7-C7)/C7 -> 0.10738386 | J7: ='2025.06'!$L$40 -> 0 | AA7: ='2025.06'!$B$40 -> 1.2 | AB7: ='2025.06'!$C$40 -> 6.242 | AC7: ='2025.06'!$D$40 -> 0.19224607
A8: ='2025.07'!$N$2 -> 2025.07 | B8: ='2025.07'!$B$40-'2025.07'!$G$40 -> 1.82 | C8: =C7+B8 -> 22.12 | D8: ='2025.07'!$D$40-'2025.07'!$I$40 -> 0.28249026 | E8: =E7+D8 -> 3.7818508 | F8: 6.688 | G8: =E8*F8 -> 25.293018 | H8: =G8-C8 -> 3.1730183 | I8: =(G8-C8)/C8 -> 0.14344568 | J8: ='2025.07'!$L$40 -> 0 | AA8: ='2025.07'!$B$40 -> 1.82 | AB8: ='2025.07'!$C$40 -> 6.4427 | AC8: ='2025.07'!$D$40 -> 0.28249026
A9: ='2025.08'!$N$2 -> 2025.08 | B9: ='2025.08'!$B$40-'2025.08'!$G$40 -> 1.83 | C9: =C8+B9 -> 23.95 | D9: ='2025.08'!$D$40-'2025.08'!$I$40 -> 0.2753536 | E9: =E8+D9 -> 4.0572044 | F9: 6.672 | G9: =E9*F9 -> 27.069668 | H9: =G9-C9 -> 3.1196679 | I9: =(G9-C9)/C9 -> 0.13025753 | J9: ='2025.08'!$L$40 -> 0 | AA9: ='2025.08'!$B$40 -> 1.83 | AB9: ='2025.08'!$C$40 -> 6.646 | AC9: ='2025.08'!$D$40 -> 0.2753536
A10: ='2025.09'!$N$2 -> 2025.09 | B10: ='2025.09'!$B$40-'2025.09'!$G$40 -> 1.82 | C10: =C9+B10 -> 25.77 | D10: ='2025.09'!$D$40-'2025.09'!$I$40 -> 0.27241431 | E10: =E9+D10 -> 4.3296187 | F10: 7.035 | G10: =E10*F10 -> 30.458868 | H10: =G10-C10 -> 4.6888678 | I10: =(G10-C10)/C10 -> 0.18195063 | J10: ='2025.09'!$L$40 -> 0 | AA10: ='2025.09'!$B$40 -> 1.82 | AB10: ='2025.09'!$C$40 -> 6.681 | AC10: ='2025.09'!$D$40 -> 0.27241431
A11: ='2025.10'!$N$2 -> 2025.10 | B11: ='2025.10'!$B$40-'2025.10'!$G$40 -> 2.5 | C11: =C10+B11 -> 28.27 | D11: ='2025.10'!$D$40-'2025.10'!$I$40 -> 0.34559027 | E11: =E10+D11 -> 4.675209 | F11: 7.432 | G11: =E11*F11 -> 34.746153 | H11: =G11-C11 -> 6.4761533 | I11: =(G11-C11)/C11 -> 0.22908218 | J11: ='2025.10'!$L$40 -> 0 | AA11: ='2025.10'!$B$40 -> 2.5 | AB11: ='2025.10'!$C$40 -> 7.234 | AC11: ='2025.10'!$D$40 -> 0.34559027
A12: ='2025.11'!$N$2 -> 2025.11 | B12: ='2025.11'!$B$40-'2025.11'!$G$40 -> 2.51 | C12: =C11+B12 -> 30.78 | D12: ='2025.11'!$D$40-'2025.11'!$I$40 -> 0.3404313 | E12: =E11+D12 -> 5.0156403 | F12: 7.313 | G12: =E12*F12 -> 36.679378 | H12: =G12-C12 -> 5.8993776 | I12: =(G12-C12)/C12 -> 0.19166269 | J12: ='2025.11'!$L$40 -> 0 | AA12: ='2025.11'!$B$40 -> 2.51 | AB12: ='2025.11'!$C$40 -> 7.373 | AC12: ='2025.11'!$D$40 -> 0.3404313
A13: ='2025.12'!$N$2 -> 2025.12 | B13: ='2025.12'!$B$40-'2025.12'!$G$40 -> 2.49 | C13: =C12+B13 -> 33.27 | D13: ='2025.12'!$D$40-'2025.12'!$I$40 -> 0.34143265 | E13: =E12+D13 -> 5.357073 | F13: 7.35 | G13: =E13*F13 -> 39.374486 | H13: =G13-C13 -> 6.1044862 | I13: =(G13-C13)/C13 -> 0.1834832 | J13: ='2025.12'!$L$40 -> 0 | AA13: ='2025.12'!$B$40 -> 2.49 | AB13: ='2025.12'!$C$40 -> 7.2928 | AC13: ='2025.12'!$D$40 -> 0.34143265
A14: ='2026.01'!$N$2 -> 2026.01 | B14: ='2026.01'!$B$40-'2026.01'!$G$40 -> 2.56 | C14: =C13+B14 -> 35.83 | D14: ='2026.01'!$D$40-'2026.01'!$I$40 -> 0.33342016 | E14: =E13+D14 -> 5.6904931 | F14: 7.891 | G14: =E14*F14 -> 44.903681 | H14: =G14-C14 -> 9.0736812 | I14: =(G14-C14)/C14 -> 0.25324257 | J14: ='2026.01'!$L$40 -> 0 | AA14: ='2026.01'!$B$40 -> 2.56 | AB14: ='2026.01'!$C$40 -> 7.678 | AC14: ='2026.01'!$D$40 -> 0.33342016
A15: ='2026.02'!$N$2 -> 2026.02 | B15: ='2026.02'!$B$40-'2026.02'!$G$40 -> 2.62 | C15: =C14+B15 -> 38.45 | D15: ='2026.02'!$D$40-'2026.02'!$I$40 -> 0.32765564 | E15: =E14+D15 -> 6.0181488 | F15: 8.392 | G15: =E15*F15 -> 50.504304 | H15: =G15-C15 -> 12.054304 | I15: =(G15-C15)/C15 -> 0.31350596 | J15: ='2026.02'!$L$40 -> 0 | AA15: ='2026.02'!$B$40 -> 2.62 | AB15: ='2026.02'!$C$40 -> 7.9962 | AC15: ='2026.02'!$D$40 -> 0.32765564
A16: ='2026.03'!$N$2 -> 2026.03 | B16: ='2026.03'!$B$40-'2026.03'!$G$40 -> 2.72 | C16: =C15+B16 -> 41.17 | D16: ='2026.03'!$D$40-'2026.03'!$I$40 -> 0.34234075 | E16: =E15+D16 -> 6.3604895 | F16: 7.516 | G16: =E16*F16 -> 47.805439 | H16: =G16-C16 -> 6.6354391 | I16: =(G16-C16)/C16 -> 0.16117171 | J16: ='2026.03'!$L$40 -> 0 | AA16: ='2026.03'!$B$40 -> 2.72 | AB16: ='2026.03'!$C$40 -> 7.9453 | AC16: ='2026.03'!$D$40 -> 0.34234075
A17: ='2026.04'!$N$2 -> 2026.04 | B17: ='2026.04'!$B$40-'2026.04'!$G$40 -> 2.65 | C17: =C16+B17 -> 43.82 | D17: ='2026.04'!$D$40-'2026.04'!$I$40 -> 0.34363816 | E17: =E16+D17 -> 6.7041277 | F17: 8.424 | G17: =E17*F17 -> 56.475571 | H17: =G17-C17 -> 12.655571 | I17: =(G17-C17)/C17 -> 0.28880811 | J17: ='2026.04'!$L$40 -> 0 | AA17: ='2026.04'!$B$40 -> 2.65 | AB17: ='2026.04'!$C$40 -> 7.7116 | AC17: ='2026.04'!$D$40 -> 0.34363816
A18: ='2026.05'!$N$2 -> 2026.05 | B18: ='2026.05'!$B$39-'2026.05'!$G$39 -> 2.75 | C18: =C17+B18 -> 46.57 | D18: ='2026.05'!$D$39-'2026.05'!$I$39 -> 0.3185525 | E18: =E17+D18 -> 7.0226802 | F18: 9.24 | G18: =E18*F18 -> 64.889565 | H18: =G18-C18 -> 18.319565 | I18: =(G18-C18)/C18 -> 0.39337695 | J18: ='2026.05'!$L$39 -> 0 | AA18: ='2026.05'!$B$39 -> 2.75 | AB18: ='2026.05'!$C$39 -> 8.6328 | AC18: ='2026.05'!$D$39 -> 0.3185525
A19: ='2026.06'!$N$2 -> 2026.06 | B19: ='2026.06'!$B$39-'2026.06'!$G$39 -> 2.84 | C19: =C18+B19 -> 49.41 | D19: ='2026.06'!$D$39-'2026.06'!$I$39 -> 0.29948329 | E19: =E18+D19 -> 7.3221634 | F19: 9.436 | G19: =E19*F19 -> 69.091934 | H19: =G19-C19 -> 19.681934 | I19: =(G19-C19)/C19 -> 0.39833909 | J19: ='2026.06'!$L$39 -> 0 | AA19: ='2026.06'!$B$39 -> 2.84 | AB19: ='2026.06'!$C$39 -> 9.483 | AC19: ='2026.06'!$D$39 -> 0.29948329
A20: ='2026.07'!$N$2 -> 2026.07 | B20: ='2026.07'!$B$39 -> 2.77 | C20: =C19+B20 -> 52.18 | D20: ='2026.07'!$D$39 -> 0.30227635 | E20: =E19+D20 -> 7.6244398 | F20: 8.961 | G20: =E20*F20 -> 68.322605 | H20: =G20-C20 -> 16.142605 | I20: =(G20-C20)/C20 -> 0.30936384 | J20: ='2026.07'!$L$39 -> 0

Sheet SGAJ
A1: SGAJ GY iShares MSCI Japan ESG Screened
A3: Data | B3: Suma, EUR | D3: Kiekis | F3: Mėnesio gale | J3: Dividendai | L3: SGAJ | M3: Įnešta | N3: Kiekis | O3: Parduota | P3: Pelnas | Q3: % | R3: Dividendai | S3: Vid. Kaina | AA3: Suma | AB3: Kaina | AC3: Kiekis
B4: Įnešta | C4: Viso | D4: Mėnesio | E4: Viso | F4: Kaina | G4: Vertė | H4: Pelnas | I4: %
A5: ='2025.04'!$N$2 -> 2025.04 | B5: ='2025.04'!$B$50-'2025.04'!$G$50 -> 6.02 | C5: =B5 -> 6.02 | D5: ='2025.04'!$D$50-'2025.04'!$I$50 -> 1.0564056 | E5: =D5 -> 1.0564056 | F5: 6.179 | G5: =E5*F5 -> 6.5275304 | H5: =G5-C5 -> 0.50753037 | I5: =(G5-C5)/C5 -> 0.084307371 | J5: ='2025.04'!$L$50 -> 0 | L5: Viso: | M5: =SUM(B5:B200) -> 22.8 | N5: =SUM(D5:D200) -> 3.414462 | O5: 29.11 | P5: =IF(O5>0,O5-M5,"") -> 6.31 | Q5: =IF(O5>0,(O5-M5)/M5,"") -> 0.27675439 | R5: =SUM(J5:J200) -> 0 | S5: {=SUMPRODUCT(IFERROR(AB5:AB200,0),IFERROR(AC5:AC200,0))/SUM(IFERROR(AC5:AC200,0))} -> 6.5997734 | AA5: ='2025.04'!$B$50 -> 6.02 | AB5: ='2025.04'!$C$50 -> 5.6985687 | AC5: ='2025.04'!$D$50 -> 1.0564056
A6: ='2025.05'!$N$2 -> 2025.05 | B6: ='2025.05'!$B$50-'2025.05'!$G$50 -> 2.49 | C6: =C5+B6 -> 8.51 | D6: ='2025.05'!$D$50-'2025.05'!$I$50 -> 0.39199757 | E6: =E5+D6 -> 1.4484032 | F6: 6.413 | G6: =E6*F6 -> 9.2886097 | H6: =G6-C6 -> 0.7786097 | I6: =(G6-C6)/C6 -> 0.091493501 | J6: ='2025.05'!$L$50 -> 0 | AA6: ='2025.05'!$B$50 -> 2.49 | AB6: ='2025.05'!$C$50 -> 6.3520802 | AC6: ='2025.05'!$D$50 -> 0.39199757
A7: ='2025.06'!$N$2 -> 2025.06 | B7: ='2025.06'!$B$50-'2025.06'!$G$50 -> 0.56 | C7: =C6+B7 -> 9.07 | D7: ='2025.06'!$D$50-'2025.06'!$I$50 -> 0.087646534 | E7: =E6+D7 -> 1.5360497 | F7: 6.321 | G7: =E7*F7 -> 9.7093703 | H7: =G7-C7 -> 0.63937034 | I7: =(G7-C7)/C7 -> 0.070492871 | J7: ='2025.06'!$L$50 -> 0 | AA7: ='2025.06'!$B$50 -> 0.56 | AB7: ='2025.06'!$C$50 -> 6.3893 | AC7: ='2025.06'!$D$50 -> 0.087646534
A8: ='2025.07'!$N$2 -> 2025.07 | B8: ='2025.07'!$B$50-'2025.07'!$G$50 -> 0.82 | C8: =C7+B8 -> 9.89 | D8: ='2025.07'!$D$50-'2025.07'!$I$50 -> 0.13038639 | E8: =E7+D8 -> 1.6664361 | F8: 6.388 | G8: =E8*F8 -> 10.645194 | H8: =G8-C8 -> 0.75519393 | I8: =(G8-C8)/C8 -> 0.076359346 | J8: ='2025.07'!$L$50 -> 0 | AA8: ='2025.07'!$B$50 -> 0.82 | AB8: ='2025.07'!$C$50 -> 6.289 | AC8: ='2025.07'!$D$50 -> 0.13038639
A9: ='2025.08'!$N$2 -> 2025.08 | B9: ='2025.08'!$B$50-'2025.08'!$G$50 -> 0.81 | C9: =C8+B9 -> 10.7 | D9: ='2025.08'!$D$50-'2025.08'!$I$50 -> 0.12573735 | E9: =E8+D9 -> 1.7921735 | F9: 6.621 | G9: =E9*F9 -> 11.865981 | H9: =G9-C9 -> 1.1659805 | I9: =(G9-C9)/C9 -> 0.10897014 | J9: ='2025.08'!$L$50 -> 0 | AA9: ='2025.08'!$B$50 -> 0.81 | AB9: ='2025.08'!$C$50 -> 6.442 | AC9: ='2025.08'!$D$50 -> 0.12573735
A10: ='2025.09'!$N$2 -> 2025.09 | B10: ='2025.09'!$B$50-'2025.09'!$G$50 -> 0.82 | C10: =C9+B10 -> 11.52 | D10: ='2025.09'!$D$50-'2025.09'!$I$50 -> 0.12386707 | E10: =E9+D10 -> 1.9160405 | F10: 6.737 | G10: =E10*F10 -> 12.908365 | H10: =G10-C10 -> 1.3883651 | I10: =(G10-C10)/C10 -> 0.1205178 | J10: ='2025.09'!$L$50 -> 0 | AA10: ='2025.09'!$B$50 -> 0.82 | AB10: ='2025.09'!$C$50 -> 6.62 | AC10: ='2025.09'!$D$50 -> 0.12386707
A11: ='2025.10'!$N$2 -> 2025.10 | B11: ='2025.10'!$B$50-'2025.10'!$G$50 -> 1.12 | C11: =C10+B11 -> 12.64 | D11: ='2025.10'!$D$50-'2025.10'!$I$50 -> 0.16071172 | E11: =E10+D11 -> 2.0767523 | F11: 7.139 | G11: =E11*F11 -> 14.825934 | H11: =G11-C11 -> 2.1859344 | I11: =(G11-C11)/C11 -> 0.17293785 | J11: ='2025.10'!$L$50 -> 0 | AA11: ='2025.10'!$B$50 -> 1.12 | AB11: ='2025.10'!$C$50 -> 6.969 | AC11: ='2025.10'!$D$50 -> 0.16071172
A12: ='2025.11'!$N$2 -> 2025.11 | B12: ='2025.11'!$B$50-'2025.11'!$G$50 -> 1.1 | C12: =C11+B12 -> 13.74 | D12: ='2025.11'!$D$50-'2025.11'!$I$50 -> 0.15426688 | E12: =E11+D12 -> 2.2310191 | F12: 7.061 | G12: =E12*F12 -> 15.753226 | H12: =G12-C12 -> 2.0132262 | I12: =(G12-C12)/C12 -> 0.14652301 | J12: ='2025.11'!$L$50 -> 0 | AA12: ='2025.11'!$B$50 -> 1.1 | AB12: ='2025.11'!$C$50 -> 7.1305 | AC12: ='2025.11'!$D$50 -> 0.15426688
A13: ='2025.12'!$N$2 -> 2025.12 | B13: ='2025.12'!$B$50-'2025.12'!$G$50 -> 1.09 | C13: =C12+B13 -> 14.83 | D13: ='2025.12'!$D$50-'2025.12'!$I$50 -> 0.15507185 | E13: =E12+D13 -> 2.386091 | F13: 7.095 | G13: =E13*F13 -> 16.929316 | H13: =G13-C13 -> 2.0993156 | I13: =(G13-C13)/C13 -> 0.1415587 | J13: ='2025.12'!$L$50 -> 0 | AA13: ='2025.12'!$B$50 -> 1.09 | AB13: ='2025.12'!$C$50 -> 7.029 | AC13: ='2025.12'!$D$50 -> 0.15507185
A14: ='2026.01'!$N$2 -> 2026.01 | B14: ='2026.01'!$B$50-'2026.01'!$G$50 -> 1.1 | C14: =C13+B14 -> 15.93 | D14: ='2026.01'!$D$50-'2026.01'!$I$50 -> 0.15062303 | E14: =E13+D14 -> 2.536714 | F14: 7.399 | G14: =E14*F14 -> 18.769147 | H14: =G14-C14 -> 2.839147 | I14: =(G14-C14)/C14 -> 0.17822643 | J14: ='2026.01'!$L$50 -> 0 | AA14: ='2026.01'!$B$50 -> 1.1 | AB14: ='2026.01'!$C$50 -> 7.303 | AC14: ='2026.01'!$D$50 -> 0.15062303
A15: ='2026.02'!$N$2 -> 2026.02 | B15: ='2026.02'!$B$50-'2026.02'!$G$50 -> 1.11 | C15: =C14+B15 -> 17.04 | D15: ='2026.02'!$D$50-'2026.02'!$I$50 -> 0.14742994 | E15: =E14+D15 -> 2.684144 | F15: 7.999 | G15: =E15*F15 -> 21.470468 | H15: =G15-C15 -> 4.4304675 | I15: =(G15-C15)/C15 -> 0.26000396 | J15: ='2026.02'!$L$50 -> 0 | AA15: ='2026.02'!$B$50 -> 1.11 | AB15: ='2026.02'!$C$50 -> 7.529 | AC15: ='2026.02'!$D$50 -> 0.14742994
A16: ='2026.03'!$N$2 -> 2026.03 | B16: ='2026.03'!$B$50-'2026.03'!$G$50 -> 1.17 | C16: =C15+B16 -> 18.21 | D16: ='2026.03'!$D$50-'2026.03'!$I$50 -> 0.15612073 | E16: =E15+D16 -> 2.8402647 | F16: 7.307 | G16: =E16*F16 -> 20.753814 | H16: =G16-C16 -> 2.5438141 | I16: =(G16-C16)/C16 -> 0.13969325 | J16: ='2026.03'!$L$50 -> 0 | AA16: ='2026.03'!$B$50 -> 1.17 | AB16: ='2026.03'!$C$50 -> 7.4942 | AC16: ='2026.03'!$D$50 -> 0.15612073
A17: ='2026.04'!$N$2 -> 2026.04 | B17: ='2026.04'!$B$50-'2026.04'!$G$50 -> 1.18 | C17: =C16+B17 -> 19.39 | D17: ='2026.04'!$D$50-'2026.04'!$I$50 -> 0.1574593 | E17: =E16+D17 -> 2.997724 | F17: 7.63 | G17: =E17*F17 -> 22.872634 | H17: =G17-C17 -> 3.482634 | I17: =(G17-C17)/C17 -> 0.1796098 | J17: ='2026.04'!$L$50 -> 0 | AA17: ='2026.04'!$B$50 -> 1.18 | AB17: ='2026.04'!$C$50 -> 7.494 | AC17: ='2026.04'!$D$50 -> 0.1574593
A18: ='2026.05'!$N$2 -> 2026.05 | B18: ='2026.05'!$B$49-'2026.05'!$G$49 -> 1.13 | C18: =C17+B18 -> 20.52 | D18: ='2026.05'!$D$49-'2026.05'!$I$49 -> 0.14524422 | E18: =E17+D18 -> 3.1429682 | F18: 8.209 | G18: =E18*F18 -> 25.800626 | H18: =G18-C18 -> 5.280626 | I18: =(G18-C18)/C18 -> 0.25734045 | J18: ='2026.05'!$L$49 -> 0 | AA18: ='2026.05'!$B$49 -> 1.13 | AB18: ='2026.05'!$C$49 -> 7.78 | AC18: ='2026.05'!$D$49 -> 0.14524422
A19: ='2026.06'!$N$2 -> 2026.06 | B19: ='2026.06'!$B$49-'2026.06'!$G$49 -> 1.12 | C19: =C18+B19 -> 21.64 | D19: ='2026.06'!$D$49-'2026.06'!$I$49 -> 0.13593223 | E19: =E18+D19 -> 3.2789004 | F19: 8.502 | G19: =E19*F19 -> 27.877211 | H19: =G19-C19 -> 6.2372115 | I19: =(G19-C19)/C19 -> 0.28822604 | J19: ='2026.06'!$L$49 -> 0 | AA19: ='2026.06'!$B$49 -> 1.12 | AB19: ='2026.06'!$C$49 -> 8.2394 | AC19: ='2026.06'!$D$49 -> 0.13593223
A20: ='2026.07'!$N$2 -> 2026.07 | B20: ='2026.07'!$B$49 -> 1.16 | C20: =C19+B20 -> 22.8 | D20: ='2026.07'!$D$49 -> 0.13556153 | E20: =E19+D20 -> 3.414462 | F20: 8.525 | G20: =E20*F20 -> 29.108288 | H20: =G20-C20 -> 6.3082882 | I20: =(G20-C20)/C20 -> 0.27667931 | J20: ='2026.07'!$L$49 -> 0

Sheet EDMU
A1: EDMU GY iShares MSCI USA ESG Enhanced
A3: Data | B3: Suma, EUR | D3: Kiekis | F3: Mėnesio gale | J3: Dividendai | L3: SGAJ | M3: Įnešta | N3: Kiekis | O3: Parduota | P3: Pelnas | Q3: % | R3: Dividendai | S3: Vid. Kaina | AA3: Suma | AB3: Kaina | AC3: Kiekis
B4: Įnešta | C4: Viso | D4: Mėnesio | E4: Viso | F4: Kaina | G4: Vertė | H4: Pelnas | I4: %
A5: ='2025.04'!$N$2 -> 2025.04 | B5: ='2025.04'!$B$60-'2025.04'!$G$60 -> 35.65 | C5: =B5 -> 35.65 | D5: ='2025.04'!$D$60-'2025.04'!$I$60 -> 4.2148669 | E5: =D5 -> 4.2148669 | F5: 8.775 | G5: =E5*F5 -> 36.985457 | H5: =G5-C5 -> 1.3354573 | I5: =(G5-C5)/C5 -> 0.037460233 | J5: ='2025.04'!$L$60 -> 0 | L5: Viso: | M5: =SUM(B5:B200) -> 131.43 | N5: =SUM(D5:D200) -> 13.487338 | O5: 159.41 | P5: =IF(O5>0,O5-M5,"") -> 27.98 | Q5: =IF(O5>0,(O5-M5)/M5,"") -> 0.21288899 | R5: =SUM(J5:J200) -> 0 | S5: {=SUMPRODUCT(IFERROR(AB5:AB200,0),IFERROR(AC5:AC200,0))/SUM(IFERROR(AC5:AC200,0))} -> 9.6588768 | AA5: ='2025.04'!$B$60 -> 35.65 | AB5: ='2025.04'!$C$60 -> 8.4581555 | AC5: ='2025.04'!$D$60 -> 4.2148669
A6: ='2025.05'!$N$2 -> 2025.05 | B6: ='2025.05'!$B$60-'2025.05'!$G$60 -> 14.64 | C6: =C5+B6 -> 50.29 | D6: ='2025.05'!$D$60-'2025.05'!$I$60 -> 1.556211 | E6: =E5+D6 -> 5.771078 | F6: 9.39 | G6: =E6*F6 -> 54.190422 | H6: =G6-C6 -> 3.900422 | I6: =(G6-C6)/C6 -> 0.077558599 | J6: ='2025.05'!$L$60 -> 0 | AA6: ='2025.05'!$B$60 -> 14.64 | AB6: ='2025.05'!$C$60 -> 9.4074645 | AC6: ='2025.05'!$D$60 -> 1.556211
A7: ='2025.06'!$N$2 -> 2025.06 | B7: ='2025.06'!$B$60-'2025.06'!$G$60 -> 3.22 | C7: =C6+B7 -> 53.51 | D7: ='2025.06'!$D$60-'2025.06'!$I$60 -> 0.34416417 | E7: =E6+D7 -> 6.1152421 | F7: 9.5 | G7: =E7*F7 -> 58.0948 | H7: =G7-C7 -> 4.5848002 | I7: =(G7-C7)/C7 -> 0.085681184 | J7: ='2025.06'!$L$60 -> 0 | AA7: ='2025.06'!$B$60 -> 3.22 | AB7: ='2025.06'!$C$60 -> 9.356 | AC7: ='2025.06'!$D$60 -> 0.34416417
A8: ='2025.07'!$N$2 -> 2025.07 | B8: ='2025.07'!$B$60-'2025.07'!$G$60 -> 4.82 | C8: =C7+B8 -> 58.33 | D8: ='2025.07'!$D$60-'2025.07'!$I$60 -> 0.50806367 | E8: =E7+D8 -> 6.6233058 | F8: 10.086 | G8: =E8*F8 -> 66.802662 | H8: =G8-C8 -> 8.4726622 | I8: =(G8-C8)/C8 -> 0.14525394 | J8: ='2025.07'!$L$60 -> 0 | AA8: ='2025.07'!$B$60 -> 4.82 | AB8: ='2025.07'!$C$60 -> 9.487 | AC8: ='2025.07'!$D$60 -> 0.50806367
A9: ='2025.08'!$N$2 -> 2025.08 | B9: ='2025.08'!$B$60-'2025.08'!$G$60 -> 4.88 | C9: =C8+B9 -> 63.21 | D9: ='2025.08'!$D$60-'2025.08'!$I$60 -> 0.49161831 | E9: =E8+D9 -> 7.1149241 | F9: 9.96 | G9: =E9*F9 -> 70.864644 | H9: =G9-C9 -> 7.654644 | I9: =(G9-C9)/C9 -> 0.12109862 | J9: ='2025.08'!$L$60 -> 0 | AA9: ='2025.08'!$B$60 -> 4.88 | AB9: ='2025.08'!$C$60 -> 9.9264 | AC9: ='2025.08'!$D$60 -> 0.49161831
A10: ='2025.09'!$N$2 -> 2025.09 | B10: ='2025.09'!$B$60-'2025.09'!$G$60 -> 4.86 | C10: =C9+B10 -> 68.07 | D10: ='2025.09'!$D$60-'2025.09'!$I$60 -> 0.48847167 | E10: =E9+D10 -> 7.6033958 | F10: 10.22 | G10: =E10*F10 -> 77.706705 | H10: =G10-C10 -> 9.6367047 | I10: =(G10-C10)/C10 -> 0.14157051 | J10: ='2025.09'!$L$60 -> 0 | AA10: ='2025.09'!$B$60 -> 4.86 | AB10: ='2025.09'!$C$60 -> 9.9494 | AC10: ='2025.09'!$D$60 -> 0.48847167
A11: ='2025.10'!$N$2 -> 2025.10 | B11: ='2025.10'!$B$60-'2025.10'!$G$60 -> 6.43 | C11: =C10+B11 -> 74.5 | D11: ='2025.10'!$D$60-'2025.10'!$I$60 -> 0.61794837 | E11: =E10+D11 -> 8.2213441 | F11: 10.676 | G11: =E11*F11 -> 87.77107 | H11: =G11-C11 -> 13.27107 | I11: =(G11-C11)/C11 -> 0.17813517 | J11: ='2025.10'!$L$60 -> 0 | AA11: ='2025.10'!$B$60 -> 6.43 | AB11: ='2025.10'!$C$60 -> 10.4054 | AC11: ='2025.10'!$D$60 -> 0.61794837
A12: ='2025.11'!$N$2 -> 2025.11 | B12: ='2025.11'!$B$60-'2025.11'!$G$60 -> 6.45 | C12: =C11+B12 -> 80.95 | D12: ='2025.11'!$D$60-'2025.11'!$I$60 -> 0.60753341 | E12: =E11+D12 -> 8.8288776 | F12: 10.614 | G12: =E12*F12 -> 93.709706 | H12: =G12-C12 -> 12.759706 | I12: =(G12-C12)/C12 -> 0.15762454 | J12: ='2025.11'!$L$60 -> 0 | AA12: ='2025.11'!$B$60 -> 6.45 | AB12: ='2025.11'!$C$60 -> 10.6167 | AC12: ='2025.11'!$D$60 -> 0.60753341
A13: ='2025.12'!$N$2 -> 2025.12 | B13: ='2025.12'!$B$60-'2025.12'!$G$60 -> 6.45 | C13: =C12+B13 -> 87.4 | D13: ='2025.12'!$D$60-'2025.12'!$I$60 -> 0.60964083 | E13: =E12+D13 -> 9.4385184 | F13: 10.578 | G13: =E13*F13 -> 99.840647 | H13: =G13-C13 -> 12.440647 | I13: =(G13-C13)/C13 -> 0.1423415 | J13: ='2025.12'!$L$60 -> 0 | AA13: ='2025.12'!$B$60 -> 6.45 | AB13: ='2025.12'!$C$60 -> 10.58 | AC13: ='2025.12'!$D$60 -> 0.60964083
A14: ='2026.01'!$N$2 -> 2026.01 | B14: ='2026.01'!$B$60-'2026.01'!$G$60 -> 6.36 | C14: =C13+B14 -> 93.76 | D14: ='2026.01'!$D$60-'2026.01'!$I$60 -> 0.59977367 | E14: =E13+D14 -> 10.038292 | F14: 10.452 | G14: =E14*F14 -> 104.92023 | H14: =G14-C14 -> 11.160229 | I14: =(G14-C14)/C14 -> 0.11902974 | J14: ='2026.01'!$L$60 -> 0 | AA14: ='2026.01'!$B$60 -> 6.36 | AB14: ='2026.01'!$C$60 -> 10.604 | AC14: ='2026.01'!$D$60 -> 0.59977367
A15: ='2026.02'!$N$2 -> 2026.02 | B15: ='2026.02'!$B$60-'2026.02'!$G$60 -> 6.29 | C15: =C14+B15 -> 100.05 | D15: ='2026.02'!$D$60-'2026.02'!$I$60 -> 0.59429327 | E15: =E14+D15 -> 10.632585 | F15: 10.633 | G15: =E15*F15 -> 113.05628 | H15: =G15-C15 -> 13.00628 | I15: =(G15-C15)/C15 -> 0.1299978 | J15: ='2026.02'!$L$60 -> 0 | AA15: ='2026.02'!$B$60 -> 6.29 | AB15: ='2026.02'!$C$60 -> 10.584 | AC15: ='2026.02'!$D$60 -> 0.59429327
A16: ='2026.03'!$N$2 -> 2026.03 | B16: ='2026.03'!$B$60-'2026.03'!$G$60 -> 6.23 | C16: =C15+B16 -> 106.28 | D16: ='2026.03'!$D$60-'2026.03'!$I$60 -> 0.59880815 | E16: =E15+D16 -> 11.231393 | F16: 9.955 | G16: =E16*F16 -> 111.80852 | H16: =G16-C16 -> 5.5285221 | I16: =(G16-C16)/C16 -> 0.052018462 | J16: ='2026.03'!$L$60 -> 0 | AA16: ='2026.03'!$B$60 -> 6.23 | AB16: ='2026.03'!$C$60 -> 10.404 | AC16: ='2026.03'!$D$60 -> 0.59880815
A17: ='2026.04'!$N$2 -> 2026.04 | B17: ='2026.04'!$B$60-'2026.04'!$G$60 -> 6.29 | C17: =C16+B17 -> 112.57 | D17: ='2026.04'!$D$60-'2026.04'!$I$60 -> 0.61842493 | E17: =E16+D17 -> 11.849818 | F17: 10.9 | G17: =E17*F17 -> 129.16302 | H17: =G17-C17 -> 16.593021 | I17: =(G17-C17)/C17 -> 0.1474018 | J17: ='2026.04'!$L$60 -> 0 | AA17: ='2026.04'!$B$60 -> 6.29 | AB17: ='2026.04'!$C$60 -> 10.171 | AC17: ='2026.04'!$D$60 -> 0.61842493
A18: ='2026.05'!$N$2 -> 2026.05 | B18: ='2026.05'!$B$59-'2026.05'!$G$59 -> 6.3 | C18: =C17+B18 -> 118.87 | D18: ='2026.05'!$D$59-'2026.05'!$I$59 -> 0.57003257 | E18: =E17+D18 -> 12.419851 | F18: 11.64 | G18: =E18*F18 -> 144.56707 | H18: =G18-C18 -> 25.697065 | I18: =(G18-C18)/C18 -> 0.21617789 | J18: ='2026.05'!$L$59 -> 0 | AA18: ='2026.05'!$B$59 -> 6.3 | AB18: ='2026.05'!$C$59 -> 11.052 | AC18: ='2026.05'!$D$59 -> 0.57003257
A19: ='2026.06'!$N$2 -> 2026.06 | B19: ='2026.06'!$B$59-'2026.06'!$G$59 -> 6.3 | C19: =C18+B19 -> 125.17 | D19: ='2026.06'!$D$59-'2026.06'!$I$59 -> 0.53921275 | E19: =E18+D19 -> 12.959064 | F19: 11.77 | G19: =E19*F19 -> 152.52818 | H19: =G19-C19 -> 27.35818 | I19: =(G19-C19)/C19 -> 0.21856819 | J19: ='2026.06'!$L$59 -> 0 | AA19: ='2026.06'!$B$59 -> 6.3 | AB19: ='2026.06'!$C$59 -> 11.6837 | AC19: ='2026.06'!$D$59 -> 0.53921275
A20: ='2026.07'!$N$2 -> 2026.07 | B20: ='2026.07'!$B$59 -> 6.26 | C20: =C19+B20 -> 131.43 | D20: ='2026.07'!$D$59 -> 0.5282745 | E20: =E19+D20 -> 13.487338 | F20: 11.8193 | G20: =E20*F20 -> 159.4109 | H20: =G20-C20 -> 27.980897 | I20: =(G20-C20)/C20 -> 0.21289581 | J20: ='2026.07'!$L$59 -> 0

Sheet 2026.07
N2: 2026.07
N3: Robo-Advisor Investment
N4: Data | O4: Suma, EUR | P4: Invest. | Q4: Parduota | R4: Gryni | S4: Dividendai | T4: Mokestis
N5: 46212 | O5: 20 | P5: =B15+B25+B35+B45+B55 -> 19.98 | Q5: =G19+G29+G39+G49+G59 -> 504.8 | R5: =O5-P5+Q5 -> 504.82 | S5: =L19+L29+L39+L49+L59 -> 0
N9: Viso: | O9: =SUM(O5:O8) -> 20 | P9: =SUM(P5:P8) -> 19.98 | Q9: =SUM(Q5:Q8) -> 504.8 | R9: =SUM(R5:R8) -> 504.82 | S9: =SUM(S5:S8) -> 0 | T9: =SUM(T5:T8) -> 0
A12: SGAS GY iShares MSCI USA ESG Screened
A13: Pirkimas | F13: Pardavimas | K13: Dividendai
A14: Data | B14: Suma, EUR | C14: Kaina | D14: Kiekis | F14: Data | G14: Suma,EUR | H14: Kaina | I14: Kiekis | K14: Data | L14: Suma,EUR
A15: =N5 -> 46212 | B15: 6.54 | C15: 13.734 | D15: =B15/C15 -> 0.47619048 | F15: 46219 | G15: 166.31 | H15: 13.708 | I15: =G15/H15 -> 12.132331
A19: Viso: | B19: =SUM(B15:B18) -> 6.54 | C19: =SUMPRODUCT(C15:C18,D15:D18)/SUM(D15:D18) -> 13.734 | D19: =SUM(D15:D18) -> 0.47619048 | F19: Viso: | G19: =SUM(G15:G18) -> 166.31 | I19: =SUM(I15:I18) -> 12.132331 | K19: Viso: | L19: =SUM(L15:L18) -> 0
A22: SLMC GY iShares MSCI Europe ESG Screened
A23: Pirkimas | F23: Pardavimas | K23: Dividendai
A24: Data | B24: Suma, EUR | C24: Kaina | D24: Kiekis | F24: Data | G24: Suma,EUR | H24: Kaina | I24: Kiekis | K24: Data | L24: Suma,EUR
A25: =N5 -> 46212 | B25: 3.25 | C25: 11.106 | D25: =B25/C25 -> 0.29263461 | F25: 46219 | G25: 81.65 | H25: 10.872 | I25: =G25/H25 -> 7.5101177
A29: Viso: | B29: =SUM(B25:B28) -> 3.25 | C29: =SUMPRODUCT(C25:C28,D25:D28)/SUM(D25:D28) -> 11.106 | D29: =SUM(D25:D28) -> 0.29263461 | F29: Viso: | G29: =SUM(G25:G28) -> 81.65 | I29: =SUM(I25:I28) -> 7.5101177 | K29: Viso: | L29: =SUM(L25:L28) -> 0
A32: AYEM GY iShares MSCI EM IMI ESG Screened
A33: Pirkimas | F33: Pardavimas | K33: Dividendai
A34: Data | B34: Suma, EUR | C34: Kaina | D34: Kiekis | F34: Data | G34: Suma,EUR | H34: Kaina | I34: Kiekis | K34: Data | L34: Suma,EUR
A35: =N5 -> 46212 | B35: 2.77 | C35: 9.1638 | D35: =B35/C35 -> 0.30227635 | F35: 46219 | G35: 68.32 | H35: 8.963 | I35: =G35/H35 -> 7.6224478
A39: Viso: | B39: =SUM(B35:B38) -> 2.77 | C39: =SUMPRODUCT(C35:C38,D35:D38)/SUM(D35:D38) -> 9.1638 | D39: =SUM(D35:D38) -> 0.30227635 | F39: Viso: | G39: =SUM(G35:G38) -> 68.32 | I39: =SUM(I35:I38) -> 7.6224478 | K39: Viso: | L39: =SUM(L35:L38) -> 0
A42: SGAJ GY iShares MSCI Japan ESG Screened
A43: Pirkimas | F43: Pardavimas | K43: Dividendai
A44: Data | B44: Suma, EUR | C44: Kaina | D44: Kiekis | F44: Data | G44: Suma,EUR | H44: Kaina | I44: Kiekis | K44: Data | L44: Suma,EUR
A45: =N5 -> 46212 | B45: 1.16 | C45: 8.557 | D45: =B45/C45 -> 0.13556153 | F45: 46219 | G45: 29.11 | H45: 8.531 | I45: =G45/H45 -> 3.4122612
A49: Viso: | B49: =SUM(B45:B48) -> 1.16 | C49: =SUMPRODUCT(C45:C48,D45:D48)/SUM(D45:D48) -> 8.557 | D49: =SUM(D45:D48) -> 0.13556153 | F49: Viso: | G49: =SUM(G45:G48) -> 29.11 | I49: =SUM(I45:I48) -> 3.4122612 | K49: Viso: | L49: =SUM(L45:L48) -> 0
A52: EDMU GY iShares MSCI USA ESG Enhanced
A53: Pirkimas | F53: Pardavimas | K53: Dividendai
A54: Data | B54: Suma, EUR | C54: Kaina | D54: Kiekis | F54: Data | G54: Suma,EUR | H54: Kaina | I54: Kiekis | K54: Data | L54: Suma,EUR
A55: =N5 -> 46212 | B55: 6.26 | C55: 11.8499 | D55: =B55/C55 -> 0.5282745 | F55: 46219 | G55: 159.41 | H55: 11.8193 | I55: =G55/H55 -> 13.487262
A59: Viso: | B59: =SUM(B55:B58) -> 6.26 | C59: =SUMPRODUCT(C55:C58,D55:D58)/SUM(D55:D58) -> 11.8499 | D59: =SUM(D55:D58) -> 0.5282745 | F59: Viso: | G59: =SUM(G55:G58) -> 159.41 | I59: =SUM(I55:I58) -> 13.487262 | K59: Viso: | L59: =SUM(L55:L58) -> 0

Sheet 2026.06
N2: 2026.06
N3: Robo-Advisor Investment
N4: Data | O4: Suma, EUR | P4: Invest. | Q4: Parduota | R4: Gryni | S4: Dividendai | T4: Mokestis
N5: 46177 | O5: 20 | P5: =B15+B25+B35+B45+B55 -> 20.02 | Q5: =G19+G29+G39+G49+G59 -> 0 | R5: =O5-P5+Q5 -> -0.02 | S5: =L19+L29+L39+L49+L59 -> 0 | T5: 0.31
N9: Viso: | O9: =SUM(O5:O8) -> 20 | P9: =SUM(P5:P8) -> 20.02 | Q9: =SUM(Q5:Q8) -> 0 | R9: =SUM(R5:R8) -> -0.02 | S9: =SUM(S5:S8) -> 0 | T9: =SUM(T5:T8) -> 0.31
A12: SGAS GY iShares MSCI USA ESG Screened
A13: Pirkimas | F13: Pardavimas | K13: Dividendai
A14: Data | B14: Suma, EUR | C14: Kaina | D14: Kiekis | F14: Data | G14: Suma,EUR | H14: Kaina | I14: Kiekis | K14: Data | L14: Suma,EUR
A15: =N5 -> 46177 | B15: 6.6 | C15: 13.6021 | D15: =B15/C15 -> 0.48521919
A19: Viso: | B19: =SUM(B15:B18) -> 6.6 | C19: =SUMPRODUCT(C15:C18,D15:D18)/SUM(D15:D18) -> 13.6021 | D19: =SUM(D15:D18) -> 0.48521919 | F19: Viso: | G19: =SUM(G15:G18) -> 0 | I19: =SUM(I15:I18) -> 0 | K19: Viso: | L19: =SUM(L15:L18) -> 0
A22: SLMC GY iShares MSCI Europe ESG Screened
A23: Pirkimas | F23: Pardavimas | K23: Dividendai
A24: Data | B24: Suma, EUR | C24: Kaina | D24: Kiekis | F24: Data | G24: Suma,EUR | H24: Kaina | I24: Kiekis | K24: Data | L24: Suma,EUR
A25: =N5 -> 46177 | B25: 3.16 | C25: 10.6666 | D25: =B25/C25 -> 0.29625185
A29: Viso: | B29: =SUM(B25:B28) -> 3.16 | C29: =SUMPRODUCT(C25:C28,D25:D28)/SUM(D25:D28) -> 10.6666 | D29: =SUM(D25:D28) -> 0.29625185 | F29: Viso: | G29: =SUM(G25:G28) -> 0 | I29: =SUM(I25:I28) -> 0 | K29: Viso: | L29: =SUM(L25:L28) -> 0
A32: AYEM GY iShares MSCI EM IMI ESG Screened
A33: Pirkimas | F33: Pardavimas | K33: Dividendai
A34: Data | B34: Suma, EUR | C34: Kaina | D34: Kiekis | F34: Data | G34: Suma,EUR | H34: Kaina | I34: Kiekis | K34: Data | L34: Suma,EUR
A35: =N5 -> 46177 | B35: 2.84 | C35: 9.483 | D35: =B35/C35 -> 0.29948329
A39: Viso: | B39: =SUM(B35:B38) -> 2.84 | C39: =SUMPRODUCT(C35:C38,D35:D38)/SUM(D35:D38) -> 9.483 | D39: =SUM(D35:D38) -> 0.29948329 | F39: Viso: | G39: =SUM(G35:G38) -> 0 | I39: =SUM(I35:I38) -> 0 | K39: Viso: | L39: =SUM(L35:L38) -> 0
A42: SGAJ GY iShares MSCI Japan ESG Screened
A43: Pirkimas | F43: Pardavimas | K43: Dividendai
A44: Data | B44: Suma, EUR | C44: Kaina | D44: Kiekis | F44: Data | G44: Suma,EUR | H44: Kaina | I44: Kiekis | K44: Data | L44: Suma,EUR
A45: =N5 -> 46177 | B45: 1.12 | C45: 8.2394 | D45: =B45/C45 -> 0.13593223
A49: Viso: | B49: =SUM(B45:B48) -> 1.12 | C49: =SUMPRODUCT(C45:C48,D45:D48)/SUM(D45:D48) -> 8.2394 | D49: =SUM(D45:D48) -> 0.13593223 | F49: Viso: | G49: =SUM(G45:G48) -> 0 | I49: =SUM(I45:I48) -> 0 | K49: Viso: | L49: =SUM(L45:L48) -> 0
A52: EDMU GY iShares MSCI USA ESG Enhanced
A53: Pirkimas | F53: Pardavimas | K53: Dividendai
A54: Data | B54: Suma, EUR | C54: Kaina | D54: Kiekis | F54: Data | G54: Suma,EUR | H54: Kaina | I54: Kiekis | K54: Data | L54: Suma,EUR
A55: =N5 -> 46177 | B55: 6.3 | C55: 11.6837 | D55: =B55/C55 -> 0.53921275
A59: Viso: | B59: =SUM(B55:B58) -> 6.3 | C59: =SUMPRODUCT(C55:C58,D55:D58)/SUM(D55:D58) -> 11.6837 | D59: =SUM(D55:D58) -> 0.53921275 | F59: Viso: | G59: =SUM(G55:G58) -> 0 | I59: =SUM(I55:I58) -> 0 | K59: Viso: | L59: =SUM(L55:L58) -> 0

Sheet 2026.05
N2: 2026.05
N3: Robo-Advisor Investment
N4: Data | O4: Suma, EUR | P4: Invest. | Q4: Parduota | R4: Gryni | S4: Dividendai | T4: Mokestis
N5: 46147 | O5: 20 | P5: =B15+B25+B35+B45+B55 -> 19.97 | Q5: =G19+G29+G39+G49+G59 -> 0 | R5: =O5-P5+Q5 -> 0.03 | S5: =L19+L29+L39+L49+L59 -> 0 | T5: 0.3
N9: Viso: | O9: =SUM(O5:O8) -> 20 | P9: =SUM(P5:P8) -> 19.97 | Q9: =SUM(Q5:Q8) -> 0 | R9: =SUM(R5:R8) -> 0.03 | S9: =SUM(S5:S8) -> 0 | T9: =SUM(T5:T8) -> 0.3
A12: SGAS GY iShares MSCI USA ESG Screened
A13: Pirkimas | F13: Pardavimas | K13: Dividendai
A14: Data | B14: Suma, EUR | C14: Kaina | D14: Kiekis | F14: Data | G14: Suma,EUR | H14: Kaina | I14: Kiekis | K14: Data | L14: Suma,EUR
A15: =N5 -> 46147 | B15: 6.56 | C15: 12.8152 | D15: =B15/C15 -> 0.51189213
A19: Viso: | B19: =SUM(B15:B18) -> 6.56 | C19: =SUMPRODUCT(C15:C18,D15:D18)/SUM(D15:D18) -> 12.8152 | D19: =SUM(D15:D18) -> 0.51189213 | F19: Viso: | G19: =SUM(G15:G18) -> 0 | I19: =SUM(I15:I18) -> 0 | K19: Viso: | L19: =SUM(L15:L18) -> 0
A22: SLMC GY iShares MSCI Europe ESG Screened
A23: Pirkimas | F23: Pardavimas | K23: Dividendai
A24: Data | B24: Suma, EUR | C24: Kaina | D24: Kiekis | F24: Data | G24: Suma,EUR | H24: Kaina | I24: Kiekis | K24: Data | L24: Suma,EUR
A25: =N5 -> 46147 | B25: 3.23 | C25: 10.2187 | D25: =B25/C25 -> 0.31608717
A29: Viso: | B29: =SUM(B25:B28) -> 3.23 | C29: =SUMPRODUCT(C25:C28,D25:D28)/SUM(D25:D28) -> 10.2187 | D29: =SUM(D25:D28) -> 0.31608717 | F29: Viso: | G29: =SUM(G25:G28) -> 0 | I29: =SUM(I25:I28) -> 0 | K29: Viso: | L29: =SUM(L25:L28) -> 0
A32: AYEM GY iShares MSCI EM IMI ESG Screened
A33: Pirkimas | F33: Pardavimas | K33: Dividendai
A34: Data | B34: Suma, EUR | C34: Kaina | D34: Kiekis | F34: Data | G34: Suma,EUR | H34: Kaina | I34: Kiekis | K34: Data | L34: Suma,EUR
A35: =N5 -> 46147 | B35: 2.75 | C35: 8.6328 | D35: =B35/C35 -> 0.3185525
A39: Viso: | B39: =SUM(B35:B38) -> 2.75 | C39: =SUMPRODUCT(C35:C38,D35:D38)/SUM(D35:D38) -> 8.6328 | D39: =SUM(D35:D38) -> 0.3185525 | F39: Viso: | G39: =SUM(G35:G38) -> 0 | I39: =SUM(I35:I38) -> 0 | K39: Viso: | L39: =SUM(L35:L38) -> 0
A42: SGAJ GY iShares MSCI Japan ESG Screened
A43: Pirkimas | F43: Pardavimas | K43: Dividendai
A44: Data | B44: Suma, EUR | C44: Kaina | D44: Kiekis | F44: Data | G44: Suma,EUR | H44: Kaina | I44: Kiekis | K44: Data | L44: Suma,EUR
A45: =N5 -> 46147 | B45: 1.13 | C45: 7.78 | D45: =B45/C45 -> 0.14524422
A49: Viso: | B49: =SUM(B45:B48) -> 1.13 | C49: =SUMPRODUCT(C45:C48,D45:D48)/SUM(D45:D48) -> 7.78 | D49: =SUM(D45:D48) -> 0.14524422 | F49: Viso: | G49: =SUM(G45:G48) -> 0 | I49: =SUM(I45:I48) -> 0 | K49: Viso: | L49: =SUM(L45:L48) -> 0
A52: EDMU GY iShares MSCI USA ESG Enhanced
A53: Pirkimas | F53: Pardavimas | K53: Dividendai
A54: Data | B54: Suma, EUR | C54: Kaina | D54: Kiekis | F54: Data | G54: Suma,EUR | H54: Kaina | I54: Kiekis | K54: Data | L54: Suma,EUR
A55: =N5 -> 46147 | B55: 6.3 | C55: 11.052 | D55: =B55/C55 -> 0.57003257
A59: Viso: | B59: =SUM(B55:B58) -> 6.3 | C59: =SUMPRODUCT(C55:C58,D55:D58)/SUM(D55:D58) -> 11.052 | D59: =SUM(D55:D58) -> 0.57003257 | F59: Viso: | G59: =SUM(G55:G58) -> 0 | I59: =SUM(I55:I58) -> 0 | K59: Viso: | L59: =SUM(L55:L58) -> 0

Sheet 2026.04
N2: 2026.04
N3: Robo-Advisor Investment
N4: Data | O4: Suma, EUR | P4: Invest. | Q4: Parduota | R4: Gryni | S4: Dividendai | T4: Mokestis
N5: 46121 | O5: 20 | P5: =B16+B26+B36+B46+B56 -> 20.07 | Q5: =G20+G30+G40+G50+G60 -> 0 | R5: =O5-P5+Q5 -> -0.07 | S5: =L20+L30+L40+L50+L60 -> 0 | T5: 0.27
N9: Viso: | O9: =SUM(O5:O8) -> 20 | P9: =SUM(P5:P8) -> 20.07 | Q9: =SUM(Q5:Q8) -> 0 | R9: =SUM(R5:R8) -> -0.07 | S9: =SUM(S5:S8) -> 0 | T9: =SUM(T5:T8) -> 0.27
A13: SGAS GY iShares MSCI USA ESG Screened
A14: Pirkimas | F14: Pardavimas | K14: Dividendai
A15: Data | B15: Suma, EUR | C15: Kaina | D15: Kiekis | F15: Data | G15: Suma,EUR | H15: Kaina | I15: Kiekis | K15: Data | L15: Suma,EUR
A16: =N5 -> 46121 | B16: 6.52 | C16: 11.72 | D16: =B16/C16 -> 0.55631399
A20: Viso: | B20: =SUM(B16:B19) -> 6.52 | C20: =SUMPRODUCT(C16:C19,D16:D19)/SUM(D16:D19) -> 11.72 | D20: =SUM(D16:D19) -> 0.55631399 | F20: Viso: | G20: =SUM(G16:G19) -> 0 | I20: =SUM(I16:I19) -> 0 | K20: Viso: | L20: =SUM(L16:L19) -> 0
A23: SLMC GY iShares MSCI Europe ESG Screened
A24: Pirkimas | F24: Pardavimas | K24: Dividendai
A25: Data | B25: Suma, EUR | C25: Kaina | D25: Kiekis | F25: Data | G25: Suma,EUR | H25: Kaina | I25: Kiekis | K25: Data | L25: Suma,EUR
A26: =N5 -> 46121 | B26: 3.43 | C26: 9.966 | D26: =B26/C26 -> 0.34417018
A30: Viso: | B30: =SUM(B26:B29) -> 3.43 | C30: =SUMPRODUCT(C26:C29,D26:D29)/SUM(D26:D29) -> 9.966 | D30: =SUM(D26:D29) -> 0.34417018 | F30: Viso: | G30: =SUM(G26:G29) -> 0 | I30: =SUM(I26:I29) -> 0 | K30: Viso: | L30: =SUM(L26:L29) -> 0
A33: AYEM GY iShares MSCI EM IMI ESG Screened
A34: Pirkimas | F34: Pardavimas | K34: Dividendai
A35: Data | B35: Suma, EUR | C35: Kaina | D35: Kiekis | F35: Data | G35: Suma,EUR | H35: Kaina | I35: Kiekis | K35: Data | L35: Suma,EUR
A36: =N5 -> 46121 | B36: 2.65 | C36: 7.7116 | D36: =B36/C36 -> 0.34363816
A40: Viso: | B40: =SUM(B36:B39) -> 2.65 | C40: =SUMPRODUCT(C36:C39,D36:D39)/SUM(D36:D39) -> 7.7116 | D40: =SUM(D36:D39) -> 0.34363816 | F40: Viso: | G40: =SUM(G36:G39) -> 0 | I40: =SUM(I36:I39) -> 0 | K40: Viso: | L40: =SUM(L36:L39) -> 0
A43: SGAJ GY iShares MSCI Japan ESG Screened
A44: Pirkimas | F44: Pardavimas | K44: Dividendai
A45: Data | B45: Suma, EUR | C45: Kaina | D45: Kiekis | F45: Data | G45: Suma,EUR | H45: Kaina | I45: Kiekis | K45: Data | L45: Suma,EUR
A46: =N5 -> 46121 | B46: 1.18 | C46: 7.494 | D46: =B46/C46 -> 0.1574593
A50: Viso: | B50: =SUM(B46:B49) -> 1.18 | C50: =SUMPRODUCT(C46:C49,D46:D49)/SUM(D46:D49) -> 7.494 | D50: =SUM(D46:D49) -> 0.1574593 | F50: Viso: | G50: =SUM(G46:G49) -> 0 | I50: =SUM(I46:I49) -> 0 | K50: Viso: | L50: =SUM(L46:L49) -> 0
A53: EDMU GY iShares MSCI USA ESG Enhanced
A54: Pirkimas | F54: Pardavimas | K54: Dividendai
A55: Data | B55: Suma, EUR | C55: Kaina | D55: Kiekis | F55: Data | G55: Suma,EUR | H55: Kaina | I55: Kiekis | K55: Data | L55: Suma,EUR
A56: =N5 -> 46121 | B56: 6.29 | C56: 10.171 | D56: =B56/C56 -> 0.61842493
A60: Viso: | B60: =SUM(B56:B59) -> 6.29 | C60: =SUMPRODUCT(C56:C59,D56:D59)/SUM(D56:D59) -> 10.171 | D60: =SUM(D56:D59) -> 0.61842493 | F60: Viso: | G60: =SUM(G56:G59) -> 0 | I60: =SUM(I56:I59) -> 0 | K60: Viso: | L60: =SUM(L56:L59) -> 0

Sheet 2026.03
N2: 2026.03
N3: Robo-Advisor Investment
N4: Data | O4: Suma, EUR | P4: Invest. | Q4: Parduota | R4: Gryni | S4: Dividendai | T4: Mokestis
N5: 46086 | O5: 20 | P5: =B16+B26+B36+B46+B56 -> 19.98 | Q5: =G20+G30+G40+G50+G60 -> 0 | R5: =O5-P5+Q5 -> 0.02 | S5: =L20+L30+L40+L50+L60 -> 0 | T5: 0.25
N9: Viso: | O9: =SUM(O5:O8) -> 20 | P9: =SUM(P5:P8) -> 19.98 | Q9: =SUM(Q5:Q8) -> 0 | R9: =SUM(R5:R8) -> 0.02 | S9: =SUM(S5:S8) -> 0 | T9: =SUM(T5:T8) -> 0.25
A13: SGAS GY iShares MSCI USA ESG Screened
A14: Pirkimas | F14: Pardavimas | K14: Dividendai
A15: Data | B15: Suma, EUR | C15: Kaina | D15: Kiekis | F15: Data | G15: Suma,EUR | H15: Kaina | I15: Kiekis | K15: Data | L15: Suma,EUR
A16: =N5 -> 46086 | B16: 6.44 | C16: 11.944 | D16: =B16/C16 -> 0.53918285
A20: Viso: | B20: =SUM(B16:B19) -> 6.44 | C20: =SUMPRODUCT(C16:C19,D16:D19)/SUM(D16:D19) -> 11.944 | D20: =SUM(D16:D19) -> 0.53918285 | F20: Viso: | G20: =SUM(G16:G19) -> 0 | I20: =SUM(I16:I19) -> 0 | K20: Viso: | L20: =SUM(L16:L19) -> 0
A23: SLMC GY iShares MSCI Europe ESG Screened
A24: Pirkimas | F24: Pardavimas | K24: Dividendai
A25: Data | B25: Suma, EUR | C25: Kaina | D25: Kiekis | F25: Data | G25: Suma,EUR | H25: Kaina | I25: Kiekis | K25: Data | L25: Suma,EUR
A26: =N5 -> 46086 | B26: 3.42 | C26: 10.114 | D26: =B26/C26 -> 0.33814515
A30: Viso: | B30: =SUM(B26:B29) -> 3.42 | C30: =SUMPRODUCT(C26:C29,D26:D29)/SUM(D26:D29) -> 10.114 | D30: =SUM(D26:D29) -> 0.33814515 | F30: Viso: | G30: =SUM(G26:G29) -> 0 | I30: =SUM(I26:I29) -> 0 | K30: Viso: | L30: =SUM(L26:L29) -> 0
A33: AYEM GY iShares MSCI EM IMI ESG Screened
A34: Pirkimas | F34: Pardavimas | K34: Dividendai
A35: Data | B35: Suma, EUR | C35: Kaina | D35: Kiekis | F35: Data | G35: Suma,EUR | H35: Kaina | I35: Kiekis | K35: Data | L35: Suma,EUR
A36: =N5 -> 46086 | B36: 2.72 | C36: 7.9453 | D36: =B36/C36 -> 0.34234075
A40: Viso: | B40: =SUM(B36:B39) -> 2.72 | C40: =SUMPRODUCT(C36:C39,D36:D39)/SUM(D36:D39) -> 7.9453 | D40: =SUM(D36:D39) -> 0.34234075 | F40: Viso: | G40: =SUM(G36:G39) -> 0 | I40: =SUM(I36:I39) -> 0 | K40: Viso: | L40: =SUM(L36:L39) -> 0
A43: SGAJ GY iShares MSCI Japan ESG Screened
A44: Pirkimas | F44: Pardavimas | K44: Dividendai
A45: Data | B45: Suma, EUR | C45: Kaina | D45: Kiekis | F45: Data | G45: Suma,EUR | H45: Kaina | I45: Kiekis | K45: Data | L45: Suma,EUR
A46: =N5 -> 46086 | B46: 1.17 | C46: 7.4942 | D46: =B46/C46 -> 0.15612073
